Workbook

Sheet 0. Hướng dẫn
A1: CÔNG CỤ TÍNH GIÁ THÀNH THEO KỲ
B3: 6 BƯỚC SỬ DỤNG
B4: BƯỚC 1 – Chọn kỳ và phương pháp: mở [1. Danh mục & Tham số], nhập Tên DN, Kỳ, Từ ngày, Đến ngày; chọn Loại hình, Phương pháp, cách đánh giá dở dang, tiêu thức phân bổ; nhập Công suất bình thường và Mức hoạt động thực tế.
B5: BƯỚC 2 – Khai báo đối tượng: điền Danh mục đối tượng (Mã, Tên, Loại hình, ĐVT, Sản lượng, Giờ máy/Giờ công, Doanh thu, Hệ số, Giá thành ĐM, Trạng thái).
B6: BƯỚC 3 – Nhập chi phí: mở [2. Nhập chi phí]; chi phí trực tiếp chọn Mã đối tượng + Trực tiếp; chi phí chung chọn Mã = CHUNG + Chung; 627 chọn Cố định/Biến đổi. Chỉ chứng từ trong kỳ được tính.
B7: BƯỚC 4 – Nhập dở dang: mở [3. Dở dang], nhập số dư đầu kỳ và sản lượng/% dở dang.
B8: BƯỚC 5 – Kiểm tra cảnh báo: mở [6. Kiểm soát]; xử lý hết 🔴 và rà 🟡 trước khi tin kết quả.
B9: BƯỚC 6 – Xem giá thành và báo cáo: [4. Thẻ tính giá thành], [5. Báo cáo giá thành], [7. Dashboard], [8. Đối chiếu 154].
B11: CÁC Ô NÀO NGƯỜI DÙNG ĐƯỢC NHẬP?
B12: Chỉ các Ô VÀNG: khối Tham số & thông tin kỳ, Danh mục đối tượng, bảng Nhập chi phí, các ô dở dang. Tất cả ô XÁM là công thức đã khóa.
B13: Ô công thức (xám) đã khóa để tránh sửa nhầm; sheet bảo vệ KHÔNG mật khẩu, muốn sửa: Review ▸ Unprotect Sheet.
B15: NẾU XUẤT HIỆN CẢNH BÁO THÌ XỬ LÝ THẾ NÀO?
B16: 🔴 “TỔNG TIÊU THỨC = 0”: bạn có chi phí chung nhưng chưa nhập tiêu thức phân bổ cho đối tượng (giờ máy, nhân công…). Nhập tiêu thức tương ứng.
... B43: Kênh chia sẻ kiến thức Tài chính – Kế toán – Kiểm toán.

Sheet 1. Danh mục & Tham số
A1: DANH MỤC & THAM SỐ
P2: VÙNG DANH MỤC KỸ THUẬT (không sửa) | AB2: Danh sách mã (tự động)
A3: Tên doanh nghiệp | B3: Công ty TNHH ABC | P3: Sản xuất giản đơn | Q3: Sản phẩm | R3: Giản đơn | S3: Theo NVL trực tiếp | T3: NVL trực tiếp (621) | U3: NVL trực tiếp (621) | V3: Cố định | W3: Trực tiếp | X3: Đang thực hiện | Y3: NVL trực tiếp (621) | Z3: 621 | AB3: CHUNG
A4: Kỳ tính giá thành | B4: Tháng 08/2026 | P4: Sản xuất theo đơn đặt hàng | Q4: Đơn hàng | R4: Hệ số | S4: Theo sản lượng hoàn thành tương đương | T4: Nhân công trực tiếp (622) | U4: Nhân công trực tiếp (622) | V4: Biến đổi | W4: Chung | X4: Hoàn thành | Y4: Nhân công trực tiếp (622) | Z4: 622 | AB4: =IF(INDEX(DM_Ma,1)="","",INDEX(DM_Ma,1))
A5: Từ ngày | B5: 46235 | P5: Xây lắp | Q5: Công trình / Hạng mục | R5: Tỷ lệ | S5: Theo định mức | T5: Giờ máy | U5: Máy thi công (623) | V5: — | Y5: Máy thi công (623) | Z5: 623 | AB5: =IF(INDEX(DM_Ma,2)="","",INDEX(DM_Ma,2))
A6: Đến ngày | B6: 46265 | P6: Dịch vụ – gia công | Q6: Dịch vụ | R6: Đơn đặt hàng | T6: Giờ công | U6: SXC (627) | Y6: SXC (627) | Z6: 627 | AB6: =IF(INDEX(DM_Ma,3)="","",INDEX(DM_Ma,3))
A7: Đơn vị tiền tệ | B7: VND | T7: Sản lượng | U7: Phế liệu thu hồi | Y7: Phế liệu thu hồi | Z7: 154* | AB7: =IF(INDEX(DM_Ma,4)="","",INDEX(DM_Ma,4))
A8: Người lập | T8: Doanh thu | U8: SP hỏng ngoài định mức | Y8: SP hỏng ngoài định mức | Z8: 154* | AB8: =IF(INDEX(DM_Ma,5)="","",INDEX(DM_Ma,5))
A9: Ngày lập | B9: 46265 | T9: Tiêu thức khác | AB9: =IF(INDEX(DM_Ma,6)="","",INDEX(DM_Ma,6))
A10: Phiên bản file | B10: 2.0 | AB10: =IF(INDEX(DM_Ma,7)="","",INDEX(DM_Ma,7))
AB11: =IF(INDEX(DM_Ma,8)="","",INDEX(DM_Ma,8))
A12: Loại hình SXKD | B12: Sản xuất giản đơn | AB12: =IF(INDEX(DM_Ma,9)="","",INDEX(DM_Ma,9))
A13: Phương pháp tính giá thành | B13: Giản đơn | AB13: =IF(INDEX(DM_Ma,10)="","",INDEX(DM_Ma,10))
A14: Đánh giá dở dang cuối kỳ | B14: Theo sản lượng hoàn thành tương đương | AB14: =IF(INDEX(DM_Ma,11)="","",INDEX(DM_Ma,11))
A15: Tiêu thức phân bổ chi phí chung | B15: Nhân công trực tiếp (622) | AB15: =IF(INDEX(DM_Ma,12)="","",INDEX(DM_Ma,12))
A16: Công suất bình thường (giờ máy/kỳ) | B16: 1000 | AB16: =IF(INDEX(DM_Ma,13)="","",INDEX(DM_Ma,13))
A17: Mức hoạt động thực tế (giờ máy/kỳ) | B17: 900 | AB17: =IF(INDEX(DM_Ma,14)="","",INDEX(DM_Ma,14))
A18: → Tên đối tượng tính giá thành | B18: =INDEX(MAP_TenDT,MATCH(pLoaiHinh,LST_LoaiHinh,0)) | AB18: =IF(INDEX(DM_Ma,15)="","",INDEX(DM_Ma,15))
AB19: =IF(INDEX(DM_Ma,16)="","",INDEX(DM_Ma,16))
A20: DANH MỤC ĐỐI TƯỢNG TÍNH GIÁ THÀNH — thêm đối tượng tự do (đã chừa sẵn 80 dòng) | AB20: =IF(INDEX(DM_Ma,17)="","",INDEX(DM_Ma,17))
A21: Mã đối tượng | B21: Tên đối tượng | C21: Loại hình | D21: ĐVT | E21: SL hoàn thành | F21: Giờ máy | G21: Giờ công | H21: Doanh thu | I21: Tiêu thức khác | J21: Hệ số quy đổi | K21: Giá thành ĐM đơn vị | L21: Trạng thái | M21: (K.tra trùng) | N21: (K.tra mã) | AB21: =IF(INDEX(DM_Ma,18)="","",INDEX(DM_Ma,18))
M22: =IF($A22="","",IF(COUNTIF(DM_Ma,$A22)>1,"TRÙNG","")) | N22: =IF(AND($A22="",$B22<>""),"THIẾU MÃ","") | AB22: =IF(INDEX(DM_Ma,19)="","",INDEX(DM_Ma,19))
M23: =IF($A23="","",IF(COUNTIF(DM_Ma,$A23)>1,"TRÙNG","")) | N23: =IF(AND($A23="",$B23<>""),"THIẾU MÃ","") | AB23: =IF(INDEX(DM_Ma,20)="","",INDEX(DM_Ma,20))
M24: =IF($A24="","",IF(COUNTIF(DM_Ma,$A24)>1,"TRÙNG","")) | N24: =IF(AND($A24="",$B24<>""),"THIẾU MÃ","") | AB24: =IF(INDEX(DM_Ma,21)="","",INDEX(DM_Ma,21))
M25: =IF($A25="","",IF(COUNTIF(DM_Ma,$A25)>1,"TRÙNG","")) | N25: =IF(AND($A25="",$B25<>""),"THIẾU MÃ","") | AB25: =IF(INDEX(DM_Ma,22)="","",INDEX(DM_Ma,22))
M26: =IF($A26="","",IF(COUNTIF(DM_Ma,$A26)>1,"TRÙNG","")) | N26: =IF(AND($A26="",$B26<>""),"THIẾU MÃ","") | AB26: =IF(INDEX(DM_Ma,23)="","",INDEX(DM_Ma,23))
M27: =IF($A27="","",IF(COUNTIF(DM_Ma,$A27)>1,"TRÙNG","")) | N27: =IF(AND($A27="",$B27<>""),"THIẾU MÃ","") | AB27: =IF(INDEX(DM_Ma,24)="","",INDEX(DM_Ma,24))
M28: =IF($A28="","",IF(COUNTIF(DM_Ma,$A28)>1,"TRÙNG","")) | N28: =IF(AND($A28="",$B28<>""),"THIẾU MÃ","") | AB28: =IF(INDEX(DM_Ma,25)="","",INDEX(DM_Ma,25))
M29: =IF($A29="","",IF(COUNTIF(DM_Ma,$A29)>1,"TRÙNG","")) | N29: =IF(AND($A29="",$B29<>""),"THIẾU MÃ","") | AB29: =IF(INDEX(DM_Ma,26)="","",INDEX(DM_Ma,26))
M30: =IF($A30="","",IF(COUNTIF(DM_Ma,$A30)>1,"TRÙNG","")) | N30: =IF(AND($A30="",$B30<>""),"THIẾU MÃ","") | AB30: =IF(INDEX(DM_Ma,27)="","",INDEX(DM_Ma,27))
M31: =IF($A31="","",IF(COUNTIF(DM_Ma,$A31)>1,"TRÙNG","")) | N31: =IF(AND($A31="",$B31<>""),"THIẾU MÃ","") | AB31: =IF(INDEX(DM_Ma,28)="","",INDEX(DM_Ma,28))
M32: =IF($A32="","",IF(COUNTIF(DM_Ma,$A32)>1,"TRÙNG","")) | N32: =IF(AND($A32="",$B32<>""),"THIẾU MÃ","") | AB32: =IF(INDEX(DM_Ma,29)="","",INDEX(DM_Ma,29))
M33: =IF($A33="","",IF(COUNTIF(DM_Ma,$A33)>1,"TRÙNG","")) | N33: =IF(AND($A33="",$B33<>""),"THIẾU MÃ","") | AB33: =IF(INDEX(DM_Ma,30)="","",INDEX(DM_Ma,30))
M34: =IF($A34="","",IF(COUNTIF(DM_Ma,$A34)>1,"TRÙNG","")) | N34: =IF(AND($A34="",$B34<>""),"THIẾU MÃ","") | AB34: =IF(INDEX(DM_Ma,31)="","",INDEX(DM_Ma,31))
M35: =IF($A35="","",IF(COUNTIF(DM_Ma,$A35)>1,"TRÙNG","")) | N35: =IF(AND($A35="",$B35<>""),"THIẾU MÃ","") | AB35: =IF(INDEX(DM_Ma,32)="","",INDEX(DM_Ma,32))
M36: =IF($A36="","",IF(COUNTIF(DM_Ma,$A36)>1,"TRÙNG","")) | N36: =IF(AND($A36="",$B36<>""),"THIẾU MÃ","") | AB36: =IF(INDEX(DM_Ma,33)="","",INDEX(DM_Ma,33))
M37: =IF($A37="","",IF(COUNTIF(DM_Ma,$A37)>1,"TRÙNG","")) | N37: =IF(AND($A37="",$B37<>""),"THIẾU MÃ","") | AB37: =IF(INDEX(DM_Ma,34)="","",INDEX(DM_Ma,34))
M38: =IF($A38="","",IF(COUNTIF(DM_Ma,$A38)>1,"TRÙNG","")) | N38: =IF(AND($A38="",$B38<>""),"THIẾU MÃ","") | AB38: =IF(INDEX(DM_Ma,35)="","",INDEX(DM_Ma,35))
M39: =IF($A39="","",IF(COUNTIF(DM_Ma,$A39)>1,"TRÙNG","")) | N39: =IF(AND($A39="",$B39<>""),"THIẾU MÃ","") | AB39: =IF(INDEX(DM_Ma,36)="","",INDEX(DM_Ma,36))
M40: =IF($A40="","",IF(COUNTIF(DM_Ma,$A40)>1,"TRÙNG","")) | N40: =IF(AND($A40="",$B40<>""),"THIẾU MÃ","") | AB40: =IF(INDEX(DM_Ma,37)="","",INDEX(DM_Ma,37))
...

Sheet 2. Nhập chi phí
A1: ="NHẬP CHI PHÍ — "&pTenDoiTuong&" ("&TEXT(pTu,"dd/mm/yyyy")&" ÷ "&TEXT(pDen,"dd/mm/yyyy")&")"
A2: Nhập liên tục. Chi phí trực tiếp: chọn Mã đối tượng + Trực tiếp. Chi phí chung: Mã=CHUNG + Chung (sẽ phân bổ). Chỉ chi phí có Ngày trong kỳ mới được tính.
A4: Ngày | B4: Số CT | C4: Mã đối tượng | D4: Khoản mục chi phí | E4: TK | F4: Trực tiếp/Chung | G4: Tính chất SXC | H4: Tiêu thức PB (ghi chú) | I4: Diễn giải | J4: Số tiền | K4: Ghi chú
E5: =IFERROR(INDEX(MAP_TK,MATCH($D5,MAP_KM,0)),"") | M5: =IF($C5="","",IF(OR($C5="CHUNG",COUNTIF(DM_Ma,$C5)>0),"","MÃ LẠ")) | N5: =IF($A5="","",IF(AND($A5>=pTu,$A5<=pDen),"","NGOÀI KỲ")) | O5: =IF($J5="","",IF($J5<=0,"≤0","")) | P5: =IF(AND($D5="SXC (627)",$F5="Chung"),IF(OR($G5="Cố định",$G5="Biến đổi"),"","THIẾU TÍNH CHẤT"),"")
E6: =IFERROR(INDEX(MAP_TK,MATCH($D6,MAP_KM,0)),"") | M6: =IF($C6="","",IF(OR($C6="CHUNG",COUNTIF(DM_Ma,$C6)>0),"","MÃ LẠ")) | N6: =IF($A6="","",IF(AND($A6>=pTu,$A6<=pDen),"","NGOÀI KỲ")) | O6: =IF($J6="","",IF($J6<=0,"≤0","")) | P6: =IF(AND($D6="SXC (627)",$F6="Chung"),IF(OR($G6="Cố định",$G6="Biến đổi"),"","THIẾU TÍNH CHẤT"),"")
E7: =IFERROR(INDEX(MAP_TK,MATCH($D7,MAP_KM,0)),"") | M7: =IF($C7="","",IF(OR($C7="CHUNG",COUNTIF(DM_Ma,$C7)>0),"","MÃ LẠ")) | N7: =IF($A7="","",IF(AND($A7>=pTu,$A7<=pDen),"","NGOÀI KỲ")) | O7: =IF($J7="","",IF($J7<=0,"≤0","")) | P7: =IF(AND($D7="SXC (627)",$F7="Chung"),IF(OR($G7="Cố định",$G7="Biến đổi"),"","THIẾU TÍNH CHẤT"),"")
E8: =IFERROR(INDEX(MAP_TK,MATCH($D8,MAP_KM,0)),"") | M8: =IF($C8="","",IF(OR($C8="CHUNG",COUNTIF(DM_Ma,$C8)>0),"","MÃ LẠ")) | N8: =IF($A8="","",IF(AND($A8>=pTu,$A8<=pDen),"","NGOÀI KỲ")) | O8: =IF($J8="","",IF($J8<=0,"≤0","")) | P8: =IF(AND($D8="SXC (627)",$F8="Chung"),IF(OR($G8="Cố định",$G8="Biến đổi"),"","THIẾU TÍNH CHẤT"),"")
E9: =IFERROR(INDEX(MAP_TK,MATCH($D9,MAP_KM,0)),"") | M9: =IF($C9="","",IF(OR($C9="CHUNG",COUNTIF(DM_Ma,$C9)>0),"","MÃ LẠ")) | N9: =IF($A9="","",IF(AND($A9>=pTu,$A9<=pDen),"","NGOÀI KỲ")) | O9: =IF($J9="","",IF($J9<=0,"≤0","")) | P9: =IF(AND($D9="SXC (627)",$F9="Chung"),IF(OR($G9="Cố định",$G9="Biến đổi"),"","THIẾU TÍNH CHẤT"),"")
E10: =IFERROR(INDEX(MAP_TK,MATCH($D10,MAP_KM,0)),"") | M10: =IF($C10="","",IF(OR($C10="CHUNG",COUNTIF(DM_Ma,$C10)>0),"","MÃ LẠ")) | N10: =IF($A10="","",IF(AND($A10>=pTu,$A10<=pDen),"","NGOÀI KỲ")) | O10: =IF($J10="","",IF($J10<=0,"≤0","")) | P10: =IF(AND($D10="SXC (627)",$F10="Chung"),IF(OR($G10="Cố định",$G10="Biến đổi"),"","THIẾU TÍNH CHẤT"),"")
E11: =IFERROR(INDEX(MAP_TK,MATCH($D11,MAP_KM,0)),"") | M11: =IF($C11="","",IF(OR($C11="CHUNG",COUNTIF(DM_Ma,$C11)>0),"","MÃ LẠ")) | N11: =IF($A11="","",IF(AND($A11>=pTu,$A11<=pDen),"","NGOÀI KỲ")) | O11: =IF($J11="","",IF($J11<=0,"≤0","")) | P11: =IF(AND($D11="SXC (627)",$F11="Chung"),IF(OR($G11="Cố định",$G11="Biến đổi"),"","THIẾU TÍNH CHẤT"),"")
E12: =IFERROR(INDEX(MAP_TK,MATCH($D12,MAP_KM,0)),"") | M12: =IF($C12="","",IF(OR($C12="CHUNG",COUNTIF(DM_Ma,$C12)>0),"","MÃ LẠ")) | N12: =IF($A12="","",IF(AND($A12>=pTu,$A12<=pDen),"","NGOÀI KỲ")) | O12: =IF($J12="","",IF($J12<=0,"≤0","")) | P12: =IF(AND($D12="SXC (627)",$F12="Chung"),IF(OR($G12="Cố định",$G12="Biến đổi"),"","THIẾU TÍNH CHẤT"),"")
E13: =IFERROR(INDEX(MAP_TK,MATCH($D13,MAP_KM,0)),"") | M13: =IF($C13="","",IF(OR($C13="CHUNG",COUNTIF(DM_Ma,$C13)>0),"","MÃ LẠ")) | N13: =IF($A13="","",IF(AND($A13>=pTu,$A13<=pDen),"","NGOÀI KỲ")) | O13: =IF($J13="","",IF($J13<=0,"≤0","")) | P13: =IF(AND($D13="SXC (627)",$F13="Chung"),IF(OR($G13="Cố định",$G13="Biến đổi"),"","THIẾU TÍNH CHẤT"),"")
E14: =IFERROR(INDEX(MAP_TK,MATCH($D14,MAP_KM,0)),"") | M14: =IF($C14="","",IF(OR($C14="CHUNG",COUNTIF(DM_Ma,$C14)>0),"","MÃ LẠ")) | N14: =IF($A14="","",IF(AND($A14>=pTu,$A14<=pDen),"","NGOÀI KỲ")) | O14: =IF($J14="","",IF($J14<=0,"≤0","")) | P14: =IF(AND($D14="SXC (627)",$F14="Chung"),IF(OR($G14="Cố định",$G14="Biến đổi"),"","THIẾU TÍNH CHẤT"),"")
E15: =IFERROR(INDEX(MAP_TK,MATCH($D15,MAP_KM,0)),"") | M15: =IF($C15="","",IF(OR($C15="CHUNG",COUNTIF(DM_Ma,$C15)>0),"","MÃ LẠ")) | N15: =IF($A15="","",IF(AND($A15>=pTu,$A15<=pDen),"","NGOÀI KỲ")) | O15: =IF($J15="","",IF($J15<=0,"≤0","")) | P15: =IF(AND($D15="SXC (627)",$F15="Chung"),IF(OR($G15="Cố định",$G15="Biến đổi"),"","THIẾU TÍNH CHẤT"),"")
E16: =IFERROR(INDEX(MAP_TK,MATCH($D16,MAP_KM,0)),"") | M16: =IF($C16="","",IF(OR($C16="CHUNG",COUNTIF(DM_Ma,$C16)>0),"","MÃ LẠ")) | N16: =IF($A16="","",IF(AND($A16>=pTu,$A16<=pDen),"","NGOÀI KỲ")) | O16: =IF($J16="","",IF($J16<=0,"≤0","")) | P16: =IF(AND($D16="SXC (627)",$F16="Chung"),IF(OR($G16="Cố định",$G16="Biến đổi"),"","THIẾU TÍNH CHẤT"),"")
... E804: =IFERROR(INDEX(MAP_TK,MATCH($D804,MAP_KM,0)),"") | M804: =IF($C804="","",IF(OR($C804="CHUNG",COUNTIF(DM_Ma,$C804)>0),"","MÃ LẠ")) | N804: =IF($A804="","",IF(AND($A804>=pTu,$A804<=pDen),"","NGOÀI KỲ")) | O804: =IF($J804="","",IF($J804<=0,"≤0","")) | P804: =IF(AND($D804="SXC (627)",$F804="Chung"),IF(OR($G804="Cố định",$G804="Biến đổi"),"","THIẾU TÍNH CHẤT"),"")

Sheet 3. Dở dang
A1: ="ĐÁNH GIÁ DỞ DANG — "&pDoDang
A2: Nhập số dư đầu kỳ & sản lượng dở dang (ô vàng). DDCK tự tính theo phương pháp đã chọn. Đối tượng 'Đang thực hiện' sẽ tự treo toàn bộ chi phí là dở dang.
A4: ="Mã "&pTenDoiTuong | B4: Tên | C4: Trạng thái | D4: DDĐK 621 | E4: DDĐK 622 | F4: DDĐK 623 | G4: DDĐK 627 | H4: SL dở dang | I4: % hoàn thành | J4: Đơn giá ĐM DD | K4: SL hoàn thành | L4: DDCK (kết quả) | M4: (K.tra %)
A5: =IF(INDEX(DM_Ma,1)="","",INDEX(DM_Ma,1)) | B5: =IF($A5="","",INDEX(DM_Ten,1)) | C5: =IF($A5="","",INDEX(DM_TrangThai,1)) | K5: =IF($A5="","",INDEX(DM_SLHT,1)) | L5: =IF($A5="","",'4. Thẻ tính giá thành'!$Z$14) | M5: =IF($A5="","",IF(OR(INDEX(DM_Pct_v,1)<0,INDEX(DM_Pct_v,1)>1),"❌ % SAI",""))
A6: =IF(INDEX(DM_Ma,2)="","",INDEX(DM_Ma,2)) | B6: =IF($A6="","",INDEX(DM_Ten,2)) | C6: =IF($A6="","",INDEX(DM_TrangThai,2)) | K6: =IF($A6="","",INDEX(DM_SLHT,2)) | L6: =IF($A6="","",'4. Thẻ tính giá thành'!$Z$15) | M6: =IF($A6="","",IF(OR(INDEX(DM_Pct_v,2)<0,INDEX(DM_Pct_v,2)>1),"❌ % SAI",""))
A7: =IF(INDEX(DM_Ma,3)="","",INDEX(DM_Ma,3)) | B7: =IF($A7="","",INDEX(DM_Ten,3)) | C7: =IF($A7="","",INDEX(DM_TrangThai,3)) | K7: =IF($A7="","",INDEX(DM_SLHT,3)) | L7: =IF($A7="","",'4. Thẻ tính giá thành'!$Z$16) | M7: =IF($A7="","",IF(OR(INDEX(DM_Pct_v,3)<0,INDEX(DM_Pct_v,3)>1),"❌ % SAI",""))
A8: =IF(INDEX(DM_Ma,4)="","",INDEX(DM_Ma,4)) | B8: =IF($A8="","",INDEX(DM_Ten,4)) | C8: =IF($A8="","",INDEX(DM_TrangThai,4)) | K8: =IF($A8="","",INDEX(DM_SLHT,4)) | L8: =IF($A8="","",'4. Thẻ tính giá thành'!$Z$17) | M8: =IF($A8="","",IF(OR(INDEX(DM_Pct_v,4)<0,INDEX(DM_Pct_v,4)>1),"❌ % SAI",""))
A9: =IF(INDEX(DM_Ma,5)="","",INDEX(DM_Ma,5)) | B9: =IF($A9="","",INDEX(DM_Ten,5)) | C9: =IF($A9="","",INDEX(DM_TrangThai,5)) | K9: =IF($A9="","",INDEX(DM_SLHT,5)) | L9: =IF($A9="","",'4. Thẻ tính giá thành'!$Z$18) | M9: =IF($A9="","",IF(OR(INDEX(DM_Pct_v,5)<0,INDEX(DM_Pct_v,5)>1),"❌ % SAI",""))
A10: =IF(INDEX(DM_Ma,6)="","",INDEX(DM_Ma,6)) | B10: =IF($A10="","",INDEX(DM_Ten,6)) | C10: =IF($A10="","",INDEX(DM_TrangThai,6)) | K10: =IF($A10="","",INDEX(DM_SLHT,6)) | L10: =IF($A10="","",'4. Thẻ tính giá thành'!$Z$19) | M10: =IF($A10="","",IF(OR(INDEX(DM_Pct_v,6)<0,INDEX(DM_Pct_v,6)>1),"❌ % SAI",""))
A11: =IF(INDEX(DM_Ma,7)="","",INDEX(DM_Ma,7)) | B11: =IF($A11="","",INDEX(DM_Ten,7)) | C11: =IF($A11="","",INDEX(DM_TrangThai,7)) | K11: =IF($A11="","",INDEX(DM_SLHT,7)) | L11: =IF($A11="","",'4. Thẻ tính giá thành'!$Z$20) | M11: =IF($A11="","",IF(OR(INDEX(DM_Pct_v,7)<0,INDEX(DM_Pct_v,7)>1),"❌ % SAI",""))
A12: =IF(INDEX(DM_Ma,8)="","",INDEX(DM_Ma,8)) | B12: =IF($A12="","",INDEX(DM_Ten,8)) | C12: =IF($A12="","",INDEX(DM_TrangThai,8)) | K12: =IF($A12="","",INDEX(DM_SLHT,8)) | L12: =IF($A12="","",'4. Thẻ tính giá thành'!$Z$21) | M12: =IF($A12="","",IF(OR(INDEX(DM_Pct_v,8)<0,INDEX(DM_Pct_v,8)>1),"❌ % SAI",""))
A13: =IF(INDEX(DM_Ma,9)="","",INDEX(DM_Ma,9)) | B13: =IF($A13="","",INDEX(DM_Ten,9)) | C13: =IF($A13="","",INDEX(DM_TrangThai,9)) | K13: =IF($A13="","",INDEX(DM_SLHT,9)) | L13: =IF($A13="","",'4. Thẻ tính giá thành'!$Z$22) | M13: =IF($A13="","",IF(OR(INDEX(DM_Pct_v,9)<0,INDEX(DM_Pct_v,9)>1),"❌ % SAI",""))
A14: =IF(INDEX(DM_Ma,10)="","",INDEX(DM_Ma,10)) | B14: =IF($A14="","",INDEX(DM_Ten,10)) | C14: =IF($A14="","",INDEX(DM_TrangThai,10)) | K14: =IF($A14="","",INDEX(DM_SLHT,10)) | L14: =IF($A14="","",'4. Thẻ tính giá thành'!$Z$23) | M14: =IF($A14="","",IF(OR(INDEX(DM_Pct_v,10)<0,INDEX(DM_Pct_v,10)>1),"❌ % SAI",""))
A15: =IF(INDEX(DM_Ma,11)="","",INDEX(DM_Ma,11)) | B15: =IF($A15="","",INDEX(DM_Ten,11)) | C15: =IF($A15="","",INDEX(DM_TrangThai,11)) | K15: =IF($A15="","",INDEX(DM_SLHT,11)) | L15: =IF($A15="","",'4. Thẻ tính giá thành'!$Z$24) | M15: =IF($A15="","",IF(OR(INDEX(DM_Pct_v,11)<0,INDEX(DM_Pct_v,11)>1),"❌ % SAI",""))
A16: =IF(INDEX(DM_Ma,12)="","",INDEX(DM_Ma,12)) | B16: =IF($A16="","",INDEX(DM_Ten,12)) | C16: =IF($A16="","",INDEX(DM_TrangThai,12)) | K16: =IF($A16="","",INDEX(DM_SLHT,12)) | L16: =IF($A16="","",'4. Thẻ tính giá thành'!$Z$25) | M16: =IF($A16="","",IF(OR(INDEX(DM_Pct_v,12)<0,INDEX(DM_Pct_v,12)>1),"❌ % SAI",""))
A17: =IF(INDEX(DM_Ma,13)="","",INDEX(DM_Ma,13)) | B17: =IF($A17="","",INDEX(DM_Ten,13)) | C17: =IF($A17="","",INDEX(DM_TrangThai,13)) | K17: =IF($A17="","",INDEX(DM_SLHT,13)) | L17: =IF($A17="","",'4. Thẻ tính giá thành'!$Z$26) | M17: =IF($A17="","",IF(OR(INDEX(DM_Pct_v,13)<0,INDEX(DM_Pct_v,13)>1),"❌ % SAI",""))
A18: =IF(INDEX(DM_Ma,14)="","",INDEX(DM_Ma,14)) | B18: =IF($A18="","",INDEX(DM_Ten,14)) | C18: =IF($A18="","",INDEX(DM_TrangThai,14)) | K18: =IF($A18="","",INDEX(DM_SLHT,14)) | L18: =IF($A18="","",'4. Thẻ tính giá thành'!$Z$27) | M18: =IF($A18="","",IF(OR(INDEX(DM_Pct_v,14)<0,INDEX(DM_Pct_v,14)>1),"❌ % SAI",""))
A19: =IF(INDEX(DM_Ma,15)="","",INDEX(DM_Ma,15)) | B19: =IF($A19="","",INDEX(DM_Ten,15)) | C19: =IF($A19="","",INDEX(DM_TrangThai,15)) | K19: =IF($A19="","",INDEX(DM_SLHT,15)) | L19: =IF($A19="","",'4. Thẻ tính giá thành'!$Z$28) | M19: =IF($A19="","",IF(OR(INDEX(DM_Pct_v,15)<0,INDEX(DM_Pct_v,15)>1),"❌ % SAI",""))
A20: =IF(INDEX(DM_Ma,16)="","",INDEX(DM_Ma,16)) | B20: =IF($A20="","",INDEX(DM_Ten,16)) | C20: =IF($A20="","",INDEX(DM_TrangThai,16)) | K20: =IF($A20="","",INDEX(DM_SLHT,16)) | L20: =IF($A20="","",'4. Thẻ tính giá thành'!$Z$29) | M20: =IF($A20="","",IF(OR(INDEX(DM_Pct_v,16)<0,INDEX(DM_Pct_v,16)>1),"❌ % SAI",""))
A21: =IF(INDEX(DM_Ma,17)="","",INDEX(DM_Ma,17)) | B21: =IF($A21="","",INDEX(DM_Ten,17)) | C21: =IF($A21="","",INDEX(DM_TrangThai,17)) | K21: =IF($A21="","",INDEX(DM_SLHT,17)) | L21: =IF($A21="","",'4. Thẻ tính giá thành'!$Z$30) | M21: =IF($A21="","",IF(OR(INDEX(DM_Pct_v,17)<0,INDEX(DM_Pct_v,17)>1),"❌ % SAI",""))
A22: =IF(INDEX(DM_Ma,18)="","",INDEX(DM_Ma,18)) | B22: =IF($A22="","",INDEX(DM_Ten,18)) | C22: =IF($A22="","",INDEX(DM_TrangThai,18)) | K22: =IF($A22="","",INDEX(DM_SLHT,18)) | L22: =IF($A22="","",'4. Thẻ tính giá thành'!$Z$31) | M22: =IF($A22="","",IF(OR(INDEX(DM_Pct_v,18)<0,INDEX(DM_Pct_v,18)>1),"❌ % SAI",""))
A23: =IF(INDEX(DM_Ma,19)="","",INDEX(DM_Ma,19)) | B23: =IF($A23="","",INDEX(DM_Ten,19)) | C23: =IF($A23="","",INDEX(DM_TrangThai,19)) | K23: =IF($A23="","",INDEX(DM_SLHT,19)) | L23: =IF($A23="","",'4. Thẻ tính giá thành'!$Z$32) | M23: =IF($A23="","",IF(OR(INDEX(DM_Pct_v,19)<0,INDEX(DM_Pct_v,19)>1),"❌ % SAI",""))
A24: =IF(INDEX(DM_Ma,20)="","",INDEX(DM_Ma,20)) | B24: =IF($A24="","",INDEX(DM_Ten,20)) | C24: =IF($A24="","",INDEX(DM_TrangThai,20)) | K24: =IF($A24="","",INDEX(DM_SLHT,20)) | L24: =IF($A24="","",'4. Thẻ tính giá thành'!$Z$33) | M24: =IF($A24="","",IF(OR(INDEX(DM_Pct_v,20)<0,INDEX(DM_Pct_v,20)>1),"❌ % SAI",""))
A25: =IF(INDEX(DM_Ma,21)="","",INDEX(DM_Ma,21)) | B25: =IF($A25="","",INDEX(DM_Ten,21)) | C25: =IF($A25="","",INDEX(DM_TrangThai,21)) | K25: =IF($A25="","",INDEX(DM_SLHT,21)) | L25: =IF($A25="","",'4. Thẻ tính giá thành'!$Z$34) | M25: =IF($A25="","",IF(OR(INDEX(DM_Pct_v,21)<0,INDEX(DM_Pct_v,21)>1),"❌ % SAI",""))
A26: =IF(INDEX(DM_Ma,22)="","",INDEX(DM_Ma,22)) | B26: =IF($A26="","",INDEX(DM_Ten,22)) | C26: =IF($A26="","",INDEX(DM_TrangThai,22)) | K26: =IF($A26="","",INDEX(DM_SLHT,22)) | L26: =IF($A26="","",'4. Thẻ tính giá thành'!$Z$35) | M26: =IF($A26="","",IF(OR(INDEX(DM_Pct_v,22)<0,INDEX(DM_Pct_v,22)>1),"❌ % SAI",""))
A27: =IF(INDEX(DM_Ma,23)="","",INDEX(DM_Ma,23)) | B27: =IF($A27="","",INDEX(DM_Ten,23)) | C27: =IF($A27="","",INDEX(DM_TrangThai,23)) | K27: =IF($A27="","",INDEX(DM_SLHT,23)) | L27: =IF($A27="","",'4. Thẻ tính giá thành'!$Z$36) | M27: =IF($A27="","",IF(OR(INDEX(DM_Pct_v,23)<0,INDEX(DM_Pct_v,23)>1),"❌ % SAI",""))
A28: =IF(INDEX(DM_Ma,24)="","",INDEX(DM_Ma,24)) | B28: =IF($A28="","",INDEX(DM_Ten,24)) | C28: =IF($A28="","",INDEX(DM_TrangThai,24)) | K28: =IF($A28="","",INDEX(DM_SLHT,24)) | L28: =IF($A28="","",'4. Thẻ tính giá thành'!$Z$37) | M28: =IF($A28="","",IF(OR(INDEX(DM_Pct_v,24)<0,INDEX(DM_Pct_v,24)>1),"❌ % SAI",""))
A29: =IF(INDEX(DM_Ma,25)="","",INDEX(DM_Ma,25)) | B29: =IF($A29="","",INDEX(DM_Ten,25)) | C29: =IF($A29="","",INDEX(DM_TrangThai,25)) | K29: =IF($A29="","",INDEX(DM_SLHT,25)) | L29: =IF($A29="","",'4. Thẻ tính giá thành'!$Z$38) | M29: =IF($A29="","",IF(OR(INDEX(DM_Pct_v,25)<0,INDEX(DM_Pct_v,25)>1),"❌ % SAI",""))
A30: =IF(INDEX(DM_Ma,26)="","",INDEX(DM_Ma,26)) | B30: =IF($A30="","",INDEX(DM_Ten,26)) | C30: =IF($A30="","",INDEX(DM_TrangThai,26)) | K30: =IF($A30="","",INDEX(DM_SLHT,26)) | L30: =IF($A30="","",'4. Thẻ tính giá thành'!$Z$39) | M30: =IF($A30="","",IF(OR(INDEX(DM_Pct_v,26)<0,INDEX(DM_Pct_v,26)>1),"❌ % SAI",""))
A31: =IF(INDEX(DM_Ma,27)="","",INDEX(DM_Ma,27)) | B31: =IF($A31="","",INDEX(DM_Ten,27)) | C31: =IF($A31="","",INDEX(DM_TrangThai,27)) | K31: =IF($A31="","",INDEX(DM_SLHT,27)) | L31: =IF($A31="","",'4. Thẻ tính giá thành'!$Z$40) | M31: =IF($A31="","",IF(OR(INDEX(DM_Pct_v,27)<0,INDEX(DM_Pct_v,27)>1),"❌ % SAI",""))
A32: =IF(INDEX(DM_Ma,28)="","",INDEX(DM_Ma,28)) | B32: =IF($A32="","",INDEX(DM_Ten,28)) | C32: =IF($A32="","",INDEX(DM_TrangThai,28)) | K32: =IF($A32="","",INDEX(DM_SLHT,28)) | L32: =IF($A32="","",'4. Thẻ tính giá thành'!$Z$41) | M32: =IF($A32="","",IF(OR(INDEX(DM_Pct_v,28)<0,INDEX(DM_Pct_v,28)>1),"❌ % SAI",""))
A33: =IF(INDEX(DM_Ma,29)="","",INDEX(DM_Ma,29)) | B33: =IF($A33="","",INDEX(DM_Ten,29)) | C33: =IF($A33="","",INDEX(DM_TrangThai,29)) | K33: =IF($A33="","",INDEX(DM_SLHT,29)) | L33: =IF($A33="","",'4. Thẻ tính giá thành'!$Z$42) | M33: =IF($A33="","",IF(OR(INDEX(DM_Pct_v,29)<0,INDEX(DM_Pct_v,29)>1),"❌ % SAI",""))
A34: =IF(INDEX(DM_Ma,30)="","",INDEX(DM_Ma,30)) | B34: =IF($A34="","",INDEX(DM_Ten,30)) | C34: =IF($A34="","",INDEX(DM_TrangThai,30)) | K34: =IF($A34="","",INDEX(DM_SLHT,30)) | L34: =IF($A34="","",'4. Thẻ tính giá thành'!$Z$43) | M34: =IF($A34="","",IF(OR(INDEX(DM_Pct_v,30)<0,INDEX(DM_Pct_v,30)>1),"❌ % SAI",""))
A35: =IF(INDEX(DM_Ma,31)="","",INDEX(DM_Ma,31)) | B35: =IF($A35="","",INDEX(DM_Ten,31)) | C35: =IF($A35="","",INDEX(DM_TrangThai,31)) | K35: =IF($A35="","",INDEX(DM_SLHT,31)) | L35: =IF($A35="","",'4. Thẻ tính giá thành'!$Z$44) | M35: =IF($A35="","",IF(OR(INDEX(DM_Pct_v,31)<0,INDEX(DM_Pct_v,31)>1),"❌ % SAI",""))
A36: =IF(INDEX(DM_Ma,32)="","",INDEX(DM_Ma,32)) | B36: =IF($A36="","",INDEX(DM_Ten,32)) | C36: =IF($A36="","",INDEX(DM_TrangThai,32)) | K36: =IF($A36="","",INDEX(DM_SLHT,32)) | L36: =IF($A36="","",'4. Thẻ tính giá thành'!$Z$45) | M36: =IF($A36="","",IF(OR(INDEX(DM_Pct_v,32)<0,INDEX(DM_Pct_v,32)>1),"❌ % SAI",""))
A37: =IF(INDEX(DM_Ma,33)="","",INDEX(DM_Ma,33)) | B37: =IF($A37="","",INDEX(DM_Ten,33)) | C37: =IF($A37="","",INDEX(DM_TrangThai,33)) | K37: =IF($A37="","",INDEX(DM_SLHT,33)) | L37: =IF($A37="","",'4. Thẻ tính giá thành'!$Z$46) | M37: =IF($A37="","",IF(OR(INDEX(DM_Pct_v,33)<0,INDEX(DM_Pct_v,33)>1),"❌ % SAI",""))
A38: =IF(INDEX(DM_Ma,34)="","",INDEX(DM_Ma,34)) | B38: =IF($A38="","",INDEX(DM_Ten,34)) | C38: =IF($A38="","",INDEX(DM_TrangThai,34)) | K38: =IF($A38="","",INDEX(DM_SLHT,34)) | L38: =IF($A38="","",'4. Thẻ tính giá thành'!$Z$47) | M38: =IF($A38="","",IF(OR(INDEX(DM_Pct_v,34)<0,INDEX(DM_Pct_v,34)>1),"❌ % SAI",""))
A39: =IF(INDEX(DM_Ma,35)="","",INDEX(DM_Ma,35)) | B39: =IF($A39="","",INDEX(DM_Ten,35)) | C39: =IF($A39="","",INDEX(DM_TrangThai,35)) | K39: =IF($A39="","",INDEX(DM_SLHT,35)) | L39: =IF($A39="","",'4. Thẻ tính giá thành'!$Z$48) | M39: =IF($A39="","",IF(OR(INDEX(DM_Pct_v,35)<0,INDEX(DM_Pct_v,35)>1),"❌ % SAI",""))
A40: =IF(INDEX(DM_Ma,36)="","",INDEX(DM_Ma,36)) | B40: =IF($A40="","",INDEX(DM_Ten,36)) | C40: =IF($A40="","",INDEX(DM_TrangThai,36)) | K40: =IF($A40="","",INDEX(DM_SLHT,36)) | L40: =IF($A40="","",'4. Thẻ tính giá thành'!$Z$49) | M40: =IF($A40="","",IF(OR(INDEX(DM_Pct_v,36)<0,INDEX(DM_Pct_v,36)>1),"❌ % SAI",""))
A41: =IF(INDEX(DM_Ma,37)="","",INDEX(DM_Ma,37)) | B41: =IF($A41="","",INDEX(DM_Ten,37)) | C41: =IF($A41="","",INDEX(DM_TrangThai,37)) | K41: =IF($A41="","",INDEX(DM_SLHT,37)) | L41: =IF($A41="","",'4. Thẻ tính giá thành'!$Z$50) | M41: =IF($A41="","",IF(OR(INDEX(DM_Pct_v,37)<0,INDEX(DM_Pct_v,37)>1),"❌ % SAI",""))
...

Sheet 4. Thẻ tính giá thành
A1: ="THẺ TÍNH GIÁ THÀNH — "&pTenDoiTuong
A3: SXC 621 chung (chờ phân bổ) | E3: =SUMIFS(L_ST,L_KM,"NVL trực tiếp (621)",L_TT,"Chung",L_Ngay,">="&pTu,L_Ngay,"<="&pDen) | G3: =IF(AND(tBase=0,(pool621+pool622+pool623+pool627BD+t627CDabs)>0),"⚠ KHÔNG THỂ PHÂN BỔ – TỔNG TIÊU THỨC = 0","")
A4: 622 chung | E4: =SUMIFS(L_ST,L_KM,"Nhân công trực tiếp (622)",L_TT,"Chung",L_Ngay,">="&pTu,L_Ngay,"<="&pDen)
A5: 623 chung | E5: =SUMIFS(L_ST,L_KM,"Máy thi công (623)",L_TT,"Chung",L_Ngay,">="&pTu,L_Ngay,"<="&pDen) | G5: =IF(AND(pCongSuat<=0,pool627CD>0),"⚠ CHƯA NHẬP CÔNG SUẤT BÌNH THƯỜNG – KHÔNG XÁC ĐỊNH ĐƯỢC SXC CỐ ĐỊNH PHÂN BỔ","")
A6: 627 biến đổi (chung) | E6: =SUMIFS(L_ST,L_KM,"SXC (627)",L_TT,"Chung",L_Tinh,"Biến đổi",L_Ngay,">="&pTu,L_Ngay,"<="&pDen)
A7: 627 cố định (chung) | E7: =SUMIFS(L_ST,L_KM,"SXC (627)",L_TT,"Chung",L_Tinh,"Cố định",L_Ngay,">="&pTu,L_Ngay,"<="&pDen)
A8: Mức hoạt động = thực tế / bình thường | E8: =IFERROR(pHoatDong/pCongSuat,0)
A9: 627 cố định ĐƯỢC phân bổ vào giá thành | E9: =IF(pCongSuat<=0,0,MIN(1,tRatio)*pool627CD)
A10: 627 cố định VƯỢT công suất → Giá vốn 632 | E10: =pool627CD-t627CDabs
A13: ="Mã "&pTenDoiTuong | B13: Tên | C13: Loại hình | D13: Trạng thái | E13: 621 t.tiếp | F13: 622 t.tiếp | G13: 623 t.tiếp | H13: 627BĐ t.tiếp | I13: 627CĐ t.tiếp | J13: Tiêu thức | K13: 621 p.bổ | L13: 622 p.bổ | M13: 623 p.bổ | N13: 627BĐ p.bổ | O13: 627CĐ p.bổ | P13: 621 | Q13: 622 | R13: 623 | S13: 627 BĐ | T13: 627 CĐ | U13: Cộng 627 | V13: DDĐK | W13: Phế liệu | X13: SP hỏng | Y13: Cộng CP PS | Z13: DDCK | AA13: TỔNG GIÁ THÀNH | AB13: SL hoàn thành | AC13: Giá thành ĐV | AD13: hlpNVLTT | AE13: hlpTĐ | AF13: hlpĐM | AG13: chkSL | AH13: chkDDam | AI13: chkZam
A14: =IF(INDEX(DM_Ma,1)="","",INDEX(DM_Ma,1)) | B14: =IF($A14="","",INDEX(DM_Ten,1)) | C14: =IF($A14="","",INDEX(DM_Loai,1)) | D14: =IF($A14="","",INDEX(DM_TrangThai,1)) | E14: =IF($A14="","",SUMIFS(L_ST,L_Ma,$A14,L_KM,"NVL trực tiếp (621)",L_TT,"Trực tiếp",L_Ngay,">="&pTu,L_Ngay,"<="&pDen)) | F14: =IF($A14="","",SUMIFS(L_ST,L_Ma,$A14,L_KM,"Nhân công trực tiếp (622)",L_TT,"Trực tiếp",L_Ngay,">="&pTu,L_Ngay,"<="&pDen)) | G14: =IF($A14="","",SUMIFS(L_ST,L_Ma,$A14,L_KM,"Máy thi công (623)",L_TT,"Trực tiếp",L_Ngay,">="&pTu,L_Ngay,"<="&pDen)) | H14: =IF($A14="","",SUMIFS(L_ST,L_Ma,$A14,L_KM,"SXC (627)",L_TT,"Trực tiếp",L_Tinh,"Biến đổi",L_Ngay,">="&pTu,L_Ngay,"<="&pDen)) | I14: =IF($A14="","",SUMIFS(L_ST,L_Ma,$A14,L_KM,"SXC (627)",L_TT,"Trực tiếp",L_Tinh,"Cố định",L_Ngay,">="&pTu,L_Ngay,"<="&pDen)) | J14: =IF($A14="","",CHOOSE(MATCH(pTieuThuc,LST_TieuThuc,0),$E14,$F14,INDEX(DM_GioMay,1),INDEX(DM_GioCong,1),INDEX(DM_SLHT,1),INDEX(DM_DThu,1),INDEX(DM_TieuKhac,1))) | K14: =IF($A14="","",IF(tBase=0,0,$J14/tBase*pool621)) | L14: =IF($A14="","",IF(tBase=0,0,$J14/tBase*pool622)) | M14: =IF($A14="","",IF(tBase=0,0,$J14/tBase*pool623)) | N14: =IF($A14="","",IF(tBase=0,0,$J14/tBase*pool627BD)) | O14: =IF($A14="","",IF(tBase=0,0,$J14/tBase*t627CDabs)) | P14: =IF($A14="","",$E14+$K14) | Q14: =IF($A14="","",$F14+$L14) | R14: =IF($A14="","",$G14+$M14) | S14: =IF($A14="","",$H14+$N14) | T14: =IF($A14="","",$I14+$O14) | U14: =IF($A14="","",$S14+$T14) | V14: =IF($A14="","",INDEX(DM_DDK621,1)+INDEX(DM_DDK622,1)+INDEX(DM_DDK623,1)+INDEX(DM_DDK627,1)) | W14: =IF($A14="","",SUMIFS(L_ST,L_Ma,$A14,L_KM,"Phế liệu thu hồi",L_Ngay,">="&pTu,L_Ngay,"<="&pDen)) | X14: =IF($A14="","",SUMIFS(L_ST,L_Ma,$A14,L_KM,"SP hỏng ngoài định mức",L_Ngay,">="&pTu,L_Ngay,"<="&pDen)) | Y14: =IF($A14="","",$P14+$Q14+$R14+$U14) | Z14: =IF($A14="","",IF($D14="Đang thực hiện",$V14+$Y14,CHOOSE(MATCH(pDoDang,LST_DoDang,0),$AE14,$AF14,$AG14))) | AA14: =IF($A14="","",$V14+$Y14-$Z14-$W14-$X14) | AB14: =IF($A14="","",INDEX(DM_SLHT,1)) | AC14: =IF($A14="","",IF($AB14<=0,"⚠ CHƯA CÓ SL",ROUND($AA14/$AB14,0))) | AE14: =IF($A14="","",IFERROR((INDEX(DM_DDK621,1)+$P14)/($AB14+INDEX(DM_SLDD,1))*INDEX(DM_SLDD,1),0)) | AF14: =IF($A14="","",IFERROR((INDEX(DM_DDK621,1)+$P14)/($AB14+INDEX(DM_SLDD,1))*INDEX(DM_SLDD,1),0)+IFERROR((INDEX(DM_DDK622,1)+$Q14)/($AB14+INDEX(DM_SLDD,1)*INDEX(DM_Pct,1))*(INDEX(DM_SLDD,1)*INDEX(DM_Pct,1)),0)+IFERROR((INDEX(DM_DDK623,1)+$R14)/($AB14+INDEX(DM_SLDD,1)*INDEX(DM_Pct,1))*(INDEX(DM_SLDD,1)*INDEX(DM_Pct,1)),0)+IFERROR((INDEX(DM_DDK627,1)+$U14)/($AB14+INDEX(DM_SLDD,1)*INDEX(DM_Pct,1))*(INDEX(DM_SLDD,1)*INDEX(DM_Pct,1)),0)) | AG14: =IF($A14="","",INDEX(DM_SLDD,1)*INDEX(DM_DGDinhMuc,1)) | AH14: =IF($A14="",0,IF(AND(ISNUMBER($AA14),$AA14>0,$AB14<=0),1,0)) | AI14: =IF($A14="",0,IF(AND(ISNUMBER($Z14),$Z14<0),1,0)) | AJ14: =IF($A14="",0,IF(AND(ISNUMBER($AA14),$AA14<0),1,0))
A15: =IF(INDEX(DM_Ma,2)="","",INDEX(DM_Ma,2)) | B15: =IF($A15="","",INDEX(DM_Ten,2)) | C15: =IF($A15="","",INDEX(DM_Loai,2)) | D15: =IF($A15="","",INDEX(DM_TrangThai,2)) | E15: =IF($A15="","",SUMIFS(L_ST,L_Ma,$A15,L_KM,"NVL trực tiếp (621)",L_TT,"Trực tiếp",L_Ngay,">="&pTu,L_Ngay,"<="&pDen)) | F15: =IF($A15="","",SUMIFS(L_ST,L_Ma,$A15,L_KM,"Nhân công trực tiếp (622)",L_TT,"Trực tiếp",L_Ngay,">="&pTu,L_Ngay,"<="&pDen)) | G15: =IF($A15="","",SUMIFS(L_ST,L_Ma,$A15,L_KM,"Máy thi công (623)",L_TT,"Trực tiếp",L_Ngay,">="&pTu,L_Ngay,"<="&pDen)) | H15: =IF($A15="","",SUMIFS(L_ST,L_Ma,$A15,L_KM,"SXC (627)",L_TT,"Trực tiếp",L_Tinh,"Biến đổi",L_Ngay,">="&pTu,L_Ngay,"<="&pDen)) | I15: =IF($A15="","",SUMIFS(L_ST,L_Ma,$A15,L_KM,"SXC (627)",L_TT,"Trực tiếp",L_Tinh,"Cố định",L_Ngay,">="&pTu,L_Ngay,"<="&pDen)) | J15: =IF($A15="","",CHOOSE(MATCH(pTieuThuc,LST_TieuThuc,0),$E15,$F15,INDEX(DM_GioMay,2),INDEX(DM_GioCong,2),INDEX(DM_SLHT,2),INDEX(DM_DThu,2),INDEX(DM_TieuKhac,2))) | K15: =IF($A15="","",IF(tBase=0,0,$J15/tBase*pool621)) | L15: =IF($A15="","",IF(tBase=0,0,$J15/tBase*pool622)) | M15: =IF($A15="","",IF(tBase=0,0,$J15/tBase*pool623)) | N15: =IF($A15="","",IF(tBase=0,0,$J15/tBase*pool627BD)) | O15: =IF($A15="","",IF(tBase=0,0,$J15/tBase*t627CDabs)) | P15: =IF($A15="","",$E15+$K15) | Q15: =IF($A15="","",$F15+$L15) | R15: =IF($A15="","",$G15+$M15) | S15: =IF($A15="","",$H15+$N15) | T15: =IF($A15="","",$I15+$O15) | U15: =IF($A15="","",$S15+$T15) | V15: =IF($A15="","",INDEX(DM_DDK621,2)+INDEX(DM_DDK622,2)+INDEX(DM_DDK623,2)+INDEX(DM_DDK627,2)) | W15: =IF($A15="","",SUMIFS(L_ST,L_Ma,$A15,L_KM,"Phế liệu thu hồi",L_Ngay,">="&pTu,L_Ngay,"<="&pDen)) | X15: =IF($A15="","",SUMIFS(L_ST,L_Ma,$A15,L_KM,"SP hỏng ngoài định mức",L_Ngay,">="&pTu,L_Ngay,"<="&pDen)) | Y15: =IF($A15="","",$P15+$Q15+$R15+$U15) | Z15: =IF($A15="","",IF($D15="Đang thực hiện",$V15+$Y15,CHOOSE(MATCH(pDoDang,LST_DoDang,0),$AE15,$AF15,$AG15))) | AA15: =IF($A15="","",$V15+$Y15-$Z15-$W15-$X15) | AB15: =IF($A15="","",INDEX(DM_SLHT,2)) | AC15: =IF($A15="","",IF($AB15<=0,"⚠ CHƯA CÓ SL",ROUND($AA15/$AB15,0))) | AE15: =IF($A15="","",IFERROR((INDEX(DM_DDK621,2)+$P15)/($AB15+INDEX(DM_SLDD,2))*INDEX(DM_SLDD,2),0)) | AF15: =IF($A15="","",IFERROR((INDEX(DM_DDK621,2)+$P15)/($AB15+INDEX(DM_SLDD,2))*INDEX(DM_SLDD,2),0)+IFERROR((INDEX(DM_DDK622,2)+$Q15)/($AB15+INDEX(DM_SLDD,2)*INDEX(DM_Pct,2))*(INDEX(DM_SLDD,2)*INDEX(DM_Pct,2)),0)+IFERROR((INDEX(DM_DDK623,2)+$R15)/($AB15+INDEX(DM_SLDD,2)*INDEX(DM_Pct,2))*(INDEX(DM_SLDD,2)*INDEX(DM_Pct,2)),0)+IFERROR((INDEX(DM_DDK627,2)+$U15)/($AB15+INDEX(DM_SLDD,2)*INDEX(DM_Pct,2))*(INDEX(DM_SLDD,2)*INDEX(DM_Pct,2)),0)) | AG15: =IF($A15="","",INDEX(DM_SLDD,2)*INDEX(DM_DGDinhMuc,2)) | AH15: =IF($A15="",0,IF(AND(ISNUMBER($AA15),$AA15>0,$AB15<=0),1,0)) | AI15: =IF($A15="",0,IF(AND(ISNUMBER($Z15),$Z15<0),1,0)) | AJ15: =IF($A15="",0,IF(AND(ISNUMBER($AA15),$AA15<0),1,0))
A16: =IF(INDEX(DM_Ma,3)="","",INDEX(DM_Ma,3)) | B16: =IF($A16="","",INDEX(DM_Ten,3)) | C16: =IF($A16="","",INDEX(DM_Loai,3)) | D16: =IF($A16="","",INDEX(DM_TrangThai,3)) | E16: =IF($A16="","",SUMIFS(L_ST,L_Ma,$A16,L_KM,"NVL trực tiếp (621)",L_TT,"Trực tiếp",L_Ngay,">="&pTu,L_Ngay,"<="&pDen)) | F16: =IF($A16="","",SUMIFS(L_ST,L_Ma,$A16,L_KM,"Nhân công trực tiếp (622)",L_TT,"Trực tiếp",L_Ngay,">="&pTu,L_Ngay,"<="&pDen)) | G16: =IF($A16="","",SUMIFS(L_ST,L_Ma,$A16,L_KM,"Máy thi công (623)",L_TT,"Trực tiếp",L_Ngay,">="&pTu,L_Ngay,"<="&pDen)) | H16: =IF($A16="","",SUMIFS(L_ST,L_Ma,$A16,L_KM,"SXC (627)",L_TT,"Trực tiếp",L_Tinh,"Biến đổi",L_Ngay,">="&pTu,L_Ngay,"<="&pDen)) | I16: =IF($A16="","",SUMIFS(L_ST,L_Ma,$A16,L_KM,"SXC (627)",L_TT,"Trực tiếp",L_Tinh,"Cố định",L_Ngay,">="&pTu,L_Ngay,"<="&pDen)) | J16: =IF($A16="","",CHOOSE(MATCH(pTieuThuc,LST_TieuThuc,0),$E16,$F16,INDEX(DM_GioMay,3),INDEX(DM_GioCong,3),INDEX(DM_SLHT,3),INDEX(DM_DThu,3),INDEX(DM_TieuKhac,3))) | K16: =IF($A16="","",IF(tBase=0,0,$J16/tBase*pool621)) | L16: =IF($A16="","",IF(tBase=0,0,$J16/tBase*pool622)) | M16: =IF($A16="","",IF(tBase=0,0,$J16/tBase*pool623)) | N16: =IF($A16="","",IF(tBase=0,0,$J16/tBase*pool627BD)) | O16: =IF($A16="","",IF(tBase=0,0,$J16/tBase*t627CDabs)) | P16: =IF($A16="","",$E16+$K16) | Q16: =IF($A16="","",$F16+$L16) | R16: =IF($A16="","",$G16+$M16) | S16: =IF($A16="","",$H16+$N16) | T16: =IF($A16="","",$I16+$O16) | U16: =IF($A16="","",$S16+$T16) | V16: =IF($A16="","",INDEX(DM_DDK621,3)+INDEX(DM_DDK622,3)+INDEX(DM_DDK623,3)+INDEX(DM_DDK627,3)) | W16: =IF($A16="","",SUMIFS(L_ST,L_Ma,$A16,L_KM,"Phế liệu thu hồi",L_Ngay,">="&pTu,L_Ngay,"<="&pDen)) | X16: =IF($A16="","",SUMIFS(L_ST,L_Ma,$A16,L_KM,"SP hỏng ngoài định mức",L_Ngay,">="&pTu,L_Ngay,"<="&pDen)) | Y16: =IF($A16="","",$P16+$Q16+$R16+$U16) | Z16: =IF($A16="","",IF($D16="Đang thực hiện",$V16+$Y16,CHOOSE(MATCH(pDoDang,LST_DoDang,0),$AE16,$AF16,$AG16))) | AA16: =IF($A16="","",$V16+$Y16-$Z16-$W16-$X16) | AB16: =IF($A16="","",INDEX(DM_SLHT,3)) | AC16: =IF($A16="","",IF($AB16<=0,"⚠ CHƯA CÓ SL",ROUND($AA16/$AB16,0))) | AE16: =IF($A16="","",IFERROR((INDEX(DM_DDK621,3)+$P16)/($AB16+INDEX(DM_SLDD,3))*INDEX(DM_SLDD,3),0)) | AF16: =IF($A16="","",IFERROR((INDEX(DM_DDK621,3)+$P16)/($AB16+INDEX(DM_SLDD,3))*INDEX(DM_SLDD,3),0)+IFERROR((INDEX(DM_DDK622,3)+$Q16)/($AB16+INDEX(DM_SLDD,3)*INDEX(DM_Pct,3))*(INDEX(DM_SLDD,3)*INDEX(DM_Pct,3)),0)+IFERROR((INDEX(DM_DDK623,3)+$R16)/($AB16+INDEX(DM_SLDD,3)*INDEX(DM_Pct,3))*(INDEX(DM_SLDD,3)*INDEX(DM_Pct,3)),0)+IFERROR((INDEX(DM_DDK627,3)+$U16)/($AB16+INDEX(DM_SLDD,3)*INDEX(DM_Pct,3))*(INDEX(DM_SLDD,3)*INDEX(DM_Pct,3)),0)) | AG16: =IF($A16="","",INDEX(DM_SLDD,3)*INDEX(DM_DGDinhMuc,3)) | AH16: =IF($A16="",0,IF(AND(ISNUMBER($AA16),$AA16>0,$AB16<=0),1,0)) | AI16: =IF($A16="",0,IF(AND(ISNUMBER($Z16),$Z16<0),1,0)) | AJ16: =IF($A16="",0,IF(AND(ISNUMBER($AA16),$AA16<0),1,0))
A17: =IF(INDEX(DM_Ma,4)="","",INDEX(DM_Ma,4)) | B17: =IF($A17="","",INDEX(DM_Ten,4)) | C17: =IF($A17="","",INDEX(DM_Loai,4)) | D17: =IF($A17="","",INDEX(DM_TrangThai,4)) | E17: =IF($A17="","",SUMIFS(L_ST,L_Ma,$A17,L_KM,"NVL trực tiếp (621)",L_TT,"Trực tiếp",L_Ngay,">="&pTu,L_Ngay,"<="&pDen)) | F17: =IF($A17="","",SUMIFS(L_ST,L_Ma,$A17,L_KM,"Nhân công trực tiếp (622)",L_TT,"Trực tiếp",L_Ngay,">="&pTu,L_Ngay,"<="&pDen)) | G17: =IF($A17="","",SUMIFS(L_ST,L_Ma,$A17,L_KM,"Máy thi công (623)",L_TT,"Trực tiếp",L_Ngay,">="&pTu,L_Ngay,"<="&pDen)) | H17: =IF($A17="","",SUMIFS(L_ST,L_Ma,$A17,L_KM,"SXC (627)",L_TT,"Trực tiếp",L_Tinh,"Biến đổi",L_Ngay,">="&pTu,L_Ngay,"<="&pDen)) | I17: =IF($A17="","",SUMIFS(L_ST,L_Ma,$A17,L_KM,"SXC (627)",L_TT,"Trực tiếp",L_Tinh,"Cố định",L_Ngay,">="&pTu,L_Ngay,"<="&pDen)) | J17: =IF($A17="","",CHOOSE(MATCH(pTieuThuc,LST_TieuThuc,0),$E17,$F17,INDEX(DM_GioMay,4),INDEX(DM_GioCong,4),INDEX(DM_SLHT,4),INDEX(DM_DThu,4),INDEX(DM_TieuKhac,4))) | K17: =IF($A17="","",IF(tBase=0,0,$J17/tBase*pool621)) | L17: =IF($A17="","",IF(tBase=0,0,$J17/tBase*pool622)) | M17: =IF($A17="","",IF(tBase=0,0,$J17/tBase*pool623)) | N17: =IF($A17="","",IF(tBase=0,0,$J17/tBase*pool627BD)) | O17: =IF($A17="","",IF(tBase=0,0,$J17/tBase*t627CDabs)) | P17: =IF($A17="","",$E17+$K17) | Q17: =IF($A17="","",$F17+$L17) | R17: =IF($A17="","",$G17+$M17) | S17: =IF($A17="","",$H17+$N17) | T17: =IF($A17="","",$I17+$O17) | U17: =IF($A17="","",$S17+$T17) | V17: =IF($A17="","",INDEX(DM_DDK621,4)+INDEX(DM_DDK622,4)+INDEX(DM_DDK623,4)+INDEX(DM_DDK627,4)) | W17: =IF($A17="","",SUMIFS(L_ST,L_Ma,$A17,L_KM,"Phế liệu thu hồi",L_Ngay,">="&pTu,L_Ngay,"<="&pDen)) | X17: =IF($A17="","",SUMIFS(L_ST,L_Ma,$A17,L_KM,"SP hỏng ngoài định mức",L_Ngay,">="&pTu,L_Ngay,"<="&pDen)) | Y17: =IF($A17="","",$P17+$Q17+$R17+$U17) | Z17: =IF($A17="","",IF($D17="Đang thực hiện",$V17+$Y17,CHOOSE(MATCH(pDoDang,LST_DoDang,0),$AE17,$AF17,$AG17))) | AA17: =IF($A17="","",$V17+$Y17-$Z17-$W17-$X17) | AB17: =IF($A17="","",INDEX(DM_SLHT,4)) | AC17: =IF($A17="","",IF($AB17<=0,"⚠ CHƯA CÓ SL",ROUND($AA17/$AB17,0))) | AE17: =IF($A17="","",IFERROR((INDEX(DM_DDK621,4)+$P17)/($AB17+INDEX(DM_SLDD,4))*INDEX(DM_SLDD,4),0)) | AF17: =IF($A17="","",IFERROR((INDEX(DM_DDK621,4)+$P17)/($AB17+INDEX(DM_SLDD,4))*INDEX(DM_SLDD,4),0)+IFERROR((INDEX(DM_DDK622,4)+$Q17)/($AB17+INDEX(DM_SLDD,4)*INDEX(DM_Pct,4))*(INDEX(DM_SLDD,4)*INDEX(DM_Pct,4)),0)+IFERROR((INDEX(DM_DDK623,4)+$R17)/($AB17+INDEX(DM_SLDD,4)*INDEX(DM_Pct,4))*(INDEX(DM_SLDD,4)*INDEX(DM_Pct,4)),0)+IFERROR((INDEX(DM_DDK627,4)+$U17)/($AB17+INDEX(DM_SLDD,4)*INDEX(DM_Pct,4))*(INDEX(DM_SLDD,4)*INDEX(DM_Pct,4)),0)) | AG17: =IF($A17="","",INDEX(DM_SLDD,4)*INDEX(DM_DGDinhMuc,4)) | AH17: =IF($A17="",0,IF(AND(ISNUMBER($AA17),$AA17>0,$AB17<=0),1,0)) | AI17: =IF($A17="",0,IF(AND(ISNUMBER($Z17),$Z17<0),1,0)) | AJ17: =IF($A17="",0,IF(AND(ISNUMBER($AA17),$AA17<0),1,0))
A18: =IF(INDEX(DM_Ma,5)="","",INDEX(DM_Ma,5)) | B18: =IF($A18="","",INDEX(DM_Ten,5)) | C18: =IF($A18="","",INDEX(DM_Loai,5)) | D18: =IF($A18="","",INDEX(DM_TrangThai,5)) | E18: =IF($A18="","",SUMIFS(L_ST,L_Ma,$A18,L_KM,"NVL trực tiếp (621)",L_TT,"Trực tiếp",L_Ngay,">="&pTu,L_Ngay,"<="&pDen)) | F18: =IF($A18="","",SUMIFS(L_ST,L_Ma,$A18,L_KM,"Nhân công trực tiếp (622)",L_TT,"Trực tiếp",L_Ngay,">="&pTu,L_Ngay,"<="&pDen)) | G18: =IF($A18="","",SUMIFS(L_ST,L_Ma,$A18,L_KM,"Máy thi công (623)",L_TT,"Trực tiếp",L_Ngay,">="&pTu,L_Ngay,"<="&pDen)) | H18: =IF($A18="","",SUMIFS(L_ST,L_Ma,$A18,L_KM,"SXC (627)",L_TT,"Trực tiếp",L_Tinh,"Biến đổi",L_Ngay,">="&pTu,L_Ngay,"<="&pDen)) | I18: =IF($A18="","",SUMIFS(L_ST,L_Ma,$A18,L_KM,"SXC (627)",L_TT,"Trực tiếp",L_Tinh,"Cố định",L_Ngay,">="&pTu,L_Ngay,"<="&pDen)) | J18: =IF($A18="","",CHOOSE(MATCH(pTieuThuc,LST_TieuThuc,0),$E18,$F18,INDEX(DM_GioMay,5),INDEX(DM_GioCong,5),INDEX(DM_SLHT,5),INDEX(DM_DThu,5),INDEX(DM_TieuKhac,5))) | K18: =IF($A18="","",IF(tBase=0,0,$J18/tBase*pool621)) | L18: =IF($A18="","",IF(tBase=0,0,$J18/tBase*pool622)) | M18: =IF($A18="","",IF(tBase=0,0,$J18/tBase*pool623)) | N18: =IF($A18="","",IF(tBase=0,0,$J18/tBase*pool627BD)) | O18: =IF($A18="","",IF(tBase=0,0,$J18/tBase*t627CDabs)) | P18: =IF($A18="","",$E18+$K18) | Q18: =IF($A18="","",$F18+$L18) | R18: =IF($A18="","",$G18+$M18) | S18: =IF($A18="","",$H18+$N18) | T18: =IF($A18="","",$I18+$O18) | U18: =IF($A18="","",$S18+$T18) | V18: =IF($A18="","",INDEX(DM_DDK621,5)+INDEX(DM_DDK622,5)+INDEX(DM_DDK623,5)+INDEX(DM_DDK627,5)) | W18: =IF($A18="","",SUMIFS(L_ST,L_Ma,$A18,L_KM,"Phế liệu thu hồi",L_Ngay,">="&pTu,L_Ngay,"<="&pDen)) | X18: =IF($A18="","",SUMIFS(L_ST,L_Ma,$A18,L_KM,"SP hỏng ngoài định mức",L_Ngay,">="&pTu,L_Ngay,"<="&pDen)) | Y18: =IF($A18="","",$P18+$Q18+$R18+$U18) | Z18: =IF($A18="","",IF($D18="Đang thực hiện",$V18+$Y18,CHOOSE(MATCH(pDoDang,LST_DoDang,0),$AE18,$AF18,$AG18))) | AA18: =IF($A18="","",$V18+$Y18-$Z18-$W18-$X18) | AB18: =IF($A18="","",INDEX(DM_SLHT,5)) | AC18: =IF($A18="","",IF($AB18<=0,"⚠ CHƯA CÓ SL",ROUND($AA18/$AB18,0))) | AE18: =IF($A18="","",IFERROR((INDEX(DM_DDK621,5)+$P18)/($AB18+INDEX(DM_SLDD,5))*INDEX(DM_SLDD,5),0)) | AF18: =IF($A18="","",IFERROR((INDEX(DM_DDK621,5)+$P18)/($AB18+INDEX(DM_SLDD,5))*INDEX(DM_SLDD,5),0)+IFERROR((INDEX(DM_DDK622,5)+$Q18)/($AB18+INDEX(DM_SLDD,5)*INDEX(DM_Pct,5))*(INDEX(DM_SLDD,5)*INDEX(DM_Pct,5)),0)+IFERROR((INDEX(DM_DDK623,5)+$R18)/($AB18+INDEX(DM_SLDD,5)*INDEX(DM_Pct,5))*(INDEX(DM_SLDD,5)*INDEX(DM_Pct,5)),0)+IFERROR((INDEX(DM_DDK627,5)+$U18)/($AB18+INDEX(DM_SLDD,5)*INDEX(DM_Pct,5))*(INDEX(DM_SLDD,5)*INDEX(DM_Pct,5)),0)) | AG18: =IF($A18="","",INDEX(DM_SLDD,5)*INDEX(DM_DGDinhMuc,5)) | AH18: =IF($A18="",0,IF(AND(ISNUMBER($AA18),$AA18>0,$AB18<=0),1,0)) | AI18: =IF($A18="",0,IF(AND(ISNUMBER($Z18),$Z18<0),1,0)) | AJ18: =IF($A18="",0,IF(AND(ISNUMBER($AA18),$AA18<0),1,0))
A19: =IF(INDEX(DM_Ma,6)="","",INDEX(DM_Ma,6)) | B19: =IF($A19="","",INDEX(DM_Ten,6)) | C19: =IF($A19="","",INDEX(DM_Loai,6)) | D19: =IF($A19="","",INDEX(DM_TrangThai,6)) | E19: =IF($A19="","",SUMIFS(L_ST,L_Ma,$A19,L_KM,"NVL trực tiếp (621)",L_TT,"Trực tiếp",L_Ngay,">="&pTu,L_Ngay,"<="&pDen)) | F19: =IF($A19="","",SUMIFS(L_ST,L_Ma,$A19,L_KM,"Nhân công trực tiếp (622)",L_TT,"Trực tiếp",L_Ngay,">="&pTu,L_Ngay,"<="&pDen)) | G19: =IF($A19="","",SUMIFS(L_ST,L_Ma,$A19,L_KM,"Máy thi công (623)",L_TT,"Trực tiếp",L_Ngay,">="&pTu,L_Ngay,"<="&pDen)) | H19: =IF($A19="","",SUMIFS(L_ST,L_Ma,$A19,L_KM,"SXC (627)",L_TT,"Trực tiếp",L_Tinh,"Biến đổi",L_Ngay,">="&pTu,L_Ngay,"<="&pDen)) | I19: =IF($A19="","",SUMIFS(L_ST,L_Ma,$A19,L_KM,"SXC (627)",L_TT,"Trực tiếp",L_Tinh,"Cố định",L_Ngay,">="&pTu,L_Ngay,"<="&pDen)) | J19: =IF($A19="","",CHOOSE(MATCH(pTieuThuc,LST_TieuThuc,0),$E19,$F19,INDEX(DM_GioMay,6),INDEX(DM_GioCong,6),INDEX(DM_SLHT,6),INDEX(DM_DThu,6),INDEX(DM_TieuKhac,6))) | K19: =IF($A19="","",IF(tBase=0,0,$J19/tBase*pool621)) | L19: =IF($A19="","",IF(tBase=0,0,$J19/tBase*pool622)) | M19: =IF($A19="","",IF(tBase=0,0,$J19/tBase*pool623)) | N19: =IF($A19="","",IF(tBase=0,0,$J19/tBase*pool627BD)) | O19: =IF($A19="","",IF(tBase=0,0,$J19/tBase*t627CDabs)) | P19: =IF($A19="","",$E19+$K19) | Q19: =IF($A19="","",$F19+$L19) | R19: =IF($A19="","",$G19+$M19) | S19: =IF($A19="","",$H19+$N19) | T19: =IF($A19="","",$I19+$O19) | U19: =IF($A19="","",$S19+$T19) | V19: =IF($A19="","",INDEX(DM_DDK621,6)+INDEX(DM_DDK622,6)+INDEX(DM_DDK623,6)+INDEX(DM_DDK627,6)) | W19: =IF($A19="","",SUMIFS(L_ST,L_Ma,$A19,L_KM,"Phế liệu thu hồi",L_Ngay,">="&pTu,L_Ngay,"<="&pDen)) | X19: =IF($A19="","",SUMIFS(L_ST,L_Ma,$A19,L_KM,"SP hỏng ngoài định mức",L_Ngay,">="&pTu,L_Ngay,"<="&pDen)) | Y19: =IF($A19="","",$P19+$Q19+$R19+$U19) | Z19: =IF($A19="","",IF($D19="Đang thực hiện",$V19+$Y19,CHOOSE(MATCH(pDoDang,LST_DoDang,0),$AE19,$AF19,$AG19))) | AA19: =IF($A19="","",$V19+$Y19-$Z19-$W19-$X19) | AB19: =IF($A19="","",INDEX(DM_SLHT,6)) | AC19: =IF($A19="","",IF($AB19<=0,"⚠ CHƯA CÓ SL",ROUND($AA19/$AB19,0))) | AE19: =IF($A19="","",IFERROR((INDEX(DM_DDK621,6)+$P19)/($AB19+INDEX(DM_SLDD,6))*INDEX(DM_SLDD,6),0)) | AF19: =IF($A19="","",IFERROR((INDEX(DM_DDK621,6)+$P19)/($AB19+INDEX(DM_SLDD,6))*INDEX(DM_SLDD,6),0)+IFERROR((INDEX(DM_DDK622,6)+$Q19)/($AB19+INDEX(DM_SLDD,6)*INDEX(DM_Pct,6))*(INDEX(DM_SLDD,6)*INDEX(DM_Pct,6)),0)+IFERROR((INDEX(DM_DDK623,6)+$R19)/($AB19+INDEX(DM_SLDD,6)*INDEX(DM_Pct,6))*(INDEX(DM_SLDD,6)*INDEX(DM_Pct,6)),0)+IFERROR((INDEX(DM_DDK627,6)+$U19)/($AB19+INDEX(DM_SLDD,6)*INDEX(DM_Pct,6))*(INDEX(DM_SLDD,6)*INDEX(DM_Pct,6)),0)) | AG19: =IF($A19="","",INDEX(DM_SLDD,6)*INDEX(DM_DGDinhMuc,6)) | AH19: =IF($A19="",0,IF(AND(ISNUMBER($AA19),$AA19>0,$AB19<=0),1,0)) | AI19: =IF($A19="",0,IF(AND(ISNUMBER($Z19),$Z19<0),1,0)) | AJ19: =IF($A19="",0,IF(AND(ISNUMBER($AA19),$AA19<0),1,0))
A20: =IF(INDEX(DM_Ma,7)="","",INDEX(DM_Ma,7)) | B20: =IF($A20="","",INDEX(DM_Ten,7)) | C20: =IF($A20="","",INDEX(DM_Loai,7)) | D20: =IF($A20="","",INDEX(DM_TrangThai,7)) | E20: =IF($A20="","",SUMIFS(L_ST,L_Ma,$A20,L_KM,"NVL trực tiếp (621)",L_TT,"Trực tiếp",L_Ngay,">="&pTu,L_Ngay,"<="&pDen)) | F20: =IF($A20="","",SUMIFS(L_ST,L_Ma,$A20,L_KM,"Nhân công trực tiếp (622)",L_TT,"Trực tiếp",L_Ngay,">="&pTu,L_Ngay,"<="&pDen)) | G20: =IF($A20="","",SUMIFS(L_ST,L_Ma,$A20,L_KM,"Máy thi công (623)",L_TT,"Trực tiếp",L_Ngay,">="&pTu,L_Ngay,"<="&pDen)) | H20: =IF($A20="","",SUMIFS(L_ST,L_Ma,$A20,L_KM,"SXC (627)",L_TT,"Trực tiếp",L_Tinh,"Biến đổi",L_Ngay,">="&pTu,L_Ngay,"<="&pDen)) | I20: =IF($A20="","",SUMIFS(L_ST,L_Ma,$A20,L_KM,"SXC (627)",L_TT,"Trực tiếp",L_Tinh,"Cố định",L_Ngay,">="&pTu,L_Ngay,"<="&pDen)) | J20: =IF($A20="","",CHOOSE(MATCH(pTieuThuc,LST_TieuThuc,0),$E20,$F20,INDEX(DM_GioMay,7),INDEX(DM_GioCong,7),INDEX(DM_SLHT,7),INDEX(DM_DThu,7),INDEX(DM_TieuKhac,7))) | K20: =IF($A20="","",IF(tBase=0,0,$J20/tBase*pool621)) | L20: =IF($A20="","",IF(tBase=0,0,$J20/tBase*pool622)) | M20: =IF($A20="","",IF(tBase=0,0,$J20/tBase*pool623)) | N20: =IF($A20="","",IF(tBase=0,0,$J20/tBase*pool627BD)) | O20: =IF($A20="","",IF(tBase=0,0,$J20/tBase*t627CDabs)) | P20: =IF($A20="","",$E20+$K20) | Q20: =IF($A20="","",$F20+$L20) | R20: =IF($A20="","",$G20+$M20) | S20: =IF($A20="","",$H20+$N20) | T20: =IF($A20="","",$I20+$O20) | U20: =IF($A20="","",$S20+$T20) | V20: =IF($A20="","",INDEX(DM_DDK621,7)+INDEX(DM_DDK622,7)+INDEX(DM_DDK623,7)+INDEX(DM_DDK627,7)) | W20: =IF($A20="","",SUMIFS(L_ST,L_Ma,$A20,L_KM,"Phế liệu thu hồi",L_Ngay,">="&pTu,L_Ngay,"<="&pDen)) | X20: =IF($A20="","",SUMIFS(L_ST,L_Ma,$A20,L_KM,"SP hỏng ngoài định mức",L_Ngay,">="&pTu,L_Ngay,"<="&pDen)) | Y20: =IF($A20="","",$P20+$Q20+$R20+$U20) | Z20: =IF($A20="","",IF($D20="Đang thực hiện",$V20+$Y20,CHOOSE(MATCH(pDoDang,LST_DoDang,0),$AE20,$AF20,$AG20))) | AA20: =IF($A20="","",$V20+$Y20-$Z20-$W20-$X20) | AB20: =IF($A20="","",INDEX(DM_SLHT,7)) | AC20: =IF($A20="","",IF($AB20<=0,"⚠ CHƯA CÓ SL",ROUND($AA20/$AB20,0))) | AE20: =IF($A20="","",IFERROR((INDEX(DM_DDK621,7)+$P20)/($AB20+INDEX(DM_SLDD,7))*INDEX(DM_SLDD,7),0)) | AF20: =IF($A20="","",IFERROR((INDEX(DM_DDK621,7)+$P20)/($AB20+INDEX(DM_SLDD,7))*INDEX(DM_SLDD,7),0)+IFERROR((INDEX(DM_DDK622,7)+$Q20)/($AB20+INDEX(DM_SLDD,7)*INDEX(DM_Pct,7))*(INDEX(DM_SLDD,7)*INDEX(DM_Pct,7)),0)+IFERROR((INDEX(DM_DDK623,7)+$R20)/($AB20+INDEX(DM_SLDD,7)*INDEX(DM_Pct,7))*(INDEX(DM_SLDD,7)*INDEX(DM_Pct,7)),0)+IFERROR((INDEX(DM_DDK627,7)+$U20)/($AB20+INDEX(DM_SLDD,7)*INDEX(DM_Pct,7))*(INDEX(DM_SLDD,7)*INDEX(DM_Pct,7)),0)) | AG20: =IF($A20="","",INDEX(DM_SLDD,7)*INDEX(DM_DGDinhMuc,7)) | AH20: =IF($A20="",0,IF(AND(ISNUMBER($AA20),$AA20>0,$AB20<=0),1,0)) | AI20: =IF($A20="",0,IF(AND(ISNUMBER($Z20),$Z20<0),1,0)) | AJ20: =IF($A20="",0,IF(AND(ISNUMBER($AA20),$AA20<0),1,0))
A21: =IF(INDEX(DM_Ma,8)="","",INDEX(DM_Ma,8)) | B21: =IF($A21="","",INDEX(DM_Ten,8)) | C21: =IF($A21="","",INDEX(DM_Loai,8)) | D21: =IF($A21="","",INDEX(DM_TrangThai,8)) | E21: =IF($A21="","",SUMIFS(L_ST,L_Ma,$A21,L_KM,"NVL trực tiếp (621)",L_TT,"Trực tiếp",L_Ngay,">="&pTu,L_Ngay,"<="&pDen)) | F21: =IF($A21="","",SUMIFS(L_ST,L_Ma,$A21,L_KM,"Nhân công trực tiếp (622)",L_TT,"Trực tiếp",L_Ngay,">="&pTu,L_Ngay,"<="&pDen)) | G21: =IF($A21="","",SUMIFS(L_ST,L_Ma,$A21,L_KM,"Máy thi công (623)",L_TT,"Trực tiếp",L_Ngay,">="&pTu,L_Ngay,"<="&pDen)) | H21: =IF($A21="","",SUMIFS(L_ST,L_Ma,$A21,L_KM,"SXC (627)",L_TT,"Trực tiếp",L_Tinh,"Biến đổi",L_Ngay,">="&pTu,L_Ngay,"<="&pDen)) | I21: =IF($A21="","",SUMIFS(L_ST,L_Ma,$A21,L_KM,"SXC (627)",L_TT,"Trực tiếp",L_Tinh,"Cố định",L_Ngay,">="&pTu,L_Ngay,"<="&pDen)) | J21: =IF($A21="","",CHOOSE(MATCH(pTieuThuc,LST_TieuThuc,0),$E21,$F21,INDEX(DM_GioMay,8),INDEX(DM_GioCong,8),INDEX(DM_SLHT,8),INDEX(DM_DThu,8),INDEX(DM_TieuKhac,8))) | K21: =IF($A21="","",IF(tBase=0,0,$J21/tBase*pool621)) | L21: =IF($A21="","",IF(tBase=0,0,$J21/tBase*pool622)) | M21: =IF($A21="","",IF(tBase=0,0,$J21/tBase*pool623)) | N21: =IF($A21="","",IF(tBase=0,0,$J21/tBase*pool627BD)) | O21: =IF($A21="","",IF(tBase=0,0,$J21/tBase*t627CDabs)) | P21: =IF($A21="","",$E21+$K21) | Q21: =IF($A21="","",$F21+$L21) | R21: =IF($A21="","",$G21+$M21) | S21: =IF($A21="","",$H21+$N21) | T21: =IF($A21="","",$I21+$O21) | U21: =IF($A21="","",$S21+$T21) | V21: =IF($A21="","",INDEX(DM_DDK621,8)+INDEX(DM_DDK622,8)+INDEX(DM_DDK623,8)+INDEX(DM_DDK627,8)) | W21: =IF($A21="","",SUMIFS(L_ST,L_Ma,$A21,L_KM,"Phế liệu thu hồi",L_Ngay,">="&pTu,L_Ngay,"<="&pDen)) | X21: =IF($A21="","",SUMIFS(L_ST,L_Ma,$A21,L_KM,"SP hỏng ngoài định mức",L_Ngay,">="&pTu,L_Ngay,"<="&pDen)) | Y21: =IF($A21="","",$P21+$Q21+$R21+$U21) | Z21: =IF($A21="","",IF($D21="Đang thực hiện",$V21+$Y21,CHOOSE(MATCH(pDoDang,LST_DoDang,0),$AE21,$AF21,$AG21))) | AA21: =IF($A21="","",$V21+$Y21-$Z21-$W21-$X21) | AB21: =IF($A21="","",INDEX(DM_SLHT,8)) | AC21: =IF($A21="","",IF($AB21<=0,"⚠ CHƯA CÓ SL",ROUND($AA21/$AB21,0))) | AE21: =IF($A21="","",IFERROR((INDEX(DM_DDK621,8)+$P21)/($AB21+INDEX(DM_SLDD,8))*INDEX(DM_SLDD,8),0)) | AF21: =IF($A21="","",IFERROR((INDEX(DM_DDK621,8)+$P21)/($AB21+INDEX(DM_SLDD,8))*INDEX(DM_SLDD,8),0)+IFERROR((INDEX(DM_DDK622,8)+$Q21)/($AB21+INDEX(DM_SLDD,8)*INDEX(DM_Pct,8))*(INDEX(DM_SLDD,8)*INDEX(DM_Pct,8)),0)+IFERROR((INDEX(DM_DDK623,8)+$R21)/($AB21+INDEX(DM_SLDD,8)*INDEX(DM_Pct,8))*(INDEX(DM_SLDD,8)*INDEX(DM_Pct,8)),0)+IFERROR((INDEX(DM_DDK627,8)+$U21)/($AB21+INDEX(DM_SLDD,8)*INDEX(DM_Pct,8))*(INDEX(DM_SLDD,8)*INDEX(DM_Pct,8)),0)) | AG21: =IF($A21="","",INDEX(DM_SLDD,8)*INDEX(DM_DGDinhMuc,8)) | AH21: =IF($A21="",0,IF(AND(ISNUMBER($AA21),$AA21>0,$AB21<=0),1,0)) | AI21: =IF($A21="",0,IF(AND(ISNUMBER($Z21),$Z21<0),1,0)) | AJ21: =IF($A21="",0,IF(AND(ISNUMBER($AA21),$AA21<0),1,0))
A22: =IF(INDEX(DM_Ma,9)="","",INDEX(DM_Ma,9)) | B22: =IF($A22="","",INDEX(DM_Ten,9)) | C22: =IF($A22="","",INDEX(DM_Loai,9)) | D22: =IF($A22="","",INDEX(DM_TrangThai,9)) | E22: =IF($A22="","",SUMIFS(L_ST,L_Ma,$A22,L_KM,"NVL trực tiếp (621)",L_TT,"Trực tiếp",L_Ngay,">="&pTu,L_Ngay,"<="&pDen)) | F22: =IF($A22="","",SUMIFS(L_ST,L_Ma,$A22,L_KM,"Nhân công trực tiếp (622)",L_TT,"Trực tiếp",L_Ngay,">="&pTu,L_Ngay,"<="&pDen)) | G22: =IF($A22="","",SUMIFS(L_ST,L_Ma,$A22,L_KM,"Máy thi công (623)",L_TT,"Trực tiếp",L_Ngay,">="&pTu,L_Ngay,"<="&pDen)) | H22: =IF($A22="","",SUMIFS(L_ST,L_Ma,$A22,L_KM,"SXC (627)",L_TT,"Trực tiếp",L_Tinh,"Biến đổi",L_Ngay,">="&pTu,L_Ngay,"<="&pDen)) | I22: =IF($A22="","",SUMIFS(L_ST,L_Ma,$A22,L_KM,"SXC (627)",L_TT,"Trực tiếp",L_Tinh,"Cố định",L_Ngay,">="&pTu,L_Ngay,"<="&pDen)) | J22: =IF($A22="","",CHOOSE(MATCH(pTieuThuc,LST_TieuThuc,0),$E22,$F22,INDEX(DM_GioMay,9),INDEX(DM_GioCong,9),INDEX(DM_SLHT,9),INDEX(DM_DThu,9),INDEX(DM_TieuKhac,9))) | K22: =IF($A22="","",IF(tBase=0,0,$J22/tBase*pool621)) | L22: =IF($A22="","",IF(tBase=0,0,$J22/tBase*pool622)) | M22: =IF($A22="","",IF(tBase=0,0,$J22/tBase*pool623)) | N22: =IF($A22="","",IF(tBase=0,0,$J22/tBase*pool627BD)) | O22: =IF($A22="","",IF(tBase=0,0,$J22/tBase*t627CDabs)) | P22: =IF($A22="","",$E22+$K22) | Q22: =IF($A22="","",$F22+$L22) | R22: =IF($A22="","",$G22+$M22) | S22: =IF($A22="","",$H22+$N22) | T22: =IF($A22="","",$I22+$O22) | U22: =IF($A22="","",$S22+$T22) | V22: =IF($A22="","",INDEX(DM_DDK621,9)+INDEX(DM_DDK622,9)+INDEX(DM_DDK623,9)+INDEX(DM_DDK627,9)) | W22: =IF($A22="","",SUMIFS(L_ST,L_Ma,$A22,L_KM,"Phế liệu thu hồi",L_Ngay,">="&pTu,L_Ngay,"<="&pDen)) | X22: =IF($A22="","",SUMIFS(L_ST,L_Ma,$A22,L_KM,"SP hỏng ngoài định mức",L_Ngay,">="&pTu,L_Ngay,"<="&pDen)) | Y22: =IF($A22="","",$P22+$Q22+$R22+$U22) | Z22: =IF($A22="","",IF($D22="Đang thực hiện",$V22+$Y22,CHOOSE(MATCH(pDoDang,LST_DoDang,0),$AE22,$AF22,$AG22))) | AA22: =IF($A22="","",$V22+$Y22-$Z22-$W22-$X22) | AB22: =IF($A22="","",INDEX(DM_SLHT,9)) | AC22: =IF($A22="","",IF($AB22<=0,"⚠ CHƯA CÓ SL",ROUND($AA22/$AB22,0))) | AE22: =IF($A22="","",IFERROR((INDEX(DM_DDK621,9)+$P22)/($AB22+INDEX(DM_SLDD,9))*INDEX(DM_SLDD,9),0)) | AF22: =IF($A22="","",IFERROR((INDEX(DM_DDK621,9)+$P22)/($AB22+INDEX(DM_SLDD,9))*INDEX(DM_SLDD,9),0)+IFERROR((INDEX(DM_DDK622,9)+$Q22)/($AB22+INDEX(DM_SLDD,9)*INDEX(DM_Pct,9))*(INDEX(DM_SLDD,9)*INDEX(DM_Pct,9)),0)+IFERROR((INDEX(DM_DDK623,9)+$R22)/($AB22+INDEX(DM_SLDD,9)*INDEX(DM_Pct,9))*(INDEX(DM_SLDD,9)*INDEX(DM_Pct,9)),0)+IFERROR((INDEX(DM_DDK627,9)+$U22)/($AB22+INDEX(DM_SLDD,9)*INDEX(DM_Pct,9))*(INDEX(DM_SLDD,9)*INDEX(DM_Pct,9)),0)) | AG22: =IF($A22="","",INDEX(DM_SLDD,9)*INDEX(DM_DGDinhMuc,9)) | AH22: =IF($A22="",0,IF(AND(ISNUMBER($AA22),$AA22>0,$AB22<=0),1,0)) | AI22: =IF($A22="",0,IF(AND(ISNUMBER($Z22),$Z22<0),1,0)) | AJ22: =IF($A22="",0,IF(AND(ISNUMBER($AA22),$AA22<0),1,0))
A23: =IF(INDEX(DM_Ma,10)="","",INDEX(DM_Ma,10)) | B23: =IF($A23="","",INDEX(DM_Ten,10)) | C23: =IF($A23="","",INDEX(DM_Loai,10)) | D23: =IF($A23="","",INDEX(DM_TrangThai,10)) | E23: =IF($A23="","",SUMIFS(L_ST,L_Ma,$A23,L_KM,"NVL trực tiếp (621)",L_TT,"Trực tiếp",L_Ngay,">="&pTu,L_Ngay,"<="&pDen)) | F23: =IF($A23="","",SUMIFS(L_ST,L_Ma,$A23,L_KM,"Nhân công trực tiếp (622)",L_TT,"Trực tiếp",L_Ngay,">="&pTu,L_Ngay,"<="&pDen)) | G23: =IF($A23="","",SUMIFS(L_ST,L_Ma,$A23,L_KM,"Máy thi công (623)",L_TT,"Trực tiếp",L_Ngay,">="&pTu,L_Ngay,"<="&pDen)) | H23: =IF($A23="","",SUMIFS(L_ST,L_Ma,$A23,L_KM,"SXC (627)",L_TT,"Trực tiếp",L_Tinh,"Biến đổi",L_Ngay,">="&pTu,L_Ngay,"<="&pDen)) | I23: =IF($A23="","",SUMIFS(L_ST,L_Ma,$A23,L_KM,"SXC (627)",L_TT,"Trực tiếp",L_Tinh,"Cố định",L_Ngay,">="&pTu,L_Ngay,"<="&pDen)) | J23: =IF($A23="","",CHOOSE(MATCH(pTieuThuc,LST_TieuThuc,0),$E23,$F23,INDEX(DM_GioMay,10),INDEX(DM_GioCong,10),INDEX(DM_SLHT,10),INDEX(DM_DThu,10),INDEX(DM_TieuKhac,10))) | K23: =IF($A23="","",IF(tBase=0,0,$J23/tBase*pool621)) | L23: =IF($A23="","",IF(tBase=0,0,$J23/tBase*pool622)) | M23: =IF($A23="","",IF(tBase=0,0,$J23/tBase*pool623)) | N23: =IF($A23="","",IF(tBase=0,0,$J23/tBase*pool627BD)) | O23: =IF($A23="","",IF(tBase=0,0,$J23/tBase*t627CDabs)) | P23: =IF($A23="","",$E23+$K23) | Q23: =IF($A23="","",$F23+$L23) | R23: =IF($A23="","",$G23+$M23) | S23: =IF($A23="","",$H23+$N23) | T23: =IF($A23="","",$I23+$O23) | U23: =IF($A23="","",$S23+$T23) | V23: =IF($A23="","",INDEX(DM_DDK621,10)+INDEX(DM_DDK622,10)+INDEX(DM_DDK623,10)+INDEX(DM_DDK627,10)) | W23: =IF($A23="","",SUMIFS(L_ST,L_Ma,$A23,L_KM,"Phế liệu thu hồi",L_Ngay,">="&pTu,L_Ngay,"<="&pDen)) | X23: =IF($A23="","",SUMIFS(L_ST,L_Ma,$A23,L_KM,"SP hỏng ngoài định mức",L_Ngay,">="&pTu,L_Ngay,"<="&pDen)) | Y23: =IF($A23="","",$P23+$Q23+$R23+$U23) | Z23: =IF($A23="","",IF($D23="Đang thực hiện",$V23+$Y23,CHOOSE(MATCH(pDoDang,LST_DoDang,0),$AE23,$AF23,$AG23))) | AA23: =IF($A23="","",$V23+$Y23-$Z23-$W23-$X23) | AB23: =IF($A23="","",INDEX(DM_SLHT,10)) | AC23: =IF($A23="","",IF($AB23<=0,"⚠ CHƯA CÓ SL",ROUND($AA23/$AB23,0))) | AE23: =IF($A23="","",IFERROR((INDEX(DM_DDK621,10)+$P23)/($AB23+INDEX(DM_SLDD,10))*INDEX(DM_SLDD,10),0)) | AF23: =IF($A23="","",IFERROR((INDEX(DM_DDK621,10)+$P23)/($AB23+INDEX(DM_SLDD,10))*INDEX(DM_SLDD,10),0)+IFERROR((INDEX(DM_DDK622,10)+$Q23)/($AB23+INDEX(DM_SLDD,10)*INDEX(DM_Pct,10))*(INDEX(DM_SLDD,10)*INDEX(DM_Pct,10)),0)+IFERROR((INDEX(DM_DDK623,10)+$R23)/($AB23+INDEX(DM_SLDD,10)*INDEX(DM_Pct,10))*(INDEX(DM_SLDD,10)*INDEX(DM_Pct,10)),0)+IFERROR((INDEX(DM_DDK627,10)+$U23)/($AB23+INDEX(DM_SLDD,10)*INDEX(DM_Pct,10))*(INDEX(DM_SLDD,10)*INDEX(DM_Pct,10)),0)) | AG23: =IF($A23="","",INDEX(DM_SLDD,10)*INDEX(DM_DGDinhMuc,10)) | AH23: =IF($A23="",0,IF(AND(ISNUMBER($AA23),$AA23>0,$AB23<=0),1,0)) | AI23: =IF($A23="",0,IF(AND(ISNUMBER($Z23),$Z23<0),1,0)) | AJ23: =IF($A23="",0,IF(AND(ISNUMBER($AA23),$AA23<0),1,0))
A24: =IF(INDEX(DM_Ma,11)="","",INDEX(DM_Ma,11)) | B24: =IF($A24="","",INDEX(DM_Ten,11)) | C24: =IF($A24="","",INDEX(DM_Loai,11)) | D24: =IF($A24="","",INDEX(DM_TrangThai,11)) | E24: =IF($A24="","",SUMIFS(L_ST,L_Ma,$A24,L_KM,"NVL trực tiếp (621)",L_TT,"Trực tiếp",L_Ngay,">="&pTu,L_Ngay,"<="&pDen)) | F24: =IF($A24="","",SUMIFS(L_ST,L_Ma,$A24,L_KM,"Nhân công trực tiếp (622)",L_TT,"Trực tiếp",L_Ngay,">="&pTu,L_Ngay,"<="&pDen)) | G24: =IF($A24="","",SUMIFS(L_ST,L_Ma,$A24,L_KM,"Máy thi công (623)",L_TT,"Trực tiếp",L_Ngay,">="&pTu,L_Ngay,"<="&pDen)) | H24: =IF($A24="","",SUMIFS(L_ST,L_Ma,$A24,L_KM,"SXC (627)",L_TT,"Trực tiếp",L_Tinh,"Biến đổi",L_Ngay,">="&pTu,L_Ngay,"<="&pDen)) | I24: =IF($A24="","",SUMIFS(L_ST,L_Ma,$A24,L_KM,"SXC (627)",L_TT,"Trực tiếp",L_Tinh,"Cố định",L_Ngay,">="&pTu,L_Ngay,"<="&pDen)) | J24: =IF($A24="","",CHOOSE(MATCH(pTieuThuc,LST_TieuThuc,0),$E24,$F24,INDEX(DM_GioMay,11),INDEX(DM_GioCong,11),INDEX(DM_SLHT,11),INDEX(DM_DThu,11),INDEX(DM_TieuKhac,11))) | K24: =IF($A24="","",IF(tBase=0,0,$J24/tBase*pool621)) | L24: =IF($A24="","",IF(tBase=0,0,$J24/tBase*pool622)) | M24: =IF($A24="","",IF(tBase=0,0,$J24/tBase*pool623)) | N24: =IF($A24="","",IF(tBase=0,0,$J24/tBase*pool627BD)) | O24: =IF($A24="","",IF(tBase=0,0,$J24/tBase*t627CDabs)) | P24: =IF($A24="","",$E24+$K24) | Q24: =IF($A24="","",$F24+$L24) | R24: =IF($A24="","",$G24+$M24) | S24: =IF($A24="","",$H24+$N24) | T24: =IF($A24="","",$I24+$O24) | U24: =IF($A24="","",$S24+$T24) | V24: =IF($A24="","",INDEX(DM_DDK621,11)+INDEX(DM_DDK622,11)+INDEX(DM_DDK623,11)+INDEX(DM_DDK627,11)) | W24: =IF($A24="","",SUMIFS(L_ST,L_Ma,$A24,L_KM,"Phế liệu thu hồi",L_Ngay,">="&pTu,L_Ngay,"<="&pDen)) | X24: =IF($A24="","",SUMIFS(L_ST,L_Ma,$A24,L_KM,"SP hỏng ngoài định mức",L_Ngay,">="&pTu,L_Ngay,"<="&pDen)) | Y24: =IF($A24="","",$P24+$Q24+$R24+$U24) | Z24: =IF($A24="","",IF($D24="Đang thực hiện",$V24+$Y24,CHOOSE(MATCH(pDoDang,LST_DoDang,0),$AE24,$AF24,$AG24))) | AA24: =IF($A24="","",$V24+$Y24-$Z24-$W24-$X24) | AB24: =IF($A24="","",INDEX(DM_SLHT,11)) | AC24: =IF($A24="","",IF($AB24<=0,"⚠ CHƯA CÓ SL",ROUND($AA24/$AB24,0))) | AE24: =IF($A24="","",IFERROR((INDEX(DM_DDK621,11)+$P24)/($AB24+INDEX(DM_SLDD,11))*INDEX(DM_SLDD,11),0)) | AF24: =IF($A24="","",IFERROR((INDEX(DM_DDK621,11)+$P24)/($AB24+INDEX(DM_SLDD,11))*INDEX(DM_SLDD,11),0)+IFERROR((INDEX(DM_DDK622,11)+$Q24)/($AB24+INDEX(DM_SLDD,11)*INDEX(DM_Pct,11))*(INDEX(DM_SLDD,11)*INDEX(DM_Pct,11)),0)+IFERROR((INDEX(DM_DDK623,11)+$R24)/($AB24+INDEX(DM_SLDD,11)*INDEX(DM_Pct,11))*(INDEX(DM_SLDD,11)*INDEX(DM_Pct,11)),0)+IFERROR((INDEX(DM_DDK627,11)+$U24)/($AB24+INDEX(DM_SLDD,11)*INDEX(DM_Pct,11))*(INDEX(DM_SLDD,11)*INDEX(DM_Pct,11)),0)) | AG24: =IF($A24="","",INDEX(DM_SLDD,11)*INDEX(DM_DGDinhMuc,11)) | AH24: =IF($A24="",0,IF(AND(ISNUMBER($AA24),$AA24>0,$AB24<=0),1,0)) | AI24: =IF($A24="",0,IF(AND(ISNUMBER($Z24),$Z24<0),1,0)) | AJ24: =IF($A24="",0,IF(AND(ISNUMBER($AA24),$AA24<0),1,0))
