Workbook

Sheet HDSD
B2: HƯỚNG DẪN SỬ DỤNG PHẦN MỀM KẾ TOÁN EXCEL — CHẾ ĐỘ KẾ TOÁN TT 99/2025/TT-BTC
B3: Xây dựng & phát hành bởi: KK HOME — Kế toán · Kiểm toán · Tư vấn Thuế
B4: Liên hệ hỗ trợ: [điền SĐT/Zalo · Email · Website/Fanpage của KK HOME tại đây]
B6: GIỚI THIỆU
B7: File này là sổ kế toán + báo cáo tài chính hoàn chỉnh cho doanh nghiệp quy mô vừa và nhỏ, áp dụng Chế độ kế toán doanh nghiệp theo Thông tư 99/2025/TT-BTC (hiệu lực 01/01/2026, thay thế TT 200/2014), hình thức Nhật ký chung, thuế GTGT khấu trừ. Một file = một năm tài chính.
B8: Nguyên tắc màu: Ô VÀNG = nhập liệu. Ô TRẮNG = công thức tự động, KHÔNG sửa. Các sheet đã được bảo vệ không mật khẩu — nếu thật sự cần sửa công thức: Review/Xem lại → Unprotect Sheet.
B9: QUY TRÌNH 6 BƯỚC
B10: Bước 1 — TT_DN: điền tên công ty, MST, địa chỉ, kỳ báo cáo (mặc định cả năm), người ký.
B11: Bước 2 — DM_DT: khai báo mã khách hàng (KH...), nhà cung cấp (NCC...) để theo dõi công nợ.
B12: Bước 3 — SDDK: nhập số dư đầu năm theo TK chi tiết; riêng 131/331 nhập theo TỪNG ĐỐI TƯỢNG ở bảng dưới cùng sheet (hệ thống tự cộng lên TK). Ô kiểm tra ở đầu sheet phải báo ✔ CÂN. Doanh nghiệp mới thành lập: bỏ qua, chỉ nhập vốn góp khi phát sinh.
B13: Bước 4 — NKC: nhập chứng từ hằng ngày, mỗi dòng một cặp Nợ/Có (định khoản nhiều TK thì tách nhiều dòng cùng Số chứng từ). Cột 'Kiểm tra dòng' tự cảnh báo lỗi ngay khi nhập.
B14: Bước 5 — Xem sổ & báo cáo: CDPS (cân đối phát sinh), SOCAI (chọn TK bất kỳ), CONGNO (chi tiết 131/331), B01, B02, B03_TT, B03_GT, TM. Tất cả tự động.
... B36: Thuế suất, mức giảm trừ, tỷ lệ BHXH... trong bộ số liệu ví dụ chỉ mang tính minh họa tại thời điểm lập (2026); luôn kiểm tra quy định hiện hành khi hạch toán thật.

Sheet TT_DN
B2: THÔNG TIN DOANH NGHIỆP & KỲ BÁO CÁO
B3: Áp dụng Chế độ kế toán doanh nghiệp theo Thông tư 99/2025/TT-BTC (hiệu lực từ 01/01/2026) — Hình thức Nhật ký chung
B5: Tên doanh nghiệp | C5: CÔNG TY TNHH THƯƠNG MẠI VÀ DỊCH VỤ AN PHÁT | E5: Hướng dẫn nhanh:
B6: Mã số thuế | C6: 0101234567 | E6: 1) Điền thông tin DN và kỳ báo cáo tại các ô vàng bên trái.
B7: Địa chỉ | C7: Số 25 phố Duy Tân, phường Cầu Giấy, TP. Hà Nội | E7: 2) Nhập số dư đầu năm tại sheet SDDK (chỉ nhập ở TK chi tiết).
B8: Kỳ báo cáo - Từ ngày | C8: 46023 | E8: 3) Nhập chứng từ hằng ngày vào sheet NKC (Nhật ký chung).
B9: Kỳ báo cáo - Đến ngày | C9: 46387 | E9: 4) CDPS, CONGNO, SOCAI, B01, B02, B03, TM tự động cập nhật.
B10: Người lập biểu | C10: Nguyễn Thị Kế | E10: 5) Trước khi in/nộp: mở sheet KIEMTRA — tất cả phải ✔ Khớp.
B11: Kế toán trưởng | C11: Trần Văn Toán | E11: Toàn bộ ô màu vàng = ô nhập liệu; ô trắng = công thức, không sửa.
B12: Người đại diện theo pháp luật | C12: Lê Quang Đốc | E12: Kỳ báo cáo mặc định là cả năm; có thể thu hẹp để xem báo cáo giữa niên độ.
B13: Đơn vị tiền tệ ghi sổ | C13: Đồng Việt Nam (VND)
B14: Phương pháp thuế GTGT | C14: Khấu trừ
B15: Phương pháp khấu hao TSCĐ | C15: Đường thẳng
B16: Phương pháp tính giá hàng tồn kho | C16: Bình quân gia quyền
B18: Phần mềm: Kế toán Excel TT 99/2025 — © KK HOME

Sheet DMTK
A2: DANH MỤC HỆ THỐNG TÀI KHOẢN KẾ TOÁN
A3: Theo Phụ lục II Thông tư 99/2025/TT-BTC — 71 TK cấp 1, 101 TK cấp 2, 10 TK cấp 3, 2 TK cấp 4. Doanh nghiệp được tự mở TK chi tiết (Điều 11).
A4: Thêm TK chi tiết của riêng bạn vào các dòng trống cuối bảng: mã TK con phải BẮT ĐẦU bằng mã TK chuẩn (ví dụ 1121 - TGNH Vietcombank thuộc TK 112).
A6: Mã TK | B6: Tên tài khoản | C6: Cấp | D6: TK cha | E6: Tính chất số dư | F6: Ghi chú
A7: 111 | B7: Tiền mặt | C7: 1 | E7: Dư Nợ
A8: 112 | B8: Tiền gửi không kỳ hạn | C8: 1 | E8: Dư Nợ | F8: TT99 đổi tên: Tiền gửi không kỳ hạn (TGNH có kỳ hạn theo dõi ở 1281)
A9: 113 | B9: Tiền đang chuyển | C9: 1 | E9: Dư Nợ
A10: 121 | B10: Chứng khoán kinh doanh | C10: 1 | E10: Dư Nợ
A11: 128 | B11: Đầu tư nắm giữ đến ngày đáo hạn | C11: 1 | E11: Dư Nợ
A12: 1281 | B12: Tiền gửi có kỳ hạn | C12: 2 | D12: 128 | E12: Dư Nợ
A13: 1282 | B13: Trái phiếu | C13: 2 | D13: 128 | E13: Dư Nợ
A14: 1283 | B14: Cho vay | C14: 2 | D14: 128 | E14: Dư Nợ
A15: 1288 | B15: Các khoản đầu tư khác nắm giữ đến ngày đáo hạn | C15: 2 | D15: 128 | E15: Dư Nợ
A16: 131 | B16: Phải thu của khách hàng | C16: 1 | E16: Lưỡng tính | F16: Bắt buộc ghi Mã đối tượng trong NKC
A17: 133 | B17: Thuế GTGT được khấu trừ | C17: 1 | E17: Dư Nợ
A18: 1331 | B18: Thuế GTGT được khấu trừ của hàng hóa, dịch vụ | C18: 2 | D18: 133 | E18: Dư Nợ
A19: 1332 | B19: Thuế GTGT được khấu trừ của TSCĐ | C19: 2 | D19: 133 | E19: Dư Nợ
A20: 136 | B20: Phải thu nội bộ | C20: 1 | E20: Dư Nợ
A21: 1361 | B21: Vốn kinh doanh ở đơn vị trực thuộc | C21: 2 | D21: 136 | E21: Dư Nợ
A22: 1362 | B22: Phải thu nội bộ về chênh lệch tỷ giá | C22: 2 | D22: 136 | E22: Dư Nợ
A23: 1363 | B23: Phải thu nội bộ về chi phí đi vay đủ điều kiện được vốn hoá | C23: 2 | D23: 136 | E23: Dư Nợ
A24: 1368 | B24: Phải thu nội bộ khác | C24: 2 | D24: 136 | E24: Dư Nợ
A25: 138 | B25: Phải thu khác | C25: 1 | E25: Lưỡng tính
A26: 1381 | B26: Tài sản thiếu chờ xử lý | C26: 2 | D26: 138 | E26: Dư Nợ
A27: 1383 | B27: Thuế TTĐB của hàng nhập khẩu | C27: 2 | D27: 138 | E27: Dư Nợ
A28: 1388 | B28: Phải thu khác | C28: 2 | D28: 138 | E28: Lưỡng tính
A29: 141 | B29: Tạm ứng | C29: 1 | E29: Dư Nợ
A30: 151 | B30: Hàng mua đang đi đường | C30: 1 | E30: Dư Nợ
A31: 152 | B31: Nguyên liệu, vật liệu | C31: 1 | E31: Dư Nợ
A32: 153 | B32: Công cụ, dụng cụ | C32: 1 | E32: Dư Nợ
A33: 154 | B33: Chi phí sản xuất, kinh doanh dở dang | C33: 1 | E33: Dư Nợ
A34: 155 | B34: Sản phẩm | C34: 1 | E34: Dư Nợ | F34: TT99 đổi tên từ 'Thành phẩm'
A35: 156 | B35: Hàng hóa | C35: 1 | E35: Dư Nợ
A36: 157 | B36: Hàng gửi đi bán | C36: 1 | E36: Dư Nợ
A37: 158 | B37: Nguyên liệu, vật tư tại kho bảo thuế | C37: 1 | E37: Dư Nợ
A38: 171 | B38: Giao dịch mua, bán lại trái phiếu chính phủ | C38: 1 | E38: Lưỡng tính
A39: 211 | B39: Tài sản cố định hữu hình | C39: 1 | E39: Dư Nợ
A40: 212 | B40: Tài sản cố định thuê tài chính | C40: 1 | E40: Dư Nợ
A41: 213 | B41: Tài sản cố định vô hình | C41: 1 | E41: Dư Nợ
A42: 214 | B42: Hao mòn tài sản cố định | C42: 1 | E42: Dư Có (điều chỉnh giảm tài sản)
...

Sheet DM_DT
A2: DANH MỤC ĐỐI TƯỢNG (KHÁCH HÀNG / NHÀ CUNG CẤP / NHÂN VIÊN...)
A3: Mỗi khách hàng, nhà cung cấp cần một mã riêng để theo dõi công nợ 131/331. Mã dùng trong cột 'Mã ĐT' của Nhật ký chung.
A6: Mã ĐT | B6: Tên đối tượng | C6: Loại | D6: Mã số thuế | E6: Địa chỉ | F6: Ghi chú
A7: KH001 | B7: Công ty CP Bình Minh | C7: KH
A8: KH002 | B8: Công ty TNHH Sao Mai | C8: KH
A9: KH003 | B9: Đại lý Hòa Bình | C9: KH
A10: NCC001 | B10: Công ty TNHH Phú Thành | C10: NCC
A11: NCC002 | B11: Công ty CP Thiết bị Đại Nam | C11: NCC

Sheet SDDK
A2: SỐ DƯ ĐẦU NĂM CÁC TÀI KHOẢN
A3: Chỉ nhập ở TK CHI TIẾT NHẤT mà bạn dùng để ghi sổ (nếu nhập ở TK cha thì đừng nhập lại ở TK con). Riêng TK 131, 331: nhập theo TỪNG ĐỐI TƯỢNG ở bảng dưới, hệ thống tự cộng lên.
B4: KIỂM TRA CÂN ĐỐI: Tổng dư Nợ = | C4: =SUM(C8:C251) | D4: =SUM(D8:D251) | E4: =IF(C4=D4,"✔ CÂN","✘ LỆCH: "&TEXT(C4-D4,"#,##0"))
A7: Mã TK | B7: Tên tài khoản | C7: Dư Nợ đầu năm | D7: Dư Có đầu năm | E7: Ghi chú
A8: 111 | B8: Tiền mặt | C8: 80000000
A9: 112 | B9: Tiền gửi không kỳ hạn | C9: 520000000
A10: 113 | B10: Tiền đang chuyển
A11: 121 | B11: Chứng khoán kinh doanh
A12: 128 | B12: Đầu tư nắm giữ đến ngày đáo hạn
A13: 1281 | B13: Tiền gửi có kỳ hạn
A14: 1282 | B14: Trái phiếu
A15: 1283 | B15: Cho vay
A16: 1288 | B16: Các khoản đầu tư khác nắm giữ đến ngày đáo hạn
A17: 131 | B17: Phải thu của khách hàng | C17: =SUMIFS($D$256:$D$375,$A$256:$A$375,$A17) | D17: =SUMIFS($E$256:$E$375,$A$256:$A$375,$A17) | E17: Tự cộng từ bảng công nợ bên dưới
A18: 133 | B18: Thuế GTGT được khấu trừ
A19: 1331 | B19: Thuế GTGT được khấu trừ của hàng hóa, dịch vụ
A20: 1332 | B20: Thuế GTGT được khấu trừ của TSCĐ
A21: 136 | B21: Phải thu nội bộ
A22: 1361 | B22: Vốn kinh doanh ở đơn vị trực thuộc
A23: 1362 | B23: Phải thu nội bộ về chênh lệch tỷ giá
A24: 1363 | B24: Phải thu nội bộ về chi phí đi vay đủ điều kiện được vốn hoá
A25: 1368 | B25: Phải thu nội bộ khác
A26: 138 | B26: Phải thu khác
A27: 1381 | B27: Tài sản thiếu chờ xử lý
A28: 1383 | B28: Thuế TTĐB của hàng nhập khẩu
A29: 1388 | B29: Phải thu khác
... A35: 155 | B35: Sản phẩm
A36: 156 | B36: Hàng hóa | C36: 350000000
A37: 157 | B37: Hàng gửi đi bán
A38: 158 | B38: Nguyên liệu, vật tư tại kho bảo thuế
A39: 171 | B39: Giao dịch mua, bán lại trái phiếu chính phủ
A40: 211 | B40: Tài sản cố định hữu hình | C40: 480000000
A41: 212 | B41: Tài sản cố định thuê tài chính
A42: 213 | B42: Tài sản cố định vô hình
A43: 214 | B43: Hao mòn tài sản cố định
A44: 2141 | B44: Hao mòn TSCĐ hữu hình | D44: 120000000
A45: 2142 | B45: Hao mòn TSCĐ thuê tài chính
A46: 2143 | B46: Hao mòn TSCĐ vô hình
A47: 2147 | B47: Hao mòn bất động sản đầu tư
A48: 215 | B48: Tài sản sinh học
...

Sheet NKC
A2: SỔ NHẬT KÝ CHUNG
A3: =CONCATENATE("Đơn vị: ",TT_DN!$C$5," — Năm: ",TEXT(TU_NGAY,"YYYY")," (Mẫu số S03a-DN vận dụng — sổ thiết kế lại theo Điều 12 TT 99/2025/TT-BTC)")
A4: Mỗi dòng một cặp Nợ/Có. Bút toán nhiều TK: tách thành nhiều dòng, cùng Số CT. Cột Mã LCTT chỉ ghi khi muốn ép mã lưu chuyển tiền tệ (VD: 21 khi trả tiền mua TSCĐ qua TK 331). KHÔNG cần bút toán kết chuyển cuối kỳ — báo cáo tự tính (có nhập kết chuyển qua 911 file vẫn đúng).
P5: 0
A6: STT | B6: Ngày ghi sổ | C6: Số chứng từ | D6: Ngày CT | E6: Diễn giải | F6: TK Nợ | G6: TK Có | H6: Số tiền | I6: Mã ĐT | J6: Mã LCTT | K6: Ghi chú | L6: Kiểm tra dòng | M6: Hướng | N6: Đ.ứng | O6: MãLC | P6: SC
A7: =IF($H7="","",ROW()-6) | B7: 46027 | C7: PN001 | D7: 46027 | E7: Mua hàng hóa nhập kho - Cty Phú Thành | F7: 156 | G7: 331 | H7: 200000000 | I7: NCC001 | L7: =IF($H7="","",TRIM(IF(COUNTIF(DMTK!$A$7:$A$250,$F7)=0,"TK Nợ sai! ","")&IF(COUNTIF(DMTK!$A$7:$A$250,$G7)=0,"TK Có sai! ","")&IF(N($H7)<=0,"Tiền phải > 0! ","")&IF($B7="","Thiếu ngày! ","")&IF(AND(OR(LEFT($F7,3)="131",LEFT($G7,3)="131",LEFT($F7,3)="331",LEFT($G7,3)="331"),$I7=""),"Thiếu Mã ĐT! ","")&IF(AND($I7<>"",COUNTIF(DM_DT!$A$7:$A$306,$I7)=0),"Mã ĐT chưa khai báo! ",""))) | M7: =IF($H7="","",IF(AND(OR(LEFT($F7,3)="111",LEFT($F7,3)="112",LEFT($F7,3)="113"),OR(LEFT($G7,3)="111",LEFT($G7,3)="112",LEFT($G7,3)="113")),"NB",IF(OR(LEFT($F7,3)="111",LEFT($F7,3)="112",LEFT($F7,3)="113"),"THU",IF(OR(LEFT($G7,3)="111",LEFT($G7,3)="112",LEFT($G7,3)="113"),"CHI","")))) | N7: =IF($M7="THU",$G7,IF($M7="CHI",$F7,"")) | O7: =IF(OR($M7="",$M7="NB"),"",IF($J7<>"",TEXT($J7,"00"),IFERROR(VLOOKUP(LEFT($N7,4),LCTT_MAP!$A$7:$C$66,IF($M7="THU",2,3),FALSE()),IFERROR(VLOOKUP(LEFT($N7,3),LCTT_MAP!$A$7:$C$66,IF($M7="THU",2,3),FALSE()),IFERROR(VLOOKUP(LEFT($N7,2),LCTT_MAP!$A$7:$C$66,IF($M7="THU",2,3),FALSE()),IFERROR(VLOOKUP(LEFT($N7,1),LCTT_MAP!$A$7:$C$66,IF($M7="THU",2,3),FALSE()),IF($M7="THU","06","07"))))))) | P7: =0+IF(AND($H7<>"",OR(LEFT($F7,LEN(SC_TK))=SC_TK,LEFT($G7,LEN(SC_TK))=SC_TK)),1,0)
A8: =IF($H8="","",ROW()-6) | B8: 46027 | C8: PN001 | D8: 46027 | E8: Thuế GTGT đầu vào mua hàng hóa | F8: 1331 | G8: 331 | H8: 16000000 | I8: NCC001 | L8: =IF($H8="","",TRIM(IF(COUNTIF(DMTK!$A$7:$A$250,$F8)=0,"TK Nợ sai! ","")&IF(COUNTIF(DMTK!$A$7:$A$250,$G8)=0,"TK Có sai! ","")&IF(N($H8)<=0,"Tiền phải > 0! ","")&IF($B8="","Thiếu ngày! ","")&IF(AND(OR(LEFT($F8,3)="131",LEFT($G8,3)="131",LEFT($F8,3)="331",LEFT($G8,3)="331"),$I8=""),"Thiếu Mã ĐT! ","")&IF(AND($I8<>"",COUNTIF(DM_DT!$A$7:$A$306,$I8)=0),"Mã ĐT chưa khai báo! ",""))) | M8: =IF($H8="","",IF(AND(OR(LEFT($F8,3)="111",LEFT($F8,3)="112",LEFT($F8,3)="113"),OR(LEFT($G8,3)="111",LEFT($G8,3)="112",LEFT($G8,3)="113")),"NB",IF(OR(LEFT($F8,3)="111",LEFT($F8,3)="112",LEFT($F8,3)="113"),"THU",IF(OR(LEFT($G8,3)="111",LEFT($G8,3)="112",LEFT($G8,3)="113"),"CHI","")))) | N8: =IF($M8="THU",$G8,IF($M8="CHI",$F8,"")) | O8: =IF(OR($M8="",$M8="NB"),"",IF($J8<>"",TEXT($J8,"00"),IFERROR(VLOOKUP(LEFT($N8,4),LCTT_MAP!$A$7:$C$66,IF($M8="THU",2,3),FALSE()),IFERROR(VLOOKUP(LEFT($N8,3),LCTT_MAP!$A$7:$C$66,IF($M8="THU",2,3),FALSE()),IFERROR(VLOOKUP(LEFT($N8,2),LCTT_MAP!$A$7:$C$66,IF($M8="THU",2,3),FALSE()),IFERROR(VLOOKUP(LEFT($N8,1),LCTT_MAP!$A$7:$C$66,IF($M8="THU",2,3),FALSE()),IF($M8="THU","06","07"))))))) | P8: =P7+IF(AND($H8<>"",OR(LEFT($F8,LEN(SC_TK))=SC_TK,LEFT($G8,LEN(SC_TK))=SC_TK)),1,0)
A9: =IF($H9="","",ROW()-6) | B9: 46032 | C9: HD0001 | D9: 46032 | E9: Bán hàng hóa - Cty Bình Minh | F9: 131 | G9: 511 | H9: 250000000 | I9: KH001 | L9: =IF($H9="","",TRIM(IF(COUNTIF(DMTK!$A$7:$A$250,$F9)=0,"TK Nợ sai! ","")&IF(COUNTIF(DMTK!$A$7:$A$250,$G9)=0,"TK Có sai! ","")&IF(N($H9)<=0,"Tiền phải > 0! ","")&IF($B9="","Thiếu ngày! ","")&IF(AND(OR(LEFT($F9,3)="131",LEFT($G9,3)="131",LEFT($F9,3)="331",LEFT($G9,3)="331"),$I9=""),"Thiếu Mã ĐT! ","")&IF(AND($I9<>"",COUNTIF(DM_DT!$A$7:$A$306,$I9)=0),"Mã ĐT chưa khai báo! ",""))) | M9: =IF($H9="","",IF(AND(OR(LEFT($F9,3)="111",LEFT($F9,3)="112",LEFT($F9,3)="113"),OR(LEFT($G9,3)="111",LEFT($G9,3)="112",LEFT($G9,3)="113")),"NB",IF(OR(LEFT($F9,3)="111",LEFT($F9,3)="112",LEFT($F9,3)="113"),"THU",IF(OR(LEFT($G9,3)="111",LEFT($G9,3)="112",LEFT($G9,3)="113"),"CHI","")))) | N9: =IF($M9="THU",$G9,IF($M9="CHI",$F9,"")) | O9: =IF(OR($M9="",$M9="NB"),"",IF($J9<>"",TEXT($J9,"00"),IFERROR(VLOOKUP(LEFT($N9,4),LCTT_MAP!$A$7:$C$66,IF($M9="THU",2,3),FALSE()),IFERROR(VLOOKUP(LEFT($N9,3),LCTT_MAP!$A$7:$C$66,IF($M9="THU",2,3),FALSE()),IFERROR(VLOOKUP(LEFT($N9,2),LCTT_MAP!$A$7:$C$66,IF($M9="THU",2,3),FALSE()),IFERROR(VLOOKUP(LEFT($N9,1),LCTT_MAP!$A$7:$C$66,IF($M9="THU",2,3),FALSE()),IF($M9="THU","06","07"))))))) | P9: =P8+IF(AND($H9<>"",OR(LEFT($F9,LEN(SC_TK))=SC_TK,LEFT($G9,LEN(SC_TK))=SC_TK)),1,0)
A10: =IF($H10="","",ROW()-6) | B10: 46032 | C10: HD0001 | D10: 46032 | E10: Thuế GTGT đầu ra bán hàng | F10: 131 | G10: 33311 | H10: 20000000 | I10: KH001 | L10: =IF($H10="","",TRIM(IF(COUNTIF(DMTK!$A$7:$A$250,$F10)=0,"TK Nợ sai! ","")&IF(COUNTIF(DMTK!$A$7:$A$250,$G10)=0,"TK Có sai! ","")&IF(N($H10)<=0,"Tiền phải > 0! ","")&IF($B10="","Thiếu ngày! ","")&IF(AND(OR(LEFT($F10,3)="131",LEFT($G10,3)="131",LEFT($F10,3)="331",LEFT($G10,3)="331"),$I10=""),"Thiếu Mã ĐT! ","")&IF(AND($I10<>"",COUNTIF(DM_DT!$A$7:$A$306,$I10)=0),"Mã ĐT chưa khai báo! ",""))) | M10: =IF($H10="","",IF(AND(OR(LEFT($F10,3)="111",LEFT($F10,3)="112",LEFT($F10,3)="113"),OR(LEFT($G10,3)="111",LEFT($G10,3)="112",LEFT($G10,3)="113")),"NB",IF(OR(LEFT($F10,3)="111",LEFT($F10,3)="112",LEFT($F10,3)="113"),"THU",IF(OR(LEFT($G10,3)="111",LEFT($G10,3)="112",LEFT($G10,3)="113"),"CHI","")))) | N10: =IF($M10="THU",$G10,IF($M10="CHI",$F10,"")) | O10: =IF(OR($M10="",$M10="NB"),"",IF($J10<>"",TEXT($J10,"00"),IFERROR(VLOOKUP(LEFT($N10,4),LCTT_MAP!$A$7:$C$66,IF($M10="THU",2,3),FALSE()),IFERROR(VLOOKUP(LEFT($N10,3),LCTT_MAP!$A$7:$C$66,IF($M10="THU",2,3),FALSE()),IFERROR(VLOOKUP(LEFT($N10,2),LCTT_MAP!$A$7:$C$66,IF($M10="THU",2,3),FALSE()),IFERROR(VLOOKUP(LEFT($N10,1),LCTT_MAP!$A$7:$C$66,IF($M10="THU",2,3),FALSE()),IF($M10="THU","06","07"))))))) | P10: =P9+IF(AND($H10<>"",OR(LEFT($F10,LEN(SC_TK))=SC_TK,LEFT($G10,LEN(SC_TK))=SC_TK)),1,0)
A11: =IF($H11="","",ROW()-6) | B11: 46032 | C11: PX001 | D11: 46032 | E11: Giá vốn hàng bán HĐ 0001 | F11: 632 | G11: 156 | H11: 180000000 | L11: =IF($H11="","",TRIM(IF(COUNTIF(DMTK!$A$7:$A$250,$F11)=0,"TK Nợ sai! ","")&IF(COUNTIF(DMTK!$A$7:$A$250,$G11)=0,"TK Có sai! ","")&IF(N($H11)<=0,"Tiền phải > 0! ","")&IF($B11="","Thiếu ngày! ","")&IF(AND(OR(LEFT($F11,3)="131",LEFT($G11,3)="131",LEFT($F11,3)="331",LEFT($G11,3)="331"),$I11=""),"Thiếu Mã ĐT! ","")&IF(AND($I11<>"",COUNTIF(DM_DT!$A$7:$A$306,$I11)=0),"Mã ĐT chưa khai báo! ",""))) | M11: =IF($H11="","",IF(AND(OR(LEFT($F11,3)="111",LEFT($F11,3)="112",LEFT($F11,3)="113"),OR(LEFT($G11,3)="111",LEFT($G11,3)="112",LEFT($G11,3)="113")),"NB",IF(OR(LEFT($F11,3)="111",LEFT($F11,3)="112",LEFT($F11,3)="113"),"THU",IF(OR(LEFT($G11,3)="111",LEFT($G11,3)="112",LEFT($G11,3)="113"),"CHI","")))) | N11: =IF($M11="THU",$G11,IF($M11="CHI",$F11,"")) | O11: =IF(OR($M11="",$M11="NB"),"",IF($J11<>"",TEXT($J11,"00"),IFERROR(VLOOKUP(LEFT($N11,4),LCTT_MAP!$A$7:$C$66,IF($M11="THU",2,3),FALSE()),IFERROR(VLOOKUP(LEFT($N11,3),LCTT_MAP!$A$7:$C$66,IF($M11="THU",2,3),FALSE()),IFERROR(VLOOKUP(LEFT($N11,2),LCTT_MAP!$A$7:$C$66,IF($M11="THU",2,3),FALSE()),IFERROR(VLOOKUP(LEFT($N11,1),LCTT_MAP!$A$7:$C$66,IF($M11="THU",2,3),FALSE()),IF($M11="THU","06","07"))))))) | P11: =P10+IF(AND($H11<>"",OR(LEFT($F11,LEN(SC_TK))=SC_TK,LEFT($G11,LEN(SC_TK))=SC_TK)),1,0)
A12: =IF($H12="","",ROW()-6) | B12: 46042 | C12: BC001 | D12: 46042 | E12: Thu tiền bán hàng - Cty Bình Minh (CK) | F12: 112 | G12: 131 | H12: 250000000 | I12: KH001 | L12: =IF($H12="","",TRIM(IF(COUNTIF(DMTK!$A$7:$A$250,$F12)=0,"TK Nợ sai! ","")&IF(COUNTIF(DMTK!$A$7:$A$250,$G12)=0,"TK Có sai! ","")&IF(N($H12)<=0,"Tiền phải > 0! ","")&IF($B12="","Thiếu ngày! ","")&IF(AND(OR(LEFT($F12,3)="131",LEFT($G12,3)="131",LEFT($F12,3)="331",LEFT($G12,3)="331"),$I12=""),"Thiếu Mã ĐT! ","")&IF(AND($I12<>"",COUNTIF(DM_DT!$A$7:$A$306,$I12)=0),"Mã ĐT chưa khai báo! ",""))) | M12: =IF($H12="","",IF(AND(OR(LEFT($F12,3)="111",LEFT($F12,3)="112",LEFT($F12,3)="113"),OR(LEFT($G12,3)="111",LEFT($G12,3)="112",LEFT($G12,3)="113")),"NB",IF(OR(LEFT($F12,3)="111",LEFT($F12,3)="112",LEFT($F12,3)="113"),"THU",IF(OR(LEFT($G12,3)="111",LEFT($G12,3)="112",LEFT($G12,3)="113"),"CHI","")))) | N12: =IF($M12="THU",$G12,IF($M12="CHI",$F12,"")) | O12: =IF(OR($M12="",$M12="NB"),"",IF($J12<>"",TEXT($J12,"00"),IFERROR(VLOOKUP(LEFT($N12,4),LCTT_MAP!$A$7:$C$66,IF($M12="THU",2,3),FALSE()),IFERROR(VLOOKUP(LEFT($N12,3),LCTT_MAP!$A$7:$C$66,IF($M12="THU",2,3),FALSE()),IFERROR(VLOOKUP(LEFT($N12,2),LCTT_MAP!$A$7:$C$66,IF($M12="THU",2,3),FALSE()),IFERROR(VLOOKUP(LEFT($N12,1),LCTT_MAP!$A$7:$C$66,IF($M12="THU",2,3),FALSE()),IF($M12="THU","06","07"))))))) | P12: =P11+IF(AND($H12<>"",OR(LEFT($F12,LEN(SC_TK))=SC_TK,LEFT($G12,LEN(SC_TK))=SC_TK)),1,0)
A13: =IF($H13="","",ROW()-6) | B13: 46047 | C13: UNC001 | D13: 46047 | E13: Trả tiền mua hàng - Cty Phú Thành | F13: 331 | G13: 112 | H13: 216000000 | I13: NCC001 | L13: =IF($H13="","",TRIM(IF(COUNTIF(DMTK!$A$7:$A$250,$F13)=0,"TK Nợ sai! ","")&IF(COUNTIF(DMTK!$A$7:$A$250,$G13)=0,"TK Có sai! ","")&IF(N($H13)<=0,"Tiền phải > 0! ","")&IF($B13="","Thiếu ngày! ","")&IF(AND(OR(LEFT($F13,3)="131",LEFT($G13,3)="131",LEFT($F13,3)="331",LEFT($G13,3)="331"),$I13=""),"Thiếu Mã ĐT! ","")&IF(AND($I13<>"",COUNTIF(DM_DT!$A$7:$A$306,$I13)=0),"Mã ĐT chưa khai báo! ",""))) | M13: =IF($H13="","",IF(AND(OR(LEFT($F13,3)="111",LEFT($F13,3)="112",LEFT($F13,3)="113"),OR(LEFT($G13,3)="111",LEFT($G13,3)="112",LEFT($G13,3)="113")),"NB",IF(OR(LEFT($F13,3)="111",LEFT($F13,3)="112",LEFT($F13,3)="113"),"THU",IF(OR(LEFT($G13,3)="111",LEFT($G13,3)="112",LEFT($G13,3)="113"),"CHI","")))) | N13: =IF($M13="THU",$G13,IF($M13="CHI",$F13,"")) | O13: =IF(OR($M13="",$M13="NB"),"",IF($J13<>"",TEXT($J13,"00"),IFERROR(VLOOKUP(LEFT($N13,4),LCTT_MAP!$A$7:$C$66,IF($M13="THU",2,3),FALSE()),IFERROR(VLOOKUP(LEFT($N13,3),LCTT_MAP!$A$7:$C$66,IF($M13="THU",2,3),FALSE()),IFERROR(VLOOKUP(LEFT($N13,2),LCTT_MAP!$A$7:$C$66,IF($M13="THU",2,3),FALSE()),IFERROR(VLOOKUP(LEFT($N13,1),LCTT_MAP!$A$7:$C$66,IF($M13="THU",2,3),FALSE()),IF($M13="THU","06","07"))))))) | P13: =P12+IF(AND($H13<>"",OR(LEFT($F13,LEN(SC_TK))=SC_TK,LEFT($G13,LEN(SC_TK))=SC_TK)),1,0)
A14: =IF($H14="","",ROW()-6) | B14: 46053 | C14: BL001 | D14: 46053 | E14: Lương tháng 01 - bộ phận QLDN | F14: 6421 | G14: 334 | H14: 40000000 | L14: =IF($H14="","",TRIM(IF(COUNTIF(DMTK!$A$7:$A$250,$F14)=0,"TK Nợ sai! ","")&IF(COUNTIF(DMTK!$A$7:$A$250,$G14)=0,"TK Có sai! ","")&IF(N($H14)<=0,"Tiền phải > 0! ","")&IF($B14="","Thiếu ngày! ","")&IF(AND(OR(LEFT($F14,3)="131",LEFT($G14,3)="131",LEFT($F14,3)="331",LEFT($G14,3)="331"),$I14=""),"Thiếu Mã ĐT! ","")&IF(AND($I14<>"",COUNTIF(DM_DT!$A$7:$A$306,$I14)=0),"Mã ĐT chưa khai báo! ",""))) | M14: =IF($H14="","",IF(AND(OR(LEFT($F14,3)="111",LEFT($F14,3)="112",LEFT($F14,3)="113"),OR(LEFT($G14,3)="111",LEFT($G14,3)="112",LEFT($G14,3)="113")),"NB",IF(OR(LEFT($F14,3)="111",LEFT($F14,3)="112",LEFT($F14,3)="113"),"THU",IF(OR(LEFT($G14,3)="111",LEFT($G14,3)="112",LEFT($G14,3)="113"),"CHI","")))) | N14: =IF($M14="THU",$G14,IF($M14="CHI",$F14,"")) | O14: =IF(OR($M14="",$M14="NB"),"",IF($J14<>"",TEXT($J14,"00"),IFERROR(VLOOKUP(LEFT($N14,4),LCTT_MAP!$A$7:$C$66,IF($M14="THU",2,3),FALSE()),IFERROR(VLOOKUP(LEFT($N14,3),LCTT_MAP!$A$7:$C$66,IF($M14="THU",2,3),FALSE()),IFERROR(VLOOKUP(LEFT($N14,2),LCTT_MAP!$A$7:$C$66,IF($M14="THU",2,3),FALSE()),IFERROR(VLOOKUP(LEFT($N14,1),LCTT_MAP!$A$7:$C$66,IF($M14="THU",2,3),FALSE()),IF($M14="THU","06","07"))))))) | P14: =P13+IF(AND($H14<>"",OR(LEFT($F14,LEN(SC_TK))=SC_TK,LEFT($G14,LEN(SC_TK))=SC_TK)),1,0)
A15: =IF($H15="","",ROW()-6) | B15: 46053 | C15: BL001 | D15: 46053 | E15: Lương tháng 01 - bộ phận bán hàng | F15: 6411 | G15: 334 | H15: 25000000 | L15: =IF($H15="","",TRIM(IF(COUNTIF(DMTK!$A$7:$A$250,$F15)=0,"TK Nợ sai! ","")&IF(COUNTIF(DMTK!$A$7:$A$250,$G15)=0,"TK Có sai! ","")&IF(N($H15)<=0,"Tiền phải > 0! ","")&IF($B15="","Thiếu ngày! ","")&IF(AND(OR(LEFT($F15,3)="131",LEFT($G15,3)="131",LEFT($F15,3)="331",LEFT($G15,3)="331"),$I15=""),"Thiếu Mã ĐT! ","")&IF(AND($I15<>"",COUNTIF(DM_DT!$A$7:$A$306,$I15)=0),"Mã ĐT chưa khai báo! ",""))) | M15: =IF($H15="","",IF(AND(OR(LEFT($F15,3)="111",LEFT($F15,3)="112",LEFT($F15,3)="113"),OR(LEFT($G15,3)="111",LEFT($G15,3)="112",LEFT($G15,3)="113")),"NB",IF(OR(LEFT($F15,3)="111",LEFT($F15,3)="112",LEFT($F15,3)="113"),"THU",IF(OR(LEFT($G15,3)="111",LEFT($G15,3)="112",LEFT($G15,3)="113"),"CHI","")))) | N15: =IF($M15="THU",$G15,IF($M15="CHI",$F15,"")) | O15: =IF(OR($M15="",$M15="NB"),"",IF($J15<>"",TEXT($J15,"00"),IFERROR(VLOOKUP(LEFT($N15,4),LCTT_MAP!$A$7:$C$66,IF($M15="THU",2,3),FALSE()),IFERROR(VLOOKUP(LEFT($N15,3),LCTT_MAP!$A$7:$C$66,IF($M15="THU",2,3),FALSE()),IFERROR(VLOOKUP(LEFT($N15,2),LCTT_MAP!$A$7:$C$66,IF($M15="THU",2,3),FALSE()),IFERROR(VLOOKUP(LEFT($N15,1),LCTT_MAP!$A$7:$C$66,IF($M15="THU",2,3),FALSE()),IF($M15="THU","06","07"))))))) | P15: =P14+IF(AND($H15<>"",OR(LEFT($F15,LEN(SC_TK))=SC_TK,LEFT($G15,LEN(SC_TK))=SC_TK)),1,0)
A16: =IF($H16="","",ROW()-6) | B16: 46053 | C16: BL001 | D16: 46053 | E16: BHXH, BHYT, BHTN, KPCĐ doanh nghiệp đóng - QLDN | F16: 6421 | G16: 3383 | H16: 9400000 | L16: =IF($H16="","",TRIM(IF(COUNTIF(DMTK!$A$7:$A$250,$F16)=0,"TK Nợ sai! ","")&IF(COUNTIF(DMTK!$A$7:$A$250,$G16)=0,"TK Có sai! ","")&IF(N($H16)<=0,"Tiền phải > 0! ","")&IF($B16="","Thiếu ngày! ","")&IF(AND(OR(LEFT($F16,3)="131",LEFT($G16,3)="131",LEFT($F16,3)="331",LEFT($G16,3)="331"),$I16=""),"Thiếu Mã ĐT! ","")&IF(AND($I16<>"",COUNTIF(DM_DT!$A$7:$A$306,$I16)=0),"Mã ĐT chưa khai báo! ",""))) | M16: =IF($H16="","",IF(AND(OR(LEFT($F16,3)="111",LEFT($F16,3)="112",LEFT($F16,3)="113"),OR(LEFT($G16,3)="111",LEFT($G16,3)="112",LEFT($G16,3)="113")),"NB",IF(OR(LEFT($F16,3)="111",LEFT($F16,3)="112",LEFT($F16,3)="113"),"THU",IF(OR(LEFT($G16,3)="111",LEFT($G16,3)="112",LEFT($G16,3)="113"),"CHI","")))) | N16: =IF($M16="THU",$G16,IF($M16="CHI",$F16,"")) | O16: =IF(OR($M16="",$M16="NB"),"",IF($J16<>"",TEXT($J16,"00"),IFERROR(VLOOKUP(LEFT($N16,4),LCTT_MAP!$A$7:$C$66,IF($M16="THU",2,3),FALSE()),IFERROR(VLOOKUP(LEFT($N16,3),LCTT_MAP!$A$7:$C$66,IF($M16="THU",2,3),FALSE()),IFERROR(VLOOKUP(LEFT($N16,2),LCTT_MAP!$A$7:$C$66,IF($M16="THU",2,3),FALSE()),IFERROR(VLOOKUP(LEFT($N16,1),LCTT_MAP!$A$7:$C$66,IF($M16="THU",2,3),FALSE()),IF($M16="THU","06","07"))))))) | P16: =P15+IF(AND($H16<>"",OR(LEFT($F16,LEN(SC_TK))=SC_TK,LEFT($G16,LEN(SC_TK))=SC_TK)),1,0)
A17: =IF($H17="","",ROW()-6) | B17: 46053 | C17: BL001 | D17: 46053 | E17: BHXH, BHYT, BHTN, KPCĐ doanh nghiệp đóng - bán hàng | F17: 6411 | G17: 3383 | H17: 5875000 | L17: =IF($H17="","",TRIM(IF(COUNTIF(DMTK!$A$7:$A$250,$F17)=0,"TK Nợ sai! ","")&IF(COUNTIF(DMTK!$A$7:$A$250,$G17)=0,"TK Có sai! ","")&IF(N($H17)<=0,"Tiền phải > 0! ","")&IF($B17="","Thiếu ngày! ","")&IF(AND(OR(LEFT($F17,3)="131",LEFT($G17,3)="131",LEFT($F17,3)="331",LEFT($G17,3)="331"),$I17=""),"Thiếu Mã ĐT! ","")&IF(AND($I17<>"",COUNTIF(DM_DT!$A$7:$A$306,$I17)=0),"Mã ĐT chưa khai báo! ",""))) | M17: =IF($H17="","",IF(AND(OR(LEFT($F17,3)="111",LEFT($F17,3)="112",LEFT($F17,3)="113"),OR(LEFT($G17,3)="111",LEFT($G17,3)="112",LEFT($G17,3)="113")),"NB",IF(OR(LEFT($F17,3)="111",LEFT($F17,3)="112",LEFT($F17,3)="113"),"THU",IF(OR(LEFT($G17,3)="111",LEFT($G17,3)="112",LEFT($G17,3)="113"),"CHI","")))) | N17: =IF($M17="THU",$G17,IF($M17="CHI",$F17,"")) | O17: =IF(OR($M17="",$M17="NB"),"",IF($J17<>"",TEXT($J17,"00"),IFERROR(VLOOKUP(LEFT($N17,4),LCTT_MAP!$A$7:$C$66,IF($M17="THU",2,3),FALSE()),IFERROR(VLOOKUP(LEFT($N17,3),LCTT_MAP!$A$7:$C$66,IF($M17="THU",2,3),FALSE()),IFERROR(VLOOKUP(LEFT($N17,2),LCTT_MAP!$A$7:$C$66,IF($M17="THU",2,3),FALSE()),IFERROR(VLOOKUP(LEFT($N17,1),LCTT_MAP!$A$7:$C$66,IF($M17="THU",2,3),FALSE()),IF($M17="THU","06","07"))))))) | P17: =P16+IF(AND($H17<>"",OR(LEFT($F17,LEN(SC_TK))=SC_TK,LEFT($G17,LEN(SC_TK))=SC_TK)),1,0)
A18: =IF($H18="","",ROW()-6) | B18: 46053 | C18: BL001 | D18: 46053 | E18: Bảo hiểm trừ vào lương người lao động (10,5%) | F18: 334 | G18: 3383 | H18: 6825000 | L18: =IF($H18="","",TRIM(IF(COUNTIF(DMTK!$A$7:$A$250,$F18)=0,"TK Nợ sai! ","")&IF(COUNTIF(DMTK!$A$7:$A$250,$G18)=0,"TK Có sai! ","")&IF(N($H18)<=0,"Tiền phải > 0! ","")&IF($B18="","Thiếu ngày! ","")&IF(AND(OR(LEFT($F18,3)="131",LEFT($G18,3)="131",LEFT($F18,3)="331",LEFT($G18,3)="331"),$I18=""),"Thiếu Mã ĐT! ","")&IF(AND($I18<>"",COUNTIF(DM_DT!$A$7:$A$306,$I18)=0),"Mã ĐT chưa khai báo! ",""))) | M18: =IF($H18="","",IF(AND(OR(LEFT($F18,3)="111",LEFT($F18,3)="112",LEFT($F18,3)="113"),OR(LEFT($G18,3)="111",LEFT($G18,3)="112",LEFT($G18,3)="113")),"NB",IF(OR(LEFT($F18,3)="111",LEFT($F18,3)="112",LEFT($F18,3)="113"),"THU",IF(OR(LEFT($G18,3)="111",LEFT($G18,3)="112",LEFT($G18,3)="113"),"CHI","")))) | N18: =IF($M18="THU",$G18,IF($M18="CHI",$F18,"")) | O18: =IF(OR($M18="",$M18="NB"),"",IF($J18<>"",TEXT($J18,"00"),IFERROR(VLOOKUP(LEFT($N18,4),LCTT_MAP!$A$7:$C$66,IF($M18="THU",2,3),FALSE()),IFERROR(VLOOKUP(LEFT($N18,3),LCTT_MAP!$A$7:$C$66,IF($M18="THU",2,3),FALSE()),IFERROR(VLOOKUP(LEFT($N18,2),LCTT_MAP!$A$7:$C$66,IF($M18="THU",2,3),FALSE()),IFERROR(VLOOKUP(LEFT($N18,1),LCTT_MAP!$A$7:$C$66,IF($M18="THU",2,3),FALSE()),IF($M18="THU","06","07"))))))) | P18: =P17+IF(AND($H18<>"",OR(LEFT($F18,LEN(SC_TK))=SC_TK,LEFT($G18,LEN(SC_TK))=SC_TK)),1,0)
A19: =IF($H19="","",ROW()-6) | B19: 46058 | C19: UNC002 | D19: 46058 | E19: Chi trả lương tháng 01 qua ngân hàng | F19: 334 | G19: 112 | H19: 58175000 | L19: =IF($H19="","",TRIM(IF(COUNTIF(DMTK!$A$7:$A$250,$F19)=0,"TK Nợ sai! ","")&IF(COUNTIF(DMTK!$A$7:$A$250,$G19)=0,"TK Có sai! ","")&IF(N($H19)<=0,"Tiền phải > 0! ","")&IF($B19="","Thiếu ngày! ","")&IF(AND(OR(LEFT($F19,3)="131",LEFT($G19,3)="131",LEFT($F19,3)="331",LEFT($G19,3)="331"),$I19=""),"Thiếu Mã ĐT! ","")&IF(AND($I19<>"",COUNTIF(DM_DT!$A$7:$A$306,$I19)=0),"Mã ĐT chưa khai báo! ",""))) | M19: =IF($H19="","",IF(AND(OR(LEFT($F19,3)="111",LEFT($F19,3)="112",LEFT($F19,3)="113"),OR(LEFT($G19,3)="111",LEFT($G19,3)="112",LEFT($G19,3)="113")),"NB",IF(OR(LEFT($F19,3)="111",LEFT($F19,3)="112",LEFT($F19,3)="113"),"THU",IF(OR(LEFT($G19,3)="111",LEFT($G19,3)="112",LEFT($G19,3)="113"),"CHI","")))) | N19: =IF($M19="THU",$G19,IF($M19="CHI",$F19,"")) | O19: =IF(OR($M19="",$M19="NB"),"",IF($J19<>"",TEXT($J19,"00"),IFERROR(VLOOKUP(LEFT($N19,4),LCTT_MAP!$A$7:$C$66,IF($M19="THU",2,3),FALSE()),IFERROR(VLOOKUP(LEFT($N19,3),LCTT_MAP!$A$7:$C$66,IF($M19="THU",2,3),FALSE()),IFERROR(VLOOKUP(LEFT($N19,2),LCTT_MAP!$A$7:$C$66,IF($M19="THU",2,3),FALSE()),IFERROR(VLOOKUP(LEFT($N19,1),LCTT_MAP!$A$7:$C$66,IF($M19="THU",2,3),FALSE()),IF($M19="THU","06","07"))))))) | P19: =P18+IF(AND($H19<>"",OR(LEFT($F19,LEN(SC_TK))=SC_TK,LEFT($G19,LEN(SC_TK))=SC_TK)),1,0)
A20: =IF($H20="","",ROW()-6) | B20: 46058 | C20: UNC003 | D20: 46058 | E20: Nộp BHXH, BHYT, BHTN, KPCĐ tháng 01 | F20: 3383 | G20: 112 | H20: 22100000 | L20: =IF($H20="","",TRIM(IF(COUNTIF(DMTK!$A$7:$A$250,$F20)=0,"TK Nợ sai! ","")&IF(COUNTIF(DMTK!$A$7:$A$250,$G20)=0,"TK Có sai! ","")&IF(N($H20)<=0,"Tiền phải > 0! ","")&IF($B20="","Thiếu ngày! ","")&IF(AND(OR(LEFT($F20,3)="131",LEFT($G20,3)="131",LEFT($F20,3)="331",LEFT($G20,3)="331"),$I20=""),"Thiếu Mã ĐT! ","")&IF(AND($I20<>"",COUNTIF(DM_DT!$A$7:$A$306,$I20)=0),"Mã ĐT chưa khai báo! ",""))) | M20: =IF($H20="","",IF(AND(OR(LEFT($F20,3)="111",LEFT($F20,3)="112",LEFT($F20,3)="113"),OR(LEFT($G20,3)="111",LEFT($G20,3)="112",LEFT($G20,3)="113")),"NB",IF(OR(LEFT($F20,3)="111",LEFT($F20,3)="112",LEFT($F20,3)="113"),"THU",IF(OR(LEFT($G20,3)="111",LEFT($G20,3)="112",LEFT($G20,3)="113"),"CHI","")))) | N20: =IF($M20="THU",$G20,IF($M20="CHI",$F20,"")) | O20: =IF(OR($M20="",$M20="NB"),"",IF($J20<>"",TEXT($J20,"00"),IFERROR(VLOOKUP(LEFT($N20,4),LCTT_MAP!$A$7:$C$66,IF($M20="THU",2,3),FALSE()),IFERROR(VLOOKUP(LEFT($N20,3),LCTT_MAP!$A$7:$C$66,IF($M20="THU",2,3),FALSE()),IFERROR(VLOOKUP(LEFT($N20,2),LCTT_MAP!$A$7:$C$66,IF($M20="THU",2,3),FALSE()),IFERROR(VLOOKUP(LEFT($N20,1),LCTT_MAP!$A$7:$C$66,IF($M20="THU",2,3),FALSE()),IF($M20="THU","06","07"))))))) | P20: =P19+IF(AND($H20<>"",OR(LEFT($F20,LEN(SC_TK))=SC_TK,LEFT($G20,LEN(SC_TK))=SC_TK)),1,0)
A21: =IF($H21="","",ROW()-6) | B21: 46068 | C21: HD0002 | D21: 46068 | E21: Bán hàng hóa - Cty Sao Mai | F21: 131 | G21: 511 | H21: 180000000 | I21: KH002 | L21: =IF($H21="","",TRIM(IF(COUNTIF(DMTK!$A$7:$A$250,$F21)=0,"TK Nợ sai! ","")&IF(COUNTIF(DMTK!$A$7:$A$250,$G21)=0,"TK Có sai! ","")&IF(N($H21)<=0,"Tiền phải > 0! ","")&IF($B21="","Thiếu ngày! ","")&IF(AND(OR(LEFT($F21,3)="131",LEFT($G21,3)="131",LEFT($F21,3)="331",LEFT($G21,3)="331"),$I21=""),"Thiếu Mã ĐT! ","")&IF(AND($I21<>"",COUNTIF(DM_DT!$A$7:$A$306,$I21)=0),"Mã ĐT chưa khai báo! ",""))) | M21: =IF($H21="","",IF(AND(OR(LEFT($F21,3)="111",LEFT($F21,3)="112",LEFT($F21,3)="113"),OR(LEFT($G21,3)="111",LEFT($G21,3)="112",LEFT($G21,3)="113")),"NB",IF(OR(LEFT($F21,3)="111",LEFT($F21,3)="112",LEFT($F21,3)="113"),"THU",IF(OR(LEFT($G21,3)="111",LEFT($G21,3)="112",LEFT($G21,3)="113"),"CHI","")))) | N21: =IF($M21="THU",$G21,IF($M21="CHI",$F21,"")) | O21: =IF(OR($M21="",$M21="NB"),"",IF($J21<>"",TEXT($J21,"00"),IFERROR(VLOOKUP(LEFT($N21,4),LCTT_MAP!$A$7:$C$66,IF($M21="THU",2,3),FALSE()),IFERROR(VLOOKUP(LEFT($N21,3),LCTT_MAP!$A$7:$C$66,IF($M21="THU",2,3),FALSE()),IFERROR(VLOOKUP(LEFT($N21,2),LCTT_MAP!$A$7:$C$66,IF($M21="THU",2,3),FALSE()),IFERROR(VLOOKUP(LEFT($N21,1),LCTT_MAP!$A$7:$C$66,IF($M21="THU",2,3),FALSE()),IF($M21="THU","06","07"))))))) | P21: =P20+IF(AND($H21<>"",OR(LEFT($F21,LEN(SC_TK))=SC_TK,LEFT($G21,LEN(SC_TK))=SC_TK)),1,0)
A22: =IF($H22="","",ROW()-6) | B22: 46068 | C22: HD0002 | D22: 46068 | E22: Thuế GTGT đầu ra bán hàng | F22: 131 | G22: 33311 | H22: 14400000 | I22: KH002 | L22: =IF($H22="","",TRIM(IF(COUNTIF(DMTK!$A$7:$A$250,$F22)=0,"TK Nợ sai! ","")&IF(COUNTIF(DMTK!$A$7:$A$250,$G22)=0,"TK Có sai! ","")&IF(N($H22)<=0,"Tiền phải > 0! ","")&IF($B22="","Thiếu ngày! ","")&IF(AND(OR(LEFT($F22,3)="131",LEFT($G22,3)="131",LEFT($F22,3)="331",LEFT($G22,3)="331"),$I22=""),"Thiếu Mã ĐT! ","")&IF(AND($I22<>"",COUNTIF(DM_DT!$A$7:$A$306,$I22)=0),"Mã ĐT chưa khai báo! ",""))) | M22: =IF($H22="","",IF(AND(OR(LEFT($F22,3)="111",LEFT($F22,3)="112",LEFT($F22,3)="113"),OR(LEFT($G22,3)="111",LEFT($G22,3)="112",LEFT($G22,3)="113")),"NB",IF(OR(LEFT($F22,3)="111",LEFT($F22,3)="112",LEFT($F22,3)="113"),"THU",IF(OR(LEFT($G22,3)="111",LEFT($G22,3)="112",LEFT($G22,3)="113"),"CHI","")))) | N22: =IF($M22="THU",$G22,IF($M22="CHI",$F22,"")) | O22: =IF(OR($M22="",$M22="NB"),"",IF($J22<>"",TEXT($J22,"00"),IFERROR(VLOOKUP(LEFT($N22,4),LCTT_MAP!$A$7:$C$66,IF($M22="THU",2,3),FALSE()),IFERROR(VLOOKUP(LEFT($N22,3),LCTT_MAP!$A$7:$C$66,IF($M22="THU",2,3),FALSE()),IFERROR(VLOOKUP(LEFT($N22,2),LCTT_MAP!$A$7:$C$66,IF($M22="THU",2,3),FALSE()),IFERROR(VLOOKUP(LEFT($N22,1),LCTT_MAP!$A$7:$C$66,IF($M22="THU",2,3),FALSE()),IF($M22="THU","06","07"))))))) | P22: =P21+IF(AND($H22<>"",OR(LEFT($F22,LEN(SC_TK))=SC_TK,LEFT($G22,LEN(SC_TK))=SC_TK)),1,0)
A23: =IF($H23="","",ROW()-6) | B23: 46068 | C23: PX002 | D23: 46068 | E23: Giá vốn hàng bán HĐ 0002 | F23: 632 | G23: 156 | H23: 130000000 | L23: =IF($H23="","",TRIM(IF(COUNTIF(DMTK!$A$7:$A$250,$F23)=0,"TK Nợ sai! ","")&IF(COUNTIF(DMTK!$A$7:$A$250,$G23)=0,"TK Có sai! ","")&IF(N($H23)<=0,"Tiền phải > 0! ","")&IF($B23="","Thiếu ngày! ","")&IF(AND(OR(LEFT($F23,3)="131",LEFT($G23,3)="131",LEFT($F23,3)="331",LEFT($G23,3)="331"),$I23=""),"Thiếu Mã ĐT! ","")&IF(AND($I23<>"",COUNTIF(DM_DT!$A$7:$A$306,$I23)=0),"Mã ĐT chưa khai báo! ",""))) | M23: =IF($H23="","",IF(AND(OR(LEFT($F23,3)="111",LEFT($F23,3)="112",LEFT($F23,3)="113"),OR(LEFT($G23,3)="111",LEFT($G23,3)="112",LEFT($G23,3)="113")),"NB",IF(OR(LEFT($F23,3)="111",LEFT($F23,3)="112",LEFT($F23,3)="113"),"THU",IF(OR(LEFT($G23,3)="111",LEFT($G23,3)="112",LEFT($G23,3)="113"),"CHI","")))) | N23: =IF($M23="THU",$G23,IF($M23="CHI",$F23,"")) | O23: =IF(OR($M23="",$M23="NB"),"",IF($J23<>"",TEXT($J23,"00"),IFERROR(VLOOKUP(LEFT($N23,4),LCTT_MAP!$A$7:$C$66,IF($M23="THU",2,3),FALSE()),IFERROR(VLOOKUP(LEFT($N23,3),LCTT_MAP!$A$7:$C$66,IF($M23="THU",2,3),FALSE()),IFERROR(VLOOKUP(LEFT($N23,2),LCTT_MAP!$A$7:$C$66,IF($M23="THU",2,3),FALSE()),IFERROR(VLOOKUP(LEFT($N23,1),LCTT_MAP!$A$7:$C$66,IF($M23="THU",2,3),FALSE()),IF($M23="THU","06","07"))))))) | P23: =P22+IF(AND($H23<>"",OR(LEFT($F23,LEN(SC_TK))=SC_TK,LEFT($G23,LEN(SC_TK))=SC_TK)),1,0)
A24: =IF($H24="","",ROW()-6) | B24: 46081 | C24: PC001 | D24: 46081 | E24: Chi tiếp khách bằng tiền mặt | F24: 6428 | G24: 111 | H24: 8000000 | L24: =IF($H24="","",TRIM(IF(COUNTIF(DMTK!$A$7:$A$250,$F24)=0,"TK Nợ sai! ","")&IF(COUNTIF(DMTK!$A$7:$A$250,$G24)=0,"TK Có sai! ","")&IF(N($H24)<=0,"Tiền phải > 0! ","")&IF($B24="","Thiếu ngày! ","")&IF(AND(OR(LEFT($F24,3)="131",LEFT($G24,3)="131",LEFT($F24,3)="331",LEFT($G24,3)="331"),$I24=""),"Thiếu Mã ĐT! ","")&IF(AND($I24<>"",COUNTIF(DM_DT!$A$7:$A$306,$I24)=0),"Mã ĐT chưa khai báo! ",""))) | M24: =IF($H24="","",IF(AND(OR(LEFT($F24,3)="111",LEFT($F24,3)="112",LEFT($F24,3)="113"),OR(LEFT($G24,3)="111",LEFT($G24,3)="112",LEFT($G24,3)="113")),"NB",IF(OR(LEFT($F24,3)="111",LEFT($F24,3)="112",LEFT($F24,3)="113"),"THU",IF(OR(LEFT($G24,3)="111",LEFT($G24,3)="112",LEFT($G24,3)="113"),"CHI","")))) | N24: =IF($M24="THU",$G24,IF($M24="CHI",$F24,"")) | O24: =IF(OR($M24="",$M24="NB"),"",IF($J24<>"",TEXT($J24,"00"),IFERROR(VLOOKUP(LEFT($N24,4),LCTT_MAP!$A$7:$C$66,IF($M24="THU",2,3),FALSE()),IFERROR(VLOOKUP(LEFT($N24,3),LCTT_MAP!$A$7:$C$66,IF($M24="THU",2,3),FALSE()),IFERROR(VLOOKUP(LEFT($N24,2),LCTT_MAP!$A$7:$C$66,IF($M24="THU",2,3),FALSE()),IFERROR(VLOOKUP(LEFT($N24,1),LCTT_MAP!$A$7:$C$66,IF($M24="THU",2,3),FALSE()),IF($M24="THU","06","07"))))))) | P24: =P23+IF(AND($H24<>"",OR(LEFT($F24,LEN(SC_TK))=SC_TK,LEFT($G24,LEN(SC_TK))=SC_TK)),1,0)
A25: =IF($H25="","",ROW()-6) | B25: 46081 | C25: PKT001 | D25: 46081 | E25: Khấu trừ thuế GTGT đầu vào với đầu ra | F25: 33311 | G25: 1331 | H25: 16000000 | L25: =IF($H25="","",TRIM(IF(COUNTIF(DMTK!$A$7:$A$250,$F25)=0,"TK Nợ sai! ","")&IF(COUNTIF(DMTK!$A$7:$A$250,$G25)=0,"TK Có sai! ","")&IF(N($H25)<=0,"Tiền phải > 0! ","")&IF($B25="","Thiếu ngày! ","")&IF(AND(OR(LEFT($F25,3)="131",LEFT($G25,3)="131",LEFT($F25,3)="331",LEFT($G25,3)="331"),$I25=""),"Thiếu Mã ĐT! ","")&IF(AND($I25<>"",COUNTIF(DM_DT!$A$7:$A$306,$I25)=0),"Mã ĐT chưa khai báo! ",""))) | M25: =IF($H25="","",IF(AND(OR(LEFT($F25,3)="111",LEFT($F25,3)="112",LEFT($F25,3)="113"),OR(LEFT($G25,3)="111",LEFT($G25,3)="112",LEFT($G25,3)="113")),"NB",IF(OR(LEFT($F25,3)="111",LEFT($F25,3)="112",LEFT($F25,3)="113"),"THU",IF(OR(LEFT($G25,3)="111",LEFT($G25,3)="112",LEFT($G25,3)="113"),"CHI","")))) | N25: =IF($M25="THU",$G25,IF($M25="CHI",$F25,"")) | O25: =IF(OR($M25="",$M25="NB"),"",IF($J25<>"",TEXT($J25,"00"),IFERROR(VLOOKUP(LEFT($N25,4),LCTT_MAP!$A$7:$C$66,IF($M25="THU",2,3),FALSE()),IFERROR(VLOOKUP(LEFT($N25,3),LCTT_MAP!$A$7:$C$66,IF($M25="THU",2,3),FALSE()),IFERROR(VLOOKUP(LEFT($N25,2),LCTT_MAP!$A$7:$C$66,IF($M25="THU",2,3),FALSE()),IFERROR(VLOOKUP(LEFT($N25,1),LCTT_MAP!$A$7:$C$66,IF($M25="THU",2,3),FALSE()),IF($M25="THU","06","07"))))))) | P25: =P24+IF(AND($H25<>"",OR(LEFT($F25,LEN(SC_TK))=SC_TK,LEFT($G25,LEN(SC_TK))=SC_TK)),1,0)
A26: =IF($H26="","",ROW()-6) | B26: 46091 | C26: BC002 | D26: 46091 | E26: Thu nợ tiền hàng - Cty Sao Mai | F26: 112 | G26: 131 | H26: 200000000 | I26: KH002 | L26: =IF($H26="","",TRIM(IF(COUNTIF(DMTK!$A$7:$A$250,$F26)=0,"TK Nợ sai! ","")&IF(COUNTIF(DMTK!$A$7:$A$250,$G26)=0,"TK Có sai! ","")&IF(N($H26)<=0,"Tiền phải > 0! ","")&IF($B26="","Thiếu ngày! ","")&IF(AND(OR(LEFT($F26,3)="131",LEFT($G26,3)="131",LEFT($F26,3)="331",LEFT($G26,3)="331"),$I26=""),"Thiếu Mã ĐT! ","")&IF(AND($I26<>"",COUNTIF(DM_DT!$A$7:$A$306,$I26)=0),"Mã ĐT chưa khai báo! ",""))) | M26: =IF($H26="","",IF(AND(OR(LEFT($F26,3)="111",LEFT($F26,3)="112",LEFT($F26,3)="113"),OR(LEFT($G26,3)="111",LEFT($G26,3)="112",LEFT($G26,3)="113")),"NB",IF(OR(LEFT($F26,3)="111",LEFT($F26,3)="112",LEFT($F26,3)="113"),"THU",IF(OR(LEFT($G26,3)="111",LEFT($G26,3)="112",LEFT($G26,3)="113"),"CHI","")))) | N26: =IF($M26="THU",$G26,IF($M26="CHI",$F26,"")) | O26: =IF(OR($M26="",$M26="NB"),"",IF($J26<>"",TEXT($J26,"00"),IFERROR(VLOOKUP(LEFT($N26,4),LCTT_MAP!$A$7:$C$66,IF($M26="THU",2,3),FALSE()),IFERROR(VLOOKUP(LEFT($N26,3),LCTT_MAP!$A$7:$C$66,IF($M26="THU",2,3),FALSE()),IFERROR(VLOOKUP(LEFT($N26,2),LCTT_MAP!$A$7:$C$66,IF($M26="THU",2,3),FALSE()),IFERROR(VLOOKUP(LEFT($N26,1),LCTT_MAP!$A$7:$C$66,IF($M26="THU",2,3),FALSE()),IF($M26="THU","06","07"))))))) | P26: =P25+IF(AND($H26<>"",OR(LEFT($F26,LEN(SC_TK))=SC_TK,LEFT($G26,LEN(SC_TK))=SC_TK)),1,0)
A27: =IF($H27="","",ROW()-6) | B27: 46101 | C27: UNC004 | D27: 46101 | E27: Nộp thuế TNDN còn phải nộp năm 2025 | F27: 3334 | G27: 112 | H27: 12000000 | L27: =IF($H27="","",TRIM(IF(COUNTIF(DMTK!$A$7:$A$250,$F27)=0,"TK Nợ sai! ","")&IF(COUNTIF(DMTK!$A$7:$A$250,$G27)=0,"TK Có sai! ","")&IF(N($H27)<=0,"Tiền phải > 0! ","")&IF($B27="","Thiếu ngày! ","")&IF(AND(OR(LEFT($F27,3)="131",LEFT($G27,3)="131",LEFT($F27,3)="331",LEFT($G27,3)="331"),$I27=""),"Thiếu Mã ĐT! ","")&IF(AND($I27<>"",COUNTIF(DM_DT!$A$7:$A$306,$I27)=0),"Mã ĐT chưa khai báo! ",""))) | M27: =IF($H27="","",IF(AND(OR(LEFT($F27,3)="111",LEFT($F27,3)="112",LEFT($F27,3)="113"),OR(LEFT($G27,3)="111",LEFT($G27,3)="112",LEFT($G27,3)="113")),"NB",IF(OR(LEFT($F27,3)="111",LEFT($F27,3)="112",LEFT($F27,3)="113"),"THU",IF(OR(LEFT($G27,3)="111",LEFT($G27,3)="112",LEFT($G27,3)="113"),"CHI","")))) | N27: =IF($M27="THU",$G27,IF($M27="CHI",$F27,"")) | O27: =IF(OR($M27="",$M27="NB"),"",IF($J27<>"",TEXT($J27,"00"),IFERROR(VLOOKUP(LEFT($N27,4),LCTT_MAP!$A$7:$C$66,IF($M27="THU",2,3),FALSE()),IFERROR(VLOOKUP(LEFT($N27,3),LCTT_MAP!$A$7:$C$66,IF($M27="THU",2,3),FALSE()),IFERROR(VLOOKUP(LEFT($N27,2),LCTT_MAP!$A$7:$C$66,IF($M27="THU",2,3),FALSE()),IFERROR(VLOOKUP(LEFT($N27,1),LCTT_MAP!$A$7:$C$66,IF($M27="THU",2,3),FALSE()),IF($M27="THU","06","07"))))))) | P27: =P26+IF(AND($H27<>"",OR(LEFT($F27,LEN(SC_TK))=SC_TK,LEFT($G27,LEN(SC_TK))=SC_TK)),1,0)
A28: =IF($H28="","",ROW()-6) | B28: 46106 | C28: UNC005 | D28: 46106 | E28: Nộp thuế GTGT vào NSNN | F28: 33311 | G28: 112 | H28: 18400000 | L28: =IF($H28="","",TRIM(IF(COUNTIF(DMTK!$A$7:$A$250,$F28)=0,"TK Nợ sai! ","")&IF(COUNTIF(DMTK!$A$7:$A$250,$G28)=0,"TK Có sai! ","")&IF(N($H28)<=0,"Tiền phải > 0! ","")&IF($B28="","Thiếu ngày! ","")&IF(AND(OR(LEFT($F28,3)="131",LEFT($G28,3)="131",LEFT($F28,3)="331",LEFT($G28,3)="331"),$I28=""),"Thiếu Mã ĐT! ","")&IF(AND($I28<>"",COUNTIF(DM_DT!$A$7:$A$306,$I28)=0),"Mã ĐT chưa khai báo! ",""))) | M28: =IF($H28="","",IF(AND(OR(LEFT($F28,3)="111",LEFT($F28,3)="112",LEFT($F28,3)="113"),OR(LEFT($G28,3)="111",LEFT($G28,3)="112",LEFT($G28,3)="113")),"NB",IF(OR(LEFT($F28,3)="111",LEFT($F28,3)="112",LEFT($F28,3)="113"),"THU",IF(OR(LEFT($G28,3)="111",LEFT($G28,3)="112",LEFT($G28,3)="113"),"CHI","")))) | N28: =IF($M28="THU",$G28,IF($M28="CHI",$F28,"")) | O28: =IF(OR($M28="",$M28="NB"),"",IF($J28<>"",TEXT($J28,"00"),IFERROR(VLOOKUP(LEFT($N28,4),LCTT_MAP!$A$7:$C$66,IF($M28="THU",2,3),FALSE()),IFERROR(VLOOKUP(LEFT($N28,3),LCTT_MAP!$A$7:$C$66,IF($M28="THU",2,3),FALSE()),IFERROR(VLOOKUP(LEFT($N28,2),LCTT_MAP!$A$7:$C$66,IF($M28="THU",2,3),FALSE()),IFERROR(VLOOKUP(LEFT($N28,1),LCTT_MAP!$A$7:$C$66,IF($M28="THU",2,3),FALSE()),IF($M28="THU","06","07"))))))) | P28: =P27+IF(AND($H28<>"",OR(LEFT($F28,LEN(SC_TK))=SC_TK,LEFT($G28,LEN(SC_TK))=SC_TK)),1,0)
A29: =IF($H29="","",ROW()-6) | B29: 46112 | C29: PKT002 | D29: 46112 | E29: Khấu hao TSCĐ quý 1 - bộ phận QLDN | F29: 6424 | G29: 2141 | H29: 15000000 | L29: =IF($H29="","",TRIM(IF(COUNTIF(DMTK!$A$7:$A$250,$F29)=0,"TK Nợ sai! ","")&IF(COUNTIF(DMTK!$A$7:$A$250,$G29)=0,"TK Có sai! ","")&IF(N($H29)<=0,"Tiền phải > 0! ","")&IF($B29="","Thiếu ngày! ","")&IF(AND(OR(LEFT($F29,3)="131",LEFT($G29,3)="131",LEFT($F29,3)="331",LEFT($G29,3)="331"),$I29=""),"Thiếu Mã ĐT! ","")&IF(AND($I29<>"",COUNTIF(DM_DT!$A$7:$A$306,$I29)=0),"Mã ĐT chưa khai báo! ",""))) | M29: =IF($H29="","",IF(AND(OR(LEFT($F29,3)="111",LEFT($F29,3)="112",LEFT($F29,3)="113"),OR(LEFT($G29,3)="111",LEFT($G29,3)="112",LEFT($G29,3)="113")),"NB",IF(OR(LEFT($F29,3)="111",LEFT($F29,3)="112",LEFT($F29,3)="113"),"THU",IF(OR(LEFT($G29,3)="111",LEFT($G29,3)="112",LEFT($G29,3)="113"),"CHI","")))) | N29: =IF($M29="THU",$G29,IF($M29="CHI",$F29,"")) | O29: =IF(OR($M29="",$M29="NB"),"",IF($J29<>"",TEXT($J29,"00"),IFERROR(VLOOKUP(LEFT($N29,4),LCTT_MAP!$A$7:$C$66,IF($M29="THU",2,3),FALSE()),IFERROR(VLOOKUP(LEFT($N29,3),LCTT_MAP!$A$7:$C$66,IF($M29="THU",2,3),FALSE()),IFERROR(VLOOKUP(LEFT($N29,2),LCTT_MAP!$A$7:$C$66,IF($M29="THU",2,3),FALSE()),IFERROR(VLOOKUP(LEFT($N29,1),LCTT_MAP!$A$7:$C$66,IF($M29="THU",2,3),FALSE()),IF($M29="THU","06","07"))))))) | P29: =P28+IF(AND($H29<>"",OR(LEFT($F29,LEN(SC_TK))=SC_TK,LEFT($G29,LEN(SC_TK))=SC_TK)),1,0)
A30: =IF($H30="","",ROW()-6) | B30: 46117 | C30: PC002 | D30: 46117 | E30: Mua văn phòng phẩm bằng tiền mặt | F30: 6423 | G30: 111 | H30: 5000000 | L30: =IF($H30="","",TRIM(IF(COUNTIF(DMTK!$A$7:$A$250,$F30)=0,"TK Nợ sai! ","")&IF(COUNTIF(DMTK!$A$7:$A$250,$G30)=0,"TK Có sai! ","")&IF(N($H30)<=0,"Tiền phải > 0! ","")&IF($B30="","Thiếu ngày! ","")&IF(AND(OR(LEFT($F30,3)="131",LEFT($G30,3)="131",LEFT($F30,3)="331",LEFT($G30,3)="331"),$I30=""),"Thiếu Mã ĐT! ","")&IF(AND($I30<>"",COUNTIF(DM_DT!$A$7:$A$306,$I30)=0),"Mã ĐT chưa khai báo! ",""))) | M30: =IF($H30="","",IF(AND(OR(LEFT($F30,3)="111",LEFT($F30,3)="112",LEFT($F30,3)="113"),OR(LEFT($G30,3)="111",LEFT($G30,3)="112",LEFT($G30,3)="113")),"NB",IF(OR(LEFT($F30,3)="111",LEFT($F30,3)="112",LEFT($F30,3)="113"),"THU",IF(OR(LEFT($G30,3)="111",LEFT($G30,3)="112",LEFT($G30,3)="113"),"CHI","")))) | N30: =IF($M30="THU",$G30,IF($M30="CHI",$F30,"")) | O30: =IF(OR($M30="",$M30="NB"),"",IF($J30<>"",TEXT($J30,"00"),IFERROR(VLOOKUP(LEFT($N30,4),LCTT_MAP!$A$7:$C$66,IF($M30="THU",2,3),FALSE()),IFERROR(VLOOKUP(LEFT($N30,3),LCTT_MAP!$A$7:$C$66,IF($M30="THU",2,3),FALSE()),IFERROR(VLOOKUP(LEFT($N30,2),LCTT_MAP!$A$7:$C$66,IF($M30="THU",2,3),FALSE()),IFERROR(VLOOKUP(LEFT($N30,1),LCTT_MAP!$A$7:$C$66,IF($M30="THU",2,3),FALSE()),IF($M30="THU","06","07"))))))) | P30: =P29+IF(AND($H30<>"",OR(LEFT($F30,LEN(SC_TK))=SC_TK,LEFT($G30,LEN(SC_TK))=SC_TK)),1,0)
A31: =IF($H31="","",ROW()-6) | B31: 46117 | C31: PC002 | D31: 46117 | E31: Thuế GTGT đầu vào văn phòng phẩm | F31: 1331 | G31: 111 | H31: 400000 | L31: =IF($H31="","",TRIM(IF(COUNTIF(DMTK!$A$7:$A$250,$F31)=0,"TK Nợ sai! ","")&IF(COUNTIF(DMTK!$A$7:$A$250,$G31)=0,"TK Có sai! ","")&IF(N($H31)<=0,"Tiền phải > 0! ","")&IF($B31="","Thiếu ngày! ","")&IF(AND(OR(LEFT($F31,3)="131",LEFT($G31,3)="131",LEFT($F31,3)="331",LEFT($G31,3)="331"),$I31=""),"Thiếu Mã ĐT! ","")&IF(AND($I31<>"",COUNTIF(DM_DT!$A$7:$A$306,$I31)=0),"Mã ĐT chưa khai báo! ",""))) | M31: =IF($H31="","",IF(AND(OR(LEFT($F31,3)="111",LEFT($F31,3)="112",LEFT($F31,3)="113"),OR(LEFT($G31,3)="111",LEFT($G31,3)="112",LEFT($G31,3)="113")),"NB",IF(OR(LEFT($F31,3)="111",LEFT($F31,3)="112",LEFT($F31,3)="113"),"THU",IF(OR(LEFT($G31,3)="111",LEFT($G31,3)="112",LEFT($G31,3)="113"),"CHI","")))) | N31: =IF($M31="THU",$G31,IF($M31="CHI",$F31,"")) | O31: =IF(OR($M31="",$M31="NB"),"",IF($J31<>"",TEXT($J31,"00"),IFERROR(VLOOKUP(LEFT($N31,4),LCTT_MAP!$A$7:$C$66,IF($M31="THU",2,3),FALSE()),IFERROR(VLOOKUP(LEFT($N31,3),LCTT_MAP!$A$7:$C$66,IF($M31="THU",2,3),FALSE()),IFERROR(VLOOKUP(LEFT($N31,2),LCTT_MAP!$A$7:$C$66,IF($M31="THU",2,3),FALSE()),IFERROR(VLOOKUP(LEFT($N31,1),LCTT_MAP!$A$7:$C$66,IF($M31="THU",2,3),FALSE()),IF($M31="THU","06","07"))))))) | P31: =P30+IF(AND($H31<>"",OR(LEFT($F31,LEN(SC_TK))=SC_TK,LEFT($G31,LEN(SC_TK))=SC_TK)),1,0)
A32: =IF($H32="","",ROW()-6) | B32: 46127 | C32: HDM001 | D32: 46127 | E32: Mua xe tải giao hàng - Cty Đại Nam | F32: 211 | G32: 331 | H32: 240000000 | I32: NCC002 | L32: =IF($H32="","",TRIM(IF(COUNTIF(DMTK!$A$7:$A$250,$F32)=0,"TK Nợ sai! ","")&IF(COUNTIF(DMTK!$A$7:$A$250,$G32)=0,"TK Có sai! ","")&IF(N($H32)<=0,"Tiền phải > 0! ","")&IF($B32="","Thiếu ngày! ","")&IF(AND(OR(LEFT($F32,3)="131",LEFT($G32,3)="131",LEFT($F32,3)="331",LEFT($G32,3)="331"),$I32=""),"Thiếu Mã ĐT! ","")&IF(AND($I32<>"",COUNTIF(DM_DT!$A$7:$A$306,$I32)=0),"Mã ĐT chưa khai báo! ",""))) | M32: =IF($H32="","",IF(AND(OR(LEFT($F32,3)="111",LEFT($F32,3)="112",LEFT($F32,3)="113"),OR(LEFT($G32,3)="111",LEFT($G32,3)="112",LEFT($G32,3)="113")),"NB",IF(OR(LEFT($F32,3)="111",LEFT($F32,3)="112",LEFT($F32,3)="113"),"THU",IF(OR(LEFT($G32,3)="111",LEFT($G32,3)="112",LEFT($G32,3)="113"),"CHI","")))) | N32: =IF($M32="THU",$G32,IF($M32="CHI",$F32,"")) | O32: =IF(OR($M32="",$M32="NB"),"",IF($J32<>"",TEXT($J32,"00"),IFERROR(VLOOKUP(LEFT($N32,4),LCTT_MAP!$A$7:$C$66,IF($M32="THU",2,3),FALSE()),IFERROR(VLOOKUP(LEFT($N32,3),LCTT_MAP!$A$7:$C$66,IF($M32="THU",2,3),FALSE()),IFERROR(VLOOKUP(LEFT($N32,2),LCTT_MAP!$A$7:$C$66,IF($M32="THU",2,3),FALSE()),IFERROR(VLOOKUP(LEFT($N32,1),LCTT_MAP!$A$7:$C$66,IF($M32="THU",2,3),FALSE()),IF($M32="THU","06","07"))))))) | P32: =P31+IF(AND($H32<>"",OR(LEFT($F32,LEN(SC_TK))=SC_TK,LEFT($G32,LEN(SC_TK))=SC_TK)),1,0)
A33: =IF($H33="","",ROW()-6) | B33: 46127 | C33: HDM001 | D33: 46127 | E33: Thuế GTGT đầu vào TSCĐ (xe tải) | F33: 1332 | G33: 331 | H33: 19200000 | I33: NCC002 | L33: =IF($H33="","",TRIM(IF(COUNTIF(DMTK!$A$7:$A$250,$F33)=0,"TK Nợ sai! ","")&IF(COUNTIF(DMTK!$A$7:$A$250,$G33)=0,"TK Có sai! ","")&IF(N($H33)<=0,"Tiền phải > 0! ","")&IF($B33="","Thiếu ngày! ","")&IF(AND(OR(LEFT($F33,3)="131",LEFT($G33,3)="131",LEFT($F33,3)="331",LEFT($G33,3)="331"),$I33=""),"Thiếu Mã ĐT! ","")&IF(AND($I33<>"",COUNTIF(DM_DT!$A$7:$A$306,$I33)=0),"Mã ĐT chưa khai báo! ",""))) | M33: =IF($H33="","",IF(AND(OR(LEFT($F33,3)="111",LEFT($F33,3)="112",LEFT($F33,3)="113"),OR(LEFT($G33,3)="111",LEFT($G33,3)="112",LEFT($G33,3)="113")),"NB",IF(OR(LEFT($F33,3)="111",LEFT($F33,3)="112",LEFT($F33,3)="113"),"THU",IF(OR(LEFT($G33,3)="111",LEFT($G33,3)="112",LEFT($G33,3)="113"),"CHI","")))) | N33: =IF($M33="THU",$G33,IF($M33="CHI",$F33,"")) | O33: =IF(OR($M33="",$M33="NB"),"",IF($J33<>"",TEXT($J33,"00"),IFERROR(VLOOKUP(LEFT($N33,4),LCTT_MAP!$A$7:$C$66,IF($M33="THU",2,3),FALSE()),IFERROR(VLOOKUP(LEFT($N33,3),LCTT_MAP!$A$7:$C$66,IF($M33="THU",2,3),FALSE()),IFERROR(VLOOKUP(LEFT($N33,2),LCTT_MAP!$A$7:$C$66,IF($M33="THU",2,3),FALSE()),IFERROR(VLOOKUP(LEFT($N33,1),LCTT_MAP!$A$7:$C$66,IF($M33="THU",2,3),FALSE()),IF($M33="THU","06","07"))))))) | P33: =P32+IF(AND($H33<>"",OR(LEFT($F33,LEN(SC_TK))=SC_TK,LEFT($G33,LEN(SC_TK))=SC_TK)),1,0)
A34: =IF($H34="","",ROW()-6) | B34: 46132 | C34: UNC006 | D34: 46132 | E34: Trả tiền mua xe tải - Cty Đại Nam | F34: 331 | G34: 112 | H34: 259200000 | I34: NCC002 | J34: 21 | L34: =IF($H34="","",TRIM(IF(COUNTIF(DMTK!$A$7:$A$250,$F34)=0,"TK Nợ sai! ","")&IF(COUNTIF(DMTK!$A$7:$A$250,$G34)=0,"TK Có sai! ","")&IF(N($H34)<=0,"Tiền phải > 0! ","")&IF($B34="","Thiếu ngày! ","")&IF(AND(OR(LEFT($F34,3)="131",LEFT($G34,3)="131",LEFT($F34,3)="331",LEFT($G34,3)="331"),$I34=""),"Thiếu Mã ĐT! ","")&IF(AND($I34<>"",COUNTIF(DM_DT!$A$7:$A$306,$I34)=0),"Mã ĐT chưa khai báo! ",""))) | M34: =IF($H34="","",IF(AND(OR(LEFT($F34,3)="111",LEFT($F34,3)="112",LEFT($F34,3)="113"),OR(LEFT($G34,3)="111",LEFT($G34,3)="112",LEFT($G34,3)="113")),"NB",IF(OR(LEFT($F34,3)="111",LEFT($F34,3)="112",LEFT($F34,3)="113"),"THU",IF(OR(LEFT($G34,3)="111",LEFT($G34,3)="112",LEFT($G34,3)="113"),"CHI","")))) | N34: =IF($M34="THU",$G34,IF($M34="CHI",$F34,"")) | O34: =IF(OR($M34="",$M34="NB"),"",IF($J34<>"",TEXT($J34,"00"),IFERROR(VLOOKUP(LEFT($N34,4),LCTT_MAP!$A$7:$C$66,IF($M34="THU",2,3),FALSE()),IFERROR(VLOOKUP(LEFT($N34,3),LCTT_MAP!$A$7:$C$66,IF($M34="THU",2,3),FALSE()),IFERROR(VLOOKUP(LEFT($N34,2),LCTT_MAP!$A$7:$C$66,IF($M34="THU",2,3),FALSE()),IFERROR(VLOOKUP(LEFT($N34,1),LCTT_MAP!$A$7:$C$66,IF($M34="THU",2,3),FALSE()),IF($M34="THU","06","07"))))))) | P34: =P33+IF(AND($H34<>"",OR(LEFT($F34,LEN(SC_TK))=SC_TK,LEFT($G34,LEN(SC_TK))=SC_TK)),1,0)
A35: =IF($H35="","",ROW()-6) | B35: 46152 | C35: BC003 | D35: 46152 | E35: Vay ngắn hạn NH bổ sung vốn lưu động | F35: 112 | G35: 3411 | H35: 150000000 | L35: =IF($H35="","",TRIM(IF(COUNTIF(DMTK!$A$7:$A$250,$F35)=0,"TK Nợ sai! ","")&IF(COUNTIF(DMTK!$A$7:$A$250,$G35)=0,"TK Có sai! ","")&IF(N($H35)<=0,"Tiền phải > 0! ","")&IF($B35="","Thiếu ngày! ","")&IF(AND(OR(LEFT($F35,3)="131",LEFT($G35,3)="131",LEFT($F35,3)="331",LEFT($G35,3)="331"),$I35=""),"Thiếu Mã ĐT! ","")&IF(AND($I35<>"",COUNTIF(DM_DT!$A$7:$A$306,$I35)=0),"Mã ĐT chưa khai báo! ",""))) | M35: =IF($H35="","",IF(AND(OR(LEFT($F35,3)="111",LEFT($F35,3)="112",LEFT($F35,3)="113"),OR(LEFT($G35,3)="111",LEFT($G35,3)="112",LEFT($G35,3)="113")),"NB",IF(OR(LEFT($F35,3)="111",LEFT($F35,3)="112",LEFT($F35,3)="113"),"THU",IF(OR(LEFT($G35,3)="111",LEFT($G35,3)="112",LEFT($G35,3)="113"),"CHI","")))) | N35: =IF($M35="THU",$G35,IF($M35="CHI",$F35,"")) | O35: =IF(OR($M35="",$M35="NB"),"",IF($J35<>"",TEXT($J35,"00"),IFERROR(VLOOKUP(LEFT($N35,4),LCTT_MAP!$A$7:$C$66,IF($M35="THU",2,3),FALSE()),IFERROR(VLOOKUP(LEFT($N35,3),LCTT_MAP!$A$7:$C$66,IF($M35="THU",2,3),FALSE()),IFERROR(VLOOKUP(LEFT($N35,2),LCTT_MAP!$A$7:$C$66,IF($M35="THU",2,3),FALSE()),IFERROR(VLOOKUP(LEFT($N35,1),LCTT_MAP!$A$7:$C$66,IF($M35="THU",2,3),FALSE()),IF($M35="THU","06","07"))))))) | P35: =P34+IF(AND($H35<>"",OR(LEFT($F35,LEN(SC_TK))=SC_TK,LEFT($G35,LEN(SC_TK))=SC_TK)),1,0)
A36: =IF($H36="","",ROW()-6) | B36: 46203 | C36: UNC007 | D36: 46203 | E36: Trả lãi vay ngân hàng 6 tháng đầu năm | F36: 635 | G36: 112 | H36: 12000000 | L36: =IF($H36="","",TRIM(IF(COUNTIF(DMTK!$A$7:$A$250,$F36)=0,"TK Nợ sai! ","")&IF(COUNTIF(DMTK!$A$7:$A$250,$G36)=0,"TK Có sai! ","")&IF(N($H36)<=0,"Tiền phải > 0! ","")&IF($B36="","Thiếu ngày! ","")&IF(AND(OR(LEFT($F36,3)="131",LEFT($G36,3)="131",LEFT($F36,3)="331",LEFT($G36,3)="331"),$I36=""),"Thiếu Mã ĐT! ","")&IF(AND($I36<>"",COUNTIF(DM_DT!$A$7:$A$306,$I36)=0),"Mã ĐT chưa khai báo! ",""))) | M36: =IF($H36="","",IF(AND(OR(LEFT($F36,3)="111",LEFT($F36,3)="112",LEFT($F36,3)="113"),OR(LEFT($G36,3)="111",LEFT($G36,3)="112",LEFT($G36,3)="113")),"NB",IF(OR(LEFT($F36,3)="111",LEFT($F36,3)="112",LEFT($F36,3)="113"),"THU",IF(OR(LEFT($G36,3)="111",LEFT($G36,3)="112",LEFT($G36,3)="113"),"CHI","")))) | N36: =IF($M36="THU",$G36,IF($M36="CHI",$F36,"")) | O36: =IF(OR($M36="",$M36="NB"),"",IF($J36<>"",TEXT($J36,"00"),IFERROR(VLOOKUP(LEFT($N36,4),LCTT_MAP!$A$7:$C$66,IF($M36="THU",2,3),FALSE()),IFERROR(VLOOKUP(LEFT($N36,3),LCTT_MAP!$A$7:$C$66,IF($M36="THU",2,3),FALSE()),IFERROR(VLOOKUP(LEFT($N36,2),LCTT_MAP!$A$7:$C$66,IF($M36="THU",2,3),FALSE()),IFERROR(VLOOKUP(LEFT($N36,1),LCTT_MAP!$A$7:$C$66,IF($M36="THU",2,3),FALSE()),IF($M36="THU","06","07"))))))) | P36: =P35+IF(AND($H36<>"",OR(LEFT($F36,LEN(SC_TK))=SC_TK,LEFT($G36,LEN(SC_TK))=SC_TK)),1,0)
A37: =IF($H37="","",ROW()-6) | B37: 46203 | C37: PKT003 | D37: 46203 | E37: Phân bổ chi phí thuê văn phòng trả trước (6T đầu năm) | F37: 6427 | G37: 242 | H37: 18000000 | L37: =IF($H37="","",TRIM(IF(COUNTIF(DMTK!$A$7:$A$250,$F37)=0,"TK Nợ sai! ","")&IF(COUNTIF(DMTK!$A$7:$A$250,$G37)=0,"TK Có sai! ","")&IF(N($H37)<=0,"Tiền phải > 0! ","")&IF($B37="","Thiếu ngày! ","")&IF(AND(OR(LEFT($F37,3)="131",LEFT($G37,3)="131",LEFT($F37,3)="331",LEFT($G37,3)="331"),$I37=""),"Thiếu Mã ĐT! ","")&IF(AND($I37<>"",COUNTIF(DM_DT!$A$7:$A$306,$I37)=0),"Mã ĐT chưa khai báo! ",""))) | M37: =IF($H37="","",IF(AND(OR(LEFT($F37,3)="111",LEFT($F37,3)="112",LEFT($F37,3)="113"),OR(LEFT($G37,3)="111",LEFT($G37,3)="112",LEFT($G37,3)="113")),"NB",IF(OR(LEFT($F37,3)="111",LEFT($F37,3)="112",LEFT($F37,3)="113"),"THU",IF(OR(LEFT($G37,3)="111",LEFT($G37,3)="112",LEFT($G37,3)="113"),"CHI","")))) | N37: =IF($M37="THU",$G37,IF($M37="CHI",$F37,"")) | O37: =IF(OR($M37="",$M37="NB"),"",IF($J37<>"",TEXT($J37,"00"),IFERROR(VLOOKUP(LEFT($N37,4),LCTT_MAP!$A$7:$C$66,IF($M37="THU",2,3),FALSE()),IFERROR(VLOOKUP(LEFT($N37,3),LCTT_MAP!$A$7:$C$66,IF($M37="THU",2,3),FALSE()),IFERROR(VLOOKUP(LEFT($N37,2),LCTT_MAP!$A$7:$C$66,IF($M37="THU",2,3),FALSE()),IFERROR(VLOOKUP(LEFT($N37,1),LCTT_MAP!$A$7:$C$66,IF($M37="THU",2,3),FALSE()),IF($M37="THU","06","07"))))))) | P37: =P36+IF(AND($H37<>"",OR(LEFT($F37,LEN(SC_TK))=SC_TK,LEFT($G37,LEN(SC_TK))=SC_TK)),1,0)
A38: =IF($H38="","",ROW()-6) | B38: 46203 | C38: PKT004 | D38: 46203 | E38: Khấu hao TSCĐ quý 2 (gồm xe tải từ tháng 5) | F38: 6424 | G38: 2141 | H38: 23000000 | L38: =IF($H38="","",TRIM(IF(COUNTIF(DMTK!$A$7:$A$250,$F38)=0,"TK Nợ sai! ","")&IF(COUNTIF(DMTK!$A$7:$A$250,$G38)=0,"TK Có sai! ","")&IF(N($H38)<=0,"Tiền phải > 0! ","")&IF($B38="","Thiếu ngày! ","")&IF(AND(OR(LEFT($F38,3)="131",LEFT($G38,3)="131",LEFT($F38,3)="331",LEFT($G38,3)="331"),$I38=""),"Thiếu Mã ĐT! ","")&IF(AND($I38<>"",COUNTIF(DM_DT!$A$7:$A$306,$I38)=0),"Mã ĐT chưa khai báo! ",""))) | M38: =IF($H38="","",IF(AND(OR(LEFT($F38,3)="111",LEFT($F38,3)="112",LEFT($F38,3)="113"),OR(LEFT($G38,3)="111",LEFT($G38,3)="112",LEFT($G38,3)="113")),"NB",IF(OR(LEFT($F38,3)="111",LEFT($F38,3)="112",LEFT($F38,3)="113"),"THU",IF(OR(LEFT($G38,3)="111",LEFT($G38,3)="112",LEFT($G38,3)="113"),"CHI","")))) | N38: =IF($M38="THU",$G38,IF($M38="CHI",$F38,"")) | O38: =IF(OR($M38="",$M38="NB"),"",IF($J38<>"",TEXT($J38,"00"),IFERROR(VLOOKUP(LEFT($N38,4),LCTT_MAP!$A$7:$C$66,IF($M38="THU",2,3),FALSE()),IFERROR(VLOOKUP(LEFT($N38,3),LCTT_MAP!$A$7:$C$66,IF($M38="THU",2,3),FALSE()),IFERROR(VLOOKUP(LEFT($N38,2),LCTT_MAP!$A$7:$C$66,IF($M38="THU",2,3),FALSE()),IFERROR(VLOOKUP(LEFT($N38,1),LCTT_MAP!$A$7:$C$66,IF($M38="THU",2,3),FALSE()),IF($M38="THU","06","07"))))))) | P38: =P37+IF(AND($H38<>"",OR(LEFT($F38,LEN(SC_TK))=SC_TK,LEFT($G38,LEN(SC_TK))=SC_TK)),1,0)
A39: =IF($H39="","",ROW()-6) | B39: 46218 | C39: HD0003 | D39: 46218 | E39: Doanh thu dịch vụ vận chuyển - Cty Bình Minh | F39: 131 | G39: 511 | H39: 120000000 | I39: KH001 | L39: =IF($H39="","",TRIM(IF(COUNTIF(DMTK!$A$7:$A$250,$F39)=0,"TK Nợ sai! ","")&IF(COUNTIF(DMTK!$A$7:$A$250,$G39)=0,"TK Có sai! ","")&IF(N($H39)<=0,"Tiền phải > 0! ","")&IF($B39="","Thiếu ngày! ","")&IF(AND(OR(LEFT($F39,3)="131",LEFT($G39,3)="131",LEFT($F39,3)="331",LEFT($G39,3)="331"),$I39=""),"Thiếu Mã ĐT! ","")&IF(AND($I39<>"",COUNTIF(DM_DT!$A$7:$A$306,$I39)=0),"Mã ĐT chưa khai báo! ",""))) | M39: =IF($H39="","",IF(AND(OR(LEFT($F39,3)="111",LEFT($F39,3)="112",LEFT($F39,3)="113"),OR(LEFT($G39,3)="111",LEFT($G39,3)="112",LEFT($G39,3)="113")),"NB",IF(OR(LEFT($F39,3)="111",LEFT($F39,3)="112",LEFT($F39,3)="113"),"THU",IF(OR(LEFT($G39,3)="111",LEFT($G39,3)="112",LEFT($G39,3)="113"),"CHI","")))) | N39: =IF($M39="THU",$G39,IF($M39="CHI",$F39,"")) | O39: =IF(OR($M39="",$M39="NB"),"",IF($J39<>"",TEXT($J39,"00"),IFERROR(VLOOKUP(LEFT($N39,4),LCTT_MAP!$A$7:$C$66,IF($M39="THU",2,3),FALSE()),IFERROR(VLOOKUP(LEFT($N39,3),LCTT_MAP!$A$7:$C$66,IF($M39="THU",2,3),FALSE()),IFERROR(VLOOKUP(LEFT($N39,2),LCTT_MAP!$A$7:$C$66,IF($M39="THU",2,3),FALSE()),IFERROR(VLOOKUP(LEFT($N39,1),LCTT_MAP!$A$7:$C$66,IF($M39="THU",2,3),FALSE()),IF($M39="THU","06","07"))))))) | P39: =P38+IF(AND($H39<>"",OR(LEFT($F39,LEN(SC_TK))=SC_TK,LEFT($G39,LEN(SC_TK))=SC_TK)),1,0)
A40: =IF($H40="","",ROW()-6) | B40: 46218 | C40: HD0003 | D40: 46218 | E40: Thuế GTGT đầu ra dịch vụ | F40: 131 | G40: 33311 | H40: 9600000 | I40: KH001 | L40: =IF($H40="","",TRIM(IF(COUNTIF(DMTK!$A$7:$A$250,$F40)=0,"TK Nợ sai! ","")&IF(COUNTIF(DMTK!$A$7:$A$250,$G40)=0,"TK Có sai! ","")&IF(N($H40)<=0,"Tiền phải > 0! ","")&IF($B40="","Thiếu ngày! ","")&IF(AND(OR(LEFT($F40,3)="131",LEFT($G40,3)="131",LEFT($F40,3)="331",LEFT($G40,3)="331"),$I40=""),"Thiếu Mã ĐT! ","")&IF(AND($I40<>"",COUNTIF(DM_DT!$A$7:$A$306,$I40)=0),"Mã ĐT chưa khai báo! ",""))) | M40: =IF($H40="","",IF(AND(OR(LEFT($F40,3)="111",LEFT($F40,3)="112",LEFT($F40,3)="113"),OR(LEFT($G40,3)="111",LEFT($G40,3)="112",LEFT($G40,3)="113")),"NB",IF(OR(LEFT($F40,3)="111",LEFT($F40,3)="112",LEFT($F40,3)="113"),"THU",IF(OR(LEFT($G40,3)="111",LEFT($G40,3)="112",LEFT($G40,3)="113"),"CHI","")))) | N40: =IF($M40="THU",$G40,IF($M40="CHI",$F40,"")) | O40: =IF(OR($M40="",$M40="NB"),"",IF($J40<>"",TEXT($J40,"00"),IFERROR(VLOOKUP(LEFT($N40,4),LCTT_MAP!$A$7:$C$66,IF($M40="THU",2,3),FALSE()),IFERROR(VLOOKUP(LEFT($N40,3),LCTT_MAP!$A$7:$C$66,IF($M40="THU",2,3),FALSE()),IFERROR(VLOOKUP(LEFT($N40,2),LCTT_MAP!$A$7:$C$66,IF($M40="THU",2,3),FALSE()),IFERROR(VLOOKUP(LEFT($N40,1),LCTT_MAP!$A$7:$C$66,IF($M40="THU",2,3),FALSE()),IF($M40="THU","06","07"))))))) | P40: =P39+IF(AND($H40<>"",OR(LEFT($F40,LEN(SC_TK))=SC_TK,LEFT($G40,LEN(SC_TK))=SC_TK)),1,0)
A41: =IF($H41="","",ROW()-6) | B41: 46228 | C41: BC004 | D41: 46228 | E41: Thu tiền dịch vụ - Cty Bình Minh | F41: 112 | G41: 131 | H41: 129600000 | I41: KH001 | L41: =IF($H41="","",TRIM(IF(COUNTIF(DMTK!$A$7:$A$250,$F41)=0,"TK Nợ sai! ","")&IF(COUNTIF(DMTK!$A$7:$A$250,$G41)=0,"TK Có sai! ","")&IF(N($H41)<=0,"Tiền phải > 0! ","")&IF($B41="","Thiếu ngày! ","")&IF(AND(OR(LEFT($F41,3)="131",LEFT($G41,3)="131",LEFT($F41,3)="331",LEFT($G41,3)="331"),$I41=""),"Thiếu Mã ĐT! ","")&IF(AND($I41<>"",COUNTIF(DM_DT!$A$7:$A$306,$I41)=0),"Mã ĐT chưa khai báo! ",""))) | M41: =IF($H41="","",IF(AND(OR(LEFT($F41,3)="111",LEFT($F41,3)="112",LEFT($F41,3)="113"),OR(LEFT($G41,3)="111",LEFT($G41,3)="112",LEFT($G41,3)="113")),"NB",IF(OR(LEFT($F41,3)="111",LEFT($F41,3)="112",LEFT($F41,3)="113"),"THU",IF(OR(LEFT($G41,3)="111",LEFT($G41,3)="112",LEFT($G41,3)="113"),"CHI","")))) | N41: =IF($M41="THU",$G41,IF($M41="CHI",$F41,"")) | O41: =IF(OR($M41="",$M41="NB"),"",IF($J41<>"",TEXT($J41,"00"),IFERROR(VLOOKUP(LEFT($N41,4),LCTT_MAP!$A$7:$C$66,IF($M41="THU",2,3),FALSE()),IFERROR(VLOOKUP(LEFT($N41,3),LCTT_MAP!$A$7:$C$66,IF($M41="THU",2,3),FALSE()),IFERROR(VLOOKUP(LEFT($N41,2),LCTT_MAP!$A$7:$C$66,IF($M41="THU",2,3),FALSE()),IFERROR(VLOOKUP(LEFT($N41,1),LCTT_MAP!$A$7:$C$66,IF($M41="THU",2,3),FALSE()),IF($M41="THU","06","07"))))))) | P41: =P40+IF(AND($H41<>"",OR(LEFT($F41,LEN(SC_TK))=SC_TK,LEFT($G41,LEN(SC_TK))=SC_TK)),1,0)
...

Sheet CDPS
A1: =TT_DN!$C$5 | H1: Mẫu số S06-DN
A2: =TT_DN!$C$7 | H2: (Ban hành kèm theo Thông tư số 99/2025/TT-BTC ngày 27/10/2025 của Bộ Tài chính)
A3: BẢNG CÂN ĐỐI SỐ PHÁT SINH
A4: =CONCATENATE("Kỳ: từ ",TEXT(TU_NGAY,"DD/MM/YYYY")," đến ",TEXT(DEN_NGAY,"DD/MM/YYYY")," — Đơn vị tính: Đồng Việt Nam")
A6: Số hiệu TK | B6: Tên tài khoản | C6: Cấp | D6: Số dư đầu kỳ | F6: Số phát sinh trong kỳ | H6: Số dư cuối kỳ
D7: Nợ | E7: Có | F7: Nợ | G7: Có | H7: Nợ | I7: Có | K7: SDĐK Nợ | L7: SDĐK Có | M7: PSNợ trước kỳ | N7: PSCó trước kỳ | O7: PSNợ kỳ | P7: PSCó kỳ | Q7: Net ĐK | R7: uĐK Nợ | S7: uĐK Có | T7: Net CK | U7: uCK Nợ | V7: uCK Có
