Workbook

Sheet HUONG_DAN
A1: BẢNG CHẤM CÔNG TỰ ĐỘNG 2026 – KHỚP NỐI FILE TÍNH LƯƠNG W1 | KK HOME
A2: Bản sạch dùng trên Excel 365. File chấm công theo lưới ngày 1–31 bằng ký hiệu, tự tổng hợp ngày công, ngày nghỉ và giờ làm thêm, rồi kết xuất đúng thứ tự cột của sheet CHAM_CONG_THANG trong file NS06_Bang_Luong_Tu_Dong_2026.xlsx. Hai file dùng chung mã nhân viên và chung thứ tự dòng.
A5: QUY TRÌNH SỬ DỤNG
A6: Bước 1 | B6: THAM_SO_CC | C6: Điền tên đơn vị, Từ ngày – Đến ngày của kỳ, giờ làm việc/ngày, chế độ nghỉ hằng tuần và danh sách ngày lễ, Tết trong kỳ. Ngày công chuẩn để chế độ Theo lịch thì file tự tính.
A7: Bước 2 | B7: KY_HIEU | C7: Xem bộ ký hiệu chấm công. Mỗi ký hiệu khai giá trị ngày cho từng chỉ tiêu, nên có cả ký hiệu nửa ngày làm việc ghép nửa ngày nghỉ. Được thêm ký hiệu mới từ dòng trống.
A8: Bước 3 | B8: DM_NHAN_SU | C8: Khai mã NV, họ tên, bộ phận, chức danh, ngày vào, ngày nghỉ việc. Mã NV phải trùng khít với file lương, không để dòng trống ở giữa.
A9: Bước 4 | B9: BANG_CHAM_CONG | C9: Chấm công lưới ngày 1–31 bằng ký hiệu chọn từ danh sách xổ xuống. Cột ngày nghỉ tuần và ngày lễ tự đổi màu. Bảy cột tổng hợp bên phải tự chạy.
A10: Bước 5 | B10: CC_OT_GIO | C10: Nhập giờ làm thêm và giờ làm ban đêm theo từng ngày. File tự xếp vào OT ngày thường, OT ngày nghỉ tuần hay OT ngày lễ theo danh sách ngày lễ đã khai.
A11: Bước 6 | B11: TONG_HOP_CC | C11: Đối chiếu ngày công, giờ công, giờ OT của từng người và xử lý hết cảnh báo trước khi chốt công.
A12: Bước 7 | B12: XUAT_SANG_LUONG | C12: Copy 3 khối sang file NS06_Bang_Luong_Tu_Dong_2026.xlsx theo đúng ô đích ghi trên đầu mỗi khối. Luôn dán bằng Paste Values.
A13: Bước 8 | B13: BAO_CAO | C13: Xem tổng hợp theo bộ phận và bảng kiểm tra khớp nối. Bảy dòng kiểm tra phải bằng 0 mới phát hành.
A15: CÁCH NỐI VỚI FILE TÍNH LƯƠNG NS06_Bang_Luong_Tu_Dong_2026.xlsx
A16: Khối 0 | B16: DM_NHAN_SU – ô B6 | C16: Copy XUAT_SANG_LUONG cột W:AB (Mã NV → Ngày nghỉ), dán Paste Values vào ô B6 sheet DM_NHAN_SU của file lương. Làm bước này trước để hai file cùng thứ tự dòng.
A17: Khối 1 | B17: CHAM_CONG_THANG – ô D6 | C17: Copy XUAT_SANG_LUONG cột E:N (Nguồn công → OT lễ đêm), dán Paste Values vào ô D6 sheet CHAM_CONG_THANG. Đúng 10 cột D:M.
A18: Khối 2 | B18: CHAM_CONG_THANG – ô AL6 | C18: Copy XUAT_SANG_LUONG cột P:U (Phép năm → Nghỉ không lương), dán Paste Values vào ô AL6 sheet CHAM_CONG_THANG. Đúng 6 cột AL:AQ.
A19: Sau khi dán | B19: Kiểm tra lại | C19: Trên file lương, cột AC:AK và AR:AW phải hiện đúng số vừa dán. Không dán đè lên hai vùng công thức này. Đối chiếu tổng tại BAO_CAO với sheet TONG_HOP của file lương.
A21: QUY ƯỚC MÀU
A22: Ô nhập liệu | C22: Người dùng được sửa | E22: Ô công thức | G22: Không sửa nếu chưa hiểu logic
A23: Cảnh báo | C23: Cần kiểm tra hồ sơ, dữ liệu | E23: Kết quả | G23: Dùng để đối chiếu hoặc kết xuất
A24: Ngày lễ, Tết | C24: Theo danh sách tại THAM_SO_CC | E24: Ngày nghỉ tuần | G24: Theo chế độ nghỉ tuần đã chọn
A26: QUY ƯỚC NGÀY CÔNG VÀ LƯU Ý
A27: Ngày công chuẩn là số ngày phải làm theo lịch doanh nghiệp, không gồm ngày nghỉ hằng tuần và ngày lễ, Tết. Mỗi ngày chỉ chấm một ký hiệu; muốn nửa ngày làm việc ghép nửa ngày nghỉ thì dùng ký hiệu ghép X-P, X-R, X-O, X-KL. Ngày nghỉ hằng tuần mà người lao động vẫn đi làm thì chấm NT trên lưới và nhập số giờ tại CC_OT_GIO, không chấm X, để công làm việc không bị đội lên. Giờ đêm trong ca là phần 22:00–06:00 nằm trong ca bình thường, file chỉ chuyển sang file lương để tính phần trả thêm ban đêm; giờ OT nhập tại CC_OT_GIO là giờ ngoài giờ tiêu chuẩn, không cộng vào công làm việc.
A31: Trước khi chốt lương, phải đối chiếu bảng chấm công với đơn xin nghỉ phép, giấy ra viện, hồ sơ hưởng chế độ BHXH, văn bản thoả thuận làm thêm giờ và giới hạn giờ làm thêm theo Bộ luật Lao động 45/2019/QH14 cùng Nghị định 145/2020/NĐ-CP. File là công cụ kiểm soát, không thay thế hồ sơ gốc và không tự kết luận tính hợp lệ của giờ làm thêm.

Sheet THAM_SO_CC
A1: THAM SỐ KỲ CHẤM CÔNG
A2: Ô vàng là dữ liệu phải điền. Từ ngày – Đến ngày quyết định lưới ngày 1–31 và cách tô màu ngày nghỉ. Danh sách ngày lễ, Tết dùng để tô màu lưới và xếp giờ làm thêm vào nhóm OT ngày lễ.
A5: THÔNG TIN KỲ CHẤM CÔNG | E5: NGÀY LỄ, TẾT VÀ NGÀY NGHỈ HƯỞNG LƯƠNG TRONG KỲ
A6: Tên đơn vị | B6: CÔNG TY … | E6: Nhập ngày lễ, Tết rơi vào kỳ chấm công. Ngày trong danh sách được tô cam trên lưới chấm công, bị trừ khỏi ngày công chuẩn theo lịch, và giờ làm thêm của ngày đó tự xếp vào nhóm OT ngày lễ.
A7: Địa chỉ | B7: Địa chỉ doanh nghiệp
A8: Từ ngày | B8: 46204
A9: Đến ngày | B9: 46234 | E9: STT | F9: Ngày | G9: Nội dung
A10: Ngày công chuẩn nhập tay | B10: 26 | E10: =IF($F10="","",ROW()-9) | F10: 46266 | G10: Ví dụ – xoá nếu không thuộc kỳ
A11: Giờ làm việc/ngày | B11: 8 | E11: =IF($F11="","",ROW()-9) | F11: 46267 | G11: Ví dụ – xoá nếu không thuộc kỳ
A12: Chế độ nghỉ hằng tuần | B12: CN | E12: =IF($F12="","",ROW()-9)
A13: Người chấm công | B13: Họ tên người chấm công | E13: =IF($F13="","",ROW()-9)
A14: Người duyệt | B14: Họ tên người duyệt | E14: =IF($F14="","",ROW()-9)
A15: Ngày cập nhật | B15: 46272 | E15: =IF($F15="","",ROW()-9)
A16: Phiên bản | B16: KK HOME Timesheet 2026.1 – Excel 365 | E16: =IF($F16="","",ROW()-9)
A17: Kỳ chấm công | B17: =IF($B$8="","","Từ "&TEXT($B$8,"dd/mm/yyyy")&" đến "&TEXT($B$9,"dd/mm/yyyy")) | E17: =IF($F17="","",ROW()-9)
A18: Số ngày dương lịch trong kỳ | B18: =IF(OR($B$8="",$B$9=""),"",$B$9-$B$8+1) | E18: =IF($F18="","",ROW()-9)
A19: Ngày công chuẩn theo lịch (tự tính) | B19: =IF(OR($B$8="",$B$9=""),"",SUMPRODUCT(((WEEKDAY(ROW(INDIRECT($B$8&":"&$B$9)),2)<7)*($B$12="CN")+(WEEKDAY(ROW(INDIRECT($B$8&":"&$B$9)),2)<6)*($B$12="T7+CN"))*(COUNTIF($F$10:$F$40,ROW(INDIRECT($B$8&":"&$B$9)))=0))) | E19: =IF($F19="","",ROW()-9)
A20: Cách lấy ngày công chuẩn | B20: Theo lịch | E20: =IF($F20="","",ROW()-9)
A21: Ngày công chuẩn đang áp dụng | B21: =IF($B$20="Nhập tay",$B$10,$B$19) | E21: =IF($F21="","",ROW()-9)
A22: Số ngày lễ, Tết trong kỳ | B22: =IF(OR($B$8="",$B$9=""),"",SUMPRODUCT(($F$10:$F$40>=$B$8)*($F$10:$F$40<=$B$9)*($F$10:$F$40<>""))) | E22: =IF($F22="","",ROW()-9)
E23: =IF($F23="","",ROW()-9)
A24: Hệ số làm thêm giờ, hệ số ban đêm, lương tối thiểu vùng và toàn bộ tham số thuế – bảo hiểm nằm ở sheet THAM_SO của file NS06_Bang_Luong_Tu_Dong_2026.xlsx. File chấm công chỉ đếm ngày và giờ, không tính tiền, để hai file không lệch tham số. | E24: =IF($F24="","",ROW()-9)
E25: =IF($F25="","",ROW()-9)
E26: =IF($F26="","",ROW()-9)
E27: =IF($F27="","",ROW()-9)
E28: =IF($F28="","",ROW()-9)
E29: =IF($F29="","",ROW()-9)
E30: =IF($F30="","",ROW()-9)
E31: =IF($F31="","",ROW()-9)
E32: =IF($F32="","",ROW()-9)
E33: =IF($F33="","",ROW()-9)
E34: =IF($F34="","",ROW()-9)
E35: =IF($F35="","",ROW()-9)
E36: =IF($F36="","",ROW()-9)
... E40: =IF($F40="","",ROW()-9)

Sheet KY_HIEU
A1: BỘ KÝ HIỆU CHẤM CÔNG VÀ GIÁ TRỊ QUY ĐỔI
A2: Bảy cột C:I là số ngày quy đổi của một ô chấm cho từng chỉ tiêu trên bảng lương. Cột J phải bằng 1 với ngày phải làm và bằng 0 với ngày không tính công. Thêm ký hiệu mới từ dòng trống và khai đủ giá trị, phần tổng hợp sẽ tự nhận.
A5: Mã ký hiệu | B5: Diễn giải | C5: Làm việc | D5: Phép năm | E5: Lễ/Tết | F5: Việc riêng | G5: Ốm BHXH | H5: Thai sản | I5: Không lương | J5: Tổng ngày quy đổi | K5: Ghi chú
A6: X | B6: Làm việc đủ ngày | C6: 1 | D6: 0 | E6: 0 | F6: 0 | G6: 0 | H6: 0 | I6: 0 | J6: =IF($A6="","",SUM($C6:$I6))
A7: X/2 | B7: Làm việc nửa ngày, nửa ngày còn lại không chấm | C7: 0.5 | D7: 0 | E7: 0 | F7: 0 | G7: 0 | H7: 0 | I7: 0 | J7: =IF($A7="","",SUM($C7:$I7)) | K7: Dùng khi nửa ngày kia không thuộc ngày phải làm
A8: P | B8: Nghỉ phép năm hưởng lương cả ngày | C8: 0 | D8: 1 | E8: 0 | F8: 0 | G8: 0 | H8: 0 | I8: 0 | J8: =IF($A8="","",SUM($C8:$I8))
A9: P/2 | B9: Nghỉ phép năm nửa ngày | C9: 0 | D9: 0.5 | E9: 0 | F9: 0 | G9: 0 | H9: 0 | I9: 0 | J9: =IF($A9="","",SUM($C9:$I9))
A10: X-P | B10: Nửa ngày làm việc, nửa ngày nghỉ phép năm | C10: 0.5 | D10: 0.5 | E10: 0 | F10: 0 | G10: 0 | H10: 0 | I10: 0 | J10: =IF($A10="","",SUM($C10:$I10)) | K10: Ký hiệu ghép
A11: L | B11: Nghỉ lễ, Tết hưởng nguyên lương | C11: 0 | D11: 0 | E11: 1 | F11: 0 | G11: 0 | H11: 0 | I11: 0 | J11: =IF($A11="","",SUM($C11:$I11)) | K11: Không nằm trong ngày công chuẩn
A12: R | B12: Nghỉ việc riêng hưởng lương cả ngày | C12: 0 | D12: 0 | E12: 0 | F12: 1 | G12: 0 | H12: 0 | I12: 0 | J12: =IF($A12="","",SUM($C12:$I12)) | K12: Kết hôn, con kết hôn, tang chế
A13: R/2 | B13: Nghỉ việc riêng hưởng lương nửa ngày | C13: 0 | D13: 0 | E13: 0 | F13: 0.5 | G13: 0 | H13: 0 | I13: 0 | J13: =IF($A13="","",SUM($C13:$I13))
A14: X-R | B14: Nửa ngày làm việc, nửa ngày việc riêng | C14: 0.5 | D14: 0 | E14: 0 | F14: 0.5 | G14: 0 | H14: 0 | I14: 0 | J14: =IF($A14="","",SUM($C14:$I14)) | K14: Ký hiệu ghép
A15: O | B15: Nghỉ ốm hưởng chế độ BHXH | C15: 0 | D15: 0 | E15: 0 | F15: 0 | G15: 1 | H15: 0 | I15: 0 | J15: =IF($A15="","",SUM($C15:$I15)) | K15: Cần giấy ra viện, giấy nghỉ hưởng BHXH
A16: CO | B16: Nghỉ chăm con ốm hưởng chế độ BHXH | C16: 0 | D16: 0 | E16: 0 | F16: 0 | G16: 1 | H16: 0 | I16: 0 | J16: =IF($A16="","",SUM($C16:$I16))
A17: DS | B17: Nghỉ dưỡng sức, phục hồi sức khoẻ | C17: 0 | D17: 0 | E17: 0 | F17: 0 | G17: 1 | H17: 0 | I17: 0 | J17: =IF($A17="","",SUM($C17:$I17))
A18: X-O | B18: Nửa ngày làm việc, nửa ngày nghỉ ốm | C18: 0.5 | D18: 0 | E18: 0 | F18: 0 | G18: 0.5 | H18: 0 | I18: 0 | J18: =IF($A18="","",SUM($C18:$I18)) | K18: Ký hiệu ghép
A19: TS | B19: Nghỉ thai sản hưởng chế độ BHXH | C19: 0 | D19: 0 | E19: 0 | F19: 0 | G19: 0 | H19: 1 | I19: 0 | J19: =IF($A19="","",SUM($C19:$I19))
A20: KCT | B20: Nghỉ khám thai hưởng chế độ BHXH | C20: 0 | D20: 0 | E20: 0 | F20: 0 | G20: 0 | H20: 1 | I20: 0 | J20: =IF($A20="","",SUM($C20:$I20))
A21: KL | B21: Nghỉ không hưởng lương, có xin phép | C21: 0 | D21: 0 | E21: 0 | F21: 0 | G21: 0 | H21: 0 | I21: 1 | J21: =IF($A21="","",SUM($C21:$I21))
A22: KL/2 | B22: Nghỉ không hưởng lương nửa ngày | C22: 0 | D22: 0 | E22: 0 | F22: 0 | G22: 0 | H22: 0 | I22: 0.5 | J22: =IF($A22="","",SUM($C22:$I22))
A23: X-KL | B23: Nửa ngày làm việc, nửa ngày không lương | C23: 0.5 | D23: 0 | E23: 0 | F23: 0 | G23: 0 | H23: 0 | I23: 0.5 | J23: =IF($A23="","",SUM($C23:$I23)) | K23: Ký hiệu ghép
A24: NN | B24: Nghỉ không phép, không hưởng lương | C24: 0 | D24: 0 | E24: 0 | F24: 0 | G24: 0 | H24: 0 | I24: 1 | J24: =IF($A24="","",SUM($C24:$I24)) | K24: Rà soát xử lý kỷ luật lao động
A25: NT | B25: Ngày nghỉ hằng tuần theo lịch | C25: 0 | D25: 0 | E25: 0 | F25: 0 | G25: 0 | H25: 0 | I25: 0 | J25: =IF($A25="","",SUM($C25:$I25)) | K25: Đi làm ngày này thì nhập giờ tại CC_OT_GIO
A26: TN | B26: Nghỉ do tai nạn lao động, bệnh nghề nghiệp | C26: 0 | D26: 0 | E26: 0 | F26: 0 | G26: 0 | H26: 0 | I26: 0 | J26: =IF($A26="","",SUM($C26:$I26)) | K26: Khai riêng tại CHE_DO_BHXH của file lương
A27: NV | B27: Chưa vào làm hoặc đã nghỉ việc | C27: 0 | D27: 0 | E27: 0 | F27: 0 | G27: 0 | H27: 0 | I27: 0 | J27: =IF($A27="","",SUM($C27:$I27))
J28: =IF($A28="","",SUM($C28:$I28))
J29: =IF($A29="","",SUM($C29:$I29))
J30: =IF($A30="","",SUM($C30:$I30))
J31: =IF($A31="","",SUM($C31:$I31))
J32: =IF($A32="","",SUM($C32:$I32))
J33: =IF($A33="","",SUM($C33:$I33))
J34: =IF($A34="","",SUM($C34:$I34))
J35: =IF($A35="","",SUM($C35:$I35))
J36: =IF($A36="","",SUM($C36:$I36))
J37: =IF($A37="","",SUM($C37:$I37))
J38: =IF($A38="","",SUM($C38:$I38))
J39: =IF($A39="","",SUM($C39:$I39))
... J45: =IF($A45="","",SUM($C45:$I45))

Sheet DM_NHAN_SU
A1: DANH MỤC NHÂN SỰ CHẤM CÔNG
A2: Nhập một dòng cho mỗi nhân viên, không để dòng trống ở giữa. Mã NV phải trùng khít với sheet DM_NHAN_SU của file NS06_Bang_Luong_Tu_Dong_2026.xlsx – dùng khối W:AB tại sheet XUAT_SANG_LUONG để dán danh sách này sang file lương, hai file sẽ cùng thứ tự dòng. Cột H, I chỉ điền khi người này khác mặt bằng chung của đơn vị.
A5: STT | B5: Mã NV | C5: Họ và tên | D5: Bộ phận | E5: Chức danh | F5: Ngày vào | G5: Ngày nghỉ việc | H5: Giờ/ngày riêng | I5: Ngày công chuẩn riêng | J5: Ghi chú
A6: =IF($B6="","",ROW()-5)
A7: =IF($B7="","",ROW()-5)
A8: =IF($B8="","",ROW()-5)
A9: =IF($B9="","",ROW()-5)
A10: =IF($B10="","",ROW()-5)
A11: =IF($B11="","",ROW()-5)
A12: =IF($B12="","",ROW()-5)
A13: =IF($B13="","",ROW()-5)
A14: =IF($B14="","",ROW()-5)
A15: =IF($B15="","",ROW()-5)
A16: =IF($B16="","",ROW()-5)
A17: =IF($B17="","",ROW()-5)
... A155: =IF($B155="","",ROW()-5)

Sheet BANG_CHAM_CONG
A1: BẢNG CHẤM CÔNG THÁNG – LƯỚI NGÀY 1 ĐẾN 31
A2: Mỗi ngày chỉ chấm một ký hiệu, chọn từ danh sách xổ xuống. Cột xanh nhạt là ngày nghỉ hằng tuần, cột cam là ngày lễ – Tết, cột xám đậm là ngày không thuộc kỳ. Nửa ngày làm việc ghép nửa ngày nghỉ thì dùng ký hiệu ghép X-P, X-R, X-O, X-KL. Bảy cột tổng hợp bên phải chạy theo sheet KY_HIEU, không sửa.
A4: Thứ trong tuần → | F4: =IF(THAM_SO_CC!$B$8+0>THAM_SO_CC!$B$9,"",CHOOSE(WEEKDAY(THAM_SO_CC!$B$8+0,2),"T2","T3","T4","T5","T6","T7","CN")) | G4: =IF(THAM_SO_CC!$B$8+1>THAM_SO_CC!$B$9,"",CHOOSE(WEEKDAY(THAM_SO_CC!$B$8+1,2),"T2","T3","T4","T5","T6","T7","CN")) | H4: =IF(THAM_SO_CC!$B$8+2>THAM_SO_CC!$B$9,"",CHOOSE(WEEKDAY(THAM_SO_CC!$B$8+2,2),"T2","T3","T4","T5","T6","T7","CN")) | I4: =IF(THAM_SO_CC!$B$8+3>THAM_SO_CC!$B$9,"",CHOOSE(WEEKDAY(THAM_SO_CC!$B$8+3,2),"T2","T3","T4","T5","T6","T7","CN")) | J4: =IF(THAM_SO_CC!$B$8+4>THAM_SO_CC!$B$9,"",CHOOSE(WEEKDAY(THAM_SO_CC!$B$8+4,2),"T2","T3","T4","T5","T6","T7","CN")) | K4: =IF(THAM_SO_CC!$B$8+5>THAM_SO_CC!$B$9,"",CHOOSE(WEEKDAY(THAM_SO_CC!$B$8+5,2),"T2","T3","T4","T5","T6","T7","CN")) | L4: =IF(THAM_SO_CC!$B$8+6>THAM_SO_CC!$B$9,"",CHOOSE(WEEKDAY(THAM_SO_CC!$B$8+6,2),"T2","T3","T4","T5","T6","T7","CN")) | M4: =IF(THAM_SO_CC!$B$8+7>THAM_SO_CC!$B$9,"",CHOOSE(WEEKDAY(THAM_SO_CC!$B$8+7,2),"T2","T3","T4","T5","T6","T7","CN")) | N4: =IF(THAM_SO_CC!$B$8+8>THAM_SO_CC!$B$9,"",CHOOSE(WEEKDAY(THAM_SO_CC!$B$8+8,2),"T2","T3","T4","T5","T6","T7","CN")) | O4: =IF(THAM_SO_CC!$B$8+9>THAM_SO_CC!$B$9,"",CHOOSE(WEEKDAY(THAM_SO_CC!$B$8+9,2),"T2","T3","T4","T5","T6","T7","CN")) | P4: =IF(THAM_SO_CC!$B$8+10>THAM_SO_CC!$B$9,"",CHOOSE(WEEKDAY(THAM_SO_CC!$B$8+10,2),"T2","T3","T4","T5","T6","T7","CN")) | Q4: =IF(THAM_SO_CC!$B$8+11>THAM_SO_CC!$B$9,"",CHOOSE(WEEKDAY(THAM_SO_CC!$B$8+11,2),"T2","T3","T4","T5","T6","T7","CN")) | R4: =IF(THAM_SO_CC!$B$8+12>THAM_SO_CC!$B$9,"",CHOOSE(WEEKDAY(THAM_SO_CC!$B$8+12,2),"T2","T3","T4","T5","T6","T7","CN")) | S4: =IF(THAM_SO_CC!$B$8+13>THAM_SO_CC!$B$9,"",CHOOSE(WEEKDAY(THAM_SO_CC!$B$8+13,2),"T2","T3","T4","T5","T6","T7","CN")) | T4: =IF(THAM_SO_CC!$B$8+14>THAM_SO_CC!$B$9,"",CHOOSE(WEEKDAY(THAM_SO_CC!$B$8+14,2),"T2","T3","T4","T5","T6","T7","CN")) | U4: =IF(THAM_SO_CC!$B$8+15>THAM_SO_CC!$B$9,"",CHOOSE(WEEKDAY(THAM_SO_CC!$B$8+15,2),"T2","T3","T4","T5","T6","T7","CN")) | V4: =IF(THAM_SO_CC!$B$8+16>THAM_SO_CC!$B$9,"",CHOOSE(WEEKDAY(THAM_SO_CC!$B$8+16,2),"T2","T3","T4","T5","T6","T7","CN")) | W4: =IF(THAM_SO_CC!$B$8+17>THAM_SO_CC!$B$9,"",CHOOSE(WEEKDAY(THAM_SO_CC!$B$8+17,2),"T2","T3","T4","T5","T6","T7","CN")) | X4: =IF(THAM_SO_CC!$B$8+18>THAM_SO_CC!$B$9,"",CHOOSE(WEEKDAY(THAM_SO_CC!$B$8+18,2),"T2","T3","T4","T5","T6","T7","CN")) | Y4: =IF(THAM_SO_CC!$B$8+19>THAM_SO_CC!$B$9,"",CHOOSE(WEEKDAY(THAM_SO_CC!$B$8+19,2),"T2","T3","T4","T5","T6","T7","CN")) | Z4: =IF(THAM_SO_CC!$B$8+20>THAM_SO_CC!$B$9,"",CHOOSE(WEEKDAY(THAM_SO_CC!$B$8+20,2),"T2","T3","T4","T5","T6","T7","CN")) | AA4: =IF(THAM_SO_CC!$B$8+21>THAM_SO_CC!$B$9,"",CHOOSE(WEEKDAY(THAM_SO_CC!$B$8+21,2),"T2","T3","T4","T5","T6","T7","CN")) | AB4: =IF(THAM_SO_CC!$B$8+22>THAM_SO_CC!$B$9,"",CHOOSE(WEEKDAY(THAM_SO_CC!$B$8+22,2),"T2","T3","T4","T5","T6","T7","CN")) | AC4: =IF(THAM_SO_CC!$B$8+23>THAM_SO_CC!$B$9,"",CHOOSE(WEEKDAY(THAM_SO_CC!$B$8+23,2),"T2","T3","T4","T5","T6","T7","CN")) | AD4: =IF(THAM_SO_CC!$B$8+24>THAM_SO_CC!$B$9,"",CHOOSE(WEEKDAY(THAM_SO_CC!$B$8+24,2),"T2","T3","T4","T5","T6","T7","CN")) | AE4: =IF(THAM_SO_CC!$B$8+25>THAM_SO_CC!$B$9,"",CHOOSE(WEEKDAY(THAM_SO_CC!$B$8+25,2),"T2","T3","T4","T5","T6","T7","CN")) | AF4: =IF(THAM_SO_CC!$B$8+26>THAM_SO_CC!$B$9,"",CHOOSE(WEEKDAY(THAM_SO_CC!$B$8+26,2),"T2","T3","T4","T5","T6","T7","CN")) | AG4: =IF(THAM_SO_CC!$B$8+27>THAM_SO_CC!$B$9,"",CHOOSE(WEEKDAY(THAM_SO_CC!$B$8+27,2),"T2","T3","T4","T5","T6","T7","CN")) | AH4: =IF(THAM_SO_CC!$B$8+28>THAM_SO_CC!$B$9,"",CHOOSE(WEEKDAY(THAM_SO_CC!$B$8+28,2),"T2","T3","T4","T5","T6","T7","CN")) | AI4: =IF(THAM_SO_CC!$B$8+29>THAM_SO_CC!$B$9,"",CHOOSE(WEEKDAY(THAM_SO_CC!$B$8+29,2),"T2","T3","T4","T5","T6","T7","CN")) | AJ4: =IF(THAM_SO_CC!$B$8+30>THAM_SO_CC!$B$9,"",CHOOSE(WEEKDAY(THAM_SO_CC!$B$8+30,2),"T2","T3","T4","T5","T6","T7","CN")) | AK4: Làm việc | AL4: Phép năm | AM4: Lễ/Tết | AN4: Việc riêng | AO4: Ốm BHXH | AP4: Thai sản | AQ4: Không lương
A5: STT | B5: Mã NV | C5: Họ và tên | D5: Bộ phận | E5: Chức danh | F5: =IF(THAM_SO_CC!$B$8+0>THAM_SO_CC!$B$9,"",DAY(THAM_SO_CC!$B$8+0)) | G5: =IF(THAM_SO_CC!$B$8+1>THAM_SO_CC!$B$9,"",DAY(THAM_SO_CC!$B$8+1)) | H5: =IF(THAM_SO_CC!$B$8+2>THAM_SO_CC!$B$9,"",DAY(THAM_SO_CC!$B$8+2)) | I5: =IF(THAM_SO_CC!$B$8+3>THAM_SO_CC!$B$9,"",DAY(THAM_SO_CC!$B$8+3)) | J5: =IF(THAM_SO_CC!$B$8+4>THAM_SO_CC!$B$9,"",DAY(THAM_SO_CC!$B$8+4)) | K5: =IF(THAM_SO_CC!$B$8+5>THAM_SO_CC!$B$9,"",DAY(THAM_SO_CC!$B$8+5)) | L5: =IF(THAM_SO_CC!$B$8+6>THAM_SO_CC!$B$9,"",DAY(THAM_SO_CC!$B$8+6)) | M5: =IF(THAM_SO_CC!$B$8+7>THAM_SO_CC!$B$9,"",DAY(THAM_SO_CC!$B$8+7)) | N5: =IF(THAM_SO_CC!$B$8+8>THAM_SO_CC!$B$9,"",DAY(THAM_SO_CC!$B$8+8)) | O5: =IF(THAM_SO_CC!$B$8+9>THAM_SO_CC!$B$9,"",DAY(THAM_SO_CC!$B$8+9)) | P5: =IF(THAM_SO_CC!$B$8+10>THAM_SO_CC!$B$9,"",DAY(THAM_SO_CC!$B$8+10)) | Q5: =IF(THAM_SO_CC!$B$8+11>THAM_SO_CC!$B$9,"",DAY(THAM_SO_CC!$B$8+11)) | R5: =IF(THAM_SO_CC!$B$8+12>THAM_SO_CC!$B$9,"",DAY(THAM_SO_CC!$B$8+12)) | S5: =IF(THAM_SO_CC!$B$8+13>THAM_SO_CC!$B$9,"",DAY(THAM_SO_CC!$B$8+13)) | T5: =IF(THAM_SO_CC!$B$8+14>THAM_SO_CC!$B$9,"",DAY(THAM_SO_CC!$B$8+14)) | U5: =IF(THAM_SO_CC!$B$8+15>THAM_SO_CC!$B$9,"",DAY(THAM_SO_CC!$B$8+15)) | V5: =IF(THAM_SO_CC!$B$8+16>THAM_SO_CC!$B$9,"",DAY(THAM_SO_CC!$B$8+16)) | W5: =IF(THAM_SO_CC!$B$8+17>THAM_SO_CC!$B$9,"",DAY(THAM_SO_CC!$B$8+17)) | X5: =IF(THAM_SO_CC!$B$8+18>THAM_SO_CC!$B$9,"",DAY(THAM_SO_CC!$B$8+18)) | Y5: =IF(THAM_SO_CC!$B$8+19>THAM_SO_CC!$B$9,"",DAY(THAM_SO_CC!$B$8+19)) | Z5: =IF(THAM_SO_CC!$B$8+20>THAM_SO_CC!$B$9,"",DAY(THAM_SO_CC!$B$8+20)) | AA5: =IF(THAM_SO_CC!$B$8+21>THAM_SO_CC!$B$9,"",DAY(THAM_SO_CC!$B$8+21)) | AB5: =IF(THAM_SO_CC!$B$8+22>THAM_SO_CC!$B$9,"",DAY(THAM_SO_CC!$B$8+22)) | AC5: =IF(THAM_SO_CC!$B$8+23>THAM_SO_CC!$B$9,"",DAY(THAM_SO_CC!$B$8+23)) | AD5: =IF(THAM_SO_CC!$B$8+24>THAM_SO_CC!$B$9,"",DAY(THAM_SO_CC!$B$8+24)) | AE5: =IF(THAM_SO_CC!$B$8+25>THAM_SO_CC!$B$9,"",DAY(THAM_SO_CC!$B$8+25)) | AF5: =IF(THAM_SO_CC!$B$8+26>THAM_SO_CC!$B$9,"",DAY(THAM_SO_CC!$B$8+26)) | AG5: =IF(THAM_SO_CC!$B$8+27>THAM_SO_CC!$B$9,"",DAY(THAM_SO_CC!$B$8+27)) | AH5: =IF(THAM_SO_CC!$B$8+28>THAM_SO_CC!$B$9,"",DAY(THAM_SO_CC!$B$8+28)) | AI5: =IF(THAM_SO_CC!$B$8+29>THAM_SO_CC!$B$9,"",DAY(THAM_SO_CC!$B$8+29)) | AJ5: =IF(THAM_SO_CC!$B$8+30>THAM_SO_CC!$B$9,"",DAY(THAM_SO_CC!$B$8+30)) | AK5: Công làm việc | AL5: Phép năm hưởng lương | AM5: Lễ/Tết hưởng lương | AN5: Việc riêng hưởng lương | AO5: Nghỉ ốm hưởng BHXH | AP5: Nghỉ thai sản | AQ5: Nghỉ không lương | AR5: Tổng ngày phải làm đã chấm | AS5: Ngày công chuẩn kỳ | AT5: Chênh lệch | AU5: Cảnh báo
A6: =IF($B6="","",ROW()-5) | B6: =IF(DM_NHAN_SU!B6="","",DM_NHAN_SU!B6) | C6: =IF($B6="","",DM_NHAN_SU!C6) | D6: =IF($B6="","",DM_NHAN_SU!D6) | E6: =IF($B6="","",DM_NHAN_SU!E6) | AK6: =IF($B6="","",SUMPRODUCT(COUNTIF($F6:$AJ6,KY_HIEU!$A$6:$A$45)*KY_HIEU!$C$6:$C$45)) | AL6: =IF($B6="","",SUMPRODUCT(COUNTIF($F6:$AJ6,KY_HIEU!$A$6:$A$45)*KY_HIEU!$D$6:$D$45)) | AM6: =IF($B6="","",SUMPRODUCT(COUNTIF($F6:$AJ6,KY_HIEU!$A$6:$A$45)*KY_HIEU!$E$6:$E$45)) | AN6: =IF($B6="","",SUMPRODUCT(COUNTIF($F6:$AJ6,KY_HIEU!$A$6:$A$45)*KY_HIEU!$F$6:$F$45)) | AO6: =IF($B6="","",SUMPRODUCT(COUNTIF($F6:$AJ6,KY_HIEU!$A$6:$A$45)*KY_HIEU!$G$6:$G$45)) | AP6: =IF($B6="","",SUMPRODUCT(COUNTIF($F6:$AJ6,KY_HIEU!$A$6:$A$45)*KY_HIEU!$H$6:$H$45)) | AQ6: =IF($B6="","",SUMPRODUCT(COUNTIF($F6:$AJ6,KY_HIEU!$A$6:$A$45)*KY_HIEU!$I$6:$I$45)) | AR6: =IF($B6="","",$AK6+$AL6+$AN6+$AO6+$AP6+$AQ6) | AS6: =IF($B6="","",IF(DM_NHAN_SU!$I6<>"",DM_NHAN_SU!$I6,IF(THAM_SO_CC!$B$20="Nhập tay",THAM_SO_CC!$B$10,SUMPRODUCT(((WEEKDAY(ROW(INDIRECT(THAM_SO_CC!$B$8&":"&THAM_SO_CC!$B$9)),2)<7)*(THAM_SO_CC!$B$12="CN")+(WEEKDAY(ROW(INDIRECT(THAM_SO_CC!$B$8&":"&THAM_SO_CC!$B$9)),2)<6)*(THAM_SO_CC!$B$12="T7+CN"))*(COUNTIF(THAM_SO_CC!$F$10:$F$40,ROW(INDIRECT(THAM_SO_CC!$B$8&":"&THAM_SO_CC!$B$9)))=0)*(ROW(INDIRECT(THAM_SO_CC!$B$8&":"&THAM_SO_CC!$B$9))>=IF(DM_NHAN_SU!$F6="",THAM_SO_CC!$B$8,DM_NHAN_SU!$F6))*(ROW(INDIRECT(THAM_SO_CC!$B$8&":"&THAM_SO_CC!$B$9))<=IF(DM_NHAN_SU!$G6="",THAM_SO_CC!$B$9,DM_NHAN_SU!$G6)))))) | AT6: =IF($B6="","",$AR6-$AS6) | AU6: =IF($B6="","",TRIM(IF(SUMPRODUCT(--($F6:$AJ6<>""))-SUMPRODUCT(COUNTIF($F6:$AJ6,KY_HIEU!$A$6:$A$45))>0,"Ký hiệu lạ; ","")&IF(ROUND($AT6,2)<>0,"Lệch ngày công "&TEXT($AT6,"0.0")&"; ","")&IF(SUMPRODUCT(--($F6:$AJ6<>""),--((THAM_SO_CC!$B$8+COLUMN($F$1:$AJ$1)-6)>THAM_SO_CC!$B$9))>0,"Chấm ngoài kỳ; ","")&IF(AND(DM_NHAN_SU!$F6<>"",SUMPRODUCT(--($F6:$AJ6<>""),--($F6:$AJ6<>"NV"),--($F6:$AJ6<>"NT"),--($F6:$AJ6<>"TN"),--((THAM_SO_CC!$B$8+COLUMN($F$1:$AJ$1)-6)<DM_NHAN_SU!$F6))>0),"Chấm trước ngày vào; ","")&IF(AND(DM_NHAN_SU!$G6<>"",SUMPRODUCT(--($F6:$AJ6<>""),--($F6:$AJ6<>"NV"),--($F6:$AJ6<>"NT"),--($F6:$AJ6<>"TN"),--((THAM_SO_CC!$B$8+COLUMN($F$1:$AJ$1)-6)>DM_NHAN_SU!$G6))>0),"Chấm sau ngày nghỉ việc; ","")))
A7: =IF($B7="","",ROW()-5) | B7: =IF(DM_NHAN_SU!B7="","",DM_NHAN_SU!B7) | C7: =IF($B7="","",DM_NHAN_SU!C7) | D7: =IF($B7="","",DM_NHAN_SU!D7) | E7: =IF($B7="","",DM_NHAN_SU!E7) | AK7: =IF($B7="","",SUMPRODUCT(COUNTIF($F7:$AJ7,KY_HIEU!$A$6:$A$45)*KY_HIEU!$C$6:$C$45)) | AL7: =IF($B7="","",SUMPRODUCT(COUNTIF($F7:$AJ7,KY_HIEU!$A$6:$A$45)*KY_HIEU!$D$6:$D$45)) | AM7: =IF($B7="","",SUMPRODUCT(COUNTIF($F7:$AJ7,KY_HIEU!$A$6:$A$45)*KY_HIEU!$E$6:$E$45)) | AN7: =IF($B7="","",SUMPRODUCT(COUNTIF($F7:$AJ7,KY_HIEU!$A$6:$A$45)*KY_HIEU!$F$6:$F$45)) | AO7: =IF($B7="","",SUMPRODUCT(COUNTIF($F7:$AJ7,KY_HIEU!$A$6:$A$45)*KY_HIEU!$G$6:$G$45)) | AP7: =IF($B7="","",SUMPRODUCT(COUNTIF($F7:$AJ7,KY_HIEU!$A$6:$A$45)*KY_HIEU!$H$6:$H$45)) | AQ7: =IF($B7="","",SUMPRODUCT(COUNTIF($F7:$AJ7,KY_HIEU!$A$6:$A$45)*KY_HIEU!$I$6:$I$45)) | AR7: =IF($B7="","",$AK7+$AL7+$AN7+$AO7+$AP7+$AQ7) | AS7: =IF($B7="","",IF(DM_NHAN_SU!$I7<>"",DM_NHAN_SU!$I7,IF(THAM_SO_CC!$B$20="Nhập tay",THAM_SO_CC!$B$10,SUMPRODUCT(((WEEKDAY(ROW(INDIRECT(THAM_SO_CC!$B$8&":"&THAM_SO_CC!$B$9)),2)<7)*(THAM_SO_CC!$B$12="CN")+(WEEKDAY(ROW(INDIRECT(THAM_SO_CC!$B$8&":"&THAM_SO_CC!$B$9)),2)<6)*(THAM_SO_CC!$B$12="T7+CN"))*(COUNTIF(THAM_SO_CC!$F$10:$F$40,ROW(INDIRECT(THAM_SO_CC!$B$8&":"&THAM_SO_CC!$B$9)))=0)*(ROW(INDIRECT(THAM_SO_CC!$B$8&":"&THAM_SO_CC!$B$9))>=IF(DM_NHAN_SU!$F7="",THAM_SO_CC!$B$8,DM_NHAN_SU!$F7))*(ROW(INDIRECT(THAM_SO_CC!$B$8&":"&THAM_SO_CC!$B$9))<=IF(DM_NHAN_SU!$G7="",THAM_SO_CC!$B$9,DM_NHAN_SU!$G7)))))) | AT7: =IF($B7="","",$AR7-$AS7) | AU7: =IF($B7="","",TRIM(IF(SUMPRODUCT(--($F7:$AJ7<>""))-SUMPRODUCT(COUNTIF($F7:$AJ7,KY_HIEU!$A$6:$A$45))>0,"Ký hiệu lạ; ","")&IF(ROUND($AT7,2)<>0,"Lệch ngày công "&TEXT($AT7,"0.0")&"; ","")&IF(SUMPRODUCT(--($F7:$AJ7<>""),--((THAM_SO_CC!$B$8+COLUMN($F$1:$AJ$1)-6)>THAM_SO_CC!$B$9))>0,"Chấm ngoài kỳ; ","")&IF(AND(DM_NHAN_SU!$F7<>"",SUMPRODUCT(--($F7:$AJ7<>""),--($F7:$AJ7<>"NV"),--($F7:$AJ7<>"NT"),--($F7:$AJ7<>"TN"),--((THAM_SO_CC!$B$8+COLUMN($F$1:$AJ$1)-6)<DM_NHAN_SU!$F7))>0),"Chấm trước ngày vào; ","")&IF(AND(DM_NHAN_SU!$G7<>"",SUMPRODUCT(--($F7:$AJ7<>""),--($F7:$AJ7<>"NV"),--($F7:$AJ7<>"NT"),--($F7:$AJ7<>"TN"),--((THAM_SO_CC!$B$8+COLUMN($F$1:$AJ$1)-6)>DM_NHAN_SU!$G7))>0),"Chấm sau ngày nghỉ việc; ","")))
A8: =IF($B8="","",ROW()-5) | B8: =IF(DM_NHAN_SU!B8="","",DM_NHAN_SU!B8) | C8: =IF($B8="","",DM_NHAN_SU!C8) | D8: =IF($B8="","",DM_NHAN_SU!D8) | E8: =IF($B8="","",DM_NHAN_SU!E8) | AK8: =IF($B8="","",SUMPRODUCT(COUNTIF($F8:$AJ8,KY_HIEU!$A$6:$A$45)*KY_HIEU!$C$6:$C$45)) | AL8: =IF($B8="","",SUMPRODUCT(COUNTIF($F8:$AJ8,KY_HIEU!$A$6:$A$45)*KY_HIEU!$D$6:$D$45)) | AM8: =IF($B8="","",SUMPRODUCT(COUNTIF($F8:$AJ8,KY_HIEU!$A$6:$A$45)*KY_HIEU!$E$6:$E$45)) | AN8: =IF($B8="","",SUMPRODUCT(COUNTIF($F8:$AJ8,KY_HIEU!$A$6:$A$45)*KY_HIEU!$F$6:$F$45)) | AO8: =IF($B8="","",SUMPRODUCT(COUNTIF($F8:$AJ8,KY_HIEU!$A$6:$A$45)*KY_HIEU!$G$6:$G$45)) | AP8: =IF($B8="","",SUMPRODUCT(COUNTIF($F8:$AJ8,KY_HIEU!$A$6:$A$45)*KY_HIEU!$H$6:$H$45)) | AQ8: =IF($B8="","",SUMPRODUCT(COUNTIF($F8:$AJ8,KY_HIEU!$A$6:$A$45)*KY_HIEU!$I$6:$I$45)) | AR8: =IF($B8="","",$AK8+$AL8+$AN8+$AO8+$AP8+$AQ8) | AS8: =IF($B8="","",IF(DM_NHAN_SU!$I8<>"",DM_NHAN_SU!$I8,IF(THAM_SO_CC!$B$20="Nhập tay",THAM_SO_CC!$B$10,SUMPRODUCT(((WEEKDAY(ROW(INDIRECT(THAM_SO_CC!$B$8&":"&THAM_SO_CC!$B$9)),2)<7)*(THAM_SO_CC!$B$12="CN")+(WEEKDAY(ROW(INDIRECT(THAM_SO_CC!$B$8&":"&THAM_SO_CC!$B$9)),2)<6)*(THAM_SO_CC!$B$12="T7+CN"))*(COUNTIF(THAM_SO_CC!$F$10:$F$40,ROW(INDIRECT(THAM_SO_CC!$B$8&":"&THAM_SO_CC!$B$9)))=0)*(ROW(INDIRECT(THAM_SO_CC!$B$8&":"&THAM_SO_CC!$B$9))>=IF(DM_NHAN_SU!$F8="",THAM_SO_CC!$B$8,DM_NHAN_SU!$F8))*(ROW(INDIRECT(THAM_SO_CC!$B$8&":"&THAM_SO_CC!$B$9))<=IF(DM_NHAN_SU!$G8="",THAM_SO_CC!$B$9,DM_NHAN_SU!$G8)))))) | AT8: =IF($B8="","",$AR8-$AS8) | AU8: =IF($B8="","",TRIM(IF(SUMPRODUCT(--($F8:$AJ8<>""))-SUMPRODUCT(COUNTIF($F8:$AJ8,KY_HIEU!$A$6:$A$45))>0,"Ký hiệu lạ; ","")&IF(ROUND($AT8,2)<>0,"Lệch ngày công "&TEXT($AT8,"0.0")&"; ","")&IF(SUMPRODUCT(--($F8:$AJ8<>""),--((THAM_SO_CC!$B$8+COLUMN($F$1:$AJ$1)-6)>THAM_SO_CC!$B$9))>0,"Chấm ngoài kỳ; ","")&IF(AND(DM_NHAN_SU!$F8<>"",SUMPRODUCT(--($F8:$AJ8<>""),--($F8:$AJ8<>"NV"),--($F8:$AJ8<>"NT"),--($F8:$AJ8<>"TN"),--((THAM_SO_CC!$B$8+COLUMN($F$1:$AJ$1)-6)<DM_NHAN_SU!$F8))>0),"Chấm trước ngày vào; ","")&IF(AND(DM_NHAN_SU!$G8<>"",SUMPRODUCT(--($F8:$AJ8<>""),--($F8:$AJ8<>"NV"),--($F8:$AJ8<>"NT"),--($F8:$AJ8<>"TN"),--((THAM_SO_CC!$B$8+COLUMN($F$1:$AJ$1)-6)>DM_NHAN_SU!$G8))>0),"Chấm sau ngày nghỉ việc; ","")))
A9: =IF($B9="","",ROW()-5) | B9: =IF(DM_NHAN_SU!B9="","",DM_NHAN_SU!B9) | C9: =IF($B9="","",DM_NHAN_SU!C9) | D9: =IF($B9="","",DM_NHAN_SU!D9) | E9: =IF($B9="","",DM_NHAN_SU!E9) | AK9: =IF($B9="","",SUMPRODUCT(COUNTIF($F9:$AJ9,KY_HIEU!$A$6:$A$45)*KY_HIEU!$C$6:$C$45)) | AL9: =IF($B9="","",SUMPRODUCT(COUNTIF($F9:$AJ9,KY_HIEU!$A$6:$A$45)*KY_HIEU!$D$6:$D$45)) | AM9: =IF($B9="","",SUMPRODUCT(COUNTIF($F9:$AJ9,KY_HIEU!$A$6:$A$45)*KY_HIEU!$E$6:$E$45)) | AN9: =IF($B9="","",SUMPRODUCT(COUNTIF($F9:$AJ9,KY_HIEU!$A$6:$A$45)*KY_HIEU!$F$6:$F$45)) | AO9: =IF($B9="","",SUMPRODUCT(COUNTIF($F9:$AJ9,KY_HIEU!$A$6:$A$45)*KY_HIEU!$G$6:$G$45)) | AP9: =IF($B9="","",SUMPRODUCT(COUNTIF($F9:$AJ9,KY_HIEU!$A$6:$A$45)*KY_HIEU!$H$6:$H$45)) | AQ9: =IF($B9="","",SUMPRODUCT(COUNTIF($F9:$AJ9,KY_HIEU!$A$6:$A$45)*KY_HIEU!$I$6:$I$45)) | AR9: =IF($B9="","",$AK9+$AL9+$AN9+$AO9+$AP9+$AQ9) | AS9: =IF($B9="","",IF(DM_NHAN_SU!$I9<>"",DM_NHAN_SU!$I9,IF(THAM_SO_CC!$B$20="Nhập tay",THAM_SO_CC!$B$10,SUMPRODUCT(((WEEKDAY(ROW(INDIRECT(THAM_SO_CC!$B$8&":"&THAM_SO_CC!$B$9)),2)<7)*(THAM_SO_CC!$B$12="CN")+(WEEKDAY(ROW(INDIRECT(THAM_SO_CC!$B$8&":"&THAM_SO_CC!$B$9)),2)<6)*(THAM_SO_CC!$B$12="T7+CN"))*(COUNTIF(THAM_SO_CC!$F$10:$F$40,ROW(INDIRECT(THAM_SO_CC!$B$8&":"&THAM_SO_CC!$B$9)))=0)*(ROW(INDIRECT(THAM_SO_CC!$B$8&":"&THAM_SO_CC!$B$9))>=IF(DM_NHAN_SU!$F9="",THAM_SO_CC!$B$8,DM_NHAN_SU!$F9))*(ROW(INDIRECT(THAM_SO_CC!$B$8&":"&THAM_SO_CC!$B$9))<=IF(DM_NHAN_SU!$G9="",THAM_SO_CC!$B$9,DM_NHAN_SU!$G9)))))) | AT9: =IF($B9="","",$AR9-$AS9) | AU9: =IF($B9="","",TRIM(IF(SUMPRODUCT(--($F9:$AJ9<>""))-SUMPRODUCT(COUNTIF($F9:$AJ9,KY_HIEU!$A$6:$A$45))>0,"Ký hiệu lạ; ","")&IF(ROUND($AT9,2)<>0,"Lệch ngày công "&TEXT($AT9,"0.0")&"; ","")&IF(SUMPRODUCT(--($F9:$AJ9<>""),--((THAM_SO_CC!$B$8+COLUMN($F$1:$AJ$1)-6)>THAM_SO_CC!$B$9))>0,"Chấm ngoài kỳ; ","")&IF(AND(DM_NHAN_SU!$F9<>"",SUMPRODUCT(--($F9:$AJ9<>""),--($F9:$AJ9<>"NV"),--($F9:$AJ9<>"NT"),--($F9:$AJ9<>"TN"),--((THAM_SO_CC!$B$8+COLUMN($F$1:$AJ$1)-6)<DM_NHAN_SU!$F9))>0),"Chấm trước ngày vào; ","")&IF(AND(DM_NHAN_SU!$G9<>"",SUMPRODUCT(--($F9:$AJ9<>""),--($F9:$AJ9<>"NV"),--($F9:$AJ9<>"NT"),--($F9:$AJ9<>"TN"),--((THAM_SO_CC!$B$8+COLUMN($F$1:$AJ$1)-6)>DM_NHAN_SU!$G9))>0),"Chấm sau ngày nghỉ việc; ","")))
A10: =IF($B10="","",ROW()-5) | B10: =IF(DM_NHAN_SU!B10="","",DM_NHAN_SU!B10) | C10: =IF($B10="","",DM_NHAN_SU!C10) | D10: =IF($B10="","",DM_NHAN_SU!D10) | E10: =IF($B10="","",DM_NHAN_SU!E10) | AK10: =IF($B10="","",SUMPRODUCT(COUNTIF($F10:$AJ10,KY_HIEU!$A$6:$A$45)*KY_HIEU!$C$6:$C$45)) | AL10: =IF($B10="","",SUMPRODUCT(COUNTIF($F10:$AJ10,KY_HIEU!$A$6:$A$45)*KY_HIEU!$D$6:$D$45)) | AM10: =IF($B10="","",SUMPRODUCT(COUNTIF($F10:$AJ10,KY_HIEU!$A$6:$A$45)*KY_HIEU!$E$6:$E$45)) | AN10: =IF($B10="","",SUMPRODUCT(COUNTIF($F10:$AJ10,KY_HIEU!$A$6:$A$45)*KY_HIEU!$F$6:$F$45)) | AO10: =IF($B10="","",SUMPRODUCT(COUNTIF($F10:$AJ10,KY_HIEU!$A$6:$A$45)*KY_HIEU!$G$6:$G$45)) | AP10: =IF($B10="","",SUMPRODUCT(COUNTIF($F10:$AJ10,KY_HIEU!$A$6:$A$45)*KY_HIEU!$H$6:$H$45)) | AQ10: =IF($B10="","",SUMPRODUCT(COUNTIF($F10:$AJ10,KY_HIEU!$A$6:$A$45)*KY_HIEU!$I$6:$I$45)) | AR10: =IF($B10="","",$AK10+$AL10+$AN10+$AO10+$AP10+$AQ10) | AS10: =IF($B10="","",IF(DM_NHAN_SU!$I10<>"",DM_NHAN_SU!$I10,IF(THAM_SO_CC!$B$20="Nhập tay",THAM_SO_CC!$B$10,SUMPRODUCT(((WEEKDAY(ROW(INDIRECT(THAM_SO_CC!$B$8&":"&THAM_SO_CC!$B$9)),2)<7)*(THAM_SO_CC!$B$12="CN")+(WEEKDAY(ROW(INDIRECT(THAM_SO_CC!$B$8&":"&THAM_SO_CC!$B$9)),2)<6)*(THAM_SO_CC!$B$12="T7+CN"))*(COUNTIF(THAM_SO_CC!$F$10:$F$40,ROW(INDIRECT(THAM_SO_CC!$B$8&":"&THAM_SO_CC!$B$9)))=0)*(ROW(INDIRECT(THAM_SO_CC!$B$8&":"&THAM_SO_CC!$B$9))>=IF(DM_NHAN_SU!$F10="",THAM_SO_CC!$B$8,DM_NHAN_SU!$F10))*(ROW(INDIRECT(THAM_SO_CC!$B$8&":"&THAM_SO_CC!$B$9))<=IF(DM_NHAN_SU!$G10="",THAM_SO_CC!$B$9,DM_NHAN_SU!$G10)))))) | AT10: =IF($B10="","",$AR10-$AS10) | AU10: =IF($B10="","",TRIM(IF(SUMPRODUCT(--($F10:$AJ10<>""))-SUMPRODUCT(COUNTIF($F10:$AJ10,KY_HIEU!$A$6:$A$45))>0,"Ký hiệu lạ; ","")&IF(ROUND($AT10,2)<>0,"Lệch ngày công "&TEXT($AT10,"0.0")&"; ","")&IF(SUMPRODUCT(--($F10:$AJ10<>""),--((THAM_SO_CC!$B$8+COLUMN($F$1:$AJ$1)-6)>THAM_SO_CC!$B$9))>0,"Chấm ngoài kỳ; ","")&IF(AND(DM_NHAN_SU!$F10<>"",SUMPRODUCT(--($F10:$AJ10<>""),--($F10:$AJ10<>"NV"),--($F10:$AJ10<>"NT"),--($F10:$AJ10<>"TN"),--((THAM_SO_CC!$B$8+COLUMN($F$1:$AJ$1)-6)<DM_NHAN_SU!$F10))>0),"Chấm trước ngày vào; ","")&IF(AND(DM_NHAN_SU!$G10<>"",SUMPRODUCT(--($F10:$AJ10<>""),--($F10:$AJ10<>"NV"),--($F10:$AJ10<>"NT"),--($F10:$AJ10<>"TN"),--((THAM_SO_CC!$B$8+COLUMN($F$1:$AJ$1)-6)>DM_NHAN_SU!$G10))>0),"Chấm sau ngày nghỉ việc; ","")))
A11: =IF($B11="","",ROW()-5) | B11: =IF(DM_NHAN_SU!B11="","",DM_NHAN_SU!B11) | C11: =IF($B11="","",DM_NHAN_SU!C11) | D11: =IF($B11="","",DM_NHAN_SU!D11) | E11: =IF($B11="","",DM_NHAN_SU!E11) | AK11: =IF($B11="","",SUMPRODUCT(COUNTIF($F11:$AJ11,KY_HIEU!$A$6:$A$45)*KY_HIEU!$C$6:$C$45)) | AL11: =IF($B11="","",SUMPRODUCT(COUNTIF($F11:$AJ11,KY_HIEU!$A$6:$A$45)*KY_HIEU!$D$6:$D$45)) | AM11: =IF($B11="","",SUMPRODUCT(COUNTIF($F11:$AJ11,KY_HIEU!$A$6:$A$45)*KY_HIEU!$E$6:$E$45)) | AN11: =IF($B11="","",SUMPRODUCT(COUNTIF($F11:$AJ11,KY_HIEU!$A$6:$A$45)*KY_HIEU!$F$6:$F$45)) | AO11: =IF($B11="","",SUMPRODUCT(COUNTIF($F11:$AJ11,KY_HIEU!$A$6:$A$45)*KY_HIEU!$G$6:$G$45)) | AP11: =IF($B11="","",SUMPRODUCT(COUNTIF($F11:$AJ11,KY_HIEU!$A$6:$A$45)*KY_HIEU!$H$6:$H$45)) | AQ11: =IF($B11="","",SUMPRODUCT(COUNTIF($F11:$AJ11,KY_HIEU!$A$6:$A$45)*KY_HIEU!$I$6:$I$45)) | AR11: =IF($B11="","",$AK11+$AL11+$AN11+$AO11+$AP11+$AQ11) | AS11: =IF($B11="","",IF(DM_NHAN_SU!$I11<>"",DM_NHAN_SU!$I11,IF(THAM_SO_CC!$B$20="Nhập tay",THAM_SO_CC!$B$10,SUMPRODUCT(((WEEKDAY(ROW(INDIRECT(THAM_SO_CC!$B$8&":"&THAM_SO_CC!$B$9)),2)<7)*(THAM_SO_CC!$B$12="CN")+(WEEKDAY(ROW(INDIRECT(THAM_SO_CC!$B$8&":"&THAM_SO_CC!$B$9)),2)<6)*(THAM_SO_CC!$B$12="T7+CN"))*(COUNTIF(THAM_SO_CC!$F$10:$F$40,ROW(INDIRECT(THAM_SO_CC!$B$8&":"&THAM_SO_CC!$B$9)))=0)*(ROW(INDIRECT(THAM_SO_CC!$B$8&":"&THAM_SO_CC!$B$9))>=IF(DM_NHAN_SU!$F11="",THAM_SO_CC!$B$8,DM_NHAN_SU!$F11))*(ROW(INDIRECT(THAM_SO_CC!$B$8&":"&THAM_SO_CC!$B$9))<=IF(DM_NHAN_SU!$G11="",THAM_SO_CC!$B$9,DM_NHAN_SU!$G11)))))) | AT11: =IF($B11="","",$AR11-$AS11) | AU11: =IF($B11="","",TRIM(IF(SUMPRODUCT(--($F11:$AJ11<>""))-SUMPRODUCT(COUNTIF($F11:$AJ11,KY_HIEU!$A$6:$A$45))>0,"Ký hiệu lạ; ","")&IF(ROUND($AT11,2)<>0,"Lệch ngày công "&TEXT($AT11,"0.0")&"; ","")&IF(SUMPRODUCT(--($F11:$AJ11<>""),--((THAM_SO_CC!$B$8+COLUMN($F$1:$AJ$1)-6)>THAM_SO_CC!$B$9))>0,"Chấm ngoài kỳ; ","")&IF(AND(DM_NHAN_SU!$F11<>"",SUMPRODUCT(--($F11:$AJ11<>""),--($F11:$AJ11<>"NV"),--($F11:$AJ11<>"NT"),--($F11:$AJ11<>"TN"),--((THAM_SO_CC!$B$8+COLUMN($F$1:$AJ$1)-6)<DM_NHAN_SU!$F11))>0),"Chấm trước ngày vào; ","")&IF(AND(DM_NHAN_SU!$G11<>"",SUMPRODUCT(--($F11:$AJ11<>""),--($F11:$AJ11<>"NV"),--($F11:$AJ11<>"NT"),--($F11:$AJ11<>"TN"),--((THAM_SO_CC!$B$8+COLUMN($F$1:$AJ$1)-6)>DM_NHAN_SU!$G11))>0),"Chấm sau ngày nghỉ việc; ","")))
A12: =IF($B12="","",ROW()-5) | B12: =IF(DM_NHAN_SU!B12="","",DM_NHAN_SU!B12) | C12: =IF($B12="","",DM_NHAN_SU!C12) | D12: =IF($B12="","",DM_NHAN_SU!D12) | E12: =IF($B12="","",DM_NHAN_SU!E12) | AK12: =IF($B12="","",SUMPRODUCT(COUNTIF($F12:$AJ12,KY_HIEU!$A$6:$A$45)*KY_HIEU!$C$6:$C$45)) | AL12: =IF($B12="","",SUMPRODUCT(COUNTIF($F12:$AJ12,KY_HIEU!$A$6:$A$45)*KY_HIEU!$D$6:$D$45)) | AM12: =IF($B12="","",SUMPRODUCT(COUNTIF($F12:$AJ12,KY_HIEU!$A$6:$A$45)*KY_HIEU!$E$6:$E$45)) | AN12: =IF($B12="","",SUMPRODUCT(COUNTIF($F12:$AJ12,KY_HIEU!$A$6:$A$45)*KY_HIEU!$F$6:$F$45)) | AO12: =IF($B12="","",SUMPRODUCT(COUNTIF($F12:$AJ12,KY_HIEU!$A$6:$A$45)*KY_HIEU!$G$6:$G$45)) | AP12: =IF($B12="","",SUMPRODUCT(COUNTIF($F12:$AJ12,KY_HIEU!$A$6:$A$45)*KY_HIEU!$H$6:$H$45)) | AQ12: =IF($B12="","",SUMPRODUCT(COUNTIF($F12:$AJ12,KY_HIEU!$A$6:$A$45)*KY_HIEU!$I$6:$I$45)) | AR12: =IF($B12="","",$AK12+$AL12+$AN12+$AO12+$AP12+$AQ12) | AS12: =IF($B12="","",IF(DM_NHAN_SU!$I12<>"",DM_NHAN_SU!$I12,IF(THAM_SO_CC!$B$20="Nhập tay",THAM_SO_CC!$B$10,SUMPRODUCT(((WEEKDAY(ROW(INDIRECT(THAM_SO_CC!$B$8&":"&THAM_SO_CC!$B$9)),2)<7)*(THAM_SO_CC!$B$12="CN")+(WEEKDAY(ROW(INDIRECT(THAM_SO_CC!$B$8&":"&THAM_SO_CC!$B$9)),2)<6)*(THAM_SO_CC!$B$12="T7+CN"))*(COUNTIF(THAM_SO_CC!$F$10:$F$40,ROW(INDIRECT(THAM_SO_CC!$B$8&":"&THAM_SO_CC!$B$9)))=0)*(ROW(INDIRECT(THAM_SO_CC!$B$8&":"&THAM_SO_CC!$B$9))>=IF(DM_NHAN_SU!$F12="",THAM_SO_CC!$B$8,DM_NHAN_SU!$F12))*(ROW(INDIRECT(THAM_SO_CC!$B$8&":"&THAM_SO_CC!$B$9))<=IF(DM_NHAN_SU!$G12="",THAM_SO_CC!$B$9,DM_NHAN_SU!$G12)))))) | AT12: =IF($B12="","",$AR12-$AS12) | AU12: =IF($B12="","",TRIM(IF(SUMPRODUCT(--($F12:$AJ12<>""))-SUMPRODUCT(COUNTIF($F12:$AJ12,KY_HIEU!$A$6:$A$45))>0,"Ký hiệu lạ; ","")&IF(ROUND($AT12,2)<>0,"Lệch ngày công "&TEXT($AT12,"0.0")&"; ","")&IF(SUMPRODUCT(--($F12:$AJ12<>""),--((THAM_SO_CC!$B$8+COLUMN($F$1:$AJ$1)-6)>THAM_SO_CC!$B$9))>0,"Chấm ngoài kỳ; ","")&IF(AND(DM_NHAN_SU!$F12<>"",SUMPRODUCT(--($F12:$AJ12<>""),--($F12:$AJ12<>"NV"),--($F12:$AJ12<>"NT"),--($F12:$AJ12<>"TN"),--((THAM_SO_CC!$B$8+COLUMN($F$1:$AJ$1)-6)<DM_NHAN_SU!$F12))>0),"Chấm trước ngày vào; ","")&IF(AND(DM_NHAN_SU!$G12<>"",SUMPRODUCT(--($F12:$AJ12<>""),--($F12:$AJ12<>"NV"),--($F12:$AJ12<>"NT"),--($F12:$AJ12<>"TN"),--((THAM_SO_CC!$B$8+COLUMN($F$1:$AJ$1)-6)>DM_NHAN_SU!$G12))>0),"Chấm sau ngày nghỉ việc; ","")))
A13: =IF($B13="","",ROW()-5) | B13: =IF(DM_NHAN_SU!B13="","",DM_NHAN_SU!B13) | C13: =IF($B13="","",DM_NHAN_SU!C13) | D13: =IF($B13="","",DM_NHAN_SU!D13) | E13: =IF($B13="","",DM_NHAN_SU!E13) | AK13: =IF($B13="","",SUMPRODUCT(COUNTIF($F13:$AJ13,KY_HIEU!$A$6:$A$45)*KY_HIEU!$C$6:$C$45)) | AL13: =IF($B13="","",SUMPRODUCT(COUNTIF($F13:$AJ13,KY_HIEU!$A$6:$A$45)*KY_HIEU!$D$6:$D$45)) | AM13: =IF($B13="","",SUMPRODUCT(COUNTIF($F13:$AJ13,KY_HIEU!$A$6:$A$45)*KY_HIEU!$E$6:$E$45)) | AN13: =IF($B13="","",SUMPRODUCT(COUNTIF($F13:$AJ13,KY_HIEU!$A$6:$A$45)*KY_HIEU!$F$6:$F$45)) | AO13: =IF($B13="","",SUMPRODUCT(COUNTIF($F13:$AJ13,KY_HIEU!$A$6:$A$45)*KY_HIEU!$G$6:$G$45)) | AP13: =IF($B13="","",SUMPRODUCT(COUNTIF($F13:$AJ13,KY_HIEU!$A$6:$A$45)*KY_HIEU!$H$6:$H$45)) | AQ13: =IF($B13="","",SUMPRODUCT(COUNTIF($F13:$AJ13,KY_HIEU!$A$6:$A$45)*KY_HIEU!$I$6:$I$45)) | AR13: =IF($B13="","",$AK13+$AL13+$AN13+$AO13+$AP13+$AQ13) | AS13: =IF($B13="","",IF(DM_NHAN_SU!$I13<>"",DM_NHAN_SU!$I13,IF(THAM_SO_CC!$B$20="Nhập tay",THAM_SO_CC!$B$10,SUMPRODUCT(((WEEKDAY(ROW(INDIRECT(THAM_SO_CC!$B$8&":"&THAM_SO_CC!$B$9)),2)<7)*(THAM_SO_CC!$B$12="CN")+(WEEKDAY(ROW(INDIRECT(THAM_SO_CC!$B$8&":"&THAM_SO_CC!$B$9)),2)<6)*(THAM_SO_CC!$B$12="T7+CN"))*(COUNTIF(THAM_SO_CC!$F$10:$F$40,ROW(INDIRECT(THAM_SO_CC!$B$8&":"&THAM_SO_CC!$B$9)))=0)*(ROW(INDIRECT(THAM_SO_CC!$B$8&":"&THAM_SO_CC!$B$9))>=IF(DM_NHAN_SU!$F13="",THAM_SO_CC!$B$8,DM_NHAN_SU!$F13))*(ROW(INDIRECT(THAM_SO_CC!$B$8&":"&THAM_SO_CC!$B$9))<=IF(DM_NHAN_SU!$G13="",THAM_SO_CC!$B$9,DM_NHAN_SU!$G13)))))) | AT13: =IF($B13="","",$AR13-$AS13) | AU13: =IF($B13="","",TRIM(IF(SUMPRODUCT(--($F13:$AJ13<>""))-SUMPRODUCT(COUNTIF($F13:$AJ13,KY_HIEU!$A$6:$A$45))>0,"Ký hiệu lạ; ","")&IF(ROUND($AT13,2)<>0,"Lệch ngày công "&TEXT($AT13,"0.0")&"; ","")&IF(SUMPRODUCT(--($F13:$AJ13<>""),--((THAM_SO_CC!$B$8+COLUMN($F$1:$AJ$1)-6)>THAM_SO_CC!$B$9))>0,"Chấm ngoài kỳ; ","")&IF(AND(DM_NHAN_SU!$F13<>"",SUMPRODUCT(--($F13:$AJ13<>""),--($F13:$AJ13<>"NV"),--($F13:$AJ13<>"NT"),--($F13:$AJ13<>"TN"),--((THAM_SO_CC!$B$8+COLUMN($F$1:$AJ$1)-6)<DM_NHAN_SU!$F13))>0),"Chấm trước ngày vào; ","")&IF(AND(DM_NHAN_SU!$G13<>"",SUMPRODUCT(--($F13:$AJ13<>""),--($F13:$AJ13<>"NV"),--($F13:$AJ13<>"NT"),--($F13:$AJ13<>"TN"),--((THAM_SO_CC!$B$8+COLUMN($F$1:$AJ$1)-6)>DM_NHAN_SU!$G13))>0),"Chấm sau ngày nghỉ việc; ","")))
A14: =IF($B14="","",ROW()-5) | B14: =IF(DM_NHAN_SU!B14="","",DM_NHAN_SU!B14) | C14: =IF($B14="","",DM_NHAN_SU!C14) | D14: =IF($B14="","",DM_NHAN_SU!D14) | E14: =IF($B14="","",DM_NHAN_SU!E14) | AK14: =IF($B14="","",SUMPRODUCT(COUNTIF($F14:$AJ14,KY_HIEU!$A$6:$A$45)*KY_HIEU!$C$6:$C$45)) | AL14: =IF($B14="","",SUMPRODUCT(COUNTIF($F14:$AJ14,KY_HIEU!$A$6:$A$45)*KY_HIEU!$D$6:$D$45)) | AM14: =IF($B14="","",SUMPRODUCT(COUNTIF($F14:$AJ14,KY_HIEU!$A$6:$A$45)*KY_HIEU!$E$6:$E$45)) | AN14: =IF($B14="","",SUMPRODUCT(COUNTIF($F14:$AJ14,KY_HIEU!$A$6:$A$45)*KY_HIEU!$F$6:$F$45)) | AO14: =IF($B14="","",SUMPRODUCT(COUNTIF($F14:$AJ14,KY_HIEU!$A$6:$A$45)*KY_HIEU!$G$6:$G$45)) | AP14: =IF($B14="","",SUMPRODUCT(COUNTIF($F14:$AJ14,KY_HIEU!$A$6:$A$45)*KY_HIEU!$H$6:$H$45)) | AQ14: =IF($B14="","",SUMPRODUCT(COUNTIF($F14:$AJ14,KY_HIEU!$A$6:$A$45)*KY_HIEU!$I$6:$I$45)) | AR14: =IF($B14="","",$AK14+$AL14+$AN14+$AO14+$AP14+$AQ14) | AS14: =IF($B14="","",IF(DM_NHAN_SU!$I14<>"",DM_NHAN_SU!$I14,IF(THAM_SO_CC!$B$20="Nhập tay",THAM_SO_CC!$B$10,SUMPRODUCT(((WEEKDAY(ROW(INDIRECT(THAM_SO_CC!$B$8&":"&THAM_SO_CC!$B$9)),2)<7)*(THAM_SO_CC!$B$12="CN")+(WEEKDAY(ROW(INDIRECT(THAM_SO_CC!$B$8&":"&THAM_SO_CC!$B$9)),2)<6)*(THAM_SO_CC!$B$12="T7+CN"))*(COUNTIF(THAM_SO_CC!$F$10:$F$40,ROW(INDIRECT(THAM_SO_CC!$B$8&":"&THAM_SO_CC!$B$9)))=0)*(ROW(INDIRECT(THAM_SO_CC!$B$8&":"&THAM_SO_CC!$B$9))>=IF(DM_NHAN_SU!$F14="",THAM_SO_CC!$B$8,DM_NHAN_SU!$F14))*(ROW(INDIRECT(THAM_SO_CC!$B$8&":"&THAM_SO_CC!$B$9))<=IF(DM_NHAN_SU!$G14="",THAM_SO_CC!$B$9,DM_NHAN_SU!$G14)))))) | AT14: =IF($B14="","",$AR14-$AS14) | AU14: =IF($B14="","",TRIM(IF(SUMPRODUCT(--($F14:$AJ14<>""))-SUMPRODUCT(COUNTIF($F14:$AJ14,KY_HIEU!$A$6:$A$45))>0,"Ký hiệu lạ; ","")&IF(ROUND($AT14,2)<>0,"Lệch ngày công "&TEXT($AT14,"0.0")&"; ","")&IF(SUMPRODUCT(--($F14:$AJ14<>""),--((THAM_SO_CC!$B$8+COLUMN($F$1:$AJ$1)-6)>THAM_SO_CC!$B$9))>0,"Chấm ngoài kỳ; ","")&IF(AND(DM_NHAN_SU!$F14<>"",SUMPRODUCT(--($F14:$AJ14<>""),--($F14:$AJ14<>"NV"),--($F14:$AJ14<>"NT"),--($F14:$AJ14<>"TN"),--((THAM_SO_CC!$B$8+COLUMN($F$1:$AJ$1)-6)<DM_NHAN_SU!$F14))>0),"Chấm trước ngày vào; ","")&IF(AND(DM_NHAN_SU!$G14<>"",SUMPRODUCT(--($F14:$AJ14<>""),--($F14:$AJ14<>"NV"),--($F14:$AJ14<>"NT"),--($F14:$AJ14<>"TN"),--((THAM_SO_CC!$B$8+COLUMN($F$1:$AJ$1)-6)>DM_NHAN_SU!$G14))>0),"Chấm sau ngày nghỉ việc; ","")))
A15: =IF($B15="","",ROW()-5) | B15: =IF(DM_NHAN_SU!B15="","",DM_NHAN_SU!B15) | C15: =IF($B15="","",DM_NHAN_SU!C15) | D15: =IF($B15="","",DM_NHAN_SU!D15) | E15: =IF($B15="","",DM_NHAN_SU!E15) | AK15: =IF($B15="","",SUMPRODUCT(COUNTIF($F15:$AJ15,KY_HIEU!$A$6:$A$45)*KY_HIEU!$C$6:$C$45)) | AL15: =IF($B15="","",SUMPRODUCT(COUNTIF($F15:$AJ15,KY_HIEU!$A$6:$A$45)*KY_HIEU!$D$6:$D$45)) | AM15: =IF($B15="","",SUMPRODUCT(COUNTIF($F15:$AJ15,KY_HIEU!$A$6:$A$45)*KY_HIEU!$E$6:$E$45)) | AN15: =IF($B15="","",SUMPRODUCT(COUNTIF($F15:$AJ15,KY_HIEU!$A$6:$A$45)*KY_HIEU!$F$6:$F$45)) | AO15: =IF($B15="","",SUMPRODUCT(COUNTIF($F15:$AJ15,KY_HIEU!$A$6:$A$45)*KY_HIEU!$G$6:$G$45)) | AP15: =IF($B15="","",SUMPRODUCT(COUNTIF($F15:$AJ15,KY_HIEU!$A$6:$A$45)*KY_HIEU!$H$6:$H$45)) | AQ15: =IF($B15="","",SUMPRODUCT(COUNTIF($F15:$AJ15,KY_HIEU!$A$6:$A$45)*KY_HIEU!$I$6:$I$45)) | AR15: =IF($B15="","",$AK15+$AL15+$AN15+$AO15+$AP15+$AQ15) | AS15: =IF($B15="","",IF(DM_NHAN_SU!$I15<>"",DM_NHAN_SU!$I15,IF(THAM_SO_CC!$B$20="Nhập tay",THAM_SO_CC!$B$10,SUMPRODUCT(((WEEKDAY(ROW(INDIRECT(THAM_SO_CC!$B$8&":"&THAM_SO_CC!$B$9)),2)<7)*(THAM_SO_CC!$B$12="CN")+(WEEKDAY(ROW(INDIRECT(THAM_SO_CC!$B$8&":"&THAM_SO_CC!$B$9)),2)<6)*(THAM_SO_CC!$B$12="T7+CN"))*(COUNTIF(THAM_SO_CC!$F$10:$F$40,ROW(INDIRECT(THAM_SO_CC!$B$8&":"&THAM_SO_CC!$B$9)))=0)*(ROW(INDIRECT(THAM_SO_CC!$B$8&":"&THAM_SO_CC!$B$9))>=IF(DM_NHAN_SU!$F15="",THAM_SO_CC!$B$8,DM_NHAN_SU!$F15))*(ROW(INDIRECT(THAM_SO_CC!$B$8&":"&THAM_SO_CC!$B$9))<=IF(DM_NHAN_SU!$G15="",THAM_SO_CC!$B$9,DM_NHAN_SU!$G15)))))) | AT15: =IF($B15="","",$AR15-$AS15) | AU15: =IF($B15="","",TRIM(IF(SUMPRODUCT(--($F15:$AJ15<>""))-SUMPRODUCT(COUNTIF($F15:$AJ15,KY_HIEU!$A$6:$A$45))>0,"Ký hiệu lạ; ","")&IF(ROUND($AT15,2)<>0,"Lệch ngày công "&TEXT($AT15,"0.0")&"; ","")&IF(SUMPRODUCT(--($F15:$AJ15<>""),--((THAM_SO_CC!$B$8+COLUMN($F$1:$AJ$1)-6)>THAM_SO_CC!$B$9))>0,"Chấm ngoài kỳ; ","")&IF(AND(DM_NHAN_SU!$F15<>"",SUMPRODUCT(--($F15:$AJ15<>""),--($F15:$AJ15<>"NV"),--($F15:$AJ15<>"NT"),--($F15:$AJ15<>"TN"),--((THAM_SO_CC!$B$8+COLUMN($F$1:$AJ$1)-6)<DM_NHAN_SU!$F15))>0),"Chấm trước ngày vào; ","")&IF(AND(DM_NHAN_SU!$G15<>"",SUMPRODUCT(--($F15:$AJ15<>""),--($F15:$AJ15<>"NV"),--($F15:$AJ15<>"NT"),--($F15:$AJ15<>"TN"),--((THAM_SO_CC!$B$8+COLUMN($F$1:$AJ$1)-6)>DM_NHAN_SU!$G15))>0),"Chấm sau ngày nghỉ việc; ","")))
A16: =IF($B16="","",ROW()-5) | B16: =IF(DM_NHAN_SU!B16="","",DM_NHAN_SU!B16) | C16: =IF($B16="","",DM_NHAN_SU!C16) | D16: =IF($B16="","",DM_NHAN_SU!D16) | E16: =IF($B16="","",DM_NHAN_SU!E16) | AK16: =IF($B16="","",SUMPRODUCT(COUNTIF($F16:$AJ16,KY_HIEU!$A$6:$A$45)*KY_HIEU!$C$6:$C$45)) | AL16: =IF($B16="","",SUMPRODUCT(COUNTIF($F16:$AJ16,KY_HIEU!$A$6:$A$45)*KY_HIEU!$D$6:$D$45)) | AM16: =IF($B16="","",SUMPRODUCT(COUNTIF($F16:$AJ16,KY_HIEU!$A$6:$A$45)*KY_HIEU!$E$6:$E$45)) | AN16: =IF($B16="","",SUMPRODUCT(COUNTIF($F16:$AJ16,KY_HIEU!$A$6:$A$45)*KY_HIEU!$F$6:$F$45)) | AO16: =IF($B16="","",SUMPRODUCT(COUNTIF($F16:$AJ16,KY_HIEU!$A$6:$A$45)*KY_HIEU!$G$6:$G$45)) | AP16: =IF($B16="","",SUMPRODUCT(COUNTIF($F16:$AJ16,KY_HIEU!$A$6:$A$45)*KY_HIEU!$H$6:$H$45)) | AQ16: =IF($B16="","",SUMPRODUCT(COUNTIF($F16:$AJ16,KY_HIEU!$A$6:$A$45)*KY_HIEU!$I$6:$I$45)) | AR16: =IF($B16="","",$AK16+$AL16+$AN16+$AO16+$AP16+$AQ16) | AS16: =IF($B16="","",IF(DM_NHAN_SU!$I16<>"",DM_NHAN_SU!$I16,IF(THAM_SO_CC!$B$20="Nhập tay",THAM_SO_CC!$B$10,SUMPRODUCT(((WEEKDAY(ROW(INDIRECT(THAM_SO_CC!$B$8&":"&THAM_SO_CC!$B$9)),2)<7)*(THAM_SO_CC!$B$12="CN")+(WEEKDAY(ROW(INDIRECT(THAM_SO_CC!$B$8&":"&THAM_SO_CC!$B$9)),2)<6)*(THAM_SO_CC!$B$12="T7+CN"))*(COUNTIF(THAM_SO_CC!$F$10:$F$40,ROW(INDIRECT(THAM_SO_CC!$B$8&":"&THAM_SO_CC!$B$9)))=0)*(ROW(INDIRECT(THAM_SO_CC!$B$8&":"&THAM_SO_CC!$B$9))>=IF(DM_NHAN_SU!$F16="",THAM_SO_CC!$B$8,DM_NHAN_SU!$F16))*(ROW(INDIRECT(THAM_SO_CC!$B$8&":"&THAM_SO_CC!$B$9))<=IF(DM_NHAN_SU!$G16="",THAM_SO_CC!$B$9,DM_NHAN_SU!$G16)))))) | AT16: =IF($B16="","",$AR16-$AS16) | AU16: =IF($B16="","",TRIM(IF(SUMPRODUCT(--($F16:$AJ16<>""))-SUMPRODUCT(COUNTIF($F16:$AJ16,KY_HIEU!$A$6:$A$45))>0,"Ký hiệu lạ; ","")&IF(ROUND($AT16,2)<>0,"Lệch ngày công "&TEXT($AT16,"0.0")&"; ","")&IF(SUMPRODUCT(--($F16:$AJ16<>""),--((THAM_SO_CC!$B$8+COLUMN($F$1:$AJ$1)-6)>THAM_SO_CC!$B$9))>0,"Chấm ngoài kỳ; ","")&IF(AND(DM_NHAN_SU!$F16<>"",SUMPRODUCT(--($F16:$AJ16<>""),--($F16:$AJ16<>"NV"),--($F16:$AJ16<>"NT"),--($F16:$AJ16<>"TN"),--((THAM_SO_CC!$B$8+COLUMN($F$1:$AJ$1)-6)<DM_NHAN_SU!$F16))>0),"Chấm trước ngày vào; ","")&IF(AND(DM_NHAN_SU!$G16<>"",SUMPRODUCT(--($F16:$AJ16<>""),--($F16:$AJ16<>"NV"),--($F16:$AJ16<>"NT"),--($F16:$AJ16<>"TN"),--((THAM_SO_CC!$B$8+COLUMN($F$1:$AJ$1)-6)>DM_NHAN_SU!$G16))>0),"Chấm sau ngày nghỉ việc; ","")))
A17: =IF($B17="","",ROW()-5) | B17: =IF(DM_NHAN_SU!B17="","",DM_NHAN_SU!B17) | C17: =IF($B17="","",DM_NHAN_SU!C17) | D17: =IF($B17="","",DM_NHAN_SU!D17) | E17: =IF($B17="","",DM_NHAN_SU!E17) | AK17: =IF($B17="","",SUMPRODUCT(COUNTIF($F17:$AJ17,KY_HIEU!$A$6:$A$45)*KY_HIEU!$C$6:$C$45)) | AL17: =IF($B17="","",SUMPRODUCT(COUNTIF($F17:$AJ17,KY_HIEU!$A$6:$A$45)*KY_HIEU!$D$6:$D$45)) | AM17: =IF($B17="","",SUMPRODUCT(COUNTIF($F17:$AJ17,KY_HIEU!$A$6:$A$45)*KY_HIEU!$E$6:$E$45)) | AN17: =IF($B17="","",SUMPRODUCT(COUNTIF($F17:$AJ17,KY_HIEU!$A$6:$A$45)*KY_HIEU!$F$6:$F$45)) | AO17: =IF($B17="","",SUMPRODUCT(COUNTIF($F17:$AJ17,KY_HIEU!$A$6:$A$45)*KY_HIEU!$G$6:$G$45)) | AP17: =IF($B17="","",SUMPRODUCT(COUNTIF($F17:$AJ17,KY_HIEU!$A$6:$A$45)*KY_HIEU!$H$6:$H$45)) | AQ17: =IF($B17="","",SUMPRODUCT(COUNTIF($F17:$AJ17,KY_HIEU!$A$6:$A$45)*KY_HIEU!$I$6:$I$45)) | AR17: =IF($B17="","",$AK17+$AL17+$AN17+$AO17+$AP17+$AQ17) | AS17: =IF($B17="","",IF(DM_NHAN_SU!$I17<>"",DM_NHAN_SU!$I17,IF(THAM_SO_CC!$B$20="Nhập tay",THAM_SO_CC!$B$10,SUMPRODUCT(((WEEKDAY(ROW(INDIRECT(THAM_SO_CC!$B$8&":"&THAM_SO_CC!$B$9)),2)<7)*(THAM_SO_CC!$B$12="CN")+(WEEKDAY(ROW(INDIRECT(THAM_SO_CC!$B$8&":"&THAM_SO_CC!$B$9)),2)<6)*(THAM_SO_CC!$B$12="T7+CN"))*(COUNTIF(THAM_SO_CC!$F$10:$F$40,ROW(INDIRECT(THAM_SO_CC!$B$8&":"&THAM_SO_CC!$B$9)))=0)*(ROW(INDIRECT(THAM_SO_CC!$B$8&":"&THAM_SO_CC!$B$9))>=IF(DM_NHAN_SU!$F17="",THAM_SO_CC!$B$8,DM_NHAN_SU!$F17))*(ROW(INDIRECT(THAM_SO_CC!$B$8&":"&THAM_SO_CC!$B$9))<=IF(DM_NHAN_SU!$G17="",THAM_SO_CC!$B$9,DM_NHAN_SU!$G17)))))) | AT17: =IF($B17="","",$AR17-$AS17) | AU17: =IF($B17="","",TRIM(IF(SUMPRODUCT(--($F17:$AJ17<>""))-SUMPRODUCT(COUNTIF($F17:$AJ17,KY_HIEU!$A$6:$A$45))>0,"Ký hiệu lạ; ","")&IF(ROUND($AT17,2)<>0,"Lệch ngày công "&TEXT($AT17,"0.0")&"; ","")&IF(SUMPRODUCT(--($F17:$AJ17<>""),--((THAM_SO_CC!$B$8+COLUMN($F$1:$AJ$1)-6)>THAM_SO_CC!$B$9))>0,"Chấm ngoài kỳ; ","")&IF(AND(DM_NHAN_SU!$F17<>"",SUMPRODUCT(--($F17:$AJ17<>""),--($F17:$AJ17<>"NV"),--($F17:$AJ17<>"NT"),--($F17:$AJ17<>"TN"),--((THAM_SO_CC!$B$8+COLUMN($F$1:$AJ$1)-6)<DM_NHAN_SU!$F17))>0),"Chấm trước ngày vào; ","")&IF(AND(DM_NHAN_SU!$G17<>"",SUMPRODUCT(--($F17:$AJ17<>""),--($F17:$AJ17<>"NV"),--($F17:$AJ17<>"NT"),--($F17:$AJ17<>"TN"),--((THAM_SO_CC!$B$8+COLUMN($F$1:$AJ$1)-6)>DM_NHAN_SU!$G17))>0),"Chấm sau ngày nghỉ việc; ","")))
... A155: =IF($B155="","",ROW()-5) | B155: =IF(DM_NHAN_SU!B155="","",DM_NHAN_SU!B155) | C155: =IF($B155="","",DM_NHAN_SU!C155) | D155: =IF($B155="","",DM_NHAN_SU!D155) | E155: =IF($B155="","",DM_NHAN_SU!E155) | AK155: =IF($B155="","",SUMPRODUCT(COUNTIF($F155:$AJ155,KY_HIEU!$A$6:$A$45)*KY_HIEU!$C$6:$C$45)) | AL155: =IF($B155="","",SUMPRODUCT(COUNTIF($F155:$AJ155,KY_HIEU!$A$6:$A$45)*KY_HIEU!$D$6:$D$45)) | AM155: =IF($B155="","",SUMPRODUCT(COUNTIF($F155:$AJ155,KY_HIEU!$A$6:$A$45)*KY_HIEU!$E$6:$E$45)) | AN155: =IF($B155="","",SUMPRODUCT(COUNTIF($F155:$AJ155,KY_HIEU!$A$6:$A$45)*KY_HIEU!$F$6:$F$45)) | AO155: =IF($B155="","",SUMPRODUCT(COUNTIF($F155:$AJ155,KY_HIEU!$A$6:$A$45)*KY_HIEU!$G$6:$G$45)) | AP155: =IF($B155="","",SUMPRODUCT(COUNTIF($F155:$AJ155,KY_HIEU!$A$6:$A$45)*KY_HIEU!$H$6:$H$45)) | AQ155: =IF($B155="","",SUMPRODUCT(COUNTIF($F155:$AJ155,KY_HIEU!$A$6:$A$45)*KY_HIEU!$I$6:$I$45)) | AR155: =IF($B155="","",$AK155+$AL155+$AN155+$AO155+$AP155+$AQ155) | AS155: =IF($B155="","",IF(DM_NHAN_SU!$I155<>"",DM_NHAN_SU!$I155,IF(THAM_SO_CC!$B$20="Nhập tay",THAM_SO_CC!$B$10,SUMPRODUCT(((WEEKDAY(ROW(INDIRECT(THAM_SO_CC!$B$8&":"&THAM_SO_CC!$B$9)),2)<7)*(THAM_SO_CC!$B$12="CN")+(WEEKDAY(ROW(INDIRECT(THAM_SO_CC!$B$8&":"&THAM_SO_CC!$B$9)),2)<6)*(THAM_SO_CC!$B$12="T7+CN"))*(COUNTIF(THAM_SO_CC!$F$10:$F$40,ROW(INDIRECT(THAM_SO_CC!$B$8&":"&THAM_SO_CC!$B$9)))=0)*(ROW(INDIRECT(THAM_SO_CC!$B$8&":"&THAM_SO_CC!$B$9))>=IF(DM_NHAN_SU!$F155="",THAM_SO_CC!$B$8,DM_NHAN_SU!$F155))*(ROW(INDIRECT(THAM_SO_CC!$B$8&":"&THAM_SO_CC!$B$9))<=IF(DM_NHAN_SU!$G155="",THAM_SO_CC!$B$9,DM_NHAN_SU!$G155)))))) | AT155: =IF($B155="","",$AR155-$AS155) | AU155: =IF($B155="","",TRIM(IF(SUMPRODUCT(--($F155:$AJ155<>""))-SUMPRODUCT(COUNTIF($F155:$AJ155,KY_HIEU!$A$6:$A$45))>0,"Ký hiệu lạ; ","")&IF(ROUND($AT155,2)<>0,"Lệch ngày công "&TEXT($AT155,"0.0")&"; ","")&IF(SUMPRODUCT(--($F155:$AJ155<>""),--((THAM_SO_CC!$B$8+COLUMN($F$1:$AJ$1)-6)>THAM_SO_CC!$B$9))>0,"Chấm ngoài kỳ; ","")&IF(AND(DM_NHAN_SU!$F155<>"",SUMPRODUCT(--($F155:$AJ155<>""),--($F155:$AJ155<>"NV"),--($F155:$AJ155<>"NT"),--($F155:$AJ155<>"TN"),--((THAM_SO_CC!$B$8+COLUMN($F$1:$AJ$1)-6)<DM_NHAN_SU!$F155))>0),"Chấm trước ngày vào; ","")&IF(AND(DM_NHAN_SU!$G155<>"",SUMPRODUCT(--($F155:$AJ155<>""),--($F155:$AJ155<>"NV"),--($F155:$AJ155<>"NT"),--($F155:$AJ155<>"TN"),--((THAM_SO_CC!$B$8+COLUMN($F$1:$AJ$1)-6)>DM_NHAN_SU!$G155))>0),"Chấm sau ngày nghỉ việc; ","")))

Sheet CC_OT_GIO
A1: CHẤM GIỜ LÀM THÊM VÀ GIỜ BAN ĐÊM THEO NGÀY
A2: Chỉ nhập cho ngày thực tế có làm thêm giờ hoặc làm ban đêm. Nhập Mã NV, Ngày, số giờ OT ban ngày và số giờ OT ban đêm; file tự xác định loại ngày rồi xếp vào đúng nhóm OT. Giờ đêm trong ca là phần 22:00–06:00 nằm trong ca bình thường, không phải giờ OT, nhập riêng tại cột F.
A5: STT | B5: Mã NV | C5: Họ và tên | D5: Ngày | E5: Loại ngày | F5: Giờ đêm trong ca | G5: Giờ OT ban ngày | H5: Giờ OT ban đêm | I5: Ghi chú | J5: OT thường ngày | K5: OT nghỉ tuần ngày | L5: OT lễ ngày | M5: OT thường đêm | N5: OT nghỉ tuần đêm | O5: OT lễ đêm
A6: =IF($B6="","",ROW()-5) | C6: =IF($B6="","",IFERROR(INDEX(DM_NHAN_SU!$C$6:$C$155,MATCH($B6,DM_NHAN_SU!$B$6:$B$155,0)),"SAI MÃ NV")) | E6: =IF(OR($B6="",$D6=""),"",IF(COUNTIF(THAM_SO_CC!$F$10:$F$40,$D6)>0,"Lễ",IF(IF(THAM_SO_CC!$B$12="T7+CN",WEEKDAY($D6,2)>=6,WEEKDAY($D6,2)=7),"Nghỉ tuần","Ngày thường"))) | J6: =IF($B6="","",IF($E6="Ngày thường",N($G6),0)) | K6: =IF($B6="","",IF($E6="Nghỉ tuần",N($G6),0)) | L6: =IF($B6="","",IF($E6="Lễ",N($G6),0)) | M6: =IF($B6="","",IF($E6="Ngày thường",N($H6),0)) | N6: =IF($B6="","",IF($E6="Nghỉ tuần",N($H6),0)) | O6: =IF($B6="","",IF($E6="Lễ",N($H6),0))
A7: =IF($B7="","",ROW()-5) | C7: =IF($B7="","",IFERROR(INDEX(DM_NHAN_SU!$C$6:$C$155,MATCH($B7,DM_NHAN_SU!$B$6:$B$155,0)),"SAI MÃ NV")) | E7: =IF(OR($B7="",$D7=""),"",IF(COUNTIF(THAM_SO_CC!$F$10:$F$40,$D7)>0,"Lễ",IF(IF(THAM_SO_CC!$B$12="T7+CN",WEEKDAY($D7,2)>=6,WEEKDAY($D7,2)=7),"Nghỉ tuần","Ngày thường"))) | J7: =IF($B7="","",IF($E7="Ngày thường",N($G7),0)) | K7: =IF($B7="","",IF($E7="Nghỉ tuần",N($G7),0)) | L7: =IF($B7="","",IF($E7="Lễ",N($G7),0)) | M7: =IF($B7="","",IF($E7="Ngày thường",N($H7),0)) | N7: =IF($B7="","",IF($E7="Nghỉ tuần",N($H7),0)) | O7: =IF($B7="","",IF($E7="Lễ",N($H7),0))
A8: =IF($B8="","",ROW()-5) | C8: =IF($B8="","",IFERROR(INDEX(DM_NHAN_SU!$C$6:$C$155,MATCH($B8,DM_NHAN_SU!$B$6:$B$155,0)),"SAI MÃ NV")) | E8: =IF(OR($B8="",$D8=""),"",IF(COUNTIF(THAM_SO_CC!$F$10:$F$40,$D8)>0,"Lễ",IF(IF(THAM_SO_CC!$B$12="T7+CN",WEEKDAY($D8,2)>=6,WEEKDAY($D8,2)=7),"Nghỉ tuần","Ngày thường"))) | J8: =IF($B8="","",IF($E8="Ngày thường",N($G8),0)) | K8: =IF($B8="","",IF($E8="Nghỉ tuần",N($G8),0)) | L8: =IF($B8="","",IF($E8="Lễ",N($G8),0)) | M8: =IF($B8="","",IF($E8="Ngày thường",N($H8),0)) | N8: =IF($B8="","",IF($E8="Nghỉ tuần",N($H8),0)) | O8: =IF($B8="","",IF($E8="Lễ",N($H8),0))
A9: =IF($B9="","",ROW()-5) | C9: =IF($B9="","",IFERROR(INDEX(DM_NHAN_SU!$C$6:$C$155,MATCH($B9,DM_NHAN_SU!$B$6:$B$155,0)),"SAI MÃ NV")) | E9: =IF(OR($B9="",$D9=""),"",IF(COUNTIF(THAM_SO_CC!$F$10:$F$40,$D9)>0,"Lễ",IF(IF(THAM_SO_CC!$B$12="T7+CN",WEEKDAY($D9,2)>=6,WEEKDAY($D9,2)=7),"Nghỉ tuần","Ngày thường"))) | J9: =IF($B9="","",IF($E9="Ngày thường",N($G9),0)) | K9: =IF($B9="","",IF($E9="Nghỉ tuần",N($G9),0)) | L9: =IF($B9="","",IF($E9="Lễ",N($G9),0)) | M9: =IF($B9="","",IF($E9="Ngày thường",N($H9),0)) | N9: =IF($B9="","",IF($E9="Nghỉ tuần",N($H9),0)) | O9: =IF($B9="","",IF($E9="Lễ",N($H9),0))
A10: =IF($B10="","",ROW()-5) | C10: =IF($B10="","",IFERROR(INDEX(DM_NHAN_SU!$C$6:$C$155,MATCH($B10,DM_NHAN_SU!$B$6:$B$155,0)),"SAI MÃ NV")) | E10: =IF(OR($B10="",$D10=""),"",IF(COUNTIF(THAM_SO_CC!$F$10:$F$40,$D10)>0,"Lễ",IF(IF(THAM_SO_CC!$B$12="T7+CN",WEEKDAY($D10,2)>=6,WEEKDAY($D10,2)=7),"Nghỉ tuần","Ngày thường"))) | J10: =IF($B10="","",IF($E10="Ngày thường",N($G10),0)) | K10: =IF($B10="","",IF($E10="Nghỉ tuần",N($G10),0)) | L10: =IF($B10="","",IF($E10="Lễ",N($G10),0)) | M10: =IF($B10="","",IF($E10="Ngày thường",N($H10),0)) | N10: =IF($B10="","",IF($E10="Nghỉ tuần",N($H10),0)) | O10: =IF($B10="","",IF($E10="Lễ",N($H10),0))
A11: =IF($B11="","",ROW()-5) | C11: =IF($B11="","",IFERROR(INDEX(DM_NHAN_SU!$C$6:$C$155,MATCH($B11,DM_NHAN_SU!$B$6:$B$155,0)),"SAI MÃ NV")) | E11: =IF(OR($B11="",$D11=""),"",IF(COUNTIF(THAM_SO_CC!$F$10:$F$40,$D11)>0,"Lễ",IF(IF(THAM_SO_CC!$B$12="T7+CN",WEEKDAY($D11,2)>=6,WEEKDAY($D11,2)=7),"Nghỉ tuần","Ngày thường"))) | J11: =IF($B11="","",IF($E11="Ngày thường",N($G11),0)) | K11: =IF($B11="","",IF($E11="Nghỉ tuần",N($G11),0)) | L11: =IF($B11="","",IF($E11="Lễ",N($G11),0)) | M11: =IF($B11="","",IF($E11="Ngày thường",N($H11),0)) | N11: =IF($B11="","",IF($E11="Nghỉ tuần",N($H11),0)) | O11: =IF($B11="","",IF($E11="Lễ",N($H11),0))
A12: =IF($B12="","",ROW()-5) | C12: =IF($B12="","",IFERROR(INDEX(DM_NHAN_SU!$C$6:$C$155,MATCH($B12,DM_NHAN_SU!$B$6:$B$155,0)),"SAI MÃ NV")) | E12: =IF(OR($B12="",$D12=""),"",IF(COUNTIF(THAM_SO_CC!$F$10:$F$40,$D12)>0,"Lễ",IF(IF(THAM_SO_CC!$B$12="T7+CN",WEEKDAY($D12,2)>=6,WEEKDAY($D12,2)=7),"Nghỉ tuần","Ngày thường"))) | J12: =IF($B12="","",IF($E12="Ngày thường",N($G12),0)) | K12: =IF($B12="","",IF($E12="Nghỉ tuần",N($G12),0)) | L12: =IF($B12="","",IF($E12="Lễ",N($G12),0)) | M12: =IF($B12="","",IF($E12="Ngày thường",N($H12),0)) | N12: =IF($B12="","",IF($E12="Nghỉ tuần",N($H12),0)) | O12: =IF($B12="","",IF($E12="Lễ",N($H12),0))
A13: =IF($B13="","",ROW()-5) | C13: =IF($B13="","",IFERROR(INDEX(DM_NHAN_SU!$C$6:$C$155,MATCH($B13,DM_NHAN_SU!$B$6:$B$155,0)),"SAI MÃ NV")) | E13: =IF(OR($B13="",$D13=""),"",IF(COUNTIF(THAM_SO_CC!$F$10:$F$40,$D13)>0,"Lễ",IF(IF(THAM_SO_CC!$B$12="T7+CN",WEEKDAY($D13,2)>=6,WEEKDAY($D13,2)=7),"Nghỉ tuần","Ngày thường"))) | J13: =IF($B13="","",IF($E13="Ngày thường",N($G13),0)) | K13: =IF($B13="","",IF($E13="Nghỉ tuần",N($G13),0)) | L13: =IF($B13="","",IF($E13="Lễ",N($G13),0)) | M13: =IF($B13="","",IF($E13="Ngày thường",N($H13),0)) | N13: =IF($B13="","",IF($E13="Nghỉ tuần",N($H13),0)) | O13: =IF($B13="","",IF($E13="Lễ",N($H13),0))
A14: =IF($B14="","",ROW()-5) | C14: =IF($B14="","",IFERROR(INDEX(DM_NHAN_SU!$C$6:$C$155,MATCH($B14,DM_NHAN_SU!$B$6:$B$155,0)),"SAI MÃ NV")) | E14: =IF(OR($B14="",$D14=""),"",IF(COUNTIF(THAM_SO_CC!$F$10:$F$40,$D14)>0,"Lễ",IF(IF(THAM_SO_CC!$B$12="T7+CN",WEEKDAY($D14,2)>=6,WEEKDAY($D14,2)=7),"Nghỉ tuần","Ngày thường"))) | J14: =IF($B14="","",IF($E14="Ngày thường",N($G14),0)) | K14: =IF($B14="","",IF($E14="Nghỉ tuần",N($G14),0)) | L14: =IF($B14="","",IF($E14="Lễ",N($G14),0)) | M14: =IF($B14="","",IF($E14="Ngày thường",N($H14),0)) | N14: =IF($B14="","",IF($E14="Nghỉ tuần",N($H14),0)) | O14: =IF($B14="","",IF($E14="Lễ",N($H14),0))
A15: =IF($B15="","",ROW()-5) | C15: =IF($B15="","",IFERROR(INDEX(DM_NHAN_SU!$C$6:$C$155,MATCH($B15,DM_NHAN_SU!$B$6:$B$155,0)),"SAI MÃ NV")) | E15: =IF(OR($B15="",$D15=""),"",IF(COUNTIF(THAM_SO_CC!$F$10:$F$40,$D15)>0,"Lễ",IF(IF(THAM_SO_CC!$B$12="T7+CN",WEEKDAY($D15,2)>=6,WEEKDAY($D15,2)=7),"Nghỉ tuần","Ngày thường"))) | J15: =IF($B15="","",IF($E15="Ngày thường",N($G15),0)) | K15: =IF($B15="","",IF($E15="Nghỉ tuần",N($G15),0)) | L15: =IF($B15="","",IF($E15="Lễ",N($G15),0)) | M15: =IF($B15="","",IF($E15="Ngày thường",N($H15),0)) | N15: =IF($B15="","",IF($E15="Nghỉ tuần",N($H15),0)) | O15: =IF($B15="","",IF($E15="Lễ",N($H15),0))
A16: =IF($B16="","",ROW()-5) | C16: =IF($B16="","",IFERROR(INDEX(DM_NHAN_SU!$C$6:$C$155,MATCH($B16,DM_NHAN_SU!$B$6:$B$155,0)),"SAI MÃ NV")) | E16: =IF(OR($B16="",$D16=""),"",IF(COUNTIF(THAM_SO_CC!$F$10:$F$40,$D16)>0,"Lễ",IF(IF(THAM_SO_CC!$B$12="T7+CN",WEEKDAY($D16,2)>=6,WEEKDAY($D16,2)=7),"Nghỉ tuần","Ngày thường"))) | J16: =IF($B16="","",IF($E16="Ngày thường",N($G16),0)) | K16: =IF($B16="","",IF($E16="Nghỉ tuần",N($G16),0)) | L16: =IF($B16="","",IF($E16="Lễ",N($G16),0)) | M16: =IF($B16="","",IF($E16="Ngày thường",N($H16),0)) | N16: =IF($B16="","",IF($E16="Nghỉ tuần",N($H16),0)) | O16: =IF($B16="","",IF($E16="Lễ",N($H16),0))
A17: =IF($B17="","",ROW()-5) | C17: =IF($B17="","",IFERROR(INDEX(DM_NHAN_SU!$C$6:$C$155,MATCH($B17,DM_NHAN_SU!$B$6:$B$155,0)),"SAI MÃ NV")) | E17: =IF(OR($B17="",$D17=""),"",IF(COUNTIF(THAM_SO_CC!$F$10:$F$40,$D17)>0,"Lễ",IF(IF(THAM_SO_CC!$B$12="T7+CN",WEEKDAY($D17,2)>=6,WEEKDAY($D17,2)=7),"Nghỉ tuần","Ngày thường"))) | J17: =IF($B17="","",IF($E17="Ngày thường",N($G17),0)) | K17: =IF($B17="","",IF($E17="Nghỉ tuần",N($G17),0)) | L17: =IF($B17="","",IF($E17="Lễ",N($G17),0)) | M17: =IF($B17="","",IF($E17="Ngày thường",N($H17),0)) | N17: =IF($B17="","",IF($E17="Nghỉ tuần",N($H17),0)) | O17: =IF($B17="","",IF($E17="Lễ",N($H17),0))
... A2005: =IF($B2005="","",ROW()-5) | C2005: =IF($B2005="","",IFERROR(INDEX(DM_NHAN_SU!$C$6:$C$155,MATCH($B2005,DM_NHAN_SU!$B$6:$B$155,0)),"SAI MÃ NV")) | E2005: =IF(OR($B2005="",$D2005=""),"",IF(COUNTIF(THAM_SO_CC!$F$10:$F$40,$D2005)>0,"Lễ",IF(IF(THAM_SO_CC!$B$12="T7+CN",WEEKDAY($D2005,2)>=6,WEEKDAY($D2005,2)=7),"Nghỉ tuần","Ngày thường"))) | J2005: =IF($B2005="","",IF($E2005="Ngày thường",N($G2005),0)) | K2005: =IF($B2005="","",IF($E2005="Nghỉ tuần",N($G2005),0)) | L2005: =IF($B2005="","",IF($E2005="Lễ",N($G2005),0)) | M2005: =IF($B2005="","",IF($E2005="Ngày thường",N($H2005),0)) | N2005: =IF($B2005="","",IF($E2005="Nghỉ tuần",N($H2005),0)) | O2005: =IF($B2005="","",IF($E2005="Lễ",N($H2005),0))

Sheet TONG_HOP_CC
A1: TỔNG HỢP CHẤM CÔNG THEO NHÂN VIÊN
A2: Toàn bộ sheet là công thức. Ngày công lấy từ BANG_CHAM_CONG, giờ làm thêm lấy từ CC_OT_GIO trong khoảng Từ ngày – Đến ngày của THAM_SO_CC. Đây là số được kết xuất sang file lương tại sheet XUAT_SANG_LUONG.
A5: STT | B5: Mã NV | C5: Họ và tên | D5: Bộ phận | E5: Công làm việc | F5: Giờ/ngày áp dụng | G5: Giờ thường | H5: Giờ đêm trong ca | I5: OT thường ngày | J5: OT nghỉ tuần ngày | K5: OT lễ ngày | L5: OT thường đêm | M5: OT nghỉ tuần đêm | N5: OT lễ đêm | O5: Phép năm hưởng lương | P5: Lễ/Tết hưởng lương | Q5: Việc riêng hưởng lương | R5: Nghỉ ốm hưởng BHXH | S5: Nghỉ thai sản | T5: Nghỉ không lương | U5: Tổng giờ OT | V5: Cảnh báo
