Workbook

Sheet HUONG_DAN
A1: CÔNG CỤ TÍNH LƯƠNG – BHXH – THUẾ TNCN 2026 | QUÀ TẶNG CỘNG ĐỒNG W1
A3: Bản sạch dùng trên Excel 365 cho cá nhân cư trú ký hợp đồng lao động từ 03 tháng. Công cụ hỗ trợ lương Gross, Net–Gross, lương tháng/ngày/giờ/sản phẩm, KPI, hoa hồng, hai cách nhập chấm công, nghỉ phép, chế độ BHXH, thưởng tháng 13/Tết, đoàn phí và quyết toán nghỉ việc.
A6: QUY TRÌNH SỬ DỤNG
A7: Bước 1 | B7: THAM_SO | C7: Điền thông tin doanh nghiệp, kỳ lương, ngày công chuẩn và kiểm tra các tham số pháp lý.
A8: Bước 2 | B8: DM_NHAN_SU | C8: Khai nhân viên, thỏa thuận lương, căn cứ đóng bảo hiểm, đoàn viên và dữ liệu phép năm.
A9: Bước 3 | B9: CHAM_CONG_THANG / NGAY | C9: Chọn nguồn Tổng hợp hoặc Theo ngày; công làm việc phải tách khỏi phép, lễ, việc riêng, ốm, thai sản và nghỉ không lương.
A10: Bước 4 | B10: NGHI_PHEP / CHE_DO_BHXH | C10: Đối chiếu phép còn lại; nhập căn cứ, số ngày/tháng và số thực nhận để so sánh ước tính chế độ ốm đau, thai sản.
A11: Bước 5 | B11: THUONG_T13_TET / QT_NGHI_VIEC | C11: Chọn cách tính thưởng từng người; nếu nghỉ việc, khai riêng khoản chịu thuế, miễn thuế và các khoản phải thu.
A12: Bước 6 | B12: TINH_LUONG / BANG_LUONG | C12: Kiểm tra Gross-up, bảo hiểm, thuế TNCN, đoàn phí, thực lĩnh và toàn bộ cảnh báo trước khi phê duyệt.
A13: Bước 7 | B13: PHIEU_LUONG / TONG_HOP | C13: Chọn mã nhân viên để in phiếu; đối chiếu quỹ lương, thuế, bảo hiểm, trợ cấp và danh sách chuyển khoản.
A15: PHẠM VI VÀ GIẢ ĐỊNH TÍNH
A16: 1 | B16: Net–Gross | C16: Với nhân viên loại Net, toàn bộ khoản chịu thuế nhập trong tháng được hiểu là số tiền người lao động cần nhận sau BH bắt buộc và thuế TNCN. Khoản miễn thuế được cộng riêng.
A17: 2 | B17: Bảo hiểm | C17: Căn cứ đóng BH do người dùng khai theo lương công việc/chức danh, phụ cấp lương và khoản bổ sung cố định. File áp sàn, trần và đưa cảnh báo khi dữ liệu bất thường.
A18: 3 | B18: Làm thêm/ban đêm | C18: Tiền lương làm thêm, làm ban đêm trong giới hạn và điều kiện của pháp luật lao động được miễn TNCN đến mức luật định; phần trả vượt mức hoặc không đủ điều kiện chịu thuế. Cột loại trừ cho phép đưa phần không đủ điều kiện trở lại thu nhập chịu thuế.
A19: 4 | B19: Nghỉ việc/BHXH | C19: Tiền phép chưa nghỉ khi chấm dứt HĐLĐ và trợ cấp đúng mức luật định được tách miễn thuế; phần vượt mức chịu thuế. Ước tính ốm đau, thai sản không thay thế quyết định của cơ quan BHXH.
A20: 5 | B20: Ngoài phạm vi | C20: Chưa xử lý HĐLĐ dưới 03 tháng, cá nhân không cư trú, lao động nước ngoài, thu nhập nhiều nơi, quyết toán thuế năm hoặc tự kết luận bồi thường trong tranh chấp lao động.
A22: QUY ƯỚC MÀU
A23: Ô nhập liệu | C23: Người dùng được sửa | E23: Ô công thức | G23: Không sửa nếu chưa hiểu logic
A24: Cảnh báo | C24: Cần kiểm tra hồ sơ/dữ liệu | E24: Kết quả | G24: Dùng để đối chiếu hoặc xuất báo cáo
A25: Nguồn pháp lý | C25: Xem tại sheet THAM_SO | E25: Bản sạch | G25: Không chứa hồ sơ nhân viên hoặc chấm công mẫu
A27: LƯU Ý TRƯỚC KHI PHÁT HÀNH HOẶC ÁP DỤNG
A28: Đây là công cụ tham khảo và hỗ trợ kiểm soát, không thay thế tư vấn pháp lý, quyết định hưởng BHXH hoặc hồ sơ quyết toán của doanh nghiệp. Trước khi trả lương, kê khai thuế hoặc đóng bảo hiểm, phải đối chiếu văn bản còn hiệu lực, HĐLĐ, thỏa ước/quy chế lương thưởng, nghị quyết công đoàn, hồ sơ người phụ thuộc và chứng từ thực tế.
A33: Quy ước ngày công: “Ngày công chuẩn” là số ngày phải làm theo lịch doanh nghiệp, không gồm ngày nghỉ hằng tuần và ngày lễ/Tết. Với lương tháng, ngày lễ/Tết được theo dõi nhưng không cộng thêm lần hai; phép năm và việc riêng hưởng lương dùng để bù ngày phải làm. Với lương ngày/giờ/sản phẩm, file tính riêng tiền ngày nghỉ hưởng lương.
A37: Đoàn phí: mặc định 0,5% căn cứ đóng BHXH và có trần 10% mức lương cơ sở; có thể chọn cách tính theo thực nhận hoặc nhập tay khi công đoàn cơ sở có nghị quyết/quy chế phù hợp. File tự đưa đoàn phí về 0 khi dữ liệu thể hiện hưởng chế độ BHXH từ 01 tháng trở lên hoặc nghỉ không lương đủ cả tháng; vẫn phải kiểm tra hồ sơ thực tế.

Sheet THAM_SO
A1: THAM SỐ TÍNH LƯƠNG – PHÁP LÝ 2026
A3: THÔNG TIN KỲ LƯƠNG | E3: THUẾ TNCN – KỲ TÍNH THUẾ 2026 | L3: BHXH – BHYT – BHTN – KPCĐ
A4: Tên đơn vị | B4: CÔNG TY … | E4: Giảm trừ bản thân/tháng | F4: 15500000 | L4: Mức tham chiếu trước 01/7/2026 | M4: 2340000
A5: Địa chỉ | B5: Địa chỉ doanh nghiệp | E5: Giảm trừ 01 NPT/tháng | F5: 6200000 | L5: Mức tham chiếu từ 01/7/2026 | M5: 2530000
A6: Từ ngày | B6: 46204 | E6: Tiền ăn ca bằng tiền miễn tối đa | F6: 1200000 | L6: Mức tham chiếu áp dụng | M6: =IF($B$6>=DATE(2026,7,1),$M$5,$M$4)
A7: Đến ngày | B7: 46234 | E7: Năm tính thuế | F7: 2026 | L7: Trần BHXH/BHYT | M7: =$M$6*20
A8: Ngày trả lương | B8: 46234 | L8: NLĐ – BHXH | M8: 0.08
A9: Ngày công chuẩn | B9: 26 | E9: Bậc | F9: Từ | G9: Đến | H9: Thuế suất | I9: Giảm trừ nhanh | J9: Ngưỡng Net sau thuế | L9: NLĐ – BHYT | M9: 0.015
A10: Giờ làm việc/ngày | B10: 8 | E10: 1 | F10: 0 | G10: 10000000 | H10: 0.05 | I10: 0 | J10: 9500000 | L10: NLĐ – BHTN | M10: 0.01
A11: Vùng mặc định | B11: Vùng I | E11: 2 | F11: 10000000 | G11: 30000000 | H11: 0.1 | I11: 500000 | J11: 27500000 | L11: NSDLĐ – BHXH | M11: 0.175
A12: Địa điểm lập | B12: Hà Nội | E12: 3 | F12: 30000000 | G12: 60000000 | H12: 0.2 | I12: 3500000 | J12: 51500000 | L12: NSDLĐ – BHYT | M12: 0.03
A13: Ngày cập nhật pháp lý | B13: 46232 | E13: 4 | F13: 60000000 | G13: 100000000 | H13: 0.3 | I13: 9500000 | J13: 79500000 | L13: NSDLĐ – BHTN | M13: 0.01
A14: Phiên bản | B14: KK HOME Payroll 2026.2 – Excel 365 | E14: 5 | F14: 100000000 | H14: 0.35 | I14: 14500000 | L14: Kinh phí công đoàn | M14: 0.02
L16: Vùng | M16: Lương tối thiểu tháng | N16: Lương tối thiểu giờ | O16: Sàn BHTN | P16: Trần BHTN
A17: HỆ SỐ LÀM THÊM GIỜ / BAN ĐÊM | L17: Vùng I | M17: 5310000 | N17: 25500 | O17: =$M$6 | P17: =M17*20
A18: Loại giờ | B18: Mức luật định | C18: Mức doanh nghiệp | D18: Xử lý TNCN | E18: Ghi chú | L18: Vùng II | M18: 4730000 | N18: 22700 | O18: =$M$6 | P18: =M18*20
A19: OT ngày thường – ban ngày | B19: 1.5 | C19: 1.5 | D19: Miễn đến mức luật định | E19: Ít nhất 150%; phần trả cao hơn mức luật định chịu thuế | L19: Vùng III | M19: 4140000 | N19: 20000 | O19: =$M$6 | P19: =M19*20
A20: OT ngày nghỉ tuần – ban ngày | B20: 2 | C20: 2 | D20: Miễn đến mức luật định | E20: Ít nhất 200%; phần trả cao hơn mức luật định chịu thuế | L20: Vùng IV | M20: 3700000 | N20: 17800 | O20: =$M$6 | P20: =M20*20
A21: OT ngày lễ – ban ngày | B21: 3 | C21: 3 | D21: Miễn đến mức luật định | E21: Ít nhất 300%; chưa gồm lương ngày lễ nếu NLĐ hưởng lương ngày
A22: Làm việc ban đêm trong ca | B22: 0.3 | C22: 0.3 | D22: Miễn đến mức luật định | E22: Phần trả thêm ít nhất 30% | L22: ĐOÀN PHÍ VÀ MỨC TRỢ CẤP THAM CHIẾU
A23: OT ngày thường – ban đêm | B23: 2 | C23: 2 | D23: Miễn đến mức luật định | E23: Tổng tối thiểu 200% theo cấu phần luật định | L23: Đoàn phí mặc định trên căn cứ BH | M23: 0.005
A24: OT ngày nghỉ tuần – ban đêm | B24: 2.7 | C24: 2.7 | D24: Miễn đến mức luật định | E24: Tổng tối thiểu 270% theo cấu phần luật định | L24: Mức lương cơ sở tính trần | M24: =$M$6
A25: OT ngày lễ – ban đêm | B25: 3.9 | C25: 3.9 | D25: Miễn đến mức luật định | E25: Tổng tối thiểu 390%; chưa gồm lương ngày lễ nếu NLĐ hưởng lương ngày | L25: Tỷ lệ trần trên lương cơ sở | M25: 0.1
L26: Trần đoàn phí/tháng | M26: =$M$24*$M$25
L27: Dưỡng sức/ngày | M27: =$M$6*30%
A28: VĂN BẢN VÀ NGUỒN ĐỐI CHIẾU
A29: Văn bản | B29: Nội dung dùng trong file | C29: Hiệu lực/áp dụng | D29: URL | E29: LƯU Ý PHÁP LÝ VÀ PHÂN LOẠI KHOẢN THU NHẬP
A30: Luật 109/2025/QH15 | B30: Thuế TNCN; biểu thuế 05 bậc; giảm trừ | C30: Thu nhập tiền lương áp dụng kỳ tính thuế 2026 | D30: https://vanban.chinhphu.vn/?classid=1&docid=216495&pageid=27160&typegroupid=3 | E30: Tham số được cập nhật đến 29/7/2026. Ô vàng là dữ liệu phải rà soát. OT/ban đêm được miễn TNCN đến mức luật định nếu đúng giới hạn, điều kiện và hồ sơ; phần vượt hoặc không đủ điều kiện chịu thuế. Tiền phép chưa nghỉ chỉ được tách miễn thuế khi thanh toán đúng trường hợp chấm dứt HĐLĐ/mất việc. Thưởng tháng 13, Tết, KPI/hoa hồng thông thường chịu TNCN và không tự động vào căn cứ BH nếu không phải khoản cố định, thường xuyên theo HĐLĐ.
A31: Nghị định 253/2026/NĐ-CP | B31: Hướng dẫn thuế TNCN; tiền ăn ca; OT/ban đêm | C31: 01/7/2026; nội dung tiền lương áp dụng kỳ tính thuế 2026 | D31: https://vanban.chinhphu.vn/?classid=1&docid=218684&pageid=27160&typegroupid=4
A32: Thông tư 87/2026/TT-BTC | B32: Hướng dẫn chi tiết Luật TNCN và NĐ 253 | C32: 01/7/2026 | D32: https://vanban.chinhphu.vn/?docid=218772&pageid=27160
A33: Nghị quyết 110/2025/UBTVQH15 | B33: Giảm trừ bản thân 15,5 triệu; NPT 6,2 triệu | C33: Kỳ tính thuế 2026 | D33: https://xaydungchinhsach.chinhphu.vn/nghi-quyet-110-2025-ubtvqh15-dieu-chinh-muc-giam-tru-gia-canh-cua-thue-thu-nhap-ca-nhan-119251110101313787.htm
A34: Luật 41/2024/QH15 | B34: Căn cứ đóng; mức hưởng ốm đau, thai sản, dưỡng sức | C34: 01/7/2025 | D34: https://vanban.chinhphu.vn/?docid=211199&pageid=27160
A35: Thông tư 12/2025/TT-BNV | B35: Hướng dẫn BHXH bắt buộc và hồ sơ chế độ | C35: 01/7/2025 | D35: https://xaydungchinhsach.chinhphu.vn/toan-van-thong-tu-12-2025-tt-bnv-quy-dinh-chi-tiet-mot-so-dieu-cua-luat-bhxh-ve-bhxh-bat-buoc-11925070415595016.htm
A36: Nghị định 158/2025/NĐ-CP | B36: Tiền lương làm căn cứ đóng BHXH bắt buộc | C36: 01/7/2025 | D36: https://vanban.chinhphu.vn/?docid=214189&pageid=27160
A37: Nghị định 293/2025/NĐ-CP | B37: Lương tối thiểu vùng năm 2026 | C37: 01/01/2026 | D37: https://vanban.chinhphu.vn/?docid=215832&pageid=27160
A38: Nghị định 161/2026/NĐ-CP | B38: Mức lương cơ sở 2,53 triệu từ 01/7/2026 | C38: 01/7/2026 | D38: https://vanban.chinhphu.vn/?docid=218107&pageid=27160
A39: Luật Việc làm 74/2025/QH15 | B39: Đối tượng, căn cứ và trần đóng BHTN | C39: 01/01/2026 | D39: https://vanban.chinhphu.vn/?docid=214560&pageid=27160
A40: Bộ luật Lao động 45/2019/QH14 | B40: OT/ban đêm; phép năm; trợ cấp và thanh toán khi chấm dứt HĐLĐ | C40: 01/01/2021 | D40: https://vanban.chinhphu.vn/?docid=198540&pageid=27160
A41: Nghị định 145/2020/NĐ-CP | B41: Công thức OT, nghỉ phép, trợ cấp thôi việc/mất việc | C41: 01/02/2021 | D41: https://vanban.chinhphu.vn/?docid=201967&pageid=27160
A42: Luật Công đoàn 50/2024/QH15 | B42: Kinh phí công đoàn bằng 2% quỹ lương đóng BHXH | C42: 01/7/2025 | D42: https://vanban.chinhphu.vn/?classid=1&docid=212478&pageid=27160&typegroupid=3
...

Sheet DM_NHAN_SU
A1: DANH MỤC NHÂN SỰ VÀ THỎA THUẬN LƯƠNG
A2: Nhập một dòng cho mỗi nhân viên. Mức lương/đơn giá tại K là Gross hoặc Net theo I. Căn cứ đóng BH tại N:P lấy từ HĐLĐ/phụ lục và quy chế; không mặc định bằng tổng thu nhập. AA:AH dùng cho đoàn phí và phép năm; ngày phép cơ bản phải chọn 12/14/16 theo điều kiện công việc, cộng thâm niên riêng.
A5: STT | B5: Mã NV | C5: Họ và tên | D5: Bộ phận | E5: Chức danh | F5: Ngày vào | G5: Ngày nghỉ | H5: Vùng | I5: Loại lương | J5: Hình thức trả lương | K5: Mức lương/đơn giá | L5: Công chuẩn riêng | M5: Giờ/ngày riêng | N5: Lương công việc đóng BH | O5: Phụ cấp lương đóng BH | P5: Bổ sung cố định đóng BH | Q5: Lương giờ tính OT (ghi đè) | R5: BHXH+BHYT | S5: BHTN | T5: Số NPT | U5: MST | V5: CCCD | W5: Số tài khoản | X5: Ngân hàng | Y5: Email | Z5: Ghi chú | AA5: Đoàn viên | AB5: Cách tính đoàn phí | AC5: Đoàn phí nhập tay | AD5: Phép cơ bản/năm | AE5: Phép tăng do thâm niên | AF5: Phép chuyển sang | AG5: Phép đã dùng trước kỳ | AH5: Đơn giá ngày phép/lễ ghi đè
A6: =IF($B6="","",ROW()-5)
A7: =IF($B7="","",ROW()-5)
A8: =IF($B8="","",ROW()-5)
A9: =IF($B9="","",ROW()-5)
A10: =IF($B10="","",ROW()-5)
A11: =IF($B11="","",ROW()-5)
A12: =IF($B12="","",ROW()-5)
A13: =IF($B13="","",ROW()-5)
A14: =IF($B14="","",ROW()-5)
A15: =IF($B15="","",ROW()-5)
A16: =IF($B16="","",ROW()-5)
A17: =IF($B17="","",ROW()-5)
... A155: =IF($B155="","",ROW()-5)

Sheet CHAM_CONG_THANG
A1: DỮ LIỆU CHẤM CÔNG VÀ THU NHẬP THEO THÁNG
A2: Mỗi dòng khớp DM_NHAN_SU. Chọn “Tổng hợp” để nhập E:M và AL:AQ; chọn “Theo ngày” để hệ thống cộng CHAM_CONG_NGAY. Công làm việc phải tách khỏi phép/lễ/việc riêng hưởng lương. AC:AK và AR:AW là dữ liệu dùng để tính lương.
A5: STT | B5: Mã NV | C5: Họ và tên | D5: Nguồn công | E5: Công làm việc | F5: Giờ thường | G5: Giờ đêm trong ca | H5: OT thường ngày | I5: OT nghỉ tuần ngày | J5: OT lễ ngày | K5: OT thường đêm | L5: OT nghỉ tuần đêm | M5: OT lễ đêm | N5: Số lượng SP | O5: KPI | P5: Hoa hồng | Q5: Thưởng khác | R5: Phụ cấp chịu thuế | S5: Tiền ăn ca bằng tiền | T5: Khoán chi/hoàn trả miễn thuế | U5: Thu nhập miễn thuế khác | V5: OT/đêm không đủ điều kiện miễn TNCN | W5: Giảm trừ khác hợp lệ | X5: Tạm ứng | Y5: Khấu trừ khác | Z5: Điều chỉnh PIT | AA5: Không đóng BH tháng này | AB5: Ghi chú | AC5: Công dùng | AD5: Giờ thường dùng | AE5: Giờ đêm dùng | AF5: OT thường ngày dùng | AG5: OT nghỉ tuần ngày dùng | AH5: OT lễ ngày dùng | AI5: OT thường đêm dùng | AJ5: OT nghỉ tuần đêm dùng | AK5: OT lễ đêm dùng | AL5: Phép năm hưởng lương | AM5: Lễ/Tết hưởng lương | AN5: Việc riêng hưởng lương | AO5: Nghỉ ốm hưởng BHXH | AP5: Nghỉ thai sản | AQ5: Nghỉ không lương | AR5: Phép năm dùng | AS5: Lễ/Tết dùng | AT5: Việc riêng dùng | AU5: Ốm BHXH dùng | AV5: Thai sản dùng | AW5: Không lương dùng
A6: =IF($B6="","",ROW()-5) | B6: =IF('DM_NHAN_SU'!B6="","",'DM_NHAN_SU'!B6) | C6: =IF('DM_NHAN_SU'!B6="","",'DM_NHAN_SU'!C6) | AC6: =IF($B6="","",IF($D6="Theo ngày",SUMIFS('CHAM_CONG_NGAY'!$E$6:$E$4655,'CHAM_CONG_NGAY'!$B$6:$B$4655,$B6,'CHAM_CONG_NGAY'!$C$6:$C$4655,">="&'THAM_SO'!$B$6,'CHAM_CONG_NGAY'!$C$6:$C$4655,"<="&'THAM_SO'!$B$7),$E6)) | AD6: =IF($B6="","",IF($D6="Theo ngày",SUMIFS('CHAM_CONG_NGAY'!$F$6:$F$4655,'CHAM_CONG_NGAY'!$B$6:$B$4655,$B6,'CHAM_CONG_NGAY'!$C$6:$C$4655,">="&'THAM_SO'!$B$6,'CHAM_CONG_NGAY'!$C$6:$C$4655,"<="&'THAM_SO'!$B$7),$F6)) | AE6: =IF($B6="","",IF($D6="Theo ngày",SUMIFS('CHAM_CONG_NGAY'!$G$6:$G$4655,'CHAM_CONG_NGAY'!$B$6:$B$4655,$B6,'CHAM_CONG_NGAY'!$C$6:$C$4655,">="&'THAM_SO'!$B$6,'CHAM_CONG_NGAY'!$C$6:$C$4655,"<="&'THAM_SO'!$B$7),$G6)) | AF6: =IF($B6="","",IF($D6="Theo ngày",SUMIFS('CHAM_CONG_NGAY'!$H$6:$H$4655,'CHAM_CONG_NGAY'!$B$6:$B$4655,$B6,'CHAM_CONG_NGAY'!$C$6:$C$4655,">="&'THAM_SO'!$B$6,'CHAM_CONG_NGAY'!$C$6:$C$4655,"<="&'THAM_SO'!$B$7),$H6)) | AG6: =IF($B6="","",IF($D6="Theo ngày",SUMIFS('CHAM_CONG_NGAY'!$I$6:$I$4655,'CHAM_CONG_NGAY'!$B$6:$B$4655,$B6,'CHAM_CONG_NGAY'!$C$6:$C$4655,">="&'THAM_SO'!$B$6,'CHAM_CONG_NGAY'!$C$6:$C$4655,"<="&'THAM_SO'!$B$7),$I6)) | AH6: =IF($B6="","",IF($D6="Theo ngày",SUMIFS('CHAM_CONG_NGAY'!$J$6:$J$4655,'CHAM_CONG_NGAY'!$B$6:$B$4655,$B6,'CHAM_CONG_NGAY'!$C$6:$C$4655,">="&'THAM_SO'!$B$6,'CHAM_CONG_NGAY'!$C$6:$C$4655,"<="&'THAM_SO'!$B$7),$J6)) | AI6: =IF($B6="","",IF($D6="Theo ngày",SUMIFS('CHAM_CONG_NGAY'!$K$6:$K$4655,'CHAM_CONG_NGAY'!$B$6:$B$4655,$B6,'CHAM_CONG_NGAY'!$C$6:$C$4655,">="&'THAM_SO'!$B$6,'CHAM_CONG_NGAY'!$C$6:$C$4655,"<="&'THAM_SO'!$B$7),$K6)) | AJ6: =IF($B6="","",IF($D6="Theo ngày",SUMIFS('CHAM_CONG_NGAY'!$L$6:$L$4655,'CHAM_CONG_NGAY'!$B$6:$B$4655,$B6,'CHAM_CONG_NGAY'!$C$6:$C$4655,">="&'THAM_SO'!$B$6,'CHAM_CONG_NGAY'!$C$6:$C$4655,"<="&'THAM_SO'!$B$7),$L6)) | AK6: =IF($B6="","",IF($D6="Theo ngày",SUMIFS('CHAM_CONG_NGAY'!$M$6:$M$4655,'CHAM_CONG_NGAY'!$B$6:$B$4655,$B6,'CHAM_CONG_NGAY'!$C$6:$C$4655,">="&'THAM_SO'!$B$6,'CHAM_CONG_NGAY'!$C$6:$C$4655,"<="&'THAM_SO'!$B$7),$M6)) | AR6: =IF($B6="","",IF($D6="Theo ngày",SUMIFS('CHAM_CONG_NGAY'!$O$6:$O$4655,'CHAM_CONG_NGAY'!$B$6:$B$4655,$B6,'CHAM_CONG_NGAY'!$C$6:$C$4655,">="&'THAM_SO'!$B$6,'CHAM_CONG_NGAY'!$C$6:$C$4655,"<="&'THAM_SO'!$B$7),$AL6)) | AS6: =IF($B6="","",IF($D6="Theo ngày",SUMIFS('CHAM_CONG_NGAY'!$P$6:$P$4655,'CHAM_CONG_NGAY'!$B$6:$B$4655,$B6,'CHAM_CONG_NGAY'!$C$6:$C$4655,">="&'THAM_SO'!$B$6,'CHAM_CONG_NGAY'!$C$6:$C$4655,"<="&'THAM_SO'!$B$7),$AM6)) | AT6: =IF($B6="","",IF($D6="Theo ngày",SUMIFS('CHAM_CONG_NGAY'!$Q$6:$Q$4655,'CHAM_CONG_NGAY'!$B$6:$B$4655,$B6,'CHAM_CONG_NGAY'!$C$6:$C$4655,">="&'THAM_SO'!$B$6,'CHAM_CONG_NGAY'!$C$6:$C$4655,"<="&'THAM_SO'!$B$7),$AN6)) | AU6: =IF($B6="","",IF($D6="Theo ngày",SUMIFS('CHAM_CONG_NGAY'!$R$6:$R$4655,'CHAM_CONG_NGAY'!$B$6:$B$4655,$B6,'CHAM_CONG_NGAY'!$C$6:$C$4655,">="&'THAM_SO'!$B$6,'CHAM_CONG_NGAY'!$C$6:$C$4655,"<="&'THAM_SO'!$B$7),$AO6)) | AV6: =IF($B6="","",IF($D6="Theo ngày",SUMIFS('CHAM_CONG_NGAY'!$S$6:$S$4655,'CHAM_CONG_NGAY'!$B$6:$B$4655,$B6,'CHAM_CONG_NGAY'!$C$6:$C$4655,">="&'THAM_SO'!$B$6,'CHAM_CONG_NGAY'!$C$6:$C$4655,"<="&'THAM_SO'!$B$7),$AP6)) | AW6: =IF($B6="","",IF($D6="Theo ngày",SUMIFS('CHAM_CONG_NGAY'!$T$6:$T$4655,'CHAM_CONG_NGAY'!$B$6:$B$4655,$B6,'CHAM_CONG_NGAY'!$C$6:$C$4655,">="&'THAM_SO'!$B$6,'CHAM_CONG_NGAY'!$C$6:$C$4655,"<="&'THAM_SO'!$B$7),$AQ6))
A7: =IF($B7="","",ROW()-5) | B7: =IF('DM_NHAN_SU'!B7="","",'DM_NHAN_SU'!B7) | C7: =IF('DM_NHAN_SU'!B7="","",'DM_NHAN_SU'!C7) | AC7: =IF($B7="","",IF($D7="Theo ngày",SUMIFS('CHAM_CONG_NGAY'!$E$6:$E$4655,'CHAM_CONG_NGAY'!$B$6:$B$4655,$B7,'CHAM_CONG_NGAY'!$C$6:$C$4655,">="&'THAM_SO'!$B$6,'CHAM_CONG_NGAY'!$C$6:$C$4655,"<="&'THAM_SO'!$B$7),$E7)) | AD7: =IF($B7="","",IF($D7="Theo ngày",SUMIFS('CHAM_CONG_NGAY'!$F$6:$F$4655,'CHAM_CONG_NGAY'!$B$6:$B$4655,$B7,'CHAM_CONG_NGAY'!$C$6:$C$4655,">="&'THAM_SO'!$B$6,'CHAM_CONG_NGAY'!$C$6:$C$4655,"<="&'THAM_SO'!$B$7),$F7)) | AE7: =IF($B7="","",IF($D7="Theo ngày",SUMIFS('CHAM_CONG_NGAY'!$G$6:$G$4655,'CHAM_CONG_NGAY'!$B$6:$B$4655,$B7,'CHAM_CONG_NGAY'!$C$6:$C$4655,">="&'THAM_SO'!$B$6,'CHAM_CONG_NGAY'!$C$6:$C$4655,"<="&'THAM_SO'!$B$7),$G7)) | AF7: =IF($B7="","",IF($D7="Theo ngày",SUMIFS('CHAM_CONG_NGAY'!$H$6:$H$4655,'CHAM_CONG_NGAY'!$B$6:$B$4655,$B7,'CHAM_CONG_NGAY'!$C$6:$C$4655,">="&'THAM_SO'!$B$6,'CHAM_CONG_NGAY'!$C$6:$C$4655,"<="&'THAM_SO'!$B$7),$H7)) | AG7: =IF($B7="","",IF($D7="Theo ngày",SUMIFS('CHAM_CONG_NGAY'!$I$6:$I$4655,'CHAM_CONG_NGAY'!$B$6:$B$4655,$B7,'CHAM_CONG_NGAY'!$C$6:$C$4655,">="&'THAM_SO'!$B$6,'CHAM_CONG_NGAY'!$C$6:$C$4655,"<="&'THAM_SO'!$B$7),$I7)) | AH7: =IF($B7="","",IF($D7="Theo ngày",SUMIFS('CHAM_CONG_NGAY'!$J$6:$J$4655,'CHAM_CONG_NGAY'!$B$6:$B$4655,$B7,'CHAM_CONG_NGAY'!$C$6:$C$4655,">="&'THAM_SO'!$B$6,'CHAM_CONG_NGAY'!$C$6:$C$4655,"<="&'THAM_SO'!$B$7),$J7)) | AI7: =IF($B7="","",IF($D7="Theo ngày",SUMIFS('CHAM_CONG_NGAY'!$K$6:$K$4655,'CHAM_CONG_NGAY'!$B$6:$B$4655,$B7,'CHAM_CONG_NGAY'!$C$6:$C$4655,">="&'THAM_SO'!$B$6,'CHAM_CONG_NGAY'!$C$6:$C$4655,"<="&'THAM_SO'!$B$7),$K7)) | AJ7: =IF($B7="","",IF($D7="Theo ngày",SUMIFS('CHAM_CONG_NGAY'!$L$6:$L$4655,'CHAM_CONG_NGAY'!$B$6:$B$4655,$B7,'CHAM_CONG_NGAY'!$C$6:$C$4655,">="&'THAM_SO'!$B$6,'CHAM_CONG_NGAY'!$C$6:$C$4655,"<="&'THAM_SO'!$B$7),$L7)) | AK7: =IF($B7="","",IF($D7="Theo ngày",SUMIFS('CHAM_CONG_NGAY'!$M$6:$M$4655,'CHAM_CONG_NGAY'!$B$6:$B$4655,$B7,'CHAM_CONG_NGAY'!$C$6:$C$4655,">="&'THAM_SO'!$B$6,'CHAM_CONG_NGAY'!$C$6:$C$4655,"<="&'THAM_SO'!$B$7),$M7)) | AR7: =IF($B7="","",IF($D7="Theo ngày",SUMIFS('CHAM_CONG_NGAY'!$O$6:$O$4655,'CHAM_CONG_NGAY'!$B$6:$B$4655,$B7,'CHAM_CONG_NGAY'!$C$6:$C$4655,">="&'THAM_SO'!$B$6,'CHAM_CONG_NGAY'!$C$6:$C$4655,"<="&'THAM_SO'!$B$7),$AL7)) | AS7: =IF($B7="","",IF($D7="Theo ngày",SUMIFS('CHAM_CONG_NGAY'!$P$6:$P$4655,'CHAM_CONG_NGAY'!$B$6:$B$4655,$B7,'CHAM_CONG_NGAY'!$C$6:$C$4655,">="&'THAM_SO'!$B$6,'CHAM_CONG_NGAY'!$C$6:$C$4655,"<="&'THAM_SO'!$B$7),$AM7)) | AT7: =IF($B7="","",IF($D7="Theo ngày",SUMIFS('CHAM_CONG_NGAY'!$Q$6:$Q$4655,'CHAM_CONG_NGAY'!$B$6:$B$4655,$B7,'CHAM_CONG_NGAY'!$C$6:$C$4655,">="&'THAM_SO'!$B$6,'CHAM_CONG_NGAY'!$C$6:$C$4655,"<="&'THAM_SO'!$B$7),$AN7)) | AU7: =IF($B7="","",IF($D7="Theo ngày",SUMIFS('CHAM_CONG_NGAY'!$R$6:$R$4655,'CHAM_CONG_NGAY'!$B$6:$B$4655,$B7,'CHAM_CONG_NGAY'!$C$6:$C$4655,">="&'THAM_SO'!$B$6,'CHAM_CONG_NGAY'!$C$6:$C$4655,"<="&'THAM_SO'!$B$7),$AO7)) | AV7: =IF($B7="","",IF($D7="Theo ngày",SUMIFS('CHAM_CONG_NGAY'!$S$6:$S$4655,'CHAM_CONG_NGAY'!$B$6:$B$4655,$B7,'CHAM_CONG_NGAY'!$C$6:$C$4655,">="&'THAM_SO'!$B$6,'CHAM_CONG_NGAY'!$C$6:$C$4655,"<="&'THAM_SO'!$B$7),$AP7)) | AW7: =IF($B7="","",IF($D7="Theo ngày",SUMIFS('CHAM_CONG_NGAY'!$T$6:$T$4655,'CHAM_CONG_NGAY'!$B$6:$B$4655,$B7,'CHAM_CONG_NGAY'!$C$6:$C$4655,">="&'THAM_SO'!$B$6,'CHAM_CONG_NGAY'!$C$6:$C$4655,"<="&'THAM_SO'!$B$7),$AQ7))
A8: =IF($B8="","",ROW()-5) | B8: =IF('DM_NHAN_SU'!B8="","",'DM_NHAN_SU'!B8) | C8: =IF('DM_NHAN_SU'!B8="","",'DM_NHAN_SU'!C8) | AC8: =IF($B8="","",IF($D8="Theo ngày",SUMIFS('CHAM_CONG_NGAY'!$E$6:$E$4655,'CHAM_CONG_NGAY'!$B$6:$B$4655,$B8,'CHAM_CONG_NGAY'!$C$6:$C$4655,">="&'THAM_SO'!$B$6,'CHAM_CONG_NGAY'!$C$6:$C$4655,"<="&'THAM_SO'!$B$7),$E8)) | AD8: =IF($B8="","",IF($D8="Theo ngày",SUMIFS('CHAM_CONG_NGAY'!$F$6:$F$4655,'CHAM_CONG_NGAY'!$B$6:$B$4655,$B8,'CHAM_CONG_NGAY'!$C$6:$C$4655,">="&'THAM_SO'!$B$6,'CHAM_CONG_NGAY'!$C$6:$C$4655,"<="&'THAM_SO'!$B$7),$F8)) | AE8: =IF($B8="","",IF($D8="Theo ngày",SUMIFS('CHAM_CONG_NGAY'!$G$6:$G$4655,'CHAM_CONG_NGAY'!$B$6:$B$4655,$B8,'CHAM_CONG_NGAY'!$C$6:$C$4655,">="&'THAM_SO'!$B$6,'CHAM_CONG_NGAY'!$C$6:$C$4655,"<="&'THAM_SO'!$B$7),$G8)) | AF8: =IF($B8="","",IF($D8="Theo ngày",SUMIFS('CHAM_CONG_NGAY'!$H$6:$H$4655,'CHAM_CONG_NGAY'!$B$6:$B$4655,$B8,'CHAM_CONG_NGAY'!$C$6:$C$4655,">="&'THAM_SO'!$B$6,'CHAM_CONG_NGAY'!$C$6:$C$4655,"<="&'THAM_SO'!$B$7),$H8)) | AG8: =IF($B8="","",IF($D8="Theo ngày",SUMIFS('CHAM_CONG_NGAY'!$I$6:$I$4655,'CHAM_CONG_NGAY'!$B$6:$B$4655,$B8,'CHAM_CONG_NGAY'!$C$6:$C$4655,">="&'THAM_SO'!$B$6,'CHAM_CONG_NGAY'!$C$6:$C$4655,"<="&'THAM_SO'!$B$7),$I8)) | AH8: =IF($B8="","",IF($D8="Theo ngày",SUMIFS('CHAM_CONG_NGAY'!$J$6:$J$4655,'CHAM_CONG_NGAY'!$B$6:$B$4655,$B8,'CHAM_CONG_NGAY'!$C$6:$C$4655,">="&'THAM_SO'!$B$6,'CHAM_CONG_NGAY'!$C$6:$C$4655,"<="&'THAM_SO'!$B$7),$J8)) | AI8: =IF($B8="","",IF($D8="Theo ngày",SUMIFS('CHAM_CONG_NGAY'!$K$6:$K$4655,'CHAM_CONG_NGAY'!$B$6:$B$4655,$B8,'CHAM_CONG_NGAY'!$C$6:$C$4655,">="&'THAM_SO'!$B$6,'CHAM_CONG_NGAY'!$C$6:$C$4655,"<="&'THAM_SO'!$B$7),$K8)) | AJ8: =IF($B8="","",IF($D8="Theo ngày",SUMIFS('CHAM_CONG_NGAY'!$L$6:$L$4655,'CHAM_CONG_NGAY'!$B$6:$B$4655,$B8,'CHAM_CONG_NGAY'!$C$6:$C$4655,">="&'THAM_SO'!$B$6,'CHAM_CONG_NGAY'!$C$6:$C$4655,"<="&'THAM_SO'!$B$7),$L8)) | AK8: =IF($B8="","",IF($D8="Theo ngày",SUMIFS('CHAM_CONG_NGAY'!$M$6:$M$4655,'CHAM_CONG_NGAY'!$B$6:$B$4655,$B8,'CHAM_CONG_NGAY'!$C$6:$C$4655,">="&'THAM_SO'!$B$6,'CHAM_CONG_NGAY'!$C$6:$C$4655,"<="&'THAM_SO'!$B$7),$M8)) | AR8: =IF($B8="","",IF($D8="Theo ngày",SUMIFS('CHAM_CONG_NGAY'!$O$6:$O$4655,'CHAM_CONG_NGAY'!$B$6:$B$4655,$B8,'CHAM_CONG_NGAY'!$C$6:$C$4655,">="&'THAM_SO'!$B$6,'CHAM_CONG_NGAY'!$C$6:$C$4655,"<="&'THAM_SO'!$B$7),$AL8)) | AS8: =IF($B8="","",IF($D8="Theo ngày",SUMIFS('CHAM_CONG_NGAY'!$P$6:$P$4655,'CHAM_CONG_NGAY'!$B$6:$B$4655,$B8,'CHAM_CONG_NGAY'!$C$6:$C$4655,">="&'THAM_SO'!$B$6,'CHAM_CONG_NGAY'!$C$6:$C$4655,"<="&'THAM_SO'!$B$7),$AM8)) | AT8: =IF($B8="","",IF($D8="Theo ngày",SUMIFS('CHAM_CONG_NGAY'!$Q$6:$Q$4655,'CHAM_CONG_NGAY'!$B$6:$B$4655,$B8,'CHAM_CONG_NGAY'!$C$6:$C$4655,">="&'THAM_SO'!$B$6,'CHAM_CONG_NGAY'!$C$6:$C$4655,"<="&'THAM_SO'!$B$7),$AN8)) | AU8: =IF($B8="","",IF($D8="Theo ngày",SUMIFS('CHAM_CONG_NGAY'!$R$6:$R$4655,'CHAM_CONG_NGAY'!$B$6:$B$4655,$B8,'CHAM_CONG_NGAY'!$C$6:$C$4655,">="&'THAM_SO'!$B$6,'CHAM_CONG_NGAY'!$C$6:$C$4655,"<="&'THAM_SO'!$B$7),$AO8)) | AV8: =IF($B8="","",IF($D8="Theo ngày",SUMIFS('CHAM_CONG_NGAY'!$S$6:$S$4655,'CHAM_CONG_NGAY'!$B$6:$B$4655,$B8,'CHAM_CONG_NGAY'!$C$6:$C$4655,">="&'THAM_SO'!$B$6,'CHAM_CONG_NGAY'!$C$6:$C$4655,"<="&'THAM_SO'!$B$7),$AP8)) | AW8: =IF($B8="","",IF($D8="Theo ngày",SUMIFS('CHAM_CONG_NGAY'!$T$6:$T$4655,'CHAM_CONG_NGAY'!$B$6:$B$4655,$B8,'CHAM_CONG_NGAY'!$C$6:$C$4655,">="&'THAM_SO'!$B$6,'CHAM_CONG_NGAY'!$C$6:$C$4655,"<="&'THAM_SO'!$B$7),$AQ8))
A9: =IF($B9="","",ROW()-5) | B9: =IF('DM_NHAN_SU'!B9="","",'DM_NHAN_SU'!B9) | C9: =IF('DM_NHAN_SU'!B9="","",'DM_NHAN_SU'!C9) | AC9: =IF($B9="","",IF($D9="Theo ngày",SUMIFS('CHAM_CONG_NGAY'!$E$6:$E$4655,'CHAM_CONG_NGAY'!$B$6:$B$4655,$B9,'CHAM_CONG_NGAY'!$C$6:$C$4655,">="&'THAM_SO'!$B$6,'CHAM_CONG_NGAY'!$C$6:$C$4655,"<="&'THAM_SO'!$B$7),$E9)) | AD9: =IF($B9="","",IF($D9="Theo ngày",SUMIFS('CHAM_CONG_NGAY'!$F$6:$F$4655,'CHAM_CONG_NGAY'!$B$6:$B$4655,$B9,'CHAM_CONG_NGAY'!$C$6:$C$4655,">="&'THAM_SO'!$B$6,'CHAM_CONG_NGAY'!$C$6:$C$4655,"<="&'THAM_SO'!$B$7),$F9)) | AE9: =IF($B9="","",IF($D9="Theo ngày",SUMIFS('CHAM_CONG_NGAY'!$G$6:$G$4655,'CHAM_CONG_NGAY'!$B$6:$B$4655,$B9,'CHAM_CONG_NGAY'!$C$6:$C$4655,">="&'THAM_SO'!$B$6,'CHAM_CONG_NGAY'!$C$6:$C$4655,"<="&'THAM_SO'!$B$7),$G9)) | AF9: =IF($B9="","",IF($D9="Theo ngày",SUMIFS('CHAM_CONG_NGAY'!$H$6:$H$4655,'CHAM_CONG_NGAY'!$B$6:$B$4655,$B9,'CHAM_CONG_NGAY'!$C$6:$C$4655,">="&'THAM_SO'!$B$6,'CHAM_CONG_NGAY'!$C$6:$C$4655,"<="&'THAM_SO'!$B$7),$H9)) | AG9: =IF($B9="","",IF($D9="Theo ngày",SUMIFS('CHAM_CONG_NGAY'!$I$6:$I$4655,'CHAM_CONG_NGAY'!$B$6:$B$4655,$B9,'CHAM_CONG_NGAY'!$C$6:$C$4655,">="&'THAM_SO'!$B$6,'CHAM_CONG_NGAY'!$C$6:$C$4655,"<="&'THAM_SO'!$B$7),$I9)) | AH9: =IF($B9="","",IF($D9="Theo ngày",SUMIFS('CHAM_CONG_NGAY'!$J$6:$J$4655,'CHAM_CONG_NGAY'!$B$6:$B$4655,$B9,'CHAM_CONG_NGAY'!$C$6:$C$4655,">="&'THAM_SO'!$B$6,'CHAM_CONG_NGAY'!$C$6:$C$4655,"<="&'THAM_SO'!$B$7),$J9)) | AI9: =IF($B9="","",IF($D9="Theo ngày",SUMIFS('CHAM_CONG_NGAY'!$K$6:$K$4655,'CHAM_CONG_NGAY'!$B$6:$B$4655,$B9,'CHAM_CONG_NGAY'!$C$6:$C$4655,">="&'THAM_SO'!$B$6,'CHAM_CONG_NGAY'!$C$6:$C$4655,"<="&'THAM_SO'!$B$7),$K9)) | AJ9: =IF($B9="","",IF($D9="Theo ngày",SUMIFS('CHAM_CONG_NGAY'!$L$6:$L$4655,'CHAM_CONG_NGAY'!$B$6:$B$4655,$B9,'CHAM_CONG_NGAY'!$C$6:$C$4655,">="&'THAM_SO'!$B$6,'CHAM_CONG_NGAY'!$C$6:$C$4655,"<="&'THAM_SO'!$B$7),$L9)) | AK9: =IF($B9="","",IF($D9="Theo ngày",SUMIFS('CHAM_CONG_NGAY'!$M$6:$M$4655,'CHAM_CONG_NGAY'!$B$6:$B$4655,$B9,'CHAM_CONG_NGAY'!$C$6:$C$4655,">="&'THAM_SO'!$B$6,'CHAM_CONG_NGAY'!$C$6:$C$4655,"<="&'THAM_SO'!$B$7),$M9)) | AR9: =IF($B9="","",IF($D9="Theo ngày",SUMIFS('CHAM_CONG_NGAY'!$O$6:$O$4655,'CHAM_CONG_NGAY'!$B$6:$B$4655,$B9,'CHAM_CONG_NGAY'!$C$6:$C$4655,">="&'THAM_SO'!$B$6,'CHAM_CONG_NGAY'!$C$6:$C$4655,"<="&'THAM_SO'!$B$7),$AL9)) | AS9: =IF($B9="","",IF($D9="Theo ngày",SUMIFS('CHAM_CONG_NGAY'!$P$6:$P$4655,'CHAM_CONG_NGAY'!$B$6:$B$4655,$B9,'CHAM_CONG_NGAY'!$C$6:$C$4655,">="&'THAM_SO'!$B$6,'CHAM_CONG_NGAY'!$C$6:$C$4655,"<="&'THAM_SO'!$B$7),$AM9)) | AT9: =IF($B9="","",IF($D9="Theo ngày",SUMIFS('CHAM_CONG_NGAY'!$Q$6:$Q$4655,'CHAM_CONG_NGAY'!$B$6:$B$4655,$B9,'CHAM_CONG_NGAY'!$C$6:$C$4655,">="&'THAM_SO'!$B$6,'CHAM_CONG_NGAY'!$C$6:$C$4655,"<="&'THAM_SO'!$B$7),$AN9)) | AU9: =IF($B9="","",IF($D9="Theo ngày",SUMIFS('CHAM_CONG_NGAY'!$R$6:$R$4655,'CHAM_CONG_NGAY'!$B$6:$B$4655,$B9,'CHAM_CONG_NGAY'!$C$6:$C$4655,">="&'THAM_SO'!$B$6,'CHAM_CONG_NGAY'!$C$6:$C$4655,"<="&'THAM_SO'!$B$7),$AO9)) | AV9: =IF($B9="","",IF($D9="Theo ngày",SUMIFS('CHAM_CONG_NGAY'!$S$6:$S$4655,'CHAM_CONG_NGAY'!$B$6:$B$4655,$B9,'CHAM_CONG_NGAY'!$C$6:$C$4655,">="&'THAM_SO'!$B$6,'CHAM_CONG_NGAY'!$C$6:$C$4655,"<="&'THAM_SO'!$B$7),$AP9)) | AW9: =IF($B9="","",IF($D9="Theo ngày",SUMIFS('CHAM_CONG_NGAY'!$T$6:$T$4655,'CHAM_CONG_NGAY'!$B$6:$B$4655,$B9,'CHAM_CONG_NGAY'!$C$6:$C$4655,">="&'THAM_SO'!$B$6,'CHAM_CONG_NGAY'!$C$6:$C$4655,"<="&'THAM_SO'!$B$7),$AQ9))
A10: =IF($B10="","",ROW()-5) | B10: =IF('DM_NHAN_SU'!B10="","",'DM_NHAN_SU'!B10) | C10: =IF('DM_NHAN_SU'!B10="","",'DM_NHAN_SU'!C10) | AC10: =IF($B10="","",IF($D10="Theo ngày",SUMIFS('CHAM_CONG_NGAY'!$E$6:$E$4655,'CHAM_CONG_NGAY'!$B$6:$B$4655,$B10,'CHAM_CONG_NGAY'!$C$6:$C$4655,">="&'THAM_SO'!$B$6,'CHAM_CONG_NGAY'!$C$6:$C$4655,"<="&'THAM_SO'!$B$7),$E10)) | AD10: =IF($B10="","",IF($D10="Theo ngày",SUMIFS('CHAM_CONG_NGAY'!$F$6:$F$4655,'CHAM_CONG_NGAY'!$B$6:$B$4655,$B10,'CHAM_CONG_NGAY'!$C$6:$C$4655,">="&'THAM_SO'!$B$6,'CHAM_CONG_NGAY'!$C$6:$C$4655,"<="&'THAM_SO'!$B$7),$F10)) | AE10: =IF($B10="","",IF($D10="Theo ngày",SUMIFS('CHAM_CONG_NGAY'!$G$6:$G$4655,'CHAM_CONG_NGAY'!$B$6:$B$4655,$B10,'CHAM_CONG_NGAY'!$C$6:$C$4655,">="&'THAM_SO'!$B$6,'CHAM_CONG_NGAY'!$C$6:$C$4655,"<="&'THAM_SO'!$B$7),$G10)) | AF10: =IF($B10="","",IF($D10="Theo ngày",SUMIFS('CHAM_CONG_NGAY'!$H$6:$H$4655,'CHAM_CONG_NGAY'!$B$6:$B$4655,$B10,'CHAM_CONG_NGAY'!$C$6:$C$4655,">="&'THAM_SO'!$B$6,'CHAM_CONG_NGAY'!$C$6:$C$4655,"<="&'THAM_SO'!$B$7),$H10)) | AG10: =IF($B10="","",IF($D10="Theo ngày",SUMIFS('CHAM_CONG_NGAY'!$I$6:$I$4655,'CHAM_CONG_NGAY'!$B$6:$B$4655,$B10,'CHAM_CONG_NGAY'!$C$6:$C$4655,">="&'THAM_SO'!$B$6,'CHAM_CONG_NGAY'!$C$6:$C$4655,"<="&'THAM_SO'!$B$7),$I10)) | AH10: =IF($B10="","",IF($D10="Theo ngày",SUMIFS('CHAM_CONG_NGAY'!$J$6:$J$4655,'CHAM_CONG_NGAY'!$B$6:$B$4655,$B10,'CHAM_CONG_NGAY'!$C$6:$C$4655,">="&'THAM_SO'!$B$6,'CHAM_CONG_NGAY'!$C$6:$C$4655,"<="&'THAM_SO'!$B$7),$J10)) | AI10: =IF($B10="","",IF($D10="Theo ngày",SUMIFS('CHAM_CONG_NGAY'!$K$6:$K$4655,'CHAM_CONG_NGAY'!$B$6:$B$4655,$B10,'CHAM_CONG_NGAY'!$C$6:$C$4655,">="&'THAM_SO'!$B$6,'CHAM_CONG_NGAY'!$C$6:$C$4655,"<="&'THAM_SO'!$B$7),$K10)) | AJ10: =IF($B10="","",IF($D10="Theo ngày",SUMIFS('CHAM_CONG_NGAY'!$L$6:$L$4655,'CHAM_CONG_NGAY'!$B$6:$B$4655,$B10,'CHAM_CONG_NGAY'!$C$6:$C$4655,">="&'THAM_SO'!$B$6,'CHAM_CONG_NGAY'!$C$6:$C$4655,"<="&'THAM_SO'!$B$7),$L10)) | AK10: =IF($B10="","",IF($D10="Theo ngày",SUMIFS('CHAM_CONG_NGAY'!$M$6:$M$4655,'CHAM_CONG_NGAY'!$B$6:$B$4655,$B10,'CHAM_CONG_NGAY'!$C$6:$C$4655,">="&'THAM_SO'!$B$6,'CHAM_CONG_NGAY'!$C$6:$C$4655,"<="&'THAM_SO'!$B$7),$M10)) | AR10: =IF($B10="","",IF($D10="Theo ngày",SUMIFS('CHAM_CONG_NGAY'!$O$6:$O$4655,'CHAM_CONG_NGAY'!$B$6:$B$4655,$B10,'CHAM_CONG_NGAY'!$C$6:$C$4655,">="&'THAM_SO'!$B$6,'CHAM_CONG_NGAY'!$C$6:$C$4655,"<="&'THAM_SO'!$B$7),$AL10)) | AS10: =IF($B10="","",IF($D10="Theo ngày",SUMIFS('CHAM_CONG_NGAY'!$P$6:$P$4655,'CHAM_CONG_NGAY'!$B$6:$B$4655,$B10,'CHAM_CONG_NGAY'!$C$6:$C$4655,">="&'THAM_SO'!$B$6,'CHAM_CONG_NGAY'!$C$6:$C$4655,"<="&'THAM_SO'!$B$7),$AM10)) | AT10: =IF($B10="","",IF($D10="Theo ngày",SUMIFS('CHAM_CONG_NGAY'!$Q$6:$Q$4655,'CHAM_CONG_NGAY'!$B$6:$B$4655,$B10,'CHAM_CONG_NGAY'!$C$6:$C$4655,">="&'THAM_SO'!$B$6,'CHAM_CONG_NGAY'!$C$6:$C$4655,"<="&'THAM_SO'!$B$7),$AN10)) | AU10: =IF($B10="","",IF($D10="Theo ngày",SUMIFS('CHAM_CONG_NGAY'!$R$6:$R$4655,'CHAM_CONG_NGAY'!$B$6:$B$4655,$B10,'CHAM_CONG_NGAY'!$C$6:$C$4655,">="&'THAM_SO'!$B$6,'CHAM_CONG_NGAY'!$C$6:$C$4655,"<="&'THAM_SO'!$B$7),$AO10)) | AV10: =IF($B10="","",IF($D10="Theo ngày",SUMIFS('CHAM_CONG_NGAY'!$S$6:$S$4655,'CHAM_CONG_NGAY'!$B$6:$B$4655,$B10,'CHAM_CONG_NGAY'!$C$6:$C$4655,">="&'THAM_SO'!$B$6,'CHAM_CONG_NGAY'!$C$6:$C$4655,"<="&'THAM_SO'!$B$7),$AP10)) | AW10: =IF($B10="","",IF($D10="Theo ngày",SUMIFS('CHAM_CONG_NGAY'!$T$6:$T$4655,'CHAM_CONG_NGAY'!$B$6:$B$4655,$B10,'CHAM_CONG_NGAY'!$C$6:$C$4655,">="&'THAM_SO'!$B$6,'CHAM_CONG_NGAY'!$C$6:$C$4655,"<="&'THAM_SO'!$B$7),$AQ10))
A11: =IF($B11="","",ROW()-5) | B11: =IF('DM_NHAN_SU'!B11="","",'DM_NHAN_SU'!B11) | C11: =IF('DM_NHAN_SU'!B11="","",'DM_NHAN_SU'!C11) | AC11: =IF($B11="","",IF($D11="Theo ngày",SUMIFS('CHAM_CONG_NGAY'!$E$6:$E$4655,'CHAM_CONG_NGAY'!$B$6:$B$4655,$B11,'CHAM_CONG_NGAY'!$C$6:$C$4655,">="&'THAM_SO'!$B$6,'CHAM_CONG_NGAY'!$C$6:$C$4655,"<="&'THAM_SO'!$B$7),$E11)) | AD11: =IF($B11="","",IF($D11="Theo ngày",SUMIFS('CHAM_CONG_NGAY'!$F$6:$F$4655,'CHAM_CONG_NGAY'!$B$6:$B$4655,$B11,'CHAM_CONG_NGAY'!$C$6:$C$4655,">="&'THAM_SO'!$B$6,'CHAM_CONG_NGAY'!$C$6:$C$4655,"<="&'THAM_SO'!$B$7),$F11)) | AE11: =IF($B11="","",IF($D11="Theo ngày",SUMIFS('CHAM_CONG_NGAY'!$G$6:$G$4655,'CHAM_CONG_NGAY'!$B$6:$B$4655,$B11,'CHAM_CONG_NGAY'!$C$6:$C$4655,">="&'THAM_SO'!$B$6,'CHAM_CONG_NGAY'!$C$6:$C$4655,"<="&'THAM_SO'!$B$7),$G11)) | AF11: =IF($B11="","",IF($D11="Theo ngày",SUMIFS('CHAM_CONG_NGAY'!$H$6:$H$4655,'CHAM_CONG_NGAY'!$B$6:$B$4655,$B11,'CHAM_CONG_NGAY'!$C$6:$C$4655,">="&'THAM_SO'!$B$6,'CHAM_CONG_NGAY'!$C$6:$C$4655,"<="&'THAM_SO'!$B$7),$H11)) | AG11: =IF($B11="","",IF($D11="Theo ngày",SUMIFS('CHAM_CONG_NGAY'!$I$6:$I$4655,'CHAM_CONG_NGAY'!$B$6:$B$4655,$B11,'CHAM_CONG_NGAY'!$C$6:$C$4655,">="&'THAM_SO'!$B$6,'CHAM_CONG_NGAY'!$C$6:$C$4655,"<="&'THAM_SO'!$B$7),$I11)) | AH11: =IF($B11="","",IF($D11="Theo ngày",SUMIFS('CHAM_CONG_NGAY'!$J$6:$J$4655,'CHAM_CONG_NGAY'!$B$6:$B$4655,$B11,'CHAM_CONG_NGAY'!$C$6:$C$4655,">="&'THAM_SO'!$B$6,'CHAM_CONG_NGAY'!$C$6:$C$4655,"<="&'THAM_SO'!$B$7),$J11)) | AI11: =IF($B11="","",IF($D11="Theo ngày",SUMIFS('CHAM_CONG_NGAY'!$K$6:$K$4655,'CHAM_CONG_NGAY'!$B$6:$B$4655,$B11,'CHAM_CONG_NGAY'!$C$6:$C$4655,">="&'THAM_SO'!$B$6,'CHAM_CONG_NGAY'!$C$6:$C$4655,"<="&'THAM_SO'!$B$7),$K11)) | AJ11: =IF($B11="","",IF($D11="Theo ngày",SUMIFS('CHAM_CONG_NGAY'!$L$6:$L$4655,'CHAM_CONG_NGAY'!$B$6:$B$4655,$B11,'CHAM_CONG_NGAY'!$C$6:$C$4655,">="&'THAM_SO'!$B$6,'CHAM_CONG_NGAY'!$C$6:$C$4655,"<="&'THAM_SO'!$B$7),$L11)) | AK11: =IF($B11="","",IF($D11="Theo ngày",SUMIFS('CHAM_CONG_NGAY'!$M$6:$M$4655,'CHAM_CONG_NGAY'!$B$6:$B$4655,$B11,'CHAM_CONG_NGAY'!$C$6:$C$4655,">="&'THAM_SO'!$B$6,'CHAM_CONG_NGAY'!$C$6:$C$4655,"<="&'THAM_SO'!$B$7),$M11)) | AR11: =IF($B11="","",IF($D11="Theo ngày",SUMIFS('CHAM_CONG_NGAY'!$O$6:$O$4655,'CHAM_CONG_NGAY'!$B$6:$B$4655,$B11,'CHAM_CONG_NGAY'!$C$6:$C$4655,">="&'THAM_SO'!$B$6,'CHAM_CONG_NGAY'!$C$6:$C$4655,"<="&'THAM_SO'!$B$7),$AL11)) | AS11: =IF($B11="","",IF($D11="Theo ngày",SUMIFS('CHAM_CONG_NGAY'!$P$6:$P$4655,'CHAM_CONG_NGAY'!$B$6:$B$4655,$B11,'CHAM_CONG_NGAY'!$C$6:$C$4655,">="&'THAM_SO'!$B$6,'CHAM_CONG_NGAY'!$C$6:$C$4655,"<="&'THAM_SO'!$B$7),$AM11)) | AT11: =IF($B11="","",IF($D11="Theo ngày",SUMIFS('CHAM_CONG_NGAY'!$Q$6:$Q$4655,'CHAM_CONG_NGAY'!$B$6:$B$4655,$B11,'CHAM_CONG_NGAY'!$C$6:$C$4655,">="&'THAM_SO'!$B$6,'CHAM_CONG_NGAY'!$C$6:$C$4655,"<="&'THAM_SO'!$B$7),$AN11)) | AU11: =IF($B11="","",IF($D11="Theo ngày",SUMIFS('CHAM_CONG_NGAY'!$R$6:$R$4655,'CHAM_CONG_NGAY'!$B$6:$B$4655,$B11,'CHAM_CONG_NGAY'!$C$6:$C$4655,">="&'THAM_SO'!$B$6,'CHAM_CONG_NGAY'!$C$6:$C$4655,"<="&'THAM_SO'!$B$7),$AO11)) | AV11: =IF($B11="","",IF($D11="Theo ngày",SUMIFS('CHAM_CONG_NGAY'!$S$6:$S$4655,'CHAM_CONG_NGAY'!$B$6:$B$4655,$B11,'CHAM_CONG_NGAY'!$C$6:$C$4655,">="&'THAM_SO'!$B$6,'CHAM_CONG_NGAY'!$C$6:$C$4655,"<="&'THAM_SO'!$B$7),$AP11)) | AW11: =IF($B11="","",IF($D11="Theo ngày",SUMIFS('CHAM_CONG_NGAY'!$T$6:$T$4655,'CHAM_CONG_NGAY'!$B$6:$B$4655,$B11,'CHAM_CONG_NGAY'!$C$6:$C$4655,">="&'THAM_SO'!$B$6,'CHAM_CONG_NGAY'!$C$6:$C$4655,"<="&'THAM_SO'!$B$7),$AQ11))
A12: =IF($B12="","",ROW()-5) | B12: =IF('DM_NHAN_SU'!B12="","",'DM_NHAN_SU'!B12) | C12: =IF('DM_NHAN_SU'!B12="","",'DM_NHAN_SU'!C12) | AC12: =IF($B12="","",IF($D12="Theo ngày",SUMIFS('CHAM_CONG_NGAY'!$E$6:$E$4655,'CHAM_CONG_NGAY'!$B$6:$B$4655,$B12,'CHAM_CONG_NGAY'!$C$6:$C$4655,">="&'THAM_SO'!$B$6,'CHAM_CONG_NGAY'!$C$6:$C$4655,"<="&'THAM_SO'!$B$7),$E12)) | AD12: =IF($B12="","",IF($D12="Theo ngày",SUMIFS('CHAM_CONG_NGAY'!$F$6:$F$4655,'CHAM_CONG_NGAY'!$B$6:$B$4655,$B12,'CHAM_CONG_NGAY'!$C$6:$C$4655,">="&'THAM_SO'!$B$6,'CHAM_CONG_NGAY'!$C$6:$C$4655,"<="&'THAM_SO'!$B$7),$F12)) | AE12: =IF($B12="","",IF($D12="Theo ngày",SUMIFS('CHAM_CONG_NGAY'!$G$6:$G$4655,'CHAM_CONG_NGAY'!$B$6:$B$4655,$B12,'CHAM_CONG_NGAY'!$C$6:$C$4655,">="&'THAM_SO'!$B$6,'CHAM_CONG_NGAY'!$C$6:$C$4655,"<="&'THAM_SO'!$B$7),$G12)) | AF12: =IF($B12="","",IF($D12="Theo ngày",SUMIFS('CHAM_CONG_NGAY'!$H$6:$H$4655,'CHAM_CONG_NGAY'!$B$6:$B$4655,$B12,'CHAM_CONG_NGAY'!$C$6:$C$4655,">="&'THAM_SO'!$B$6,'CHAM_CONG_NGAY'!$C$6:$C$4655,"<="&'THAM_SO'!$B$7),$H12)) | AG12: =IF($B12="","",IF($D12="Theo ngày",SUMIFS('CHAM_CONG_NGAY'!$I$6:$I$4655,'CHAM_CONG_NGAY'!$B$6:$B$4655,$B12,'CHAM_CONG_NGAY'!$C$6:$C$4655,">="&'THAM_SO'!$B$6,'CHAM_CONG_NGAY'!$C$6:$C$4655,"<="&'THAM_SO'!$B$7),$I12)) | AH12: =IF($B12="","",IF($D12="Theo ngày",SUMIFS('CHAM_CONG_NGAY'!$J$6:$J$4655,'CHAM_CONG_NGAY'!$B$6:$B$4655,$B12,'CHAM_CONG_NGAY'!$C$6:$C$4655,">="&'THAM_SO'!$B$6,'CHAM_CONG_NGAY'!$C$6:$C$4655,"<="&'THAM_SO'!$B$7),$J12)) | AI12: =IF($B12="","",IF($D12="Theo ngày",SUMIFS('CHAM_CONG_NGAY'!$K$6:$K$4655,'CHAM_CONG_NGAY'!$B$6:$B$4655,$B12,'CHAM_CONG_NGAY'!$C$6:$C$4655,">="&'THAM_SO'!$B$6,'CHAM_CONG_NGAY'!$C$6:$C$4655,"<="&'THAM_SO'!$B$7),$K12)) | AJ12: =IF($B12="","",IF($D12="Theo ngày",SUMIFS('CHAM_CONG_NGAY'!$L$6:$L$4655,'CHAM_CONG_NGAY'!$B$6:$B$4655,$B12,'CHAM_CONG_NGAY'!$C$6:$C$4655,">="&'THAM_SO'!$B$6,'CHAM_CONG_NGAY'!$C$6:$C$4655,"<="&'THAM_SO'!$B$7),$L12)) | AK12: =IF($B12="","",IF($D12="Theo ngày",SUMIFS('CHAM_CONG_NGAY'!$M$6:$M$4655,'CHAM_CONG_NGAY'!$B$6:$B$4655,$B12,'CHAM_CONG_NGAY'!$C$6:$C$4655,">="&'THAM_SO'!$B$6,'CHAM_CONG_NGAY'!$C$6:$C$4655,"<="&'THAM_SO'!$B$7),$M12)) | AR12: =IF($B12="","",IF($D12="Theo ngày",SUMIFS('CHAM_CONG_NGAY'!$O$6:$O$4655,'CHAM_CONG_NGAY'!$B$6:$B$4655,$B12,'CHAM_CONG_NGAY'!$C$6:$C$4655,">="&'THAM_SO'!$B$6,'CHAM_CONG_NGAY'!$C$6:$C$4655,"<="&'THAM_SO'!$B$7),$AL12)) | AS12: =IF($B12="","",IF($D12="Theo ngày",SUMIFS('CHAM_CONG_NGAY'!$P$6:$P$4655,'CHAM_CONG_NGAY'!$B$6:$B$4655,$B12,'CHAM_CONG_NGAY'!$C$6:$C$4655,">="&'THAM_SO'!$B$6,'CHAM_CONG_NGAY'!$C$6:$C$4655,"<="&'THAM_SO'!$B$7),$AM12)) | AT12: =IF($B12="","",IF($D12="Theo ngày",SUMIFS('CHAM_CONG_NGAY'!$Q$6:$Q$4655,'CHAM_CONG_NGAY'!$B$6:$B$4655,$B12,'CHAM_CONG_NGAY'!$C$6:$C$4655,">="&'THAM_SO'!$B$6,'CHAM_CONG_NGAY'!$C$6:$C$4655,"<="&'THAM_SO'!$B$7),$AN12)) | AU12: =IF($B12="","",IF($D12="Theo ngày",SUMIFS('CHAM_CONG_NGAY'!$R$6:$R$4655,'CHAM_CONG_NGAY'!$B$6:$B$4655,$B12,'CHAM_CONG_NGAY'!$C$6:$C$4655,">="&'THAM_SO'!$B$6,'CHAM_CONG_NGAY'!$C$6:$C$4655,"<="&'THAM_SO'!$B$7),$AO12)) | AV12: =IF($B12="","",IF($D12="Theo ngày",SUMIFS('CHAM_CONG_NGAY'!$S$6:$S$4655,'CHAM_CONG_NGAY'!$B$6:$B$4655,$B12,'CHAM_CONG_NGAY'!$C$6:$C$4655,">="&'THAM_SO'!$B$6,'CHAM_CONG_NGAY'!$C$6:$C$4655,"<="&'THAM_SO'!$B$7),$AP12)) | AW12: =IF($B12="","",IF($D12="Theo ngày",SUMIFS('CHAM_CONG_NGAY'!$T$6:$T$4655,'CHAM_CONG_NGAY'!$B$6:$B$4655,$B12,'CHAM_CONG_NGAY'!$C$6:$C$4655,">="&'THAM_SO'!$B$6,'CHAM_CONG_NGAY'!$C$6:$C$4655,"<="&'THAM_SO'!$B$7),$AQ12))
A13: =IF($B13="","",ROW()-5) | B13: =IF('DM_NHAN_SU'!B13="","",'DM_NHAN_SU'!B13) | C13: =IF('DM_NHAN_SU'!B13="","",'DM_NHAN_SU'!C13) | AC13: =IF($B13="","",IF($D13="Theo ngày",SUMIFS('CHAM_CONG_NGAY'!$E$6:$E$4655,'CHAM_CONG_NGAY'!$B$6:$B$4655,$B13,'CHAM_CONG_NGAY'!$C$6:$C$4655,">="&'THAM_SO'!$B$6,'CHAM_CONG_NGAY'!$C$6:$C$4655,"<="&'THAM_SO'!$B$7),$E13)) | AD13: =IF($B13="","",IF($D13="Theo ngày",SUMIFS('CHAM_CONG_NGAY'!$F$6:$F$4655,'CHAM_CONG_NGAY'!$B$6:$B$4655,$B13,'CHAM_CONG_NGAY'!$C$6:$C$4655,">="&'THAM_SO'!$B$6,'CHAM_CONG_NGAY'!$C$6:$C$4655,"<="&'THAM_SO'!$B$7),$F13)) | AE13: =IF($B13="","",IF($D13="Theo ngày",SUMIFS('CHAM_CONG_NGAY'!$G$6:$G$4655,'CHAM_CONG_NGAY'!$B$6:$B$4655,$B13,'CHAM_CONG_NGAY'!$C$6:$C$4655,">="&'THAM_SO'!$B$6,'CHAM_CONG_NGAY'!$C$6:$C$4655,"<="&'THAM_SO'!$B$7),$G13)) | AF13: =IF($B13="","",IF($D13="Theo ngày",SUMIFS('CHAM_CONG_NGAY'!$H$6:$H$4655,'CHAM_CONG_NGAY'!$B$6:$B$4655,$B13,'CHAM_CONG_NGAY'!$C$6:$C$4655,">="&'THAM_SO'!$B$6,'CHAM_CONG_NGAY'!$C$6:$C$4655,"<="&'THAM_SO'!$B$7),$H13)) | AG13: =IF($B13="","",IF($D13="Theo ngày",SUMIFS('CHAM_CONG_NGAY'!$I$6:$I$4655,'CHAM_CONG_NGAY'!$B$6:$B$4655,$B13,'CHAM_CONG_NGAY'!$C$6:$C$4655,">="&'THAM_SO'!$B$6,'CHAM_CONG_NGAY'!$C$6:$C$4655,"<="&'THAM_SO'!$B$7),$I13)) | AH13: =IF($B13="","",IF($D13="Theo ngày",SUMIFS('CHAM_CONG_NGAY'!$J$6:$J$4655,'CHAM_CONG_NGAY'!$B$6:$B$4655,$B13,'CHAM_CONG_NGAY'!$C$6:$C$4655,">="&'THAM_SO'!$B$6,'CHAM_CONG_NGAY'!$C$6:$C$4655,"<="&'THAM_SO'!$B$7),$J13)) | AI13: =IF($B13="","",IF($D13="Theo ngày",SUMIFS('CHAM_CONG_NGAY'!$K$6:$K$4655,'CHAM_CONG_NGAY'!$B$6:$B$4655,$B13,'CHAM_CONG_NGAY'!$C$6:$C$4655,">="&'THAM_SO'!$B$6,'CHAM_CONG_NGAY'!$C$6:$C$4655,"<="&'THAM_SO'!$B$7),$K13)) | AJ13: =IF($B13="","",IF($D13="Theo ngày",SUMIFS('CHAM_CONG_NGAY'!$L$6:$L$4655,'CHAM_CONG_NGAY'!$B$6:$B$4655,$B13,'CHAM_CONG_NGAY'!$C$6:$C$4655,">="&'THAM_SO'!$B$6,'CHAM_CONG_NGAY'!$C$6:$C$4655,"<="&'THAM_SO'!$B$7),$L13)) | AK13: =IF($B13="","",IF($D13="Theo ngày",SUMIFS('CHAM_CONG_NGAY'!$M$6:$M$4655,'CHAM_CONG_NGAY'!$B$6:$B$4655,$B13,'CHAM_CONG_NGAY'!$C$6:$C$4655,">="&'THAM_SO'!$B$6,'CHAM_CONG_NGAY'!$C$6:$C$4655,"<="&'THAM_SO'!$B$7),$M13)) | AR13: =IF($B13="","",IF($D13="Theo ngày",SUMIFS('CHAM_CONG_NGAY'!$O$6:$O$4655,'CHAM_CONG_NGAY'!$B$6:$B$4655,$B13,'CHAM_CONG_NGAY'!$C$6:$C$4655,">="&'THAM_SO'!$B$6,'CHAM_CONG_NGAY'!$C$6:$C$4655,"<="&'THAM_SO'!$B$7),$AL13)) | AS13: =IF($B13="","",IF($D13="Theo ngày",SUMIFS('CHAM_CONG_NGAY'!$P$6:$P$4655,'CHAM_CONG_NGAY'!$B$6:$B$4655,$B13,'CHAM_CONG_NGAY'!$C$6:$C$4655,">="&'THAM_SO'!$B$6,'CHAM_CONG_NGAY'!$C$6:$C$4655,"<="&'THAM_SO'!$B$7),$AM13)) | AT13: =IF($B13="","",IF($D13="Theo ngày",SUMIFS('CHAM_CONG_NGAY'!$Q$6:$Q$4655,'CHAM_CONG_NGAY'!$B$6:$B$4655,$B13,'CHAM_CONG_NGAY'!$C$6:$C$4655,">="&'THAM_SO'!$B$6,'CHAM_CONG_NGAY'!$C$6:$C$4655,"<="&'THAM_SO'!$B$7),$AN13)) | AU13: =IF($B13="","",IF($D13="Theo ngày",SUMIFS('CHAM_CONG_NGAY'!$R$6:$R$4655,'CHAM_CONG_NGAY'!$B$6:$B$4655,$B13,'CHAM_CONG_NGAY'!$C$6:$C$4655,">="&'THAM_SO'!$B$6,'CHAM_CONG_NGAY'!$C$6:$C$4655,"<="&'THAM_SO'!$B$7),$AO13)) | AV13: =IF($B13="","",IF($D13="Theo ngày",SUMIFS('CHAM_CONG_NGAY'!$S$6:$S$4655,'CHAM_CONG_NGAY'!$B$6:$B$4655,$B13,'CHAM_CONG_NGAY'!$C$6:$C$4655,">="&'THAM_SO'!$B$6,'CHAM_CONG_NGAY'!$C$6:$C$4655,"<="&'THAM_SO'!$B$7),$AP13)) | AW13: =IF($B13="","",IF($D13="Theo ngày",SUMIFS('CHAM_CONG_NGAY'!$T$6:$T$4655,'CHAM_CONG_NGAY'!$B$6:$B$4655,$B13,'CHAM_CONG_NGAY'!$C$6:$C$4655,">="&'THAM_SO'!$B$6,'CHAM_CONG_NGAY'!$C$6:$C$4655,"<="&'THAM_SO'!$B$7),$AQ13))
A14: =IF($B14="","",ROW()-5) | B14: =IF('DM_NHAN_SU'!B14="","",'DM_NHAN_SU'!B14) | C14: =IF('DM_NHAN_SU'!B14="","",'DM_NHAN_SU'!C14) | AC14: =IF($B14="","",IF($D14="Theo ngày",SUMIFS('CHAM_CONG_NGAY'!$E$6:$E$4655,'CHAM_CONG_NGAY'!$B$6:$B$4655,$B14,'CHAM_CONG_NGAY'!$C$6:$C$4655,">="&'THAM_SO'!$B$6,'CHAM_CONG_NGAY'!$C$6:$C$4655,"<="&'THAM_SO'!$B$7),$E14)) | AD14: =IF($B14="","",IF($D14="Theo ngày",SUMIFS('CHAM_CONG_NGAY'!$F$6:$F$4655,'CHAM_CONG_NGAY'!$B$6:$B$4655,$B14,'CHAM_CONG_NGAY'!$C$6:$C$4655,">="&'THAM_SO'!$B$6,'CHAM_CONG_NGAY'!$C$6:$C$4655,"<="&'THAM_SO'!$B$7),$F14)) | AE14: =IF($B14="","",IF($D14="Theo ngày",SUMIFS('CHAM_CONG_NGAY'!$G$6:$G$4655,'CHAM_CONG_NGAY'!$B$6:$B$4655,$B14,'CHAM_CONG_NGAY'!$C$6:$C$4655,">="&'THAM_SO'!$B$6,'CHAM_CONG_NGAY'!$C$6:$C$4655,"<="&'THAM_SO'!$B$7),$G14)) | AF14: =IF($B14="","",IF($D14="Theo ngày",SUMIFS('CHAM_CONG_NGAY'!$H$6:$H$4655,'CHAM_CONG_NGAY'!$B$6:$B$4655,$B14,'CHAM_CONG_NGAY'!$C$6:$C$4655,">="&'THAM_SO'!$B$6,'CHAM_CONG_NGAY'!$C$6:$C$4655,"<="&'THAM_SO'!$B$7),$H14)) | AG14: =IF($B14="","",IF($D14="Theo ngày",SUMIFS('CHAM_CONG_NGAY'!$I$6:$I$4655,'CHAM_CONG_NGAY'!$B$6:$B$4655,$B14,'CHAM_CONG_NGAY'!$C$6:$C$4655,">="&'THAM_SO'!$B$6,'CHAM_CONG_NGAY'!$C$6:$C$4655,"<="&'THAM_SO'!$B$7),$I14)) | AH14: =IF($B14="","",IF($D14="Theo ngày",SUMIFS('CHAM_CONG_NGAY'!$J$6:$J$4655,'CHAM_CONG_NGAY'!$B$6:$B$4655,$B14,'CHAM_CONG_NGAY'!$C$6:$C$4655,">="&'THAM_SO'!$B$6,'CHAM_CONG_NGAY'!$C$6:$C$4655,"<="&'THAM_SO'!$B$7),$J14)) | AI14: =IF($B14="","",IF($D14="Theo ngày",SUMIFS('CHAM_CONG_NGAY'!$K$6:$K$4655,'CHAM_CONG_NGAY'!$B$6:$B$4655,$B14,'CHAM_CONG_NGAY'!$C$6:$C$4655,">="&'THAM_SO'!$B$6,'CHAM_CONG_NGAY'!$C$6:$C$4655,"<="&'THAM_SO'!$B$7),$K14)) | AJ14: =IF($B14="","",IF($D14="Theo ngày",SUMIFS('CHAM_CONG_NGAY'!$L$6:$L$4655,'CHAM_CONG_NGAY'!$B$6:$B$4655,$B14,'CHAM_CONG_NGAY'!$C$6:$C$4655,">="&'THAM_SO'!$B$6,'CHAM_CONG_NGAY'!$C$6:$C$4655,"<="&'THAM_SO'!$B$7),$L14)) | AK14: =IF($B14="","",IF($D14="Theo ngày",SUMIFS('CHAM_CONG_NGAY'!$M$6:$M$4655,'CHAM_CONG_NGAY'!$B$6:$B$4655,$B14,'CHAM_CONG_NGAY'!$C$6:$C$4655,">="&'THAM_SO'!$B$6,'CHAM_CONG_NGAY'!$C$6:$C$4655,"<="&'THAM_SO'!$B$7),$M14)) | AR14: =IF($B14="","",IF($D14="Theo ngày",SUMIFS('CHAM_CONG_NGAY'!$O$6:$O$4655,'CHAM_CONG_NGAY'!$B$6:$B$4655,$B14,'CHAM_CONG_NGAY'!$C$6:$C$4655,">="&'THAM_SO'!$B$6,'CHAM_CONG_NGAY'!$C$6:$C$4655,"<="&'THAM_SO'!$B$7),$AL14)) | AS14: =IF($B14="","",IF($D14="Theo ngày",SUMIFS('CHAM_CONG_NGAY'!$P$6:$P$4655,'CHAM_CONG_NGAY'!$B$6:$B$4655,$B14,'CHAM_CONG_NGAY'!$C$6:$C$4655,">="&'THAM_SO'!$B$6,'CHAM_CONG_NGAY'!$C$6:$C$4655,"<="&'THAM_SO'!$B$7),$AM14)) | AT14: =IF($B14="","",IF($D14="Theo ngày",SUMIFS('CHAM_CONG_NGAY'!$Q$6:$Q$4655,'CHAM_CONG_NGAY'!$B$6:$B$4655,$B14,'CHAM_CONG_NGAY'!$C$6:$C$4655,">="&'THAM_SO'!$B$6,'CHAM_CONG_NGAY'!$C$6:$C$4655,"<="&'THAM_SO'!$B$7),$AN14)) | AU14: =IF($B14="","",IF($D14="Theo ngày",SUMIFS('CHAM_CONG_NGAY'!$R$6:$R$4655,'CHAM_CONG_NGAY'!$B$6:$B$4655,$B14,'CHAM_CONG_NGAY'!$C$6:$C$4655,">="&'THAM_SO'!$B$6,'CHAM_CONG_NGAY'!$C$6:$C$4655,"<="&'THAM_SO'!$B$7),$AO14)) | AV14: =IF($B14="","",IF($D14="Theo ngày",SUMIFS('CHAM_CONG_NGAY'!$S$6:$S$4655,'CHAM_CONG_NGAY'!$B$6:$B$4655,$B14,'CHAM_CONG_NGAY'!$C$6:$C$4655,">="&'THAM_SO'!$B$6,'CHAM_CONG_NGAY'!$C$6:$C$4655,"<="&'THAM_SO'!$B$7),$AP14)) | AW14: =IF($B14="","",IF($D14="Theo ngày",SUMIFS('CHAM_CONG_NGAY'!$T$6:$T$4655,'CHAM_CONG_NGAY'!$B$6:$B$4655,$B14,'CHAM_CONG_NGAY'!$C$6:$C$4655,">="&'THAM_SO'!$B$6,'CHAM_CONG_NGAY'!$C$6:$C$4655,"<="&'THAM_SO'!$B$7),$AQ14))
A15: =IF($B15="","",ROW()-5) | B15: =IF('DM_NHAN_SU'!B15="","",'DM_NHAN_SU'!B15) | C15: =IF('DM_NHAN_SU'!B15="","",'DM_NHAN_SU'!C15) | AC15: =IF($B15="","",IF($D15="Theo ngày",SUMIFS('CHAM_CONG_NGAY'!$E$6:$E$4655,'CHAM_CONG_NGAY'!$B$6:$B$4655,$B15,'CHAM_CONG_NGAY'!$C$6:$C$4655,">="&'THAM_SO'!$B$6,'CHAM_CONG_NGAY'!$C$6:$C$4655,"<="&'THAM_SO'!$B$7),$E15)) | AD15: =IF($B15="","",IF($D15="Theo ngày",SUMIFS('CHAM_CONG_NGAY'!$F$6:$F$4655,'CHAM_CONG_NGAY'!$B$6:$B$4655,$B15,'CHAM_CONG_NGAY'!$C$6:$C$4655,">="&'THAM_SO'!$B$6,'CHAM_CONG_NGAY'!$C$6:$C$4655,"<="&'THAM_SO'!$B$7),$F15)) | AE15: =IF($B15="","",IF($D15="Theo ngày",SUMIFS('CHAM_CONG_NGAY'!$G$6:$G$4655,'CHAM_CONG_NGAY'!$B$6:$B$4655,$B15,'CHAM_CONG_NGAY'!$C$6:$C$4655,">="&'THAM_SO'!$B$6,'CHAM_CONG_NGAY'!$C$6:$C$4655,"<="&'THAM_SO'!$B$7),$G15)) | AF15: =IF($B15="","",IF($D15="Theo ngày",SUMIFS('CHAM_CONG_NGAY'!$H$6:$H$4655,'CHAM_CONG_NGAY'!$B$6:$B$4655,$B15,'CHAM_CONG_NGAY'!$C$6:$C$4655,">="&'THAM_SO'!$B$6,'CHAM_CONG_NGAY'!$C$6:$C$4655,"<="&'THAM_SO'!$B$7),$H15)) | AG15: =IF($B15="","",IF($D15="Theo ngày",SUMIFS('CHAM_CONG_NGAY'!$I$6:$I$4655,'CHAM_CONG_NGAY'!$B$6:$B$4655,$B15,'CHAM_CONG_NGAY'!$C$6:$C$4655,">="&'THAM_SO'!$B$6,'CHAM_CONG_NGAY'!$C$6:$C$4655,"<="&'THAM_SO'!$B$7),$I15)) | AH15: =IF($B15="","",IF($D15="Theo ngày",SUMIFS('CHAM_CONG_NGAY'!$J$6:$J$4655,'CHAM_CONG_NGAY'!$B$6:$B$4655,$B15,'CHAM_CONG_NGAY'!$C$6:$C$4655,">="&'THAM_SO'!$B$6,'CHAM_CONG_NGAY'!$C$6:$C$4655,"<="&'THAM_SO'!$B$7),$J15)) | AI15: =IF($B15="","",IF($D15="Theo ngày",SUMIFS('CHAM_CONG_NGAY'!$K$6:$K$4655,'CHAM_CONG_NGAY'!$B$6:$B$4655,$B15,'CHAM_CONG_NGAY'!$C$6:$C$4655,">="&'THAM_SO'!$B$6,'CHAM_CONG_NGAY'!$C$6:$C$4655,"<="&'THAM_SO'!$B$7),$K15)) | AJ15: =IF($B15="","",IF($D15="Theo ngày",SUMIFS('CHAM_CONG_NGAY'!$L$6:$L$4655,'CHAM_CONG_NGAY'!$B$6:$B$4655,$B15,'CHAM_CONG_NGAY'!$C$6:$C$4655,">="&'THAM_SO'!$B$6,'CHAM_CONG_NGAY'!$C$6:$C$4655,"<="&'THAM_SO'!$B$7),$L15)) | AK15: =IF($B15="","",IF($D15="Theo ngày",SUMIFS('CHAM_CONG_NGAY'!$M$6:$M$4655,'CHAM_CONG_NGAY'!$B$6:$B$4655,$B15,'CHAM_CONG_NGAY'!$C$6:$C$4655,">="&'THAM_SO'!$B$6,'CHAM_CONG_NGAY'!$C$6:$C$4655,"<="&'THAM_SO'!$B$7),$M15)) | AR15: =IF($B15="","",IF($D15="Theo ngày",SUMIFS('CHAM_CONG_NGAY'!$O$6:$O$4655,'CHAM_CONG_NGAY'!$B$6:$B$4655,$B15,'CHAM_CONG_NGAY'!$C$6:$C$4655,">="&'THAM_SO'!$B$6,'CHAM_CONG_NGAY'!$C$6:$C$4655,"<="&'THAM_SO'!$B$7),$AL15)) | AS15: =IF($B15="","",IF($D15="Theo ngày",SUMIFS('CHAM_CONG_NGAY'!$P$6:$P$4655,'CHAM_CONG_NGAY'!$B$6:$B$4655,$B15,'CHAM_CONG_NGAY'!$C$6:$C$4655,">="&'THAM_SO'!$B$6,'CHAM_CONG_NGAY'!$C$6:$C$4655,"<="&'THAM_SO'!$B$7),$AM15)) | AT15: =IF($B15="","",IF($D15="Theo ngày",SUMIFS('CHAM_CONG_NGAY'!$Q$6:$Q$4655,'CHAM_CONG_NGAY'!$B$6:$B$4655,$B15,'CHAM_CONG_NGAY'!$C$6:$C$4655,">="&'THAM_SO'!$B$6,'CHAM_CONG_NGAY'!$C$6:$C$4655,"<="&'THAM_SO'!$B$7),$AN15)) | AU15: =IF($B15="","",IF($D15="Theo ngày",SUMIFS('CHAM_CONG_NGAY'!$R$6:$R$4655,'CHAM_CONG_NGAY'!$B$6:$B$4655,$B15,'CHAM_CONG_NGAY'!$C$6:$C$4655,">="&'THAM_SO'!$B$6,'CHAM_CONG_NGAY'!$C$6:$C$4655,"<="&'THAM_SO'!$B$7),$AO15)) | AV15: =IF($B15="","",IF($D15="Theo ngày",SUMIFS('CHAM_CONG_NGAY'!$S$6:$S$4655,'CHAM_CONG_NGAY'!$B$6:$B$4655,$B15,'CHAM_CONG_NGAY'!$C$6:$C$4655,">="&'THAM_SO'!$B$6,'CHAM_CONG_NGAY'!$C$6:$C$4655,"<="&'THAM_SO'!$B$7),$AP15)) | AW15: =IF($B15="","",IF($D15="Theo ngày",SUMIFS('CHAM_CONG_NGAY'!$T$6:$T$4655,'CHAM_CONG_NGAY'!$B$6:$B$4655,$B15,'CHAM_CONG_NGAY'!$C$6:$C$4655,">="&'THAM_SO'!$B$6,'CHAM_CONG_NGAY'!$C$6:$C$4655,"<="&'THAM_SO'!$B$7),$AQ15))
A16: =IF($B16="","",ROW()-5) | B16: =IF('DM_NHAN_SU'!B16="","",'DM_NHAN_SU'!B16) | C16: =IF('DM_NHAN_SU'!B16="","",'DM_NHAN_SU'!C16) | AC16: =IF($B16="","",IF($D16="Theo ngày",SUMIFS('CHAM_CONG_NGAY'!$E$6:$E$4655,'CHAM_CONG_NGAY'!$B$6:$B$4655,$B16,'CHAM_CONG_NGAY'!$C$6:$C$4655,">="&'THAM_SO'!$B$6,'CHAM_CONG_NGAY'!$C$6:$C$4655,"<="&'THAM_SO'!$B$7),$E16)) | AD16: =IF($B16="","",IF($D16="Theo ngày",SUMIFS('CHAM_CONG_NGAY'!$F$6:$F$4655,'CHAM_CONG_NGAY'!$B$6:$B$4655,$B16,'CHAM_CONG_NGAY'!$C$6:$C$4655,">="&'THAM_SO'!$B$6,'CHAM_CONG_NGAY'!$C$6:$C$4655,"<="&'THAM_SO'!$B$7),$F16)) | AE16: =IF($B16="","",IF($D16="Theo ngày",SUMIFS('CHAM_CONG_NGAY'!$G$6:$G$4655,'CHAM_CONG_NGAY'!$B$6:$B$4655,$B16,'CHAM_CONG_NGAY'!$C$6:$C$4655,">="&'THAM_SO'!$B$6,'CHAM_CONG_NGAY'!$C$6:$C$4655,"<="&'THAM_SO'!$B$7),$G16)) | AF16: =IF($B16="","",IF($D16="Theo ngày",SUMIFS('CHAM_CONG_NGAY'!$H$6:$H$4655,'CHAM_CONG_NGAY'!$B$6:$B$4655,$B16,'CHAM_CONG_NGAY'!$C$6:$C$4655,">="&'THAM_SO'!$B$6,'CHAM_CONG_NGAY'!$C$6:$C$4655,"<="&'THAM_SO'!$B$7),$H16)) | AG16: =IF($B16="","",IF($D16="Theo ngày",SUMIFS('CHAM_CONG_NGAY'!$I$6:$I$4655,'CHAM_CONG_NGAY'!$B$6:$B$4655,$B16,'CHAM_CONG_NGAY'!$C$6:$C$4655,">="&'THAM_SO'!$B$6,'CHAM_CONG_NGAY'!$C$6:$C$4655,"<="&'THAM_SO'!$B$7),$I16)) | AH16: =IF($B16="","",IF($D16="Theo ngày",SUMIFS('CHAM_CONG_NGAY'!$J$6:$J$4655,'CHAM_CONG_NGAY'!$B$6:$B$4655,$B16,'CHAM_CONG_NGAY'!$C$6:$C$4655,">="&'THAM_SO'!$B$6,'CHAM_CONG_NGAY'!$C$6:$C$4655,"<="&'THAM_SO'!$B$7),$J16)) | AI16: =IF($B16="","",IF($D16="Theo ngày",SUMIFS('CHAM_CONG_NGAY'!$K$6:$K$4655,'CHAM_CONG_NGAY'!$B$6:$B$4655,$B16,'CHAM_CONG_NGAY'!$C$6:$C$4655,">="&'THAM_SO'!$B$6,'CHAM_CONG_NGAY'!$C$6:$C$4655,"<="&'THAM_SO'!$B$7),$K16)) | AJ16: =IF($B16="","",IF($D16="Theo ngày",SUMIFS('CHAM_CONG_NGAY'!$L$6:$L$4655,'CHAM_CONG_NGAY'!$B$6:$B$4655,$B16,'CHAM_CONG_NGAY'!$C$6:$C$4655,">="&'THAM_SO'!$B$6,'CHAM_CONG_NGAY'!$C$6:$C$4655,"<="&'THAM_SO'!$B$7),$L16)) | AK16: =IF($B16="","",IF($D16="Theo ngày",SUMIFS('CHAM_CONG_NGAY'!$M$6:$M$4655,'CHAM_CONG_NGAY'!$B$6:$B$4655,$B16,'CHAM_CONG_NGAY'!$C$6:$C$4655,">="&'THAM_SO'!$B$6,'CHAM_CONG_NGAY'!$C$6:$C$4655,"<="&'THAM_SO'!$B$7),$M16)) | AR16: =IF($B16="","",IF($D16="Theo ngày",SUMIFS('CHAM_CONG_NGAY'!$O$6:$O$4655,'CHAM_CONG_NGAY'!$B$6:$B$4655,$B16,'CHAM_CONG_NGAY'!$C$6:$C$4655,">="&'THAM_SO'!$B$6,'CHAM_CONG_NGAY'!$C$6:$C$4655,"<="&'THAM_SO'!$B$7),$AL16)) | AS16: =IF($B16="","",IF($D16="Theo ngày",SUMIFS('CHAM_CONG_NGAY'!$P$6:$P$4655,'CHAM_CONG_NGAY'!$B$6:$B$4655,$B16,'CHAM_CONG_NGAY'!$C$6:$C$4655,">="&'THAM_SO'!$B$6,'CHAM_CONG_NGAY'!$C$6:$C$4655,"<="&'THAM_SO'!$B$7),$AM16)) | AT16: =IF($B16="","",IF($D16="Theo ngày",SUMIFS('CHAM_CONG_NGAY'!$Q$6:$Q$4655,'CHAM_CONG_NGAY'!$B$6:$B$4655,$B16,'CHAM_CONG_NGAY'!$C$6:$C$4655,">="&'THAM_SO'!$B$6,'CHAM_CONG_NGAY'!$C$6:$C$4655,"<="&'THAM_SO'!$B$7),$AN16)) | AU16: =IF($B16="","",IF($D16="Theo ngày",SUMIFS('CHAM_CONG_NGAY'!$R$6:$R$4655,'CHAM_CONG_NGAY'!$B$6:$B$4655,$B16,'CHAM_CONG_NGAY'!$C$6:$C$4655,">="&'THAM_SO'!$B$6,'CHAM_CONG_NGAY'!$C$6:$C$4655,"<="&'THAM_SO'!$B$7),$AO16)) | AV16: =IF($B16="","",IF($D16="Theo ngày",SUMIFS('CHAM_CONG_NGAY'!$S$6:$S$4655,'CHAM_CONG_NGAY'!$B$6:$B$4655,$B16,'CHAM_CONG_NGAY'!$C$6:$C$4655,">="&'THAM_SO'!$B$6,'CHAM_CONG_NGAY'!$C$6:$C$4655,"<="&'THAM_SO'!$B$7),$AP16)) | AW16: =IF($B16="","",IF($D16="Theo ngày",SUMIFS('CHAM_CONG_NGAY'!$T$6:$T$4655,'CHAM_CONG_NGAY'!$B$6:$B$4655,$B16,'CHAM_CONG_NGAY'!$C$6:$C$4655,">="&'THAM_SO'!$B$6,'CHAM_CONG_NGAY'!$C$6:$C$4655,"<="&'THAM_SO'!$B$7),$AQ16))
A17: =IF($B17="","",ROW()-5) | B17: =IF('DM_NHAN_SU'!B17="","",'DM_NHAN_SU'!B17) | C17: =IF('DM_NHAN_SU'!B17="","",'DM_NHAN_SU'!C17) | AC17: =IF($B17="","",IF($D17="Theo ngày",SUMIFS('CHAM_CONG_NGAY'!$E$6:$E$4655,'CHAM_CONG_NGAY'!$B$6:$B$4655,$B17,'CHAM_CONG_NGAY'!$C$6:$C$4655,">="&'THAM_SO'!$B$6,'CHAM_CONG_NGAY'!$C$6:$C$4655,"<="&'THAM_SO'!$B$7),$E17)) | AD17: =IF($B17="","",IF($D17="Theo ngày",SUMIFS('CHAM_CONG_NGAY'!$F$6:$F$4655,'CHAM_CONG_NGAY'!$B$6:$B$4655,$B17,'CHAM_CONG_NGAY'!$C$6:$C$4655,">="&'THAM_SO'!$B$6,'CHAM_CONG_NGAY'!$C$6:$C$4655,"<="&'THAM_SO'!$B$7),$F17)) | AE17: =IF($B17="","",IF($D17="Theo ngày",SUMIFS('CHAM_CONG_NGAY'!$G$6:$G$4655,'CHAM_CONG_NGAY'!$B$6:$B$4655,$B17,'CHAM_CONG_NGAY'!$C$6:$C$4655,">="&'THAM_SO'!$B$6,'CHAM_CONG_NGAY'!$C$6:$C$4655,"<="&'THAM_SO'!$B$7),$G17)) | AF17: =IF($B17="","",IF($D17="Theo ngày",SUMIFS('CHAM_CONG_NGAY'!$H$6:$H$4655,'CHAM_CONG_NGAY'!$B$6:$B$4655,$B17,'CHAM_CONG_NGAY'!$C$6:$C$4655,">="&'THAM_SO'!$B$6,'CHAM_CONG_NGAY'!$C$6:$C$4655,"<="&'THAM_SO'!$B$7),$H17)) | AG17: =IF($B17="","",IF($D17="Theo ngày",SUMIFS('CHAM_CONG_NGAY'!$I$6:$I$4655,'CHAM_CONG_NGAY'!$B$6:$B$4655,$B17,'CHAM_CONG_NGAY'!$C$6:$C$4655,">="&'THAM_SO'!$B$6,'CHAM_CONG_NGAY'!$C$6:$C$4655,"<="&'THAM_SO'!$B$7),$I17)) | AH17: =IF($B17="","",IF($D17="Theo ngày",SUMIFS('CHAM_CONG_NGAY'!$J$6:$J$4655,'CHAM_CONG_NGAY'!$B$6:$B$4655,$B17,'CHAM_CONG_NGAY'!$C$6:$C$4655,">="&'THAM_SO'!$B$6,'CHAM_CONG_NGAY'!$C$6:$C$4655,"<="&'THAM_SO'!$B$7),$J17)) | AI17: =IF($B17="","",IF($D17="Theo ngày",SUMIFS('CHAM_CONG_NGAY'!$K$6:$K$4655,'CHAM_CONG_NGAY'!$B$6:$B$4655,$B17,'CHAM_CONG_NGAY'!$C$6:$C$4655,">="&'THAM_SO'!$B$6,'CHAM_CONG_NGAY'!$C$6:$C$4655,"<="&'THAM_SO'!$B$7),$K17)) | AJ17: =IF($B17="","",IF($D17="Theo ngày",SUMIFS('CHAM_CONG_NGAY'!$L$6:$L$4655,'CHAM_CONG_NGAY'!$B$6:$B$4655,$B17,'CHAM_CONG_NGAY'!$C$6:$C$4655,">="&'THAM_SO'!$B$6,'CHAM_CONG_NGAY'!$C$6:$C$4655,"<="&'THAM_SO'!$B$7),$L17)) | AK17: =IF($B17="","",IF($D17="Theo ngày",SUMIFS('CHAM_CONG_NGAY'!$M$6:$M$4655,'CHAM_CONG_NGAY'!$B$6:$B$4655,$B17,'CHAM_CONG_NGAY'!$C$6:$C$4655,">="&'THAM_SO'!$B$6,'CHAM_CONG_NGAY'!$C$6:$C$4655,"<="&'THAM_SO'!$B$7),$M17)) | AR17: =IF($B17="","",IF($D17="Theo ngày",SUMIFS('CHAM_CONG_NGAY'!$O$6:$O$4655,'CHAM_CONG_NGAY'!$B$6:$B$4655,$B17,'CHAM_CONG_NGAY'!$C$6:$C$4655,">="&'THAM_SO'!$B$6,'CHAM_CONG_NGAY'!$C$6:$C$4655,"<="&'THAM_SO'!$B$7),$AL17)) | AS17: =IF($B17="","",IF($D17="Theo ngày",SUMIFS('CHAM_CONG_NGAY'!$P$6:$P$4655,'CHAM_CONG_NGAY'!$B$6:$B$4655,$B17,'CHAM_CONG_NGAY'!$C$6:$C$4655,">="&'THAM_SO'!$B$6,'CHAM_CONG_NGAY'!$C$6:$C$4655,"<="&'THAM_SO'!$B$7),$AM17)) | AT17: =IF($B17="","",IF($D17="Theo ngày",SUMIFS('CHAM_CONG_NGAY'!$Q$6:$Q$4655,'CHAM_CONG_NGAY'!$B$6:$B$4655,$B17,'CHAM_CONG_NGAY'!$C$6:$C$4655,">="&'THAM_SO'!$B$6,'CHAM_CONG_NGAY'!$C$6:$C$4655,"<="&'THAM_SO'!$B$7),$AN17)) | AU17: =IF($B17="","",IF($D17="Theo ngày",SUMIFS('CHAM_CONG_NGAY'!$R$6:$R$4655,'CHAM_CONG_NGAY'!$B$6:$B$4655,$B17,'CHAM_CONG_NGAY'!$C$6:$C$4655,">="&'THAM_SO'!$B$6,'CHAM_CONG_NGAY'!$C$6:$C$4655,"<="&'THAM_SO'!$B$7),$AO17)) | AV17: =IF($B17="","",IF($D17="Theo ngày",SUMIFS('CHAM_CONG_NGAY'!$S$6:$S$4655,'CHAM_CONG_NGAY'!$B$6:$B$4655,$B17,'CHAM_CONG_NGAY'!$C$6:$C$4655,">="&'THAM_SO'!$B$6,'CHAM_CONG_NGAY'!$C$6:$C$4655,"<="&'THAM_SO'!$B$7),$AP17)) | AW17: =IF($B17="","",IF($D17="Theo ngày",SUMIFS('CHAM_CONG_NGAY'!$T$6:$T$4655,'CHAM_CONG_NGAY'!$B$6:$B$4655,$B17,'CHAM_CONG_NGAY'!$C$6:$C$4655,">="&'THAM_SO'!$B$6,'CHAM_CONG_NGAY'!$C$6:$C$4655,"<="&'THAM_SO'!$B$7),$AQ17))
... A155: =IF($B155="","",ROW()-5) | B155: =IF('DM_NHAN_SU'!B155="","",'DM_NHAN_SU'!B155) | C155: =IF('DM_NHAN_SU'!B155="","",'DM_NHAN_SU'!C155) | AC155: =IF($B155="","",IF($D155="Theo ngày",SUMIFS('CHAM_CONG_NGAY'!$E$6:$E$4655,'CHAM_CONG_NGAY'!$B$6:$B$4655,$B155,'CHAM_CONG_NGAY'!$C$6:$C$4655,">="&'THAM_SO'!$B$6,'CHAM_CONG_NGAY'!$C$6:$C$4655,"<="&'THAM_SO'!$B$7),$E155)) | AD155: =IF($B155="","",IF($D155="Theo ngày",SUMIFS('CHAM_CONG_NGAY'!$F$6:$F$4655,'CHAM_CONG_NGAY'!$B$6:$B$4655,$B155,'CHAM_CONG_NGAY'!$C$6:$C$4655,">="&'THAM_SO'!$B$6,'CHAM_CONG_NGAY'!$C$6:$C$4655,"<="&'THAM_SO'!$B$7),$F155)) | AE155: =IF($B155="","",IF($D155="Theo ngày",SUMIFS('CHAM_CONG_NGAY'!$G$6:$G$4655,'CHAM_CONG_NGAY'!$B$6:$B$4655,$B155,'CHAM_CONG_NGAY'!$C$6:$C$4655,">="&'THAM_SO'!$B$6,'CHAM_CONG_NGAY'!$C$6:$C$4655,"<="&'THAM_SO'!$B$7),$G155)) | AF155: =IF($B155="","",IF($D155="Theo ngày",SUMIFS('CHAM_CONG_NGAY'!$H$6:$H$4655,'CHAM_CONG_NGAY'!$B$6:$B$4655,$B155,'CHAM_CONG_NGAY'!$C$6:$C$4655,">="&'THAM_SO'!$B$6,'CHAM_CONG_NGAY'!$C$6:$C$4655,"<="&'THAM_SO'!$B$7),$H155)) | AG155: =IF($B155="","",IF($D155="Theo ngày",SUMIFS('CHAM_CONG_NGAY'!$I$6:$I$4655,'CHAM_CONG_NGAY'!$B$6:$B$4655,$B155,'CHAM_CONG_NGAY'!$C$6:$C$4655,">="&'THAM_SO'!$B$6,'CHAM_CONG_NGAY'!$C$6:$C$4655,"<="&'THAM_SO'!$B$7),$I155)) | AH155: =IF($B155="","",IF($D155="Theo ngày",SUMIFS('CHAM_CONG_NGAY'!$J$6:$J$4655,'CHAM_CONG_NGAY'!$B$6:$B$4655,$B155,'CHAM_CONG_NGAY'!$C$6:$C$4655,">="&'THAM_SO'!$B$6,'CHAM_CONG_NGAY'!$C$6:$C$4655,"<="&'THAM_SO'!$B$7),$J155)) | AI155: =IF($B155="","",IF($D155="Theo ngày",SUMIFS('CHAM_CONG_NGAY'!$K$6:$K$4655,'CHAM_CONG_NGAY'!$B$6:$B$4655,$B155,'CHAM_CONG_NGAY'!$C$6:$C$4655,">="&'THAM_SO'!$B$6,'CHAM_CONG_NGAY'!$C$6:$C$4655,"<="&'THAM_SO'!$B$7),$K155)) | AJ155: =IF($B155="","",IF($D155="Theo ngày",SUMIFS('CHAM_CONG_NGAY'!$L$6:$L$4655,'CHAM_CONG_NGAY'!$B$6:$B$4655,$B155,'CHAM_CONG_NGAY'!$C$6:$C$4655,">="&'THAM_SO'!$B$6,'CHAM_CONG_NGAY'!$C$6:$C$4655,"<="&'THAM_SO'!$B$7),$L155)) | AK155: =IF($B155="","",IF($D155="Theo ngày",SUMIFS('CHAM_CONG_NGAY'!$M$6:$M$4655,'CHAM_CONG_NGAY'!$B$6:$B$4655,$B155,'CHAM_CONG_NGAY'!$C$6:$C$4655,">="&'THAM_SO'!$B$6,'CHAM_CONG_NGAY'!$C$6:$C$4655,"<="&'THAM_SO'!$B$7),$M155)) | AR155: =IF($B155="","",IF($D155="Theo ngày",SUMIFS('CHAM_CONG_NGAY'!$O$6:$O$4655,'CHAM_CONG_NGAY'!$B$6:$B$4655,$B155,'CHAM_CONG_NGAY'!$C$6:$C$4655,">="&'THAM_SO'!$B$6,'CHAM_CONG_NGAY'!$C$6:$C$4655,"<="&'THAM_SO'!$B$7),$AL155)) | AS155: =IF($B155="","",IF($D155="Theo ngày",SUMIFS('CHAM_CONG_NGAY'!$P$6:$P$4655,'CHAM_CONG_NGAY'!$B$6:$B$4655,$B155,'CHAM_CONG_NGAY'!$C$6:$C$4655,">="&'THAM_SO'!$B$6,'CHAM_CONG_NGAY'!$C$6:$C$4655,"<="&'THAM_SO'!$B$7),$AM155)) | AT155: =IF($B155="","",IF($D155="Theo ngày",SUMIFS('CHAM_CONG_NGAY'!$Q$6:$Q$4655,'CHAM_CONG_NGAY'!$B$6:$B$4655,$B155,'CHAM_CONG_NGAY'!$C$6:$C$4655,">="&'THAM_SO'!$B$6,'CHAM_CONG_NGAY'!$C$6:$C$4655,"<="&'THAM_SO'!$B$7),$AN155)) | AU155: =IF($B155="","",IF($D155="Theo ngày",SUMIFS('CHAM_CONG_NGAY'!$R$6:$R$4655,'CHAM_CONG_NGAY'!$B$6:$B$4655,$B155,'CHAM_CONG_NGAY'!$C$6:$C$4655,">="&'THAM_SO'!$B$6,'CHAM_CONG_NGAY'!$C$6:$C$4655,"<="&'THAM_SO'!$B$7),$AO155)) | AV155: =IF($B155="","",IF($D155="Theo ngày",SUMIFS('CHAM_CONG_NGAY'!$S$6:$S$4655,'CHAM_CONG_NGAY'!$B$6:$B$4655,$B155,'CHAM_CONG_NGAY'!$C$6:$C$4655,">="&'THAM_SO'!$B$6,'CHAM_CONG_NGAY'!$C$6:$C$4655,"<="&'THAM_SO'!$B$7),$AP155)) | AW155: =IF($B155="","",IF($D155="Theo ngày",SUMIFS('CHAM_CONG_NGAY'!$T$6:$T$4655,'CHAM_CONG_NGAY'!$B$6:$B$4655,$B155,'CHAM_CONG_NGAY'!$C$6:$C$4655,">="&'THAM_SO'!$B$6,'CHAM_CONG_NGAY'!$C$6:$C$4655,"<="&'THAM_SO'!$B$7),$AQ155))

Sheet CHAM_CONG_NGAY
A1: CHẤM CÔNG CHI TIẾT THEO NGÀY
A2: Chỉ nhập cho nhân viên chọn nguồn “Theo ngày”. Cột E là ngày thực tế làm việc, không gồm phép/lễ/việc riêng hưởng lương; nhập các loại nghỉ riêng tại O:T để tránh tính trùng. Giờ đêm trong ca là phần 22:00–06:00 đã nằm trong giờ thường; file chỉ cộng phần trả thêm ban đêm.
A5: STT | B5: Mã NV | C5: Ngày | D5: Ký hiệu | E5: Công làm việc | F5: Giờ thường | G5: Giờ đêm trong ca | H5: OT thường ngày | I5: OT nghỉ tuần ngày | J5: OT lễ ngày | K5: OT thường đêm | L5: OT nghỉ tuần đêm | M5: OT lễ đêm | N5: Ghi chú | O5: Phép năm hưởng lương | P5: Lễ/Tết hưởng lương | Q5: Việc riêng hưởng lương | R5: Nghỉ ốm hưởng BHXH | S5: Nghỉ thai sản | T5: Nghỉ không lương
A6: =IF($B6="","",ROW()-5)
A7: =IF($B7="","",ROW()-5)
A8: =IF($B8="","",ROW()-5)
A9: =IF($B9="","",ROW()-5)
A10: =IF($B10="","",ROW()-5)
A11: =IF($B11="","",ROW()-5)
A12: =IF($B12="","",ROW()-5)
A13: =IF($B13="","",ROW()-5)
A14: =IF($B14="","",ROW()-5)
A15: =IF($B15="","",ROW()-5)
A16: =IF($B16="","",ROW()-5)
A17: =IF($B17="","",ROW()-5)
... A4655: =IF($B4655="","",ROW()-5)

Sheet NGHI_PHEP
A1: THEO DÕI PHÉP NĂM
A2: Phép cơ bản lấy từ DM_NHAN_SU; nếu bỏ trống, file tạm dùng 12 ngày và cảnh báo. Người dùng phải điều chỉnh đối tượng 14/16 ngày, tỷ lệ làm chưa đủ 12 tháng, thâm niên, phép chuyển sang và quy chế doanh nghiệp. Cột J dùng cho mọi điều chỉnh tăng/giảm có hồ sơ.
A5: STT | B5: Mã NV | C5: Họ và tên | D5: Phép cơ bản | E5: Tăng do thâm niên | F5: Chuyển sang | G5: Tổng quyền lợi | H5: Đã dùng trước kỳ | I5: Dùng trong kỳ | J5: Điều chỉnh +/- | K5: Còn lại | L5: Cảnh báo
