Workbook

Sheet HUONG_DAN
A1: HƯỚNG DẪN SỬ DỤNG BỘ FILE BÁO CÁO TÀI CHÍNH THEO THÔNG TƯ 133/2016/TT-BTC
A3: A | B3: CÁC SHEET TRONG FILE
B4: 1. HUONG_DAN — Trang này.
B5: 2. THONG_TIN_DN — Thông tin đơn vị, kỳ kế toán, chế độ kế toán áp dụng, tùy chọn trình bày.
B6: 3. DATA_F01 — Bảng cân đối tài khoản gốc (dữ liệu nguồn duy nhất). Ô nền vàng là ô NHẬP LIỆU.
B7: 4. MAPPING — Bảng ánh xạ tài khoản → chỉ tiêu BCTC, có ghi rõ nguồn số liệu và căn cứ.
B8: 5. ADJUSTMENT — Nhật ký điều chỉnh phân loại (audit trail: chỉ tiêu, số tiền, lý do, người nhập, thời điểm).
B9: 6. B01A_DNN / B01B_DNN — Báo cáo tình hình tài chính.
B10: 7. B02_DNN — Báo cáo kết quả hoạt động kinh doanh.
B11: 8. B09_DNN — Bản thuyết minh báo cáo tài chính (bán tự động).
B12: 9. F01_DNN — Bảng cân đối tài khoản theo mẫu nộp cơ quan thuế.
B13: 10. B03_DNN — Báo cáo lưu chuyển tiền tệ (nếu sử dụng).
B14: 11. KIEM_TRA_BCTC — Kết quả kiểm tra 3 cấp: Lỗi / Cần kiểm tra / Đã kiểm tra và bảng đối chiếu lợi nhuận.
B15: 12. DOI_CHIEU_THUE — Danh mục rà soát thuế và bảng chuyển lợi nhuận kế toán sang thu nhập tính thuế.
A17: B | B17: QUY ƯỚC MÀU
B18: • Ô nền VÀNG NHẠT = ô nhập liệu, không khóa — bạn có thể sửa.
B19: • Ô nền XANH NHẠT, chữ đậm = ô công thức, đã khóa — Excel sẽ tính lại khi bạn sửa dữ liệu nguồn.
B20: • Sheet được bảo vệ KHÔNG đặt mật khẩu: vào Review → Unprotect Sheet là bỏ khóa được.
A22: C | B22: CÁCH SỬ DỤNG
B23: 1. Sửa số liệu trên sheet DATA_F01 (các ô vàng). Các sheet báo cáo sẽ tự tính lại theo công thức Excel.
B24: 2. Kiểm tra 3 đẳng thức trên F01_DNN: tổng dư Nợ đầu kỳ = tổng dư Có đầu kỳ; tổng PS Nợ = tổng PS Có; tổng dư Nợ cuối kỳ = tổng dư Có cuối kỳ.
B25: 3. Kiểm tra Tổng cộng tài sản = Tổng cộng nguồn vốn trên sheet báo cáo tình hình tài chính.
B26: 4. Rà soát sheet KIEM_TRA_BCTC và DOI_CHIEU_THUE trước khi chốt số.
A28: D | B28: CĂN CỨ PHÁP LÝ
B29: Thông tư 133/2016/TT-BTC (hiệu lực 01/01/2017) hiện CÒN HIỆU LỰC. Từ 01/01/2026, doanh nghiệp nhỏ và vừa được QUYỀN LỰA CHỌN tiếp tục áp dụng TT 133/2016/TT-BTC hoặc chuyển sang Thông tư 99/2025/TT-BTC (Chế độ kế toán doanh nghiệp, thay TT 200/2014 từ 01/01/2026). Nếu chuyển sang TT99 phải áp dụng nhất quán tối thiểu một năm kế toán, trình bày lại số liệu so sánh và giải trình trong thuyết minh. Bộ Tài chính dự kiến sửa đổi TT133 trong năm 2026 — người dùng cần theo dõi cập nhật.
B30: • Thông tư 133/2016/TT-BTC — Điều 71 (Hệ thống báo cáo tài chính)
B31: • Thông tư 133/2016/TT-BTC — Điều 73, 74 (Giả định hoạt động liên tục)
B32: • Thông tư 133/2016/TT-BTC — Điều 81 (Lập B01a-DNN), Điều 82 (B02-DNN), Điều 83 (F01-DNN)
B33: • Thông tư 133/2016/TT-BTC — Phụ lục 2 (Biểu mẫu BCTC)
A35: E | B35: GIỚI HẠN CỦA CÔNG CỤ
B36: • Công cụ KHÔNG tự suy diễn số liệu khi bảng cân đối tài khoản không đủ căn cứ (kỳ hạn, đối ứng tài khoản, chi tiết theo đối tượng).
B37: • Công cụ KHÔNG bù trừ số dư Nợ/Có trái với bản chất khoản mục.
B38: • Chênh lệch giữa số liệu kế toán và số liệu thuế KHÔNG được coi là lỗi mặc định.
B39: • Kết quả phụ thuộc chất lượng dữ liệu đầu vào; người sử dụng chịu trách nhiệm kiểm tra số liệu cuối cùng.

Sheet THONG_TIN_DN
A1: THÔNG TIN DOANH NGHIỆP VÀ KỲ KẾ TOÁN
A2: Tên doanh nghiệp | B2: CÔNG TY TNHH THƯƠNG MẠI MINH ANH
A3: Mã số thuế | B3: 0101234567
A4: Địa chỉ | B4: Số 12 phố Láng Hạ, phường Láng, TP Hà Nội
A5: Năm tài chính | B5: 2025
A6: Ngày bắt đầu kỳ kế toán | B6: 01/01/2025
A7: Ngày kết thúc kỳ kế toán | B7: 31/12/2025
A8: Đơn vị tiền tệ trong kế toán | B8: VND
A9: Đơn vị trình bày trên báo cáo | B9: Đồng
A10: Chế độ kế toán áp dụng | B10: Thông tư 133/2016/TT-BTC — DN nhỏ và vừa
A11: Giả định hoạt động liên tục | B11: Có đáp ứng
A12: Mẫu Báo cáo tình hình tài chính | B12: B01a-DNN
A13: Báo cáo lưu chuyển tiền tệ | B13: Không lập
... A21: Thời điểm xuất file | B21: 10:59:49 14/8/2026

Sheet DATA_F01
A1: DỮ LIỆU NGUỒN — BẢNG CÂN ĐỐI TÀI KHOẢN
A2: Đơn vị tính: Đồng (số gốc, chưa quy đổi đơn vị trình bày). Ô vàng = nhập liệu.
A3: Số hiệu TK | B3: Tên tài khoản | C3: Dư Nợ đầu kỳ | D3: Dư Có đầu kỳ | E3: PS Nợ | F3: PS Có | G3: Dư Nợ cuối kỳ | H3: Dư Có cuối kỳ | I3: Dòng lá?
A4: 111 | B4: Tiền mặt | C4: 120000000 | D4: 0 | E4: 498500000 | F4: 263000000 | G4: 355500000 | H4: 0 | I4: =IF(A4="",0,IF(SUMPRODUCT((LEFT($A$4:$A$108,LEN(A4))=A4)*(LEN($A$4:$A$108)>LEN(A4)))>0,0,1))
A5: 112 | B5: Tiền gửi Ngân hàng | C5: 480000000 | D5: 0 | E5: 5948000000 | F5: 6061000000 | G5: 367000000 | H5: 0 | I5: =IF(A5="",0,IF(SUMPRODUCT((LEFT($A$4:$A$108,LEN(A5))=A5)*(LEN($A$4:$A$108)>LEN(A5)))>0,0,1))
A6: 1281 | B6: Tiền gửi có kỳ hạn | C6: 200000000 | D6: 0 | E6: 300000000 | F6: 100000000 | G6: 400000000 | H6: 0 | I6: =IF(A6="",0,IF(SUMPRODUCT((LEFT($A$4:$A$108,LEN(A6))=A6)*(LEN($A$4:$A$108)>LEN(A6)))>0,0,1))
A7: 131-KH01 | B7: Phải thu KH — Công ty An Phát | C7: 350000000 | D7: 0 | E7: 2200000000 | F7: 1955000000 | G7: 595000000 | H7: 0 | I7: =IF(A7="",0,IF(SUMPRODUCT((LEFT($A$4:$A$108,LEN(A7))=A7)*(LEN($A$4:$A$108)>LEN(A7)))>0,0,1))
A8: 131-KH02 | B8: Phải thu KH — Công ty Bình Minh | C8: 180000000 | D8: 0 | E8: 1100000000 | F8: 1250000000 | G8: 30000000 | H8: 0 | I8: =IF(A8="",0,IF(SUMPRODUCT((LEFT($A$4:$A$108,LEN(A8))=A8)*(LEN($A$4:$A$108)>LEN(A8)))>0,0,1))
A9: 131-KH03 | B9: Phải thu KH — Công ty Cường Thịnh | C9: 0 | D9: 60000000 | E9: 330000000 | F9: 440000000 | G9: 0 | H9: 170000000 | I9: =IF(A9="",0,IF(SUMPRODUCT((LEFT($A$4:$A$108,LEN(A9))=A9)*(LEN($A$4:$A$108)>LEN(A9)))>0,0,1))
A10: 133 | B10: Thuế GTGT được khấu trừ | C10: 45000000 | D10: 0 | E10: 395000000 | F10: 420000000 | G10: 20000000 | H10: 0 | I10: =IF(A10="",0,IF(SUMPRODUCT((LEFT($A$4:$A$108,LEN(A10))=A10)*(LEN($A$4:$A$108)>LEN(A10)))>0,0,1))
A11: 1381 | B11: Tài sản thiếu chờ xử lý | C11: 0 | D11: 0 | E11: 12000000 | F11: 0 | G11: 12000000 | H11: 0 | I11: =IF(A11="",0,IF(SUMPRODUCT((LEFT($A$4:$A$108,LEN(A11))=A11)*(LEN($A$4:$A$108)>LEN(A11)))>0,0,1))
A12: 1388 | B12: Phải thu khác | C12: 20000000 | D12: 0 | E12: 55000000 | F12: 60000000 | G12: 15000000 | H12: 0 | I12: =IF(A12="",0,IF(SUMPRODUCT((LEFT($A$4:$A$108,LEN(A12))=A12)*(LEN($A$4:$A$108)>LEN(A12)))>0,0,1))
A13: 141 | B13: Tạm ứng | C13: 15000000 | D13: 0 | E13: 70000000 | F13: 60000000 | G13: 25000000 | H13: 0 | I13: =IF(A13="",0,IF(SUMPRODUCT((LEFT($A$4:$A$108,LEN(A13))=A13)*(LEN($A$4:$A$108)>LEN(A13)))>0,0,1))
A14: 152 | B14: Nguyên liệu, vật liệu | C14: 260000000 | D14: 0 | E14: 200000000 | F14: 60000000 | G14: 400000000 | H14: 0 | I14: =IF(A14="",0,IF(SUMPRODUCT((LEFT($A$4:$A$108,LEN(A14))=A14)*(LEN($A$4:$A$108)>LEN(A14)))>0,0,1))
A15: 156 | B15: Hàng hóa | C15: 890000000 | D15: 0 | E15: 3400000000 | F15: 3212000000 | G15: 1078000000 | H15: 0 | I15: =IF(A15="",0,IF(SUMPRODUCT((LEFT($A$4:$A$108,LEN(A15))=A15)*(LEN($A$4:$A$108)>LEN(A15)))>0,0,1))
... A48: 911 | B48: Xác định kết quả kinh doanh | C48: 0 | D48: 0 | E48: 4878000000 | F48: 4878000000 | G48: 0 | H48: 0 | I48: =IF(A48="",0,IF(SUMPRODUCT((LEFT($A$4:$A$108,LEN(A48))=A48)*(LEN($A$4:$A$108)>LEN(A48)))>0,0,1))
I49: =IF(A49="",0,IF(SUMPRODUCT((LEFT($A$4:$A$108,LEN(A49))=A49)*(LEN($A$4:$A$108)>LEN(A49)))>0,0,1))
I50: =IF(A50="",0,IF(SUMPRODUCT((LEFT($A$4:$A$108,LEN(A50))=A50)*(LEN($A$4:$A$108)>LEN(A50)))>0,0,1))
I51: =IF(A51="",0,IF(SUMPRODUCT((LEFT($A$4:$A$108,LEN(A51))=A51)*(LEN($A$4:$A$108)>LEN(A51)))>0,0,1))
I52: =IF(A52="",0,IF(SUMPRODUCT((LEFT($A$4:$A$108,LEN(A52))=A52)*(LEN($A$4:$A$108)>LEN(A52)))>0,0,1))
I53: =IF(A53="",0,IF(SUMPRODUCT((LEFT($A$4:$A$108,LEN(A53))=A53)*(LEN($A$4:$A$108)>LEN(A53)))>0,0,1))
I54: =IF(A54="",0,IF(SUMPRODUCT((LEFT($A$4:$A$108,LEN(A54))=A54)*(LEN($A$4:$A$108)>LEN(A54)))>0,0,1))
I55: =IF(A55="",0,IF(SUMPRODUCT((LEFT($A$4:$A$108,LEN(A55))=A55)*(LEN($A$4:$A$108)>LEN(A55)))>0,0,1))
I56: =IF(A56="",0,IF(SUMPRODUCT((LEFT($A$4:$A$108,LEN(A56))=A56)*(LEN($A$4:$A$108)>LEN(A56)))>0,0,1))
I57: =IF(A57="",0,IF(SUMPRODUCT((LEFT($A$4:$A$108,LEN(A57))=A57)*(LEN($A$4:$A$108)>LEN(A57)))>0,0,1))
I58: =IF(A58="",0,IF(SUMPRODUCT((LEFT($A$4:$A$108,LEN(A58))=A58)*(LEN($A$4:$A$108)>LEN(A58)))>0,0,1))
I59: =IF(A59="",0,IF(SUMPRODUCT((LEFT($A$4:$A$108,LEN(A59))=A59)*(LEN($A$4:$A$108)>LEN(A59)))>0,0,1))
I60: =IF(A60="",0,IF(SUMPRODUCT((LEFT($A$4:$A$108,LEN(A60))=A60)*(LEN($A$4:$A$108)>LEN(A60)))>0,0,1))
... I108: =IF(A108="",0,IF(SUMPRODUCT((LEFT($A$4:$A$108,LEN(A108))=A108)*(LEN($A$4:$A$108)>LEN(A108)))>0,0,1))
B109: CỘNG (chỉ dòng lá) | C109: =SUMPRODUCT(($I$4:$I$108=1)*C$4:C$108) | D109: =SUMPRODUCT(($I$4:$I$108=1)*D$4:D$108) | E109: =SUMPRODUCT(($I$4:$I$108=1)*E$4:E$108) | F109: =SUMPRODUCT(($I$4:$I$108=1)*F$4:F$108) | G109: =SUMPRODUCT(($I$4:$I$108=1)*G$4:G$108) | H109: =SUMPRODUCT(($I$4:$I$108=1)*H$4:H$108)
B110: KIỂM TRA CÂN ĐỐI | C110: =IF(ABS(C109-D109)<=1,"✓ Dư đầu kỳ cân","✗ Lệch "&TEXT(C109-D109,"#,##0")) | E110: =IF(ABS(E109-F109)<=1,"✓ Phát sinh cân","✗ Lệch "&TEXT(E109-F109,"#,##0")) | G110: =IF(ABS(G109-H109)<=1,"✓ Dư cuối kỳ cân","✗ Lệch "&TEXT(G109-H109,"#,##0"))
A112: Lập bằng Công cụ lập & kiểm tra BCTC theo Thông tư 133 — KK HOME · · TT133-MAP-2026.08 · Xuất lúc 10:59:49 14/8/2026

Sheet MAPPING
A1: BẢNG MAPPING TÀI KHOẢN → CHỈ TIÊU BÁO CÁO TÀI CHÍNH · TT133-MAP-2026.08
A2: Bảng này tách khỏi giao diện để dễ bảo trì khi Thông tư thay đổi. Mỗi chỉ tiêu ghi rõ nguồn số liệu và căn cứ.
A3: Mã số | B3: Tên chỉ tiêu | C3: Tài khoản nguồn / Công thức | D3: Dấu trình bày | E3: Ghi chú nguồn số liệu — căn cứ TT133
A4: BÁO CÁO TÌNH HÌNH TÀI CHÍNH — B01a-DNN
A5: 110 | B5: Tiền và các khoản tương đương tiền | C5: TK 111 (dư Nợ), TK 112 (dư Nợ), + khai báo CASH_EQ_128 | D5: Dương | E5: Tiền mặt, tiền gửi ngân hàng không kỳ hạn và các khoản tương đương tiền (TK 1281, 1288 có kỳ hạn gốc ≤ 3 tháng). Phần TK 128 là tương đương tiền phải nhập ở Bước 3 vì bảng cân đối tổng hợp không tách được kỳ hạn.
A6: 120 | B6: Đầu tư tài chính | C6: = Mã 121 + Mã 122 + Mã 123 + Mã 124 | D6: Dương | E6: Chỉ tiêu tổng hợp: 120 = 121 + 122 + 123 + 124 (mã 124 đã mang dấu âm).
A7: 121 | B7: Chứng khoán kinh doanh | C7: TK 121 (dư Nợ) | D7: Dương | E7: Số dư Nợ TK 121.
A8: 122 | B8: Đầu tư nắm giữ đến ngày đáo hạn | C8: TK 1281 (dư Nợ), TK 1288 (dư Nợ), − khai báo CASH_EQ_128, − khai báo LOAN_1288 | D8: Dương | E8: Số dư Nợ TK 1281, 1288 SAU KHI trừ phần đã trình bày ở mã 110 (tương đương tiền) và phần cho vay đưa vào mã 134.
A9: 123 | B9: Đầu tư góp vốn vào đơn vị khác | C9: TK 228 (dư Nợ) | D9: Dương | E9: Số dư Nợ TK 228 (2281, 2288).
A10: 124 | B10: Dự phòng tổn thất đầu tư tài chính (*) | C10: TK 2291 (dư Có), TK 2292 (dư Có) | D10: Luôn ghi âm ( ) | E10: Số dư Có TK 2291 + 2292. Luôn ghi bằng số âm trong ngoặc đơn.
A11: 130 | B11: Các khoản phải thu | C11: = Mã 131 + Mã 132 + Mã 133 + Mã 134 + Mã 135 + Mã 136 | D11: Dương | E11: Chỉ tiêu tổng hợp: 130 = 131+132+133+134+135+136.
A12: 131 | B12: Phải thu của khách hàng | C12: TK 131 (dư Nợ) | D12: Dương | E12: TỔNG SỐ DƯ NỢ CHI TIẾT của TK 131 mở theo từng khách hàng. KHÔNG bù trừ với mã 312.
A13: 132 | B13: Trả trước cho người bán | C13: TK 331 (dư Nợ) | D13: Dương | E13: TỔNG SỐ DƯ NỢ CHI TIẾT của TK 331 mở theo từng người bán. KHÔNG bù trừ với mã 311.
A14: 133 | B14: Vốn kinh doanh ở đơn vị trực thuộc | C14: TK 1361 (dư Nợ) | D14: Dương | E14: Số dư Nợ TK 1361 — chỉ trình bày trên BCTC riêng của đơn vị cấp trên.
A15: 134 | B15: Phải thu khác | C15: TK 1368 (dư Nợ), TK 1386 (dư Nợ), TK 1388 (dư Nợ), TK 334 (dư Nợ), TK 338 (dư Nợ), TK 141 (dư Nợ), + khai báo LOAN_1288 | D15: Dương | E15: Số dư Nợ chi tiết TK 1288 (phần cho vay), 1368, 1386, 1388, 334, 338, 141.
A16: 135 | B16: Tài sản thiếu chờ xử lý | C16: TK 1381 (dư Nợ) | D16: Dương | E16: Số dư Nợ TK 1381.
... A51: 500 | B51: TỔNG CỘNG NGUỒN VỐN | C51: = Mã 300 + Mã 400 | D51: Dương | E51: 500 = 300 + 400. Bắt buộc: Mã 200 = Mã 500.
A52: BÁO CÁO KẾT QUẢ HOẠT ĐỘNG KINH DOANH — B02-DNN
A53: 01 | B53: 1. Doanh thu bán hàng và cung cấp dịch vụ | C53: TK 511 (PS Có) | D53: Dương | E53: Lũy kế số phát sinh bên Có TK 511 trong kỳ báo cáo (Điều 82 TT133). KHÔNG bao gồm thuế gián thu phải nộp (GTGT, TTĐB, xuất khẩu, bảo vệ môi trường) và các khoản phí thu hộ Nhà nước.
A54: 02 | B54: 2. Các khoản giảm trừ doanh thu | C54: nhập tay | D54: Dương | E54: Tổng số phát sinh bên Nợ TK 511 đối ứng bên Có các TK 111, 112, 131 (chiết khấu thương mại, giảm giá hàng bán, hàng bán bị trả lại). TT133 KHÔNG có TK 521 nên bảng cân đối tổng hợp không tách được — mặc định lấy PS Nợ TK 511 trừ phần kết chuyển sang TK 911; người dùng nên nhập/kiểm tra lại ở Bước 3.
A55: 10 | B55: 3. Doanh thu thuần về bán hàng và cung cấp dịch vụ (10 = 01 - 02) | C55: = Mã 01 − Mã 02 | D55: Dương
A56: 11 | B56: 4. Giá vốn hàng bán | C56: TK 632 (PS Nợ) | D56: Dương | E56: TT133: lũy kế số phát sinh bên Có TK 632 đối ứng bên Nợ TK 911. Bảng cân đối tài khoản không có thông tin đối ứng nên công cụ lấy lũy kế PS Nợ TK 632 — bằng đúng số kết chuyển khi tài khoản đã kết chuyển hết (PS Nợ = PS Có) và vẫn đúng khi sổ chưa kết chuyển. Nếu trong kỳ có bút toán giảm giá vốn (Nợ 156/Có 632 do hàng bán bị trả lại), cần điều chỉnh giảm tương ứng.
A57: 20 | B57: 5. Lợi nhuận gộp về bán hàng và cung cấp dịch vụ (20 = 10 - 11) | C57: = Mã 10 − Mã 11 | D57: Ghi âm nếu ngược dấu
A58: 21 | B58: 6. Doanh thu hoạt động tài chính | C58: TK 515 (PS Có) | D58: Dương | E58: TT133: lũy kế PS Nợ TK 515 đối ứng bên Có TK 911 (bút toán kết chuyển). Công cụ lấy lũy kế PS Có TK 515 (bên ghi nhận doanh thu) — bằng đúng số kết chuyển khi tài khoản đã kết chuyển hết.
A59: 22 | B59: 7. Chi phí tài chính | C59: TK 635 (PS Nợ) | D59: Dương | E59: TT133: lũy kế PS Có TK 635 đối ứng bên Nợ TK 911. Công cụ lấy lũy kế PS Nợ TK 635 (bên ghi nhận chi phí) — bằng đúng số kết chuyển khi tài khoản đã kết chuyển hết. Gồm lãi vay phải trả, lỗ tỷ giá, chiết khấu thanh toán…
A60: 23 | B60: - Trong đó: Chi phí lãi vay | C60: nhập tay | D60: Dương | E60: Số liệu CHI TIẾT về chi phí lãi vay trên TK 635. Không suy ra được từ bảng cân đối tổng hợp — người dùng nhập ở Bước 3. Chỉ tiêu này KHÔNG tham gia công thức cộng trừ.
A61: 24 | B61: 8. Chi phí quản lý kinh doanh | C61: TK 642 (PS Nợ) | D61: Dương | E61: TT133: tổng PS Có TK 642 đối ứng bên Nợ TK 911. Công cụ lấy lũy kế PS Nợ TK 642 (bên ghi nhận chi phí). TT133 gộp chi phí bán hàng (6421) và chi phí quản lý doanh nghiệp (6422) vào MỘT dòng — khác TT200 có 2 dòng mã 25 và 26.
A62: 30 | B62: 9. Lợi nhuận thuần từ hoạt động kinh doanh (30 = 20 + 21 - 22 - 24) | C62: = Mã 20 + Mã 21 − Mã 22 − Mã 24 | D62: Ghi âm nếu ngược dấu
A63: 31 | B63: 10. Thu nhập khác | C63: TK 711 (PS Có) | D63: Dương | E63: TT133: tổng PS Nợ TK 711 đối ứng bên Có TK 911. Công cụ lấy lũy kế PS Có TK 711 (bên ghi nhận thu nhập). Với thanh lý, nhượng bán TSCĐ: phần chênh lệch khoản thu CAO HƠN giá trị còn lại và chi phí thanh lý.
A64: 32 | B64: 11. Chi phí khác | C64: TK 811 (PS Nợ) | D64: Dương | E64: TT133: tổng PS Có TK 811 đối ứng bên Nợ TK 911. Công cụ lấy lũy kế PS Nợ TK 811 (bên ghi nhận chi phí).
A65: 40 | B65: 12. Lợi nhuận khác (40 = 31 - 32) | C65: = Mã 31 − Mã 32 | D65: Ghi âm nếu ngược dấu
A66: 50 | B66: 13. Tổng lợi nhuận kế toán trước thuế (50 = 30 + 40) | C66: = Mã 30 + Mã 40 | D66: Ghi âm nếu ngược dấu
A67: 51 | B67: 14. Chi phí thuế thu nhập doanh nghiệp | C67: TK 821 (PS Nợ) | D67: Ghi âm nếu ngược dấu | E67: TT133: tổng PS Có TK 821 đối ứng Nợ TK 911; nếu là PS Nợ TK 821 đối ứng Có TK 911 thì ghi số âm trong ngoặc đơn. Công cụ lấy lũy kế PS Nợ TK 821 (bên ghi nhận chi phí thuế). Trường hợp hoàn nhập chi phí thuế TNDN làm chỉ tiêu này ÂM, hãy dùng khoản điều chỉnh phân loại ở Bước 3 để thể hiện.
A68: 60 | B68: 15. Lợi nhuận sau thuế thu nhập doanh nghiệp (60 = 50 - 51) | C68: = Mã 50 − Mã 51 | D68: Ghi âm nếu ngược dấu

Sheet ADJUSTMENT
A1: NHẬT KÝ ĐIỀU CHỈNH PHÂN LOẠI BÁO CÁO TÀI CHÍNH (AUDIT TRAIL)
A2: Điều chỉnh phân loại KHÔNG sửa dữ liệu sổ cái gốc. Mọi khoản đều lưu chỉ tiêu, số tiền, lý do, người nhập và thời điểm.
A3: # | B3: Báo cáo | C3: Mã số | D3: Nội dung | E3: Tăng | F3: Giảm | G3: Thuần | H3: Lý do điều chỉnh / Người nhập / Thời điểm
D4: Không có khoản điều chỉnh nào.
A6: NHẬT KÝ TRUY VẾT NGUỒN SỐ LIỆU (TRACE) — mọi khoản KHÔNG lấy trực tiếp từ số dư/phát sinh tài khoản
A7: # | B7: Báo cáo | C7: Mã số | D7: Tên chỉ tiêu | E7: Số tiền | F7: Nguồn / Diễn giải | G7: Loại
A8: 1 | B8: B02 | C8: 02 | D8: 2. Các khoản giảm trừ doanh thu | E8: 50000000 | F8: Suy ra từ PS Nợ TK 511 − kết chuyển doanh thu thuần (PS Có TK 911 − PS Nợ TK 515 − PS Nợ TK 711) | G8: Công cụ SUY RA

Sheet B01A_DNN
A1: CÔNG TY TNHH THƯƠNG MẠI MINH ANH
A2: MST: 0101234567 · Số 12 phố Láng Hạ, phường Láng, TP Hà Nội
A4: BÁO CÁO TÌNH HÌNH TÀI CHÍNH
A5: Tại ngày 31/12/2025 · Mẫu số B01a-DNN (Ban hành theo Thông tư số 133/2016/TT-BTC ngày 26/8/2016 của Bộ Tài chính)
A6: Đơn vị tính: Đồng
A7: CHỈ TIÊU | B7: Mã số | C7: Thuyết minh | D7: Số cuối năm | E7: Số đầu năm
A8: TÀI SẢN
A9: 1. Tiền và các khoản tương đương tiền | B9: 110 | D9: =(SUMPRODUCT((DATA_F01!$I$4:$I$108=1)*(LEFT(DATA_F01!$A$4:$A$108,3)="111")*N(DATA_F01!$G$4:$G$108))+SUMPRODUCT((DATA_F01!$I$4:$I$108=1)*(LEFT(DATA_F01!$A$4:$A$108,3)="112")*N(DATA_F01!$G$4:$G$108))) | E9: =(SUMPRODUCT((DATA_F01!$I$4:$I$108=1)*(LEFT(DATA_F01!$A$4:$A$108,3)="111")*N(DATA_F01!$C$4:$C$108))+SUMPRODUCT((DATA_F01!$I$4:$I$108=1)*(LEFT(DATA_F01!$A$4:$A$108,3)="112")*N(DATA_F01!$C$4:$C$108)))
A10: 2. Đầu tư tài chính | B10: 120 | D10: =D11+D12+D13+D14 | E10: =E11+E12+E13+E14
A11: Chứng khoán kinh doanh | B11: 121 | D11: =(SUMPRODUCT((DATA_F01!$I$4:$I$108=1)*(LEFT(DATA_F01!$A$4:$A$108,3)="121")*N(DATA_F01!$G$4:$G$108))) | E11: =(SUMPRODUCT((DATA_F01!$I$4:$I$108=1)*(LEFT(DATA_F01!$A$4:$A$108,3)="121")*N(DATA_F01!$C$4:$C$108)))
A12: Đầu tư nắm giữ đến ngày đáo hạn | B12: 122 | D12: =(SUMPRODUCT((DATA_F01!$I$4:$I$108=1)*(LEFT(DATA_F01!$A$4:$A$108,4)="1281")*N(DATA_F01!$G$4:$G$108))+SUMPRODUCT((DATA_F01!$I$4:$I$108=1)*(LEFT(DATA_F01!$A$4:$A$108,4)="1288")*N(DATA_F01!$G$4:$G$108))) | E12: =(SUMPRODUCT((DATA_F01!$I$4:$I$108=1)*(LEFT(DATA_F01!$A$4:$A$108,4)="1281")*N(DATA_F01!$C$4:$C$108))+SUMPRODUCT((DATA_F01!$I$4:$I$108=1)*(LEFT(DATA_F01!$A$4:$A$108,4)="1288")*N(DATA_F01!$C$4:$C$108)))
A13: Đầu tư góp vốn vào đơn vị khác | B13: 123 | D13: =(SUMPRODUCT((DATA_F01!$I$4:$I$108=1)*(LEFT(DATA_F01!$A$4:$A$108,3)="228")*N(DATA_F01!$G$4:$G$108))) | E13: =(SUMPRODUCT((DATA_F01!$I$4:$I$108=1)*(LEFT(DATA_F01!$A$4:$A$108,3)="228")*N(DATA_F01!$C$4:$C$108)))
A14: Dự phòng tổn thất đầu tư tài chính (*) | B14: 124 | D14: =-ABS((SUMPRODUCT((DATA_F01!$I$4:$I$108=1)*(LEFT(DATA_F01!$A$4:$A$108,4)="2291")*N(DATA_F01!$H$4:$H$108))+SUMPRODUCT((DATA_F01!$I$4:$I$108=1)*(LEFT(DATA_F01!$A$4:$A$108,4)="2292")*N(DATA_F01!$H$4:$H$108)))) | E14: =-ABS((SUMPRODUCT((DATA_F01!$I$4:$I$108=1)*(LEFT(DATA_F01!$A$4:$A$108,4)="2291")*N(DATA_F01!$D$4:$D$108))+SUMPRODUCT((DATA_F01!$I$4:$I$108=1)*(LEFT(DATA_F01!$A$4:$A$108,4)="2292")*N(DATA_F01!$D$4:$D$108))))
A15: 3. Các khoản phải thu | B15: 130 | D15: =D16+D17+D18+D19+D20+D21 | E15: =E16+E17+E18+E19+E20+E21
A16: Phải thu của khách hàng | B16: 131 | D16: =(SUMPRODUCT((DATA_F01!$I$4:$I$108=1)*(LEFT(DATA_F01!$A$4:$A$108,3)="131")*N(DATA_F01!$G$4:$G$108))) | E16: =(SUMPRODUCT((DATA_F01!$I$4:$I$108=1)*(LEFT(DATA_F01!$A$4:$A$108,3)="131")*N(DATA_F01!$C$4:$C$108)))
A17: Trả trước cho người bán | B17: 132 | D17: =(SUMPRODUCT((DATA_F01!$I$4:$I$108=1)*(LEFT(DATA_F01!$A$4:$A$108,3)="331")*N(DATA_F01!$G$4:$G$108))) | E17: =(SUMPRODUCT((DATA_F01!$I$4:$I$108=1)*(LEFT(DATA_F01!$A$4:$A$108,3)="331")*N(DATA_F01!$C$4:$C$108)))
A18: Vốn kinh doanh ở đơn vị trực thuộc | B18: 133 | D18: =(SUMPRODUCT((DATA_F01!$I$4:$I$108=1)*(LEFT(DATA_F01!$A$4:$A$108,4)="1361")*N(DATA_F01!$G$4:$G$108))) | E18: =(SUMPRODUCT((DATA_F01!$I$4:$I$108=1)*(LEFT(DATA_F01!$A$4:$A$108,4)="1361")*N(DATA_F01!$C$4:$C$108)))
A19: Phải thu khác | B19: 134 | D19: =(SUMPRODUCT((DATA_F01!$I$4:$I$108=1)*(LEFT(DATA_F01!$A$4:$A$108,4)="1368")*N(DATA_F01!$G$4:$G$108))+SUMPRODUCT((DATA_F01!$I$4:$I$108=1)*(LEFT(DATA_F01!$A$4:$A$108,4)="1386")*N(DATA_F01!$G$4:$G$108))+SUMPRODUCT((DATA_F01!$I$4:$I$108=1)*(LEFT(DATA_F01!$A$4:$A$108,4)="1388")*N(DATA_F01!$G$4:$G$108))+SUMPRODUCT((DATA_F01!$I$4:$I$108=1)*(LEFT(DATA_F01!$A$4:$A$108,3)="334")*N(DATA_F01!$G$4:$G$108))+SUMPRODUCT((DATA_F01!$I$4:$I$108=1)*(LEFT(DATA_F01!$A$4:$A$108,3)="338")*N(DATA_F01!$G$4:$G$108))+SUMPRODUCT((DATA_F01!$I$4:$I$108=1)*(LEFT(DATA_F01!$A$4:$A$108,3)="141")*N(DATA_F01!$G$4:$G$108))) | E19: =(SUMPRODUCT((DATA_F01!$I$4:$I$108=1)*(LEFT(DATA_F01!$A$4:$A$108,4)="1368")*N(DATA_F01!$C$4:$C$108))+SUMPRODUCT((DATA_F01!$I$4:$I$108=1)*(LEFT(DATA_F01!$A$4:$A$108,4)="1386")*N(DATA_F01!$C$4:$C$108))+SUMPRODUCT((DATA_F01!$I$4:$I$108=1)*(LEFT(DATA_F01!$A$4:$A$108,4)="1388")*N(DATA_F01!$C$4:$C$108))+SUMPRODUCT((DATA_F01!$I$4:$I$108=1)*(LEFT(DATA_F01!$A$4:$A$108,3)="334")*N(DATA_F01!$C$4:$C$108))+SUMPRODUCT((DATA_F01!$I$4:$I$108=1)*(LEFT(DATA_F01!$A$4:$A$108,3)="338")*N(DATA_F01!$C$4:$C$108))+SUMPRODUCT((DATA_F01!$I$4:$I$108=1)*(LEFT(DATA_F01!$A$4:$A$108,3)="141")*N(DATA_F01!$C$4:$C$108)))
A20: Tài sản thiếu chờ xử lý | B20: 135 | D20: =(SUMPRODUCT((DATA_F01!$I$4:$I$108=1)*(LEFT(DATA_F01!$A$4:$A$108,4)="1381")*N(DATA_F01!$G$4:$G$108))) | E20: =(SUMPRODUCT((DATA_F01!$I$4:$I$108=1)*(LEFT(DATA_F01!$A$4:$A$108,4)="1381")*N(DATA_F01!$C$4:$C$108)))
A21: Dự phòng phải thu khó đòi (*) | B21: 136 | D21: =-ABS((SUMPRODUCT((DATA_F01!$I$4:$I$108=1)*(LEFT(DATA_F01!$A$4:$A$108,4)="2293")*N(DATA_F01!$H$4:$H$108)))) | E21: =-ABS((SUMPRODUCT((DATA_F01!$I$4:$I$108=1)*(LEFT(DATA_F01!$A$4:$A$108,4)="2293")*N(DATA_F01!$D$4:$D$108))))
A22: 4. Hàng tồn kho | B22: 140 | D22: =D23+D24 | E22: =E23+E24
A23: Hàng tồn kho | B23: 141 | D23: =(SUMPRODUCT((DATA_F01!$I$4:$I$108=1)*(LEFT(DATA_F01!$A$4:$A$108,3)="151")*N(DATA_F01!$G$4:$G$108))+SUMPRODUCT((DATA_F01!$I$4:$I$108=1)*(LEFT(DATA_F01!$A$4:$A$108,3)="152")*N(DATA_F01!$G$4:$G$108))+SUMPRODUCT((DATA_F01!$I$4:$I$108=1)*(LEFT(DATA_F01!$A$4:$A$108,3)="153")*N(DATA_F01!$G$4:$G$108))+SUMPRODUCT((DATA_F01!$I$4:$I$108=1)*(LEFT(DATA_F01!$A$4:$A$108,3)="154")*N(DATA_F01!$G$4:$G$108))+SUMPRODUCT((DATA_F01!$I$4:$I$108=1)*(LEFT(DATA_F01!$A$4:$A$108,3)="155")*N(DATA_F01!$G$4:$G$108))+SUMPRODUCT((DATA_F01!$I$4:$I$108=1)*(LEFT(DATA_F01!$A$4:$A$108,3)="156")*N(DATA_F01!$G$4:$G$108))+SUMPRODUCT((DATA_F01!$I$4:$I$108=1)*(LEFT(DATA_F01!$A$4:$A$108,3)="157")*N(DATA_F01!$G$4:$G$108))) | E23: =(SUMPRODUCT((DATA_F01!$I$4:$I$108=1)*(LEFT(DATA_F01!$A$4:$A$108,3)="151")*N(DATA_F01!$C$4:$C$108))+SUMPRODUCT((DATA_F01!$I$4:$I$108=1)*(LEFT(DATA_F01!$A$4:$A$108,3)="152")*N(DATA_F01!$C$4:$C$108))+SUMPRODUCT((DATA_F01!$I$4:$I$108=1)*(LEFT(DATA_F01!$A$4:$A$108,3)="153")*N(DATA_F01!$C$4:$C$108))+SUMPRODUCT((DATA_F01!$I$4:$I$108=1)*(LEFT(DATA_F01!$A$4:$A$108,3)="154")*N(DATA_F01!$C$4:$C$108))+SUMPRODUCT((DATA_F01!$I$4:$I$108=1)*(LEFT(DATA_F01!$A$4:$A$108,3)="155")*N(DATA_F01!$C$4:$C$108))+SUMPRODUCT((DATA_F01!$I$4:$I$108=1)*(LEFT(DATA_F01!$A$4:$A$108,3)="156")*N(DATA_F01!$C$4:$C$108))+SUMPRODUCT((DATA_F01!$I$4:$I$108=1)*(LEFT(DATA_F01!$A$4:$A$108,3)="157")*N(DATA_F01!$C$4:$C$108)))
A24: Dự phòng giảm giá hàng tồn kho (*) | B24: 142 | D24: =-ABS((SUMPRODUCT((DATA_F01!$I$4:$I$108=1)*(LEFT(DATA_F01!$A$4:$A$108,4)="2294")*N(DATA_F01!$H$4:$H$108)))) | E24: =-ABS((SUMPRODUCT((DATA_F01!$I$4:$I$108=1)*(LEFT(DATA_F01!$A$4:$A$108,4)="2294")*N(DATA_F01!$D$4:$D$108))))
A25: 5. Tài sản cố định | B25: 150 | D25: =D26+D27 | E25: =E26+E27
A26: - Nguyên giá | B26: 151 | D26: =(SUMPRODUCT((DATA_F01!$I$4:$I$108=1)*(LEFT(DATA_F01!$A$4:$A$108,3)="211")*N(DATA_F01!$G$4:$G$108))) | E26: =(SUMPRODUCT((DATA_F01!$I$4:$I$108=1)*(LEFT(DATA_F01!$A$4:$A$108,3)="211")*N(DATA_F01!$C$4:$C$108)))
A27: - Giá trị hao mòn lũy kế (*) | B27: 152 | D27: =-ABS((SUMPRODUCT((DATA_F01!$I$4:$I$108=1)*(LEFT(DATA_F01!$A$4:$A$108,4)="2141")*N(DATA_F01!$H$4:$H$108))+SUMPRODUCT((DATA_F01!$I$4:$I$108=1)*(LEFT(DATA_F01!$A$4:$A$108,4)="2142")*N(DATA_F01!$H$4:$H$108))+SUMPRODUCT((DATA_F01!$I$4:$I$108=1)*(LEFT(DATA_F01!$A$4:$A$108,4)="2143")*N(DATA_F01!$H$4:$H$108)))) | E27: =-ABS((SUMPRODUCT((DATA_F01!$I$4:$I$108=1)*(LEFT(DATA_F01!$A$4:$A$108,4)="2141")*N(DATA_F01!$D$4:$D$108))+SUMPRODUCT((DATA_F01!$I$4:$I$108=1)*(LEFT(DATA_F01!$A$4:$A$108,4)="2142")*N(DATA_F01!$D$4:$D$108))+SUMPRODUCT((DATA_F01!$I$4:$I$108=1)*(LEFT(DATA_F01!$A$4:$A$108,4)="2143")*N(DATA_F01!$D$4:$D$108))))
A28: 6. Bất động sản đầu tư | B28: 160 | D28: =D29+D30 | E28: =E29+E30
A29: - Nguyên giá | B29: 161 | D29: =(SUMPRODUCT((DATA_F01!$I$4:$I$108=1)*(LEFT(DATA_F01!$A$4:$A$108,3)="217")*N(DATA_F01!$G$4:$G$108))) | E29: =(SUMPRODUCT((DATA_F01!$I$4:$I$108=1)*(LEFT(DATA_F01!$A$4:$A$108,3)="217")*N(DATA_F01!$C$4:$C$108)))
A30: - Giá trị hao mòn lũy kế (*) | B30: 162 | D30: =-ABS((SUMPRODUCT((DATA_F01!$I$4:$I$108=1)*(LEFT(DATA_F01!$A$4:$A$108,4)="2147")*N(DATA_F01!$H$4:$H$108)))) | E30: =-ABS((SUMPRODUCT((DATA_F01!$I$4:$I$108=1)*(LEFT(DATA_F01!$A$4:$A$108,4)="2147")*N(DATA_F01!$D$4:$D$108))))
A31: 7. XDCB dở dang | B31: 170 | D31: =(SUMPRODUCT((DATA_F01!$I$4:$I$108=1)*(LEFT(DATA_F01!$A$4:$A$108,3)="241")*N(DATA_F01!$G$4:$G$108))) | E31: =(SUMPRODUCT((DATA_F01!$I$4:$I$108=1)*(LEFT(DATA_F01!$A$4:$A$108,3)="241")*N(DATA_F01!$C$4:$C$108)))
A32: 8. Tài sản khác | B32: 180 | D32: =D33+D34 | E32: =E33+E34
A33: Thuế GTGT được khấu trừ | B33: 181 | D33: =(SUMPRODUCT((DATA_F01!$I$4:$I$108=1)*(LEFT(DATA_F01!$A$4:$A$108,3)="133")*N(DATA_F01!$G$4:$G$108))) | E33: =(SUMPRODUCT((DATA_F01!$I$4:$I$108=1)*(LEFT(DATA_F01!$A$4:$A$108,3)="133")*N(DATA_F01!$C$4:$C$108)))
A34: Tài sản khác | B34: 182 | D34: =(SUMPRODUCT((DATA_F01!$I$4:$I$108=1)*(LEFT(DATA_F01!$A$4:$A$108,3)="242")*N(DATA_F01!$G$4:$G$108))+SUMPRODUCT((DATA_F01!$I$4:$I$108=1)*(LEFT(DATA_F01!$A$4:$A$108,3)="333")*N(DATA_F01!$G$4:$G$108))) | E34: =(SUMPRODUCT((DATA_F01!$I$4:$I$108=1)*(LEFT(DATA_F01!$A$4:$A$108,3)="242")*N(DATA_F01!$C$4:$C$108))+SUMPRODUCT((DATA_F01!$I$4:$I$108=1)*(LEFT(DATA_F01!$A$4:$A$108,3)="333")*N(DATA_F01!$C$4:$C$108)))
A35: TỔNG CỘNG TÀI SẢN | B35: 200 | D35: =D9+D10+D15+D22+D25+D28+D31+D32 | E35: =E9+E10+E15+E22+E25+E28+E31+E32
A36: NGUỒN VỐN
A37: I. Nợ phải trả | B37: 300 | D37: =D38+D39+D40+D41+D42+D43+D44+D45+D46+D47 | E37: =E38+E39+E40+E41+E42+E43+E44+E45+E46+E47
A38: Phải trả người bán | B38: 311 | D38: =(SUMPRODUCT((DATA_F01!$I$4:$I$108=1)*(LEFT(DATA_F01!$A$4:$A$108,3)="331")*N(DATA_F01!$H$4:$H$108))) | E38: =(SUMPRODUCT((DATA_F01!$I$4:$I$108=1)*(LEFT(DATA_F01!$A$4:$A$108,3)="331")*N(DATA_F01!$D$4:$D$108)))
A39: Người mua trả tiền trước | B39: 312 | D39: =(SUMPRODUCT((DATA_F01!$I$4:$I$108=1)*(LEFT(DATA_F01!$A$4:$A$108,3)="131")*N(DATA_F01!$H$4:$H$108))) | E39: =(SUMPRODUCT((DATA_F01!$I$4:$I$108=1)*(LEFT(DATA_F01!$A$4:$A$108,3)="131")*N(DATA_F01!$D$4:$D$108)))
A40: Thuế và các khoản phải nộp Nhà nước | B40: 313 | D40: =(SUMPRODUCT((DATA_F01!$I$4:$I$108=1)*(LEFT(DATA_F01!$A$4:$A$108,3)="333")*N(DATA_F01!$H$4:$H$108))) | E40: =(SUMPRODUCT((DATA_F01!$I$4:$I$108=1)*(LEFT(DATA_F01!$A$4:$A$108,3)="333")*N(DATA_F01!$D$4:$D$108)))
A41: Phải trả người lao động | B41: 314 | D41: =(SUMPRODUCT((DATA_F01!$I$4:$I$108=1)*(LEFT(DATA_F01!$A$4:$A$108,3)="334")*N(DATA_F01!$H$4:$H$108))) | E41: =(SUMPRODUCT((DATA_F01!$I$4:$I$108=1)*(LEFT(DATA_F01!$A$4:$A$108,3)="334")*N(DATA_F01!$D$4:$D$108)))
...

Sheet B02_DNN
A1: CÔNG TY TNHH THƯƠNG MẠI MINH ANH
A2: MST: 0101234567 · Số 12 phố Láng Hạ, phường Láng, TP Hà Nội
A4: BÁO CÁO KẾT QUẢ HOẠT ĐỘNG KINH DOANH
A5: Năm 2025 · Mẫu số B02-DNN (Ban hành theo Thông tư số 133/2016/TT-BTC ngày 26/8/2016 của Bộ Tài chính)
A6: Đơn vị tính: Đồng
A7: CHỈ TIÊU | B7: Mã số | C7: Thuyết minh | D7: Năm nay | E7: Năm trước
A8: 1. Doanh thu bán hàng và cung cấp dịch vụ | B8: 01 | D8: =(SUMPRODUCT((DATA_F01!$I$4:$I$108=1)*(LEFT(DATA_F01!$A$4:$A$108,3)="511")*N(DATA_F01!$F$4:$F$108)))
A9: 2. Các khoản giảm trừ doanh thu | B9: 02 | D9: 50000000
A10: 3. Doanh thu thuần về bán hàng và cung cấp dịch vụ (10 = 01 - 02) | B10: 10 | D10: =D8-D9
A11: 4. Giá vốn hàng bán | B11: 11 | D11: =(SUMPRODUCT((DATA_F01!$I$4:$I$108=1)*(LEFT(DATA_F01!$A$4:$A$108,3)="632")*N(DATA_F01!$E$4:$E$108)))
A12: 5. Lợi nhuận gộp về bán hàng và cung cấp dịch vụ (20 = 10 - 11) | B12: 20 | D12: =D10-D11
A13: 6. Doanh thu hoạt động tài chính | B13: 21 | D13: =(SUMPRODUCT((DATA_F01!$I$4:$I$108=1)*(LEFT(DATA_F01!$A$4:$A$108,3)="515")*N(DATA_F01!$F$4:$F$108)))
A14: 7. Chi phí tài chính | B14: 22 | D14: =(SUMPRODUCT((DATA_F01!$I$4:$I$108=1)*(LEFT(DATA_F01!$A$4:$A$108,3)="635")*N(DATA_F01!$E$4:$E$108)))
A15: - Trong đó: Chi phí lãi vay | B15: 23 | D15: 0
A16: 8. Chi phí quản lý kinh doanh | B16: 24 | D16: =(SUMPRODUCT((DATA_F01!$I$4:$I$108=1)*(LEFT(DATA_F01!$A$4:$A$108,3)="642")*N(DATA_F01!$E$4:$E$108)))
A17: 9. Lợi nhuận thuần từ hoạt động kinh doanh (30 = 20 + 21 - 22 - 24) | B17: 30 | D17: =D12+D13-D14-D16
A18: 10. Thu nhập khác | B18: 31 | D18: =(SUMPRODUCT((DATA_F01!$I$4:$I$108=1)*(LEFT(DATA_F01!$A$4:$A$108,3)="711")*N(DATA_F01!$F$4:$F$108)))
A19: 11. Chi phí khác | B19: 32 | D19: =(SUMPRODUCT((DATA_F01!$I$4:$I$108=1)*(LEFT(DATA_F01!$A$4:$A$108,3)="811")*N(DATA_F01!$E$4:$E$108)))
A20: 12. Lợi nhuận khác (40 = 31 - 32) | B20: 40 | D20: =D18-D19
A21: 13. Tổng lợi nhuận kế toán trước thuế (50 = 30 + 40) | B21: 50 | D21: =D17+D20
A22: 14. Chi phí thuế thu nhập doanh nghiệp | B22: 51 | D22: =(SUMPRODUCT((DATA_F01!$I$4:$I$108=1)*(LEFT(DATA_F01!$A$4:$A$108,3)="821")*N(DATA_F01!$E$4:$E$108)))
A23: 15. Lợi nhuận sau thuế thu nhập doanh nghiệp (60 = 50 - 51) | B23: 60 | D23: =D21-D22
A25: Mã 23 "Trong đó: Chi phí lãi vay" là dòng thuyết minh của mã 22, KHÔNG tham gia công thức cộng trừ. Mã 02 lấy từ PS Nợ TK 511 đối ứng Có TK 111/112/131 — TT133 không có TK 521 nên số liệu này do người dùng khai báo.
D27: Ngày ..... tháng ..... năm .....
A28: NGƯỜI LẬP BIỂU | C28: KẾ TOÁN TRƯỞNG | D28: NGƯỜI ĐẠI DIỆN THEO PHÁP LUẬT
A29: (Ký, họ tên) | C29: (Ký, họ tên) | D29: (Ký, họ tên, đóng dấu)
A32: Nguyễn Thị Hoa | C32: Trần Văn Nam | D32: Lê Minh Anh
A34: Lập bằng Công cụ lập & kiểm tra BCTC theo Thông tư 133 — KK HOME · · TT133-MAP-2026.08 · Xuất lúc 10:59:49 14/8/2026

Sheet B09_DNN
A1: CÔNG TY TNHH THƯƠNG MẠI MINH ANH
A2: MST: 0101234567 · Số 12 phố Láng Hạ, phường Láng, TP Hà Nội
A4: BẢN THUYẾT MINH BÁO CÁO TÀI CHÍNH
A5: Năm 2025 · Mẫu số B09-DNN (Ban hành theo Thông tư số 133/2016/TT-BTC ngày 26/8/2016 của Bộ Tài chính)
A6: I. Đặc điểm hoạt động của doanh nghiệp
A7: 1. Hình thức sở hữu vốn
A8: 2. Lĩnh vực kinh doanh
A9: 3. Ngành nghề kinh doanh
A10: 4. Chu kỳ sản xuất, kinh doanh thông thường
A11: 5. Đặc điểm hoạt động của doanh nghiệp trong năm tài chính có ảnh hưởng đến BCTC
A12: 6. Tuyên bố về khả năng so sánh thông tin trên BCTC
A13: II. Kỳ kế toán, đơn vị tiền tệ sử dụng trong kế toán
A14: 1. Kỳ kế toán năm | B14: Kỳ kế toán năm bắt đầu từ ngày 01/01/2025 và kết thúc vào ngày 31/12/2025.
A15: 2. Đơn vị tiền tệ sử dụng trong kế toán | B15: Đơn vị tiền tệ sử dụng trong kế toán: VND. Đơn vị trình bày trên báo cáo: Đồng.
A16: III. Chuẩn mực và Chế độ kế toán áp dụng
A17: Chế độ kế toán áp dụng | B17: Công ty áp dụng Chế độ kế toán doanh nghiệp nhỏ và vừa ban hành theo Thông tư số 133/2016/TT-BTC ngày 26/8/2016 của Bộ Tài chính.
A18: Tuyên bố về việc tuân thủ Chuẩn mực kế toán và Chế độ kế toán
A19: IV. Các chính sách kế toán áp dụng
A20: 1. Tỷ giá hối đoái áp dụng trong kế toán
A21: 2. Nguyên tắc chuyển đổi BCTC lập bằng ngoại tệ sang Đồng Việt Nam
A22: 3. Nguyên tắc ghi nhận tiền và các khoản tương đương tiền
A23: 4. Nguyên tắc kế toán các khoản đầu tư tài chính
A24: 5. Nguyên tắc kế toán nợ phải thu
A25: 6. Nguyên tắc ghi nhận hàng tồn kho
A26: 7. Nguyên tắc ghi nhận và phương pháp khấu hao TSCĐ
A27: 8. Nguyên tắc kế toán nợ phải trả
A28: 9. Nguyên tắc ghi nhận và vốn hóa chi phí đi vay
A29: 10. Nguyên tắc ghi nhận vốn chủ sở hữu
... A33: 1. Tiền và các khoản tương đương tiền
A34: Tài khoản | B34: Tên tài khoản | C34: Đầu năm | D34: Cuối năm
A35: 111 | B35: Tiền mặt | C35: 120000000 | D35: 355500000
A36: 112 | B36: Tiền gửi Ngân hàng | C36: 480000000 | D36: 367000000
A37: 1281 | B37: Tiền gửi có kỳ hạn | C37: 200000000 | D37: 400000000
A38: Thuyết minh bổ sung
A39: 2. Các khoản đầu tư tài chính
A40: Tài khoản | B40: Tên tài khoản | C40: Đầu năm | D40: Cuối năm
A41: 1281 | B41: Tiền gửi có kỳ hạn | C41: 200000000 | D41: 400000000
A42: 228 | B42: Đầu tư góp vốn vào đơn vị khác | C42: 500000000 | D42: 500000000
A43: ⚠ Tách ngắn hạn/dài hạn và giá trị hợp lý phải nhập tay.
A44: Thuyết minh bổ sung
...

Sheet F01_DNN
A1: CÔNG TY TNHH THƯƠNG MẠI MINH ANH
A2: MST: 0101234567 · Số 12 phố Láng Hạ, phường Láng, TP Hà Nội
A4: BẢNG CÂN ĐỐI TÀI KHOẢN
A5: Năm 2025 · Mẫu số F01-DNN (Ban hành theo Thông tư số 133/2016/TT-BTC ngày 26/8/2016 của Bộ Tài chính)
A6: Đơn vị tính: Đồng
A7: Số hiệu tài khoản | B7: Tên tài khoản | C7: Số dư đầu năm | E7: Số phát sinh trong năm | G7: Số dư cuối năm
C8: Nợ | D8: Có | E8: Nợ | F8: Có | G8: Nợ | H8: Có
A9: 111 | B9: Tiền mặt | C9: =DATA_F01!$C$4 | D9: =DATA_F01!$D$4 | E9: =DATA_F01!$E$4 | F9: =DATA_F01!$F$4 | G9: =DATA_F01!$G$4 | H9: =DATA_F01!$H$4
A10: 112 | B10: Tiền gửi Ngân hàng | C10: =DATA_F01!$C$5 | D10: =DATA_F01!$D$5 | E10: =DATA_F01!$E$5 | F10: =DATA_F01!$F$5 | G10: =DATA_F01!$G$5 | H10: =DATA_F01!$H$5
A11: 1281 | B11: Tiền gửi có kỳ hạn | C11: =DATA_F01!$C$6 | D11: =DATA_F01!$D$6 | E11: =DATA_F01!$E$6 | F11: =DATA_F01!$F$6 | G11: =DATA_F01!$G$6 | H11: =DATA_F01!$H$6
A12: 131-KH01 | B12: Phải thu KH — Công ty An Phát | C12: =DATA_F01!$C$7 | D12: =DATA_F01!$D$7 | E12: =DATA_F01!$E$7 | F12: =DATA_F01!$F$7 | G12: =DATA_F01!$G$7 | H12: =DATA_F01!$H$7
A13: 131-KH02 | B13: Phải thu KH — Công ty Bình Minh | C13: =DATA_F01!$C$8 | D13: =DATA_F01!$D$8 | E13: =DATA_F01!$E$8 | F13: =DATA_F01!$F$8 | G13: =DATA_F01!$G$8 | H13: =DATA_F01!$H$8
A14: 131-KH03 | B14: Phải thu KH — Công ty Cường Thịnh | C14: =DATA_F01!$C$9 | D14: =DATA_F01!$D$9 | E14: =DATA_F01!$E$9 | F14: =DATA_F01!$F$9 | G14: =DATA_F01!$G$9 | H14: =DATA_F01!$H$9
A15: 133 | B15: Thuế GTGT được khấu trừ | C15: =DATA_F01!$C$10 | D15: =DATA_F01!$D$10 | E15: =DATA_F01!$E$10 | F15: =DATA_F01!$F$10 | G15: =DATA_F01!$G$10 | H15: =DATA_F01!$H$10
A16: 1381 | B16: Tài sản thiếu chờ xử lý | C16: =DATA_F01!$C$11 | D16: =DATA_F01!$D$11 | E16: =DATA_F01!$E$11 | F16: =DATA_F01!$F$11 | G16: =DATA_F01!$G$11 | H16: =DATA_F01!$H$11
A17: 1388 | B17: Phải thu khác | C17: =DATA_F01!$C$12 | D17: =DATA_F01!$D$12 | E17: =DATA_F01!$E$12 | F17: =DATA_F01!$F$12 | G17: =DATA_F01!$G$12 | H17: =DATA_F01!$H$12
A18: 141 | B18: Tạm ứng | C18: =DATA_F01!$C$13 | D18: =DATA_F01!$D$13 | E18: =DATA_F01!$E$13 | F18: =DATA_F01!$F$13 | G18: =DATA_F01!$G$13 | H18: =DATA_F01!$H$13
A19: 152 | B19: Nguyên liệu, vật liệu | C19: =DATA_F01!$C$14 | D19: =DATA_F01!$D$14 | E19: =DATA_F01!$E$14 | F19: =DATA_F01!$F$14 | G19: =DATA_F01!$G$14 | H19: =DATA_F01!$H$14
A20: 156 | B20: Hàng hóa | C20: =DATA_F01!$C$15 | D20: =DATA_F01!$D$15 | E20: =DATA_F01!$E$15 | F20: =DATA_F01!$F$15 | G20: =DATA_F01!$G$15 | H20: =DATA_F01!$H$15
A21: 211 | B21: Tài sản cố định | C21: =DATA_F01!$C$16 | D21: =DATA_F01!$D$16 | E21: =DATA_F01!$E$16 | F21: =DATA_F01!$F$16 | G21: =DATA_F01!$G$16 | H21: =DATA_F01!$H$16
A22: 2141 | B22: Hao mòn TSCĐ hữu hình | C22: =DATA_F01!$C$17 | D22: =DATA_F01!$D$17 | E22: =DATA_F01!$E$17 | F22: =DATA_F01!$F$17 | G22: =DATA_F01!$G$17 | H22: =DATA_F01!$H$17
A23: 228 | B23: Đầu tư góp vốn vào đơn vị khác | C23: =DATA_F01!$C$18 | D23: =DATA_F01!$D$18 | E23: =DATA_F01!$E$18 | F23: =DATA_F01!$F$18 | G23: =DATA_F01!$G$18 | H23: =DATA_F01!$H$18
A24: 2293 | B24: Dự phòng phải thu khó đòi | C24: =DATA_F01!$C$19 | D24: =DATA_F01!$D$19 | E24: =DATA_F01!$E$19 | F24: =DATA_F01!$F$19 | G24: =DATA_F01!$G$19 | H24: =DATA_F01!$H$19
A25: 2294 | B25: Dự phòng giảm giá hàng tồn kho | C25: =DATA_F01!$C$20 | D25: =DATA_F01!$D$20 | E25: =DATA_F01!$E$20 | F25: =DATA_F01!$F$20 | G25: =DATA_F01!$G$20 | H25: =DATA_F01!$H$20
A26: 242 | B26: Chi phí trả trước | C26: =DATA_F01!$C$21 | D26: =DATA_F01!$D$21 | E26: =DATA_F01!$E$21 | F26: =DATA_F01!$F$21 | G26: =DATA_F01!$G$21 | H26: =DATA_F01!$H$21
A27: 331-NCC01 | B27: Phải trả NB — Công ty Đại Việt | C27: =DATA_F01!$C$22 | D27: =DATA_F01!$D$22 | E27: =DATA_F01!$E$22 | F27: =DATA_F01!$F$22 | G27: =DATA_F01!$G$22 | H27: =DATA_F01!$H$22
A28: 331-NCC02 | B28: Phải trả NB — Công ty Hồng Hà | C28: =DATA_F01!$C$23 | D28: =DATA_F01!$D$23 | E28: =DATA_F01!$E$23 | F28: =DATA_F01!$F$23 | G28: =DATA_F01!$G$23 | H28: =DATA_F01!$H$23
A29: 331-NCC03 | B29: Phải trả NB — Công ty Sao Mai | C29: =DATA_F01!$C$24 | D29: =DATA_F01!$D$24 | E29: =DATA_F01!$E$24 | F29: =DATA_F01!$F$24 | G29: =DATA_F01!$G$24 | H29: =DATA_F01!$H$24
A30: 33311 | B30: Thuế GTGT đầu ra | C30: =DATA_F01!$C$25 | D30: =DATA_F01!$D$25 | E30: =DATA_F01!$E$25 | F30: =DATA_F01!$F$25 | G30: =DATA_F01!$G$25 | H30: =DATA_F01!$H$25
A31: 3334 | B31: Thuế thu nhập doanh nghiệp | C31: =DATA_F01!$C$26 | D31: =DATA_F01!$D$26 | E31: =DATA_F01!$E$26 | F31: =DATA_F01!$F$26 | G31: =DATA_F01!$G$26 | H31: =DATA_F01!$H$26
A32: 3335 | B32: Thuế thu nhập cá nhân | C32: =DATA_F01!$C$27 | D32: =DATA_F01!$D$27 | E32: =DATA_F01!$E$27 | F32: =DATA_F01!$F$27 | G32: =DATA_F01!$G$27 | H32: =DATA_F01!$H$27
A33: 3338 | B33: Thuế bảo vệ môi trường và các loại thuế khác | C33: =DATA_F01!$C$28 | D33: =DATA_F01!$D$28 | E33: =DATA_F01!$E$28 | F33: =DATA_F01!$F$28 | G33: =DATA_F01!$G$28 | H33: =DATA_F01!$H$28
A34: 334 | B34: Phải trả người lao động | C34: =DATA_F01!$C$29 | D34: =DATA_F01!$D$29 | E34: =DATA_F01!$E$29 | F34: =DATA_F01!$F$29 | G34: =DATA_F01!$G$29 | H34: =DATA_F01!$H$29
A35: 3383 | B35: Bảo hiểm xã hội, y tế, thất nghiệp | C35: =DATA_F01!$C$30 | D35: =DATA_F01!$D$30 | E35: =DATA_F01!$E$30 | F35: =DATA_F01!$F$30 | G35: =DATA_F01!$G$30 | H35: =DATA_F01!$H$30
A36: 3387 | B36: Doanh thu chưa thực hiện | C36: =DATA_F01!$C$31 | D36: =DATA_F01!$D$31 | E36: =DATA_F01!$E$31 | F36: =DATA_F01!$F$31 | G36: =DATA_F01!$G$31 | H36: =DATA_F01!$H$31
A37: 3411 | B37: Các khoản đi vay | C37: =DATA_F01!$C$32 | D37: =DATA_F01!$D$32 | E37: =DATA_F01!$E$32 | F37: =DATA_F01!$F$32 | G37: =DATA_F01!$G$32 | H37: =DATA_F01!$H$32
A38: 352 | B38: Dự phòng phải trả | C38: =DATA_F01!$C$33 | D38: =DATA_F01!$D$33 | E38: =DATA_F01!$E$33 | F38: =DATA_F01!$F$33 | G38: =DATA_F01!$G$33 | H38: =DATA_F01!$H$33
A39: 353 | B39: Quỹ khen thưởng, phúc lợi | C39: =DATA_F01!$C$34 | D39: =DATA_F01!$D$34 | E39: =DATA_F01!$E$34 | F39: =DATA_F01!$F$34 | G39: =DATA_F01!$G$34 | H39: =DATA_F01!$H$34
A40: 4111 | B40: Vốn góp của chủ sở hữu | C40: =DATA_F01!$C$35 | D40: =DATA_F01!$D$35 | E40: =DATA_F01!$E$35 | F40: =DATA_F01!$F$35 | G40: =DATA_F01!$G$35 | H40: =DATA_F01!$H$35
A41: 418 | B41: Các quỹ thuộc vốn chủ sở hữu | C41: =DATA_F01!$C$36 | D41: =DATA_F01!$D$36 | E41: =DATA_F01!$E$36 | F41: =DATA_F01!$F$36 | G41: =DATA_F01!$G$36 | H41: =DATA_F01!$H$36
...

Sheet KIEM_TRA_BCTC
A1: KIỂM TRA & CẢNH BÁO BÁO CÁO TÀI CHÍNH
A2: Ba cấp: ???? Lỗi (chắc chắn sai) · ???? Cần kiểm tra (không khẳng định sai) · ???? Đã kiểm tra đạt
A3: ĐIỂM HOÀN THIỆN BCTC | B3: 14/23 kiểm tra đạt | C3: 9 nội dung cần xem lại | D3: 0 lỗi nghiêm trọng
A5: Cấp | B5: Nhóm | C5: Nội dung kiểm tra | D5: Kết quả / Giải thích
A6: ???? KIỂM TRA | B6: Tài khoản lưỡng tính | C6: TK 141 chỉ có số dư tổng hợp một bên | D6: Không đủ dữ liệu chi tiết để tự động phân loại — vui lòng nhập số liệu chi tiết (theo từng người nhận tạm ứng) ở Bước 3 hoặc điều chỉnh mapping. Dư Nợ chi tiết → Mã 134 – Phải thu khác; Dư Có chi tiết → Mã 315 – Phải trả khác. Theo TT133, KHÔNG được bù trừ số dư Nợ/Có của tài khoản này.
A7: ???? KIỂM TRA | B7: Tài khoản lưỡng tính | C7: TK 334 chỉ có số dư tổng hợp một bên | D7: Không đủ dữ liệu chi tiết để tự động phân loại — vui lòng nhập số liệu chi tiết (theo từng người lao động) ở Bước 3 hoặc điều chỉnh mapping. Dư Nợ chi tiết → Mã 134 – Phải thu khác; Dư Có chi tiết → Mã 314 – Phải trả người lao động. Theo TT133, KHÔNG được bù trừ số dư Nợ/Có của tài khoản này.
A8: ???? KIỂM TRA | B8: Tài khoản lưỡng tính | C8: TK 1388 chỉ có số dư tổng hợp một bên | D8: Không đủ dữ liệu chi tiết để tự động phân loại — vui lòng nhập số liệu chi tiết (theo từng đối tượng) ở Bước 3 hoặc điều chỉnh mapping. Dư Nợ chi tiết → Mã 134 – Phải thu khác; Dư Có chi tiết → Mã 315 – Phải trả khác. Theo TT133, KHÔNG được bù trừ số dư Nợ/Có của tài khoản này.
A9: ???? KIỂM TRA | B9: Công nợ | C9: TK 131 có số dư Có 170.000.000 | D9: Đây KHÔNG phải lỗi — là khoản người mua trả tiền trước, trình bày ở mã 312 bên Nguồn vốn. Cần xác nhận số liệu đã chi tiết theo từng khách hàng.
A10: ???? KIỂM TRA | B10: Công nợ | C10: TK 331 có số dư Nợ 100.000.000 | D10: Đây KHÔNG phải lỗi — là khoản trả trước cho người bán, trình bày ở mã 132 bên Tài sản. Cần xác nhận số liệu đã chi tiết theo từng nhà cung cấp.
A11: ???? KIỂM TRA | B11: Thuế | C11: TK 333 có số dư Nợ 8.000.000 (thuế nộp thừa) | D11: Khoản thuế nộp thừa được trình bày ở mã 182 "Tài sản khác", KHÔNG bù trừ với mã 313. Cần đối chiếu với thông báo/biên lai nộp thuế và số liệu trên eTax.
A12: ???? KIỂM TRA | B12: Dữ liệu | C12: 10 tài khoản có số dư cuối kỳ do CÔNG CỤ TỰ TÍNH, không phải số bạn nhập | D12: Các tài khoản sau không có số dư cuối kỳ trong dữ liệu nguồn nên công cụ đã tự tính theo công thức Dư cuối = Dư đầu + PS Nợ − PS Có: 511, 515, 632, 635, 6421, 6422, 711, 811, 821, 911. Phép tính này chỉ đúng khi số dư đầu kỳ và số phát sinh đã đầy đủ. Vui lòng đối chiếu với Sổ Cái trước khi chốt số.
A13: ???? KIỂM TRA | B13: B02 | C13: Mã 02 — Các khoản giảm trừ doanh thu được SUY RA, cần xác nhận | D13: TT133 không có TK 521 nên chiết khấu thương mại, giảm giá hàng bán và hàng bán bị trả lại ghi thẳng Nợ TK 511. Công cụ suy ra 50.000.000 = PS Nợ TK 511 (4.845.000.000) − doanh thu thuần kết chuyển (4.795.000.000). Phép suy này chỉ đúng khi sổ đã kết chuyển đầy đủ qua TK 911. LƯU Ý: nếu doanh nghiệp ghi nhận doanh thu gộp rồi định kỳ ghi giảm thuế gián thu (Nợ TK 511 / Có TK 3331, 3332, 3333, 33381), phần thuế đó cũng nằm trong số suy ra ở trên nhưng KHÔNG phải là khoản giảm trừ doanh thu — khi đó mã 01 đang bị tính gộp cả thuế gián thu, trái với hướng dẫn của TT133. Hãy đối chiếu sổ chi tiết TK 511 và nhập lại mã 02 ở Bước 3 nếu khác.
A14: ???? KIỂM TRA | B14: Đối chiếu | C14: Biến động TK 421 chưa giải thích hết -100.000.000 | D14: ĐÂY KHÔNG PHẢI LỖI MẶC ĐỊNH. Chênh lệch giữa LNST trên B02 và biến động TK 421 có thể do: phân phối lợi nhuận, trích lập các quỹ, chia cổ tức/lợi nhuận, điều chỉnh hồi tố sai sót năm trước, thay đổi chính sách kế toán, kết chuyển 4212 → 4211 đầu năm. Hãy nhập các khoản này vào bảng đối chiếu lợi nhuận để giải thích phần chênh lệch.
A15: ???? ĐẠT | B15: Cân đối tài khoản | C15: Tổng dư Nợ đầu kỳ = Tổng dư Có đầu kỳ | D15: Dư Nợ đầu kỳ 5.736.000.000 — Dư Có đầu kỳ 5.736.000.000 — Chênh lệch 0
... A28: ???? ĐẠT | B28: Cân đối BCTC | C28: Cột Số đầu năm cũng cân đối (Tài sản = Nguồn vốn) | D28: Tài sản 5.206.000.000 — Nguồn vốn 5.206.000.000
A30: BẢNG ĐỐI CHIẾU LỢI NHUẬN CHƯA PHÂN PHỐI
C31: Lợi nhuận chưa phân phối đầu kỳ (dư TK 421 đầu kỳ) | D31: 438000000
C32: Cộng: Lợi nhuận sau thuế năm nay (mã 60 — B02-DNN) | D32: 267000000
C33: Cộng/trừ: Điều chỉnh hồi tố sai sót, thay đổi chính sách kế toán | D33: 0
C34: Trừ: Phân phối lợi nhuận, trích lập các quỹ (TK 353, 418) | D34: 0
C35: Trừ: Cổ tức, lợi nhuận đã chia cho chủ sở hữu | D35: 0
C36: Cộng/trừ: Các nghiệp vụ khác | D36: 0
C37: = Lợi nhuận chưa phân phối cuối kỳ (theo tính toán) | D37: 705000000
C38: Số dư TK 421 cuối kỳ thực tế trên sổ | D38: 605000000
C39: Chênh lệch chưa giải thích | D39: -100000000
C41: Lưu ý | D41: Công cụ KHÔNG mặc định "Lợi nhuận sau thuế trên B02 = biến động TK 421". Chênh lệch có thể do phân phối lợi nhuận, trích lập quỹ, chia cổ tức, điều chỉnh hồi tố sai sót năm trước, thay đổi chính sách kế toán hoặc kết chuyển TK 4212 sang TK 4211.

Sheet DOI_CHIEU_THUE
A1: RÀ SOÁT THUẾ TRƯỚC KHI CHỐT BÁO CÁO TÀI CHÍNH
A2: Đây là module CẢNH BÁO, không tự động điều chỉnh BCTC. Chênh lệch giữa số liệu kế toán và số liệu thuế KHÔNG được coi là lỗi mặc định.
A3: Nhóm | B3: Nội dung rà soát | C3: Trạng thái | D3: Số liệu trên sổ | E3: Hướng dẫn đối chiếu — nguyên nhân chênh lệch có thể
A4: Thuế GTGT | B4: Số dư TK 133 cuối kỳ | C4: CẦN ĐỐI CHIẾU | D4: Thuế GTGT còn được khấu trừ chuyển kỳ sau: 20.000.000. | E4: Đối chiếu với chỉ tiêu [43] "Thuế GTGT còn được khấu trừ chuyển kỳ sau" trên tờ khai 01/GTGT tháng/quý cuối cùng của năm. Chênh lệch có thể do: hóa đơn kê khai khác kỳ hạch toán, hóa đơn bỏ sót, điều chỉnh sau thanh tra, hàng hoàn/giảm giá. KHÔNG mặc định là sai.
A5: Thuế GTGT | B5: Số dư TK 3331 cuối kỳ | C5: CẦN ĐỐI CHIẾU | D5: Thuế GTGT còn phải nộp: 78.500.000. | E5: Đối chiếu với chỉ tiêu [40] trên tờ khai và số dư trên eTax/thuedientu. Nếu đã nộp sau ngày 31/12 thì số dư này là bình thường.
A6: Thuế GTGT | B6: Đối chiếu doanh thu sổ sách với doanh thu tờ khai | C6: CẦN ĐỐI CHIẾU | D6: Doanh thu bán hàng (mã 01 B02) = 4.845.000.000; PS Có TK 3331 = 483.500.000; PS Nợ TK 133 = 395.000.000. | E6: KHÔNG mặc định doanh thu kế toán = doanh thu tính thuế GTGT. Nguyên nhân chênh lệch hợp lệ: doanh thu chưa thực hiện (TK 3387), hàng bán trả lại/giảm giá khác kỳ, doanh thu không chịu thuế/0%, hàng biếu tặng phải xuất hóa đơn, thời điểm lập hóa đơn theo NĐ 70/2025 khác thời điểm ghi nhận doanh thu.
A7: Thuế TNDN | B7: Chi phí thuế TNDN so với lợi nhuận kế toán trước thuế | C7: Không có số dư | D7: LN kế toán trước thuế (mã 50) = 334.000.000; Chi phí thuế TNDN (mã 51) = 67.000.000; tỷ lệ hiệu dụng ≈ 20.1%. | E7: KHÔNG mặc định thuế TNDN = LN kế toán × thuế suất. Chênh lệch hợp lệ: chi phí không được trừ, thu nhập miễn thuế, chuyển lỗ các năm trước, ưu đãi thuế, trích lập Quỹ KH&CN. Hãy dùng bảng "Lợi nhuận kế toán → Thu nhập tính thuế" bên dưới.
A8: Thuế TNDN | B8: Số dư TK 3334 | C8: CẦN ĐỐI CHIẾU | D8: Còn phải nộp 47.000.000; nộp thừa 0. | E8: Đối chiếu với tờ khai quyết toán 03/TNDN và chứng từ nộp thuế. Thuế nộp thừa (dư Nợ) trình bày ở mã 182, KHÔNG bù trừ với mã 313.
A9: Thuế TNCN | B9: Số dư TK 3335 | C9: CẦN ĐỐI CHIẾU | D9: Thuế TNCN còn phải nộp: 8.000.000. | E9: Đối chiếu với tờ khai 05/KK-TNCN các kỳ và quyết toán 05/QTT-TNCN. Lưu ý Luật Thuế TNCN số 109/2025/QH15 (hiệu lực 01/7/2026) áp dụng biểu thuế 5 bậc và mức giảm trừ gia cảnh mới từ kỳ tính thuế 2026 — cần xác định đúng kỳ áp dụng.
A10: Lương & BHXH | B10: Số dư TK 334 | C10: CẦN ĐỐI CHIẾU | D10: Còn phải trả người lao động: 150.000.000. | E10: Đối chiếu bảng lương tháng 12, hợp đồng lao động, quy chế lương thưởng. Lương chưa chi đến hạn nộp hồ sơ quyết toán có rủi ro bị loại khỏi chi phí được trừ — cần chứng từ chi thực tế.
A11: Lương & BHXH | B11: Số dư BHXH/BHYT/BHTN (TK 3383, 3384, 3385) | C11: CẦN ĐỐI CHIẾU | D11: Còn phải nộp: 50.000.000. | E11: Đối chiếu với thông báo kết quả đóng BHXH (mẫu C12-TS). Nợ BHXH quá hạn có thể bị loại chi phí và bị tính lãi chậm đóng.
A12: Lương & BHXH | B12: Kinh phí công đoàn (TK 3382) | C12: Không có số dư | D12: Số dư: 0. | E12: Đối chiếu tỷ lệ trích 2% quỹ tiền lương làm căn cứ đóng BHXH.
A13: Chi phí trả trước | B13: Số dư TK 242 | C13: CẦN ĐỐI CHIẾU | D13: Chi phí trả trước còn lại: 160.000.000. | E13: Rà soát bảng phân bổ: thời gian phân bổ tối đa 3 năm với công cụ dụng cụ; chi phí thuê tài sản phân bổ theo thời gian thuê. Kiểm tra khoản đã hết thời gian sử dụng nhưng chưa phân bổ hết.
A14: TSCĐ & khấu hao | B14: Nguyên giá và hao mòn lũy kế | C14: CẦN ĐỐI CHIẾU | D14: Nguyên giá 2.750.000.000; hao mòn lũy kế 660.000.000; giá trị còn lại 2.090.000.000; khấu hao trích trong kỳ (PS Có TK 214) 160.000.000. | E14: Đối chiếu Bảng tính và phân bổ khấu hao. Kiểm tra: khung thời gian trích khấu hao theo quy định hiện hành; TSCĐ không phục vụ SXKD; xe ô tô chở người từ 9 chỗ trở xuống có nguyên giá vượt 1,6 tỷ đồng (phần vượt không được trừ); TSCĐ đã khấu hao hết nhưng còn sử dụng; TSCĐ chưa có đầy đủ hồ sơ chứng minh quyền sở hữu.
... A24: Công nợ thuế | B24: Tổng hợp số dư TK 333 | C24: CẦN ĐỐI CHIẾU | D24: Còn phải nộp 133.500.000; nộp thừa 8.000.000. | E24: Đối chiếu với "Thông báo số thuế còn phải nộp" hoặc tra cứu nghĩa vụ thuế trên eTax. Chênh lệch có thể do tiền chậm nộp, phạt vi phạm hành chính chưa hạch toán, hoặc bút toán bù trừ giữa các sắc thuế.
A26: BẢNG HỖ TRỢ RÀ SOÁT QUYẾT TOÁN THUẾ TNDN
A27: A. Tổng lợi nhuận kế toán trước thuế (mã 50 — B02-DNN) | D27: 334000000
A28: B. Các khoản điều chỉnh TĂNG thu nhập chịu thuế | D28: 0 | E28: Chi phí không được trừ: chứng từ không hợp lệ, chi vượt định mức, khoản trích trước không đúng, phần chi vượt mức khống chế, tiền phạt vi phạm hành chính…
A29: C. Các khoản điều chỉnh GIẢM thu nhập chịu thuế | D29: 0 | E29: Hoàn nhập chi phí đã loại kỳ trước, thu nhập đã tính thuế ở khâu trước, chênh lệch do phương pháp khấu hao…
A30: D. Tổng thu nhập chịu thuế (D = A + B − C) | D30: =D27+D28-D29
A31: E. Thu nhập được miễn thuế | D31: 0
A32: F. Lỗ kết chuyển từ các năm trước | D32: 0 | E32: Lỗ được chuyển liên tục không quá 5 năm kể từ năm tiếp sau năm phát sinh lỗ.
A33: G. Trích lập Quỹ phát triển khoa học và công nghệ | D33: 0
A34: H. Thu nhập tính thuế (H = D − E − F − G) | D34: =D30-D31-D32-D33
A35: I. Thuế suất thuế TNDN (%) | D35: 17 | E35: Luật Thuế TNDN số 67/2025/QH15 (hiệu lực 01/10/2025, áp dụng từ kỳ tính thuế 2025) quy định thuế suất theo QUY MÔ DOANH THU: 15% với doanh thu năm không quá 3 tỷ đồng; 17% với doanh thu trên 3 tỷ đến 50 tỷ đồng; 20% với các trường hợp còn lại. Đây là thuế suất theo quy mô, KHÔNG phải ưu đãi phải đăng ký. Doanh thu thuần kỳ này (mã 10) = 4.795.000.000 → công cụ gợi ý 17%. Vui lòng tự xác định lại theo điều kiện áp dụng thực tế và các mức ưu đãi riêng (nếu có).
A36: K. Thuế TNDN phải nộp (K = H × I) | D36: =MAX(0,D34)*D35/100
A37: L. Chi phí thuế TNDN đã hạch toán (mã 51 — B02-DNN) | D37: 67000000
A38: M. Chênh lệch cần giải trình (M = K − L) | D38: =D36-D37
A40: Bảng này chỉ hỗ trợ rà soát, KHÔNG ghi vào Báo cáo tài chính. Số liệu chính thức phải căn cứ tờ khai quyết toán thuế TNDN mẫu 03/TNDN và các phụ lục kèm theo.
