Workbook

Sheet 01_DANH_MUC
A1: HỆ THỐNG QUẢN LÝ CÔNG NỢ & TUỔI NỢ ĐA NĂNG - THIẾT KẾ BỞI KK HOME
A2: Số liệu phải sắc - Kiểm soát phải chắc.
A3: Nhập dữ liệu tại các ô màu vàng. Số dư đầu kỳ là số dư ngay trước giao dịch đầu tiên được nhập tại sheet 02_NHAT_KY.
A5: DANH MỤC KHÁCH HÀNG & NHÀ CUNG CẤP
A6: Mã Đối Tượng | B6: Tên Đối Tượng | C6: Phân loại | D6: Hạn mức nợ tối đa (VND) | E6: Thời hạn cho nợ tiêu chuẩn (ngày) | F6: Số dư đầu kỳ (VND) | G6: Ngày đến hạn của dư đầu kỳ | H6: Dư đầu kỳ còn lại (FIFO) | I6: Nhóm tuổi dư đầu kỳ | J6: Kiểm tra dữ liệu
A7: KH001 | B7: Công ty TNHH Minh Phát | C7: Phải thu | D7: 150000000 | E7: 30 | F7: 50000000 | G7: 46006 | H7: =IF($A7="","",MAX(0,$F7-SUMIFS('02_NHAT_KY'!$H$7:$H$506,'02_NHAT_KY'!$C$7:$C$506,$A7,'02_NHAT_KY'!$A$7:$A$506,"<="&'03_BAO_CAO'!$E$4))) | I7: =IF($A7="","",IF($H7<=0,"Đã thanh toán",IF($G7="","Thiếu hạn",IF($G7>='03_BAO_CAO'!$E$4,"Chưa đến hạn",IF('03_BAO_CAO'!$E$4-$G7<=30,"1-30 ngày",IF('03_BAO_CAO'!$E$4-$G7<=60,"31-60 ngày",IF('03_BAO_CAO'!$E$4-$G7<=90,"61-90 ngày","Trên 90 ngày"))))))) | J7: =IF($A7="","",IF(COUNTIF($A$7:$A$206,$A7)>1,"TRÙNG MÃ",IF(OR($B7="",$C7="",$D7<0,$E7<0,$F7<0),"KIỂM TRA DỮ LIỆU",IF(AND($F7>0,$G7=""),"THIẾU HẠN DƯ ĐẦU KỲ","OK"))))
A8: KH002 | B8: Công ty CP An Khang | C8: Phải thu | D8: 120000000 | E8: 45 | F8: 0 | H8: =IF($A8="","",MAX(0,$F8-SUMIFS('02_NHAT_KY'!$H$7:$H$506,'02_NHAT_KY'!$C$7:$C$506,$A8,'02_NHAT_KY'!$A$7:$A$506,"<="&'03_BAO_CAO'!$E$4))) | I8: =IF($A8="","",IF($H8<=0,"Đã thanh toán",IF($G8="","Thiếu hạn",IF($G8>='03_BAO_CAO'!$E$4,"Chưa đến hạn",IF('03_BAO_CAO'!$E$4-$G8<=30,"1-30 ngày",IF('03_BAO_CAO'!$E$4-$G8<=60,"31-60 ngày",IF('03_BAO_CAO'!$E$4-$G8<=90,"61-90 ngày","Trên 90 ngày"))))))) | J8: =IF($A8="","",IF(COUNTIF($A$7:$A$206,$A8)>1,"TRÙNG MÃ",IF(OR($B8="",$C8="",$D8<0,$E8<0,$F8<0),"KIỂM TRA DỮ LIỆU",IF(AND($F8>0,$G8=""),"THIẾU HẠN DƯ ĐẦU KỲ","OK"))))
A9: NCC001 | B9: Công ty TNHH Nguyên Liệu Việt | C9: Phải trả | D9: 300000000 | E9: 30 | F9: 80000000 | G9: 46096 | H9: =IF($A9="","",MAX(0,$F9-SUMIFS('02_NHAT_KY'!$H$7:$H$506,'02_NHAT_KY'!$C$7:$C$506,$A9,'02_NHAT_KY'!$A$7:$A$506,"<="&'03_BAO_CAO'!$E$4))) | I9: =IF($A9="","",IF($H9<=0,"Đã thanh toán",IF($G9="","Thiếu hạn",IF($G9>='03_BAO_CAO'!$E$4,"Chưa đến hạn",IF('03_BAO_CAO'!$E$4-$G9<=30,"1-30 ngày",IF('03_BAO_CAO'!$E$4-$G9<=60,"31-60 ngày",IF('03_BAO_CAO'!$E$4-$G9<=90,"61-90 ngày","Trên 90 ngày"))))))) | J9: =IF($A9="","",IF(COUNTIF($A$7:$A$206,$A9)>1,"TRÙNG MÃ",IF(OR($B9="",$C9="",$D9<0,$E9<0,$F9<0),"KIỂM TRA DỮ LIỆU",IF(AND($F9>0,$G9=""),"THIẾU HẠN DƯ ĐẦU KỲ","OK"))))
A10: NCC002 | B10: Công ty CP Logistics Đông Nam | C10: Phải trả | D10: 150000000 | E10: 15 | F10: 0 | H10: =IF($A10="","",MAX(0,$F10-SUMIFS('02_NHAT_KY'!$H$7:$H$506,'02_NHAT_KY'!$C$7:$C$506,$A10,'02_NHAT_KY'!$A$7:$A$506,"<="&'03_BAO_CAO'!$E$4))) | I10: =IF($A10="","",IF($H10<=0,"Đã thanh toán",IF($G10="","Thiếu hạn",IF($G10>='03_BAO_CAO'!$E$4,"Chưa đến hạn",IF('03_BAO_CAO'!$E$4-$G10<=30,"1-30 ngày",IF('03_BAO_CAO'!$E$4-$G10<=60,"31-60 ngày",IF('03_BAO_CAO'!$E$4-$G10<=90,"61-90 ngày","Trên 90 ngày"))))))) | J10: =IF($A10="","",IF(COUNTIF($A$7:$A$206,$A10)>1,"TRÙNG MÃ",IF(OR($B10="",$C10="",$D10<0,$E10<0,$F10<0),"KIỂM TRA DỮ LIỆU",IF(AND($F10>0,$G10=""),"THIẾU HẠN DƯ ĐẦU KỲ","OK"))))
H11: =IF($A11="","",MAX(0,$F11-SUMIFS('02_NHAT_KY'!$H$7:$H$506,'02_NHAT_KY'!$C$7:$C$506,$A11,'02_NHAT_KY'!$A$7:$A$506,"<="&'03_BAO_CAO'!$E$4))) | I11: =IF($A11="","",IF($H11<=0,"Đã thanh toán",IF($G11="","Thiếu hạn",IF($G11>='03_BAO_CAO'!$E$4,"Chưa đến hạn",IF('03_BAO_CAO'!$E$4-$G11<=30,"1-30 ngày",IF('03_BAO_CAO'!$E$4-$G11<=60,"31-60 ngày",IF('03_BAO_CAO'!$E$4-$G11<=90,"61-90 ngày","Trên 90 ngày"))))))) | J11: =IF($A11="","",IF(COUNTIF($A$7:$A$206,$A11)>1,"TRÙNG MÃ",IF(OR($B11="",$C11="",$D11<0,$E11<0,$F11<0),"KIỂM TRA DỮ LIỆU",IF(AND($F11>0,$G11=""),"THIẾU HẠN DƯ ĐẦU KỲ","OK"))))
H12: =IF($A12="","",MAX(0,$F12-SUMIFS('02_NHAT_KY'!$H$7:$H$506,'02_NHAT_KY'!$C$7:$C$506,$A12,'02_NHAT_KY'!$A$7:$A$506,"<="&'03_BAO_CAO'!$E$4))) | I12: =IF($A12="","",IF($H12<=0,"Đã thanh toán",IF($G12="","Thiếu hạn",IF($G12>='03_BAO_CAO'!$E$4,"Chưa đến hạn",IF('03_BAO_CAO'!$E$4-$G12<=30,"1-30 ngày",IF('03_BAO_CAO'!$E$4-$G12<=60,"31-60 ngày",IF('03_BAO_CAO'!$E$4-$G12<=90,"61-90 ngày","Trên 90 ngày"))))))) | J12: =IF($A12="","",IF(COUNTIF($A$7:$A$206,$A12)>1,"TRÙNG MÃ",IF(OR($B12="",$C12="",$D12<0,$E12<0,$F12<0),"KIỂM TRA DỮ LIỆU",IF(AND($F12>0,$G12=""),"THIẾU HẠN DƯ ĐẦU KỲ","OK"))))
H13: =IF($A13="","",MAX(0,$F13-SUMIFS('02_NHAT_KY'!$H$7:$H$506,'02_NHAT_KY'!$C$7:$C$506,$A13,'02_NHAT_KY'!$A$7:$A$506,"<="&'03_BAO_CAO'!$E$4))) | I13: =IF($A13="","",IF($H13<=0,"Đã thanh toán",IF($G13="","Thiếu hạn",IF($G13>='03_BAO_CAO'!$E$4,"Chưa đến hạn",IF('03_BAO_CAO'!$E$4-$G13<=30,"1-30 ngày",IF('03_BAO_CAO'!$E$4-$G13<=60,"31-60 ngày",IF('03_BAO_CAO'!$E$4-$G13<=90,"61-90 ngày","Trên 90 ngày"))))))) | J13: =IF($A13="","",IF(COUNTIF($A$7:$A$206,$A13)>1,"TRÙNG MÃ",IF(OR($B13="",$C13="",$D13<0,$E13<0,$F13<0),"KIỂM TRA DỮ LIỆU",IF(AND($F13>0,$G13=""),"THIẾU HẠN DƯ ĐẦU KỲ","OK"))))
H14: =IF($A14="","",MAX(0,$F14-SUMIFS('02_NHAT_KY'!$H$7:$H$506,'02_NHAT_KY'!$C$7:$C$506,$A14,'02_NHAT_KY'!$A$7:$A$506,"<="&'03_BAO_CAO'!$E$4))) | I14: =IF($A14="","",IF($H14<=0,"Đã thanh toán",IF($G14="","Thiếu hạn",IF($G14>='03_BAO_CAO'!$E$4,"Chưa đến hạn",IF('03_BAO_CAO'!$E$4-$G14<=30,"1-30 ngày",IF('03_BAO_CAO'!$E$4-$G14<=60,"31-60 ngày",IF('03_BAO_CAO'!$E$4-$G14<=90,"61-90 ngày","Trên 90 ngày"))))))) | J14: =IF($A14="","",IF(COUNTIF($A$7:$A$206,$A14)>1,"TRÙNG MÃ",IF(OR($B14="",$C14="",$D14<0,$E14<0,$F14<0),"KIỂM TRA DỮ LIỆU",IF(AND($F14>0,$G14=""),"THIẾU HẠN DƯ ĐẦU KỲ","OK"))))
H15: =IF($A15="","",MAX(0,$F15-SUMIFS('02_NHAT_KY'!$H$7:$H$506,'02_NHAT_KY'!$C$7:$C$506,$A15,'02_NHAT_KY'!$A$7:$A$506,"<="&'03_BAO_CAO'!$E$4))) | I15: =IF($A15="","",IF($H15<=0,"Đã thanh toán",IF($G15="","Thiếu hạn",IF($G15>='03_BAO_CAO'!$E$4,"Chưa đến hạn",IF('03_BAO_CAO'!$E$4-$G15<=30,"1-30 ngày",IF('03_BAO_CAO'!$E$4-$G15<=60,"31-60 ngày",IF('03_BAO_CAO'!$E$4-$G15<=90,"61-90 ngày","Trên 90 ngày"))))))) | J15: =IF($A15="","",IF(COUNTIF($A$7:$A$206,$A15)>1,"TRÙNG MÃ",IF(OR($B15="",$C15="",$D15<0,$E15<0,$F15<0),"KIỂM TRA DỮ LIỆU",IF(AND($F15>0,$G15=""),"THIẾU HẠN DƯ ĐẦU KỲ","OK"))))
H16: =IF($A16="","",MAX(0,$F16-SUMIFS('02_NHAT_KY'!$H$7:$H$506,'02_NHAT_KY'!$C$7:$C$506,$A16,'02_NHAT_KY'!$A$7:$A$506,"<="&'03_BAO_CAO'!$E$4))) | I16: =IF($A16="","",IF($H16<=0,"Đã thanh toán",IF($G16="","Thiếu hạn",IF($G16>='03_BAO_CAO'!$E$4,"Chưa đến hạn",IF('03_BAO_CAO'!$E$4-$G16<=30,"1-30 ngày",IF('03_BAO_CAO'!$E$4-$G16<=60,"31-60 ngày",IF('03_BAO_CAO'!$E$4-$G16<=90,"61-90 ngày","Trên 90 ngày"))))))) | J16: =IF($A16="","",IF(COUNTIF($A$7:$A$206,$A16)>1,"TRÙNG MÃ",IF(OR($B16="",$C16="",$D16<0,$E16<0,$F16<0),"KIỂM TRA DỮ LIỆU",IF(AND($F16>0,$G16=""),"THIẾU HẠN DƯ ĐẦU KỲ","OK"))))
H17: =IF($A17="","",MAX(0,$F17-SUMIFS('02_NHAT_KY'!$H$7:$H$506,'02_NHAT_KY'!$C$7:$C$506,$A17,'02_NHAT_KY'!$A$7:$A$506,"<="&'03_BAO_CAO'!$E$4))) | I17: =IF($A17="","",IF($H17<=0,"Đã thanh toán",IF($G17="","Thiếu hạn",IF($G17>='03_BAO_CAO'!$E$4,"Chưa đến hạn",IF('03_BAO_CAO'!$E$4-$G17<=30,"1-30 ngày",IF('03_BAO_CAO'!$E$4-$G17<=60,"31-60 ngày",IF('03_BAO_CAO'!$E$4-$G17<=90,"61-90 ngày","Trên 90 ngày"))))))) | J17: =IF($A17="","",IF(COUNTIF($A$7:$A$206,$A17)>1,"TRÙNG MÃ",IF(OR($B17="",$C17="",$D17<0,$E17<0,$F17<0),"KIỂM TRA DỮ LIỆU",IF(AND($F17>0,$G17=""),"THIẾU HẠN DƯ ĐẦU KỲ","OK"))))
H18: =IF($A18="","",MAX(0,$F18-SUMIFS('02_NHAT_KY'!$H$7:$H$506,'02_NHAT_KY'!$C$7:$C$506,$A18,'02_NHAT_KY'!$A$7:$A$506,"<="&'03_BAO_CAO'!$E$4))) | I18: =IF($A18="","",IF($H18<=0,"Đã thanh toán",IF($G18="","Thiếu hạn",IF($G18>='03_BAO_CAO'!$E$4,"Chưa đến hạn",IF('03_BAO_CAO'!$E$4-$G18<=30,"1-30 ngày",IF('03_BAO_CAO'!$E$4-$G18<=60,"31-60 ngày",IF('03_BAO_CAO'!$E$4-$G18<=90,"61-90 ngày","Trên 90 ngày"))))))) | J18: =IF($A18="","",IF(COUNTIF($A$7:$A$206,$A18)>1,"TRÙNG MÃ",IF(OR($B18="",$C18="",$D18<0,$E18<0,$F18<0),"KIỂM TRA DỮ LIỆU",IF(AND($F18>0,$G18=""),"THIẾU HẠN DƯ ĐẦU KỲ","OK"))))
H19: =IF($A19="","",MAX(0,$F19-SUMIFS('02_NHAT_KY'!$H$7:$H$506,'02_NHAT_KY'!$C$7:$C$506,$A19,'02_NHAT_KY'!$A$7:$A$506,"<="&'03_BAO_CAO'!$E$4))) | I19: =IF($A19="","",IF($H19<=0,"Đã thanh toán",IF($G19="","Thiếu hạn",IF($G19>='03_BAO_CAO'!$E$4,"Chưa đến hạn",IF('03_BAO_CAO'!$E$4-$G19<=30,"1-30 ngày",IF('03_BAO_CAO'!$E$4-$G19<=60,"31-60 ngày",IF('03_BAO_CAO'!$E$4-$G19<=90,"61-90 ngày","Trên 90 ngày"))))))) | J19: =IF($A19="","",IF(COUNTIF($A$7:$A$206,$A19)>1,"TRÙNG MÃ",IF(OR($B19="",$C19="",$D19<0,$E19<0,$F19<0),"KIỂM TRA DỮ LIỆU",IF(AND($F19>0,$G19=""),"THIẾU HẠN DƯ ĐẦU KỲ","OK"))))
H20: =IF($A20="","",MAX(0,$F20-SUMIFS('02_NHAT_KY'!$H$7:$H$506,'02_NHAT_KY'!$C$7:$C$506,$A20,'02_NHAT_KY'!$A$7:$A$506,"<="&'03_BAO_CAO'!$E$4))) | I20: =IF($A20="","",IF($H20<=0,"Đã thanh toán",IF($G20="","Thiếu hạn",IF($G20>='03_BAO_CAO'!$E$4,"Chưa đến hạn",IF('03_BAO_CAO'!$E$4-$G20<=30,"1-30 ngày",IF('03_BAO_CAO'!$E$4-$G20<=60,"31-60 ngày",IF('03_BAO_CAO'!$E$4-$G20<=90,"61-90 ngày","Trên 90 ngày"))))))) | J20: =IF($A20="","",IF(COUNTIF($A$7:$A$206,$A20)>1,"TRÙNG MÃ",IF(OR($B20="",$C20="",$D20<0,$E20<0,$F20<0),"KIỂM TRA DỮ LIỆU",IF(AND($F20>0,$G20=""),"THIẾU HẠN DƯ ĐẦU KỲ","OK"))))
H21: =IF($A21="","",MAX(0,$F21-SUMIFS('02_NHAT_KY'!$H$7:$H$506,'02_NHAT_KY'!$C$7:$C$506,$A21,'02_NHAT_KY'!$A$7:$A$506,"<="&'03_BAO_CAO'!$E$4))) | I21: =IF($A21="","",IF($H21<=0,"Đã thanh toán",IF($G21="","Thiếu hạn",IF($G21>='03_BAO_CAO'!$E$4,"Chưa đến hạn",IF('03_BAO_CAO'!$E$4-$G21<=30,"1-30 ngày",IF('03_BAO_CAO'!$E$4-$G21<=60,"31-60 ngày",IF('03_BAO_CAO'!$E$4-$G21<=90,"61-90 ngày","Trên 90 ngày"))))))) | J21: =IF($A21="","",IF(COUNTIF($A$7:$A$206,$A21)>1,"TRÙNG MÃ",IF(OR($B21="",$C21="",$D21<0,$E21<0,$F21<0),"KIỂM TRA DỮ LIỆU",IF(AND($F21>0,$G21=""),"THIẾU HẠN DƯ ĐẦU KỲ","OK"))))
H22: =IF($A22="","",MAX(0,$F22-SUMIFS('02_NHAT_KY'!$H$7:$H$506,'02_NHAT_KY'!$C$7:$C$506,$A22,'02_NHAT_KY'!$A$7:$A$506,"<="&'03_BAO_CAO'!$E$4))) | I22: =IF($A22="","",IF($H22<=0,"Đã thanh toán",IF($G22="","Thiếu hạn",IF($G22>='03_BAO_CAO'!$E$4,"Chưa đến hạn",IF('03_BAO_CAO'!$E$4-$G22<=30,"1-30 ngày",IF('03_BAO_CAO'!$E$4-$G22<=60,"31-60 ngày",IF('03_BAO_CAO'!$E$4-$G22<=90,"61-90 ngày","Trên 90 ngày"))))))) | J22: =IF($A22="","",IF(COUNTIF($A$7:$A$206,$A22)>1,"TRÙNG MÃ",IF(OR($B22="",$C22="",$D22<0,$E22<0,$F22<0),"KIỂM TRA DỮ LIỆU",IF(AND($F22>0,$G22=""),"THIẾU HẠN DƯ ĐẦU KỲ","OK"))))
... H206: =IF($A206="","",MAX(0,$F206-SUMIFS('02_NHAT_KY'!$H$7:$H$506,'02_NHAT_KY'!$C$7:$C$506,$A206,'02_NHAT_KY'!$A$7:$A$506,"<="&'03_BAO_CAO'!$E$4))) | I206: =IF($A206="","",IF($H206<=0,"Đã thanh toán",IF($G206="","Thiếu hạn",IF($G206>='03_BAO_CAO'!$E$4,"Chưa đến hạn",IF('03_BAO_CAO'!$E$4-$G206<=30,"1-30 ngày",IF('03_BAO_CAO'!$E$4-$G206<=60,"31-60 ngày",IF('03_BAO_CAO'!$E$4-$G206<=90,"61-90 ngày","Trên 90 ngày"))))))) | J206: =IF($A206="","",IF(COUNTIF($A$7:$A$206,$A206)>1,"TRÙNG MÃ",IF(OR($B206="",$C206="",$D206<0,$E206<0,$F206<0),"KIỂM TRA DỮ LIỆU",IF(AND($F206>0,$G206=""),"THIẾU HẠN DƯ ĐẦU KỲ","OK"))))

Sheet 02_NHAT_KY
A1: HỆ THỐNG QUẢN LÝ CÔNG NỢ & TUỔI NỢ ĐA NĂNG - THIẾT KẾ BỞI KK HOME
A2: Số liệu phải sắc - Kiểm soát phải chắc.
A3: Nhập nhật ký theo thứ tự ngày tăng dần. Mỗi dòng chỉ nhập Phát sinh Tăng hoặc Phát sinh Giảm; hệ thống tự cấn trừ FIFO theo từng đối tượng.
A5: NHẬT KÝ PHÁT SINH CÔNG NỢ
A6: Ngày chứng từ | B6: Số chứng từ | C6: Mã Đối Tượng | D6: Tên Đối Tượng | E6: Phân loại | F6: Diễn giải | G6: Phát sinh Tăng (VND) | H6: Phát sinh Giảm (VND) | I6: Thời hạn nợ (ngày) | J6: Ngày đến hạn | K6: Dư chưa thanh toán (FIFO) | L6: Số ngày quá hạn | M6: Nhóm tuổi nợ | N6: Kiểm tra dữ liệu
A7: 46027 | B7: BH001 | C7: KH001 | D7: =IF($C7="","",XLOOKUP($C7,'01_DANH_MUC'!$A$7:$A$206,'01_DANH_MUC'!$B$7:$B$206,"KHÔNG TÌM THẤY")) | E7: =IF($C7="","",XLOOKUP($C7,'01_DANH_MUC'!$A$7:$A$206,'01_DANH_MUC'!$C$7:$C$206,"KHÔNG TÌM THẤY")) | F7: Bán hàng theo HĐ BH001 | G7: 180000000 | H7: 0 | I7: =IF($C7="","",XLOOKUP($C7,'01_DANH_MUC'!$A$7:$A$206,'01_DANH_MUC'!$E$7:$E$206,0)) | J7: =IF(OR($A7="",$C7="",$G7<=0),"",$A7+$I7) | K7: =IF($A7="","",IF(OR($C7="",$G7<=0,$A7>'03_BAO_CAO'!$E$4),0,MAX(0,$G7-MAX(0,SUMIFS($H$7:$H$506,$C$7:$C$506,$C7,$A$7:$A$506,"<="&'03_BAO_CAO'!$E$4)-XLOOKUP($C7,'01_DANH_MUC'!$A$7:$A$206,'01_DANH_MUC'!$F$7:$F$206,0))))) | L7: =IF($A7="","",IF(OR($K7<=0,$J7=""),0,MAX(0,'03_BAO_CAO'!$E$4-$J7))) | M7: =IF($A7="","",IF($K7<=0,"Đã thanh toán",IF($J7="","Thiếu ngày đến hạn",IF($J7>='03_BAO_CAO'!$E$4,"Chưa đến hạn",IF($L7<=30,"1-30 ngày",IF($L7<=60,"31-60 ngày",IF($L7<=90,"61-90 ngày","Trên 90 ngày"))))))) | N7: =IF($A7="","",IF(OR($B7="",$C7=""),"THIẾU THÔNG TIN",IF(AND($G7>0,$H7>0),"KHÔNG NHẬP ĐỒNG THỜI TĂNG/GIẢM",IF(AND($G7<=0,$H7<=0),"CHƯA NHẬP SỐ TIỀN",IF($D7="KHÔNG TÌM THẤY","MÃ KHÔNG HỢP LỆ",IF(AND($G7>0,$J7=""),"THIẾU NGÀY ĐẾN HẠN","OK"))))))
A8: 46063 | B8: PT001 | C8: KH001 | D8: =IF($C8="","",XLOOKUP($C8,'01_DANH_MUC'!$A$7:$A$206,'01_DANH_MUC'!$B$7:$B$206,"KHÔNG TÌM THẤY")) | E8: =IF($C8="","",XLOOKUP($C8,'01_DANH_MUC'!$A$7:$A$206,'01_DANH_MUC'!$C$7:$C$206,"KHÔNG TÌM THẤY")) | F8: Thu tiền khách hàng | G8: 0 | H8: 100000000 | I8: =IF($C8="","",XLOOKUP($C8,'01_DANH_MUC'!$A$7:$A$206,'01_DANH_MUC'!$E$7:$E$206,0)) | J8: =IF(OR($A8="",$C8="",$G8<=0),"",$A8+$I8) | K8: =IF($A8="","",IF(OR($C8="",$G8<=0,$A8>'03_BAO_CAO'!$E$4),0,MAX(0,$G8-MAX(0,SUMIFS($H$7:$H$506,$C$7:$C$506,$C8,$A$7:$A$506,"<="&'03_BAO_CAO'!$E$4)-XLOOKUP($C8,'01_DANH_MUC'!$A$7:$A$206,'01_DANH_MUC'!$F$7:$F$206,0)-SUMIFS($G$7:G7,$C$7:C7,$C8,$A$7:A7,"<="&'03_BAO_CAO'!$E$4))))) | L8: =IF($A8="","",IF(OR($K8<=0,$J8=""),0,MAX(0,'03_BAO_CAO'!$E$4-$J8))) | M8: =IF($A8="","",IF($K8<=0,"Đã thanh toán",IF($J8="","Thiếu ngày đến hạn",IF($J8>='03_BAO_CAO'!$E$4,"Chưa đến hạn",IF($L8<=30,"1-30 ngày",IF($L8<=60,"31-60 ngày",IF($L8<=90,"61-90 ngày","Trên 90 ngày"))))))) | N8: =IF($A8="","",IF(OR($B8="",$C8=""),"THIẾU THÔNG TIN",IF(AND($G8>0,$H8>0),"KHÔNG NHẬP ĐỒNG THỜI TĂNG/GIẢM",IF(AND($G8<=0,$H8<=0),"CHƯA NHẬP SỐ TIỀN",IF($D8="KHÔNG TÌM THẤY","MÃ KHÔNG HỢP LỆ",IF(AND($G8>0,$J8=""),"THIẾU NGÀY ĐẾN HẠN","OK"))))))
A9: 46096 | B9: BH002 | C9: KH001 | D9: =IF($C9="","",XLOOKUP($C9,'01_DANH_MUC'!$A$7:$A$206,'01_DANH_MUC'!$B$7:$B$206,"KHÔNG TÌM THẤY")) | E9: =IF($C9="","",XLOOKUP($C9,'01_DANH_MUC'!$A$7:$A$206,'01_DANH_MUC'!$C$7:$C$206,"KHÔNG TÌM THẤY")) | F9: Bán hàng theo HĐ BH002 | G9: 120000000 | H9: 0 | I9: =IF($C9="","",XLOOKUP($C9,'01_DANH_MUC'!$A$7:$A$206,'01_DANH_MUC'!$E$7:$E$206,0)) | J9: =IF(OR($A9="",$C9="",$G9<=0),"",$A9+$I9) | K9: =IF($A9="","",IF(OR($C9="",$G9<=0,$A9>'03_BAO_CAO'!$E$4),0,MAX(0,$G9-MAX(0,SUMIFS($H$7:$H$506,$C$7:$C$506,$C9,$A$7:$A$506,"<="&'03_BAO_CAO'!$E$4)-XLOOKUP($C9,'01_DANH_MUC'!$A$7:$A$206,'01_DANH_MUC'!$F$7:$F$206,0)-SUMIFS($G$7:G8,$C$7:C8,$C9,$A$7:A8,"<="&'03_BAO_CAO'!$E$4))))) | L9: =IF($A9="","",IF(OR($K9<=0,$J9=""),0,MAX(0,'03_BAO_CAO'!$E$4-$J9))) | M9: =IF($A9="","",IF($K9<=0,"Đã thanh toán",IF($J9="","Thiếu ngày đến hạn",IF($J9>='03_BAO_CAO'!$E$4,"Chưa đến hạn",IF($L9<=30,"1-30 ngày",IF($L9<=60,"31-60 ngày",IF($L9<=90,"61-90 ngày","Trên 90 ngày"))))))) | N9: =IF($A9="","",IF(OR($B9="",$C9=""),"THIẾU THÔNG TIN",IF(AND($G9>0,$H9>0),"KHÔNG NHẬP ĐỒNG THỜI TĂNG/GIẢM",IF(AND($G9<=0,$H9<=0),"CHƯA NHẬP SỐ TIỀN",IF($D9="KHÔNG TÌM THẤY","MÃ KHÔNG HỢP LỆ",IF(AND($G9>0,$J9=""),"THIẾU NGÀY ĐẾN HẠN","OK"))))))
A10: 46122 | B10: MH001 | C10: NCC001 | D10: =IF($C10="","",XLOOKUP($C10,'01_DANH_MUC'!$A$7:$A$206,'01_DANH_MUC'!$B$7:$B$206,"KHÔNG TÌM THẤY")) | E10: =IF($C10="","",XLOOKUP($C10,'01_DANH_MUC'!$A$7:$A$206,'01_DANH_MUC'!$C$7:$C$206,"KHÔNG TÌM THẤY")) | F10: Mua nguyên liệu | G10: 150000000 | H10: 0 | I10: =IF($C10="","",XLOOKUP($C10,'01_DANH_MUC'!$A$7:$A$206,'01_DANH_MUC'!$E$7:$E$206,0)) | J10: =IF(OR($A10="",$C10="",$G10<=0),"",$A10+$I10) | K10: =IF($A10="","",IF(OR($C10="",$G10<=0,$A10>'03_BAO_CAO'!$E$4),0,MAX(0,$G10-MAX(0,SUMIFS($H$7:$H$506,$C$7:$C$506,$C10,$A$7:$A$506,"<="&'03_BAO_CAO'!$E$4)-XLOOKUP($C10,'01_DANH_MUC'!$A$7:$A$206,'01_DANH_MUC'!$F$7:$F$206,0)-SUMIFS($G$7:G9,$C$7:C9,$C10,$A$7:A9,"<="&'03_BAO_CAO'!$E$4))))) | L10: =IF($A10="","",IF(OR($K10<=0,$J10=""),0,MAX(0,'03_BAO_CAO'!$E$4-$J10))) | M10: =IF($A10="","",IF($K10<=0,"Đã thanh toán",IF($J10="","Thiếu ngày đến hạn",IF($J10>='03_BAO_CAO'!$E$4,"Chưa đến hạn",IF($L10<=30,"1-30 ngày",IF($L10<=60,"31-60 ngày",IF($L10<=90,"61-90 ngày","Trên 90 ngày"))))))) | N10: =IF($A10="","",IF(OR($B10="",$C10=""),"THIẾU THÔNG TIN",IF(AND($G10>0,$H10>0),"KHÔNG NHẬP ĐỒNG THỜI TĂNG/GIẢM",IF(AND($G10<=0,$H10<=0),"CHƯA NHẬP SỐ TIỀN",IF($D10="KHÔNG TÌM THẤY","MÃ KHÔNG HỢP LỆ",IF(AND($G10>0,$J10=""),"THIẾU NGÀY ĐẾN HẠN","OK"))))))
A11: 46162 | B11: PC001 | C11: NCC001 | D11: =IF($C11="","",XLOOKUP($C11,'01_DANH_MUC'!$A$7:$A$206,'01_DANH_MUC'!$B$7:$B$206,"KHÔNG TÌM THẤY")) | E11: =IF($C11="","",XLOOKUP($C11,'01_DANH_MUC'!$A$7:$A$206,'01_DANH_MUC'!$C$7:$C$206,"KHÔNG TÌM THẤY")) | F11: Thanh toán nhà cung cấp | G11: 0 | H11: 100000000 | I11: =IF($C11="","",XLOOKUP($C11,'01_DANH_MUC'!$A$7:$A$206,'01_DANH_MUC'!$E$7:$E$206,0)) | J11: =IF(OR($A11="",$C11="",$G11<=0),"",$A11+$I11) | K11: =IF($A11="","",IF(OR($C11="",$G11<=0,$A11>'03_BAO_CAO'!$E$4),0,MAX(0,$G11-MAX(0,SUMIFS($H$7:$H$506,$C$7:$C$506,$C11,$A$7:$A$506,"<="&'03_BAO_CAO'!$E$4)-XLOOKUP($C11,'01_DANH_MUC'!$A$7:$A$206,'01_DANH_MUC'!$F$7:$F$206,0)-SUMIFS($G$7:G10,$C$7:C10,$C11,$A$7:A10,"<="&'03_BAO_CAO'!$E$4))))) | L11: =IF($A11="","",IF(OR($K11<=0,$J11=""),0,MAX(0,'03_BAO_CAO'!$E$4-$J11))) | M11: =IF($A11="","",IF($K11<=0,"Đã thanh toán",IF($J11="","Thiếu ngày đến hạn",IF($J11>='03_BAO_CAO'!$E$4,"Chưa đến hạn",IF($L11<=30,"1-30 ngày",IF($L11<=60,"31-60 ngày",IF($L11<=90,"61-90 ngày","Trên 90 ngày"))))))) | N11: =IF($A11="","",IF(OR($B11="",$C11=""),"THIẾU THÔNG TIN",IF(AND($G11>0,$H11>0),"KHÔNG NHẬP ĐỒNG THỜI TĂNG/GIẢM",IF(AND($G11<=0,$H11<=0),"CHƯA NHẬP SỐ TIỀN",IF($D11="KHÔNG TÌM THẤY","MÃ KHÔNG HỢP LỆ",IF(AND($G11>0,$J11=""),"THIẾU NGÀY ĐẾN HẠN","OK"))))))
A12: 46213 | B12: BH003 | C12: KH002 | D12: =IF($C12="","",XLOOKUP($C12,'01_DANH_MUC'!$A$7:$A$206,'01_DANH_MUC'!$B$7:$B$206,"KHÔNG TÌM THẤY")) | E12: =IF($C12="","",XLOOKUP($C12,'01_DANH_MUC'!$A$7:$A$206,'01_DANH_MUC'!$C$7:$C$206,"KHÔNG TÌM THẤY")) | F12: Bán hàng theo HĐ BH003 | G12: 90000000 | H12: 0 | I12: =IF($C12="","",XLOOKUP($C12,'01_DANH_MUC'!$A$7:$A$206,'01_DANH_MUC'!$E$7:$E$206,0)) | J12: =IF(OR($A12="",$C12="",$G12<=0),"",$A12+$I12) | K12: =IF($A12="","",IF(OR($C12="",$G12<=0,$A12>'03_BAO_CAO'!$E$4),0,MAX(0,$G12-MAX(0,SUMIFS($H$7:$H$506,$C$7:$C$506,$C12,$A$7:$A$506,"<="&'03_BAO_CAO'!$E$4)-XLOOKUP($C12,'01_DANH_MUC'!$A$7:$A$206,'01_DANH_MUC'!$F$7:$F$206,0)-SUMIFS($G$7:G11,$C$7:C11,$C12,$A$7:A11,"<="&'03_BAO_CAO'!$E$4))))) | L12: =IF($A12="","",IF(OR($K12<=0,$J12=""),0,MAX(0,'03_BAO_CAO'!$E$4-$J12))) | M12: =IF($A12="","",IF($K12<=0,"Đã thanh toán",IF($J12="","Thiếu ngày đến hạn",IF($J12>='03_BAO_CAO'!$E$4,"Chưa đến hạn",IF($L12<=30,"1-30 ngày",IF($L12<=60,"31-60 ngày",IF($L12<=90,"61-90 ngày","Trên 90 ngày"))))))) | N12: =IF($A12="","",IF(OR($B12="",$C12=""),"THIẾU THÔNG TIN",IF(AND($G12>0,$H12>0),"KHÔNG NHẬP ĐỒNG THỜI TĂNG/GIẢM",IF(AND($G12<=0,$H12<=0),"CHƯA NHẬP SỐ TIỀN",IF($D12="KHÔNG TÌM THẤY","MÃ KHÔNG HỢP LỆ",IF(AND($G12>0,$J12=""),"THIẾU NGÀY ĐẾN HẠN","OK"))))))
A13: 46221 | B13: MH002 | C13: NCC002 | D13: =IF($C13="","",XLOOKUP($C13,'01_DANH_MUC'!$A$7:$A$206,'01_DANH_MUC'!$B$7:$B$206,"KHÔNG TÌM THẤY")) | E13: =IF($C13="","",XLOOKUP($C13,'01_DANH_MUC'!$A$7:$A$206,'01_DANH_MUC'!$C$7:$C$206,"KHÔNG TÌM THẤY")) | F13: Phí logistics tháng 7 | G13: 60000000 | H13: 0 | I13: =IF($C13="","",XLOOKUP($C13,'01_DANH_MUC'!$A$7:$A$206,'01_DANH_MUC'!$E$7:$E$206,0)) | J13: =IF(OR($A13="",$C13="",$G13<=0),"",$A13+$I13) | K13: =IF($A13="","",IF(OR($C13="",$G13<=0,$A13>'03_BAO_CAO'!$E$4),0,MAX(0,$G13-MAX(0,SUMIFS($H$7:$H$506,$C$7:$C$506,$C13,$A$7:$A$506,"<="&'03_BAO_CAO'!$E$4)-XLOOKUP($C13,'01_DANH_MUC'!$A$7:$A$206,'01_DANH_MUC'!$F$7:$F$206,0)-SUMIFS($G$7:G12,$C$7:C12,$C13,$A$7:A12,"<="&'03_BAO_CAO'!$E$4))))) | L13: =IF($A13="","",IF(OR($K13<=0,$J13=""),0,MAX(0,'03_BAO_CAO'!$E$4-$J13))) | M13: =IF($A13="","",IF($K13<=0,"Đã thanh toán",IF($J13="","Thiếu ngày đến hạn",IF($J13>='03_BAO_CAO'!$E$4,"Chưa đến hạn",IF($L13<=30,"1-30 ngày",IF($L13<=60,"31-60 ngày",IF($L13<=90,"61-90 ngày","Trên 90 ngày"))))))) | N13: =IF($A13="","",IF(OR($B13="",$C13=""),"THIẾU THÔNG TIN",IF(AND($G13>0,$H13>0),"KHÔNG NHẬP ĐỒNG THỜI TĂNG/GIẢM",IF(AND($G13<=0,$H13<=0),"CHƯA NHẬP SỐ TIỀN",IF($D13="KHÔNG TÌM THẤY","MÃ KHÔNG HỢP LỆ",IF(AND($G13>0,$J13=""),"THIẾU NGÀY ĐẾN HẠN","OK"))))))
A14: 46223 | B14: PC002 | C14: NCC002 | D14: =IF($C14="","",XLOOKUP($C14,'01_DANH_MUC'!$A$7:$A$206,'01_DANH_MUC'!$B$7:$B$206,"KHÔNG TÌM THẤY")) | E14: =IF($C14="","",XLOOKUP($C14,'01_DANH_MUC'!$A$7:$A$206,'01_DANH_MUC'!$C$7:$C$206,"KHÔNG TÌM THẤY")) | F14: Thanh toán một phần | G14: 0 | H14: 10000000 | I14: =IF($C14="","",XLOOKUP($C14,'01_DANH_MUC'!$A$7:$A$206,'01_DANH_MUC'!$E$7:$E$206,0)) | J14: =IF(OR($A14="",$C14="",$G14<=0),"",$A14+$I14) | K14: =IF($A14="","",IF(OR($C14="",$G14<=0,$A14>'03_BAO_CAO'!$E$4),0,MAX(0,$G14-MAX(0,SUMIFS($H$7:$H$506,$C$7:$C$506,$C14,$A$7:$A$506,"<="&'03_BAO_CAO'!$E$4)-XLOOKUP($C14,'01_DANH_MUC'!$A$7:$A$206,'01_DANH_MUC'!$F$7:$F$206,0)-SUMIFS($G$7:G13,$C$7:C13,$C14,$A$7:A13,"<="&'03_BAO_CAO'!$E$4))))) | L14: =IF($A14="","",IF(OR($K14<=0,$J14=""),0,MAX(0,'03_BAO_CAO'!$E$4-$J14))) | M14: =IF($A14="","",IF($K14<=0,"Đã thanh toán",IF($J14="","Thiếu ngày đến hạn",IF($J14>='03_BAO_CAO'!$E$4,"Chưa đến hạn",IF($L14<=30,"1-30 ngày",IF($L14<=60,"31-60 ngày",IF($L14<=90,"61-90 ngày","Trên 90 ngày"))))))) | N14: =IF($A14="","",IF(OR($B14="",$C14=""),"THIẾU THÔNG TIN",IF(AND($G14>0,$H14>0),"KHÔNG NHẬP ĐỒNG THỜI TĂNG/GIẢM",IF(AND($G14<=0,$H14<=0),"CHƯA NHẬP SỐ TIỀN",IF($D14="KHÔNG TÌM THẤY","MÃ KHÔNG HỢP LỆ",IF(AND($G14>0,$J14=""),"THIẾU NGÀY ĐẾN HẠN","OK"))))))
D15: =IF($C15="","",XLOOKUP($C15,'01_DANH_MUC'!$A$7:$A$206,'01_DANH_MUC'!$B$7:$B$206,"KHÔNG TÌM THẤY")) | E15: =IF($C15="","",XLOOKUP($C15,'01_DANH_MUC'!$A$7:$A$206,'01_DANH_MUC'!$C$7:$C$206,"KHÔNG TÌM THẤY")) | I15: =IF($C15="","",XLOOKUP($C15,'01_DANH_MUC'!$A$7:$A$206,'01_DANH_MUC'!$E$7:$E$206,0)) | J15: =IF(OR($A15="",$C15="",$G15<=0),"",$A15+$I15) | K15: =IF($A15="","",IF(OR($C15="",$G15<=0,$A15>'03_BAO_CAO'!$E$4),0,MAX(0,$G15-MAX(0,SUMIFS($H$7:$H$506,$C$7:$C$506,$C15,$A$7:$A$506,"<="&'03_BAO_CAO'!$E$4)-XLOOKUP($C15,'01_DANH_MUC'!$A$7:$A$206,'01_DANH_MUC'!$F$7:$F$206,0)-SUMIFS($G$7:G14,$C$7:C14,$C15,$A$7:A14,"<="&'03_BAO_CAO'!$E$4))))) | L15: =IF($A15="","",IF(OR($K15<=0,$J15=""),0,MAX(0,'03_BAO_CAO'!$E$4-$J15))) | M15: =IF($A15="","",IF($K15<=0,"Đã thanh toán",IF($J15="","Thiếu ngày đến hạn",IF($J15>='03_BAO_CAO'!$E$4,"Chưa đến hạn",IF($L15<=30,"1-30 ngày",IF($L15<=60,"31-60 ngày",IF($L15<=90,"61-90 ngày","Trên 90 ngày"))))))) | N15: =IF($A15="","",IF(OR($B15="",$C15=""),"THIẾU THÔNG TIN",IF(AND($G15>0,$H15>0),"KHÔNG NHẬP ĐỒNG THỜI TĂNG/GIẢM",IF(AND($G15<=0,$H15<=0),"CHƯA NHẬP SỐ TIỀN",IF($D15="KHÔNG TÌM THẤY","MÃ KHÔNG HỢP LỆ",IF(AND($G15>0,$J15=""),"THIẾU NGÀY ĐẾN HẠN","OK"))))))
D16: =IF($C16="","",XLOOKUP($C16,'01_DANH_MUC'!$A$7:$A$206,'01_DANH_MUC'!$B$7:$B$206,"KHÔNG TÌM THẤY")) | E16: =IF($C16="","",XLOOKUP($C16,'01_DANH_MUC'!$A$7:$A$206,'01_DANH_MUC'!$C$7:$C$206,"KHÔNG TÌM THẤY")) | I16: =IF($C16="","",XLOOKUP($C16,'01_DANH_MUC'!$A$7:$A$206,'01_DANH_MUC'!$E$7:$E$206,0)) | J16: =IF(OR($A16="",$C16="",$G16<=0),"",$A16+$I16) | K16: =IF($A16="","",IF(OR($C16="",$G16<=0,$A16>'03_BAO_CAO'!$E$4),0,MAX(0,$G16-MAX(0,SUMIFS($H$7:$H$506,$C$7:$C$506,$C16,$A$7:$A$506,"<="&'03_BAO_CAO'!$E$4)-XLOOKUP($C16,'01_DANH_MUC'!$A$7:$A$206,'01_DANH_MUC'!$F$7:$F$206,0)-SUMIFS($G$7:G15,$C$7:C15,$C16,$A$7:A15,"<="&'03_BAO_CAO'!$E$4))))) | L16: =IF($A16="","",IF(OR($K16<=0,$J16=""),0,MAX(0,'03_BAO_CAO'!$E$4-$J16))) | M16: =IF($A16="","",IF($K16<=0,"Đã thanh toán",IF($J16="","Thiếu ngày đến hạn",IF($J16>='03_BAO_CAO'!$E$4,"Chưa đến hạn",IF($L16<=30,"1-30 ngày",IF($L16<=60,"31-60 ngày",IF($L16<=90,"61-90 ngày","Trên 90 ngày"))))))) | N16: =IF($A16="","",IF(OR($B16="",$C16=""),"THIẾU THÔNG TIN",IF(AND($G16>0,$H16>0),"KHÔNG NHẬP ĐỒNG THỜI TĂNG/GIẢM",IF(AND($G16<=0,$H16<=0),"CHƯA NHẬP SỐ TIỀN",IF($D16="KHÔNG TÌM THẤY","MÃ KHÔNG HỢP LỆ",IF(AND($G16>0,$J16=""),"THIẾU NGÀY ĐẾN HẠN","OK"))))))
D17: =IF($C17="","",XLOOKUP($C17,'01_DANH_MUC'!$A$7:$A$206,'01_DANH_MUC'!$B$7:$B$206,"KHÔNG TÌM THẤY")) | E17: =IF($C17="","",XLOOKUP($C17,'01_DANH_MUC'!$A$7:$A$206,'01_DANH_MUC'!$C$7:$C$206,"KHÔNG TÌM THẤY")) | I17: =IF($C17="","",XLOOKUP($C17,'01_DANH_MUC'!$A$7:$A$206,'01_DANH_MUC'!$E$7:$E$206,0)) | J17: =IF(OR($A17="",$C17="",$G17<=0),"",$A17+$I17) | K17: =IF($A17="","",IF(OR($C17="",$G17<=0,$A17>'03_BAO_CAO'!$E$4),0,MAX(0,$G17-MAX(0,SUMIFS($H$7:$H$506,$C$7:$C$506,$C17,$A$7:$A$506,"<="&'03_BAO_CAO'!$E$4)-XLOOKUP($C17,'01_DANH_MUC'!$A$7:$A$206,'01_DANH_MUC'!$F$7:$F$206,0)-SUMIFS($G$7:G16,$C$7:C16,$C17,$A$7:A16,"<="&'03_BAO_CAO'!$E$4))))) | L17: =IF($A17="","",IF(OR($K17<=0,$J17=""),0,MAX(0,'03_BAO_CAO'!$E$4-$J17))) | M17: =IF($A17="","",IF($K17<=0,"Đã thanh toán",IF($J17="","Thiếu ngày đến hạn",IF($J17>='03_BAO_CAO'!$E$4,"Chưa đến hạn",IF($L17<=30,"1-30 ngày",IF($L17<=60,"31-60 ngày",IF($L17<=90,"61-90 ngày","Trên 90 ngày"))))))) | N17: =IF($A17="","",IF(OR($B17="",$C17=""),"THIẾU THÔNG TIN",IF(AND($G17>0,$H17>0),"KHÔNG NHẬP ĐỒNG THỜI TĂNG/GIẢM",IF(AND($G17<=0,$H17<=0),"CHƯA NHẬP SỐ TIỀN",IF($D17="KHÔNG TÌM THẤY","MÃ KHÔNG HỢP LỆ",IF(AND($G17>0,$J17=""),"THIẾU NGÀY ĐẾN HẠN","OK"))))))
D18: =IF($C18="","",XLOOKUP($C18,'01_DANH_MUC'!$A$7:$A$206,'01_DANH_MUC'!$B$7:$B$206,"KHÔNG TÌM THẤY")) | E18: =IF($C18="","",XLOOKUP($C18,'01_DANH_MUC'!$A$7:$A$206,'01_DANH_MUC'!$C$7:$C$206,"KHÔNG TÌM THẤY")) | I18: =IF($C18="","",XLOOKUP($C18,'01_DANH_MUC'!$A$7:$A$206,'01_DANH_MUC'!$E$7:$E$206,0)) | J18: =IF(OR($A18="",$C18="",$G18<=0),"",$A18+$I18) | K18: =IF($A18="","",IF(OR($C18="",$G18<=0,$A18>'03_BAO_CAO'!$E$4),0,MAX(0,$G18-MAX(0,SUMIFS($H$7:$H$506,$C$7:$C$506,$C18,$A$7:$A$506,"<="&'03_BAO_CAO'!$E$4)-XLOOKUP($C18,'01_DANH_MUC'!$A$7:$A$206,'01_DANH_MUC'!$F$7:$F$206,0)-SUMIFS($G$7:G17,$C$7:C17,$C18,$A$7:A17,"<="&'03_BAO_CAO'!$E$4))))) | L18: =IF($A18="","",IF(OR($K18<=0,$J18=""),0,MAX(0,'03_BAO_CAO'!$E$4-$J18))) | M18: =IF($A18="","",IF($K18<=0,"Đã thanh toán",IF($J18="","Thiếu ngày đến hạn",IF($J18>='03_BAO_CAO'!$E$4,"Chưa đến hạn",IF($L18<=30,"1-30 ngày",IF($L18<=60,"31-60 ngày",IF($L18<=90,"61-90 ngày","Trên 90 ngày"))))))) | N18: =IF($A18="","",IF(OR($B18="",$C18=""),"THIẾU THÔNG TIN",IF(AND($G18>0,$H18>0),"KHÔNG NHẬP ĐỒNG THỜI TĂNG/GIẢM",IF(AND($G18<=0,$H18<=0),"CHƯA NHẬP SỐ TIỀN",IF($D18="KHÔNG TÌM THẤY","MÃ KHÔNG HỢP LỆ",IF(AND($G18>0,$J18=""),"THIẾU NGÀY ĐẾN HẠN","OK"))))))
D19: =IF($C19="","",XLOOKUP($C19,'01_DANH_MUC'!$A$7:$A$206,'01_DANH_MUC'!$B$7:$B$206,"KHÔNG TÌM THẤY")) | E19: =IF($C19="","",XLOOKUP($C19,'01_DANH_MUC'!$A$7:$A$206,'01_DANH_MUC'!$C$7:$C$206,"KHÔNG TÌM THẤY")) | I19: =IF($C19="","",XLOOKUP($C19,'01_DANH_MUC'!$A$7:$A$206,'01_DANH_MUC'!$E$7:$E$206,0)) | J19: =IF(OR($A19="",$C19="",$G19<=0),"",$A19+$I19) | K19: =IF($A19="","",IF(OR($C19="",$G19<=0,$A19>'03_BAO_CAO'!$E$4),0,MAX(0,$G19-MAX(0,SUMIFS($H$7:$H$506,$C$7:$C$506,$C19,$A$7:$A$506,"<="&'03_BAO_CAO'!$E$4)-XLOOKUP($C19,'01_DANH_MUC'!$A$7:$A$206,'01_DANH_MUC'!$F$7:$F$206,0)-SUMIFS($G$7:G18,$C$7:C18,$C19,$A$7:A18,"<="&'03_BAO_CAO'!$E$4))))) | L19: =IF($A19="","",IF(OR($K19<=0,$J19=""),0,MAX(0,'03_BAO_CAO'!$E$4-$J19))) | M19: =IF($A19="","",IF($K19<=0,"Đã thanh toán",IF($J19="","Thiếu ngày đến hạn",IF($J19>='03_BAO_CAO'!$E$4,"Chưa đến hạn",IF($L19<=30,"1-30 ngày",IF($L19<=60,"31-60 ngày",IF($L19<=90,"61-90 ngày","Trên 90 ngày"))))))) | N19: =IF($A19="","",IF(OR($B19="",$C19=""),"THIẾU THÔNG TIN",IF(AND($G19>0,$H19>0),"KHÔNG NHẬP ĐỒNG THỜI TĂNG/GIẢM",IF(AND($G19<=0,$H19<=0),"CHƯA NHẬP SỐ TIỀN",IF($D19="KHÔNG TÌM THẤY","MÃ KHÔNG HỢP LỆ",IF(AND($G19>0,$J19=""),"THIẾU NGÀY ĐẾN HẠN","OK"))))))
D20: =IF($C20="","",XLOOKUP($C20,'01_DANH_MUC'!$A$7:$A$206,'01_DANH_MUC'!$B$7:$B$206,"KHÔNG TÌM THẤY")) | E20: =IF($C20="","",XLOOKUP($C20,'01_DANH_MUC'!$A$7:$A$206,'01_DANH_MUC'!$C$7:$C$206,"KHÔNG TÌM THẤY")) | I20: =IF($C20="","",XLOOKUP($C20,'01_DANH_MUC'!$A$7:$A$206,'01_DANH_MUC'!$E$7:$E$206,0)) | J20: =IF(OR($A20="",$C20="",$G20<=0),"",$A20+$I20) | K20: =IF($A20="","",IF(OR($C20="",$G20<=0,$A20>'03_BAO_CAO'!$E$4),0,MAX(0,$G20-MAX(0,SUMIFS($H$7:$H$506,$C$7:$C$506,$C20,$A$7:$A$506,"<="&'03_BAO_CAO'!$E$4)-XLOOKUP($C20,'01_DANH_MUC'!$A$7:$A$206,'01_DANH_MUC'!$F$7:$F$206,0)-SUMIFS($G$7:G19,$C$7:C19,$C20,$A$7:A19,"<="&'03_BAO_CAO'!$E$4))))) | L20: =IF($A20="","",IF(OR($K20<=0,$J20=""),0,MAX(0,'03_BAO_CAO'!$E$4-$J20))) | M20: =IF($A20="","",IF($K20<=0,"Đã thanh toán",IF($J20="","Thiếu ngày đến hạn",IF($J20>='03_BAO_CAO'!$E$4,"Chưa đến hạn",IF($L20<=30,"1-30 ngày",IF($L20<=60,"31-60 ngày",IF($L20<=90,"61-90 ngày","Trên 90 ngày"))))))) | N20: =IF($A20="","",IF(OR($B20="",$C20=""),"THIẾU THÔNG TIN",IF(AND($G20>0,$H20>0),"KHÔNG NHẬP ĐỒNG THỜI TĂNG/GIẢM",IF(AND($G20<=0,$H20<=0),"CHƯA NHẬP SỐ TIỀN",IF($D20="KHÔNG TÌM THẤY","MÃ KHÔNG HỢP LỆ",IF(AND($G20>0,$J20=""),"THIẾU NGÀY ĐẾN HẠN","OK"))))))
D21: =IF($C21="","",XLOOKUP($C21,'01_DANH_MUC'!$A$7:$A$206,'01_DANH_MUC'!$B$7:$B$206,"KHÔNG TÌM THẤY")) | E21: =IF($C21="","",XLOOKUP($C21,'01_DANH_MUC'!$A$7:$A$206,'01_DANH_MUC'!$C$7:$C$206,"KHÔNG TÌM THẤY")) | I21: =IF($C21="","",XLOOKUP($C21,'01_DANH_MUC'!$A$7:$A$206,'01_DANH_MUC'!$E$7:$E$206,0)) | J21: =IF(OR($A21="",$C21="",$G21<=0),"",$A21+$I21) | K21: =IF($A21="","",IF(OR($C21="",$G21<=0,$A21>'03_BAO_CAO'!$E$4),0,MAX(0,$G21-MAX(0,SUMIFS($H$7:$H$506,$C$7:$C$506,$C21,$A$7:$A$506,"<="&'03_BAO_CAO'!$E$4)-XLOOKUP($C21,'01_DANH_MUC'!$A$7:$A$206,'01_DANH_MUC'!$F$7:$F$206,0)-SUMIFS($G$7:G20,$C$7:C20,$C21,$A$7:A20,"<="&'03_BAO_CAO'!$E$4))))) | L21: =IF($A21="","",IF(OR($K21<=0,$J21=""),0,MAX(0,'03_BAO_CAO'!$E$4-$J21))) | M21: =IF($A21="","",IF($K21<=0,"Đã thanh toán",IF($J21="","Thiếu ngày đến hạn",IF($J21>='03_BAO_CAO'!$E$4,"Chưa đến hạn",IF($L21<=30,"1-30 ngày",IF($L21<=60,"31-60 ngày",IF($L21<=90,"61-90 ngày","Trên 90 ngày"))))))) | N21: =IF($A21="","",IF(OR($B21="",$C21=""),"THIẾU THÔNG TIN",IF(AND($G21>0,$H21>0),"KHÔNG NHẬP ĐỒNG THỜI TĂNG/GIẢM",IF(AND($G21<=0,$H21<=0),"CHƯA NHẬP SỐ TIỀN",IF($D21="KHÔNG TÌM THẤY","MÃ KHÔNG HỢP LỆ",IF(AND($G21>0,$J21=""),"THIẾU NGÀY ĐẾN HẠN","OK"))))))
D22: =IF($C22="","",XLOOKUP($C22,'01_DANH_MUC'!$A$7:$A$206,'01_DANH_MUC'!$B$7:$B$206,"KHÔNG TÌM THẤY")) | E22: =IF($C22="","",XLOOKUP($C22,'01_DANH_MUC'!$A$7:$A$206,'01_DANH_MUC'!$C$7:$C$206,"KHÔNG TÌM THẤY")) | I22: =IF($C22="","",XLOOKUP($C22,'01_DANH_MUC'!$A$7:$A$206,'01_DANH_MUC'!$E$7:$E$206,0)) | J22: =IF(OR($A22="",$C22="",$G22<=0),"",$A22+$I22) | K22: =IF($A22="","",IF(OR($C22="",$G22<=0,$A22>'03_BAO_CAO'!$E$4),0,MAX(0,$G22-MAX(0,SUMIFS($H$7:$H$506,$C$7:$C$506,$C22,$A$7:$A$506,"<="&'03_BAO_CAO'!$E$4)-XLOOKUP($C22,'01_DANH_MUC'!$A$7:$A$206,'01_DANH_MUC'!$F$7:$F$206,0)-SUMIFS($G$7:G21,$C$7:C21,$C22,$A$7:A21,"<="&'03_BAO_CAO'!$E$4))))) | L22: =IF($A22="","",IF(OR($K22<=0,$J22=""),0,MAX(0,'03_BAO_CAO'!$E$4-$J22))) | M22: =IF($A22="","",IF($K22<=0,"Đã thanh toán",IF($J22="","Thiếu ngày đến hạn",IF($J22>='03_BAO_CAO'!$E$4,"Chưa đến hạn",IF($L22<=30,"1-30 ngày",IF($L22<=60,"31-60 ngày",IF($L22<=90,"61-90 ngày","Trên 90 ngày"))))))) | N22: =IF($A22="","",IF(OR($B22="",$C22=""),"THIẾU THÔNG TIN",IF(AND($G22>0,$H22>0),"KHÔNG NHẬP ĐỒNG THỜI TĂNG/GIẢM",IF(AND($G22<=0,$H22<=0),"CHƯA NHẬP SỐ TIỀN",IF($D22="KHÔNG TÌM THẤY","MÃ KHÔNG HỢP LỆ",IF(AND($G22>0,$J22=""),"THIẾU NGÀY ĐẾN HẠN","OK"))))))
D23: =IF($C23="","",XLOOKUP($C23,'01_DANH_MUC'!$A$7:$A$206,'01_DANH_MUC'!$B$7:$B$206,"KHÔNG TÌM THẤY")) | E23: =IF($C23="","",XLOOKUP($C23,'01_DANH_MUC'!$A$7:$A$206,'01_DANH_MUC'!$C$7:$C$206,"KHÔNG TÌM THẤY")) | I23: =IF($C23="","",XLOOKUP($C23,'01_DANH_MUC'!$A$7:$A$206,'01_DANH_MUC'!$E$7:$E$206,0)) | J23: =IF(OR($A23="",$C23="",$G23<=0),"",$A23+$I23) | K23: =IF($A23="","",IF(OR($C23="",$G23<=0,$A23>'03_BAO_CAO'!$E$4),0,MAX(0,$G23-MAX(0,SUMIFS($H$7:$H$506,$C$7:$C$506,$C23,$A$7:$A$506,"<="&'03_BAO_CAO'!$E$4)-XLOOKUP($C23,'01_DANH_MUC'!$A$7:$A$206,'01_DANH_MUC'!$F$7:$F$206,0)-SUMIFS($G$7:G22,$C$7:C22,$C23,$A$7:A22,"<="&'03_BAO_CAO'!$E$4))))) | L23: =IF($A23="","",IF(OR($K23<=0,$J23=""),0,MAX(0,'03_BAO_CAO'!$E$4-$J23))) | M23: =IF($A23="","",IF($K23<=0,"Đã thanh toán",IF($J23="","Thiếu ngày đến hạn",IF($J23>='03_BAO_CAO'!$E$4,"Chưa đến hạn",IF($L23<=30,"1-30 ngày",IF($L23<=60,"31-60 ngày",IF($L23<=90,"61-90 ngày","Trên 90 ngày"))))))) | N23: =IF($A23="","",IF(OR($B23="",$C23=""),"THIẾU THÔNG TIN",IF(AND($G23>0,$H23>0),"KHÔNG NHẬP ĐỒNG THỜI TĂNG/GIẢM",IF(AND($G23<=0,$H23<=0),"CHƯA NHẬP SỐ TIỀN",IF($D23="KHÔNG TÌM THẤY","MÃ KHÔNG HỢP LỆ",IF(AND($G23>0,$J23=""),"THIẾU NGÀY ĐẾN HẠN","OK"))))))
D24: =IF($C24="","",XLOOKUP($C24,'01_DANH_MUC'!$A$7:$A$206,'01_DANH_MUC'!$B$7:$B$206,"KHÔNG TÌM THẤY")) | E24: =IF($C24="","",XLOOKUP($C24,'01_DANH_MUC'!$A$7:$A$206,'01_DANH_MUC'!$C$7:$C$206,"KHÔNG TÌM THẤY")) | I24: =IF($C24="","",XLOOKUP($C24,'01_DANH_MUC'!$A$7:$A$206,'01_DANH_MUC'!$E$7:$E$206,0)) | J24: =IF(OR($A24="",$C24="",$G24<=0),"",$A24+$I24) | K24: =IF($A24="","",IF(OR($C24="",$G24<=0,$A24>'03_BAO_CAO'!$E$4),0,MAX(0,$G24-MAX(0,SUMIFS($H$7:$H$506,$C$7:$C$506,$C24,$A$7:$A$506,"<="&'03_BAO_CAO'!$E$4)-XLOOKUP($C24,'01_DANH_MUC'!$A$7:$A$206,'01_DANH_MUC'!$F$7:$F$206,0)-SUMIFS($G$7:G23,$C$7:C23,$C24,$A$7:A23,"<="&'03_BAO_CAO'!$E$4))))) | L24: =IF($A24="","",IF(OR($K24<=0,$J24=""),0,MAX(0,'03_BAO_CAO'!$E$4-$J24))) | M24: =IF($A24="","",IF($K24<=0,"Đã thanh toán",IF($J24="","Thiếu ngày đến hạn",IF($J24>='03_BAO_CAO'!$E$4,"Chưa đến hạn",IF($L24<=30,"1-30 ngày",IF($L24<=60,"31-60 ngày",IF($L24<=90,"61-90 ngày","Trên 90 ngày"))))))) | N24: =IF($A24="","",IF(OR($B24="",$C24=""),"THIẾU THÔNG TIN",IF(AND($G24>0,$H24>0),"KHÔNG NHẬP ĐỒNG THỜI TĂNG/GIẢM",IF(AND($G24<=0,$H24<=0),"CHƯA NHẬP SỐ TIỀN",IF($D24="KHÔNG TÌM THẤY","MÃ KHÔNG HỢP LỆ",IF(AND($G24>0,$J24=""),"THIẾU NGÀY ĐẾN HẠN","OK"))))))
D25: =IF($C25="","",XLOOKUP($C25,'01_DANH_MUC'!$A$7:$A$206,'01_DANH_MUC'!$B$7:$B$206,"KHÔNG TÌM THẤY")) | E25: =IF($C25="","",XLOOKUP($C25,'01_DANH_MUC'!$A$7:$A$206,'01_DANH_MUC'!$C$7:$C$206,"KHÔNG TÌM THẤY")) | I25: =IF($C25="","",XLOOKUP($C25,'01_DANH_MUC'!$A$7:$A$206,'01_DANH_MUC'!$E$7:$E$206,0)) | J25: =IF(OR($A25="",$C25="",$G25<=0),"",$A25+$I25) | K25: =IF($A25="","",IF(OR($C25="",$G25<=0,$A25>'03_BAO_CAO'!$E$4),0,MAX(0,$G25-MAX(0,SUMIFS($H$7:$H$506,$C$7:$C$506,$C25,$A$7:$A$506,"<="&'03_BAO_CAO'!$E$4)-XLOOKUP($C25,'01_DANH_MUC'!$A$7:$A$206,'01_DANH_MUC'!$F$7:$F$206,0)-SUMIFS($G$7:G24,$C$7:C24,$C25,$A$7:A24,"<="&'03_BAO_CAO'!$E$4))))) | L25: =IF($A25="","",IF(OR($K25<=0,$J25=""),0,MAX(0,'03_BAO_CAO'!$E$4-$J25))) | M25: =IF($A25="","",IF($K25<=0,"Đã thanh toán",IF($J25="","Thiếu ngày đến hạn",IF($J25>='03_BAO_CAO'!$E$4,"Chưa đến hạn",IF($L25<=30,"1-30 ngày",IF($L25<=60,"31-60 ngày",IF($L25<=90,"61-90 ngày","Trên 90 ngày"))))))) | N25: =IF($A25="","",IF(OR($B25="",$C25=""),"THIẾU THÔNG TIN",IF(AND($G25>0,$H25>0),"KHÔNG NHẬP ĐỒNG THỜI TĂNG/GIẢM",IF(AND($G25<=0,$H25<=0),"CHƯA NHẬP SỐ TIỀN",IF($D25="KHÔNG TÌM THẤY","MÃ KHÔNG HỢP LỆ",IF(AND($G25>0,$J25=""),"THIẾU NGÀY ĐẾN HẠN","OK"))))))
D26: =IF($C26="","",XLOOKUP($C26,'01_DANH_MUC'!$A$7:$A$206,'01_DANH_MUC'!$B$7:$B$206,"KHÔNG TÌM THẤY")) | E26: =IF($C26="","",XLOOKUP($C26,'01_DANH_MUC'!$A$7:$A$206,'01_DANH_MUC'!$C$7:$C$206,"KHÔNG TÌM THẤY")) | I26: =IF($C26="","",XLOOKUP($C26,'01_DANH_MUC'!$A$7:$A$206,'01_DANH_MUC'!$E$7:$E$206,0)) | J26: =IF(OR($A26="",$C26="",$G26<=0),"",$A26+$I26) | K26: =IF($A26="","",IF(OR($C26="",$G26<=0,$A26>'03_BAO_CAO'!$E$4),0,MAX(0,$G26-MAX(0,SUMIFS($H$7:$H$506,$C$7:$C$506,$C26,$A$7:$A$506,"<="&'03_BAO_CAO'!$E$4)-XLOOKUP($C26,'01_DANH_MUC'!$A$7:$A$206,'01_DANH_MUC'!$F$7:$F$206,0)-SUMIFS($G$7:G25,$C$7:C25,$C26,$A$7:A25,"<="&'03_BAO_CAO'!$E$4))))) | L26: =IF($A26="","",IF(OR($K26<=0,$J26=""),0,MAX(0,'03_BAO_CAO'!$E$4-$J26))) | M26: =IF($A26="","",IF($K26<=0,"Đã thanh toán",IF($J26="","Thiếu ngày đến hạn",IF($J26>='03_BAO_CAO'!$E$4,"Chưa đến hạn",IF($L26<=30,"1-30 ngày",IF($L26<=60,"31-60 ngày",IF($L26<=90,"61-90 ngày","Trên 90 ngày"))))))) | N26: =IF($A26="","",IF(OR($B26="",$C26=""),"THIẾU THÔNG TIN",IF(AND($G26>0,$H26>0),"KHÔNG NHẬP ĐỒNG THỜI TĂNG/GIẢM",IF(AND($G26<=0,$H26<=0),"CHƯA NHẬP SỐ TIỀN",IF($D26="KHÔNG TÌM THẤY","MÃ KHÔNG HỢP LỆ",IF(AND($G26>0,$J26=""),"THIẾU NGÀY ĐẾN HẠN","OK"))))))
... D506: =IF($C506="","",XLOOKUP($C506,'01_DANH_MUC'!$A$7:$A$206,'01_DANH_MUC'!$B$7:$B$206,"KHÔNG TÌM THẤY")) | E506: =IF($C506="","",XLOOKUP($C506,'01_DANH_MUC'!$A$7:$A$206,'01_DANH_MUC'!$C$7:$C$206,"KHÔNG TÌM THẤY")) | I506: =IF($C506="","",XLOOKUP($C506,'01_DANH_MUC'!$A$7:$A$206,'01_DANH_MUC'!$E$7:$E$206,0)) | J506: =IF(OR($A506="",$C506="",$G506<=0),"",$A506+$I506) | K506: =IF($A506="","",IF(OR($C506="",$G506<=0,$A506>'03_BAO_CAO'!$E$4),0,MAX(0,$G506-MAX(0,SUMIFS($H$7:$H$506,$C$7:$C$506,$C506,$A$7:$A$506,"<="&'03_BAO_CAO'!$E$4)-XLOOKUP($C506,'01_DANH_MUC'!$A$7:$A$206,'01_DANH_MUC'!$F$7:$F$206,0)-SUMIFS($G$7:G505,$C$7:C505,$C506,$A$7:A505,"<="&'03_BAO_CAO'!$E$4))))) | L506: =IF($A506="","",IF(OR($K506<=0,$J506=""),0,MAX(0,'03_BAO_CAO'!$E$4-$J506))) | M506: =IF($A506="","",IF($K506<=0,"Đã thanh toán",IF($J506="","Thiếu ngày đến hạn",IF($J506>='03_BAO_CAO'!$E$4,"Chưa đến hạn",IF($L506<=30,"1-30 ngày",IF($L506<=60,"31-60 ngày",IF($L506<=90,"61-90 ngày","Trên 90 ngày"))))))) | N506: =IF($A506="","",IF(OR($B506="",$C506=""),"THIẾU THÔNG TIN",IF(AND($G506>0,$H506>0),"KHÔNG NHẬP ĐỒNG THỜI TĂNG/GIẢM",IF(AND($G506<=0,$H506<=0),"CHƯA NHẬP SỐ TIỀN",IF($D506="KHÔNG TÌM THẤY","MÃ KHÔNG HỢP LỆ",IF(AND($G506>0,$J506=""),"THIẾU NGÀY ĐẾN HẠN","OK"))))))

Sheet 03_BAO_CAO
A1: HỆ THỐNG QUẢN LÝ CÔNG NỢ & TUỔI NỢ ĐA NĂNG - THIẾT KẾ BỞI KK HOME
A2: Số liệu phải sắc - Kiểm soát phải chắc.
A4: TỪ NGÀY | B4: =DATE(YEAR($E$4),1,1) | D4: NGÀY BÁO CÁO | E4: =TODAY() | F4: VƯỢT HẠN MỨC | G4: =SUMPRODUCT(--($H$17:$H$216>$D$17:$D$216),--($D$17:$D$216>0)) | H4: Nhóm tuổi nợ | I4: Giá trị (VND)
A5: Tuổi nợ được tính trên số dư từng chứng từ còn lại theo FIFO. Có thể ghi đè hai ô ngày màu vàng để lập báo cáo tại thời điểm khác. | H5: Chưa đến hạn | I5: =SUM($K$17:$K$216)
H6: 1-30 ngày | I6: =SUM($L$17:$L$216)
A7: TỔNG PHẢI THU | D7: TỔNG PHẢI TRẢ | H7: 31-60 ngày | I7: =SUM($M$17:$M$216)
A8: =SUMIFS($H$17:$H$216,$C$17:$C$216,"Phải thu") | D8: =SUMIFS($H$17:$H$216,$C$17:$C$216,"Phải trả") | H8: 61-90 ngày | I8: =SUM($N$17:$N$216)
H9: Trên 90 ngày | I9: =SUM($O$17:$O$216)
A11: TỔNG NỢ QUÁ HẠN | D11: QUÁ HẠN TRÊN 90 NGÀY
A12: =SUM($L$17:$O$216) | D12: =SUM($O$17:$O$216)
A15: BÁO CÁO TỔNG HỢP CÔNG NỢ & PHÂN TÍCH TUỔI NỢ
A16: Mã Đối Tượng | B16: Tên Đối Tượng | C16: Phân loại | D16: Hạn mức nợ (VND) | E16: Dư đầu kỳ (VND) | F16: Phát sinh Tăng trong kỳ | G16: Phát sinh Giảm trong kỳ | H16: Dư cuối kỳ (VND) | I16: Số ngày quá hạn lớn nhất | J16: Trạng thái | K16: Chưa đến hạn | L16: Quá hạn 1-30 ngày | M16: Quá hạn 31-60 ngày | N16: Quá hạn 61-90 ngày | O16: Quá hạn trên 90 ngày | P16: Kiểm tra
A17: =IF('01_DANH_MUC'!$A7="","",'01_DANH_MUC'!$A7) | B17: =IF($A17="","",'01_DANH_MUC'!$B7) | C17: =IF($A17="","",'01_DANH_MUC'!$C7) | D17: =IF($A17="","",'01_DANH_MUC'!$D7) | E17: =IF($A17="","",'01_DANH_MUC'!$F7+SUMIFS('02_NHAT_KY'!$G$7:$G$506,'02_NHAT_KY'!$C$7:$C$506,$A17,'02_NHAT_KY'!$A$7:$A$506,"<"&$B$4)-SUMIFS('02_NHAT_KY'!$H$7:$H$506,'02_NHAT_KY'!$C$7:$C$506,$A17,'02_NHAT_KY'!$A$7:$A$506,"<"&$B$4)) | F17: =IF($A17="","",SUMIFS('02_NHAT_KY'!$G$7:$G$506,'02_NHAT_KY'!$C$7:$C$506,$A17,'02_NHAT_KY'!$A$7:$A$506,">="&$B$4,'02_NHAT_KY'!$A$7:$A$506,"<="&$E$4)) | G17: =IF($A17="","",SUMIFS('02_NHAT_KY'!$H$7:$H$506,'02_NHAT_KY'!$C$7:$C$506,$A17,'02_NHAT_KY'!$A$7:$A$506,">="&$B$4,'02_NHAT_KY'!$A$7:$A$506,"<="&$E$4)) | H17: =IF($A17="","",$E17+$F17-$G17) | I17: =IF($A17="","",IF($H17<=0,0,MAX(IF(AND('01_DANH_MUC'!$H7>0,'01_DANH_MUC'!$G7<>""),MAX(0,$E$4-'01_DANH_MUC'!$G7),0),IFERROR(MAXIFS('02_NHAT_KY'!$L$7:$L$506,'02_NHAT_KY'!$C$7:$C$506,$A17),0)))) | J17: =IF($A17="","",IF($H17<=0,"Không có dư nợ",IF($I17>0,"Quá hạn","Trong hạn"))) | K17: =IF($A17="","",IF(AND('01_DANH_MUC'!$H7>0,OR('01_DANH_MUC'!$G7="",'01_DANH_MUC'!$G7>=$E$4)),'01_DANH_MUC'!$H7,0)+SUMIFS('02_NHAT_KY'!$K$7:$K$506,'02_NHAT_KY'!$C$7:$C$506,$A17,'02_NHAT_KY'!$J$7:$J$506,">="&$E$4)+SUMIFS('02_NHAT_KY'!$K$7:$K$506,'02_NHAT_KY'!$C$7:$C$506,$A17,'02_NHAT_KY'!$J$7:$J$506,"")) | L17: =IF($A17="","",IF(AND('01_DANH_MUC'!$H7>0,'01_DANH_MUC'!$G7<$E$4,$E$4-'01_DANH_MUC'!$G7<=30),'01_DANH_MUC'!$H7,0)+SUMIFS('02_NHAT_KY'!$K$7:$K$506,'02_NHAT_KY'!$C$7:$C$506,$A17,'02_NHAT_KY'!$L$7:$L$506,">=1",'02_NHAT_KY'!$L$7:$L$506,"<=30")) | M17: =IF($A17="","",IF(AND('01_DANH_MUC'!$H7>0,'01_DANH_MUC'!$G7<$E$4,$E$4-'01_DANH_MUC'!$G7>=31,$E$4-'01_DANH_MUC'!$G7<=60),'01_DANH_MUC'!$H7,0)+SUMIFS('02_NHAT_KY'!$K$7:$K$506,'02_NHAT_KY'!$C$7:$C$506,$A17,'02_NHAT_KY'!$L$7:$L$506,">=31",'02_NHAT_KY'!$L$7:$L$506,"<=60")) | N17: =IF($A17="","",IF(AND('01_DANH_MUC'!$H7>0,'01_DANH_MUC'!$G7<$E$4,$E$4-'01_DANH_MUC'!$G7>=61,$E$4-'01_DANH_MUC'!$G7<=90),'01_DANH_MUC'!$H7,0)+SUMIFS('02_NHAT_KY'!$K$7:$K$506,'02_NHAT_KY'!$C$7:$C$506,$A17,'02_NHAT_KY'!$L$7:$L$506,">=61",'02_NHAT_KY'!$L$7:$L$506,"<=90")) | O17: =IF($A17="","",IF(AND('01_DANH_MUC'!$H7>0,'01_DANH_MUC'!$G7<$E$4,$E$4-'01_DANH_MUC'!$G7>90),'01_DANH_MUC'!$H7,0)+SUMIFS('02_NHAT_KY'!$K$7:$K$506,'02_NHAT_KY'!$C$7:$C$506,$A17,'02_NHAT_KY'!$L$7:$L$506,">90")) | P17: =IF($A17="","",IF($H17<0,"DƯ ÂM/TRẢ TRƯỚC",IF(ABS($H17-SUM($K17:$O17))<1,"OK","LỆCH TUỔI NỢ")))
A18: =IF('01_DANH_MUC'!$A8="","",'01_DANH_MUC'!$A8) | B18: =IF($A18="","",'01_DANH_MUC'!$B8) | C18: =IF($A18="","",'01_DANH_MUC'!$C8) | D18: =IF($A18="","",'01_DANH_MUC'!$D8) | E18: =IF($A18="","",'01_DANH_MUC'!$F8+SUMIFS('02_NHAT_KY'!$G$7:$G$506,'02_NHAT_KY'!$C$7:$C$506,$A18,'02_NHAT_KY'!$A$7:$A$506,"<"&$B$4)-SUMIFS('02_NHAT_KY'!$H$7:$H$506,'02_NHAT_KY'!$C$7:$C$506,$A18,'02_NHAT_KY'!$A$7:$A$506,"<"&$B$4)) | F18: =IF($A18="","",SUMIFS('02_NHAT_KY'!$G$7:$G$506,'02_NHAT_KY'!$C$7:$C$506,$A18,'02_NHAT_KY'!$A$7:$A$506,">="&$B$4,'02_NHAT_KY'!$A$7:$A$506,"<="&$E$4)) | G18: =IF($A18="","",SUMIFS('02_NHAT_KY'!$H$7:$H$506,'02_NHAT_KY'!$C$7:$C$506,$A18,'02_NHAT_KY'!$A$7:$A$506,">="&$B$4,'02_NHAT_KY'!$A$7:$A$506,"<="&$E$4)) | H18: =IF($A18="","",$E18+$F18-$G18) | I18: =IF($A18="","",IF($H18<=0,0,MAX(IF(AND('01_DANH_MUC'!$H8>0,'01_DANH_MUC'!$G8<>""),MAX(0,$E$4-'01_DANH_MUC'!$G8),0),IFERROR(MAXIFS('02_NHAT_KY'!$L$7:$L$506,'02_NHAT_KY'!$C$7:$C$506,$A18),0)))) | J18: =IF($A18="","",IF($H18<=0,"Không có dư nợ",IF($I18>0,"Quá hạn","Trong hạn"))) | K18: =IF($A18="","",IF(AND('01_DANH_MUC'!$H8>0,OR('01_DANH_MUC'!$G8="",'01_DANH_MUC'!$G8>=$E$4)),'01_DANH_MUC'!$H8,0)+SUMIFS('02_NHAT_KY'!$K$7:$K$506,'02_NHAT_KY'!$C$7:$C$506,$A18,'02_NHAT_KY'!$J$7:$J$506,">="&$E$4)+SUMIFS('02_NHAT_KY'!$K$7:$K$506,'02_NHAT_KY'!$C$7:$C$506,$A18,'02_NHAT_KY'!$J$7:$J$506,"")) | L18: =IF($A18="","",IF(AND('01_DANH_MUC'!$H8>0,'01_DANH_MUC'!$G8<$E$4,$E$4-'01_DANH_MUC'!$G8<=30),'01_DANH_MUC'!$H8,0)+SUMIFS('02_NHAT_KY'!$K$7:$K$506,'02_NHAT_KY'!$C$7:$C$506,$A18,'02_NHAT_KY'!$L$7:$L$506,">=1",'02_NHAT_KY'!$L$7:$L$506,"<=30")) | M18: =IF($A18="","",IF(AND('01_DANH_MUC'!$H8>0,'01_DANH_MUC'!$G8<$E$4,$E$4-'01_DANH_MUC'!$G8>=31,$E$4-'01_DANH_MUC'!$G8<=60),'01_DANH_MUC'!$H8,0)+SUMIFS('02_NHAT_KY'!$K$7:$K$506,'02_NHAT_KY'!$C$7:$C$506,$A18,'02_NHAT_KY'!$L$7:$L$506,">=31",'02_NHAT_KY'!$L$7:$L$506,"<=60")) | N18: =IF($A18="","",IF(AND('01_DANH_MUC'!$H8>0,'01_DANH_MUC'!$G8<$E$4,$E$4-'01_DANH_MUC'!$G8>=61,$E$4-'01_DANH_MUC'!$G8<=90),'01_DANH_MUC'!$H8,0)+SUMIFS('02_NHAT_KY'!$K$7:$K$506,'02_NHAT_KY'!$C$7:$C$506,$A18,'02_NHAT_KY'!$L$7:$L$506,">=61",'02_NHAT_KY'!$L$7:$L$506,"<=90")) | O18: =IF($A18="","",IF(AND('01_DANH_MUC'!$H8>0,'01_DANH_MUC'!$G8<$E$4,$E$4-'01_DANH_MUC'!$G8>90),'01_DANH_MUC'!$H8,0)+SUMIFS('02_NHAT_KY'!$K$7:$K$506,'02_NHAT_KY'!$C$7:$C$506,$A18,'02_NHAT_KY'!$L$7:$L$506,">90")) | P18: =IF($A18="","",IF($H18<0,"DƯ ÂM/TRẢ TRƯỚC",IF(ABS($H18-SUM($K18:$O18))<1,"OK","LỆCH TUỔI NỢ")))
A19: =IF('01_DANH_MUC'!$A9="","",'01_DANH_MUC'!$A9) | B19: =IF($A19="","",'01_DANH_MUC'!$B9) | C19: =IF($A19="","",'01_DANH_MUC'!$C9) | D19: =IF($A19="","",'01_DANH_MUC'!$D9) | E19: =IF($A19="","",'01_DANH_MUC'!$F9+SUMIFS('02_NHAT_KY'!$G$7:$G$506,'02_NHAT_KY'!$C$7:$C$506,$A19,'02_NHAT_KY'!$A$7:$A$506,"<"&$B$4)-SUMIFS('02_NHAT_KY'!$H$7:$H$506,'02_NHAT_KY'!$C$7:$C$506,$A19,'02_NHAT_KY'!$A$7:$A$506,"<"&$B$4)) | F19: =IF($A19="","",SUMIFS('02_NHAT_KY'!$G$7:$G$506,'02_NHAT_KY'!$C$7:$C$506,$A19,'02_NHAT_KY'!$A$7:$A$506,">="&$B$4,'02_NHAT_KY'!$A$7:$A$506,"<="&$E$4)) | G19: =IF($A19="","",SUMIFS('02_NHAT_KY'!$H$7:$H$506,'02_NHAT_KY'!$C$7:$C$506,$A19,'02_NHAT_KY'!$A$7:$A$506,">="&$B$4,'02_NHAT_KY'!$A$7:$A$506,"<="&$E$4)) | H19: =IF($A19="","",$E19+$F19-$G19) | I19: =IF($A19="","",IF($H19<=0,0,MAX(IF(AND('01_DANH_MUC'!$H9>0,'01_DANH_MUC'!$G9<>""),MAX(0,$E$4-'01_DANH_MUC'!$G9),0),IFERROR(MAXIFS('02_NHAT_KY'!$L$7:$L$506,'02_NHAT_KY'!$C$7:$C$506,$A19),0)))) | J19: =IF($A19="","",IF($H19<=0,"Không có dư nợ",IF($I19>0,"Quá hạn","Trong hạn"))) | K19: =IF($A19="","",IF(AND('01_DANH_MUC'!$H9>0,OR('01_DANH_MUC'!$G9="",'01_DANH_MUC'!$G9>=$E$4)),'01_DANH_MUC'!$H9,0)+SUMIFS('02_NHAT_KY'!$K$7:$K$506,'02_NHAT_KY'!$C$7:$C$506,$A19,'02_NHAT_KY'!$J$7:$J$506,">="&$E$4)+SUMIFS('02_NHAT_KY'!$K$7:$K$506,'02_NHAT_KY'!$C$7:$C$506,$A19,'02_NHAT_KY'!$J$7:$J$506,"")) | L19: =IF($A19="","",IF(AND('01_DANH_MUC'!$H9>0,'01_DANH_MUC'!$G9<$E$4,$E$4-'01_DANH_MUC'!$G9<=30),'01_DANH_MUC'!$H9,0)+SUMIFS('02_NHAT_KY'!$K$7:$K$506,'02_NHAT_KY'!$C$7:$C$506,$A19,'02_NHAT_KY'!$L$7:$L$506,">=1",'02_NHAT_KY'!$L$7:$L$506,"<=30")) | M19: =IF($A19="","",IF(AND('01_DANH_MUC'!$H9>0,'01_DANH_MUC'!$G9<$E$4,$E$4-'01_DANH_MUC'!$G9>=31,$E$4-'01_DANH_MUC'!$G9<=60),'01_DANH_MUC'!$H9,0)+SUMIFS('02_NHAT_KY'!$K$7:$K$506,'02_NHAT_KY'!$C$7:$C$506,$A19,'02_NHAT_KY'!$L$7:$L$506,">=31",'02_NHAT_KY'!$L$7:$L$506,"<=60")) | N19: =IF($A19="","",IF(AND('01_DANH_MUC'!$H9>0,'01_DANH_MUC'!$G9<$E$4,$E$4-'01_DANH_MUC'!$G9>=61,$E$4-'01_DANH_MUC'!$G9<=90),'01_DANH_MUC'!$H9,0)+SUMIFS('02_NHAT_KY'!$K$7:$K$506,'02_NHAT_KY'!$C$7:$C$506,$A19,'02_NHAT_KY'!$L$7:$L$506,">=61",'02_NHAT_KY'!$L$7:$L$506,"<=90")) | O19: =IF($A19="","",IF(AND('01_DANH_MUC'!$H9>0,'01_DANH_MUC'!$G9<$E$4,$E$4-'01_DANH_MUC'!$G9>90),'01_DANH_MUC'!$H9,0)+SUMIFS('02_NHAT_KY'!$K$7:$K$506,'02_NHAT_KY'!$C$7:$C$506,$A19,'02_NHAT_KY'!$L$7:$L$506,">90")) | P19: =IF($A19="","",IF($H19<0,"DƯ ÂM/TRẢ TRƯỚC",IF(ABS($H19-SUM($K19:$O19))<1,"OK","LỆCH TUỔI NỢ")))
A20: =IF('01_DANH_MUC'!$A10="","",'01_DANH_MUC'!$A10) | B20: =IF($A20="","",'01_DANH_MUC'!$B10) | C20: =IF($A20="","",'01_DANH_MUC'!$C10) | D20: =IF($A20="","",'01_DANH_MUC'!$D10) | E20: =IF($A20="","",'01_DANH_MUC'!$F10+SUMIFS('02_NHAT_KY'!$G$7:$G$506,'02_NHAT_KY'!$C$7:$C$506,$A20,'02_NHAT_KY'!$A$7:$A$506,"<"&$B$4)-SUMIFS('02_NHAT_KY'!$H$7:$H$506,'02_NHAT_KY'!$C$7:$C$506,$A20,'02_NHAT_KY'!$A$7:$A$506,"<"&$B$4)) | F20: =IF($A20="","",SUMIFS('02_NHAT_KY'!$G$7:$G$506,'02_NHAT_KY'!$C$7:$C$506,$A20,'02_NHAT_KY'!$A$7:$A$506,">="&$B$4,'02_NHAT_KY'!$A$7:$A$506,"<="&$E$4)) | G20: =IF($A20="","",SUMIFS('02_NHAT_KY'!$H$7:$H$506,'02_NHAT_KY'!$C$7:$C$506,$A20,'02_NHAT_KY'!$A$7:$A$506,">="&$B$4,'02_NHAT_KY'!$A$7:$A$506,"<="&$E$4)) | H20: =IF($A20="","",$E20+$F20-$G20) | I20: =IF($A20="","",IF($H20<=0,0,MAX(IF(AND('01_DANH_MUC'!$H10>0,'01_DANH_MUC'!$G10<>""),MAX(0,$E$4-'01_DANH_MUC'!$G10),0),IFERROR(MAXIFS('02_NHAT_KY'!$L$7:$L$506,'02_NHAT_KY'!$C$7:$C$506,$A20),0)))) | J20: =IF($A20="","",IF($H20<=0,"Không có dư nợ",IF($I20>0,"Quá hạn","Trong hạn"))) | K20: =IF($A20="","",IF(AND('01_DANH_MUC'!$H10>0,OR('01_DANH_MUC'!$G10="",'01_DANH_MUC'!$G10>=$E$4)),'01_DANH_MUC'!$H10,0)+SUMIFS('02_NHAT_KY'!$K$7:$K$506,'02_NHAT_KY'!$C$7:$C$506,$A20,'02_NHAT_KY'!$J$7:$J$506,">="&$E$4)+SUMIFS('02_NHAT_KY'!$K$7:$K$506,'02_NHAT_KY'!$C$7:$C$506,$A20,'02_NHAT_KY'!$J$7:$J$506,"")) | L20: =IF($A20="","",IF(AND('01_DANH_MUC'!$H10>0,'01_DANH_MUC'!$G10<$E$4,$E$4-'01_DANH_MUC'!$G10<=30),'01_DANH_MUC'!$H10,0)+SUMIFS('02_NHAT_KY'!$K$7:$K$506,'02_NHAT_KY'!$C$7:$C$506,$A20,'02_NHAT_KY'!$L$7:$L$506,">=1",'02_NHAT_KY'!$L$7:$L$506,"<=30")) | M20: =IF($A20="","",IF(AND('01_DANH_MUC'!$H10>0,'01_DANH_MUC'!$G10<$E$4,$E$4-'01_DANH_MUC'!$G10>=31,$E$4-'01_DANH_MUC'!$G10<=60),'01_DANH_MUC'!$H10,0)+SUMIFS('02_NHAT_KY'!$K$7:$K$506,'02_NHAT_KY'!$C$7:$C$506,$A20,'02_NHAT_KY'!$L$7:$L$506,">=31",'02_NHAT_KY'!$L$7:$L$506,"<=60")) | N20: =IF($A20="","",IF(AND('01_DANH_MUC'!$H10>0,'01_DANH_MUC'!$G10<$E$4,$E$4-'01_DANH_MUC'!$G10>=61,$E$4-'01_DANH_MUC'!$G10<=90),'01_DANH_MUC'!$H10,0)+SUMIFS('02_NHAT_KY'!$K$7:$K$506,'02_NHAT_KY'!$C$7:$C$506,$A20,'02_NHAT_KY'!$L$7:$L$506,">=61",'02_NHAT_KY'!$L$7:$L$506,"<=90")) | O20: =IF($A20="","",IF(AND('01_DANH_MUC'!$H10>0,'01_DANH_MUC'!$G10<$E$4,$E$4-'01_DANH_MUC'!$G10>90),'01_DANH_MUC'!$H10,0)+SUMIFS('02_NHAT_KY'!$K$7:$K$506,'02_NHAT_KY'!$C$7:$C$506,$A20,'02_NHAT_KY'!$L$7:$L$506,">90")) | P20: =IF($A20="","",IF($H20<0,"DƯ ÂM/TRẢ TRƯỚC",IF(ABS($H20-SUM($K20:$O20))<1,"OK","LỆCH TUỔI NỢ")))
A21: =IF('01_DANH_MUC'!$A11="","",'01_DANH_MUC'!$A11) | B21: =IF($A21="","",'01_DANH_MUC'!$B11) | C21: =IF($A21="","",'01_DANH_MUC'!$C11) | D21: =IF($A21="","",'01_DANH_MUC'!$D11) | E21: =IF($A21="","",'01_DANH_MUC'!$F11+SUMIFS('02_NHAT_KY'!$G$7:$G$506,'02_NHAT_KY'!$C$7:$C$506,$A21,'02_NHAT_KY'!$A$7:$A$506,"<"&$B$4)-SUMIFS('02_NHAT_KY'!$H$7:$H$506,'02_NHAT_KY'!$C$7:$C$506,$A21,'02_NHAT_KY'!$A$7:$A$506,"<"&$B$4)) | F21: =IF($A21="","",SUMIFS('02_NHAT_KY'!$G$7:$G$506,'02_NHAT_KY'!$C$7:$C$506,$A21,'02_NHAT_KY'!$A$7:$A$506,">="&$B$4,'02_NHAT_KY'!$A$7:$A$506,"<="&$E$4)) | G21: =IF($A21="","",SUMIFS('02_NHAT_KY'!$H$7:$H$506,'02_NHAT_KY'!$C$7:$C$506,$A21,'02_NHAT_KY'!$A$7:$A$506,">="&$B$4,'02_NHAT_KY'!$A$7:$A$506,"<="&$E$4)) | H21: =IF($A21="","",$E21+$F21-$G21) | I21: =IF($A21="","",IF($H21<=0,0,MAX(IF(AND('01_DANH_MUC'!$H11>0,'01_DANH_MUC'!$G11<>""),MAX(0,$E$4-'01_DANH_MUC'!$G11),0),IFERROR(MAXIFS('02_NHAT_KY'!$L$7:$L$506,'02_NHAT_KY'!$C$7:$C$506,$A21),0)))) | J21: =IF($A21="","",IF($H21<=0,"Không có dư nợ",IF($I21>0,"Quá hạn","Trong hạn"))) | K21: =IF($A21="","",IF(AND('01_DANH_MUC'!$H11>0,OR('01_DANH_MUC'!$G11="",'01_DANH_MUC'!$G11>=$E$4)),'01_DANH_MUC'!$H11,0)+SUMIFS('02_NHAT_KY'!$K$7:$K$506,'02_NHAT_KY'!$C$7:$C$506,$A21,'02_NHAT_KY'!$J$7:$J$506,">="&$E$4)+SUMIFS('02_NHAT_KY'!$K$7:$K$506,'02_NHAT_KY'!$C$7:$C$506,$A21,'02_NHAT_KY'!$J$7:$J$506,"")) | L21: =IF($A21="","",IF(AND('01_DANH_MUC'!$H11>0,'01_DANH_MUC'!$G11<$E$4,$E$4-'01_DANH_MUC'!$G11<=30),'01_DANH_MUC'!$H11,0)+SUMIFS('02_NHAT_KY'!$K$7:$K$506,'02_NHAT_KY'!$C$7:$C$506,$A21,'02_NHAT_KY'!$L$7:$L$506,">=1",'02_NHAT_KY'!$L$7:$L$506,"<=30")) | M21: =IF($A21="","",IF(AND('01_DANH_MUC'!$H11>0,'01_DANH_MUC'!$G11<$E$4,$E$4-'01_DANH_MUC'!$G11>=31,$E$4-'01_DANH_MUC'!$G11<=60),'01_DANH_MUC'!$H11,0)+SUMIFS('02_NHAT_KY'!$K$7:$K$506,'02_NHAT_KY'!$C$7:$C$506,$A21,'02_NHAT_KY'!$L$7:$L$506,">=31",'02_NHAT_KY'!$L$7:$L$506,"<=60")) | N21: =IF($A21="","",IF(AND('01_DANH_MUC'!$H11>0,'01_DANH_MUC'!$G11<$E$4,$E$4-'01_DANH_MUC'!$G11>=61,$E$4-'01_DANH_MUC'!$G11<=90),'01_DANH_MUC'!$H11,0)+SUMIFS('02_NHAT_KY'!$K$7:$K$506,'02_NHAT_KY'!$C$7:$C$506,$A21,'02_NHAT_KY'!$L$7:$L$506,">=61",'02_NHAT_KY'!$L$7:$L$506,"<=90")) | O21: =IF($A21="","",IF(AND('01_DANH_MUC'!$H11>0,'01_DANH_MUC'!$G11<$E$4,$E$4-'01_DANH_MUC'!$G11>90),'01_DANH_MUC'!$H11,0)+SUMIFS('02_NHAT_KY'!$K$7:$K$506,'02_NHAT_KY'!$C$7:$C$506,$A21,'02_NHAT_KY'!$L$7:$L$506,">90")) | P21: =IF($A21="","",IF($H21<0,"DƯ ÂM/TRẢ TRƯỚC",IF(ABS($H21-SUM($K21:$O21))<1,"OK","LỆCH TUỔI NỢ")))
A22: =IF('01_DANH_MUC'!$A12="","",'01_DANH_MUC'!$A12) | B22: =IF($A22="","",'01_DANH_MUC'!$B12) | C22: =IF($A22="","",'01_DANH_MUC'!$C12) | D22: =IF($A22="","",'01_DANH_MUC'!$D12) | E22: =IF($A22="","",'01_DANH_MUC'!$F12+SUMIFS('02_NHAT_KY'!$G$7:$G$506,'02_NHAT_KY'!$C$7:$C$506,$A22,'02_NHAT_KY'!$A$7:$A$506,"<"&$B$4)-SUMIFS('02_NHAT_KY'!$H$7:$H$506,'02_NHAT_KY'!$C$7:$C$506,$A22,'02_NHAT_KY'!$A$7:$A$506,"<"&$B$4)) | F22: =IF($A22="","",SUMIFS('02_NHAT_KY'!$G$7:$G$506,'02_NHAT_KY'!$C$7:$C$506,$A22,'02_NHAT_KY'!$A$7:$A$506,">="&$B$4,'02_NHAT_KY'!$A$7:$A$506,"<="&$E$4)) | G22: =IF($A22="","",SUMIFS('02_NHAT_KY'!$H$7:$H$506,'02_NHAT_KY'!$C$7:$C$506,$A22,'02_NHAT_KY'!$A$7:$A$506,">="&$B$4,'02_NHAT_KY'!$A$7:$A$506,"<="&$E$4)) | H22: =IF($A22="","",$E22+$F22-$G22) | I22: =IF($A22="","",IF($H22<=0,0,MAX(IF(AND('01_DANH_MUC'!$H12>0,'01_DANH_MUC'!$G12<>""),MAX(0,$E$4-'01_DANH_MUC'!$G12),0),IFERROR(MAXIFS('02_NHAT_KY'!$L$7:$L$506,'02_NHAT_KY'!$C$7:$C$506,$A22),0)))) | J22: =IF($A22="","",IF($H22<=0,"Không có dư nợ",IF($I22>0,"Quá hạn","Trong hạn"))) | K22: =IF($A22="","",IF(AND('01_DANH_MUC'!$H12>0,OR('01_DANH_MUC'!$G12="",'01_DANH_MUC'!$G12>=$E$4)),'01_DANH_MUC'!$H12,0)+SUMIFS('02_NHAT_KY'!$K$7:$K$506,'02_NHAT_KY'!$C$7:$C$506,$A22,'02_NHAT_KY'!$J$7:$J$506,">="&$E$4)+SUMIFS('02_NHAT_KY'!$K$7:$K$506,'02_NHAT_KY'!$C$7:$C$506,$A22,'02_NHAT_KY'!$J$7:$J$506,"")) | L22: =IF($A22="","",IF(AND('01_DANH_MUC'!$H12>0,'01_DANH_MUC'!$G12<$E$4,$E$4-'01_DANH_MUC'!$G12<=30),'01_DANH_MUC'!$H12,0)+SUMIFS('02_NHAT_KY'!$K$7:$K$506,'02_NHAT_KY'!$C$7:$C$506,$A22,'02_NHAT_KY'!$L$7:$L$506,">=1",'02_NHAT_KY'!$L$7:$L$506,"<=30")) | M22: =IF($A22="","",IF(AND('01_DANH_MUC'!$H12>0,'01_DANH_MUC'!$G12<$E$4,$E$4-'01_DANH_MUC'!$G12>=31,$E$4-'01_DANH_MUC'!$G12<=60),'01_DANH_MUC'!$H12,0)+SUMIFS('02_NHAT_KY'!$K$7:$K$506,'02_NHAT_KY'!$C$7:$C$506,$A22,'02_NHAT_KY'!$L$7:$L$506,">=31",'02_NHAT_KY'!$L$7:$L$506,"<=60")) | N22: =IF($A22="","",IF(AND('01_DANH_MUC'!$H12>0,'01_DANH_MUC'!$G12<$E$4,$E$4-'01_DANH_MUC'!$G12>=61,$E$4-'01_DANH_MUC'!$G12<=90),'01_DANH_MUC'!$H12,0)+SUMIFS('02_NHAT_KY'!$K$7:$K$506,'02_NHAT_KY'!$C$7:$C$506,$A22,'02_NHAT_KY'!$L$7:$L$506,">=61",'02_NHAT_KY'!$L$7:$L$506,"<=90")) | O22: =IF($A22="","",IF(AND('01_DANH_MUC'!$H12>0,'01_DANH_MUC'!$G12<$E$4,$E$4-'01_DANH_MUC'!$G12>90),'01_DANH_MUC'!$H12,0)+SUMIFS('02_NHAT_KY'!$K$7:$K$506,'02_NHAT_KY'!$C$7:$C$506,$A22,'02_NHAT_KY'!$L$7:$L$506,">90")) | P22: =IF($A22="","",IF($H22<0,"DƯ ÂM/TRẢ TRƯỚC",IF(ABS($H22-SUM($K22:$O22))<1,"OK","LỆCH TUỔI NỢ")))
A23: =IF('01_DANH_MUC'!$A13="","",'01_DANH_MUC'!$A13) | B23: =IF($A23="","",'01_DANH_MUC'!$B13) | C23: =IF($A23="","",'01_DANH_MUC'!$C13) | D23: =IF($A23="","",'01_DANH_MUC'!$D13) | E23: =IF($A23="","",'01_DANH_MUC'!$F13+SUMIFS('02_NHAT_KY'!$G$7:$G$506,'02_NHAT_KY'!$C$7:$C$506,$A23,'02_NHAT_KY'!$A$7:$A$506,"<"&$B$4)-SUMIFS('02_NHAT_KY'!$H$7:$H$506,'02_NHAT_KY'!$C$7:$C$506,$A23,'02_NHAT_KY'!$A$7:$A$506,"<"&$B$4)) | F23: =IF($A23="","",SUMIFS('02_NHAT_KY'!$G$7:$G$506,'02_NHAT_KY'!$C$7:$C$506,$A23,'02_NHAT_KY'!$A$7:$A$506,">="&$B$4,'02_NHAT_KY'!$A$7:$A$506,"<="&$E$4)) | G23: =IF($A23="","",SUMIFS('02_NHAT_KY'!$H$7:$H$506,'02_NHAT_KY'!$C$7:$C$506,$A23,'02_NHAT_KY'!$A$7:$A$506,">="&$B$4,'02_NHAT_KY'!$A$7:$A$506,"<="&$E$4)) | H23: =IF($A23="","",$E23+$F23-$G23) | I23: =IF($A23="","",IF($H23<=0,0,MAX(IF(AND('01_DANH_MUC'!$H13>0,'01_DANH_MUC'!$G13<>""),MAX(0,$E$4-'01_DANH_MUC'!$G13),0),IFERROR(MAXIFS('02_NHAT_KY'!$L$7:$L$506,'02_NHAT_KY'!$C$7:$C$506,$A23),0)))) | J23: =IF($A23="","",IF($H23<=0,"Không có dư nợ",IF($I23>0,"Quá hạn","Trong hạn"))) | K23: =IF($A23="","",IF(AND('01_DANH_MUC'!$H13>0,OR('01_DANH_MUC'!$G13="",'01_DANH_MUC'!$G13>=$E$4)),'01_DANH_MUC'!$H13,0)+SUMIFS('02_NHAT_KY'!$K$7:$K$506,'02_NHAT_KY'!$C$7:$C$506,$A23,'02_NHAT_KY'!$J$7:$J$506,">="&$E$4)+SUMIFS('02_NHAT_KY'!$K$7:$K$506,'02_NHAT_KY'!$C$7:$C$506,$A23,'02_NHAT_KY'!$J$7:$J$506,"")) | L23: =IF($A23="","",IF(AND('01_DANH_MUC'!$H13>0,'01_DANH_MUC'!$G13<$E$4,$E$4-'01_DANH_MUC'!$G13<=30),'01_DANH_MUC'!$H13,0)+SUMIFS('02_NHAT_KY'!$K$7:$K$506,'02_NHAT_KY'!$C$7:$C$506,$A23,'02_NHAT_KY'!$L$7:$L$506,">=1",'02_NHAT_KY'!$L$7:$L$506,"<=30")) | M23: =IF($A23="","",IF(AND('01_DANH_MUC'!$H13>0,'01_DANH_MUC'!$G13<$E$4,$E$4-'01_DANH_MUC'!$G13>=31,$E$4-'01_DANH_MUC'!$G13<=60),'01_DANH_MUC'!$H13,0)+SUMIFS('02_NHAT_KY'!$K$7:$K$506,'02_NHAT_KY'!$C$7:$C$506,$A23,'02_NHAT_KY'!$L$7:$L$506,">=31",'02_NHAT_KY'!$L$7:$L$506,"<=60")) | N23: =IF($A23="","",IF(AND('01_DANH_MUC'!$H13>0,'01_DANH_MUC'!$G13<$E$4,$E$4-'01_DANH_MUC'!$G13>=61,$E$4-'01_DANH_MUC'!$G13<=90),'01_DANH_MUC'!$H13,0)+SUMIFS('02_NHAT_KY'!$K$7:$K$506,'02_NHAT_KY'!$C$7:$C$506,$A23,'02_NHAT_KY'!$L$7:$L$506,">=61",'02_NHAT_KY'!$L$7:$L$506,"<=90")) | O23: =IF($A23="","",IF(AND('01_DANH_MUC'!$H13>0,'01_DANH_MUC'!$G13<$E$4,$E$4-'01_DANH_MUC'!$G13>90),'01_DANH_MUC'!$H13,0)+SUMIFS('02_NHAT_KY'!$K$7:$K$506,'02_NHAT_KY'!$C$7:$C$506,$A23,'02_NHAT_KY'!$L$7:$L$506,">90")) | P23: =IF($A23="","",IF($H23<0,"DƯ ÂM/TRẢ TRƯỚC",IF(ABS($H23-SUM($K23:$O23))<1,"OK","LỆCH TUỔI NỢ")))
A24: =IF('01_DANH_MUC'!$A14="","",'01_DANH_MUC'!$A14) | B24: =IF($A24="","",'01_DANH_MUC'!$B14) | C24: =IF($A24="","",'01_DANH_MUC'!$C14) | D24: =IF($A24="","",'01_DANH_MUC'!$D14) | E24: =IF($A24="","",'01_DANH_MUC'!$F14+SUMIFS('02_NHAT_KY'!$G$7:$G$506,'02_NHAT_KY'!$C$7:$C$506,$A24,'02_NHAT_KY'!$A$7:$A$506,"<"&$B$4)-SUMIFS('02_NHAT_KY'!$H$7:$H$506,'02_NHAT_KY'!$C$7:$C$506,$A24,'02_NHAT_KY'!$A$7:$A$506,"<"&$B$4)) | F24: =IF($A24="","",SUMIFS('02_NHAT_KY'!$G$7:$G$506,'02_NHAT_KY'!$C$7:$C$506,$A24,'02_NHAT_KY'!$A$7:$A$506,">="&$B$4,'02_NHAT_KY'!$A$7:$A$506,"<="&$E$4)) | G24: =IF($A24="","",SUMIFS('02_NHAT_KY'!$H$7:$H$506,'02_NHAT_KY'!$C$7:$C$506,$A24,'02_NHAT_KY'!$A$7:$A$506,">="&$B$4,'02_NHAT_KY'!$A$7:$A$506,"<="&$E$4)) | H24: =IF($A24="","",$E24+$F24-$G24) | I24: =IF($A24="","",IF($H24<=0,0,MAX(IF(AND('01_DANH_MUC'!$H14>0,'01_DANH_MUC'!$G14<>""),MAX(0,$E$4-'01_DANH_MUC'!$G14),0),IFERROR(MAXIFS('02_NHAT_KY'!$L$7:$L$506,'02_NHAT_KY'!$C$7:$C$506,$A24),0)))) | J24: =IF($A24="","",IF($H24<=0,"Không có dư nợ",IF($I24>0,"Quá hạn","Trong hạn"))) | K24: =IF($A24="","",IF(AND('01_DANH_MUC'!$H14>0,OR('01_DANH_MUC'!$G14="",'01_DANH_MUC'!$G14>=$E$4)),'01_DANH_MUC'!$H14,0)+SUMIFS('02_NHAT_KY'!$K$7:$K$506,'02_NHAT_KY'!$C$7:$C$506,$A24,'02_NHAT_KY'!$J$7:$J$506,">="&$E$4)+SUMIFS('02_NHAT_KY'!$K$7:$K$506,'02_NHAT_KY'!$C$7:$C$506,$A24,'02_NHAT_KY'!$J$7:$J$506,"")) | L24: =IF($A24="","",IF(AND('01_DANH_MUC'!$H14>0,'01_DANH_MUC'!$G14<$E$4,$E$4-'01_DANH_MUC'!$G14<=30),'01_DANH_MUC'!$H14,0)+SUMIFS('02_NHAT_KY'!$K$7:$K$506,'02_NHAT_KY'!$C$7:$C$506,$A24,'02_NHAT_KY'!$L$7:$L$506,">=1",'02_NHAT_KY'!$L$7:$L$506,"<=30")) | M24: =IF($A24="","",IF(AND('01_DANH_MUC'!$H14>0,'01_DANH_MUC'!$G14<$E$4,$E$4-'01_DANH_MUC'!$G14>=31,$E$4-'01_DANH_MUC'!$G14<=60),'01_DANH_MUC'!$H14,0)+SUMIFS('02_NHAT_KY'!$K$7:$K$506,'02_NHAT_KY'!$C$7:$C$506,$A24,'02_NHAT_KY'!$L$7:$L$506,">=31",'02_NHAT_KY'!$L$7:$L$506,"<=60")) | N24: =IF($A24="","",IF(AND('01_DANH_MUC'!$H14>0,'01_DANH_MUC'!$G14<$E$4,$E$4-'01_DANH_MUC'!$G14>=61,$E$4-'01_DANH_MUC'!$G14<=90),'01_DANH_MUC'!$H14,0)+SUMIFS('02_NHAT_KY'!$K$7:$K$506,'02_NHAT_KY'!$C$7:$C$506,$A24,'02_NHAT_KY'!$L$7:$L$506,">=61",'02_NHAT_KY'!$L$7:$L$506,"<=90")) | O24: =IF($A24="","",IF(AND('01_DANH_MUC'!$H14>0,'01_DANH_MUC'!$G14<$E$4,$E$4-'01_DANH_MUC'!$G14>90),'01_DANH_MUC'!$H14,0)+SUMIFS('02_NHAT_KY'!$K$7:$K$506,'02_NHAT_KY'!$C$7:$C$506,$A24,'02_NHAT_KY'!$L$7:$L$506,">90")) | P24: =IF($A24="","",IF($H24<0,"DƯ ÂM/TRẢ TRƯỚC",IF(ABS($H24-SUM($K24:$O24))<1,"OK","LỆCH TUỔI NỢ")))
