Workbook

Sheet GIOI_THIEU
B1: KK HOME
B3: BỘ MẪU HỢP ĐỒNG LAO ĐỘNG TỰ ĐỘNG 2026
B6: CĂN CỨ PHÁP LÝ
B7: Bộ mẫu Hợp đồng lao động 2026 do KK HOME biên soạn, cập nhật căn cứ pháp lý đến tháng 7/2026:
B8: Bộ Luật Lao động 2019
B9: Luật BHXH 2024
B10: Luật Việc làm 2025
B11: Luật Thuế TNCN 2025
B12: Mức lương tối thiểu vùng theo Nghị định 293/2025/NĐ-CP
B14: HƯỚNG DẪN CHUNG
B15: 1. Nhập thông tin công ty (chỉ một lần) tại phần 1 của sheet NHAP_LIEU.
B16: 2. Thêm mỗi người lao động một dòng tại phần 2 — chỉ điền các ô màu vàng.
... B20: LIÊN HỆ
B21: Công ty | D21: KK HOME
B22: Địa chỉ | D22: Đồng Tháp
B23: Hotline | D23: 090 744 6543
B24: Website | D24: https://www.hkdkkhome.com/
B26: Miễn trừ: Biểu mẫu mang tính tham khảo, được xây dựng theo quy định pháp luật tại thời điểm biên soạn. Doanh nghiệp cần rà soát, điều chỉnh cho phù hợp thực tế và cập nhật khi pháp luật thay đổi. © 2026 KK HOME.

Sheet NHAP_LIEU
A1: NHẬP LIỆU HỢP ĐỒNG LAO ĐỘNG — 1 NƠI DUY NHẤT
A2: 1. THÔNG TIN CÔNG TY — CHỈ NHẬP MỘT LẦN
A4: Tên doanh nghiệp | B4: CÔNG TY TNHH KK HOME | D4: Người đại diện | E4: HUỲNH NGỌC NGÂN | G4: Ngày trả lương | H4: 5 | J4: Giờ/ngày | K4: 8
A5: Mã số thuế | B5: MST-MAU-0001 | D5: Tư cách đại diện | E5: Người đại diện theo pháp luật | G5: Vùng lương | H5: Vùng I | J5: Giờ/tuần | K5: 40
A6: Địa chỉ trụ sở | B6: 526 Lê Đại Hành, Phường Mỹ Trà, Tỉnh Đồng Tháp | D6: Chức danh đại diện | E6: Giám đốc | G6: Hình thức trả lương | H6: Chuyển khoản | J6: Giờ bắt đầu | K6: 08:00
A7: Điện thoại | B7: 090 744 6543 | D7: Địa điểm ký | E7: Đồng Tháp | G7: Hình thức làm việc | H7: Tại văn phòng/nhà máy | J7: Giờ kết thúc | K7: 17:00
A8: Email | B8: admin@hkdkkhome.com | D8: Tên viết tắt | E8: MAU | G8: Ngày nghỉ hằng tuần | H8: Thứ Bảy và Chủ nhật | J8: Nghỉ giữa giờ (phút) | K8: 60
A11: 2. DANH SÁCH NGƯỜI LAO ĐỘNG — MỖI NGƯỜI MỘT DÒNG
A12: THÔNG TIN CÁ NHÂN | P12: CÔNG VIỆC | T12: HỢP ĐỒNG & THỬ VIỆC | AA12: LƯƠNG & PHỤ CẤP | AJ12: BẢO MẬT & GHI CHÚ
A13: Mã nhân viên | B13: Số hợp đồng (tự động) | C13: Họ và tên | D13: Giới tính | E13: Ngày sinh | F13: Quốc tịch | G13: Số CCCD/Hộ chiếu | H13: Ngày cấp | I13: Nơi cấp | J13: Nơi cư trú | K13: Trình độ chuyên môn | L13: Mã số thuế TNCN | M13: Mã số BHXH | N13: Số GPLĐ/xác nhận | O13: Liên hệ khẩn cấp | P13: Chức danh/vị trí | Q13: Bộ phận/phòng ban | R13: Mô tả công việc | S13: Địa điểm làm việc | T13: Loại hợp đồng | U13: Thời hạn (tháng) | V13: Ngày ký hợp đồng | W13: Ngày bắt đầu | X13: Ngày kết thúc (tự động) | Y13: Số ngày thử việc | Z13: Thử việc từ ngày | AA13: Lương chính | AB13: Phụ cấp trách nhiệm | AC13: Tiền ăn giữa ca | AD13: Hỗ trợ điện thoại | AE13: Hỗ trợ xăng xe | AF13: Hỗ trợ nhà ở | AG13: Khoản bổ sung khác | AH13: Mức khoản bổ sung khác | AI13: Vùng lương | AJ13: Thông tin mật bổ sung | AK13: Ghi chú
A14: NV0001 | B14: =IF($A14="","",TEXT(ROW()-19,"000")&"/"&IF($V14="",2026,YEAR($V14))&"/HĐLĐ-"&$E$8) -> -005/2026/HĐLĐ-MAU | C14: Nguyễn Văn An | D14: Nam | E14: 31118 | F14: Việt Nam | G14: CCCDxxxxxxxx | H14: 44362 | I14: Cục Cảnh sát QLHC về TTXH | J14: 12 Lê Lợi, Q.1, TP.HCM | K14: Đại học | L14: MST000101 | M14: BH85000101 | O14: Người thân – 0903000101 | P14: Kế toán trưởng | Q14: Phòng Tài chính – Kế toán | R14: Tổ chức, điều hành công tác kế toán; lập và kiểm soát báo cáo tài chính. | S14: Trụ sở Công ty | T14: Không xác định thời hạn | V14: 46027 | W14: 46027 | X14: =IF($A14="","",IF($T14="Xác định thời hạn",IF(AND($W14<>"",$U14<>""),EDATE($W14,$U14)-1,""),"")) | Y14: 30 | Z14: 45997 | AA14: 25000000 | AB14: 4000000 | AC14: 730000 | AD14: 300000 | AE14: 600000 | AK14: Dữ liệu mẫu – thay bằng dữ liệu thật
A15: NV0002 | B15: =IF($A15="","",TEXT(ROW()-19,"000")&"/"&IF($V15="",2026,YEAR($V15))&"/HĐLĐ-"&$E$8) -> -004/2026/HĐLĐ-MAU | C15: Trần Thị Bích Ngọc | D15: Nữ | E15: 35271 | F15: Việt Nam | G15: CCCDxxxxxxxx | H15: 44362 | I15: Cục Cảnh sát QLHC về TTXH | J15: 45 Nguyễn Trãi, Q.5, TP.HCM | K15: Đại học | L15: MST000202 | M15: BH96000202 | O15: Người thân – 0903000202 | P15: Kế toán viên | Q15: Phòng Tài chính – Kế toán | R15: Thực hiện nghiệp vụ kế toán, kê khai thuế theo phân công. | S15: Trụ sở Công ty | T15: Xác định thời hạn | U15: 12 | V15: 46027 | W15: 46027 | X15: =IF($A15="","",IF($T15="Xác định thời hạn",IF(AND($W15<>"",$U15<>""),EDATE($W15,$U15)-1,""),"")) -> 46391 | Y15: 30 | Z15: 45997 | AA15: 12000000 | AC15: 730000 | AD15: 200000 | AE15: 400000 | AK15: Dữ liệu mẫu – thay bằng dữ liệu thật
A16: NV0003 | B16: =IF($A16="","",TEXT(ROW()-19,"000")&"/"&IF($V16="",2026,YEAR($V16))&"/HĐLĐ-"&$E$8) -> -003/2026/HĐLĐ-MAU | C16: Lê Hoàng Cường | D16: Nam | E16: 32450 | F16: Việt Nam | G16: CCCDxxxxxxxx | H16: 44362 | I16: Cục Cảnh sát QLHC về TTXH | J16: 78 Cách Mạng Tháng 8, Q.3, TP.HCM | K16: Đại học | L16: MST000303 | M16: BH88000303 | O16: Người thân – 0903000303 | P16: Trưởng phòng Nhân sự | Q16: Phòng Hành chính – Nhân sự | R16: Quản lý tuyển dụng, C&B, quan hệ lao động và hành chính. | S16: Trụ sở Công ty | T16: Không xác định thời hạn | V16: 46027 | W16: 46027 | X16: =IF($A16="","",IF($T16="Xác định thời hạn",IF(AND($W16<>"",$U16<>""),EDATE($W16,$U16)-1,""),"")) | Y16: 30 | Z16: 45997 | AA16: 22000000 | AB16: 3500000 | AC16: 730000 | AD16: 300000 | AE16: 500000 | AK16: Dữ liệu mẫu – thay bằng dữ liệu thật
A17: NV0004 | B17: =IF($A17="","",TEXT(ROW()-19,"000")&"/"&IF($V17="",2026,YEAR($V17))&"/HĐLĐ-"&$E$8) -> -002/2026/HĐLĐ-MAU | C17: Phạm Thị Dung | D17: Nữ | E17: 35479 | F17: Việt Nam | G17: CCCDxxxxxxxx | H17: 44362 | I17: Cục Cảnh sát QLHC về TTXH | J17: Chung cư Sunrise, Q.7, TP.HCM | K17: Cao đẳng | L17: MST000404 | M17: BH97000404 | O17: Người thân – 0903000404 | P17: Chuyên viên tuyển dụng | Q17: Phòng Hành chính – Nhân sự | R17: Tuyển dụng, onboarding và quản trị hồ sơ nhân sự. | S17: Trụ sở Công ty | T17: Xác định thời hạn | U17: 24 | V17: 46027 | W17: 46027 | X17: =IF($A17="","",IF($T17="Xác định thời hạn",IF(AND($W17<>"",$U17<>""),EDATE($W17,$U17)-1,""),"")) -> 46756 | Y17: 30 | Z17: 45997 | AA17: 13000000 | AC17: 730000 | AD17: 200000 | AE17: 300000 | AK17: Dữ liệu mẫu – thay bằng dữ liệu thật
A18: NV0005 | B18: =IF($A18="","",TEXT(ROW()-19,"000")&"/"&IF($V18="",2026,YEAR($V18))&"/HĐLĐ-"&$E$8) -> -001/2026/HĐLĐ-MAU | C18: Vũ Minh Đức | D18: Nam | E18: 31664 | F18: Việt Nam | G18: CCCDxxxxxxxx | H18: 44362 | I18: Cục Cảnh sát QLHC về TTXH | J18: 220 Điện Biên Phủ, Q.Bình Thạnh, TP.HCM | K18: Đại học | L18: MST000505 | M18: BH86000505 | O18: Người thân – 0903000505 | P18: Trưởng phòng Kinh doanh | Q18: Phòng Kinh doanh | R18: Xây dựng và triển khai kế hoạch kinh doanh, quản lý đội bán hàng. | S18: Trụ sở Công ty | T18: Không xác định thời hạn | V18: 46027 | W18: 46027 | X18: =IF($A18="","",IF($T18="Xác định thời hạn",IF(AND($W18<>"",$U18<>""),EDATE($W18,$U18)-1,""),"")) | Y18: 30 | Z18: 45997 | AA18: 20000000 | AB18: 5000000 | AC18: 730000 | AD18: 500000 | AE18: 700000 | AK18: Dữ liệu mẫu – thay bằng dữ liệu thật
A19: NV0006 | B19: =IF($A19="","",TEXT(ROW()-19,"000")&"/"&IF($V19="",2026,YEAR($V19))&"/HĐLĐ-"&$E$8) -> 000/2026/HĐLĐ-MAU | C19: Hoàng Thị Em | D19: Nữ | E19: 35945 | F19: Việt Nam | G19: CCCDxxxxxxxx | H19: 44362 | I19: Cục Cảnh sát QLHC về TTXH | J19: 33 Phan Xích Long, Q.Phú Nhuận, TP.HCM | K19: Cao đẳng | L19: MST000606 | M19: BH98000606 | O19: Người thân – 0903000606 | P19: Nhân viên kinh doanh | Q19: Phòng Kinh doanh | R19: Phát triển khách hàng, chăm sóc và đạt chỉ tiêu doanh số. | S19: Trụ sở Công ty | T19: Xác định thời hạn | U19: 12 | V19: 46027 | W19: 46027 | X19: =IF($A19="","",IF($T19="Xác định thời hạn",IF(AND($W19<>"",$U19<>""),EDATE($W19,$U19)-1,""),"")) -> 46391 | Y19: 30 | Z19: 45997 | AA19: 9000000 | AC19: 730000 | AD19: 300000 | AE19: 500000 | AK19: Dữ liệu mẫu – thay bằng dữ liệu thật
A20: NV0007 | B20: =IF($A20="","",TEXT(ROW()-19,"000")&"/"&IF($V20="",2026,YEAR($V20))&"/HĐLĐ-"&$E$8) -> 001/2026/HĐLĐ-MAU | C20: Đặng Quốc Phong | D20: Nam | E20: 32888 | F20: Việt Nam | G20: CCCDxxxxxxxx | H20: 44362 | I20: Cục Cảnh sát QLHC về TTXH | J20: 5 Trường Chinh, Q.Tân Bình, TP.HCM | K20: Đại học | L20: MST000707 | M20: BH90000707 | O20: Người thân – 0903000707 | P20: Kỹ sư xây dựng | Q20: Phòng Kỹ thuật | R20: Giám sát thi công, quản lý chất lượng và tiến độ công trình. | S20: Chi nhánh Công ty | T20: Không xác định thời hạn | V20: 46027 | W20: 46027 | X20: =IF($A20="","",IF($T20="Xác định thời hạn",IF(AND($W20<>"",$U20<>""),EDATE($W20,$U20)-1,""),"")) | Y20: 30 | Z20: 45997 | AA20: 18000000 | AB20: 2000000 | AC20: 730000 | AD20: 300000 | AE20: 500000 | AK20: Dữ liệu mẫu – thay bằng dữ liệu thật
A21: NV0008 | B21: =IF($A21="","",TEXT(ROW()-19,"000")&"/"&IF($V21="",2026,YEAR($V21))&"/HĐLĐ-"&$E$8) -> 002/2026/HĐLĐ-MAU | C21: Bùi Thị Giang | D21: Nữ | E21: 34918 | F21: Việt Nam | G21: CCCDxxxxxxxx | H21: 44362 | I21: Cục Cảnh sát QLHC về TTXH | J21: 90 Quang Trung, Q.Gò Vấp, TP.HCM | K21: Trung cấp | L21: MST000808 | M21: BH95000808 | O21: Người thân – 0903000808 | P21: Nhân viên QA | Q21: Phòng Sản xuất | R21: Kiểm tra chất lượng sản phẩm theo quy trình. | S21: Chi nhánh Công ty | T21: Xác định thời hạn | U21: 36 | V21: 46027 | W21: 46027 | X21: =IF($A21="","",IF($T21="Xác định thời hạn",IF(AND($W21<>"",$U21<>""),EDATE($W21,$U21)-1,""),"")) -> 47122 | Y21: 30 | Z21: 45997 | AA21: 11000000 | AC21: 730000 | AD21: 150000 | AE21: 300000 | AK21: Dữ liệu mẫu – thay bằng dữ liệu thật
A22: NV0009 | B22: =IF($A22="","",TEXT(ROW()-19,"000")&"/"&IF($V22="",2026,YEAR($V22))&"/HĐLĐ-"&$E$8) -> 003/2026/HĐLĐ-MAU | C22: Ngô Văn Hải | D22: Nam | E22: 34081 | F22: Việt Nam | G22: CCCDxxxxxxxx | H22: 44362 | I22: Cục Cảnh sát QLHC về TTXH | J22: 17 Hoàng Diệu, Q.4, TP.HCM | K22: Đại học | L22: MST000909 | M22: BH93000909 | O22: Người thân – 0903000909 | P22: Lập trình viên | Q22: Phòng Công nghệ thông tin | R22: Phát triển và bảo trì phần mềm nội bộ. | S22: Trụ sở Công ty | T22: Không xác định thời hạn | V22: 46027 | W22: 46027 | X22: =IF($A22="","",IF($T22="Xác định thời hạn",IF(AND($W22<>"",$U22<>""),EDATE($W22,$U22)-1,""),"")) | Y22: 30 | Z22: 45997 | AA22: 22000000 | AC22: 730000 | AD22: 300000 | AK22: Dữ liệu mẫu – thay bằng dữ liệu thật
A23: NV0010 | B23: =IF($A23="","",TEXT(ROW()-19,"000")&"/"&IF($V23="",2026,YEAR($V23))&"/HĐLĐ-"&$E$8) -> 004/2026/HĐLĐ-MAU | C23: Dương Thị Hoa | D23: Nữ | E23: 34669 | F23: Việt Nam | G23: CCCDxxxxxxxx | H23: 44362 | I23: Cục Cảnh sát QLHC về TTXH | J23: 62 Lý Thường Kiệt, Q.10, TP.HCM | K23: Đại học | L23: MST001010 | M23: BH94001010 | O23: Người thân – 0903001010 | P23: Nhân viên Marketing | Q23: Phòng Marketing | R23: Lập kế hoạch và triển khai hoạt động marketing, truyền thông. | S23: Trụ sở Công ty | T23: Xác định thời hạn | U23: 12 | V23: 46027 | W23: 46027 | X23: =IF($A23="","",IF($T23="Xác định thời hạn",IF(AND($W23<>"",$U23<>""),EDATE($W23,$U23)-1,""),"")) -> 46391 | Y23: 30 | Z23: 45997 | AA23: 12000000 | AC23: 730000 | AD23: 300000 | AE23: 400000 | AK23: Dữ liệu mẫu – thay bằng dữ liệu thật
A24: NV0011 | B24: =IF($A24="","",TEXT(ROW()-19,"000")&"/"&IF($V24="",2026,YEAR($V24))&"/HĐLĐ-"&$E$8) -> 005/2026/HĐLĐ-MAU | C24: Đỗ Thành Long | D24: Nam | E24: 33769 | F24: Việt Nam | G24: CCCDxxxxxxxx | H24: 44362 | I24: Cục Cảnh sát QLHC về TTXH | J24: KCN Sóng Thần, Dĩ An, Bình Dương | K24: Trung học phổ thông | L24: MST001111 | M24: BH92001111 | O24: Người thân – 0903001111 | P24: Nhân viên kho | Q24: Phòng Kho vận | R24: Quản lý xuất nhập tồn kho, sắp xếp hàng hóa. | S24: Chi nhánh Công ty | T24: Xác định thời hạn | U24: 12 | V24: 46027 | W24: 46027 | X24: =IF($A24="","",IF($T24="Xác định thời hạn",IF(AND($W24<>"",$U24<>""),EDATE($W24,$U24)-1,""),"")) -> 46391 | Y24: 30 | Z24: 45997 | AA24: 8000000 | AC24: 730000 | AD24: 150000 | AE24: 300000 | AI24: Vùng II | AK24: Dữ liệu mẫu – thay bằng dữ liệu thật
A25: NV0012 | B25: =IF($A25="","",TEXT(ROW()-19,"000")&"/"&IF($V25="",2026,YEAR($V25))&"/HĐLĐ-"&$E$8) -> 006/2026/HĐLĐ-MAU | C25: Lý Thị Kim | D25: Nữ | E25: 36227 | F25: Việt Nam | G25: CCCDxxxxxxxx | H25: 44362 | I25: Cục Cảnh sát QLHC về TTXH | J25: 28 Nguyễn Thị Minh Khai, Q.1, TP.HCM | K25: Cao đẳng | L25: MST001212 | M25: BH99001212 | O25: Người thân – 0903001212 | P25: Nhân viên CSKH | Q25: Phòng Chăm sóc khách hàng | R25: Tiếp nhận, xử lý yêu cầu và chăm sóc khách hàng. | S25: Trụ sở Công ty | T25: Xác định thời hạn | U25: 12 | V25: 46027 | W25: 46027 | X25: =IF($A25="","",IF($T25="Xác định thời hạn",IF(AND($W25<>"",$U25<>""),EDATE($W25,$U25)-1,""),"")) -> 46391 | Y25: 30 | Z25: 45997 | AA25: 9500000 | AC25: 730000 | AD25: 200000 | AK25: Dữ liệu mẫu – thay bằng dữ liệu thật
A26: NV0013 | B26: =IF($A26="","",TEXT(ROW()-19,"000")&"/"&IF($V26="",2026,YEAR($V26))&"/HĐLĐ-"&$E$8) -> 007/2026/HĐLĐ-MAU | C26: Phan Văn Minh | D26: Nam | E26: 32070 | F26: Việt Nam | G26: CCCDxxxxxxxx | H26: 44362 | I26: Cục Cảnh sát QLHC về TTXH | J26: 150 Âu Cơ, Q.Tân Phú, TP.HCM | K26: Trung cấp | L26: MST001313 | M26: BH87001313 | O26: Người thân – 0903001313 | P26: Quản đốc phân xưởng | Q26: Phòng Sản xuất | R26: Điều hành sản xuất tại phân xưởng, quản lý nhân sự ca. | S26: Chi nhánh Công ty | T26: Không xác định thời hạn | V26: 46027 | W26: 46027 | X26: =IF($A26="","",IF($T26="Xác định thời hạn",IF(AND($W26<>"",$U26<>""),EDATE($W26,$U26)-1,""),"")) | Y26: 30 | Z26: 45997 | AA26: 16000000 | AB26: 2500000 | AC26: 730000 | AD26: 200000 | AE26: 400000 | AK26: Dữ liệu mẫu – thay bằng dữ liệu thật
A27: NV0014 | B27: =IF($A27="","",TEXT(ROW()-19,"000")&"/"&IF($V27="",2026,YEAR($V27))&"/HĐLĐ-"&$E$8) -> 008/2026/HĐLĐ-MAU | C27: Trịnh Thị Nga | D27: Nữ | E27: 33430 | F27: Việt Nam | G27: CCCDxxxxxxxx | H27: 44362 | I27: Cục Cảnh sát QLHC về TTXH | J27: 9 Nam Kỳ Khởi Nghĩa, Q.1, TP.HCM | K27: Đại học | L27: MST001414 | M27: BH91001414 | O27: Người thân – 0903001414 | P27: Chuyên viên pháp chế | Q27: Phòng Pháp chế | R27: Rà soát hợp đồng, tư vấn tuân thủ pháp luật doanh nghiệp. | S27: Trụ sở Công ty | T27: Không xác định thời hạn | V27: 46027 | W27: 46027 | X27: =IF($A27="","",IF($T27="Xác định thời hạn",IF(AND($W27<>"",$U27<>""),EDATE($W27,$U27)-1,""),"")) | Y27: 30 | Z27: 45997 | AA27: 17000000 | AB27: 1500000 | AC27: 730000 | AD27: 300000 | AK27: Dữ liệu mẫu – thay bằng dữ liệu thật
A28: NV0015 | B28: =IF($A28="","",TEXT(ROW()-19,"000")&"/"&IF($V28="",2026,YEAR($V28))&"/HĐLĐ-"&$E$8) -> 009/2026/HĐLĐ-MAU | C28: Võ Hoàng Nam | D28: Nam | E28: 35031 | F28: Việt Nam | G28: CCCDxxxxxxxx | H28: 44362 | I28: Cục Cảnh sát QLHC về TTXH | J28: 41 Ba Tháng Hai, Q.11, TP.HCM | K28: Cao đẳng | L28: MST001515 | M28: BH95001515 | O28: Người thân – 0903001515 | P28: Nhân viên IT support | Q28: Phòng Công nghệ thông tin | R28: Hỗ trợ kỹ thuật, quản trị hệ thống và thiết bị. | S28: Trụ sở Công ty | T28: Xác định thời hạn | U28: 24 | V28: 46027 | W28: 46027 | X28: =IF($A28="","",IF($T28="Xác định thời hạn",IF(AND($W28<>"",$U28<>""),EDATE($W28,$U28)-1,""),"")) -> 46756 | Y28: 30 | Z28: 45997 | AA28: 11000000 | AC28: 730000 | AD28: 300000 | AK28: Dữ liệu mẫu – thay bằng dữ liệu thật
A29: NV0016 | B29: =IF($A29="","",TEXT(ROW()-19,"000")&"/"&IF($V29="",2026,YEAR($V29))&"/HĐLĐ-"&$E$8) -> 010/2026/HĐLĐ-MAU | C29: Đinh Thị Oanh | D29: Nữ | E29: 32545 | F29: Việt Nam | G29: CCCDxxxxxxxx | H29: 44362 | I29: Cục Cảnh sát QLHC về TTXH | J29: 73 Trần Hưng Đạo, Q.5, TP.HCM | K29: Đại học | L29: MST001616 | M29: BH89001616 | O29: Người thân – 0903001616 | P29: Thủ quỹ | Q29: Phòng Tài chính – Kế toán | R29: Quản lý thu chi tiền mặt, đối chiếu quỹ. | S29: Trụ sở Công ty | T29: Không xác định thời hạn | V29: 46027 | W29: 46027 | X29: =IF($A29="","",IF($T29="Xác định thời hạn",IF(AND($W29<>"",$U29<>""),EDATE($W29,$U29)-1,""),"")) | Y29: 30 | Z29: 45997 | AA29: 12000000 | AB29: 1000000 | AC29: 730000 | AD29: 200000 | AK29: Dữ liệu mẫu – thay bằng dữ liệu thật
A30: NV0017 | B30: =IF($A30="","",TEXT(ROW()-19,"000")&"/"&IF($V30="",2026,YEAR($V30))&"/HĐLĐ-"&$E$8) -> 011/2026/HĐLĐ-MAU | C30: Tạ Văn Phú | D30: Nam | E30: 33104 | F30: Việt Nam | G30: CCCDxxxxxxxx | H30: 44362 | I30: Cục Cảnh sát QLHC về TTXH | J30: KDC Vĩnh Phú, Thuận An, Bình Dương | K30: Trung học phổ thông | L30: MST001717 | M30: BH90001717 | O30: Người thân – 0903001717 | P30: Tài xế | Q30: Phòng Hành chính – Nhân sự | R30: Lái xe đưa đón, vận chuyển theo điều động. | S30: Chi nhánh Công ty | T30: Xác định thời hạn | U30: 12 | V30: 46027 | W30: 46027 | X30: =IF($A30="","",IF($T30="Xác định thời hạn",IF(AND($W30<>"",$U30<>""),EDATE($W30,$U30)-1,""),"")) -> 46391 | Y30: 30 | Z30: 45997 | AA30: 8500000 | AC30: 730000 | AE30: 600000 | AI30: Vùng II | AK30: Dữ liệu mẫu – thay bằng dữ liệu thật
A31: NV0018 | B31: =IF($A31="","",TEXT(ROW()-19,"000")&"/"&IF($V31="",2026,YEAR($V31))&"/HĐLĐ-"&$E$8) -> 012/2026/HĐLĐ-MAU | C31: Chu Thị Quỳnh | D31: Nữ | E31: 36618 | F31: Việt Nam | G31: CCCDxxxxxxxx | H31: 44362 | I31: Cục Cảnh sát QLHC về TTXH | J31: 19 Sư Vạn Hạnh, Q.10, TP.HCM | K31: Cao đẳng | L31: MST001818 | M31: BH00001818 | O31: Người thân – 0903001818 | P31: Lễ tân | Q31: Phòng Hành chính – Nhân sự | R31: Tiếp đón khách, trực tổng đài và hỗ trợ hành chính. | S31: Trụ sở Công ty | T31: Xác định thời hạn | U31: 12 | V31: 46027 | W31: 46027 | X31: =IF($A31="","",IF($T31="Xác định thời hạn",IF(AND($W31<>"",$U31<>""),EDATE($W31,$U31)-1,""),"")) -> 46391 | Y31: 30 | Z31: 45997 | AA31: 8000000 | AC31: 730000 | AD31: 150000 | AK31: Dữ liệu mẫu – thay bằng dữ liệu thật
A32: NV0019 | B32: =IF($A32="","",TEXT(ROW()-19,"000")&"/"&IF($V32="",2026,YEAR($V32))&"/HĐLĐ-"&$E$8) -> 013/2026/HĐLĐ-MAU | C32: Mai Văn Sơn | D32: Nam | E32: 32502 | F32: Việt Nam | G32: CCCDxxxxxxxx | H32: 44362 | I32: Cục Cảnh sát QLHC về TTXH | J32: 6 Kha Vạn Cân, TP.Thủ Đức, TP.HCM | K32: Trung cấp | L32: MST001919 | M32: BH88001919 | O32: Người thân – 0903001919 | P32: Kỹ thuật viên bảo trì | Q32: Phòng Kỹ thuật | R32: Bảo trì, sửa chữa máy móc thiết bị. | S32: Chi nhánh Công ty | T32: Xác định thời hạn | U32: 24 | V32: 46027 | W32: 46027 | X32: =IF($A32="","",IF($T32="Xác định thời hạn",IF(AND($W32<>"",$U32<>""),EDATE($W32,$U32)-1,""),"")) -> 46756 | Y32: 30 | Z32: 45997 | AA32: 12000000 | AC32: 730000 | AD32: 200000 | AE32: 400000 | AK32: Dữ liệu mẫu – thay bằng dữ liệu thật
A33: NV0020 | B33: =IF($A33="","",TEXT(ROW()-19,"000")&"/"&IF($V33="",2026,YEAR($V33))&"/HĐLĐ-"&$E$8) -> 014/2026/HĐLĐ-MAU | C33: Hồ Thị Tâm | D33: Nữ | E33: 34229 | F33: Việt Nam | G33: CCCDxxxxxxxx | H33: 44362 | I33: Cục Cảnh sát QLHC về TTXH | J33: 88 Xô Viết Nghệ Tĩnh, Q.Bình Thạnh, TP.HCM | K33: Đại học | L33: MST002020 | M33: BH93002020 | O33: Người thân – 0903002020 | P33: Nhân viên mua hàng | Q33: Phòng Mua hàng | R33: Tìm nguồn, đàm phán và quản lý đơn mua hàng. | S33: Trụ sở Công ty | T33: Không xác định thời hạn | V33: 46027 | W33: 46027 | X33: =IF($A33="","",IF($T33="Xác định thời hạn",IF(AND($W33<>"",$U33<>""),EDATE($W33,$U33)-1,""),"")) | Y33: 30 | Z33: 45997 | AA33: 13000000 | AB33: 1000000 | AC33: 730000 | AD33: 200000 | AK33: Dữ liệu mẫu – thay bằng dữ liệu thật
A34: NV0021 | B34: =IF($A34="","",TEXT(ROW()-19,"000")&"/"&IF($V34="",2026,YEAR($V34))&"/HĐLĐ-"&$E$8) -> 015/2026/HĐLĐ-MAU | X34: =IF($A34="","",IF($T34="Xác định thời hạn",IF(AND($W34<>"",$U34<>""),EDATE($W34,$U34)-1,""),""))
A35: NV0022 | B35: =IF($A35="","",TEXT(ROW()-19,"000")&"/"&IF($V35="",2026,YEAR($V35))&"/HĐLĐ-"&$E$8) -> 016/2026/HĐLĐ-MAU | X35: =IF($A35="","",IF($T35="Xác định thời hạn",IF(AND($W35<>"",$U35<>""),EDATE($W35,$U35)-1,""),""))
A36: NV0023 | B36: =IF($A36="","",TEXT(ROW()-19,"000")&"/"&IF($V36="",2026,YEAR($V36))&"/HĐLĐ-"&$E$8) -> 017/2026/HĐLĐ-MAU | X36: =IF($A36="","",IF($T36="Xác định thời hạn",IF(AND($W36<>"",$U36<>""),EDATE($W36,$U36)-1,""),""))
A37: NV0024 | B37: =IF($A37="","",TEXT(ROW()-19,"000")&"/"&IF($V37="",2026,YEAR($V37))&"/HĐLĐ-"&$E$8) -> 018/2026/HĐLĐ-MAU | X37: =IF($A37="","",IF($T37="Xác định thời hạn",IF(AND($W37<>"",$U37<>""),EDATE($W37,$U37)-1,""),""))
A38: NV0025 | B38: =IF($A38="","",TEXT(ROW()-19,"000")&"/"&IF($V38="",2026,YEAR($V38))&"/HĐLĐ-"&$E$8) -> 019/2026/HĐLĐ-MAU | X38: =IF($A38="","",IF($T38="Xác định thời hạn",IF(AND($W38<>"",$U38<>""),EDATE($W38,$U38)-1,""),""))
A39: NV0026 | B39: =IF($A39="","",TEXT(ROW()-19,"000")&"/"&IF($V39="",2026,YEAR($V39))&"/HĐLĐ-"&$E$8) -> 020/2026/HĐLĐ-MAU | X39: =IF($A39="","",IF($T39="Xác định thời hạn",IF(AND($W39<>"",$U39<>""),EDATE($W39,$U39)-1,""),""))
A40: NV0027 | B40: =IF($A40="","",TEXT(ROW()-19,"000")&"/"&IF($V40="",2026,YEAR($V40))&"/HĐLĐ-"&$E$8) -> 021/2026/HĐLĐ-MAU | X40: =IF($A40="","",IF($T40="Xác định thời hạn",IF(AND($W40<>"",$U40<>""),EDATE($W40,$U40)-1,""),""))
A41: NV0028 | B41: =IF($A41="","",TEXT(ROW()-19,"000")&"/"&IF($V41="",2026,YEAR($V41))&"/HĐLĐ-"&$E$8) -> 022/2026/HĐLĐ-MAU | X41: =IF($A41="","",IF($T41="Xác định thời hạn",IF(AND($W41<>"",$U41<>""),EDATE($W41,$U41)-1,""),""))
A42: NV0029 | B42: =IF($A42="","",TEXT(ROW()-19,"000")&"/"&IF($V42="",2026,YEAR($V42))&"/HĐLĐ-"&$E$8) -> 023/2026/HĐLĐ-MAU | X42: =IF($A42="","",IF($T42="Xác định thời hạn",IF(AND($W42<>"",$U42<>""),EDATE($W42,$U42)-1,""),""))
A43: NV0030 | B43: =IF($A43="","",TEXT(ROW()-19,"000")&"/"&IF($V43="",2026,YEAR($V43))&"/HĐLĐ-"&$E$8) -> 024/2026/HĐLĐ-MAU | X43: =IF($A43="","",IF($T43="Xác định thời hạn",IF(AND($W43<>"",$U43<>""),EDATE($W43,$U43)-1,""),""))
...

Sheet DANH_MUC
A1: DANH MỤC LỰA CHỌN VÀ THAM SỐ
A4: Loại hợp đồng | C4: Hình thức làm việc | E4: Hình thức trả lương | G4: Có/Không | I4: Ngày nghỉ hằng tuần | K4: Giới tính | M4: Xưng hô | O4: Trình độ chuyên môn | Q4: Địa điểm làm việc | S4: Nơi cấp CCCD | U4: Quốc tịch
A5: Không xác định thời hạn | C5: Tại văn phòng/nhà máy | E5: Chuyển khoản | G5: Có | I5: Thứ Bảy và Chủ nhật | K5: Nam | M5: Ông | O5: Trên đại học | Q5: Trụ sở Công ty | S5: Cục Cảnh sát QLHC về TTXH | U5: Việt Nam
A6: Xác định thời hạn | C6: Từ xa/kết hợp | E6: Tiền mặt | G6: Không | I6: Chủ nhật | K6: Nữ | M6: Bà | O6: Đại học | Q6: Chi nhánh Công ty | S6: Cục Cảnh sát ĐKQL cư trú và DLQG về dân cư
I7: Theo lịch phân ca | K7: Khác | O7: Cao đẳng | Q7: Văn phòng đại diện | S7: Cục Quản lý xuất nhập cảnh
O8: Trung cấp | Q8: Làm việc từ xa
O9: Trung học phổ thông | Q9: Nhiều địa điểm theo phân công
A10: LƯƠNG TỐI THIỂU VÙNG TỪ 01/01/2026 | O10: Sơ cấp/Chứng chỉ nghề
A11: Vùng | B11: Lương tối thiểu tháng | C11: Lương tối thiểu giờ | D11: Tăng so với 2025 | O11: Lao động phổ thông
A12: Vùng I | B12: 5310000 | C12: 25500 | D12: 350000
A13: Vùng II | B13: 4730000 | C13: 22700 | D13: 320000
A14: Vùng III | B14: 4140000 | C14: 20000 | D14: 280000
A15: Vùng IV | B15: 3700000 | C15: 17800 | D15: 250000

Sheet CONG_TY
A1: DỮ LIỆU KỸ THUẬT — KHÔNG CẦN NHẬP TẠI ĐÂY
A3: Toàn bộ dữ liệu sử dụng đã được gộp tại sheet NHAP_LIEU. Sheet này chỉ giữ cấu trúc cũ để tham chiếu.
A4: Trường thông tin | B4: Giá trị | C4: Hướng dẫn | D4: Phạm vi
A5: Tên doanh nghiệp | B5: CÔNG TY TNHH MẪU (THAY THẾ) | C5: Dùng tại Bên A và phần ký | D5: Thông tin cố định
A6: Mã số doanh nghiệp/Mã số thuế | B6: MST-MAU-0001 | C6: Dữ liệu mẫu; thay bằng mã thật và giữ dạng văn bản | D6: Thông tin cố định
A7: Địa chỉ trụ sở chính | B7: [NHẬP ĐỊA CHỈ TRỤ SỞ] | D7: Thông tin cố định
A8: Điện thoại | B8: 0900 000 000 | D8: Thông tin cố định
A9: Email | B9: hr@congtymau.vn | D9: Thông tin cố định
A10: Người đại diện | B10: Nguyễn Văn C | C10: Người ký phía doanh nghiệp | D10: Thông tin cố định
A11: Tư cách đại diện | B11: Người đại diện theo pháp luật | C11: Hoặc Người được ủy quyền | D11: Thông tin cố định
A12: Chức danh người đại diện | B12: Giám đốc | D12: Thông tin cố định
A13: Quốc tịch người đại diện | B13: Việt Nam | D13: Thông tin cố định
A14: Số văn bản ủy quyền | C14: Để trống nếu không áp dụng | D14: Thông tin cố định
A15: Ngày văn bản ủy quyền | C15: Để trống nếu không áp dụng | D15: Thông tin cố định
A16: Địa điểm ký mặc định | B16: Thành phố Hồ Chí Minh | C16: Có thể ghi đè theo từng lao động | D16: Giá trị mặc định
A17: Tên viết tắt công ty | B17: MAU | C17: Dùng đặt số hợp đồng | D17: Thông tin cố định
A18: Ngày trả lương mặc định | B18: 5 | C18: Ngày trong tháng | D18: Giá trị mặc định
A19: Số lần xét nâng lương/năm | B19: 1 | D19: Giá trị mặc định
A20: Số giờ làm việc/ngày | B20: 8 | D20: Giá trị mặc định
A21: Số giờ làm việc/tuần | B21: 40 | D21: Giá trị mặc định
A22: Giờ bắt đầu | B22: 08:00 | C22: Nhập dạng 08:00 | D22: Thông tin cố định
A23: Giờ kết thúc | B23: 17:00 | C23: Nhập dạng 17:00 | D23: Thông tin cố định
A24: Nghỉ giữa giờ (phút) | B24: 60 | D24: Giá trị mặc định
A25: Ngày nghỉ hằng tuần | B25: Thứ Bảy và Chủ nhật | D25: Thông tin cố định
A26: Hình thức làm việc | B26: Tại văn phòng/nhà máy | D26: Thông tin cố định
A27: Hình thức trả lương | B27: Chuyển khoản | D27: Giá trị mặc định
A28: Làm việc nhiều địa điểm | B28: Không | D28: Thông tin cố định
A29: Vùng lương | B29: Vùng I | D29: Giá trị mặc định
A30: Trang bị bảo hộ mặc định | B30: Theo tính chất công việc và quy định của Công ty | D30: Giá trị mặc định
A31: Thời hạn bảo mật (năm) | B31: 2 | C31: Khuyến nghị trong mẫu: 1–3 năm tùy vị trí | D31: Giá trị mặc định
A32: Thời hạn hoàn trả chi phí đào tạo (ngày) | B32: 30 | D32: Giá trị mặc định

Sheet NHAN_SU
A1: DỮ LIỆU KỸ THUẬT — KHÔNG CẦN NHẬP TẠI ĐÂY
A2: Nhập và quản lý người lao động tại sheet NHAP_LIEU. Sheet này chỉ giữ cấu trúc cũ để tham chiếu.
A4: THÔNG TIN CÁ NHÂN | P4: CÔNG VIỆC | V4: HỢP ĐỒNG & THỬ VIỆC | AD4: TIỀN LƯƠNG & PHỤ CẤP | AR4: TRẢ LƯƠNG & THỜI GIAN | BA4: THÔNG TIN KÝ HỢP ĐỒNG | BG4: BẢO MẬT & ĐÀO TẠO | BO4: GHI CHÚ
A5: Mã nhân viên | B5: Họ và tên | C5: Xưng hô | D5: Giới tính | E5: Ngày sinh | F5: Quốc tịch | G5: Số CCCD/Hộ chiếu | H5: Ngày cấp | I5: Nơi cấp | J5: Nơi cư trú | K5: Trình độ chuyên môn | L5: Mã số thuế TNCN | M5: Mã số BHXH | N5: Số GPLĐ/xác nhận | O5: Liên hệ khẩn cấp | P5: Chức danh/vị trí | Q5: Bộ phận/phòng ban | R5: Mô tả công việc | S5: Địa điểm làm việc | T5: Làm nhiều địa điểm | U5: Hình thức làm việc | V5: Loại hợp đồng | W5: Thời hạn (tháng) | X5: Ngày bắt đầu | Y5: Ngày kết thúc | Z5: Số ngày thử việc | AA5: Thử việc từ ngày | AB5: Thử việc đến ngày | AC5: Tỷ lệ lương thử việc (%) | AD5: Lương chính | AE5: Phụ cấp trách nhiệm | AF5: Điều kiện PC trách nhiệm | AG5: Tiền ăn giữa ca | AH5: Điều kiện ăn giữa ca | AI5: Hỗ trợ điện thoại | AJ5: Điều kiện điện thoại | AK5: Hỗ trợ xăng xe | AL5: Điều kiện xăng xe | AM5: Hỗ trợ nhà ở | AN5: Điều kiện nhà ở | AO5: Khoản bổ sung khác | AP5: Mức khoản bổ sung khác | AQ5: Điều kiện khoản khác | AR5: Hình thức trả lương | AS5: Ngày trả lương | AT5: Số lần xét nâng lương/năm | AU5: Giờ/ngày | AV5: Giờ/tuần | AW5: Giờ bắt đầu | AX5: Giờ kết thúc | AY5: Nghỉ giữa giờ (phút) | AZ5: Ngày nghỉ hằng tuần | BA5: Trang bị bảo hộ | BB5: Vùng lương | BC5: Số hợp đồng | BD5: Ngày ký hợp đồng | BE5: Địa điểm ký | BF5: Ngày hiệu lực | BG5: Thông tin mật bổ sung | BH5: Thời hạn bảo mật (năm) | BI5: Khóa đào tạo/nghề đào tạo | BJ5: Địa điểm/thời gian đào tạo | BK5: Chi phí đào tạo | BL5: Cam kết làm việc (tháng) | BM5: Thời hạn hoàn trả (ngày) | BN5: Áp dụng đào tạo | BO5: Ghi chú
A6: NV001 | B6: Nguyễn Văn A (dữ liệu mẫu) | C6: Ông | D6: Nam | E6: 34714 | F6: Việt Nam | G6: CCCD-MAU-001 | H6: 44306 | I6: Cục CSQLHC về TTXH | J6: [NHẬP NƠI CƯ TRÚ] | K6: Cử nhân Kế toán | L6: MST-CN-MAU-001 | M6: BHXH-MAU-001 | O6: Nguyễn Văn D – Anh – 0900 000 001 | P6: Kế toán viên | Q6: Phòng Tài chính – Kế toán | R6: Thực hiện nghiệp vụ kế toán theo phân công và bản mô tả công việc đính kèm. | S6: Trụ sở Công ty | V6: Không xác định thời hạn | X6: 46235 | Z6: 30 | AA6: 46204 | AB6: 46233 | AC6: 85 | AD6: 12000000 | AE6: 1000000 | AF6: Theo chức danh và thời gian làm việc thực tế | AG6: 730000 | AH6: Theo ngày làm việc thực tế | AI6: 300000 | AJ6: Theo quy chế Công ty | AK6: 500000 | AL6: Theo quy chế Công ty | BC6: 001/2026/HĐLĐ-MAU | BD6: 46235 | BF6: 46235 | BG6: Danh sách khách hàng và dữ liệu tài chính nội bộ | BI6: Khóa nghiệp vụ kế toán nâng cao | BJ6: TP.HCM, từ 10/08/2026 đến 15/08/2026 | BK6: 15000000 | BL6: 18 | BN6: Có | BO6: Dữ liệu mẫu – thay thế trước khi dùng
A7: NV002 | B7: Trần Thị B (dữ liệu mẫu) | C7: Bà | D7: Nữ | E7: 35966 | F7: Việt Nam | G7: CCCD-MAU-002 | H7: 44691 | I7: Cục CSQLHC về TTXH | J7: [NHẬP NƠI CƯ TRÚ] | K7: Cao đẳng | L7: MST-CN-MAU-002 | M7: BHXH-MAU-002 | O7: Trần Văn E – Cha – 0900 000 002 | P7: Nhân viên hành chính | Q7: Phòng Hành chính – Nhân sự | R7: Thực hiện công việc hành chính, hồ sơ nhân sự và nhiệm vụ được phân công. | S7: Chi nhánh Công ty | T7: Có | U7: Tại văn phòng/nhà máy | V7: Xác định thời hạn | W7: 12 | X7: 46235 | Y7: 46599 | Z7: 30 | AA7: 46204 | AB7: 46233 | AC7: 85 | AD7: 8500000 | AG7: 730000 | AH7: Theo ngày làm việc thực tế | AI7: 200000 | AJ7: Theo quy chế Công ty | AK7: 400000 | AL7: Theo quy chế Công ty | AR7: Chuyển khoản | AS7: 5 | AT7: 1 | AU7: 8 | AV7: 48 | AW7: 08:00 | AX7: 17:00 | AY7: 60 | AZ7: Chủ nhật | BA7: Theo yêu cầu công việc | BB7: Vùng II | BC7: 002/2026/HĐLĐ-MAU | BD7: 46235 | BE7: Thành phố Hồ Chí Minh | BF7: 46235 | BG7: Dữ liệu nhân sự và chính sách tiền lương | BH7: 2 | BN7: Không | BO7: Dữ liệu mẫu – thay thế trước khi dùng

Sheet PHU_LUC_DATA
A1: DỮ LIỆU KỸ THUẬT — KHÔNG CẦN NHẬP TẠI ĐÂY
A2: Nhập phụ lục tại phần 4 của sheet NHAP_LIEU. Sheet này chỉ giữ cấu trúc cũ để tham chiếu.
A5: Mã phụ lục | B5: Mã nhân viên | C5: Số phụ lục | D5: Ngày ký phụ lục | E5: Địa điểm ký | F5: Ngày hiệu lực | G5: Điều khoản 1 | H5: Nội dung cũ 1 | I5: Nội dung mới 1 | J5: Điều khoản 2 | K5: Nội dung cũ 2 | L5: Nội dung mới 2 | M5: Điều khoản 3 | N5: Nội dung cũ 3 | O5: Nội dung mới 3 | P5: Ghi chú
A6: PL001 | B6: NV001 | C6: 001/2026/PLHĐLĐ-MAU | D6: 46296 | E6: Thành phố Hồ Chí Minh | F6: 46296 | G6: Điều 3.1 | H6: Mức lương 12.000.000 đồng/tháng | I6: Mức lương 13.000.000 đồng/tháng | J6: Điều 3.2 | K6: Phụ cấp trách nhiệm 1.000.000 đồng/tháng | L6: Phụ cấp trách nhiệm 1.500.000 đồng/tháng | P6: Dữ liệu mẫu – thay thế trước khi dùng
A7: PL002 | B7: NV002 | C7: 002/2026/PLHĐLĐ-MAU | D7: 46327 | E7: Thành phố Hồ Chí Minh | F7: 46327 | G7: Điều 1.4 | H7: Địa điểm làm việc tại Chi nhánh Công ty | I7: Địa điểm làm việc tại Trụ sở Công ty | P7: Dữ liệu mẫu – thay thế trước khi dùng

Sheet DIEU_KHIEN
A1: BẢNG ĐIỀU KHIỂN
A3: Số nhân viên đã nhập: | B3: =COUNTA(NHAP_LIEU!$A$14:$A$513) -> 171
A4: Số phụ lục đã nhập: | B4: =COUNTA(NHAP_LIEU!$A$1026:$A$1525) -> 2
A5: Số thỏa thuận đào tạo: | B5: =COUNTIF(NHAP_LIEU!$B$520:$B$1019,"Có") -> 1
A7: CÁCH IN NHANH
A8: 1. Nhập/soát dữ liệu nhân viên tại sheet NHAP_LIEU.
A9: 2. Mở biểu mẫu cần in: HOP_DONG, PHU_LUC hoặc BAO_MAT_DT.
A10: 3. Chọn mã ở Ô VÀNG (góc trên, có nhãn “CHỌN … ĐỂ IN”).
A11: 4. Kiểm tra tên hiện ra bên dưới ô chọn cho đúng người.
A12: 5. Ctrl + P → khổ A4, dọc → In. (Ô chọn không in ra giấy.)
A14: KK HOME · Kiểm toán · Kế toán · Tư vấn Thuế

Sheet HUONG_DAN
A1: HƯỚNG DẪN SỬ DỤNG FILE HỢP ĐỒNG LAO ĐỘNG
A3: Toàn bộ dữ liệu sử dụng được nhập tại một sheet NHAP_LIEU; các biểu mẫu tự điền theo mã được chọn. File không dùng macro và tương thích Excel 2016 trở lên.
A6: BƯỚC 1 — NHẬP THÔNG TIN CÔNG TY
A7: Mở NHAP_LIEU và thay dữ liệu mẫu tại phần 1. Chỉ nhập một lần cho toàn bộ lao động.
A9: BƯỚC 2 — THÊM NGƯỜI LAO ĐỘNG
A10: Tại phần 2 của NHAP_LIEU, mỗi người một dòng. Các điều kiện lặp lại tự lấy từ phần thông tin công ty.
A12: BƯỚC 3 — DỮ LIỆU TÙY CHỌN
A13: Chỉ nhập phần 3 nếu có thỏa thuận đào tạo và phần 4 nếu có phụ lục hợp đồng.
A15: BƯỚC 4 — CHỌN VÀ KIỂM TRA
A16: Không cần chọn mã tại NHAP_LIEU nữa. Mở biểu mẫu cần in (Hợp đồng, Phụ lục, Bảo mật – Đào tạo) rồi chọn nhân viên/phụ lục ngay ở Ô VÀNG góc trên của biểu mẫu.
A18: BƯỚC 5 — IN BIỂU MẪU
A19: Mở sheet cần in. Chọn giấy A4, hướng dọc và Fit All Columns on One Page. Không chọn chế độ Fit Sheet on One Page vì chữ sẽ bị thu quá nhỏ.
A22: Ô MÀU VÀNG Nhập hoặc lựa chọn dữ liệu | E22: Ô MÀU XANH Kết quả tự động — không nhập đè
A26: LƯU Ý RÀ SOÁT • Nội dung pháp lý được giữ theo file Word nguồn, cập nhật đến tháng 7/2026; file Excel không tự cập nhật khi pháp luật thay đổi. • Tại mục 2.3 của Word nguồn có dẫn chiếu “mức lương ... theo Điều 4”, trong khi nội dung tiền lương nằm tại Điều 3. File giữ nguyên văn bản nguồn; doanh nghiệp nên rà soát dẫn chiếu này trước khi ký. • Đây là biểu mẫu tham khảo, không thay thế tư vấn cho từng trường hợp cụ thể.

Sheet HOP_DONG
B1: CỘNG HÒA XÃ HỘI CHỦ NGHĨA VIỆT NAM | I1: CHỌN NHÂN VIÊN ĐỂ IN ▼
B2: Độc lập – Tự do – Hạnh phúc | I2: NV001
B3: ————————————— | I3: =IFERROR(INDEX(NHAP_LIEU!$C$14:$C$513,MATCH($I$2,NHAP_LIEU!$A$14:$A$513,0)),"—") -> —
B4: PHẦN I — HỢP ĐỒNG LAO ĐỘNG | I4: Đổi mã ở ô vàng để in người khác. Khối này KHÔNG in ra giấy — chỉ để chọn.
B5: ="Số: "&IFERROR(IF(INDEX(NHAP_LIEU!$B$14:$B$513,MATCH($I$2,NHAP_LIEU!$A$14:$A$513,0))="","",INDEX(NHAP_LIEU!$B$14:$B$513,MATCH($I$2,NHAP_LIEU!$A$14:$A$513,0))),"") -> Số:
B6: Căn cứ:
B7: – Bộ luật Lao động số 45/2019/QH14 ngày 20/11/2019 (hiệu lực từ 01/01/2021);
B8: – Nghị định số 145/2020/NĐ-CP ngày 14/12/2020 của Chính phủ quy định chi tiết và hướng dẫn thi hành một số điều của Bộ luật Lao động về điều kiện lao động và quan hệ lao động (đã được sửa đổi, bổ sung bởi Nghị định số 70/2023/NĐ-CP);
B9: – Thông tư số 10/2020/TT-BLĐTBXH ngày 12/11/2020 hướng dẫn nội dung của hợp đồng lao động;
B10: – Luật Bảo hiểm xã hội số 41/2024/QH15 ngày 29/6/2024 (hiệu lực từ 01/7/2025) và các văn bản hướng dẫn;
B11: – Luật Việc làm số 74/2025/QH15 ngày 16/6/2025 (hiệu lực từ 01/01/2026) về bảo hiểm thất nghiệp;
B12: – Luật Bảo hiểm y tế và các văn bản hướng dẫn thi hành;
B13: – Nghị định số 293/2025/NĐ-CP quy định mức lương tối thiểu vùng (hiệu lực từ 01/01/2026);
B14: – Luật Thuế thu nhập cá nhân số 109/2025/QH15 và Nghị quyết số 110/2025/UBTVQH15 về mức giảm trừ gia cảnh (áp dụng từ kỳ tính thuế 2026);
B15: – Nội quy lao động, Thỏa ước lao động tập thể của Công ty (nếu có); nhu cầu và sự thỏa thuận tự nguyện của hai bên.
B16: =IF(IFERROR(IF(INDEX(NHAP_LIEU!$V$14:$V$513,MATCH($I$2,NHAP_LIEU!$A$14:$A$513,0))="","",INDEX(NHAP_LIEU!$V$14:$V$513,MATCH($I$2,NHAP_LIEU!$A$14:$A$513,0))),"")="","Hôm nay, ngày …… tháng …… năm ……, tại "&IF(""<>"","",NHAP_LIEU!$E$7)&", chúng tôi gồm:","Hôm nay, ngày "&TEXT(IFERROR(IF(INDEX(NHAP_LIEU!$V$14:$V$513,MATCH($I$2,NHAP_LIEU!$A$14:$A$513,0))="","",INDEX(NHAP_LIEU!$V$14:$V$513,MATCH($I$2,NHAP_LIEU!$A$14:$A$513,0))),""),"dd")&" tháng "&TEXT(IFERROR(IF(INDEX(NHAP_LIEU!$V$14:$V$513,MATCH($I$2,NHAP_LIEU!$A$14:$A$513,0))="","",INDEX(NHAP_LIEU!$V$14:$V$513,MATCH($I$2,NHAP_LIEU!$A$14:$A$513,0))),""),"mm")&" năm "&TEXT(IFERROR(IF(INDEX(NHAP_LIEU!$V$14:$V$513,MATCH($I$2,NHAP_LIEU!$A$14:$A$513,0))="","",INDEX(NHAP_LIEU!$V$14:$V$513,MATCH($I$2,NHAP_LIEU!$A$14:$A$513,0))),""),"yyyy")&", tại "&IF(""<>"","",NHAP_LIEU!$E$7)&", chúng tôi gồm:") -> Hôm nay, ngày …… tháng …… năm ……, tại Đồng Tháp, chúng tôi gồm:
B17: BÊN A — NGƯỜI SỬ DỤNG LAO ĐỘNG:
B18: ="Tên doanh nghiệp: "&NHAP_LIEU!$B$4 -> Tên doanh nghiệp: CÔNG TY TNHH KK HOME
B19: ="Mã số doanh nghiệp/Mã số thuế: "&NHAP_LIEU!$B$5 -> Mã số doanh nghiệp/Mã số thuế: MST-MAU-0001
B20: ="Địa chỉ trụ sở chính: "&NHAP_LIEU!$B$6 -> Địa chỉ trụ sở chính: 526 Lê Đại Hành, Phường Mỹ Trà, Tỉnh Đồng Tháp
B21: ="Điện thoại: "&NHAP_LIEU!$B$7&" Email: "&NHAP_LIEU!$B$8 -> Điện thoại: 090 744 6543 Email: admin@hkdkkhome.com
B22: =NHAP_LIEU!$E$5&"(*): "&NHAP_LIEU!$E$4 -> Người đại diện theo pháp luật(*): HUỲNH NGỌC NGÂN
B23: ="Chức danh: "&NHAP_LIEU!$E$6&" Quốc tịch: "&"Việt Nam" -> Chức danh: Giám đốc Quốc tịch: Việt Nam
B24: =IF(""="","","(Văn bản ủy quyền số "&""&" ngày "&IF(""="","……/……/……",TEXT("","dd/mm/yyyy"))&" — nếu ký theo ủy quyền)")
B25: (*) Người giao kết HĐLĐ bên phía NSDLĐ phải đúng thẩm quyền theo khoản 3 Điều 18 BLLĐ 2019.
B26: BÊN B — NGƯỜI LAO ĐỘNG:
B27: ="Họ và tên: "&IF(IFERROR(IF(INDEX(NHAP_LIEU!$D$14:$D$513,MATCH($I$2,NHAP_LIEU!$A$14:$A$513,0))="","",INDEX(NHAP_LIEU!$D$14:$D$513,MATCH($I$2,NHAP_LIEU!$A$14:$A$513,0))),"")="Nữ","Bà",IF(IFERROR(IF(INDEX(NHAP_LIEU!$D$14:$D$513,MATCH($I$2,NHAP_LIEU!$A$14:$A$513,0))="","",INDEX(NHAP_LIEU!$D$14:$D$513,MATCH($I$2,NHAP_LIEU!$A$14:$A$513,0))),"")="Nam","Ông",""))&" "&IFERROR(IF(INDEX(NHAP_LIEU!$C$14:$C$513,MATCH($I$2,NHAP_LIEU!$A$14:$A$513,0))="","",INDEX(NHAP_LIEU!$C$14:$C$513,MATCH($I$2,NHAP_LIEU!$A$14:$A$513,0))),"")&" Giới tính: "&IFERROR(IF(INDEX(NHAP_LIEU!$D$14:$D$513,MATCH($I$2,NHAP_LIEU!$A$14:$A$513,0))="","",INDEX(NHAP_LIEU!$D$14:$D$513,MATCH($I$2,NHAP_LIEU!$A$14:$A$513,0))),"") -> Họ và tên: Giới tính:
B28: ="Ngày, tháng, năm sinh: "&IF(IFERROR(IF(INDEX(NHAP_LIEU!$E$14:$E$513,MATCH($I$2,NHAP_LIEU!$A$14:$A$513,0))="","",INDEX(NHAP_LIEU!$E$14:$E$513,MATCH($I$2,NHAP_LIEU!$A$14:$A$513,0))),"")="","……/……/……",TEXT(IFERROR(IF(INDEX(NHAP_LIEU!$E$14:$E$513,MATCH($I$2,NHAP_LIEU!$A$14:$A$513,0))="","",INDEX(NHAP_LIEU!$E$14:$E$513,MATCH($I$2,NHAP_LIEU!$A$14:$A$513,0))),""),"dd/mm/yyyy"))&" Quốc tịch: "&IFERROR(IF(INDEX(NHAP_LIEU!$F$14:$F$513,MATCH($I$2,NHAP_LIEU!$A$14:$A$513,0))="","",INDEX(NHAP_LIEU!$F$14:$F$513,MATCH($I$2,NHAP_LIEU!$A$14:$A$513,0))),"") -> Ngày, tháng, năm sinh: ……/……/…… Quốc tịch:
B29: ="Số CCCD/Hộ chiếu: "&IFERROR(IF(INDEX(NHAP_LIEU!$G$14:$G$513,MATCH($I$2,NHAP_LIEU!$A$14:$A$513,0))="","",INDEX(NHAP_LIEU!$G$14:$G$513,MATCH($I$2,NHAP_LIEU!$A$14:$A$513,0))),"")&" Cấp ngày: "&IF(IFERROR(IF(INDEX(NHAP_LIEU!$H$14:$H$513,MATCH($I$2,NHAP_LIEU!$A$14:$A$513,0))="","",INDEX(NHAP_LIEU!$H$14:$H$513,MATCH($I$2,NHAP_LIEU!$A$14:$A$513,0))),"")="","……/……/……",TEXT(IFERROR(IF(INDEX(NHAP_LIEU!$H$14:$H$513,MATCH($I$2,NHAP_LIEU!$A$14:$A$513,0))="","",INDEX(NHAP_LIEU!$H$14:$H$513,MATCH($I$2,NHAP_LIEU!$A$14:$A$513,0))),""),"dd/mm/yyyy"))&" Nơi cấp: "&IFERROR(IF(INDEX(NHAP_LIEU!$I$14:$I$513,MATCH($I$2,NHAP_LIEU!$A$14:$A$513,0))="","",INDEX(NHAP_LIEU!$I$14:$I$513,MATCH($I$2,NHAP_LIEU!$A$14:$A$513,0))),"") -> Số CCCD/Hộ chiếu: Cấp ngày: ……/……/…… Nơi cấp:
B30: ="Nơi cư trú hiện nay: "&IFERROR(IF(INDEX(NHAP_LIEU!$J$14:$J$513,MATCH($I$2,NHAP_LIEU!$A$14:$A$513,0))="","",INDEX(NHAP_LIEU!$J$14:$J$513,MATCH($I$2,NHAP_LIEU!$A$14:$A$513,0))),"") -> Nơi cư trú hiện nay:
B31: ="Trình độ chuyên môn, kỹ thuật: "&IFERROR(IF(INDEX(NHAP_LIEU!$K$14:$K$513,MATCH($I$2,NHAP_LIEU!$A$14:$A$513,0))="","",INDEX(NHAP_LIEU!$K$14:$K$513,MATCH($I$2,NHAP_LIEU!$A$14:$A$513,0))),"") -> Trình độ chuyên môn, kỹ thuật:
B32: ="Mã số thuế TNCN: "&IFERROR(IF(INDEX(NHAP_LIEU!$L$14:$L$513,MATCH($I$2,NHAP_LIEU!$A$14:$A$513,0))="","",INDEX(NHAP_LIEU!$L$14:$L$513,MATCH($I$2,NHAP_LIEU!$A$14:$A$513,0))),"")&" Mã số BHXH: "&IFERROR(IF(INDEX(NHAP_LIEU!$M$14:$M$513,MATCH($I$2,NHAP_LIEU!$A$14:$A$513,0))="","",INDEX(NHAP_LIEU!$M$14:$M$513,MATCH($I$2,NHAP_LIEU!$A$14:$A$513,0))),"") -> Mã số thuế TNCN: Mã số BHXH:
B33: ="Giấy phép lao động/văn bản xác nhận không thuộc diện cấp GPLĐ số (áp dụng với NLĐ nước ngoài): "&IF(IFERROR(IF(INDEX(NHAP_LIEU!$N$14:$N$513,MATCH($I$2,NHAP_LIEU!$A$14:$A$513,0))="","",INDEX(NHAP_LIEU!$N$14:$N$513,MATCH($I$2,NHAP_LIEU!$A$14:$A$513,0))),"")="","Không áp dụng",IFERROR(IF(INDEX(NHAP_LIEU!$N$14:$N$513,MATCH($I$2,NHAP_LIEU!$A$14:$A$513,0))="","",INDEX(NHAP_LIEU!$N$14:$N$513,MATCH($I$2,NHAP_LIEU!$A$14:$A$513,0))),"")) -> Giấy phép lao động/văn bản xác nhận không thuộc diện cấp GPLĐ số (áp dụng với NLĐ nước ngoài): Không áp dụng
B34: ="Thông tin liên hệ khẩn cấp (họ tên, quan hệ, điện thoại): "&IFERROR(IF(INDEX(NHAP_LIEU!$O$14:$O$513,MATCH($I$2,NHAP_LIEU!$A$14:$A$513,0))="","",INDEX(NHAP_LIEU!$O$14:$O$513,MATCH($I$2,NHAP_LIEU!$A$14:$A$513,0))),"") -> Thông tin liên hệ khẩn cấp (họ tên, quan hệ, điện thoại):
B35: Hai bên thỏa thuận ký kết Hợp đồng lao động (sau đây gọi là "Hợp đồng") với các điều khoản sau đây:
B36: Điều 1. Công việc và địa điểm làm việc
B37: ="1.1. Chức danh chuyên môn/vị trí việc làm: "&IFERROR(IF(INDEX(NHAP_LIEU!$P$14:$P$513,MATCH($I$2,NHAP_LIEU!$A$14:$A$513,0))="","",INDEX(NHAP_LIEU!$P$14:$P$513,MATCH($I$2,NHAP_LIEU!$A$14:$A$513,0))),"") -> 1.1. Chức danh chuyên môn/vị trí việc làm:
B38: ="1.2. Bộ phận/phòng ban: "&IFERROR(IF(INDEX(NHAP_LIEU!$Q$14:$Q$513,MATCH($I$2,NHAP_LIEU!$A$14:$A$513,0))="","",INDEX(NHAP_LIEU!$Q$14:$Q$513,MATCH($I$2,NHAP_LIEU!$A$14:$A$513,0))),"") -> 1.2. Bộ phận/phòng ban:
B39: ="1.3. Mô tả công việc chính: "&IFERROR(IF(INDEX(NHAP_LIEU!$R$14:$R$513,MATCH($I$2,NHAP_LIEU!$A$14:$A$513,0))="","",INDEX(NHAP_LIEU!$R$14:$R$513,MATCH($I$2,NHAP_LIEU!$A$14:$A$513,0))),"") -> 1.3. Mô tả công việc chính:
B40: (Chi tiết theo Bản mô tả công việc đính kèm — là bộ phận không tách rời của Hợp đồng, nếu có.)
...

Sheet PHU_LUC
B1: CỘNG HÒA XÃ HỘI CHỦ NGHĨA VIỆT NAM | I1: CHỌN PHỤ LỤC ĐỂ IN ▼
B2: Độc lập – Tự do – Hạnh phúc | I2: PL001
B3: PHẦN II — PHỤ LỤC HỢP ĐỒNG LAO ĐỘNG | I3: =IFERROR("Của NV "&INDEX(NHAP_LIEU!$B$1026:$B$1525,MATCH($I$2,NHAP_LIEU!$A$1026:$A$1525,0)),"—") -> Của NV NV001
B4: ="Số: "&IFERROR(IF(INDEX(NHAP_LIEU!$C$1026:$C$1525,MATCH($I$2,NHAP_LIEU!$A$1026:$A$1525,0))="","",INDEX(NHAP_LIEU!$C$1026:$C$1525,MATCH($I$2,NHAP_LIEU!$A$1026:$A$1525,0))),"")&" (kèm theo HĐLĐ số "&IFERROR(IF(INDEX(NHAP_LIEU!$B$14:$B$513,MATCH(IFERROR(IF(INDEX(NHAP_LIEU!$B$1026:$B$1525,MATCH($I$2,NHAP_LIEU!$A$1026:$A$1525,0))="","",INDEX(NHAP_LIEU!$B$1026:$B$1525,MATCH($I$2,NHAP_LIEU!$A$1026:$A$1525,0))),""),NHAP_LIEU!$A$14:$A$513,0))="","",INDEX(NHAP_LIEU!$B$14:$B$513,MATCH(IFERROR(IF(INDEX(NHAP_LIEU!$B$1026:$B$1525,MATCH($I$2,NHAP_LIEU!$A$1026:$A$1525,0))="","",INDEX(NHAP_LIEU!$B$1026:$B$1525,MATCH($I$2,NHAP_LIEU!$A$1026:$A$1525,0))),""),NHAP_LIEU!$A$14:$A$513,0))),"")&" ngày "&IF(IFERROR(IF(INDEX(NHAP_LIEU!$V$14:$V$513,MATCH(IFERROR(IF(INDEX(NHAP_LIEU!$B$1026:$B$1525,MATCH($I$2,NHAP_LIEU!$A$1026:$A$1525,0))="","",INDEX(NHAP_LIEU!$B$1026:$B$1525,MATCH($I$2,NHAP_LIEU!$A$1026:$A$1525,0))),""),NHAP_LIEU!$A$14:$A$513,0))="","",INDEX(NHAP_LIEU!$V$14:$V$513,MATCH(IFERROR(IF(INDEX(NHAP_LIEU!$B$1026:$B$1525,MATCH($I$2,NHAP_LIEU!$A$1026:$A$1525,0))="","",INDEX(NHAP_LIEU!$B$1026:$B$1525,MATCH($I$2,NHAP_LIEU!$A$1026:$A$1525,0))),""),NHAP_LIEU!$A$14:$A$513,0))),"")="","……/……/……",TEXT(IFERROR(IF(INDEX(NHAP_LIEU!$V$14:$V$513,MATCH(IFERROR(IF(INDEX(NHAP_LIEU!$B$1026:$B$1525,MATCH($I$2,NHAP_LIEU!$A$1026:$A$1525,0))="","",INDEX(NHAP_LIEU!$B$1026:$B$1525,MATCH($I$2,NHAP_LIEU!$A$1026:$A$1525,0))),""),NHAP_LIEU!$A$14:$A$513,0))="","",INDEX(NHAP_LIEU!$V$14:$V$513,MATCH(IFERROR(IF(INDEX(NHAP_LIEU!$B$1026:$B$1525,MATCH($I$2,NHAP_LIEU!$A$1026:$A$1525,0))="","",INDEX(NHAP_LIEU!$B$1026:$B$1525,MATCH($I$2,NHAP_LIEU!$A$1026:$A$1525,0))),""),NHAP_LIEU!$A$14:$A$513,0))),""),"dd/mm/yyyy"))&")" -> Số: 001/2026/PLHĐLĐ-MAU (kèm theo HĐLĐ số ngày ……/……/……) | I4: Đổi mã ở ô vàng để in người khác. Khối này KHÔNG in ra giấy — chỉ để chọn.
B5: =IF(IFERROR(IF(INDEX(NHAP_LIEU!$D$1026:$D$1525,MATCH($I$2,NHAP_LIEU!$A$1026:$A$1525,0))="","",INDEX(NHAP_LIEU!$D$1026:$D$1525,MATCH($I$2,NHAP_LIEU!$A$1026:$A$1525,0))),"")="","Căn cứ Điều 22 Bộ luật Lao động 2019 và Hợp đồng lao động đã ký, hôm nay, ngày ……/……/……, tại "&IF(IFERROR(IF(INDEX(NHAP_LIEU!$E$1026:$E$1525,MATCH($I$2,NHAP_LIEU!$A$1026:$A$1525,0))="","",INDEX(NHAP_LIEU!$E$1026:$E$1525,MATCH($I$2,NHAP_LIEU!$A$1026:$A$1525,0))),"")<>"",IFERROR(IF(INDEX(NHAP_LIEU!$E$1026:$E$1525,MATCH($I$2,NHAP_LIEU!$A$1026:$A$1525,0))="","",INDEX(NHAP_LIEU!$E$1026:$E$1525,MATCH($I$2,NHAP_LIEU!$A$1026:$A$1525,0))),""),NHAP_LIEU!$E$7)&", chúng tôi gồm:","Căn cứ Điều 22 Bộ luật Lao động 2019 và Hợp đồng lao động đã ký, hôm nay, ngày "&TEXT(IFERROR(IF(INDEX(NHAP_LIEU!$D$1026:$D$1525,MATCH($I$2,NHAP_LIEU!$A$1026:$A$1525,0))="","",INDEX(NHAP_LIEU!$D$1026:$D$1525,MATCH($I$2,NHAP_LIEU!$A$1026:$A$1525,0))),""),"dd/mm/yyyy")&", tại "&IF(IFERROR(IF(INDEX(NHAP_LIEU!$E$1026:$E$1525,MATCH($I$2,NHAP_LIEU!$A$1026:$A$1525,0))="","",INDEX(NHAP_LIEU!$E$1026:$E$1525,MATCH($I$2,NHAP_LIEU!$A$1026:$A$1525,0))),"")<>"",IFERROR(IF(INDEX(NHAP_LIEU!$E$1026:$E$1525,MATCH($I$2,NHAP_LIEU!$A$1026:$A$1525,0))="","",INDEX(NHAP_LIEU!$E$1026:$E$1525,MATCH($I$2,NHAP_LIEU!$A$1026:$A$1525,0))),""),NHAP_LIEU!$E$7)&", chúng tôi gồm:") -> Căn cứ Điều 22 Bộ luật Lao động 2019 và Hợp đồng lao động đã ký, hôm nay, ngày 01/10/2026, tại Thành phố Hồ Chí Minh, chúng tôi gồm:
B6: ="BÊN A (NSDLĐ): Công ty "&NHAP_LIEU!$B$4&" — Đại diện: "&NHAP_LIEU!$E$4&" — Chức danh: "&NHAP_LIEU!$E$6 -> BÊN A (NSDLĐ): Công ty CÔNG TY TNHH KK HOME — Đại diện: HUỲNH NGỌC NGÂN — Chức danh: Giám đốc
B7: ="BÊN B (NLĐ): "&IF(IFERROR(IF(INDEX(NHAP_LIEU!$D$14:$D$513,MATCH(IFERROR(IF(INDEX(NHAP_LIEU!$B$1026:$B$1525,MATCH($I$2,NHAP_LIEU!$A$1026:$A$1525,0))="","",INDEX(NHAP_LIEU!$B$1026:$B$1525,MATCH($I$2,NHAP_LIEU!$A$1026:$A$1525,0))),""),NHAP_LIEU!$A$14:$A$513,0))="","",INDEX(NHAP_LIEU!$D$14:$D$513,MATCH(IFERROR(IF(INDEX(NHAP_LIEU!$B$1026:$B$1525,MATCH($I$2,NHAP_LIEU!$A$1026:$A$1525,0))="","",INDEX(NHAP_LIEU!$B$1026:$B$1525,MATCH($I$2,NHAP_LIEU!$A$1026:$A$1525,0))),""),NHAP_LIEU!$A$14:$A$513,0))),"")="Nữ","Bà",IF(IFERROR(IF(INDEX(NHAP_LIEU!$D$14:$D$513,MATCH(IFERROR(IF(INDEX(NHAP_LIEU!$B$1026:$B$1525,MATCH($I$2,NHAP_LIEU!$A$1026:$A$1525,0))="","",INDEX(NHAP_LIEU!$B$1026:$B$1525,MATCH($I$2,NHAP_LIEU!$A$1026:$A$1525,0))),""),NHAP_LIEU!$A$14:$A$513,0))="","",INDEX(NHAP_LIEU!$D$14:$D$513,MATCH(IFERROR(IF(INDEX(NHAP_LIEU!$B$1026:$B$1525,MATCH($I$2,NHAP_LIEU!$A$1026:$A$1525,0))="","",INDEX(NHAP_LIEU!$B$1026:$B$1525,MATCH($I$2,NHAP_LIEU!$A$1026:$A$1525,0))),""),NHAP_LIEU!$A$14:$A$513,0))),"")="Nam","Ông",""))&" "&IFERROR(IF(INDEX(NHAP_LIEU!$C$14:$C$513,MATCH(IFERROR(IF(INDEX(NHAP_LIEU!$B$1026:$B$1525,MATCH($I$2,NHAP_LIEU!$A$1026:$A$1525,0))="","",INDEX(NHAP_LIEU!$B$1026:$B$1525,MATCH($I$2,NHAP_LIEU!$A$1026:$A$1525,0))),""),NHAP_LIEU!$A$14:$A$513,0))="","",INDEX(NHAP_LIEU!$C$14:$C$513,MATCH(IFERROR(IF(INDEX(NHAP_LIEU!$B$1026:$B$1525,MATCH($I$2,NHAP_LIEU!$A$1026:$A$1525,0))="","",INDEX(NHAP_LIEU!$B$1026:$B$1525,MATCH($I$2,NHAP_LIEU!$A$1026:$A$1525,0))),""),NHAP_LIEU!$A$14:$A$513,0))),"")&" — CCCD số: "&IFERROR(IF(INDEX(NHAP_LIEU!$G$14:$G$513,MATCH(IFERROR(IF(INDEX(NHAP_LIEU!$B$1026:$B$1525,MATCH($I$2,NHAP_LIEU!$A$1026:$A$1525,0))="","",INDEX(NHAP_LIEU!$B$1026:$B$1525,MATCH($I$2,NHAP_LIEU!$A$1026:$A$1525,0))),""),NHAP_LIEU!$A$14:$A$513,0))="","",INDEX(NHAP_LIEU!$G$14:$G$513,MATCH(IFERROR(IF(INDEX(NHAP_LIEU!$B$1026:$B$1525,MATCH($I$2,NHAP_LIEU!$A$1026:$A$1525,0))="","",INDEX(NHAP_LIEU!$B$1026:$B$1525,MATCH($I$2,NHAP_LIEU!$A$1026:$A$1525,0))),""),NHAP_LIEU!$A$14:$A$513,0))),"") -> BÊN B (NLĐ): — CCCD số:
B8: Hai bên thống nhất sửa đổi, bổ sung một số nội dung của Hợp đồng lao động như sau:
B9: Điều 1. Nội dung sửa đổi, bổ sung
B10: Điều, khoản | E10: Nội dung cũ | F10: ="Nội dung mới (từ ngày "&IF(IFERROR(IF(INDEX(NHAP_LIEU!$F$1026:$F$1525,MATCH($I$2,NHAP_LIEU!$A$1026:$A$1525,0))="","",INDEX(NHAP_LIEU!$F$1026:$F$1525,MATCH($I$2,NHAP_LIEU!$A$1026:$A$1525,0))),"")="","……/……/……",TEXT(IFERROR(IF(INDEX(NHAP_LIEU!$F$1026:$F$1525,MATCH($I$2,NHAP_LIEU!$A$1026:$A$1525,0))="","",INDEX(NHAP_LIEU!$F$1026:$F$1525,MATCH($I$2,NHAP_LIEU!$A$1026:$A$1525,0))),""),"dd/mm/yyyy"))&")" -> Nội dung mới (từ ngày 01/10/2026)
B11: =IFERROR(IF(INDEX(NHAP_LIEU!$G$1026:$G$1525,MATCH($I$2,NHAP_LIEU!$A$1026:$A$1525,0))="","",INDEX(NHAP_LIEU!$G$1026:$G$1525,MATCH($I$2,NHAP_LIEU!$A$1026:$A$1525,0))),"") -> Điều 3.1 | E11: =IFERROR(IF(INDEX(NHAP_LIEU!$H$1026:$H$1525,MATCH($I$2,NHAP_LIEU!$A$1026:$A$1525,0))="","",INDEX(NHAP_LIEU!$H$1026:$H$1525,MATCH($I$2,NHAP_LIEU!$A$1026:$A$1525,0))),"") -> Mức lương 12.000.000 đồng/tháng | F11: =IFERROR(IF(INDEX(NHAP_LIEU!$I$1026:$I$1525,MATCH($I$2,NHAP_LIEU!$A$1026:$A$1525,0))="","",INDEX(NHAP_LIEU!$I$1026:$I$1525,MATCH($I$2,NHAP_LIEU!$A$1026:$A$1525,0))),"") -> Mức lương 13.000.000 đồng/tháng
B12: =IFERROR(IF(INDEX(NHAP_LIEU!$J$1026:$J$1525,MATCH($I$2,NHAP_LIEU!$A$1026:$A$1525,0))="","",INDEX(NHAP_LIEU!$J$1026:$J$1525,MATCH($I$2,NHAP_LIEU!$A$1026:$A$1525,0))),"") -> Điều 3.2 | E12: =IFERROR(IF(INDEX(NHAP_LIEU!$K$1026:$K$1525,MATCH($I$2,NHAP_LIEU!$A$1026:$A$1525,0))="","",INDEX(NHAP_LIEU!$K$1026:$K$1525,MATCH($I$2,NHAP_LIEU!$A$1026:$A$1525,0))),"") -> Phụ cấp trách nhiệm 1.000.000 đồng/tháng | F12: =IFERROR(IF(INDEX(NHAP_LIEU!$L$1026:$L$1525,MATCH($I$2,NHAP_LIEU!$A$1026:$A$1525,0))="","",INDEX(NHAP_LIEU!$L$1026:$L$1525,MATCH($I$2,NHAP_LIEU!$A$1026:$A$1525,0))),"") -> Phụ cấp trách nhiệm 1.500.000 đồng/tháng
B13: =IFERROR(IF(INDEX(NHAP_LIEU!$M$1026:$M$1525,MATCH($I$2,NHAP_LIEU!$A$1026:$A$1525,0))="","",INDEX(NHAP_LIEU!$M$1026:$M$1525,MATCH($I$2,NHAP_LIEU!$A$1026:$A$1525,0))),"") | E13: =IFERROR(IF(INDEX(NHAP_LIEU!$N$1026:$N$1525,MATCH($I$2,NHAP_LIEU!$A$1026:$A$1525,0))="","",INDEX(NHAP_LIEU!$N$1026:$N$1525,MATCH($I$2,NHAP_LIEU!$A$1026:$A$1525,0))),"") | F13: =IFERROR(IF(INDEX(NHAP_LIEU!$O$1026:$O$1525,MATCH($I$2,NHAP_LIEU!$A$1026:$A$1525,0))="","",INDEX(NHAP_LIEU!$O$1026:$O$1525,MATCH($I$2,NHAP_LIEU!$A$1026:$A$1525,0))),"")
B14: Ví dụ thường gặp: điều chỉnh mức lương, phụ cấp; thay đổi chức danh, bộ phận; thay đổi địa điểm làm việc.
B15: Điều 2. Cam kết chung
B16: 2.1. Phụ lục này không sửa đổi thời hạn của Hợp đồng lao động (khoản 2 Điều 22 BLLĐ 2019).
B17: 2.2. Các nội dung khác của Hợp đồng lao động giữ nguyên hiệu lực. Trường hợp phụ lục có nội dung dẫn đến cách hiểu khác với hợp đồng thì thực hiện theo nội dung có lợi hơn cho NLĐ.
B18: ="2.3. Phụ lục được lập thành 02 bản, mỗi bên giữ 01 bản, là bộ phận không tách rời của Hợp đồng lao động, có hiệu lực từ ngày "&IF(IFERROR(IF(INDEX(NHAP_LIEU!$F$1026:$F$1525,MATCH($I$2,NHAP_LIEU!$A$1026:$A$1525,0))="","",INDEX(NHAP_LIEU!$F$1026:$F$1525,MATCH($I$2,NHAP_LIEU!$A$1026:$A$1525,0))),"")="","……/……/……",TEXT(IFERROR(IF(INDEX(NHAP_LIEU!$F$1026:$F$1525,MATCH($I$2,NHAP_LIEU!$A$1026:$A$1525,0))="","",INDEX(NHAP_LIEU!$F$1026:$F$1525,MATCH($I$2,NHAP_LIEU!$A$1026:$A$1525,0))),""),"dd/mm/yyyy")) -> 2.3. Phụ lục được lập thành 02 bản, mỗi bên giữ 01 bản, là bộ phận không tách rời của Hợp đồng lao động, có hiệu lực từ ngày 01/10/2026
B19: ="NGƯỜI LAO ĐỘNG"&CHAR(10)&"(Ký, ghi rõ họ tên)"&CHAR(10)&CHAR(10)&CHAR(10)&IFERROR(IF(INDEX(NHAP_LIEU!$C$14:$C$513,MATCH(IFERROR(IF(INDEX(NHAP_LIEU!$B$1026:$B$1525,MATCH($I$2,NHAP_LIEU!$A$1026:$A$1525,0))="","",INDEX(NHAP_LIEU!$B$1026:$B$1525,MATCH($I$2,NHAP_LIEU!$A$1026:$A$1525,0))),""),NHAP_LIEU!$A$14:$A$513,0))="","",INDEX(NHAP_LIEU!$C$14:$C$513,MATCH(IFERROR(IF(INDEX(NHAP_LIEU!$B$1026:$B$1525,MATCH($I$2,NHAP_LIEU!$A$1026:$A$1525,0))="","",INDEX(NHAP_LIEU!$B$1026:$B$1525,MATCH($I$2,NHAP_LIEU!$A$1026:$A$1525,0))),""),NHAP_LIEU!$A$14:$A$513,0))),"") -> NGƯỜI LAO ĐỘNG (Ký, ghi rõ họ tên) | E19: ="ĐẠI DIỆN NGƯỜI SỬ DỤNG LAO ĐỘNG"&CHAR(10)&"(Ký, ghi rõ họ tên, đóng dấu)"&CHAR(10)&CHAR(10)&CHAR(10)&NHAP_LIEU!$E$4 -> ĐẠI DIỆN NGƯỜI SỬ DỤNG LAO ĐỘNG (Ký, ghi rõ họ tên, đóng dấu) HUỲNH NGỌC NGÂN
B21: KK HOME — Biểu mẫu tham khảo, nội dung nguồn cập nhật đến tháng 7/2026

Sheet BAO_MAT_DT
B1: PHẦN III — THỎA THUẬN BẢO MẬT THÔNG TIN VÀ CAM KẾT ĐÀO TẠO | I1: CHỌN NHÂN VIÊN ĐỂ IN ▼
B2: ="(Ký kèm và là bộ phận không tách rời của HĐLĐ số "&IFERROR(IF(INDEX(NHAP_LIEU!$B$14:$B$513,MATCH($I$2,NHAP_LIEU!$A$14:$A$513,0))="","",INDEX(NHAP_LIEU!$B$14:$B$513,MATCH($I$2,NHAP_LIEU!$A$14:$A$513,0))),"")&")" -> (Ký kèm và là bộ phận không tách rời của HĐLĐ số ) | I2: NV001
B3: A. THỎA THUẬN BẢO MẬT THÔNG TIN | I3: =IFERROR(INDEX(NHAP_LIEU!$C$14:$C$513,MATCH($I$2,NHAP_LIEU!$A$14:$A$513,0)),"—") -> —
B4: Điều 1. Thông tin mật | I4: Đổi mã ở ô vàng để in người khác. Khối này KHÔNG in ra giấy — chỉ để chọn.
B5: =_xlfn._LONGTEXT("""Thông tin mật"" bao gồm nhưng không giới hạn: bí mật kinh doanh, bí mật công nghệ theo pháp luật sở hữu trí tuệ và cạnh tranh; danh sách, dữ liệu khách hàng, nhà cung cấp; chính sách giá, tiền lương; kế hoạch kinh doanh, tài chính, sản phẩm; mã nguồn, tài"," liệu kỹ thuật, quy trình nội bộ; dữ liệu cá nhân mà NLĐ tiếp cận trong quá trình làm việc; và các thông tin khác được NSDLĐ xác định là mật trong quy chế: ")&IF(IFERROR(IF(INDEX(NHAP_LIEU!$AJ$14:$AJ$513,MATCH($I$2,NHAP_LIEU!$A$14:$A$513,0))="","",INDEX(NHAP_LIEU!$AJ$14:$AJ$513,MATCH($I$2,NHAP_LIEU!$A$14:$A$513,0))),"")="","không có bổ sung",IFERROR(IF(INDEX(NHAP_LIEU!$AJ$14:$AJ$513,MATCH($I$2,NHAP_LIEU!$A$14:$A$513,0))="","",INDEX(NHAP_LIEU!$AJ$14:$AJ$513,MATCH($I$2,NHAP_LIEU!$A$14:$A$513,0))),"")) -> "Thông tin mật" bao gồm nhưng không giới hạn: bí mật kinh doanh, bí mật công nghệ theo pháp luật sở hữu trí tuệ và cạnh tranh; danh sách, dữ liệu khách hàng, nhà cung cấp; chính sách giá, tiền lương; kế hoạch kinh doanh, tài chính, sản phẩm; mã nguồn, tài liệu kỹ thuật, quy trình nội bộ; dữ liệu cá nhân mà NLĐ tiếp cận trong quá trình làm việc; và các thông tin khác được NSDLĐ xác định là mật trong quy chế: không có bổ sung
B6: Điều 2. Nghĩa vụ của NLĐ
B7: ="2.1. Không tiết lộ, sao chép, sử dụng Thông tin mật ngoài phạm vi công việc được giao, cả trong thời gian làm việc và trong thời hạn "&IF(2<>"",2,2)&" năm (khuyến nghị 1–3 năm tùy vị trí) sau khi chấm dứt HĐLĐ." -> 2.1. Không tiết lộ, sao chép, sử dụng Thông tin mật ngoài phạm vi công việc được giao, cả trong thời gian làm việc và trong thời hạn 2 năm (khuyến nghị 1–3 năm tùy vị trí) sau khi chấm dứt HĐLĐ.
B8: 2.2. Bàn giao đầy đủ tài liệu, dữ liệu, thiết bị chứa Thông tin mật khi chấm dứt HĐLĐ hoặc theo yêu cầu của NSDLĐ; không lưu giữ bản sao dưới mọi hình thức.
B9: 2.3. Tuân thủ quy định của pháp luật và quy chế của Công ty về bảo vệ dữ liệu cá nhân khi xử lý dữ liệu cá nhân của khách hàng, đồng nghiệp.
B10: Điều 3. Xử lý vi phạm
B11: NLĐ vi phạm nghĩa vụ bảo mật phải bồi thường thiệt hại thực tế và trực tiếp cho NSDLĐ theo thỏa thuận tại văn bản này, nội quy lao động và quy định pháp luật (khoản 2 Điều 21 BLLĐ 2019; Điều 4 Thông tư 10/2020/TT-BLĐTBXH); tùy mức độ có thể bị xử lý kỷ luật lao động, kể cả sa thải theo Điều 125 BLLĐ 2019, và chịu trách nhiệm dân sự, hình sự theo quy định.
B12: B. CAM KẾT ĐÀO TẠO (áp dụng khi NLĐ được đào tạo bằng kinh phí của NSDLĐ)
B13: Điều 4. Nội dung đào tạo
B14: =IF(IFERROR(IF(INDEX(NHAP_LIEU!$B$520:$B$1019,MATCH($I$2,NHAP_LIEU!$A$520:$A$1019,0))="","",INDEX(NHAP_LIEU!$B$520:$B$1019,MATCH($I$2,NHAP_LIEU!$A$520:$A$1019,0))),"")="Có","Khóa đào tạo/nghề đào tạo: "&IFERROR(IF(INDEX(NHAP_LIEU!$C$520:$C$1019,MATCH($I$2,NHAP_LIEU!$A$520:$A$1019,0))="","",INDEX(NHAP_LIEU!$C$520:$C$1019,MATCH($I$2,NHAP_LIEU!$A$520:$A$1019,0))),"")&"; Địa điểm, thời gian đào tạo: "&IFERROR(IF(INDEX(NHAP_LIEU!$D$520:$D$1019,MATCH($I$2,NHAP_LIEU!$A$520:$A$1019,0))="","",INDEX(NHAP_LIEU!$D$520:$D$1019,MATCH($I$2,NHAP_LIEU!$A$520:$A$1019,0))),""),"Khóa đào tạo/nghề đào tạo: Không áp dụng.") -> Khóa đào tạo/nghề đào tạo: Khóa nghiệp vụ kế toán nâng cao; Địa điểm, thời gian đào tạo: TP.HCM, từ 10/08/2026 đến 15/08/2026
B15: =IF(IFERROR(IF(INDEX(NHAP_LIEU!$B$520:$B$1019,MATCH($I$2,NHAP_LIEU!$A$520:$A$1019,0))="","",INDEX(NHAP_LIEU!$B$520:$B$1019,MATCH($I$2,NHAP_LIEU!$A$520:$A$1019,0))),"")="Có","Tổng chi phí đào tạo (học phí, tài liệu, đi lại, lưu trú, lương và các khoản hỗ trợ trong thời gian học…): "&IF(IFERROR(IF(INDEX(NHAP_LIEU!$E$520:$E$1019,MATCH($I$2,NHAP_LIEU!$A$520:$A$1019,0))="","",INDEX(NHAP_LIEU!$E$520:$E$1019,MATCH($I$2,NHAP_LIEU!$A$520:$A$1019,0))),"")="","……",TEXT(IFERROR(IF(INDEX(NHAP_LIEU!$E$520:$E$1019,MATCH($I$2,NHAP_LIEU!$A$520:$A$1019,0))="","",INDEX(NHAP_LIEU!$E$520:$E$1019,MATCH($I$2,NHAP_LIEU!$A$520:$A$1019,0))),""),"#,##0"))&" đồng (kê chi tiết kèm chứng từ hợp lệ theo khoản 3 Điều 62 BLLĐ 2019).","Tổng chi phí đào tạo: Không áp dụng.") -> Tổng chi phí đào tạo (học phí, tài liệu, đi lại, lưu trú, lương và các khoản hỗ trợ trong thời gian học…): 15,000,000 đồng (kê chi tiết kèm chứng từ hợp lệ theo khoản 3 Điều 62 BLLĐ 2019).
B16: Điều 5. Cam kết làm việc sau đào tạo
B17: =IF(IFERROR(IF(INDEX(NHAP_LIEU!$B$520:$B$1019,MATCH($I$2,NHAP_LIEU!$A$520:$A$1019,0))="","",INDEX(NHAP_LIEU!$B$520:$B$1019,MATCH($I$2,NHAP_LIEU!$A$520:$A$1019,0))),"")="Có","5.1. NLĐ cam kết làm việc cho NSDLĐ tối thiểu "&IFERROR(IF(INDEX(NHAP_LIEU!$F$520:$F$1019,MATCH($I$2,NHAP_LIEU!$A$520:$A$1019,0))="","",INDEX(NHAP_LIEU!$F$520:$F$1019,MATCH($I$2,NHAP_LIEU!$A$520:$A$1019,0))),"")&" tháng kể từ ngày hoàn thành khóa đào tạo.","5.1. Không áp dụng cam kết thời gian làm việc sau đào tạo.") -> 5.1. NLĐ cam kết làm việc cho NSDLĐ tối thiểu 18 tháng kể từ ngày hoàn thành khóa đào tạo.
B18: =IF(IFERROR(IF(INDEX(NHAP_LIEU!$B$520:$B$1019,MATCH($I$2,NHAP_LIEU!$A$520:$A$1019,0))="","",INDEX(NHAP_LIEU!$B$520:$B$1019,MATCH($I$2,NHAP_LIEU!$A$520:$A$1019,0))),"")="Có",_xlfn._LONGTEXT("5.2. Trường hợp NLĐ đơn phương chấm dứt HĐLĐ trái pháp luật hoặc vi phạm cam kết tại khoản 5.1 (trừ trường hợp bất khả kháng hoặc hai bên có thỏa thuận khác), NLĐ hoàn trả chi phí đào tạo theo tỷ lệ: (số tháng cam kết còn lại / tổng số tháng cam kết) × tổ","ng chi phí đào tạo, trong thời hạn ")&IF(30<>"",30,30)&" ngày kể từ ngày chấm dứt HĐLĐ.","5.2. Không áp dụng.") -> 5.2. Trường hợp NLĐ đơn phương chấm dứt HĐLĐ trái pháp luật hoặc vi phạm cam kết tại khoản 5.1 (trừ trường hợp bất khả kháng hoặc hai bên có thỏa thuận khác), NLĐ hoàn trả chi phí đào tạo theo tỷ lệ: (số tháng cam kết còn lại / tổng số tháng cam kết) × tổng chi phí đào tạo, trong thời hạn 30 ngày kể từ ngày chấm dứt HĐLĐ.
B19: 5.3. Thỏa thuận này được lập thành 02 bản, mỗi bên giữ 01 bản, có hiệu lực kể từ ngày ký.
B20: ="NGƯỜI LAO ĐỘNG"&CHAR(10)&"(Ký, ghi rõ họ tên)"&CHAR(10)&CHAR(10)&CHAR(10)&IFERROR(IF(INDEX(NHAP_LIEU!$C$14:$C$513,MATCH($I$2,NHAP_LIEU!$A$14:$A$513,0))="","",INDEX(NHAP_LIEU!$C$14:$C$513,MATCH($I$2,NHAP_LIEU!$A$14:$A$513,0))),"") -> NGƯỜI LAO ĐỘNG (Ký, ghi rõ họ tên) | E20: ="ĐẠI DIỆN NGƯỜI SỬ DỤNG LAO ĐỘNG"&CHAR(10)&"(Ký, ghi rõ họ tên, đóng dấu)"&CHAR(10)&CHAR(10)&CHAR(10)&NHAP_LIEU!$E$4 -> ĐẠI DIỆN NGƯỜI SỬ DỤNG LAO ĐỘNG (Ký, ghi rõ họ tên, đóng dấu) HUỲNH NGỌC NGÂN
B22: KK HOME — Biểu mẫu tham khảo, nội dung nguồn cập nhật đến tháng 7/2026

Sheet THAM_KHAO
B1: PHẦN IV — THUYẾT MINH PHÁP LÝ VÀ HƯỚNG DẪN SỬ DỤNG
B2: (Cập nhật theo quy định có hiệu lực đến tháng 7/2026 — phần này để doanh nghiệp tham khảo, KHÔNG in kèm khi ký hợp đồng)
B3: 1. DANH MỤC CĂN CỨ PHÁP LÝ CHÍNH (còn hiệu lực)
B4: Văn bản | E4: Hiệu lực | F4: Nội dung liên quan
B5: Bộ luật Lao động 45/2019/QH14 | E5: 01/01/2021 | F5: Khung pháp lý HĐLĐ: giao kết, nội dung (Đ.21), thử việc, lương, thời giờ làm việc, chấm dứt…
B6: NĐ 145/2020/NĐ-CP (sửa bởi NĐ 70/2023/NĐ-CP) | E6: 01/02/2021 | F6: Hướng dẫn chi tiết BLLĐ về điều kiện lao động, quan hệ lao động
B7: TT 10/2020/TT-BLĐTBXH | E7: 01/01/2021 | F7: Hướng dẫn nội dung bắt buộc của HĐLĐ; bảo vệ bí mật kinh doanh, công nghệ
B8: Luật BHXH 41/2024/QH15 | E8: 01/7/2025 | F8: BHXH bắt buộc: đối tượng (HĐLĐ từ đủ 01 tháng), tiền lương làm căn cứ đóng, mức tham chiếu, xử lý trốn/chậm đóng
B9: NĐ 158/2025/NĐ-CP | E9: 01/7/2025 | F9: Quy định chi tiết Luật BHXH 2024
B10: NĐ 161/2026/NĐ-CP | E10: 01/7/2026 | F10: Mức tham chiếu 2.530.000 đ/tháng từ 01/7/2026
B11: Luật Việc làm 74/2025/QH15 | E11: 01/01/2026 | F11: BHTN: mở rộng đối tượng (gồm HĐLĐ từ đủ 01 tháng), mức đóng tối đa 1% mỗi bên, trần hưởng 5 lần lương tối thiểu vùng
B12: Luật BHYT (sửa đổi 51/2024/QH15) | E12: 01/7/2025 | F12: BHYT bắt buộc nhóm NLĐ; mức đóng 4,5% (NSDLĐ 3%, NLĐ 1,5%)
B13: NĐ 293/2025/NĐ-CP | E13: 01/01/2026 | F13: Lương tối thiểu vùng 2026 (tăng bình quân 7,2%)
B14: Luật Thuế TNCN 109/2025/QH15 | E14: 01/7/2026 (áp dụng kỳ tính thuế 2026) | F14: Biểu thuế lũy tiến 5 bậc (5%–35%) với tiền lương, tiền công
B15: NQ 110/2025/UBTVQH15 | E15: Kỳ tính thuế 2026 | F15: Giảm trừ gia cảnh: bản thân 15,5 triệu đ/tháng; người phụ thuộc 6,2 triệu đ/tháng
... B17: Luật An toàn, vệ sinh lao động 84/2015/QH13; NĐ 58/2020/NĐ-CP | E17: 01/7/2016 | F17: ATVSLĐ; mức đóng quỹ TNLĐ-BNN 0,5% (hoặc 0,3% nếu đủ điều kiện)
B18: 2. LƯƠNG TỐI THIỂU VÙNG TỪ 01/01/2026 (Nghị định 293/2025/NĐ-CP)
B19: Vùng | D19: Lương tối thiểu tháng | E19: Lương tối thiểu giờ | F19: Tăng so với 2025
B20: Vùng I | D20: 5.310.000 đ | E20: 25.500 đ | F20: +350.000 đ
B21: Vùng II | D21: 4.730.000 đ | E21: 22.700 đ | F21: +320.000 đ
B22: Vùng III | D22: 4.140.000 đ | E22: 20.000 đ | F22: +280.000 đ
B23: Vùng IV | D23: 3.700.000 đ | E23: 17.800 đ | F23: +250.000 đ
B24: – Mức lương tại Điều 3 HĐLĐ không được thấp hơn lương tối thiểu vùng nơi NLĐ làm việc; lương thử việc tối thiểu bằng 85% mức lương của công việc.
B25: – Doanh nghiệp có đơn vị, chi nhánh hoạt động trên các địa bàn có mức lương tối thiểu khác nhau thì áp dụng theo địa bàn nơi NLĐ làm việc.
