Workbook

Sheet Hướng dẫn
A1: KPI PHÒNG NHÂN SỰ – 13 VỊ TRÍ (MÔ HÌNH ĐẦY ĐỦ)
A2: Phụ lục 02 kèm Quy chế đánh giá KPI · KK HOME ·
B4: CÁCH DÙNG – 6 BƯỚC
B5: Bước 1 | C5: Chọn sheet đúng vị trí của nhân sự (bấm tên vị trí ở danh mục bên dưới để nhảy tới sheet).
B6: Bước 2 | C6: Nhập thông tin đầu sheet: Họ tên, Mã NV, Người đánh giá, Loại kỳ (Tháng/Quý/Năm), Kỳ đánh giá, Ngày đánh giá.
B7: Bước 3 | C7: Nhân sự tự chấm điểm cột F "Tự đánh giá" (1–5, được chấm lẻ 3.5).
B8: Bước 4 | C8: Quản lý trực tiếp chấm điểm chính thức cột G "Quản lý chấm". Chỉ điểm cột G được dùng để tính điểm quy đổi và xếp loại.
B9: Bước 5 | C9: Ghi chú lý do ở cột I khi điểm ≤ 1,5 hoặc = 5. Ô ghi chú tự tô cam nếu thiếu lý do (Điều 12 – Ngoại lệ).
B10: Bước 6 | C10: Xem kết quả ở cuối sheet vị trí, sheet "Tổng hợp" (toàn phòng) và "So sánh" (biểu đồ). In, ký và trình phê duyệt.
B12: QUY ƯỚC Ô
B13: Ô nền vàng, chữ xanh | C13: Ô nhập liệu. Chỉ nhập vào các ô này.
B14: Trọng số chữ xanh (cột E) | C14: Được sửa khi có quyết định điều chỉnh (Điều 17). Tổng trọng số mỗi vị trí phải = 100% – ô "Kiểm tra tổng trọng số" báo đỏ nếu sai.
B15: Ô nền xám | C15: Công thức tự tính. Không sửa.
B17: CÔNG THỨC & XẾP LOẠI (Điều 7, Điều 13 Quy chế)
B18: Điểm quy đổi | C18: Điểm quản lý chấm ÷ 5 × Trọng số × 100
B19: Tổng điểm | C19: Cộng điểm quy đổi các tiêu chí (tối đa 100 điểm)
B20: Xếp loại | C20: ≥ 80 điểm: Xuất sắc · 70 đến dưới 80: Đạt · Dưới 70: Cần cải thiện. Chưa chấm đủ tiêu chí → hiển thị "Chưa chấm đủ".
B21: Ví dụ | C21: Tiêu chí "Độ chính xác bảng lương" trọng số 15%, quản lý chấm 4 → 4 ÷ 5 × 15 = 12,0 điểm. Chấm 3.5 → 10,5 điểm.
B22: Cơ cấu nhóm | C22: Chuyên môn - Nghiệp vụ 40% · Tuân thủ - Thời hạn 35% · Phối hợp - Thái độ 25% (áp dụng cho mọi vị trí trong file).
B24: DANH MỤC 13 VỊ TRÍ
B25: 01 | C25: Trưởng phòng Nhân sự (10 tiêu chí)
B26: 02 | C26: Phó phòng Nhân sự (10 tiêu chí)
B27: 03 | C27: Chuyên viên Đối tác nhân sự (HRBP) (10 tiêu chí)
B28: 04 | C28: Trưởng nhóm Tuyển dụng (10 tiêu chí)
B29: 05 | C29: Chuyên viên Tuyển dụng (11 tiêu chí)
B30: 06 | C30: Chuyên viên Lương & Phúc lợi (C&B) (11 tiêu chí)
B31: 07 | C31: Chuyên viên BHXH & Chế độ (10 tiêu chí)
B32: 08 | C32: Chuyên viên Đào tạo & Phát triển (11 tiêu chí)
B33: 09 | C33: Chuyên viên Quan hệ lao động & Hồ sơ nhân sự (10 tiêu chí)
B34: 10 | C34: Chuyên viên Văn hóa doanh nghiệp & Truyền thông nội bộ (10 tiêu chí)
B35: 11 | C35: Chuyên viên Hệ thống thông tin & Báo cáo nhân sự (HRIS) (10 tiêu chí)
B36: 12 | C36: Nhân viên Hành chính nhân sự (11 tiêu chí)
... B39: Lưu ý | C39: Tiêu chí và cách đo là bộ mẫu. Đơn vị điều chỉnh chỉ tiêu định lượng (%, số ngày, số lỗi) theo mục tiêu đã duyệt của từng kỳ trước khi phổ biến cho nhân sự (Điều 4 – Công khai).

Sheet Tổng hợp
A1: TỔNG HỢP KẾT QUẢ KPI – PHÒNG NHÂN SỰ
A2: Phụ lục 02 · Tự cập nhật từ các sheet vị trí (Bước 4 – Điều 10) · KK HOME ·
A4: STT | B4: Vị trí | C4: Họ và tên | D4: Kỳ đánh giá | E4: Điểm tự ĐG | F4: Điểm chính thức | G4: Chênh lệch (CT − Tự ĐG) | H4: Xếp loại | I4: Chuyên môn (% đạt) | J4: Tuân thủ (% đạt) | K4: Phối hợp (% đạt) | L4: Tiến độ chấm
A5: 1 | B5: Trưởng phòng Nhân sự | C5: =IF('01. Trưởng phòng NS'!C4="","",'01. Trưởng phòng NS'!C4) | D5: =IF('01. Trưởng phòng NS'!G5="",'01. Trưởng phòng NS'!G4,'01. Trưởng phòng NS'!G5) | E5: ='01. Trưởng phòng NS'!C24 | F5: ='01. Trưởng phòng NS'!C23 | G5: =IF(E5="","",F5-E5) | H5: ='01. Trưởng phòng NS'!C26 | I5: ='01. Trưởng phòng NS'!H24 | J5: ='01. Trưởng phòng NS'!H25 | K5: ='01. Trưởng phòng NS'!H26 | L5: ='01. Trưởng phòng NS'!C25
A6: 2 | B6: Phó phòng Nhân sự | C6: =IF('02. Phó phòng NS'!C4="","",'02. Phó phòng NS'!C4) | D6: =IF('02. Phó phòng NS'!G5="",'02. Phó phòng NS'!G4,'02. Phó phòng NS'!G5) | E6: ='02. Phó phòng NS'!C24 | F6: ='02. Phó phòng NS'!C23 | G6: =IF(E6="","",F6-E6) | H6: ='02. Phó phòng NS'!C26 | I6: ='02. Phó phòng NS'!H24 | J6: ='02. Phó phòng NS'!H25 | K6: ='02. Phó phòng NS'!H26 | L6: ='02. Phó phòng NS'!C25
A7: 3 | B7: Chuyên viên Đối tác nhân sự (HRBP) | C7: =IF('03. HRBP'!C4="","",'03. HRBP'!C4) | D7: =IF('03. HRBP'!G5="",'03. HRBP'!G4,'03. HRBP'!G5) | E7: ='03. HRBP'!C24 | F7: ='03. HRBP'!C23 | G7: =IF(E7="","",F7-E7) | H7: ='03. HRBP'!C26 | I7: ='03. HRBP'!H24 | J7: ='03. HRBP'!H25 | K7: ='03. HRBP'!H26 | L7: ='03. HRBP'!C25
A8: 4 | B8: Trưởng nhóm Tuyển dụng | C8: =IF('04. Trưởng nhóm TD'!C4="","",'04. Trưởng nhóm TD'!C4) | D8: =IF('04. Trưởng nhóm TD'!G5="",'04. Trưởng nhóm TD'!G4,'04. Trưởng nhóm TD'!G5) | E8: ='04. Trưởng nhóm TD'!C24 | F8: ='04. Trưởng nhóm TD'!C23 | G8: =IF(E8="","",F8-E8) | H8: ='04. Trưởng nhóm TD'!C26 | I8: ='04. Trưởng nhóm TD'!H24 | J8: ='04. Trưởng nhóm TD'!H25 | K8: ='04. Trưởng nhóm TD'!H26 | L8: ='04. Trưởng nhóm TD'!C25
A9: 5 | B9: Chuyên viên Tuyển dụng | C9: =IF('05. CV Tuyển dụng'!C4="","",'05. CV Tuyển dụng'!C4) | D9: =IF('05. CV Tuyển dụng'!G5="",'05. CV Tuyển dụng'!G4,'05. CV Tuyển dụng'!G5) | E9: ='05. CV Tuyển dụng'!C25 | F9: ='05. CV Tuyển dụng'!C24 | G9: =IF(E9="","",F9-E9) | H9: ='05. CV Tuyển dụng'!C27 | I9: ='05. CV Tuyển dụng'!H25 | J9: ='05. CV Tuyển dụng'!H26 | K9: ='05. CV Tuyển dụng'!H27 | L9: ='05. CV Tuyển dụng'!C26
A10: 6 | B10: Chuyên viên Lương & Phúc lợi (C&B) | C10: =IF('06. CV Lương-Phúc lợi'!C4="","",'06. CV Lương-Phúc lợi'!C4) | D10: =IF('06. CV Lương-Phúc lợi'!G5="",'06. CV Lương-Phúc lợi'!G4,'06. CV Lương-Phúc lợi'!G5) | E10: ='06. CV Lương-Phúc lợi'!C25 | F10: ='06. CV Lương-Phúc lợi'!C24 | G10: =IF(E10="","",F10-E10) | H10: ='06. CV Lương-Phúc lợi'!C27 | I10: ='06. CV Lương-Phúc lợi'!H25 | J10: ='06. CV Lương-Phúc lợi'!H26 | K10: ='06. CV Lương-Phúc lợi'!H27 | L10: ='06. CV Lương-Phúc lợi'!C26
A11: 7 | B11: Chuyên viên BHXH & Chế độ | C11: =IF('07. CV BHXH'!C4="","",'07. CV BHXH'!C4) | D11: =IF('07. CV BHXH'!G5="",'07. CV BHXH'!G4,'07. CV BHXH'!G5) | E11: ='07. CV BHXH'!C24 | F11: ='07. CV BHXH'!C23 | G11: =IF(E11="","",F11-E11) | H11: ='07. CV BHXH'!C26 | I11: ='07. CV BHXH'!H24 | J11: ='07. CV BHXH'!H25 | K11: ='07. CV BHXH'!H26 | L11: ='07. CV BHXH'!C25
A12: 8 | B12: Chuyên viên Đào tạo & Phát triển | C12: =IF('08. CV Đào tạo'!C4="","",'08. CV Đào tạo'!C4) | D12: =IF('08. CV Đào tạo'!G5="",'08. CV Đào tạo'!G4,'08. CV Đào tạo'!G5) | E12: ='08. CV Đào tạo'!C25 | F12: ='08. CV Đào tạo'!C24 | G12: =IF(E12="","",F12-E12) | H12: ='08. CV Đào tạo'!C27 | I12: ='08. CV Đào tạo'!H25 | J12: ='08. CV Đào tạo'!H26 | K12: ='08. CV Đào tạo'!H27 | L12: ='08. CV Đào tạo'!C26
A13: 9 | B13: Chuyên viên Quan hệ lao động & Hồ sơ nhân sự | C13: =IF('09. CV Quan hệ LĐ'!C4="","",'09. CV Quan hệ LĐ'!C4) | D13: =IF('09. CV Quan hệ LĐ'!G5="",'09. CV Quan hệ LĐ'!G4,'09. CV Quan hệ LĐ'!G5) | E13: ='09. CV Quan hệ LĐ'!C24 | F13: ='09. CV Quan hệ LĐ'!C23 | G13: =IF(E13="","",F13-E13) | H13: ='09. CV Quan hệ LĐ'!C26 | I13: ='09. CV Quan hệ LĐ'!H24 | J13: ='09. CV Quan hệ LĐ'!H25 | K13: ='09. CV Quan hệ LĐ'!H26 | L13: ='09. CV Quan hệ LĐ'!C25
A14: 10 | B14: Chuyên viên Văn hóa doanh nghiệp & Truyền thông nội bộ | C14: =IF('10. CV Văn hóa DN'!C4="","",'10. CV Văn hóa DN'!C4) | D14: =IF('10. CV Văn hóa DN'!G5="",'10. CV Văn hóa DN'!G4,'10. CV Văn hóa DN'!G5) | E14: ='10. CV Văn hóa DN'!C24 | F14: ='10. CV Văn hóa DN'!C23 | G14: =IF(E14="","",F14-E14) | H14: ='10. CV Văn hóa DN'!C26 | I14: ='10. CV Văn hóa DN'!H24 | J14: ='10. CV Văn hóa DN'!H25 | K14: ='10. CV Văn hóa DN'!H26 | L14: ='10. CV Văn hóa DN'!C25
A15: 11 | B15: Chuyên viên Hệ thống thông tin & Báo cáo nhân sự (HRIS) | C15: =IF('11. CV HRIS'!C4="","",'11. CV HRIS'!C4) | D15: =IF('11. CV HRIS'!G5="",'11. CV HRIS'!G4,'11. CV HRIS'!G5) | E15: ='11. CV HRIS'!C24 | F15: ='11. CV HRIS'!C23 | G15: =IF(E15="","",F15-E15) | H15: ='11. CV HRIS'!C26 | I15: ='11. CV HRIS'!H24 | J15: ='11. CV HRIS'!H25 | K15: ='11. CV HRIS'!H26 | L15: ='11. CV HRIS'!C25
A16: 12 | B16: Nhân viên Hành chính nhân sự | C16: =IF('12. NV Hành chính NS'!C4="","",'12. NV Hành chính NS'!C4) | D16: =IF('12. NV Hành chính NS'!G5="",'12. NV Hành chính NS'!G4,'12. NV Hành chính NS'!G5) | E16: ='12. NV Hành chính NS'!C25 | F16: ='12. NV Hành chính NS'!C24 | G16: =IF(E16="","",F16-E16) | H16: ='12. NV Hành chính NS'!C27 | I16: ='12. NV Hành chính NS'!H25 | J16: ='12. NV Hành chính NS'!H26 | K16: ='12. NV Hành chính NS'!H27 | L16: ='12. NV Hành chính NS'!C26
A17: 13 | B17: Nhân viên Nhân sự Junior | C17: =IF('13. NV NS Junior'!C4="","",'13. NV NS Junior'!C4) | D17: =IF('13. NV NS Junior'!G5="",'13. NV NS Junior'!G4,'13. NV NS Junior'!G5) | E17: ='13. NV NS Junior'!C24 | F17: ='13. NV NS Junior'!C23 | G17: =IF(E17="","",F17-E17) | H17: ='13. NV NS Junior'!C26 | I17: ='13. NV NS Junior'!H24 | J17: ='13. NV NS Junior'!H25 | K17: ='13. NV NS Junior'!H26 | L17: ='13. NV NS Junior'!C25
B19: THỐNG KÊ TOÀN PHÒNG
B20: Số vị trí xếp loại Xuất sắc | C20: =COUNTIF(H5:H17,"Xuất sắc")
B21: Số vị trí xếp loại Đạt | C21: =COUNTIF(H5:H17,"Đạt")
B22: Số vị trí xếp loại Cần cải thiện | C22: =COUNTIF(H5:H17,"Cần cải thiện")
B23: Số vị trí chưa chấm / chưa chấm đủ | C23: =COUNTIF(H5:H17,"Chưa chấm")+COUNTIF(H5:H17,"Chưa chấm đủ")
B24: Điểm bình quân phòng (vị trí đã chấm đủ) | C24: =IFERROR(AVERAGEIFS(F5:F17,H5:H17,"<>Chưa chấm",H5:H17,"<>Chưa chấm đủ"),"")
B26: Chênh lệch tô đỏ khi điểm chính thức lệch điểm tự đánh giá từ 10 điểm trở lên – nên trao đổi kỹ ở Bước 5. Nhân sự "Cần cải thiện" từ 02 kỳ liên tiếp trở lên thuộc diện đào tạo, kèm cặp (Điều 14).

Sheet So sánh
A1: SO SÁNH KẾT QUẢ GIỮA CÁC VỊ TRÍ
A2: Phụ lục 02 · Dữ liệu lấy từ sheet Tổng hợp · KK HOME ·
A4: STT | B4: Vị trí | C4: Điểm tự ĐG | D4: Điểm chính thức | E4: Chuyên môn | F4: Tuân thủ | G4: Phối hợp
A5: 1 | B5: ='Tổng hợp'!B5 | C5: =IF('Tổng hợp'!E5="",0,'Tổng hợp'!E5) | D5: ='Tổng hợp'!F5 | E5: ='Tổng hợp'!I5 | F5: ='Tổng hợp'!J5 | G5: ='Tổng hợp'!K5
A6: 2 | B6: ='Tổng hợp'!B6 | C6: =IF('Tổng hợp'!E6="",0,'Tổng hợp'!E6) | D6: ='Tổng hợp'!F6 | E6: ='Tổng hợp'!I6 | F6: ='Tổng hợp'!J6 | G6: ='Tổng hợp'!K6
A7: 3 | B7: ='Tổng hợp'!B7 | C7: =IF('Tổng hợp'!E7="",0,'Tổng hợp'!E7) | D7: ='Tổng hợp'!F7 | E7: ='Tổng hợp'!I7 | F7: ='Tổng hợp'!J7 | G7: ='Tổng hợp'!K7
A8: 4 | B8: ='Tổng hợp'!B8 | C8: =IF('Tổng hợp'!E8="",0,'Tổng hợp'!E8) | D8: ='Tổng hợp'!F8 | E8: ='Tổng hợp'!I8 | F8: ='Tổng hợp'!J8 | G8: ='Tổng hợp'!K8
A9: 5 | B9: ='Tổng hợp'!B9 | C9: =IF('Tổng hợp'!E9="",0,'Tổng hợp'!E9) | D9: ='Tổng hợp'!F9 | E9: ='Tổng hợp'!I9 | F9: ='Tổng hợp'!J9 | G9: ='Tổng hợp'!K9
A10: 6 | B10: ='Tổng hợp'!B10 | C10: =IF('Tổng hợp'!E10="",0,'Tổng hợp'!E10) | D10: ='Tổng hợp'!F10 | E10: ='Tổng hợp'!I10 | F10: ='Tổng hợp'!J10 | G10: ='Tổng hợp'!K10
A11: 7 | B11: ='Tổng hợp'!B11 | C11: =IF('Tổng hợp'!E11="",0,'Tổng hợp'!E11) | D11: ='Tổng hợp'!F11 | E11: ='Tổng hợp'!I11 | F11: ='Tổng hợp'!J11 | G11: ='Tổng hợp'!K11
A12: 8 | B12: ='Tổng hợp'!B12 | C12: =IF('Tổng hợp'!E12="",0,'Tổng hợp'!E12) | D12: ='Tổng hợp'!F12 | E12: ='Tổng hợp'!I12 | F12: ='Tổng hợp'!J12 | G12: ='Tổng hợp'!K12
A13: 9 | B13: ='Tổng hợp'!B13 | C13: =IF('Tổng hợp'!E13="",0,'Tổng hợp'!E13) | D13: ='Tổng hợp'!F13 | E13: ='Tổng hợp'!I13 | F13: ='Tổng hợp'!J13 | G13: ='Tổng hợp'!K13
A14: 10 | B14: ='Tổng hợp'!B14 | C14: =IF('Tổng hợp'!E14="",0,'Tổng hợp'!E14) | D14: ='Tổng hợp'!F14 | E14: ='Tổng hợp'!I14 | F14: ='Tổng hợp'!J14 | G14: ='Tổng hợp'!K14
A15: 11 | B15: ='Tổng hợp'!B15 | C15: =IF('Tổng hợp'!E15="",0,'Tổng hợp'!E15) | D15: ='Tổng hợp'!F15 | E15: ='Tổng hợp'!I15 | F15: ='Tổng hợp'!J15 | G15: ='Tổng hợp'!K15
A16: 12 | B16: ='Tổng hợp'!B16 | C16: =IF('Tổng hợp'!E16="",0,'Tổng hợp'!E16) | D16: ='Tổng hợp'!F16 | E16: ='Tổng hợp'!I16 | F16: ='Tổng hợp'!J16 | G16: ='Tổng hợp'!K16
A17: 13 | B17: ='Tổng hợp'!B17 | C17: =IF('Tổng hợp'!E17="",0,'Tổng hợp'!E17) | D17: ='Tổng hợp'!F17 | E17: ='Tổng hợp'!I17 | F17: ='Tổng hợp'!J17 | G17: ='Tổng hợp'!K17

Sheet Nguyên tắc chấm
A1: NGUYÊN TẮC CHẤM ĐIỂM KPI
A2: Phụ lục 02 · Căn cứ Điều 4, 6, 7, 10, 12, 13 Quy chế · KK HOME ·
B4: 1. THANG ĐIỂM 1–5 (Điều 6)
B5: Điểm | C5: Xếp hạng | D5: Diễn giải
B6: 5 | C6: Tuyệt vời | D6: Hoàn thành xuất sắc, vượt mong đợi, tự giác và chủ động
B7: 4 | C7: Tốt | D7: Hoàn thành tốt, đạt hoặc vượt mục tiêu đề ra
B8: 3 | C8: Bình thường | D8: Đáp ứng đủ yêu cầu cơ bản
B9: 2 | C9: Chưa đạt | D9: Chưa hoàn thành tốt, có lỗi nhỏ, cần cải thiện
B10: 1 | C10: Kém | D10: Chưa hoàn thành, cần hỗ trợ nhiều, sai sót lớn
B11: Kết quả dao động giữa hai mức liền kề: được chấm điểm trung bình (VD: 3.5).
B13: 2. CÔNG THỨC & XẾP LOẠI (Điều 7, Điều 13)
B14: Điểm quy đổi tiêu chí | C14: Điểm chấm ÷ 5 × Trọng số × 100
B15: Tổng điểm vị trí | C15: Cộng điểm quy đổi các tiêu chí (tối đa 100)
B16: Xuất sắc | C16: Tổng điểm ≥ 80
B17: Đạt | C17: Từ 70 đến dưới 80
B18: Cần cải thiện | C18: Dưới 70
B20: 3. GỢI Ý QUY ĐỔI CHỨNG CỨ RA ĐIỂM (mẫu – điều chỉnh theo mục tiêu đã duyệt từng kỳ)
B21: Loại chỉ số | C21: Điểm 5 | D21: Điểm 4 | E21: Điểm 3 | F21: Điểm 2 | G21: Điểm 1
B22: Tỷ lệ hoàn thành kế hoạch (tuyển dụng, đào tạo, sự kiện…) | C22: ≥ 110% hoặc vượt rõ mục tiêu | D22: 100% – dưới 110% | E22: 90% – dưới 100% | F22: 75% – dưới 90% | G22: Dưới 75%
B23: Số lỗi, sai sót (bảng lương, BHXH, hồ sơ, chấm công…) | C23: 0 lỗi, chủ động phát hiện lỗi của khâu khác | D23: 0 lỗi | E23: 1–2 lỗi nhỏ, sửa kịp, không ảnh hưởng | F23: ≥ 3 lỗi nhỏ hoặc 1 lỗi phải điều chỉnh sau chi trả/nộp | G23: Lỗi gây thiệt hại, bị xử phạt hoặc khiếu nại
B24: Thời hạn (kỳ lương, thủ tục, báo cáo) | C24: 100% đúng hạn, nhiều việc xong sớm | D24: 100% đúng hạn | E24: ≥ 90% đúng hạn, trễ không ảnh hưởng | F24: 75% – dưới 90%, hoặc 1 lần trễ gây ảnh hưởng | G24: Dưới 75%, hoặc trễ dẫn tới bị phạt, chậm đóng
B25: Chi phí so với ngân sách | C25: Tiết kiệm ≥ 10% và vẫn đạt mục tiêu | D25: Trong ngân sách | E25: Vượt ≤ 5%, có giải trình được duyệt | F25: Vượt 5% – 10% | G25: Vượt > 10%
B26: Khảo sát hài lòng / phản hồi (thang 5) | C26: ≥ 4,5 | D26: 4,0 – dưới 4,5 | E26: 3,5 – dưới 4,0 | F26: 3,0 – dưới 3,5 | G26: Dưới 3,0
B27: Tuân thủ pháp luật, bảo mật | C27: Không vi phạm, chủ động rà soát và cảnh báo rủi ro | D27: Không vi phạm | E27: Có nhắc nhở nội bộ, đã khắc phục | F27: Vi phạm quy trình nội bộ lặp lại | G27: Bị cơ quan nhà nước xử phạt hoặc rò rỉ dữ liệu
B29: 4. NGUYÊN TẮC ĐÁNH GIÁ (Điều 4, Điều 12)
B30: Khách quan | C30: Chấm theo kết quả thực tế, không theo thiện cảm cá nhân.
B31: Công bằng | C31: Cùng vị trí dùng chung bộ tiêu chí, trọng số, thang điểm.
B32: Công khai | C32: Tiêu chí, trọng số, chỉ tiêu định lượng phổ biến cho nhân sự trước kỳ đánh giá.
B33: Định kỳ | C33: Loại kỳ (Tháng/Quý/Năm) áp dụng thống nhất cho toàn phòng trong cùng chu kỳ.
B34: Có phản hồi | C34: Trao đổi kết quả trực tiếp, thống nhất kế hoạch cải thiện.
B35: Có chứng cứ | C35: Số liệu, thời hạn, biên bản, báo cáo. Điểm ≤ 1,5 hoặc = 5 phải ghi lý do ở cột Ghi chú.
B37: 5. QUY TRÌNH 6 BƯỚC (Điều 10)
B38: Bước 1 – Chuẩn bị | C38: Xác định kỳ, thông báo lịch, phổ biến tiêu chí.
B39: Bước 2 – Tự đánh giá | C39: Nhân sự chấm cột F.
B40: Bước 3 – Quản lý chấm | C40: Quản lý trực tiếp chấm chính thức cột G, dựa trên chứng cứ.
B41: Bước 4 – Tổng hợp | C41: File tự tính điểm quy đổi, xếp loại; sheet Tổng hợp tự cập nhật.
B42: Bước 5 – Phản hồi | C42: Trao đổi kết quả, ghi nhận xét và kế hoạch cải thiện cuối sheet vị trí.
B43: Bước 6 – Phê duyệt, lưu trữ | C43: Trình người có thẩm quyền ký duyệt; lưu hồ sơ làm căn cứ lương, thưởng, quy hoạch.

Sheet 01. Trưởng phòng NS
A1: BẢNG ĐÁNH GIÁ KPI – TRƯỞNG PHÒNG NHÂN SỰ
A2: Phòng Nhân sự · Phụ lục 02 kèm Quy chế đánh giá KPI · KK HOME ·
B4: Họ và tên | E4: Loại kỳ đánh giá | G4: Quý | I4: ← chọn Tháng / Quý / Năm
B5: Mã nhân viên | E5: Kỳ đánh giá | I5: VD: Tháng 9/2026, Quý 3/2026, Năm 2026
B6: Người đánh giá | E6: Ngày đánh giá
B7: Bộ phận | C7: Phòng Nhân sự
A9: STT | B9: Nhóm tiêu chí | C9: Tiêu chí đánh giá | D9: Cách đo / Chứng cứ chấm điểm | E9: Trọng số | F9: Tự đánh giá (1–5) | G9: Quản lý chấm (1–5) | H9: Điểm quy đổi | I9: Ghi chú / Lý do (bắt buộc khi điểm ≤1,5 hoặc 5)
A10: 1 | B10: Chuyên môn - Nghiệp vụ | C10: Hoạch định nhân lực & ngân sách nhân sự | D10: Kế hoạch định biên, ngân sách quỹ lương trình duyệt đúng hạn; chi phí nhân sự thực tế lệch ngân sách không quá 5% | E10: 0.1 | H10: =IF(ISNUMBER(G10),G10/5*E10*100,0) | J10: CM
A11: 2 | C11: Hiệu quả tuyển dụng toàn công ty | D11: Tỷ lệ vị trí tuyển đủ, đúng hạn ≥ 90%; tỷ lệ nhân sự mới qua thử việc ≥ 85% | E11: 0.1 | H11: =IF(ISNUMBER(G11),G11/5*E11*100,0) | J11: CM
A12: 3 | C12: Tỷ lệ giữ chân nhân sự | D12: Tỷ lệ nghỉ việc tự nguyện so với mục tiêu đã duyệt; số nhân sự then chốt nghỉ việc trong kỳ | E12: 0.1 | H12: =IF(ISNUMBER(G12),G12/5*E12*100,0) | J12: CM
A13: 4 | C13: Xây dựng & vận hành hệ thống chính sách nhân sự | D13: Số quy chế (lương, thưởng, KPI, đào tạo) ban hành/cập nhật theo kế hoạch; mức độ các phòng áp dụng thực tế | E13: 0.1 | H13: =IF(ISNUMBER(G13),G13/5*E13*100,0) | J13: CM
A14: 5 | B14: Tuân thủ - Thời hạn | C14: Tuân thủ pháp luật lao động, BHXH, thuế TNCN | D14: Số lỗi bị cơ quan nhà nước nhắc nhở, xử phạt = 0; không phát sinh tranh chấp lao động do sai thủ tục | E14: 0.15 | H14: =IF(ISNUMBER(G14),G14/5*E14*100,0) | J14: TT
A15: 6 | C15: Tiến độ kỳ lương & báo cáo nhân sự | D15: Bảng lương duyệt đúng lịch; báo cáo nhân sự định kỳ nộp Ban lãnh đạo đúng hạn | E15: 0.1 | H15: =IF(ISNUMBER(G15),G15/5*E15*100,0) | J15: TT
A16: 7 | C16: Kiểm soát rủi ro & bảo mật dữ liệu nhân sự | D16: Hồ sơ, dữ liệu lương có phân quyền; không phát sinh rò rỉ thông tin nhân sự | E16: 0.1 | H16: =IF(ISNUMBER(G16),G16/5*E16*100,0) | J16: TT
A17: 8 | B17: Phối hợp - Thái độ | C17: Lãnh đạo & phát triển đội ngũ Phòng Nhân sự | D17: Điểm KPI bình quân của phòng; số nhân viên được kèm cặp, có lộ trình phát triển | E17: 0.1 | H17: =IF(ISNUMBER(G17),G17/5*E17*100,0) | J17: PH
A18: 9 | C18: Phối hợp với các trưởng bộ phận | D18: Phản hồi của trưởng bộ phận về hỗ trợ nhân sự; thời gian xử lý đề xuất nhân sự | E18: 0.08 | H18: =IF(ISNUMBER(G18),G18/5*E18*100,0) | J18: PH
A19: 10 | C19: Tinh thần trách nhiệm & chủ động cải tiến | D19: Số sáng kiến cải tiến quy trình nhân sự được áp dụng | E19: 0.07 | H19: =IF(ISNUMBER(G19),G19/5*E19*100,0) | J19: PH
A20: TỔNG CỘNG | E20: =SUM(E10:E19) | H20: =SUM(H10:H19)
A22: KẾT QUẢ ĐÁNH GIÁ | D22: ĐIỂM THEO NHÓM TIÊU CHÍ
A23: Tổng điểm chính thức | C23: =H20 | D23: Nhóm tiêu chí | E23: Trọng số | F23: Điểm tối đa | G23: Điểm đạt | H23: Tỷ lệ đạt
A24: Điểm tự đánh giá | C24: =IF(COUNT(F10:F19)=0,"",SUMPRODUCT(F10:F19,E10:E19)/5*100) | D24: Chuyên môn - Nghiệp vụ | E24: =SUMIF($J$10:$J$19,"CM",$E$10:$E$19) | F24: =E24*100 | G24: =SUMIF($J$10:$J$19,"CM",$H$10:$H$19) | H24: =IF(F24=0,0,G24/F24)
A25: Tiêu chí đã chấm | C25: =COUNT(G10:G19)&" / 10" | D25: Tuân thủ - Thời hạn | E25: =SUMIF($J$10:$J$19,"TT",$E$10:$E$19) | F25: =E25*100 | G25: =SUMIF($J$10:$J$19,"TT",$H$10:$H$19) | H25: =IF(F25=0,0,G25/F25)
A26: Xếp loại | C26: =IF(COUNT(G10:G19)=0,"Chưa chấm",IF(COUNT(G10:G19)<10,"Chưa chấm đủ",IF(H20>=80,"Xuất sắc",IF(H20>=70,"Đạt","Cần cải thiện")))) | D26: Phối hợp - Thái độ | E26: =SUMIF($J$10:$J$19,"PH",$E$10:$E$19) | F26: =E26*100 | G26: =SUMIF($J$10:$J$19,"PH",$H$10:$H$19) | H26: =IF(F26=0,0,G26/F26)
A27: Kiểm tra trọng số | C27: =IF(ROUND(E20,4)=1,"Hợp lệ – 100%","SAI – tổng trọng số phải = 100%")
A29: NHẬN XÉT & KẾ HOẠCH CẢI THIỆN (Bước 5 – phản hồi kết quả)
A30: Điểm mạnh
A31: Cần cải thiện
A32: Kế hoạch cải thiện
A33: Ý kiến nhân sự
B35: NHÂN SỰ ĐƯỢC ĐÁNH GIÁ | D35: QUẢN LÝ TRỰC TIẾP | G35: NGƯỜI PHÊ DUYỆT
B36: (Ký, ghi rõ họ tên) | D36: (Ký, ghi rõ họ tên) | G36: (Ký, ghi rõ họ tên)

Sheet 02. Phó phòng NS
A1: BẢNG ĐÁNH GIÁ KPI – PHÓ PHÒNG NHÂN SỰ
A2: Phòng Nhân sự · Phụ lục 02 kèm Quy chế đánh giá KPI · KK HOME ·
B4: Họ và tên | E4: Loại kỳ đánh giá | G4: Quý | I4: ← chọn Tháng / Quý / Năm
B5: Mã nhân viên | E5: Kỳ đánh giá | I5: VD: Tháng 9/2026, Quý 3/2026, Năm 2026
B6: Người đánh giá | E6: Ngày đánh giá
B7: Bộ phận | C7: Phòng Nhân sự
A9: STT | B9: Nhóm tiêu chí | C9: Tiêu chí đánh giá | D9: Cách đo / Chứng cứ chấm điểm | E9: Trọng số | F9: Tự đánh giá (1–5) | G9: Quản lý chấm (1–5) | H9: Điểm quy đổi | I9: Ghi chú / Lý do (bắt buộc khi điểm ≤1,5 hoặc 5)
A10: 1 | B10: Chuyên môn - Nghiệp vụ | C10: Kết quả các mảng được phân công | D10: Tỷ lệ hoàn thành chỉ tiêu KPI của các mảng Trưởng phòng giao | E10: 0.12 | H10: =IF(ISNUMBER(G10),G10/5*E10*100,0) | J10: CM
A11: 2 | C11: Soát xét hồ sơ, bảng lương trước khi trình duyệt | D11: Số lỗi lọt qua khâu soát xét, bị phát hiện ở cấp phê duyệt = 0 | E11: 0.1 | H11: =IF(ISNUMBER(G11),G11/5*E11*100,0) | J11: CM
A12: 3 | C12: Triển khai chính sách, quy chế nhân sự | D12: Tỷ lệ chính sách triển khai đúng kế hoạch, có văn bản hướng dẫn cho các phòng | E12: 0.1 | H12: =IF(ISNUMBER(G12),G12/5*E12*100,0) | J12: CM
A13: 4 | C13: Điều hành thay khi Trưởng phòng vắng mặt | D13: Công việc không gián đoạn; xử lý đúng phạm vi ủy quyền | E13: 0.08 | H13: =IF(ISNUMBER(G13),G13/5*E13*100,0) | J13: CM
A14: 5 | B14: Tuân thủ - Thời hạn | C14: Tuân thủ pháp luật trong mảng phụ trách | D14: Không phát sinh sai phạm về lao động, BHXH, thuế TNCN thuộc mảng phụ trách | E14: 0.15 | H14: =IF(ISNUMBER(G14),G14/5*E14*100,0) | J14: TT
A15: 6 | C15: Tiến độ công việc của nhóm | D15: Tỷ lệ đầu việc của nhóm hoàn thành đúng hạn | E15: 0.1 | H15: =IF(ISNUMBER(G15),G15/5*E15*100,0) | J15: TT
A16: 7 | C16: Báo cáo định kỳ cho Trưởng phòng | D16: Nộp đúng hạn; số liệu khớp với hồ sơ gốc | E16: 0.1 | H16: =IF(ISNUMBER(G16),G16/5*E16*100,0) | J16: TT
A17: 8 | B17: Phối hợp - Thái độ | C17: Kèm cặp, đào tạo nhân viên | D17: Số nhân viên được kèm cặp; điểm KPI của nhóm phụ trách | E17: 0.1 | H17: =IF(ISNUMBER(G17),G17/5*E17*100,0) | J17: PH
A18: 9 | C18: Phối hợp liên phòng ban | D18: Phản hồi của các phòng; số yêu cầu tồn đọng quá hạn | E18: 0.08 | H18: =IF(ISNUMBER(G18),G18/5*E18*100,0) | J18: PH
A19: 10 | C19: Tinh thần trách nhiệm & chủ động | D19: Đề xuất cải tiến; chủ động xử lý phát sinh không chờ chỉ đạo | E19: 0.07 | H19: =IF(ISNUMBER(G19),G19/5*E19*100,0) | J19: PH
A20: TỔNG CỘNG | E20: =SUM(E10:E19) | H20: =SUM(H10:H19)
A22: KẾT QUẢ ĐÁNH GIÁ | D22: ĐIỂM THEO NHÓM TIÊU CHÍ
A23: Tổng điểm chính thức | C23: =H20 | D23: Nhóm tiêu chí | E23: Trọng số | F23: Điểm tối đa | G23: Điểm đạt | H23: Tỷ lệ đạt
A24: Điểm tự đánh giá | C24: =IF(COUNT(F10:F19)=0,"",SUMPRODUCT(F10:F19,E10:E19)/5*100) | D24: Chuyên môn - Nghiệp vụ | E24: =SUMIF($J$10:$J$19,"CM",$E$10:$E$19) | F24: =E24*100 | G24: =SUMIF($J$10:$J$19,"CM",$H$10:$H$19) | H24: =IF(F24=0,0,G24/F24)
A25: Tiêu chí đã chấm | C25: =COUNT(G10:G19)&" / 10" | D25: Tuân thủ - Thời hạn | E25: =SUMIF($J$10:$J$19,"TT",$E$10:$E$19) | F25: =E25*100 | G25: =SUMIF($J$10:$J$19,"TT",$H$10:$H$19) | H25: =IF(F25=0,0,G25/F25)
A26: Xếp loại | C26: =IF(COUNT(G10:G19)=0,"Chưa chấm",IF(COUNT(G10:G19)<10,"Chưa chấm đủ",IF(H20>=80,"Xuất sắc",IF(H20>=70,"Đạt","Cần cải thiện")))) | D26: Phối hợp - Thái độ | E26: =SUMIF($J$10:$J$19,"PH",$E$10:$E$19) | F26: =E26*100 | G26: =SUMIF($J$10:$J$19,"PH",$H$10:$H$19) | H26: =IF(F26=0,0,G26/F26)
A27: Kiểm tra trọng số | C27: =IF(ROUND(E20,4)=1,"Hợp lệ – 100%","SAI – tổng trọng số phải = 100%")
A29: NHẬN XÉT & KẾ HOẠCH CẢI THIỆN (Bước 5 – phản hồi kết quả)
A30: Điểm mạnh
A31: Cần cải thiện
A32: Kế hoạch cải thiện
A33: Ý kiến nhân sự
B35: NHÂN SỰ ĐƯỢC ĐÁNH GIÁ | D35: QUẢN LÝ TRỰC TIẾP | G35: NGƯỜI PHÊ DUYỆT
B36: (Ký, ghi rõ họ tên) | D36: (Ký, ghi rõ họ tên) | G36: (Ký, ghi rõ họ tên)

Sheet 03. HRBP
A1: BẢNG ĐÁNH GIÁ KPI – CHUYÊN VIÊN ĐỐI TÁC NHÂN SỰ (HRBP)
A2: Phòng Nhân sự · Phụ lục 02 kèm Quy chế đánh giá KPI · KK HOME ·
B4: Họ và tên | E4: Loại kỳ đánh giá | G4: Quý | I4: ← chọn Tháng / Quý / Năm
B5: Mã nhân viên | E5: Kỳ đánh giá | I5: VD: Tháng 9/2026, Quý 3/2026, Năm 2026
B6: Người đánh giá | E6: Ngày đánh giá
B7: Bộ phận | C7: Phòng Nhân sự
A9: STT | B9: Nhóm tiêu chí | C9: Tiêu chí đánh giá | D9: Cách đo / Chứng cứ chấm điểm | E9: Trọng số | F9: Tự đánh giá (1–5) | G9: Quản lý chấm (1–5) | H9: Điểm quy đổi | I9: Ghi chú / Lý do (bắt buộc khi điểm ≤1,5 hoặc 5)
A10: 1 | B10: Chuyên môn - Nghiệp vụ | C10: Kế hoạch nhân sự bám mục tiêu kinh doanh của khối | D10: Kế hoạch nhân sự của khối phụ trách được duyệt, gắn với chỉ tiêu kinh doanh | E10: 0.1 | H10: =IF(ISNUMBER(G10),G10/5*E10*100,0) | J10: CM
A11: 2 | C11: Tư vấn quản lý về vấn đề con người | D11: Số vấn đề (hiệu suất, kỷ luật, cơ cấu) được tư vấn và xử lý dứt điểm | E11: 0.1 | H11: =IF(ISNUMBER(G11),G11/5*E11*100,0) | J11: CM
A12: 3 | C12: Tỷ lệ nghỉ việc tại khối phụ trách | D12: Tỷ lệ nghỉ việc tự nguyện so với mục tiêu của khối | E12: 0.1 | H12: =IF(ISNUMBER(G12),G12/5*E12*100,0) | J12: CM
A13: 4 | C13: Quản trị hiệu suất tại khối phụ trách | D13: Tỷ lệ nhân sự được đánh giá KPI đúng kỳ; nhân sự "Cần cải thiện" có kế hoạch cải thiện | E13: 0.1 | H13: =IF(ISNUMBER(G13),G13/5*E13*100,0) | J13: CM
A14: 5 | B14: Tuân thủ - Thời hạn | C14: Áp dụng đúng chính sách nhân sự | D14: Số trường hợp áp dụng sai quy chế tại khối = 0 | E14: 0.12 | H14: =IF(ISNUMBER(G14),G14/5*E14*100,0) | J14: TT
A15: 6 | C15: Tiến độ các kế hoạch nhân sự của khối | D15: Đầu việc tuyển dụng, đào tạo, luân chuyển hoàn thành đúng mốc | E15: 0.12 | H15: =IF(ISNUMBER(G15),G15/5*E15*100,0) | J15: TT
A16: 7 | C16: Kiểm soát rủi ro quan hệ lao động | D16: Rủi ro được ghi nhận và báo sớm; không có khiếu nại vượt cấp | E16: 0.11 | H16: =IF(ISNUMBER(G16),G16/5*E16*100,0) | J16: TT
A17: 8 | B17: Phối hợp - Thái độ | C17: Mức hài lòng của quản lý khối | D17: Điểm khảo sát định kỳ của quản lý khối phụ trách | E17: 0.1 | H17: =IF(ISNUMBER(G17),G17/5*E17*100,0) | J17: PH
A18: 9 | C18: Kết nối Phòng Nhân sự với khối | D18: Yêu cầu, phản hồi chuyển đúng đầu mối, đúng hạn | E18: 0.08 | H18: =IF(ISNUMBER(G18),G18/5*E18*100,0) | J18: PH
A19: 10 | C19: Tinh thần trách nhiệm & chủ động | D19: Chủ động đề xuất giải pháp nhân sự cho khối | E19: 0.07 | H19: =IF(ISNUMBER(G19),G19/5*E19*100,0) | J19: PH
A20: TỔNG CỘNG | E20: =SUM(E10:E19) | H20: =SUM(H10:H19)
A22: KẾT QUẢ ĐÁNH GIÁ | D22: ĐIỂM THEO NHÓM TIÊU CHÍ
A23: Tổng điểm chính thức | C23: =H20 | D23: Nhóm tiêu chí | E23: Trọng số | F23: Điểm tối đa | G23: Điểm đạt | H23: Tỷ lệ đạt
A24: Điểm tự đánh giá | C24: =IF(COUNT(F10:F19)=0,"",SUMPRODUCT(F10:F19,E10:E19)/5*100) | D24: Chuyên môn - Nghiệp vụ | E24: =SUMIF($J$10:$J$19,"CM",$E$10:$E$19) | F24: =E24*100 | G24: =SUMIF($J$10:$J$19,"CM",$H$10:$H$19) | H24: =IF(F24=0,0,G24/F24)
A25: Tiêu chí đã chấm | C25: =COUNT(G10:G19)&" / 10" | D25: Tuân thủ - Thời hạn | E25: =SUMIF($J$10:$J$19,"TT",$E$10:$E$19) | F25: =E25*100 | G25: =SUMIF($J$10:$J$19,"TT",$H$10:$H$19) | H25: =IF(F25=0,0,G25/F25)
A26: Xếp loại | C26: =IF(COUNT(G10:G19)=0,"Chưa chấm",IF(COUNT(G10:G19)<10,"Chưa chấm đủ",IF(H20>=80,"Xuất sắc",IF(H20>=70,"Đạt","Cần cải thiện")))) | D26: Phối hợp - Thái độ | E26: =SUMIF($J$10:$J$19,"PH",$E$10:$E$19) | F26: =E26*100 | G26: =SUMIF($J$10:$J$19,"PH",$H$10:$H$19) | H26: =IF(F26=0,0,G26/F26)
A27: Kiểm tra trọng số | C27: =IF(ROUND(E20,4)=1,"Hợp lệ – 100%","SAI – tổng trọng số phải = 100%")
A29: NHẬN XÉT & KẾ HOẠCH CẢI THIỆN (Bước 5 – phản hồi kết quả)
A30: Điểm mạnh
A31: Cần cải thiện
A32: Kế hoạch cải thiện
A33: Ý kiến nhân sự
B35: NHÂN SỰ ĐƯỢC ĐÁNH GIÁ | D35: QUẢN LÝ TRỰC TIẾP | G35: NGƯỜI PHÊ DUYỆT
B36: (Ký, ghi rõ họ tên) | D36: (Ký, ghi rõ họ tên) | G36: (Ký, ghi rõ họ tên)

Sheet 04. Trưởng nhóm TD
A1: BẢNG ĐÁNH GIÁ KPI – TRƯỞNG NHÓM TUYỂN DỤNG
A2: Phòng Nhân sự · Phụ lục 02 kèm Quy chế đánh giá KPI · KK HOME ·
B4: Họ và tên | E4: Loại kỳ đánh giá | G4: Quý | I4: ← chọn Tháng / Quý / Năm
B5: Mã nhân viên | E5: Kỳ đánh giá | I5: VD: Tháng 9/2026, Quý 3/2026, Năm 2026
B6: Người đánh giá | E6: Ngày đánh giá
B7: Bộ phận | C7: Phòng Nhân sự
A9: STT | B9: Nhóm tiêu chí | C9: Tiêu chí đánh giá | D9: Cách đo / Chứng cứ chấm điểm | E9: Trọng số | F9: Tự đánh giá (1–5) | G9: Quản lý chấm (1–5) | H9: Điểm quy đổi | I9: Ghi chú / Lý do (bắt buộc khi điểm ≤1,5 hoặc 5)
A10: 1 | B10: Chuyên môn - Nghiệp vụ | C10: Hoàn thành kế hoạch tuyển dụng của nhóm | D10: Số vị trí tuyển đủ / số vị trí được giao trong kỳ | E10: 0.12 | H10: =IF(ISNUMBER(G10),G10/5*E10*100,0) | J10: CM
A11: 2 | C11: Thời gian tuyển dụng bình quân | D11: Số ngày bình quân từ khi duyệt yêu cầu đến khi ứng viên nhận việc, so với định mức từng cấp bậc | E11: 0.1 | H11: =IF(ISNUMBER(G11),G11/5*E11*100,0) | J11: CM
A12: 3 | C12: Chất lượng tuyển dụng | D12: Tỷ lệ qua thử việc; tỷ lệ nhân sự mới gắn bó sau 6 tháng | E12: 0.1 | H12: =IF(ISNUMBER(G12),G12/5*E12*100,0) | J12: CM
A13: 4 | C13: Phát triển kênh & thương hiệu tuyển dụng | D13: Số kênh tuyển dụng hiệu quả; tỷ lệ ứng viên từ giới thiệu nội bộ | E13: 0.08 | H13: =IF(ISNUMBER(G13),G13/5*E13*100,0) | J13: CM
A14: 5 | B14: Tuân thủ - Thời hạn | C14: Kiểm soát ngân sách tuyển dụng | D14: Chi phí tuyển dụng thực tế so với ngân sách được duyệt | E14: 0.12 | H14: =IF(ISNUMBER(G14),G14/5*E14*100,0) | J14: TT
A15: 6 | C15: Tuân thủ quy trình, không phân biệt đối xử | D15: Tin tuyển dụng, câu hỏi phỏng vấn không có nội dung phân biệt giới tính, độ tuổi, tình trạng hôn nhân | E15: 0.12 | H15: =IF(ISNUMBER(G15),G15/5*E15*100,0) | J15: TT
A16: 7 | C16: Báo cáo tuyển dụng | D16: Báo cáo tuần/tháng nộp đúng hạn, số liệu khớp dữ liệu ứng viên | E16: 0.11 | H16: =IF(ISNUMBER(G16),G16/5*E16*100,0) | J16: TT
A17: 8 | B17: Phối hợp - Thái độ | C17: Quản lý, kèm cặp nhóm tuyển dụng | D17: Điểm KPI bình quân của nhóm; số thành viên được kèm cặp | E17: 0.1 | H17: =IF(ISNUMBER(G17),G17/5*E17*100,0) | J17: PH
A18: 9 | C18: Phối hợp với trưởng bộ phận có nhu cầu tuyển | D18: Thời gian phản hồi yêu cầu; mức hài lòng của trưởng bộ phận | E18: 0.08 | H18: =IF(ISNUMBER(G18),G18/5*E18*100,0) | J18: PH
A19: 10 | C19: Tinh thần trách nhiệm & chủ động | D19: Xây dựng nguồn ứng viên dự phòng cho vị trí then chốt | E19: 0.07 | H19: =IF(ISNUMBER(G19),G19/5*E19*100,0) | J19: PH
A20: TỔNG CỘNG | E20: =SUM(E10:E19) | H20: =SUM(H10:H19)
A22: KẾT QUẢ ĐÁNH GIÁ | D22: ĐIỂM THEO NHÓM TIÊU CHÍ
A23: Tổng điểm chính thức | C23: =H20 | D23: Nhóm tiêu chí | E23: Trọng số | F23: Điểm tối đa | G23: Điểm đạt | H23: Tỷ lệ đạt
A24: Điểm tự đánh giá | C24: =IF(COUNT(F10:F19)=0,"",SUMPRODUCT(F10:F19,E10:E19)/5*100) | D24: Chuyên môn - Nghiệp vụ | E24: =SUMIF($J$10:$J$19,"CM",$E$10:$E$19) | F24: =E24*100 | G24: =SUMIF($J$10:$J$19,"CM",$H$10:$H$19) | H24: =IF(F24=0,0,G24/F24)
A25: Tiêu chí đã chấm | C25: =COUNT(G10:G19)&" / 10" | D25: Tuân thủ - Thời hạn | E25: =SUMIF($J$10:$J$19,"TT",$E$10:$E$19) | F25: =E25*100 | G25: =SUMIF($J$10:$J$19,"TT",$H$10:$H$19) | H25: =IF(F25=0,0,G25/F25)
A26: Xếp loại | C26: =IF(COUNT(G10:G19)=0,"Chưa chấm",IF(COUNT(G10:G19)<10,"Chưa chấm đủ",IF(H20>=80,"Xuất sắc",IF(H20>=70,"Đạt","Cần cải thiện")))) | D26: Phối hợp - Thái độ | E26: =SUMIF($J$10:$J$19,"PH",$E$10:$E$19) | F26: =E26*100 | G26: =SUMIF($J$10:$J$19,"PH",$H$10:$H$19) | H26: =IF(F26=0,0,G26/F26)
A27: Kiểm tra trọng số | C27: =IF(ROUND(E20,4)=1,"Hợp lệ – 100%","SAI – tổng trọng số phải = 100%")
A29: NHẬN XÉT & KẾ HOẠCH CẢI THIỆN (Bước 5 – phản hồi kết quả)
A30: Điểm mạnh
A31: Cần cải thiện
A32: Kế hoạch cải thiện
A33: Ý kiến nhân sự
B35: NHÂN SỰ ĐƯỢC ĐÁNH GIÁ | D35: QUẢN LÝ TRỰC TIẾP | G35: NGƯỜI PHÊ DUYỆT
B36: (Ký, ghi rõ họ tên) | D36: (Ký, ghi rõ họ tên) | G36: (Ký, ghi rõ họ tên)

Sheet 05. CV Tuyển dụng
A1: BẢNG ĐÁNH GIÁ KPI – CHUYÊN VIÊN TUYỂN DỤNG
A2: Phòng Nhân sự · Phụ lục 02 kèm Quy chế đánh giá KPI · KK HOME ·
B4: Họ và tên | E4: Loại kỳ đánh giá | G4: Quý | I4: ← chọn Tháng / Quý / Năm
B5: Mã nhân viên | E5: Kỳ đánh giá | I5: VD: Tháng 9/2026, Quý 3/2026, Năm 2026
B6: Người đánh giá | E6: Ngày đánh giá
B7: Bộ phận | C7: Phòng Nhân sự
A9: STT | B9: Nhóm tiêu chí | C9: Tiêu chí đánh giá | D9: Cách đo / Chứng cứ chấm điểm | E9: Trọng số | F9: Tự đánh giá (1–5) | G9: Quản lý chấm (1–5) | H9: Điểm quy đổi | I9: Ghi chú / Lý do (bắt buộc khi điểm ≤1,5 hoặc 5)
A10: 1 | B10: Chuyên môn - Nghiệp vụ | C10: Tỷ lệ hoàn thành kế hoạch tuyển dụng | D10: Số vị trí tuyển đủ / số vị trí được giao trong kỳ | E10: 0.12 | H10: =IF(ISNUMBER(G10),G10/5*E10*100,0) | J10: CM
A11: 2 | C11: Thời gian tuyển dụng (time-to-fill) | D11: Số ngày bình quân từ khi duyệt yêu cầu đến khi ứng viên nhận việc, so với định mức | E11: 0.1 | H11: =IF(ISNUMBER(G11),G11/5*E11*100,0) | J11: CM
A12: 3 | C12: Chất lượng tuyển dụng | D12: Tỷ lệ nhân sự mới qua thử việc; đánh giá của quản lý trực tiếp sau 2 tháng | E12: 0.1 | H12: =IF(ISNUMBER(G12),G12/5*E12*100,0) | J12: CM
A13: 4 | C13: Chi phí tuyển dụng | D13: Chi phí bình quân cho 1 nhân sự tuyển được so với ngân sách | E13: 0.08 | H13: =IF(ISNUMBER(G13),G13/5*E13*100,0) | J13: CM
A14: 5 | B14: Tuân thủ - Thời hạn | C14: Tuân thủ quy trình tuyển dụng | D14: Đủ bước: yêu cầu tuyển được duyệt, phiếu chấm phỏng vấn, thư mời nhận việc đúng mẫu | E14: 0.12 | H14: =IF(ISNUMBER(G14),G14/5*E14*100,0) | J14: TT
A15: 6 | C15: Hồ sơ nhân sự mới đầy đủ | D15: Tỷ lệ hồ sơ đủ giấy tờ trước ngày nhận việc | E15: 0.08 | H15: =IF(ISNUMBER(G15),G15/5*E15*100,0) | J15: TT
A16: 7 | C16: Tiến độ báo cáo tuyển dụng | D16: Báo cáo tuần/tháng nộp đúng hạn, số liệu khớp | E16: 0.08 | H16: =IF(ISNUMBER(G16),G16/5*E16*100,0) | J16: TT
A17: 8 | C17: Bảo mật thông tin ứng viên | D17: Không để lộ dữ liệu cá nhân ứng viên; lưu trữ và hủy hồ sơ theo quy định nội bộ | E17: 0.07 | H17: =IF(ISNUMBER(G17),G17/5*E17*100,0) | J17: TT
A18: 9 | B18: Phối hợp - Thái độ | C18: Phối hợp với bộ phận có nhu cầu tuyển | D18: Thời gian phản hồi yêu cầu; mức hài lòng của trưởng bộ phận | E18: 0.1 | H18: =IF(ISNUMBER(G18),G18/5*E18*100,0) | J18: PH
A19: 10 | C19: Trải nghiệm ứng viên | D19: Tỷ lệ ứng viên được phản hồi kết quả trong 3 ngày làm việc sau phỏng vấn | E19: 0.08 | H19: =IF(ISNUMBER(G19),G19/5*E19*100,0) | J19: PH
A20: 11 | C20: Tinh thần trách nhiệm & chủ động | D20: Tự xây dựng nguồn ứng viên dự phòng (talent pool) | E20: 0.07 | H20: =IF(ISNUMBER(G20),G20/5*E20*100,0) | J20: PH
A21: TỔNG CỘNG | E21: =SUM(E10:E20) | H21: =SUM(H10:H20)
A23: KẾT QUẢ ĐÁNH GIÁ | D23: ĐIỂM THEO NHÓM TIÊU CHÍ
A24: Tổng điểm chính thức | C24: =H21 | D24: Nhóm tiêu chí | E24: Trọng số | F24: Điểm tối đa | G24: Điểm đạt | H24: Tỷ lệ đạt
A25: Điểm tự đánh giá | C25: =IF(COUNT(F10:F20)=0,"",SUMPRODUCT(F10:F20,E10:E20)/5*100) | D25: Chuyên môn - Nghiệp vụ | E25: =SUMIF($J$10:$J$20,"CM",$E$10:$E$20) | F25: =E25*100 | G25: =SUMIF($J$10:$J$20,"CM",$H$10:$H$20) | H25: =IF(F25=0,0,G25/F25)
A26: Tiêu chí đã chấm | C26: =COUNT(G10:G20)&" / 11" | D26: Tuân thủ - Thời hạn | E26: =SUMIF($J$10:$J$20,"TT",$E$10:$E$20) | F26: =E26*100 | G26: =SUMIF($J$10:$J$20,"TT",$H$10:$H$20) | H26: =IF(F26=0,0,G26/F26)
A27: Xếp loại | C27: =IF(COUNT(G10:G20)=0,"Chưa chấm",IF(COUNT(G10:G20)<11,"Chưa chấm đủ",IF(H21>=80,"Xuất sắc",IF(H21>=70,"Đạt","Cần cải thiện")))) | D27: Phối hợp - Thái độ | E27: =SUMIF($J$10:$J$20,"PH",$E$10:$E$20) | F27: =E27*100 | G27: =SUMIF($J$10:$J$20,"PH",$H$10:$H$20) | H27: =IF(F27=0,0,G27/F27)
A28: Kiểm tra trọng số | C28: =IF(ROUND(E21,4)=1,"Hợp lệ – 100%","SAI – tổng trọng số phải = 100%")
A30: NHẬN XÉT & KẾ HOẠCH CẢI THIỆN (Bước 5 – phản hồi kết quả)
A31: Điểm mạnh
A32: Cần cải thiện
A33: Kế hoạch cải thiện
A34: Ý kiến nhân sự
B36: NHÂN SỰ ĐƯỢC ĐÁNH GIÁ | D36: QUẢN LÝ TRỰC TIẾP | G36: NGƯỜI PHÊ DUYỆT
B37: (Ký, ghi rõ họ tên) | D37: (Ký, ghi rõ họ tên) | G37: (Ký, ghi rõ họ tên)

Sheet 06. CV Lương-Phúc lợi
A1: BẢNG ĐÁNH GIÁ KPI – CHUYÊN VIÊN LƯƠNG & PHÚC LỢI (C&B)
A2: Phòng Nhân sự · Phụ lục 02 kèm Quy chế đánh giá KPI · KK HOME ·
B4: Họ và tên | E4: Loại kỳ đánh giá | G4: Quý | I4: ← chọn Tháng / Quý / Năm
B5: Mã nhân viên | E5: Kỳ đánh giá | I5: VD: Tháng 9/2026, Quý 3/2026, Năm 2026
B6: Người đánh giá | E6: Ngày đánh giá
B7: Bộ phận | C7: Phòng Nhân sự
A9: STT | B9: Nhóm tiêu chí | C9: Tiêu chí đánh giá | D9: Cách đo / Chứng cứ chấm điểm | E9: Trọng số | F9: Tự đánh giá (1–5) | G9: Quản lý chấm (1–5) | H9: Điểm quy đổi | I9: Ghi chú / Lý do (bắt buộc khi điểm ≤1,5 hoặc 5)
A10: 1 | B10: Chuyên môn - Nghiệp vụ | C10: Độ chính xác bảng lương | D10: Số lỗi tính lương, phụ cấp, khấu trừ phát hiện sau khi chi trả = 0 | E10: 0.15 | H10: =IF(ISNUMBER(G10),G10/5*E10*100,0) | J10: CM
A11: 2 | C11: Tính thuế TNCN từ tiền lương, tiền công | D11: Khấu trừ đúng biểu thuế, giảm trừ gia cảnh; quyết toán không phải điều chỉnh | E11: 0.1 | H11: =IF(ISNUMBER(G11),G11/5*E11*100,0) | J11: CM
A12: 3 | C12: Quản lý thang bảng lương & khảo sát lương | D12: Thang bảng lương cập nhật theo lương tối thiểu vùng; có số liệu khảo sát lương thị trường cho vị trí then chốt | E12: 0.1 | H12: =IF(ISNUMBER(G12),G12/5*E12*100,0) | J12: CM
A13: 4 | C13: Quản lý chế độ phúc lợi | D13: Chi phúc lợi (hiếu hỉ, nghỉ mát, quà tặng…) đúng quy chế, đúng hạn | E13: 0.05 | H13: =IF(ISNUMBER(G13),G13/5*E13*100,0) | J13: CM
A14: 5 | B14: Tuân thủ - Thời hạn | C14: Đúng hạn kỳ lương | D14: Bảng lương trình duyệt và chi trả đúng ngày theo quy chế lương | E14: 0.12 | H14: =IF(ISNUMBER(G14),G14/5*E14*100,0) | J14: TT
A15: 6 | C15: Tuân thủ quy chế lương thưởng | D15: Áp dụng đúng thang bảng lương, quy chế thưởng, phụ cấp | E15: 0.1 | H15: =IF(ISNUMBER(G15),G15/5*E15*100,0) | J15: TT
A16: 7 | C16: Quyết toán thuế TNCN | D16: Hồ sơ khai, quyết toán thuế TNCN nộp đúng hạn; không phát sinh tiền chậm nộp | E16: 0.08 | H16: =IF(ISNUMBER(G16),G16/5*E16*100,0) | J16: TT
A17: 8 | C17: Bảo mật thông tin lương | D17: Không rò rỉ bảng lương; file lương có phân quyền | E17: 0.05 | H17: =IF(ISNUMBER(G17),G17/5*E17*100,0) | J17: TT
A18: 9 | B18: Phối hợp - Thái độ | C18: Phối hợp với Kế toán & chuyên viên BHXH | D18: Chi phí lương, khoản trích BHXH khớp sổ kế toán và dữ liệu BHXH | E18: 0.1 | H18: =IF(ISNUMBER(G18),G18/5*E18*100,0) | J18: PH
A19: 10 | C19: Giải đáp thắc mắc của người lao động | D19: Thời gian phản hồi thắc mắc về lương ≤ 2 ngày làm việc | E19: 0.08 | H19: =IF(ISNUMBER(G19),G19/5*E19*100,0) | J19: PH
A20: 11 | C20: Tinh thần trách nhiệm & chủ động | D20: Cập nhật kịp thời thay đổi chính sách lương, thuế TNCN | E20: 0.07 | H20: =IF(ISNUMBER(G20),G20/5*E20*100,0) | J20: PH
A21: TỔNG CỘNG | E21: =SUM(E10:E20) | H21: =SUM(H10:H20)
A23: KẾT QUẢ ĐÁNH GIÁ | D23: ĐIỂM THEO NHÓM TIÊU CHÍ
A24: Tổng điểm chính thức | C24: =H21 | D24: Nhóm tiêu chí | E24: Trọng số | F24: Điểm tối đa | G24: Điểm đạt | H24: Tỷ lệ đạt
A25: Điểm tự đánh giá | C25: =IF(COUNT(F10:F20)=0,"",SUMPRODUCT(F10:F20,E10:E20)/5*100) | D25: Chuyên môn - Nghiệp vụ | E25: =SUMIF($J$10:$J$20,"CM",$E$10:$E$20) | F25: =E25*100 | G25: =SUMIF($J$10:$J$20,"CM",$H$10:$H$20) | H25: =IF(F25=0,0,G25/F25)
A26: Tiêu chí đã chấm | C26: =COUNT(G10:G20)&" / 11" | D26: Tuân thủ - Thời hạn | E26: =SUMIF($J$10:$J$20,"TT",$E$10:$E$20) | F26: =E26*100 | G26: =SUMIF($J$10:$J$20,"TT",$H$10:$H$20) | H26: =IF(F26=0,0,G26/F26)
A27: Xếp loại | C27: =IF(COUNT(G10:G20)=0,"Chưa chấm",IF(COUNT(G10:G20)<11,"Chưa chấm đủ",IF(H21>=80,"Xuất sắc",IF(H21>=70,"Đạt","Cần cải thiện")))) | D27: Phối hợp - Thái độ | E27: =SUMIF($J$10:$J$20,"PH",$E$10:$E$20) | F27: =E27*100 | G27: =SUMIF($J$10:$J$20,"PH",$H$10:$H$20) | H27: =IF(F27=0,0,G27/F27)
A28: Kiểm tra trọng số | C28: =IF(ROUND(E21,4)=1,"Hợp lệ – 100%","SAI – tổng trọng số phải = 100%")
A30: NHẬN XÉT & KẾ HOẠCH CẢI THIỆN (Bước 5 – phản hồi kết quả)
A31: Điểm mạnh
A32: Cần cải thiện
A33: Kế hoạch cải thiện
A34: Ý kiến nhân sự
B36: NHÂN SỰ ĐƯỢC ĐÁNH GIÁ | D36: QUẢN LÝ TRỰC TIẾP | G36: NGƯỜI PHÊ DUYỆT
B37: (Ký, ghi rõ họ tên) | D37: (Ký, ghi rõ họ tên) | G37: (Ký, ghi rõ họ tên)

Sheet 07. CV BHXH
A1: BẢNG ĐÁNH GIÁ KPI – CHUYÊN VIÊN BHXH & CHẾ ĐỘ
A2: Phòng Nhân sự · Phụ lục 02 kèm Quy chế đánh giá KPI · KK HOME ·
B4: Họ và tên | E4: Loại kỳ đánh giá | G4: Quý | I4: ← chọn Tháng / Quý / Năm
B5: Mã nhân viên | E5: Kỳ đánh giá | I5: VD: Tháng 9/2026, Quý 3/2026, Năm 2026
B6: Người đánh giá | E6: Ngày đánh giá
B7: Bộ phận | C7: Phòng Nhân sự
A9: STT | B9: Nhóm tiêu chí | C9: Tiêu chí đánh giá | D9: Cách đo / Chứng cứ chấm điểm | E9: Trọng số | F9: Tự đánh giá (1–5) | G9: Quản lý chấm (1–5) | H9: Điểm quy đổi | I9: Ghi chú / Lý do (bắt buộc khi điểm ≤1,5 hoặc 5)
A10: 1 | B10: Chuyên môn - Nghiệp vụ | C10: Thủ tục tham gia BHXH, BHYT, BHTN | D10: Báo tăng/giảm, điều chỉnh mức đóng, cấp thẻ BHYT chính xác | E10: 0.12 | H10: =IF(ISNUMBER(G10),G10/5*E10*100,0) | J10: CM
A11: 2 | C11: Giải quyết chế độ ốm đau, thai sản, dưỡng sức | D11: Hồ sơ đủ, đúng; được cơ quan BHXH chấp nhận ngay lần nộp đầu | E11: 0.1 | H11: =IF(ISNUMBER(G11),G11/5*E11*100,0) | J11: CM
A12: 3 | C12: Đối chiếu số liệu đóng BHXH | D12: Đối chiếu hằng tháng với cơ quan BHXH; không phát sinh chênh lệch | E12: 0.1 | H12: =IF(ISNUMBER(G12),G12/5*E12*100,0) | J12: CM
A13: 4 | C13: Hồ sơ tai nạn lao động, bệnh nghề nghiệp | D13: Lập, nộp hồ sơ đủ và đúng hạn khi phát sinh (không phát sinh: chấm theo mức chuẩn bị quy trình) | E13: 0.08 | H13: =IF(ISNUMBER(G13),G13/5*E13*100,0) | J13: CM
A14: 5 | B14: Tuân thủ - Thời hạn | C14: Đúng hạn nộp tiền BHXH | D14: Không phát sinh chậm đóng, tiền lãi chậm đóng BHXH | E14: 0.15 | H14: =IF(ISNUMBER(G14),G14/5*E14*100,0) | J14: TT
A15: 6 | C15: Chốt, trả sổ BHXH khi nghỉ việc | D15: Hoàn tất xác nhận quá trình đóng và trả hồ sơ trong thời hạn luật định | E15: 0.1 | H15: =IF(ISNUMBER(G15),G15/5*E15*100,0) | J15: TT
A16: 7 | C16: Cập nhật chính sách BHXH mới | D16: Áp dụng kịp thời thay đổi về mức đóng, đối tượng, chế độ | E16: 0.1 | H16: =IF(ISNUMBER(G16),G16/5*E16*100,0) | J16: TT
A17: 8 | B17: Phối hợp - Thái độ | C17: Hướng dẫn người lao động về chế độ | D17: Thời gian phản hồi; số hồ sơ phải bổ sung do hướng dẫn sai | E17: 0.1 | H17: =IF(ISNUMBER(G17),G17/5*E17*100,0) | J17: PH
A18: 9 | C18: Phối hợp với C&B và Kế toán | D18: Số liệu trích nộp BHXH khớp bảng lương và sổ kế toán | E18: 0.08 | H18: =IF(ISNUMBER(G18),G18/5*E18*100,0) | J18: PH
A19: 10 | C19: Tinh thần trách nhiệm & chủ động | D19: Chủ động nhắc hạn, theo dõi hồ sơ tồn tại cơ quan BHXH | E19: 0.07 | H19: =IF(ISNUMBER(G19),G19/5*E19*100,0) | J19: PH
A20: TỔNG CỘNG | E20: =SUM(E10:E19) | H20: =SUM(H10:H19)
A22: KẾT QUẢ ĐÁNH GIÁ | D22: ĐIỂM THEO NHÓM TIÊU CHÍ
A23: Tổng điểm chính thức | C23: =H20 | D23: Nhóm tiêu chí | E23: Trọng số | F23: Điểm tối đa | G23: Điểm đạt | H23: Tỷ lệ đạt
A24: Điểm tự đánh giá | C24: =IF(COUNT(F10:F19)=0,"",SUMPRODUCT(F10:F19,E10:E19)/5*100) | D24: Chuyên môn - Nghiệp vụ | E24: =SUMIF($J$10:$J$19,"CM",$E$10:$E$19) | F24: =E24*100 | G24: =SUMIF($J$10:$J$19,"CM",$H$10:$H$19) | H24: =IF(F24=0,0,G24/F24)
A25: Tiêu chí đã chấm | C25: =COUNT(G10:G19)&" / 10" | D25: Tuân thủ - Thời hạn | E25: =SUMIF($J$10:$J$19,"TT",$E$10:$E$19) | F25: =E25*100 | G25: =SUMIF($J$10:$J$19,"TT",$H$10:$H$19) | H25: =IF(F25=0,0,G25/F25)
A26: Xếp loại | C26: =IF(COUNT(G10:G19)=0,"Chưa chấm",IF(COUNT(G10:G19)<10,"Chưa chấm đủ",IF(H20>=80,"Xuất sắc",IF(H20>=70,"Đạt","Cần cải thiện")))) | D26: Phối hợp - Thái độ | E26: =SUMIF($J$10:$J$19,"PH",$E$10:$E$19) | F26: =E26*100 | G26: =SUMIF($J$10:$J$19,"PH",$H$10:$H$19) | H26: =IF(F26=0,0,G26/F26)
A27: Kiểm tra trọng số | C27: =IF(ROUND(E20,4)=1,"Hợp lệ – 100%","SAI – tổng trọng số phải = 100%")
A29: NHẬN XÉT & KẾ HOẠCH CẢI THIỆN (Bước 5 – phản hồi kết quả)
A30: Điểm mạnh
A31: Cần cải thiện
A32: Kế hoạch cải thiện
A33: Ý kiến nhân sự
B35: NHÂN SỰ ĐƯỢC ĐÁNH GIÁ | D35: QUẢN LÝ TRỰC TIẾP | G35: NGƯỜI PHÊ DUYỆT
B36: (Ký, ghi rõ họ tên) | D36: (Ký, ghi rõ họ tên) | G36: (Ký, ghi rõ họ tên)

Sheet 08. CV Đào tạo
A1: BẢNG ĐÁNH GIÁ KPI – CHUYÊN VIÊN ĐÀO TẠO & PHÁT TRIỂN
A2: Phòng Nhân sự · Phụ lục 02 kèm Quy chế đánh giá KPI · KK HOME ·
B4: Họ và tên | E4: Loại kỳ đánh giá | G4: Quý | I4: ← chọn Tháng / Quý / Năm
B5: Mã nhân viên | E5: Kỳ đánh giá | I5: VD: Tháng 9/2026, Quý 3/2026, Năm 2026
B6: Người đánh giá | E6: Ngày đánh giá
B7: Bộ phận | C7: Phòng Nhân sự
A9: STT | B9: Nhóm tiêu chí | C9: Tiêu chí đánh giá | D9: Cách đo / Chứng cứ chấm điểm | E9: Trọng số | F9: Tự đánh giá (1–5) | G9: Quản lý chấm (1–5) | H9: Điểm quy đổi | I9: Ghi chú / Lý do (bắt buộc khi điểm ≤1,5 hoặc 5)
A10: 1 | B10: Chuyên môn - Nghiệp vụ | C10: Hoàn thành kế hoạch đào tạo | D10: Số khóa thực hiện / số khóa theo kế hoạch được duyệt | E10: 0.12 | H10: =IF(ISNUMBER(G10),G10/5*E10*100,0) | J10: CM
A11: 2 | C11: Hiệu quả đào tạo | D11: Điểm đánh giá sau khóa học; tỷ lệ học viên đạt bài kiểm tra | E11: 0.1 | H11: =IF(ISNUMBER(G11),G11/5*E11*100,0) | J11: CM
A12: 3 | C12: Hội nhập nhân sự mới (onboarding) | D12: Tỷ lệ nhân sự mới hoàn thành chương trình hội nhập trong 30 ngày | E12: 0.1 | H12: =IF(ISNUMBER(G12),G12/5*E12*100,0) | J12: CM
A13: 4 | C13: Khung năng lực & lộ trình phát triển | D13: Số vị trí có khung năng lực, lộ trình phát triển được duyệt | E13: 0.08 | H13: =IF(ISNUMBER(G13),G13/5*E13*100,0) | J13: CM
A14: 5 | B14: Tuân thủ - Thời hạn | C14: Kiểm soát ngân sách đào tạo | D14: Chi phí đào tạo thực tế so với ngân sách | E14: 0.1 | H14: =IF(ISNUMBER(G14),G14/5*E14*100,0) | J14: TT
A15: 6 | C15: Hồ sơ đào tạo & hợp đồng đào tạo | D15: Đủ danh sách điểm danh, kết quả; có hợp đồng đào tạo khi công ty chịu chi phí | E15: 0.1 | H15: =IF(ISNUMBER(G15),G15/5*E15*100,0) | J15: TT
A16: 7 | C16: Đúng tiến độ triển khai | D16: Khóa học tổ chức đúng lịch đã thông báo | E16: 0.08 | H16: =IF(ISNUMBER(G16),G16/5*E16*100,0) | J16: TT
A17: 8 | C17: Đào tạo bắt buộc (an toàn vệ sinh lao động, nội quy) | D17: Tỷ lệ nhân sự thuộc đối tượng hoàn thành đào tạo bắt buộc | E17: 0.07 | H17: =IF(ISNUMBER(G17),G17/5*E17*100,0) | J17: TT
A18: 9 | B18: Phối hợp - Thái độ | C18: Phối hợp xác định nhu cầu đào tạo | D18: Khảo sát nhu cầu với trưởng bộ phận hoàn thành đúng hạn | E18: 0.1 | H18: =IF(ISNUMBER(G18),G18/5*E18*100,0) | J18: PH
A19: 10 | C19: Phát triển giảng viên nội bộ | D19: Số giảng viên nội bộ tham gia giảng dạy trong kỳ | E19: 0.08 | H19: =IF(ISNUMBER(G19),G19/5*E19*100,0) | J19: PH
A20: 11 | C20: Tinh thần trách nhiệm & chủ động | D20: Đề xuất chương trình mới, cải tiến phương pháp đào tạo | E20: 0.07 | H20: =IF(ISNUMBER(G20),G20/5*E20*100,0) | J20: PH
A21: TỔNG CỘNG | E21: =SUM(E10:E20) | H21: =SUM(H10:H20)
A23: KẾT QUẢ ĐÁNH GIÁ | D23: ĐIỂM THEO NHÓM TIÊU CHÍ
A24: Tổng điểm chính thức | C24: =H21 | D24: Nhóm tiêu chí | E24: Trọng số | F24: Điểm tối đa | G24: Điểm đạt | H24: Tỷ lệ đạt
A25: Điểm tự đánh giá | C25: =IF(COUNT(F10:F20)=0,"",SUMPRODUCT(F10:F20,E10:E20)/5*100) | D25: Chuyên môn - Nghiệp vụ | E25: =SUMIF($J$10:$J$20,"CM",$E$10:$E$20) | F25: =E25*100 | G25: =SUMIF($J$10:$J$20,"CM",$H$10:$H$20) | H25: =IF(F25=0,0,G25/F25)
A26: Tiêu chí đã chấm | C26: =COUNT(G10:G20)&" / 11" | D26: Tuân thủ - Thời hạn | E26: =SUMIF($J$10:$J$20,"TT",$E$10:$E$20) | F26: =E26*100 | G26: =SUMIF($J$10:$J$20,"TT",$H$10:$H$20) | H26: =IF(F26=0,0,G26/F26)
A27: Xếp loại | C27: =IF(COUNT(G10:G20)=0,"Chưa chấm",IF(COUNT(G10:G20)<11,"Chưa chấm đủ",IF(H21>=80,"Xuất sắc",IF(H21>=70,"Đạt","Cần cải thiện")))) | D27: Phối hợp - Thái độ | E27: =SUMIF($J$10:$J$20,"PH",$E$10:$E$20) | F27: =E27*100 | G27: =SUMIF($J$10:$J$20,"PH",$H$10:$H$20) | H27: =IF(F27=0,0,G27/F27)
A28: Kiểm tra trọng số | C28: =IF(ROUND(E21,4)=1,"Hợp lệ – 100%","SAI – tổng trọng số phải = 100%")
A30: NHẬN XÉT & KẾ HOẠCH CẢI THIỆN (Bước 5 – phản hồi kết quả)
A31: Điểm mạnh
A32: Cần cải thiện
A33: Kế hoạch cải thiện
A34: Ý kiến nhân sự
B36: NHÂN SỰ ĐƯỢC ĐÁNH GIÁ | D36: QUẢN LÝ TRỰC TIẾP | G36: NGƯỜI PHÊ DUYỆT
B37: (Ký, ghi rõ họ tên) | D37: (Ký, ghi rõ họ tên) | G37: (Ký, ghi rõ họ tên)

Sheet 09. CV Quan hệ LĐ
A1: BẢNG ĐÁNH GIÁ KPI – CHUYÊN VIÊN QUAN HỆ LAO ĐỘNG & HỒ SƠ NHÂN SỰ
A2: Phòng Nhân sự · Phụ lục 02 kèm Quy chế đánh giá KPI · KK HOME ·
B4: Họ và tên | E4: Loại kỳ đánh giá | G4: Quý | I4: ← chọn Tháng / Quý / Năm
B5: Mã nhân viên | E5: Kỳ đánh giá | I5: VD: Tháng 9/2026, Quý 3/2026, Năm 2026
B6: Người đánh giá | E6: Ngày đánh giá
B7: Bộ phận | C7: Phòng Nhân sự
A9: STT | B9: Nhóm tiêu chí | C9: Tiêu chí đánh giá | D9: Cách đo / Chứng cứ chấm điểm | E9: Trọng số | F9: Tự đánh giá (1–5) | G9: Quản lý chấm (1–5) | H9: Điểm quy đổi | I9: Ghi chú / Lý do (bắt buộc khi điểm ≤1,5 hoặc 5)
A10: 1 | B10: Chuyên môn - Nghiệp vụ | C10: Quản lý hợp đồng lao động | D10: Tỷ lệ HĐLĐ ký/gia hạn trước khi hết hạn; đúng loại hợp đồng theo luật | E10: 0.12 | H10: =IF(ISNUMBER(G10),G10/5*E10*100,0) | J10: CM
A11: 2 | C11: Hồ sơ nhân sự đầy đủ, cập nhật | D11: Tỷ lệ hồ sơ đủ giấy tờ; dữ liệu phần mềm khớp hồ sơ giấy | E11: 0.1 | H11: =IF(ISNUMBER(G11),G11/5*E11*100,0) | J11: CM
A12: 3 | C12: Xử lý kỷ luật, chấm dứt HĐLĐ | D12: Đúng trình tự, có biên bản; không phát sinh tranh chấp do sai thủ tục | E12: 0.1 | H12: =IF(ISNUMBER(G12),G12/5*E12*100,0) | J12: CM
A13: 4 | C13: Nội quy lao động & thỏa ước | D13: Nội quy, thỏa ước được cập nhật, đăng ký/thông báo theo quy định | E13: 0.08 | H13: =IF(ISNUMBER(G13),G13/5*E13*100,0) | J13: CM
A14: 5 | B14: Tuân thủ - Thời hạn | C14: Tuân thủ pháp luật lao động | D14: Số vi phạm bị nhắc nhở, xử phạt khi thanh tra, kiểm tra lao động = 0 | E14: 0.15 | H14: =IF(ISNUMBER(G14),G14/5*E14*100,0) | J14: TT
A15: 6 | C15: Đúng hạn thủ tục thôi việc | D15: Thanh toán đủ quyền lợi, trả hồ sơ trong thời hạn luật định | E15: 0.1 | H15: =IF(ISNUMBER(G15),G15/5*E15*100,0) | J15: TT
A16: 7 | C16: Báo cáo tình hình sử dụng lao động | D16: Nộp báo cáo định kỳ cho cơ quan quản lý lao động đúng hạn | E16: 0.1 | H16: =IF(ISNUMBER(G16),G16/5*E16*100,0) | J16: TT
A17: 8 | B17: Phối hợp - Thái độ | C17: Đối thoại & giải quyết khiếu nại | D17: Số khiếu nại xử lý trong thời hạn; đối thoại tại nơi làm việc tổ chức đúng định kỳ | E17: 0.1 | H17: =IF(ISNUMBER(G17),G17/5*E17*100,0) | J17: PH
A18: 9 | C18: Phối hợp với tổ chức đại diện người lao động | D18: Phối hợp nội dung đối thoại, thỏa ước, kỷ luật đúng quy định | E18: 0.08 | H18: =IF(ISNUMBER(G18),G18/5*E18*100,0) | J18: PH
A19: 10 | C19: Tinh thần trách nhiệm & chủ động | D19: Cảnh báo sớm rủi ro tranh chấp lao động | E19: 0.07 | H19: =IF(ISNUMBER(G19),G19/5*E19*100,0) | J19: PH
A20: TỔNG CỘNG | E20: =SUM(E10:E19) | H20: =SUM(H10:H19)
A22: KẾT QUẢ ĐÁNH GIÁ | D22: ĐIỂM THEO NHÓM TIÊU CHÍ
A23: Tổng điểm chính thức | C23: =H20 | D23: Nhóm tiêu chí | E23: Trọng số | F23: Điểm tối đa | G23: Điểm đạt | H23: Tỷ lệ đạt
A24: Điểm tự đánh giá | C24: =IF(COUNT(F10:F19)=0,"",SUMPRODUCT(F10:F19,E10:E19)/5*100) | D24: Chuyên môn - Nghiệp vụ | E24: =SUMIF($J$10:$J$19,"CM",$E$10:$E$19) | F24: =E24*100 | G24: =SUMIF($J$10:$J$19,"CM",$H$10:$H$19) | H24: =IF(F24=0,0,G24/F24)
A25: Tiêu chí đã chấm | C25: =COUNT(G10:G19)&" / 10" | D25: Tuân thủ - Thời hạn | E25: =SUMIF($J$10:$J$19,"TT",$E$10:$E$19) | F25: =E25*100 | G25: =SUMIF($J$10:$J$19,"TT",$H$10:$H$19) | H25: =IF(F25=0,0,G25/F25)
A26: Xếp loại | C26: =IF(COUNT(G10:G19)=0,"Chưa chấm",IF(COUNT(G10:G19)<10,"Chưa chấm đủ",IF(H20>=80,"Xuất sắc",IF(H20>=70,"Đạt","Cần cải thiện")))) | D26: Phối hợp - Thái độ | E26: =SUMIF($J$10:$J$19,"PH",$E$10:$E$19) | F26: =E26*100 | G26: =SUMIF($J$10:$J$19,"PH",$H$10:$H$19) | H26: =IF(F26=0,0,G26/F26)
A27: Kiểm tra trọng số | C27: =IF(ROUND(E20,4)=1,"Hợp lệ – 100%","SAI – tổng trọng số phải = 100%")
A29: NHẬN XÉT & KẾ HOẠCH CẢI THIỆN (Bước 5 – phản hồi kết quả)
A30: Điểm mạnh
A31: Cần cải thiện
A32: Kế hoạch cải thiện
A33: Ý kiến nhân sự
B35: NHÂN SỰ ĐƯỢC ĐÁNH GIÁ | D35: QUẢN LÝ TRỰC TIẾP | G35: NGƯỜI PHÊ DUYỆT
B36: (Ký, ghi rõ họ tên) | D36: (Ký, ghi rõ họ tên) | G36: (Ký, ghi rõ họ tên)

Sheet 10. CV Văn hóa DN
A1: BẢNG ĐÁNH GIÁ KPI – CHUYÊN VIÊN VĂN HÓA DOANH NGHIỆP & TRUYỀN THÔNG NỘI BỘ
A2: Phòng Nhân sự · Phụ lục 02 kèm Quy chế đánh giá KPI · KK HOME ·
B4: Họ và tên | E4: Loại kỳ đánh giá | G4: Quý | I4: ← chọn Tháng / Quý / Năm
B5: Mã nhân viên | E5: Kỳ đánh giá | I5: VD: Tháng 9/2026, Quý 3/2026, Năm 2026
B6: Người đánh giá | E6: Ngày đánh giá
B7: Bộ phận | C7: Phòng Nhân sự
A9: STT | B9: Nhóm tiêu chí | C9: Tiêu chí đánh giá | D9: Cách đo / Chứng cứ chấm điểm | E9: Trọng số | F9: Tự đánh giá (1–5) | G9: Quản lý chấm (1–5) | H9: Điểm quy đổi | I9: Ghi chú / Lý do (bắt buộc khi điểm ≤1,5 hoặc 5)
A10: 1 | B10: Chuyên môn - Nghiệp vụ | C10: Kế hoạch văn hóa & truyền thông nội bộ | D10: Tỷ lệ hoạt động triển khai theo kế hoạch năm | E10: 0.12 | H10: =IF(ISNUMBER(G10),G10/5*E10*100,0) | J10: CM
A11: 2 | C11: Mức độ gắn kết nhân viên | D11: Điểm khảo sát gắn kết (eNPS) so với kỳ trước | E11: 0.1 | H11: =IF(ISNUMBER(G11),G11/5*E11*100,0) | J11: CM
A12: 3 | C12: Kênh truyền thông nội bộ | D12: Bản tin, thông báo phát hành đúng lịch; tỷ lệ nhân viên đọc/tương tác | E12: 0.1 | H12: =IF(ISNUMBER(G12),G12/5*E12*100,0) | J12: CM
A13: 4 | C13: Chương trình ghi nhận, khen thưởng | D13: Tổ chức đúng kỳ, đúng tiêu chí đã công bố | E13: 0.08 | H13: =IF(ISNUMBER(G13),G13/5*E13*100,0) | J13: CM
A14: 5 | B14: Tuân thủ - Thời hạn | C14: Kiểm soát ngân sách sự kiện | D14: Chi phí thực tế so với ngân sách từng sự kiện | E14: 0.12 | H14: =IF(ISNUMBER(G14),G14/5*E14*100,0) | J14: TT
A15: 6 | C15: Đúng tiến độ sự kiện | D15: Sự kiện diễn ra đúng lịch, đủ hạng mục đã duyệt | E15: 0.12 | H15: =IF(ISNUMBER(G15),G15/5*E15*100,0) | J15: TT
A16: 7 | C16: Thông tin chính xác, đúng phê duyệt | D16: Nội dung được duyệt trước khi phát hành; số lỗi thông tin = 0 | E16: 0.11 | H16: =IF(ISNUMBER(G16),G16/5*E16*100,0) | J16: TT
A17: 8 | B17: Phối hợp - Thái độ | C17: Phối hợp các phòng ban | D17: Số phòng ban tham gia; phản hồi sau sự kiện | E17: 0.1 | H17: =IF(ISNUMBER(G17),G17/5*E17*100,0) | J17: PH
A18: 9 | C18: Lan tỏa giá trị cốt lõi | D18: Số câu chuyện, gương điển hình được ghi nhận và chia sẻ | E18: 0.08 | H18: =IF(ISNUMBER(G18),G18/5*E18*100,0) | J18: PH
A19: 10 | C19: Tinh thần trách nhiệm & sáng tạo | D19: Ý tưởng mới được áp dụng trong kỳ | E19: 0.07 | H19: =IF(ISNUMBER(G19),G19/5*E19*100,0) | J19: PH
A20: TỔNG CỘNG | E20: =SUM(E10:E19) | H20: =SUM(H10:H19)
A22: KẾT QUẢ ĐÁNH GIÁ | D22: ĐIỂM THEO NHÓM TIÊU CHÍ
A23: Tổng điểm chính thức | C23: =H20 | D23: Nhóm tiêu chí | E23: Trọng số | F23: Điểm tối đa | G23: Điểm đạt | H23: Tỷ lệ đạt
A24: Điểm tự đánh giá | C24: =IF(COUNT(F10:F19)=0,"",SUMPRODUCT(F10:F19,E10:E19)/5*100) | D24: Chuyên môn - Nghiệp vụ | E24: =SUMIF($J$10:$J$19,"CM",$E$10:$E$19) | F24: =E24*100 | G24: =SUMIF($J$10:$J$19,"CM",$H$10:$H$19) | H24: =IF(F24=0,0,G24/F24)
A25: Tiêu chí đã chấm | C25: =COUNT(G10:G19)&" / 10" | D25: Tuân thủ - Thời hạn | E25: =SUMIF($J$10:$J$19,"TT",$E$10:$E$19) | F25: =E25*100 | G25: =SUMIF($J$10:$J$19,"TT",$H$10:$H$19) | H25: =IF(F25=0,0,G25/F25)
A26: Xếp loại | C26: =IF(COUNT(G10:G19)=0,"Chưa chấm",IF(COUNT(G10:G19)<10,"Chưa chấm đủ",IF(H20>=80,"Xuất sắc",IF(H20>=70,"Đạt","Cần cải thiện")))) | D26: Phối hợp - Thái độ | E26: =SUMIF($J$10:$J$19,"PH",$E$10:$E$19) | F26: =E26*100 | G26: =SUMIF($J$10:$J$19,"PH",$H$10:$H$19) | H26: =IF(F26=0,0,G26/F26)
A27: Kiểm tra trọng số | C27: =IF(ROUND(E20,4)=1,"Hợp lệ – 100%","SAI – tổng trọng số phải = 100%")
A29: NHẬN XÉT & KẾ HOẠCH CẢI THIỆN (Bước 5 – phản hồi kết quả)
A30: Điểm mạnh
A31: Cần cải thiện
A32: Kế hoạch cải thiện
A33: Ý kiến nhân sự
B35: NHÂN SỰ ĐƯỢC ĐÁNH GIÁ | D35: QUẢN LÝ TRỰC TIẾP | G35: NGƯỜI PHÊ DUYỆT
B36: (Ký, ghi rõ họ tên) | D36: (Ký, ghi rõ họ tên) | G36: (Ký, ghi rõ họ tên)

Sheet 11. CV HRIS
A1: BẢNG ĐÁNH GIÁ KPI – CHUYÊN VIÊN HỆ THỐNG THÔNG TIN & BÁO CÁO NHÂN SỰ (HRIS)
A2: Phòng Nhân sự · Phụ lục 02 kèm Quy chế đánh giá KPI · KK HOME ·
B4: Họ và tên | E4: Loại kỳ đánh giá | G4: Quý | I4: ← chọn Tháng / Quý / Năm
B5: Mã nhân viên | E5: Kỳ đánh giá | I5: VD: Tháng 9/2026, Quý 3/2026, Năm 2026
B6: Người đánh giá | E6: Ngày đánh giá
B7: Bộ phận | C7: Phòng Nhân sự
A9: STT | B9: Nhóm tiêu chí | C9: Tiêu chí đánh giá | D9: Cách đo / Chứng cứ chấm điểm | E9: Trọng số | F9: Tự đánh giá (1–5) | G9: Quản lý chấm (1–5) | H9: Điểm quy đổi | I9: Ghi chú / Lý do (bắt buộc khi điểm ≤1,5 hoặc 5)
A10: 1 | B10: Chuyên môn - Nghiệp vụ | C10: Dữ liệu nhân sự chính xác trên phần mềm | D10: Tỷ lệ bản ghi sai/thiếu qua kiểm tra chọn mẫu | E10: 0.12 | H10: =IF(ISNUMBER(G10),G10/5*E10*100,0) | J10: CM
A11: 2 | C11: Báo cáo quản trị nhân sự | D11: Báo cáo định biên, biến động, chi phí nhân sự chính xác, có phân tích và đề xuất | E11: 0.1 | H11: =IF(ISNUMBER(G11),G11/5*E11*100,0) | J11: CM
A12: 3 | C12: Vận hành & phân quyền phần mềm nhân sự | D12: Hệ thống ổn định; lỗi người dùng báo được xử lý trong ngày | E12: 0.1 | H12: =IF(ISNUMBER(G12),G12/5*E12*100,0) | J12: CM
A13: 4 | C13: Số hóa quy trình nhân sự | D13: Số quy trình chuyển sang xử lý trên hệ thống trong kỳ | E13: 0.08 | H13: =IF(ISNUMBER(G13),G13/5*E13*100,0) | J13: CM
A14: 5 | B14: Tuân thủ - Thời hạn | C14: Đúng hạn báo cáo | D14: Báo cáo tuần/tháng/quý gửi đúng lịch | E14: 0.12 | H14: =IF(ISNUMBER(G14),G14/5*E14*100,0) | J14: TT
A15: 6 | C15: Bảo vệ dữ liệu cá nhân người lao động | D15: Phân quyền đúng vai trò; không rò rỉ; tuân thủ quy định về bảo vệ dữ liệu cá nhân | E15: 0.13 | H15: =IF(ISNUMBER(G15),G15/5*E15*100,0) | J15: TT
A16: 7 | C16: Sao lưu dữ liệu | D16: Sao lưu định kỳ; thử khôi phục thành công | E16: 0.1 | H16: =IF(ISNUMBER(G16),G16/5*E16*100,0) | J16: TT
A17: 8 | B17: Phối hợp - Thái độ | C17: Hỗ trợ người dùng | D17: Thời gian phản hồi yêu cầu hỗ trợ; mức hài lòng người dùng | E17: 0.1 | H17: =IF(ISNUMBER(G17),G17/5*E17*100,0) | J17: PH
A18: 9 | C18: Phối hợp với IT, Kế toán | D18: Dữ liệu kết nối phần mềm kế toán, chấm công khớp nhau | E18: 0.08 | H18: =IF(ISNUMBER(G18),G18/5*E18*100,0) | J18: PH
A19: 10 | C19: Tinh thần trách nhiệm & chủ động | D19: Đề xuất báo cáo, dashboard mới phục vụ quản lý | E19: 0.07 | H19: =IF(ISNUMBER(G19),G19/5*E19*100,0) | J19: PH
A20: TỔNG CỘNG | E20: =SUM(E10:E19) | H20: =SUM(H10:H19)
A22: KẾT QUẢ ĐÁNH GIÁ | D22: ĐIỂM THEO NHÓM TIÊU CHÍ
A23: Tổng điểm chính thức | C23: =H20 | D23: Nhóm tiêu chí | E23: Trọng số | F23: Điểm tối đa | G23: Điểm đạt | H23: Tỷ lệ đạt
A24: Điểm tự đánh giá | C24: =IF(COUNT(F10:F19)=0,"",SUMPRODUCT(F10:F19,E10:E19)/5*100) | D24: Chuyên môn - Nghiệp vụ | E24: =SUMIF($J$10:$J$19,"CM",$E$10:$E$19) | F24: =E24*100 | G24: =SUMIF($J$10:$J$19,"CM",$H$10:$H$19) | H24: =IF(F24=0,0,G24/F24)
A25: Tiêu chí đã chấm | C25: =COUNT(G10:G19)&" / 10" | D25: Tuân thủ - Thời hạn | E25: =SUMIF($J$10:$J$19,"TT",$E$10:$E$19) | F25: =E25*100 | G25: =SUMIF($J$10:$J$19,"TT",$H$10:$H$19) | H25: =IF(F25=0,0,G25/F25)
A26: Xếp loại | C26: =IF(COUNT(G10:G19)=0,"Chưa chấm",IF(COUNT(G10:G19)<10,"Chưa chấm đủ",IF(H20>=80,"Xuất sắc",IF(H20>=70,"Đạt","Cần cải thiện")))) | D26: Phối hợp - Thái độ | E26: =SUMIF($J$10:$J$19,"PH",$E$10:$E$19) | F26: =E26*100 | G26: =SUMIF($J$10:$J$19,"PH",$H$10:$H$19) | H26: =IF(F26=0,0,G26/F26)
A27: Kiểm tra trọng số | C27: =IF(ROUND(E20,4)=1,"Hợp lệ – 100%","SAI – tổng trọng số phải = 100%")
A29: NHẬN XÉT & KẾ HOẠCH CẢI THIỆN (Bước 5 – phản hồi kết quả)
A30: Điểm mạnh
A31: Cần cải thiện
A32: Kế hoạch cải thiện
A33: Ý kiến nhân sự
B35: NHÂN SỰ ĐƯỢC ĐÁNH GIÁ | D35: QUẢN LÝ TRỰC TIẾP | G35: NGƯỜI PHÊ DUYỆT
B36: (Ký, ghi rõ họ tên) | D36: (Ký, ghi rõ họ tên) | G36: (Ký, ghi rõ họ tên)

Sheet 12. NV Hành chính NS
A1: BẢNG ĐÁNH GIÁ KPI – NHÂN VIÊN HÀNH CHÍNH NHÂN SỰ
A2: Phòng Nhân sự · Phụ lục 02 kèm Quy chế đánh giá KPI · KK HOME ·
B4: Họ và tên | E4: Loại kỳ đánh giá | G4: Quý | I4: ← chọn Tháng / Quý / Năm
B5: Mã nhân viên | E5: Kỳ đánh giá | I5: VD: Tháng 9/2026, Quý 3/2026, Năm 2026
B6: Người đánh giá | E6: Ngày đánh giá
B7: Bộ phận | C7: Phòng Nhân sự
A9: STT | B9: Nhóm tiêu chí | C9: Tiêu chí đánh giá | D9: Cách đo / Chứng cứ chấm điểm | E9: Trọng số | F9: Tự đánh giá (1–5) | G9: Quản lý chấm (1–5) | H9: Điểm quy đổi | I9: Ghi chú / Lý do (bắt buộc khi điểm ≤1,5 hoặc 5)
A10: 1 | B10: Chuyên môn - Nghiệp vụ | C10: Chấm công chính xác | D10: Dữ liệu công khớp máy chấm công, đơn từ; số khiếu nại về công | E10: 0.12 | H10: =IF(ISNUMBER(G10),G10/5*E10*100,0) | J10: CM
A11: 2 | C11: Quản lý nghỉ phép, làm thêm giờ | D11: Ngày phép, giờ làm thêm theo dõi đúng; làm thêm không vượt giới hạn luật định | E11: 0.1 | H11: =IF(ISNUMBER(G11),G11/5*E11*100,0) | J11: CM
A12: 3 | C12: Quản lý tài sản, văn phòng phẩm | D12: Kiểm kê khớp sổ theo dõi; cấp phát đúng định mức | E12: 0.1 | H12: =IF(ISNUMBER(G12),G12/5*E12*100,0) | J12: CM
A13: 4 | C13: Soạn thảo văn bản, quyết định nhân sự | D13: Đúng mẫu, đúng thể thức; số văn bản phải sửa lại | E13: 0.08 | H13: =IF(ISNUMBER(G13),G13/5*E13*100,0) | J13: CM
A14: 5 | B14: Tuân thủ - Thời hạn | C14: Đúng hạn chốt công | D14: Bảng công chuyển bộ phận lương đúng ngày chốt | E14: 0.12 | H14: =IF(ISNUMBER(G14),G14/5*E14*100,0) | J14: TT
