Workbook

Sheet Hướng dẫn
A1: KPI CÔNG TY XÂY DỰNG – 12 VỊ TRÍ
A2: Phụ lục 01 kèm Quy chế đánh giá KPI · KK HOME ·
B4: CÁCH DÙNG – 6 BƯỚC
B5: Bước 1 | C5: Chọn sheet đúng vị trí của nhân sự (bấm tên vị trí ở danh mục bên dưới để nhảy tới sheet).
B6: Bước 2 | C6: Nhập thông tin đầu sheet: Họ tên, Mã NV, Người đánh giá, Loại kỳ (Tháng/Quý/Năm), Kỳ đánh giá, Ngày đánh giá.
B7: Bước 3 | C7: Nhân sự tự chấm điểm cột F "Tự đánh giá" (1–5, được chấm lẻ 3.5).
B8: Bước 4 | C8: Quản lý trực tiếp chấm điểm chính thức cột G "Quản lý chấm". Chỉ điểm cột G được dùng để tính điểm quy đổi và xếp loại.
B9: Bước 5 | C9: Ghi chú lý do ở cột I khi điểm ≤ 1,5 hoặc = 5. Ô ghi chú tự tô cam nếu thiếu lý do (Điều 12 – Ngoại lệ).
B10: Bước 6 | C10: Xem kết quả ở cuối sheet vị trí, sheet "Tổng hợp" (toàn phòng) và "So sánh" (biểu đồ). In, ký và trình phê duyệt.
B12: QUY ƯỚC Ô
B13: Ô nền vàng, chữ xanh | C13: Ô nhập liệu. Chỉ nhập vào các ô này.
B14: Trọng số chữ xanh (cột E) | C14: Được sửa khi có quyết định điều chỉnh (Điều 17). Tổng trọng số mỗi vị trí phải = 100% – ô "Kiểm tra trọng số" báo đỏ nếu sai.
B15: Ô nền xám | C15: Công thức tự tính. Không sửa.
B17: CÔNG THỨC & XẾP LOẠI (Điều 7, Điều 13 Quy chế)
B18: Điểm quy đổi | C18: Điểm quản lý chấm ÷ 5 × Trọng số × 100
B19: Tổng điểm | C19: Cộng điểm quy đổi các tiêu chí (tối đa 100 điểm)
B20: Xếp loại | C20: ≥ 80 điểm: Xuất sắc · 70 đến dưới 80: Đạt · Dưới 70: Cần cải thiện. Chưa chấm đủ tiêu chí → hiển thị "Chưa chấm đủ".
B21: Ví dụ | C21: Tiêu chí "Tiến độ thi công tuần, tháng" trọng số 12%, quản lý chấm 4 → 4 ÷ 5 × 12 = 9,6 điểm. Chấm 3.5 → 8,4 điểm.
B22: Cơ cấu nhóm | C22: Chuyên môn - Nghiệp vụ 40% · Tuân thủ - Thời hạn 35% · Phối hợp - Thái độ 25% (áp dụng cho mọi vị trí trong file).
B24: DANH MỤC 12 VỊ TRÍ
B25: 01 | C25: Giám đốc dự án (Project Manager) (11 tiêu chí)
B26: 02 | C26: Chỉ huy trưởng công trường (11 tiêu chí)
B27: 03 | C27: Kỹ sư giám sát hiện trường (Site Engineer) (11 tiêu chí)
B28: 04 | C28: Kỹ sư quản lý chất lượng (QA/QC) (11 tiêu chí)
B29: 05 | C29: Cán bộ an toàn, vệ sinh lao động (HSE) (11 tiêu chí)
B30: 06 | C30: Kỹ sư dự toán – đấu thầu (11 tiêu chí)
B31: 07 | C31: Kỹ sư thanh toán – quyết toán, hồ sơ hoàn công (11 tiêu chí)
B32: 08 | C32: Kỹ sư kỹ thuật – bản vẽ thi công (Shop drawing) (11 tiêu chí)
B33: 09 | C33: Kỹ sư cơ điện (MEP) (11 tiêu chí)
B34: 10 | C34: Cán bộ trắc đạc (11 tiêu chí)
B35: 11 | C35: Cán bộ vật tư – thủ kho công trường (11 tiêu chí)
B36: 12 | C36: Kế toán công trình (11 tiêu chí)
B38: Lưu ý | C38: Tiêu chí và cách đo là bộ mẫu cho doanh nghiệp xây dựng dân dụng, công nghiệp. Đơn vị điều chỉnh chỉ tiêu định lượng (%, số ngày, định mức) theo mục tiêu đã duyệt của từng dự án, từng kỳ trước khi phổ biến cho nhân sự (Điều 4 – Công khai). Nhân sự luân chuyển giữa các công trình trong kỳ: mỗi Ban chỉ huy chấm phần thời gian phụ trách, Giám đốc dự án tổng hợp. Bộ file thuộc Hệ thống W1 – KPI Doanh nghiệp của KK HOME.

Sheet Tổng hợp
A1: TỔNG HỢP KẾT QUẢ KPI – CÔNG TY XÂY DỰNG
A2: Phụ lục 01 · Tự cập nhật từ các sheet vị trí (Bước 4 – Điều 10) · KK HOME ·
A4: STT | B4: Vị trí | C4: Họ và tên | D4: Kỳ đánh giá | E4: Điểm tự ĐG | F4: Điểm chính thức | G4: Chênh lệch (CT − Tự ĐG) | H4: Xếp loại | I4: Chuyên môn (% đạt) | J4: Tuân thủ (% đạt) | K4: Phối hợp (% đạt) | L4: Tiến độ chấm
A5: 1 | B5: Giám đốc dự án (Project Manager) | C5: =IF('01. Giám đốc dự án'!C4="","",'01. Giám đốc dự án'!C4) | D5: =IF('01. Giám đốc dự án'!G5="",'01. Giám đốc dự án'!G4,'01. Giám đốc dự án'!G5) | E5: ='01. Giám đốc dự án'!C25 | F5: ='01. Giám đốc dự án'!C24 | G5: =IF(E5="","",F5-E5) | H5: ='01. Giám đốc dự án'!C27 | I5: ='01. Giám đốc dự án'!H25 | J5: ='01. Giám đốc dự án'!H26 | K5: ='01. Giám đốc dự án'!H27 | L5: ='01. Giám đốc dự án'!C26
A6: 2 | B6: Chỉ huy trưởng công trường | C6: =IF('02. Chỉ huy trưởng'!C4="","",'02. Chỉ huy trưởng'!C4) | D6: =IF('02. Chỉ huy trưởng'!G5="",'02. Chỉ huy trưởng'!G4,'02. Chỉ huy trưởng'!G5) | E6: ='02. Chỉ huy trưởng'!C25 | F6: ='02. Chỉ huy trưởng'!C24 | G6: =IF(E6="","",F6-E6) | H6: ='02. Chỉ huy trưởng'!C27 | I6: ='02. Chỉ huy trưởng'!H25 | J6: ='02. Chỉ huy trưởng'!H26 | K6: ='02. Chỉ huy trưởng'!H27 | L6: ='02. Chỉ huy trưởng'!C26
A7: 3 | B7: Kỹ sư giám sát hiện trường (Site Engineer) | C7: =IF('03. KS giám sát hiện trường'!C4="","",'03. KS giám sát hiện trường'!C4) | D7: =IF('03. KS giám sát hiện trường'!G5="",'03. KS giám sát hiện trường'!G4,'03. KS giám sát hiện trường'!G5) | E7: ='03. KS giám sát hiện trường'!C25 | F7: ='03. KS giám sát hiện trường'!C24 | G7: =IF(E7="","",F7-E7) | H7: ='03. KS giám sát hiện trường'!C27 | I7: ='03. KS giám sát hiện trường'!H25 | J7: ='03. KS giám sát hiện trường'!H26 | K7: ='03. KS giám sát hiện trường'!H27 | L7: ='03. KS giám sát hiện trường'!C26
A8: 4 | B8: Kỹ sư quản lý chất lượng (QA/QC) | C8: =IF('04. KS QA-QC'!C4="","",'04. KS QA-QC'!C4) | D8: =IF('04. KS QA-QC'!G5="",'04. KS QA-QC'!G4,'04. KS QA-QC'!G5) | E8: ='04. KS QA-QC'!C25 | F8: ='04. KS QA-QC'!C24 | G8: =IF(E8="","",F8-E8) | H8: ='04. KS QA-QC'!C27 | I8: ='04. KS QA-QC'!H25 | J8: ='04. KS QA-QC'!H26 | K8: ='04. KS QA-QC'!H27 | L8: ='04. KS QA-QC'!C26
A9: 5 | B9: Cán bộ an toàn, vệ sinh lao động (HSE) | C9: =IF('05. CB an toàn HSE'!C4="","",'05. CB an toàn HSE'!C4) | D9: =IF('05. CB an toàn HSE'!G5="",'05. CB an toàn HSE'!G4,'05. CB an toàn HSE'!G5) | E9: ='05. CB an toàn HSE'!C25 | F9: ='05. CB an toàn HSE'!C24 | G9: =IF(E9="","",F9-E9) | H9: ='05. CB an toàn HSE'!C27 | I9: ='05. CB an toàn HSE'!H25 | J9: ='05. CB an toàn HSE'!H26 | K9: ='05. CB an toàn HSE'!H27 | L9: ='05. CB an toàn HSE'!C26
A10: 6 | B10: Kỹ sư dự toán – đấu thầu | C10: =IF('06. KS dự toán - đấu thầu'!C4="","",'06. KS dự toán - đấu thầu'!C4) | D10: =IF('06. KS dự toán - đấu thầu'!G5="",'06. KS dự toán - đấu thầu'!G4,'06. KS dự toán - đấu thầu'!G5) | E10: ='06. KS dự toán - đấu thầu'!C25 | F10: ='06. KS dự toán - đấu thầu'!C24 | G10: =IF(E10="","",F10-E10) | H10: ='06. KS dự toán - đấu thầu'!C27 | I10: ='06. KS dự toán - đấu thầu'!H25 | J10: ='06. KS dự toán - đấu thầu'!H26 | K10: ='06. KS dự toán - đấu thầu'!H27 | L10: ='06. KS dự toán - đấu thầu'!C26
A11: 7 | B11: Kỹ sư thanh toán – quyết toán, hồ sơ hoàn công | C11: =IF('07. KS thanh quyết toán'!C4="","",'07. KS thanh quyết toán'!C4) | D11: =IF('07. KS thanh quyết toán'!G5="",'07. KS thanh quyết toán'!G4,'07. KS thanh quyết toán'!G5) | E11: ='07. KS thanh quyết toán'!C25 | F11: ='07. KS thanh quyết toán'!C24 | G11: =IF(E11="","",F11-E11) | H11: ='07. KS thanh quyết toán'!C27 | I11: ='07. KS thanh quyết toán'!H25 | J11: ='07. KS thanh quyết toán'!H26 | K11: ='07. KS thanh quyết toán'!H27 | L11: ='07. KS thanh quyết toán'!C26
A12: 8 | B12: Kỹ sư kỹ thuật – bản vẽ thi công (Shop drawing) | C12: =IF('08. KS kỹ thuật - bản vẽ'!C4="","",'08. KS kỹ thuật - bản vẽ'!C4) | D12: =IF('08. KS kỹ thuật - bản vẽ'!G5="",'08. KS kỹ thuật - bản vẽ'!G4,'08. KS kỹ thuật - bản vẽ'!G5) | E12: ='08. KS kỹ thuật - bản vẽ'!C25 | F12: ='08. KS kỹ thuật - bản vẽ'!C24 | G12: =IF(E12="","",F12-E12) | H12: ='08. KS kỹ thuật - bản vẽ'!C27 | I12: ='08. KS kỹ thuật - bản vẽ'!H25 | J12: ='08. KS kỹ thuật - bản vẽ'!H26 | K12: ='08. KS kỹ thuật - bản vẽ'!H27 | L12: ='08. KS kỹ thuật - bản vẽ'!C26
A13: 9 | B13: Kỹ sư cơ điện (MEP) | C13: =IF('09. KS cơ điện MEP'!C4="","",'09. KS cơ điện MEP'!C4) | D13: =IF('09. KS cơ điện MEP'!G5="",'09. KS cơ điện MEP'!G4,'09. KS cơ điện MEP'!G5) | E13: ='09. KS cơ điện MEP'!C25 | F13: ='09. KS cơ điện MEP'!C24 | G13: =IF(E13="","",F13-E13) | H13: ='09. KS cơ điện MEP'!C27 | I13: ='09. KS cơ điện MEP'!H25 | J13: ='09. KS cơ điện MEP'!H26 | K13: ='09. KS cơ điện MEP'!H27 | L13: ='09. KS cơ điện MEP'!C26
A14: 10 | B14: Cán bộ trắc đạc | C14: =IF('10. Trắc đạc viên'!C4="","",'10. Trắc đạc viên'!C4) | D14: =IF('10. Trắc đạc viên'!G5="",'10. Trắc đạc viên'!G4,'10. Trắc đạc viên'!G5) | E14: ='10. Trắc đạc viên'!C25 | F14: ='10. Trắc đạc viên'!C24 | G14: =IF(E14="","",F14-E14) | H14: ='10. Trắc đạc viên'!C27 | I14: ='10. Trắc đạc viên'!H25 | J14: ='10. Trắc đạc viên'!H26 | K14: ='10. Trắc đạc viên'!H27 | L14: ='10. Trắc đạc viên'!C26
A15: 11 | B15: Cán bộ vật tư – thủ kho công trường | C15: =IF('11. CB vật tư - thủ kho CT'!C4="","",'11. CB vật tư - thủ kho CT'!C4) | D15: =IF('11. CB vật tư - thủ kho CT'!G5="",'11. CB vật tư - thủ kho CT'!G4,'11. CB vật tư - thủ kho CT'!G5) | E15: ='11. CB vật tư - thủ kho CT'!C25 | F15: ='11. CB vật tư - thủ kho CT'!C24 | G15: =IF(E15="","",F15-E15) | H15: ='11. CB vật tư - thủ kho CT'!C27 | I15: ='11. CB vật tư - thủ kho CT'!H25 | J15: ='11. CB vật tư - thủ kho CT'!H26 | K15: ='11. CB vật tư - thủ kho CT'!H27 | L15: ='11. CB vật tư - thủ kho CT'!C26
A16: 12 | B16: Kế toán công trình | C16: =IF('12. Kế toán công trình'!C4="","",'12. Kế toán công trình'!C4) | D16: =IF('12. Kế toán công trình'!G5="",'12. Kế toán công trình'!G4,'12. Kế toán công trình'!G5) | E16: ='12. Kế toán công trình'!C25 | F16: ='12. Kế toán công trình'!C24 | G16: =IF(E16="","",F16-E16) | H16: ='12. Kế toán công trình'!C27 | I16: ='12. Kế toán công trình'!H25 | J16: ='12. Kế toán công trình'!H26 | K16: ='12. Kế toán công trình'!H27 | L16: ='12. Kế toán công trình'!C26
B18: THỐNG KÊ TOÀN CÔNG TY
B19: Số vị trí xếp loại Xuất sắc | C19: =COUNTIF(H5:H16,"Xuất sắc")
B20: Số vị trí xếp loại Đạt | C20: =COUNTIF(H5:H16,"Đạt")
B21: Số vị trí xếp loại Cần cải thiện | C21: =COUNTIF(H5:H16,"Cần cải thiện")
B22: Số vị trí chưa chấm / chưa chấm đủ | C22: =COUNTIF(H5:H16,"Chưa chấm")+COUNTIF(H5:H16,"Chưa chấm đủ")
B23: Điểm bình quân (vị trí đã chấm đủ) | C23: =IFERROR(AVERAGEIFS(F5:F16,H5:H16,"<>Chưa chấm",H5:H16,"<>Chưa chấm đủ"),"")
B25: Chênh lệch tô đỏ khi điểm chính thức lệch điểm tự đánh giá từ 10 điểm trở lên – nên trao đổi kỹ ở Bước 5. Nhân sự "Cần cải thiện" từ 02 kỳ liên tiếp trở lên thuộc diện đào tạo, kèm cặp (Điều 14).

Sheet So sánh
A1: SO SÁNH KẾT QUẢ GIỮA CÁC VỊ TRÍ
A2: Phụ lục 01 · Dữ liệu lấy từ sheet Tổng hợp · KK HOME ·
A4: STT | B4: Vị trí | C4: Điểm tự ĐG | D4: Điểm chính thức | E4: Chuyên môn | F4: Tuân thủ | G4: Phối hợp
A5: 1 | B5: ='Tổng hợp'!B5 | C5: =IF('Tổng hợp'!E5="",0,'Tổng hợp'!E5) | D5: ='Tổng hợp'!F5 | E5: ='Tổng hợp'!I5 | F5: ='Tổng hợp'!J5 | G5: ='Tổng hợp'!K5
A6: 2 | B6: ='Tổng hợp'!B6 | C6: =IF('Tổng hợp'!E6="",0,'Tổng hợp'!E6) | D6: ='Tổng hợp'!F6 | E6: ='Tổng hợp'!I6 | F6: ='Tổng hợp'!J6 | G6: ='Tổng hợp'!K6
A7: 3 | B7: ='Tổng hợp'!B7 | C7: =IF('Tổng hợp'!E7="",0,'Tổng hợp'!E7) | D7: ='Tổng hợp'!F7 | E7: ='Tổng hợp'!I7 | F7: ='Tổng hợp'!J7 | G7: ='Tổng hợp'!K7
A8: 4 | B8: ='Tổng hợp'!B8 | C8: =IF('Tổng hợp'!E8="",0,'Tổng hợp'!E8) | D8: ='Tổng hợp'!F8 | E8: ='Tổng hợp'!I8 | F8: ='Tổng hợp'!J8 | G8: ='Tổng hợp'!K8
A9: 5 | B9: ='Tổng hợp'!B9 | C9: =IF('Tổng hợp'!E9="",0,'Tổng hợp'!E9) | D9: ='Tổng hợp'!F9 | E9: ='Tổng hợp'!I9 | F9: ='Tổng hợp'!J9 | G9: ='Tổng hợp'!K9
A10: 6 | B10: ='Tổng hợp'!B10 | C10: =IF('Tổng hợp'!E10="",0,'Tổng hợp'!E10) | D10: ='Tổng hợp'!F10 | E10: ='Tổng hợp'!I10 | F10: ='Tổng hợp'!J10 | G10: ='Tổng hợp'!K10
A11: 7 | B11: ='Tổng hợp'!B11 | C11: =IF('Tổng hợp'!E11="",0,'Tổng hợp'!E11) | D11: ='Tổng hợp'!F11 | E11: ='Tổng hợp'!I11 | F11: ='Tổng hợp'!J11 | G11: ='Tổng hợp'!K11
A12: 8 | B12: ='Tổng hợp'!B12 | C12: =IF('Tổng hợp'!E12="",0,'Tổng hợp'!E12) | D12: ='Tổng hợp'!F12 | E12: ='Tổng hợp'!I12 | F12: ='Tổng hợp'!J12 | G12: ='Tổng hợp'!K12
A13: 9 | B13: ='Tổng hợp'!B13 | C13: =IF('Tổng hợp'!E13="",0,'Tổng hợp'!E13) | D13: ='Tổng hợp'!F13 | E13: ='Tổng hợp'!I13 | F13: ='Tổng hợp'!J13 | G13: ='Tổng hợp'!K13
A14: 10 | B14: ='Tổng hợp'!B14 | C14: =IF('Tổng hợp'!E14="",0,'Tổng hợp'!E14) | D14: ='Tổng hợp'!F14 | E14: ='Tổng hợp'!I14 | F14: ='Tổng hợp'!J14 | G14: ='Tổng hợp'!K14
A15: 11 | B15: ='Tổng hợp'!B15 | C15: =IF('Tổng hợp'!E15="",0,'Tổng hợp'!E15) | D15: ='Tổng hợp'!F15 | E15: ='Tổng hợp'!I15 | F15: ='Tổng hợp'!J15 | G15: ='Tổng hợp'!K15
A16: 12 | B16: ='Tổng hợp'!B16 | C16: =IF('Tổng hợp'!E16="",0,'Tổng hợp'!E16) | D16: ='Tổng hợp'!F16 | E16: ='Tổng hợp'!I16 | F16: ='Tổng hợp'!J16 | G16: ='Tổng hợp'!K16
A18: Biểu đồ tự cập nhật khi chấm điểm ở các sheet vị trí. Vị trí chưa chấm hiển thị 0.

Sheet Nguyên tắc chấm
A1: NGUYÊN TẮC CHẤM ĐIỂM KPI
A2: Phụ lục 01 · Căn cứ Điều 4, 6, 7, 10, 12, 13 Quy chế · KK HOME ·
B4: 1. THANG ĐIỂM 1–5 (Điều 6)
B5: Điểm | C5: Xếp hạng | D5: Diễn giải
B6: 5 | C6: Tuyệt vời | D6: Hoàn thành xuất sắc, vượt mong đợi, tự giác và chủ động
B7: 4 | C7: Tốt | D7: Hoàn thành tốt, đạt hoặc vượt mục tiêu đề ra
B8: 3 | C8: Bình thường | D8: Đáp ứng đủ yêu cầu cơ bản
B9: 2 | C9: Chưa đạt | D9: Chưa hoàn thành tốt, có lỗi nhỏ, cần cải thiện
B10: 1 | C10: Kém | D10: Chưa hoàn thành, cần hỗ trợ nhiều, sai sót lớn
B11: Kết quả dao động giữa hai mức liền kề: được chấm điểm trung bình (VD: 3.5).
B13: 2. CÔNG THỨC & XẾP LOẠI (Điều 7, Điều 13)
B14: Điểm quy đổi tiêu chí | C14: Điểm chấm ÷ 5 × Trọng số × 100
B15: Tổng điểm vị trí | C15: Cộng điểm quy đổi các tiêu chí (tối đa 100)
B16: Xuất sắc | C16: Tổng điểm ≥ 80
B17: Đạt | C17: Từ 70 đến dưới 80
B18: Cần cải thiện | C18: Dưới 70
B20: 3. GỢI Ý QUY ĐỔI CHỨNG CỨ RA ĐIỂM (mẫu – điều chỉnh theo mục tiêu đã duyệt từng kỳ)
B21: Loại chỉ số | C21: Điểm 5 | D21: Điểm 4 | E21: Điểm 3 | F21: Điểm 2 | G21: Điểm 1
B22: Tiến độ thi công so với kế hoạch | C22: Vượt tiến độ, không tăng chi phí | D22: Đạt 100% kế hoạch | E22: 95% – dưới 100% | F22: 85% – dưới 95% | G22: Dưới 85% hoặc trễ mốc hợp đồng
B23: An toàn lao động | C23: 0 tai nạn, 0 lỗi tồn đọng | D23: 0 tai nạn, lỗi khắc phục đúng hạn | E23: 0 tai nạn, có lỗi khắc phục trễ | F23: Tai nạn nhẹ hoặc bị lập biên bản vi phạm | G23: Tai nạn nặng, chết người
B24: Nghiệm thu đạt ngay lần đầu | C24: ≥ 98% | D24: 95% – dưới 98% | E24: 90% – dưới 95% | F24: 80% – dưới 90% | G24: Dưới 80% hoặc phải phá dỡ
B25: Chi phí thực tế so với dự toán | C25: Tiết kiệm ≥ 5%, vẫn đạt chất lượng | D25: Trong dự toán | E25: Vượt ≤ 3%, có giải trình được duyệt | F25: Vượt 3% – 10% | G25: Vượt > 10%
B26: Hao hụt vật tư so với định mức | C26: Thấp hơn định mức ≥ 20% | D26: Trong định mức | E26: Vượt ≤ 5% định mức | F26: Vượt 5% – 15% | G26: Vượt > 15% hoặc mất mát
B27: Hồ sơ thanh toán, hoàn công | C27: Trước hạn, được duyệt ngay | D27: Đúng hạn | E27: Trễ ≤ 3 ngày | F27: Trễ 3 – 10 ngày | G27: Trễ > 10 ngày, ảnh hưởng dòng tiền
B29: 4. NGUYÊN TẮC ĐÁNH GIÁ (Điều 4, Điều 12)
B30: Khách quan | C30: Chấm theo kết quả thực tế, không theo thiện cảm cá nhân.
B31: Công bằng | C31: Cùng vị trí dùng chung bộ tiêu chí, trọng số, thang điểm.
B32: Công khai | C32: Tiêu chí, trọng số, chỉ tiêu định lượng phổ biến cho nhân sự trước kỳ đánh giá.
B33: Định kỳ | C33: Loại kỳ (Tháng/Quý/Năm) áp dụng thống nhất cho toàn phòng trong cùng chu kỳ.
B34: Có phản hồi | C34: Trao đổi kết quả trực tiếp, thống nhất kế hoạch cải thiện.
B35: Có chứng cứ | C35: Số liệu, thời hạn, biên bản, báo cáo. Điểm ≤ 1,5 hoặc = 5 phải ghi lý do ở cột Ghi chú.
B37: 5. QUY TRÌNH 6 BƯỚC (Điều 10)
B38: Bước 1 – Chuẩn bị | C38: Xác định kỳ, thông báo lịch, phổ biến tiêu chí.
B39: Bước 2 – Tự đánh giá | C39: Nhân sự chấm cột F.
B40: Bước 3 – Quản lý chấm | C40: Quản lý trực tiếp chấm chính thức cột G, dựa trên chứng cứ.
B41: Bước 4 – Tổng hợp | C41: File tự tính điểm quy đổi, xếp loại; sheet Tổng hợp tự cập nhật.
B42: Bước 5 – Phản hồi | C42: Trao đổi kết quả, ghi nhận xét và kế hoạch cải thiện cuối sheet vị trí.
B43: Bước 6 – Phê duyệt, lưu trữ | C43: Trình người có thẩm quyền ký duyệt; lưu hồ sơ làm căn cứ lương, thưởng, quy hoạch.

Sheet 01. Giám đốc dự án
A1: BẢNG ĐÁNH GIÁ KPI – GIÁM ĐỐC DỰ ÁN (PROJECT MANAGER)
A2: Công ty xây dựng · Phụ lục 01 kèm Quy chế đánh giá KPI · KK HOME ·
B4: Họ và tên | E4: Loại kỳ đánh giá | G4: Quý | I4: ← chọn Tháng / Quý / Năm
B5: Mã nhân viên | E5: Kỳ đánh giá | I5: VD: Tháng 9/2026, Quý 3/2026, Năm 2026
B6: Người đánh giá | E6: Ngày đánh giá
B7: Bộ phận | C7: [Ban dự án / Công trường / Phòng ...]
A9: STT | B9: Nhóm tiêu chí | C9: Tiêu chí đánh giá | D9: Cách đo / Chứng cứ chấm điểm | E9: Trọng số | F9: Tự đánh giá (1–5) | G9: Quản lý chấm (1–5) | H9: Điểm quy đổi | I9: Ghi chú / Lý do (bắt buộc khi điểm ≤1,5 hoặc 5)
A10: 1 | B10: Chuyên môn - Nghiệp vụ | C10: Tiến độ dự án | D10: Các mốc tiến độ tổng đạt đúng kế hoạch đã duyệt; chỉ số tiến độ (SPI) ≥ 0,95 | E10: 0.12 | H10: =IF(ISNUMBER(G10),G10/5*E10*100,0) | J10: CM
A11: 2 | C11: Kiểm soát chi phí dự án | D11: Chi phí thực tế so với ngân sách, dự toán được duyệt; lợi nhuận gộp dự án đạt kế hoạch | E11: 0.1 | H11: =IF(ISNUMBER(G11),G11/5*E11*100,0) | J11: CM
A12: 3 | C12: Chất lượng công trình | D12: Tỷ lệ hạng mục nghiệm thu đạt ngay lần đầu; không có hạng mục phải phá dỡ làm lại | E12: 0.1 | H12: =IF(ISNUMBER(G12),G12/5*E12*100,0) | J12: CM
A13: 4 | C13: Giá trị nghiệm thu, thanh toán | D13: Giá trị khối lượng được chủ đầu tư nghiệm thu, xuất hóa đơn so với kế hoạch dòng tiền | E13: 0.08 | H13: =IF(ISNUMBER(G13),G13/5*E13*100,0) | J13: CM
A14: 5 | B14: Tuân thủ - Thời hạn | C14: An toàn lao động công trường | D14: 0 tai nạn lao động nghiêm trọng; lỗi an toàn được khắc phục đúng hạn | E14: 0.1 | H14: =IF(ISNUMBER(G14),G14/5*E14*100,0) | J14: TT
A15: 6 | C15: Quản lý hợp đồng & phát sinh | D15: Phát sinh, thay đổi thiết kế có văn bản xác nhận của chủ đầu tư trước khi thi công | E15: 0.1 | H15: =IF(ISNUMBER(G15),G15/5*E15*100,0) | J15: TT
A16: 7 | C16: Báo cáo dự án đúng hạn | D16: Báo cáo tuần, tháng gửi Ban Giám đốc và chủ đầu tư đúng hạn, số liệu khớp | E16: 0.08 | H16: =IF(ISNUMBER(G16),G16/5*E16*100,0) | J16: TT
A17: 8 | C17: Hồ sơ pháp lý, chất lượng, hoàn công | D17: Hồ sơ quản lý chất lượng, nhật ký, hoàn công cập nhật theo tiến độ | E17: 0.07 | H17: =IF(ISNUMBER(G17),G17/5*E17*100,0) | J17: TT
A18: 9 | B18: Phối hợp - Thái độ | C18: Quan hệ chủ đầu tư, tư vấn giám sát | D18: Phản hồi, đánh giá của chủ đầu tư; số khiếu nại chính thức | E18: 0.1 | H18: =IF(ISNUMBER(G18),G18/5*E18*100,0) | J18: PH
A19: 10 | C19: Điều phối nhà thầu phụ, các bộ phận | D19: Vướng mắc, chồng chéo được xử lý trong 48 giờ; giao ban đầy đủ | E19: 0.08 | H19: =IF(ISNUMBER(G19),G19/5*E19*100,0) | J19: PH
A20: 11 | C20: Phát triển đội ngũ dự án | D20: Điểm KPI bình quân ban dự án; số nhân sự được đào tạo, kèm cặp | E20: 0.07 | H20: =IF(ISNUMBER(G20),G20/5*E20*100,0) | J20: PH
A21: TỔNG CỘNG | E21: =SUM(E10:E20) | H21: =SUM(H10:H20)
A23: KẾT QUẢ ĐÁNH GIÁ | D23: ĐIỂM THEO NHÓM TIÊU CHÍ
A24: Tổng điểm chính thức | C24: =H21 | D24: Nhóm tiêu chí | E24: Trọng số | F24: Điểm tối đa | G24: Điểm đạt | H24: Tỷ lệ đạt
A25: Điểm tự đánh giá | C25: =IF(COUNT(F10:F20)=0,"",SUMPRODUCT(F10:F20,E10:E20)/5*100) | D25: Chuyên môn - Nghiệp vụ | E25: =SUMIF($J$10:$J$20,"CM",$E$10:$E$20) | F25: =E25*100 | G25: =SUMIF($J$10:$J$20,"CM",$H$10:$H$20) | H25: =IF(F25=0,0,G25/F25)
A26: Tiêu chí đã chấm | C26: =COUNT(G10:G20)&" / 11" | D26: Tuân thủ - Thời hạn | E26: =SUMIF($J$10:$J$20,"TT",$E$10:$E$20) | F26: =E26*100 | G26: =SUMIF($J$10:$J$20,"TT",$H$10:$H$20) | H26: =IF(F26=0,0,G26/F26)
A27: Xếp loại | C27: =IF(COUNT(G10:G20)=0,"Chưa chấm",IF(COUNT(G10:G20)<11,"Chưa chấm đủ",IF(H21>=80,"Xuất sắc",IF(H21>=70,"Đạt","Cần cải thiện")))) | D27: Phối hợp - Thái độ | E27: =SUMIF($J$10:$J$20,"PH",$E$10:$E$20) | F27: =E27*100 | G27: =SUMIF($J$10:$J$20,"PH",$H$10:$H$20) | H27: =IF(F27=0,0,G27/F27)
A28: Kiểm tra trọng số | C28: =IF(ROUND(E21,4)=1,"Hợp lệ – 100%","SAI – tổng trọng số phải = 100%")
A30: NHẬN XÉT & KẾ HOẠCH CẢI THIỆN (Bước 5 – phản hồi kết quả)
A31: Điểm mạnh
A32: Cần cải thiện
A33: Kế hoạch cải thiện
A34: Ý kiến nhân sự
B36: NHÂN SỰ ĐƯỢC ĐÁNH GIÁ | D36: QUẢN LÝ TRỰC TIẾP | G36: NGƯỜI PHÊ DUYỆT
B37: (Ký, ghi rõ họ tên) | D37: (Ký, ghi rõ họ tên) | G37: (Ký, ghi rõ họ tên)

Sheet 02. Chỉ huy trưởng
A1: BẢNG ĐÁNH GIÁ KPI – CHỈ HUY TRƯỞNG CÔNG TRƯỜNG
A2: Công ty xây dựng · Phụ lục 01 kèm Quy chế đánh giá KPI · KK HOME ·
B4: Họ và tên | E4: Loại kỳ đánh giá | G4: Quý | I4: ← chọn Tháng / Quý / Năm
B5: Mã nhân viên | E5: Kỳ đánh giá | I5: VD: Tháng 9/2026, Quý 3/2026, Năm 2026
B6: Người đánh giá | E6: Ngày đánh giá
B7: Bộ phận | C7: [Ban dự án / Công trường / Phòng ...]
A9: STT | B9: Nhóm tiêu chí | C9: Tiêu chí đánh giá | D9: Cách đo / Chứng cứ chấm điểm | E9: Trọng số | F9: Tự đánh giá (1–5) | G9: Quản lý chấm (1–5) | H9: Điểm quy đổi | I9: Ghi chú / Lý do (bắt buộc khi điểm ≤1,5 hoặc 5)
A10: 1 | B10: Chuyên môn - Nghiệp vụ | C10: Tiến độ thi công tuần, tháng | D10: Khối lượng hoàn thành so với kế hoạch tuần, tháng ≥ 95% | E10: 0.12 | H10: =IF(ISNUMBER(G10),G10/5*E10*100,0) | J10: CM
A11: 2 | C11: Tổ chức nhân lực, máy, mặt bằng | D11: Năng suất tổ đội; thời gian máy chờ việc; bố trí mặt bằng hợp lý | E11: 0.1 | H11: =IF(ISNUMBER(G11),G11/5*E11*100,0) | J11: CM
A12: 3 | C12: Chất lượng thi công | D12: Hạng mục đạt nghiệm thu nội bộ và nghiệm thu với tư vấn giám sát ngay lần đầu | E12: 0.1 | H12: =IF(ISNUMBER(G12),G12/5*E12*100,0) | J12: CM
A13: 4 | C13: Kiểm soát vật tư công trường | D13: Hao hụt vật tư chính (thép, bê tông, xi măng) trong định mức | E13: 0.08 | H13: =IF(ISNUMBER(G13),G13/5*E13*100,0) | J13: CM
A14: 5 | B14: Tuân thủ - Thời hạn | C14: An toàn, vệ sinh lao động | D14: 0 tai nạn; 100% công nhân được huấn luyện, có bảo hộ; biên bản an toàn khắc phục đúng hạn | E14: 0.12 | H14: =IF(ISNUMBER(G14),G14/5*E14*100,0) | J14: TT
A15: 6 | C15: Nhật ký thi công & biên bản | D15: Nhật ký ghi hằng ngày; biên bản nghiệm thu công việc ký đúng thời điểm | E15: 0.08 | H15: =IF(ISNUMBER(G15),G15/5*E15*100,0) | J15: TT
A16: 7 | C16: Tuân thủ biện pháp, bản vẽ | D16: Thi công đúng biện pháp, bản vẽ được duyệt; không thi công khi chưa có bản vẽ | E16: 0.08 | H16: =IF(ISNUMBER(G16),G16/5*E16*100,0) | J16: TT
A17: 8 | C17: Môi trường, an ninh công trường | D17: Không bị nhắc nhở, xử phạt về bụi, tiếng ồn, chất thải, trật tự | E17: 0.07 | H17: =IF(ISNUMBER(G17),G17/5*E17*100,0) | J17: TT
A18: 9 | B18: Phối hợp - Thái độ | C18: Phối hợp tư vấn giám sát, chủ đầu tư | D18: Yêu cầu nghiệm thu gửi đúng hạn; phản hồi của tư vấn giám sát | E18: 0.1 | H18: =IF(ISNUMBER(G18),G18/5*E18*100,0) | J18: PH
A19: 10 | C19: Quản lý nhà thầu phụ, tổ đội | D19: Nhà thầu phụ tuân thủ tiến độ, an toàn; vướng mắc được xử lý kịp thời | E19: 0.08 | H19: =IF(ISNUMBER(G19),G19/5*E19*100,0) | J19: PH
A20: 11 | C20: Tinh thần trách nhiệm | D20: Có mặt công trường theo yêu cầu; xử lý sự cố ngoài giờ | E20: 0.07 | H20: =IF(ISNUMBER(G20),G20/5*E20*100,0) | J20: PH
A21: TỔNG CỘNG | E21: =SUM(E10:E20) | H21: =SUM(H10:H20)
A23: KẾT QUẢ ĐÁNH GIÁ | D23: ĐIỂM THEO NHÓM TIÊU CHÍ
A24: Tổng điểm chính thức | C24: =H21 | D24: Nhóm tiêu chí | E24: Trọng số | F24: Điểm tối đa | G24: Điểm đạt | H24: Tỷ lệ đạt
A25: Điểm tự đánh giá | C25: =IF(COUNT(F10:F20)=0,"",SUMPRODUCT(F10:F20,E10:E20)/5*100) | D25: Chuyên môn - Nghiệp vụ | E25: =SUMIF($J$10:$J$20,"CM",$E$10:$E$20) | F25: =E25*100 | G25: =SUMIF($J$10:$J$20,"CM",$H$10:$H$20) | H25: =IF(F25=0,0,G25/F25)
A26: Tiêu chí đã chấm | C26: =COUNT(G10:G20)&" / 11" | D26: Tuân thủ - Thời hạn | E26: =SUMIF($J$10:$J$20,"TT",$E$10:$E$20) | F26: =E26*100 | G26: =SUMIF($J$10:$J$20,"TT",$H$10:$H$20) | H26: =IF(F26=0,0,G26/F26)
A27: Xếp loại | C27: =IF(COUNT(G10:G20)=0,"Chưa chấm",IF(COUNT(G10:G20)<11,"Chưa chấm đủ",IF(H21>=80,"Xuất sắc",IF(H21>=70,"Đạt","Cần cải thiện")))) | D27: Phối hợp - Thái độ | E27: =SUMIF($J$10:$J$20,"PH",$E$10:$E$20) | F27: =E27*100 | G27: =SUMIF($J$10:$J$20,"PH",$H$10:$H$20) | H27: =IF(F27=0,0,G27/F27)
A28: Kiểm tra trọng số | C28: =IF(ROUND(E21,4)=1,"Hợp lệ – 100%","SAI – tổng trọng số phải = 100%")
A30: NHẬN XÉT & KẾ HOẠCH CẢI THIỆN (Bước 5 – phản hồi kết quả)
A31: Điểm mạnh
A32: Cần cải thiện
A33: Kế hoạch cải thiện
A34: Ý kiến nhân sự
B36: NHÂN SỰ ĐƯỢC ĐÁNH GIÁ | D36: QUẢN LÝ TRỰC TIẾP | G36: NGƯỜI PHÊ DUYỆT
B37: (Ký, ghi rõ họ tên) | D37: (Ký, ghi rõ họ tên) | G37: (Ký, ghi rõ họ tên)

Sheet 03. KS giám sát hiện trường
A1: BẢNG ĐÁNH GIÁ KPI – KỸ SƯ GIÁM SÁT HIỆN TRƯỜNG (SITE ENGINEER)
A2: Công ty xây dựng · Phụ lục 01 kèm Quy chế đánh giá KPI · KK HOME ·
B4: Họ và tên | E4: Loại kỳ đánh giá | G4: Quý | I4: ← chọn Tháng / Quý / Năm
B5: Mã nhân viên | E5: Kỳ đánh giá | I5: VD: Tháng 9/2026, Quý 3/2026, Năm 2026
B6: Người đánh giá | E6: Ngày đánh giá
B7: Bộ phận | C7: [Ban dự án / Công trường / Phòng ...]
A9: STT | B9: Nhóm tiêu chí | C9: Tiêu chí đánh giá | D9: Cách đo / Chứng cứ chấm điểm | E9: Trọng số | F9: Tự đánh giá (1–5) | G9: Quản lý chấm (1–5) | H9: Điểm quy đổi | I9: Ghi chú / Lý do (bắt buộc khi điểm ≤1,5 hoặc 5)
A10: 1 | B10: Chuyên môn - Nghiệp vụ | C10: Khối lượng hạng mục phụ trách | D10: Khối lượng hạng mục được giao đạt kế hoạch tuần | E10: 0.12 | H10: =IF(ISNUMBER(G10),G10/5*E10*100,0) | J10: CM
A11: 2 | C11: Kiểm tra kỹ thuật trước nghiệm thu | D11: Kiểm tra nội bộ đủ trước khi mời tư vấn giám sát; tỷ lệ đạt lần đầu | E11: 0.1 | H11: =IF(ISNUMBER(G11),G11/5*E11*100,0) | J11: CM
A12: 3 | C12: Bóc tách khối lượng hằng ngày | D12: Khối lượng thực hiện, nhân công, vật tư báo cáo hằng ngày chính xác | E12: 0.1 | H12: =IF(ISNUMBER(G12),G12/5*E12*100,0) | J12: CM
A13: 4 | C13: Xử lý kỹ thuật hiện trường | D13: Vướng mắc kỹ thuật được báo cáo, đề xuất hướng xử lý trong 24 giờ | E13: 0.08 | H13: =IF(ISNUMBER(G13),G13/5*E13*100,0) | J13: CM
A14: 5 | B14: Tuân thủ - Thời hạn | C14: An toàn khu vực phụ trách | D14: Không có vi phạm an toàn nghiêm trọng tại khu vực phụ trách | E14: 0.1 | H14: =IF(ISNUMBER(G14),G14/5*E14*100,0) | J14: TT
A15: 6 | C15: Biên bản nghiệm thu công việc | D15: Biên bản lập đúng thời điểm, đủ chữ ký các bên | E15: 0.1 | H15: =IF(ISNUMBER(G15),G15/5*E15*100,0) | J15: TT
A16: 7 | C16: Thi công đúng bản vẽ | D16: Không có sai lệch so với bản vẽ được duyệt phải sửa chữa | E16: 0.08 | H16: =IF(ISNUMBER(G16),G16/5*E16*100,0) | J16: TT
A17: 8 | C17: Báo cáo ngày, tuần đúng hạn | D17: Báo cáo gửi Chỉ huy trưởng đúng giờ quy định | E17: 0.07 | H17: =IF(ISNUMBER(G17),G17/5*E17*100,0) | J17: TT
A18: 9 | B18: Phối hợp - Thái độ | C18: Phối hợp tổ đội, nhà thầu phụ | D18: Hướng dẫn kỹ thuật rõ ràng; không phát sinh xung đột kéo dài | E18: 0.1 | H18: =IF(ISNUMBER(G18),G18/5*E18*100,0) | J18: PH
A19: 10 | C19: Đề xuất cải tiến | D19: Số đề xuất cải tiến biện pháp, tiết kiệm vật tư được áp dụng | E19: 0.08 | H19: =IF(ISNUMBER(G19),G19/5*E19*100,0) | J19: PH
A20: 11 | C20: Kỷ luật, thái độ | D20: Chấp hành giờ giấc, nội quy công trường | E20: 0.07 | H20: =IF(ISNUMBER(G20),G20/5*E20*100,0) | J20: PH
A21: TỔNG CỘNG | E21: =SUM(E10:E20) | H21: =SUM(H10:H20)
A23: KẾT QUẢ ĐÁNH GIÁ | D23: ĐIỂM THEO NHÓM TIÊU CHÍ
A24: Tổng điểm chính thức | C24: =H21 | D24: Nhóm tiêu chí | E24: Trọng số | F24: Điểm tối đa | G24: Điểm đạt | H24: Tỷ lệ đạt
A25: Điểm tự đánh giá | C25: =IF(COUNT(F10:F20)=0,"",SUMPRODUCT(F10:F20,E10:E20)/5*100) | D25: Chuyên môn - Nghiệp vụ | E25: =SUMIF($J$10:$J$20,"CM",$E$10:$E$20) | F25: =E25*100 | G25: =SUMIF($J$10:$J$20,"CM",$H$10:$H$20) | H25: =IF(F25=0,0,G25/F25)
A26: Tiêu chí đã chấm | C26: =COUNT(G10:G20)&" / 11" | D26: Tuân thủ - Thời hạn | E26: =SUMIF($J$10:$J$20,"TT",$E$10:$E$20) | F26: =E26*100 | G26: =SUMIF($J$10:$J$20,"TT",$H$10:$H$20) | H26: =IF(F26=0,0,G26/F26)
A27: Xếp loại | C27: =IF(COUNT(G10:G20)=0,"Chưa chấm",IF(COUNT(G10:G20)<11,"Chưa chấm đủ",IF(H21>=80,"Xuất sắc",IF(H21>=70,"Đạt","Cần cải thiện")))) | D27: Phối hợp - Thái độ | E27: =SUMIF($J$10:$J$20,"PH",$E$10:$E$20) | F27: =E27*100 | G27: =SUMIF($J$10:$J$20,"PH",$H$10:$H$20) | H27: =IF(F27=0,0,G27/F27)
A28: Kiểm tra trọng số | C28: =IF(ROUND(E21,4)=1,"Hợp lệ – 100%","SAI – tổng trọng số phải = 100%")
A30: NHẬN XÉT & KẾ HOẠCH CẢI THIỆN (Bước 5 – phản hồi kết quả)
A31: Điểm mạnh
A32: Cần cải thiện
A33: Kế hoạch cải thiện
A34: Ý kiến nhân sự
B36: NHÂN SỰ ĐƯỢC ĐÁNH GIÁ | D36: QUẢN LÝ TRỰC TIẾP | G36: NGƯỜI PHÊ DUYỆT
B37: (Ký, ghi rõ họ tên) | D37: (Ký, ghi rõ họ tên) | G37: (Ký, ghi rõ họ tên)

Sheet 04. KS QA-QC
A1: BẢNG ĐÁNH GIÁ KPI – KỸ SƯ QUẢN LÝ CHẤT LƯỢNG (QA/QC)
A2: Công ty xây dựng · Phụ lục 01 kèm Quy chế đánh giá KPI · KK HOME ·
B4: Họ và tên | E4: Loại kỳ đánh giá | G4: Quý | I4: ← chọn Tháng / Quý / Năm
B5: Mã nhân viên | E5: Kỳ đánh giá | I5: VD: Tháng 9/2026, Quý 3/2026, Năm 2026
B6: Người đánh giá | E6: Ngày đánh giá
B7: Bộ phận | C7: [Ban dự án / Công trường / Phòng ...]
A9: STT | B9: Nhóm tiêu chí | C9: Tiêu chí đánh giá | D9: Cách đo / Chứng cứ chấm điểm | E9: Trọng số | F9: Tự đánh giá (1–5) | G9: Quản lý chấm (1–5) | H9: Điểm quy đổi | I9: Ghi chú / Lý do (bắt buộc khi điểm ≤1,5 hoặc 5)
A10: 1 | B10: Chuyên môn - Nghiệp vụ | C10: Kế hoạch kiểm soát chất lượng | D10: Kế hoạch kiểm tra, thí nghiệm (ITP) lập đủ cho các hạng mục trước khi thi công | E10: 0.1 | H10: =IF(ISNUMBER(G10),G10/5*E10*100,0) | J10: CM
A11: 2 | C11: Kiểm tra vật liệu đầu vào | D11: 100% vật liệu chính có chứng chỉ xuất xưởng, kết quả thí nghiệm đạt trước khi sử dụng | E11: 0.12 | H11: =IF(ISNUMBER(G11),G11/5*E11*100,0) | J11: CM
A12: 3 | C12: Tỷ lệ nghiệm thu đạt lần đầu | D12: Tỷ lệ hạng mục nghiệm thu đạt ngay lần đầu ≥ 95% | E12: 0.1 | H12: =IF(ISNUMBER(G12),G12/5*E12*100,0) | J12: CM
A13: 4 | C13: Xử lý sản phẩm không phù hợp | D13: Phiếu không phù hợp (NCR) được đóng đúng hạn; lỗi không lặp lại | E13: 0.08 | H13: =IF(ISNUMBER(G13),G13/5*E13*100,0) | J13: CM
A14: 5 | B14: Tuân thủ - Thời hạn | C14: Hồ sơ quản lý chất lượng | D14: Hồ sơ chất lượng, kết quả thí nghiệm lưu đủ, đúng trình tự | E14: 0.1 | H14: =IF(ISNUMBER(G14),G14/5*E14*100,0) | J14: TT
A15: 6 | C15: Tuân thủ tiêu chuẩn, chỉ dẫn kỹ thuật | D15: Áp dụng đúng TCVN, QCVN và chỉ dẫn kỹ thuật của dự án | E15: 0.1 | H15: =IF(ISNUMBER(G15),G15/5*E15*100,0) | J15: TT
A16: 7 | C16: Lấy mẫu thí nghiệm đúng tần suất | D16: Mẫu bê tông, thép, vật liệu lấy đủ theo tiêu chuẩn | E16: 0.08 | H16: =IF(ISNUMBER(G16),G16/5*E16*100,0) | J16: TT
A17: 8 | C17: Báo cáo chất lượng định kỳ | D17: Báo cáo chất lượng tuần, tháng đúng hạn | E17: 0.07 | H17: =IF(ISNUMBER(G17),G17/5*E17*100,0) | J17: TT
A18: 9 | B18: Phối hợp - Thái độ | C18: Phối hợp tư vấn giám sát, phòng thí nghiệm | D18: Lịch nghiệm thu, thí nghiệm thống nhất, không làm chậm tiến độ | E18: 0.1 | H18: =IF(ISNUMBER(G18),G18/5*E18*100,0) | J18: PH
A19: 10 | C19: Phổ biến chất lượng cho đội thi công | D19: Số buổi phổ biến tiêu chuẩn, lỗi thường gặp cho tổ đội | E19: 0.08 | H19: =IF(ISNUMBER(G19),G19/5*E19*100,0) | J19: PH
A20: 11 | C20: Khách quan, trung thực | D20: Không bỏ qua lỗi; báo cáo đúng hiện trạng | E20: 0.07 | H20: =IF(ISNUMBER(G20),G20/5*E20*100,0) | J20: PH
A21: TỔNG CỘNG | E21: =SUM(E10:E20) | H21: =SUM(H10:H20)
A23: KẾT QUẢ ĐÁNH GIÁ | D23: ĐIỂM THEO NHÓM TIÊU CHÍ
A24: Tổng điểm chính thức | C24: =H21 | D24: Nhóm tiêu chí | E24: Trọng số | F24: Điểm tối đa | G24: Điểm đạt | H24: Tỷ lệ đạt
A25: Điểm tự đánh giá | C25: =IF(COUNT(F10:F20)=0,"",SUMPRODUCT(F10:F20,E10:E20)/5*100) | D25: Chuyên môn - Nghiệp vụ | E25: =SUMIF($J$10:$J$20,"CM",$E$10:$E$20) | F25: =E25*100 | G25: =SUMIF($J$10:$J$20,"CM",$H$10:$H$20) | H25: =IF(F25=0,0,G25/F25)
A26: Tiêu chí đã chấm | C26: =COUNT(G10:G20)&" / 11" | D26: Tuân thủ - Thời hạn | E26: =SUMIF($J$10:$J$20,"TT",$E$10:$E$20) | F26: =E26*100 | G26: =SUMIF($J$10:$J$20,"TT",$H$10:$H$20) | H26: =IF(F26=0,0,G26/F26)
A27: Xếp loại | C27: =IF(COUNT(G10:G20)=0,"Chưa chấm",IF(COUNT(G10:G20)<11,"Chưa chấm đủ",IF(H21>=80,"Xuất sắc",IF(H21>=70,"Đạt","Cần cải thiện")))) | D27: Phối hợp - Thái độ | E27: =SUMIF($J$10:$J$20,"PH",$E$10:$E$20) | F27: =E27*100 | G27: =SUMIF($J$10:$J$20,"PH",$H$10:$H$20) | H27: =IF(F27=0,0,G27/F27)
A28: Kiểm tra trọng số | C28: =IF(ROUND(E21,4)=1,"Hợp lệ – 100%","SAI – tổng trọng số phải = 100%")
A30: NHẬN XÉT & KẾ HOẠCH CẢI THIỆN (Bước 5 – phản hồi kết quả)
A31: Điểm mạnh
A32: Cần cải thiện
A33: Kế hoạch cải thiện
A34: Ý kiến nhân sự
B36: NHÂN SỰ ĐƯỢC ĐÁNH GIÁ | D36: QUẢN LÝ TRỰC TIẾP | G36: NGƯỜI PHÊ DUYỆT
B37: (Ký, ghi rõ họ tên) | D37: (Ký, ghi rõ họ tên) | G37: (Ký, ghi rõ họ tên)

Sheet 05. CB an toàn HSE
A1: BẢNG ĐÁNH GIÁ KPI – CÁN BỘ AN TOÀN, VỆ SINH LAO ĐỘNG (HSE)
A2: Công ty xây dựng · Phụ lục 01 kèm Quy chế đánh giá KPI · KK HOME ·
B4: Họ và tên | E4: Loại kỳ đánh giá | G4: Quý | I4: ← chọn Tháng / Quý / Năm
B5: Mã nhân viên | E5: Kỳ đánh giá | I5: VD: Tháng 9/2026, Quý 3/2026, Năm 2026
B6: Người đánh giá | E6: Ngày đánh giá
B7: Bộ phận | C7: [Ban dự án / Công trường / Phòng ...]
A9: STT | B9: Nhóm tiêu chí | C9: Tiêu chí đánh giá | D9: Cách đo / Chứng cứ chấm điểm | E9: Trọng số | F9: Tự đánh giá (1–5) | G9: Quản lý chấm (1–5) | H9: Điểm quy đổi | I9: Ghi chú / Lý do (bắt buộc khi điểm ≤1,5 hoặc 5)
A10: 1 | B10: Chuyên môn - Nghiệp vụ | C10: Tai nạn, sự cố | D10: 0 tai nạn lao động; 0 sự cố gây thiệt hại tài sản lớn | E10: 0.12 | H10: =IF(ISNUMBER(G10),G10/5*E10*100,0) | J10: CM
A11: 2 | C11: Kiểm tra an toàn hằng ngày | D11: Checklist an toàn hằng ngày đầy đủ; lỗi phát hiện được khắc phục trong hạn | E11: 0.1 | H11: =IF(ISNUMBER(G11),G11/5*E11*100,0) | J11: CM
A12: 3 | C12: Huấn luyện an toàn | D12: 100% người lao động được huấn luyện, có thẻ an toàn trước khi vào công trường | E12: 0.1 | H12: =IF(ISNUMBER(G12),G12/5*E12*100,0) | J12: CM
A13: 4 | C13: Kiểm định thiết bị yêu cầu nghiêm ngặt | D13: Cần trục, vận thăng, giàn giáo… có kiểm định còn hạn trước khi sử dụng | E13: 0.08 | H13: =IF(ISNUMBER(G13),G13/5*E13*100,0) | J13: CM
A14: 5 | B14: Tuân thủ - Thời hạn | C14: Hồ sơ an toàn | D14: Kế hoạch ATVSLĐ, biện pháp an toàn, sổ theo dõi, biên bản đầy đủ | E14: 0.1 | H14: =IF(ISNUMBER(G14),G14/5*E14*100,0) | J14: TT
A15: 6 | C15: Phương tiện bảo vệ cá nhân | D15: Tỷ lệ công nhân dùng đủ bảo hộ khi kiểm tra đột xuất ≥ 98% | E15: 0.1 | H15: =IF(ISNUMBER(G15),G15/5*E15*100,0) | J15: TT
A16: 7 | C16: PCCC, sơ cứu, môi trường | D16: Phương án PCCC, tủ thuốc, diễn tập theo kế hoạch | E16: 0.08 | H16: =IF(ISNUMBER(G16),G16/5*E16*100,0) | J16: TT
A17: 8 | C17: Báo cáo an toàn | D17: Báo cáo tuần, tháng đúng hạn; báo cáo sự cố ngay khi xảy ra | E17: 0.07 | H17: =IF(ISNUMBER(G17),G17/5*E17*100,0) | J17: TT
A18: 9 | B18: Phối hợp - Thái độ | C18: Phối hợp chỉ huy trưởng, nhà thầu phụ | D18: Yêu cầu dừng, khắc phục được thực hiện đầy đủ | E18: 0.1 | H18: =IF(ISNUMBER(G18),G18/5*E18*100,0) | J18: PH
A19: 10 | C19: Văn hóa an toàn | D19: Họp an toàn đầu ca; khen thưởng, nhắc nhở kịp thời | E19: 0.08 | H19: =IF(ISNUMBER(G19),G19/5*E19*100,0) | J19: PH
A20: 11 | C20: Chủ động phòng ngừa | D20: Nhận diện rủi ro trước khi thi công hạng mục mới | E20: 0.07 | H20: =IF(ISNUMBER(G20),G20/5*E20*100,0) | J20: PH
A21: TỔNG CỘNG | E21: =SUM(E10:E20) | H21: =SUM(H10:H20)
A23: KẾT QUẢ ĐÁNH GIÁ | D23: ĐIỂM THEO NHÓM TIÊU CHÍ
A24: Tổng điểm chính thức | C24: =H21 | D24: Nhóm tiêu chí | E24: Trọng số | F24: Điểm tối đa | G24: Điểm đạt | H24: Tỷ lệ đạt
A25: Điểm tự đánh giá | C25: =IF(COUNT(F10:F20)=0,"",SUMPRODUCT(F10:F20,E10:E20)/5*100) | D25: Chuyên môn - Nghiệp vụ | E25: =SUMIF($J$10:$J$20,"CM",$E$10:$E$20) | F25: =E25*100 | G25: =SUMIF($J$10:$J$20,"CM",$H$10:$H$20) | H25: =IF(F25=0,0,G25/F25)
A26: Tiêu chí đã chấm | C26: =COUNT(G10:G20)&" / 11" | D26: Tuân thủ - Thời hạn | E26: =SUMIF($J$10:$J$20,"TT",$E$10:$E$20) | F26: =E26*100 | G26: =SUMIF($J$10:$J$20,"TT",$H$10:$H$20) | H26: =IF(F26=0,0,G26/F26)
A27: Xếp loại | C27: =IF(COUNT(G10:G20)=0,"Chưa chấm",IF(COUNT(G10:G20)<11,"Chưa chấm đủ",IF(H21>=80,"Xuất sắc",IF(H21>=70,"Đạt","Cần cải thiện")))) | D27: Phối hợp - Thái độ | E27: =SUMIF($J$10:$J$20,"PH",$E$10:$E$20) | F27: =E27*100 | G27: =SUMIF($J$10:$J$20,"PH",$H$10:$H$20) | H27: =IF(F27=0,0,G27/F27)
A28: Kiểm tra trọng số | C28: =IF(ROUND(E21,4)=1,"Hợp lệ – 100%","SAI – tổng trọng số phải = 100%")
A30: NHẬN XÉT & KẾ HOẠCH CẢI THIỆN (Bước 5 – phản hồi kết quả)
A31: Điểm mạnh
A32: Cần cải thiện
A33: Kế hoạch cải thiện
A34: Ý kiến nhân sự
B36: NHÂN SỰ ĐƯỢC ĐÁNH GIÁ | D36: QUẢN LÝ TRỰC TIẾP | G36: NGƯỜI PHÊ DUYỆT
B37: (Ký, ghi rõ họ tên) | D37: (Ký, ghi rõ họ tên) | G37: (Ký, ghi rõ họ tên)

Sheet 06. KS dự toán - đấu thầu
A1: BẢNG ĐÁNH GIÁ KPI – KỸ SƯ DỰ TOÁN – ĐẤU THẦU
A2: Công ty xây dựng · Phụ lục 01 kèm Quy chế đánh giá KPI · KK HOME ·
B4: Họ và tên | E4: Loại kỳ đánh giá | G4: Quý | I4: ← chọn Tháng / Quý / Năm
B5: Mã nhân viên | E5: Kỳ đánh giá | I5: VD: Tháng 9/2026, Quý 3/2026, Năm 2026
B6: Người đánh giá | E6: Ngày đánh giá
B7: Bộ phận | C7: [Ban dự án / Công trường / Phòng ...]
A9: STT | B9: Nhóm tiêu chí | C9: Tiêu chí đánh giá | D9: Cách đo / Chứng cứ chấm điểm | E9: Trọng số | F9: Tự đánh giá (1–5) | G9: Quản lý chấm (1–5) | H9: Điểm quy đổi | I9: Ghi chú / Lý do (bắt buộc khi điểm ≤1,5 hoặc 5)
A10: 1 | B10: Chuyên môn - Nghiệp vụ | C10: Hồ sơ dự thầu đúng hạn | D10: 100% hồ sơ dự thầu nộp đúng hạn, đủ thành phần | E10: 0.12 | H10: =IF(ISNUMBER(G10),G10/5*E10*100,0) | J10: CM
A11: 2 | C11: Độ chính xác dự toán | D11: Chênh lệch dự toán dự thầu với chi phí thực tế hạng mục ≤ [5]% | E11: 0.1 | H11: =IF(ISNUMBER(G11),G11/5*E11*100,0) | J11: CM
A12: 3 | C12: Tỷ lệ trúng thầu | D12: Số gói trúng thầu / số gói tham dự; giá trị trúng thầu so với kế hoạch | E12: 0.1 | H12: =IF(ISNUMBER(G12),G12/5*E12*100,0) | J12: CM
A13: 4 | C13: Bóc tách khối lượng | D13: Sai số khối lượng bóc tách khi đối chiếu ≤ [3]% | E13: 0.08 | H13: =IF(ISNUMBER(G13),G13/5*E13*100,0) | J13: CM
A14: 5 | B14: Tuân thủ - Thời hạn | C14: Tuân thủ hồ sơ mời thầu | D14: Không bị loại vì sai sót hành chính, pháp lý | E14: 0.1 | H14: =IF(ISNUMBER(G14),G14/5*E14*100,0) | J14: TT
A15: 6 | C15: Bảo mật thông tin dự thầu | D15: Không để lộ giá dự thầu; tuân thủ quy định đấu thầu | E15: 0.1 | H15: =IF(ISNUMBER(G15),G15/5*E15*100,0) | J15: TT
A16: 7 | C16: Cập nhật đơn giá, định mức | D16: Thư viện đơn giá vật tư, nhân công, máy cập nhật hằng quý | E16: 0.08 | H16: =IF(ISNUMBER(G16),G16/5*E16*100,0) | J16: TT
A17: 8 | C17: Lưu hồ sơ dự thầu | D17: Hồ sơ lưu đầy đủ, tra cứu được | E17: 0.07 | H17: =IF(ISNUMBER(G17),G17/5*E17*100,0) | J17: TT
A18: 9 | B18: Phối hợp - Thái độ | C18: Phối hợp kỹ thuật, mua hàng | D18: Báo giá vật tư, biện pháp thi công được phối hợp kịp thời | E18: 0.1 | H18: =IF(ISNUMBER(G18),G18/5*E18*100,0) | J18: PH
A19: 10 | C19: Phân tích sau đấu thầu | D19: Báo cáo nguyên nhân trượt, trúng thầu và bài học | E19: 0.08 | H19: =IF(ISNUMBER(G19),G19/5*E19*100,0) | J19: PH
A20: 11 | C20: Chủ động, trách nhiệm | D20: Đáp ứng thời hạn nộp thầu gấp | E20: 0.07 | H20: =IF(ISNUMBER(G20),G20/5*E20*100,0) | J20: PH
A21: TỔNG CỘNG | E21: =SUM(E10:E20) | H21: =SUM(H10:H20)
A23: KẾT QUẢ ĐÁNH GIÁ | D23: ĐIỂM THEO NHÓM TIÊU CHÍ
A24: Tổng điểm chính thức | C24: =H21 | D24: Nhóm tiêu chí | E24: Trọng số | F24: Điểm tối đa | G24: Điểm đạt | H24: Tỷ lệ đạt
A25: Điểm tự đánh giá | C25: =IF(COUNT(F10:F20)=0,"",SUMPRODUCT(F10:F20,E10:E20)/5*100) | D25: Chuyên môn - Nghiệp vụ | E25: =SUMIF($J$10:$J$20,"CM",$E$10:$E$20) | F25: =E25*100 | G25: =SUMIF($J$10:$J$20,"CM",$H$10:$H$20) | H25: =IF(F25=0,0,G25/F25)
A26: Tiêu chí đã chấm | C26: =COUNT(G10:G20)&" / 11" | D26: Tuân thủ - Thời hạn | E26: =SUMIF($J$10:$J$20,"TT",$E$10:$E$20) | F26: =E26*100 | G26: =SUMIF($J$10:$J$20,"TT",$H$10:$H$20) | H26: =IF(F26=0,0,G26/F26)
A27: Xếp loại | C27: =IF(COUNT(G10:G20)=0,"Chưa chấm",IF(COUNT(G10:G20)<11,"Chưa chấm đủ",IF(H21>=80,"Xuất sắc",IF(H21>=70,"Đạt","Cần cải thiện")))) | D27: Phối hợp - Thái độ | E27: =SUMIF($J$10:$J$20,"PH",$E$10:$E$20) | F27: =E27*100 | G27: =SUMIF($J$10:$J$20,"PH",$H$10:$H$20) | H27: =IF(F27=0,0,G27/F27)
A28: Kiểm tra trọng số | C28: =IF(ROUND(E21,4)=1,"Hợp lệ – 100%","SAI – tổng trọng số phải = 100%")
A30: NHẬN XÉT & KẾ HOẠCH CẢI THIỆN (Bước 5 – phản hồi kết quả)
A31: Điểm mạnh
A32: Cần cải thiện
A33: Kế hoạch cải thiện
A34: Ý kiến nhân sự
B36: NHÂN SỰ ĐƯỢC ĐÁNH GIÁ | D36: QUẢN LÝ TRỰC TIẾP | G36: NGƯỜI PHÊ DUYỆT
B37: (Ký, ghi rõ họ tên) | D37: (Ký, ghi rõ họ tên) | G37: (Ký, ghi rõ họ tên)

Sheet 07. KS thanh quyết toán
A1: BẢNG ĐÁNH GIÁ KPI – KỸ SƯ THANH TOÁN – QUYẾT TOÁN, HỒ SƠ HOÀN CÔNG
A2: Công ty xây dựng · Phụ lục 01 kèm Quy chế đánh giá KPI · KK HOME ·
B4: Họ và tên | E4: Loại kỳ đánh giá | G4: Quý | I4: ← chọn Tháng / Quý / Năm
B5: Mã nhân viên | E5: Kỳ đánh giá | I5: VD: Tháng 9/2026, Quý 3/2026, Năm 2026
B6: Người đánh giá | E6: Ngày đánh giá
B7: Bộ phận | C7: [Ban dự án / Công trường / Phòng ...]
A9: STT | B9: Nhóm tiêu chí | C9: Tiêu chí đánh giá | D9: Cách đo / Chứng cứ chấm điểm | E9: Trọng số | F9: Tự đánh giá (1–5) | G9: Quản lý chấm (1–5) | H9: Điểm quy đổi | I9: Ghi chú / Lý do (bắt buộc khi điểm ≤1,5 hoặc 5)
A10: 1 | B10: Chuyên môn - Nghiệp vụ | C10: Hồ sơ thanh toán giai đoạn | D10: Hồ sơ thanh toán với chủ đầu tư lập trong [05] ngày sau nghiệm thu giai đoạn | E10: 0.12 | H10: =IF(ISNUMBER(G10),G10/5*E10*100,0) | J10: CM
A11: 2 | C11: Giá trị được phê duyệt | D11: Giá trị chủ đầu tư phê duyệt / giá trị đề nghị ≥ [95]% | E11: 0.1 | H11: =IF(ISNUMBER(G11),G11/5*E11*100,0) | J11: CM
A12: 3 | C12: Hồ sơ quyết toán công trình | D12: Hồ sơ quyết toán hoàn thành đúng hạn hợp đồng | E12: 0.1 | H12: =IF(ISNUMBER(G12),G12/5*E12*100,0) | J12: CM
A13: 4 | C13: Thanh toán thầu phụ đúng khối lượng | D13: Khối lượng thanh toán thầu phụ khớp nghiệm thu thực tế; không thanh toán vượt | E13: 0.08 | H13: =IF(ISNUMBER(G13),G13/5*E13*100,0) | J13: CM
A14: 5 | B14: Tuân thủ - Thời hạn | C14: Hồ sơ hoàn công | D14: Bản vẽ hoàn công, hồ sơ nghiệm thu đầy đủ theo quy định | E14: 0.1 | H14: =IF(ISNUMBER(G14),G14/5*E14*100,0) | J14: TT
A15: 6 | C15: Phát sinh có căn cứ | D15: Khối lượng phát sinh có văn bản xác nhận, phụ lục hợp đồng | E15: 0.1 | H15: =IF(ISNUMBER(G15),G15/5*E15*100,0) | J15: TT
A16: 7 | C16: Đối chiếu công nợ dự án | D16: Đối chiếu công nợ với chủ đầu tư, thầu phụ hằng quý | E16: 0.08 | H16: =IF(ISNUMBER(G16),G16/5*E16*100,0) | J16: TT
A17: 8 | C17: Bảo lãnh, tiền giữ lại | D17: Theo dõi bảo lãnh thực hiện, bảo hành, tiền giữ lại; không để quá hạn | E17: 0.07 | H17: =IF(ISNUMBER(G17),G17/5*E17*100,0) | J17: TT
A18: 9 | B18: Phối hợp - Thái độ | C18: Phối hợp kế toán | D18: Doanh thu, giá vốn công trình khớp số liệu kế toán | E18: 0.1 | H18: =IF(ISNUMBER(G18),G18/5*E18*100,0) | J18: PH
A19: 10 | C19: Phối hợp ban chỉ huy công trường | D19: Thu thập biên bản, nhật ký kịp thời | E19: 0.08 | H19: =IF(ISNUMBER(G19),G19/5*E19*100,0) | J19: PH
A20: 11 | C20: Đôn đốc thu hồi công nợ | D20: Chủ đầu tư thanh toán đúng hạn hợp đồng | E20: 0.07 | H20: =IF(ISNUMBER(G20),G20/5*E20*100,0) | J20: PH
A21: TỔNG CỘNG | E21: =SUM(E10:E20) | H21: =SUM(H10:H20)
A23: KẾT QUẢ ĐÁNH GIÁ | D23: ĐIỂM THEO NHÓM TIÊU CHÍ
A24: Tổng điểm chính thức | C24: =H21 | D24: Nhóm tiêu chí | E24: Trọng số | F24: Điểm tối đa | G24: Điểm đạt | H24: Tỷ lệ đạt
A25: Điểm tự đánh giá | C25: =IF(COUNT(F10:F20)=0,"",SUMPRODUCT(F10:F20,E10:E20)/5*100) | D25: Chuyên môn - Nghiệp vụ | E25: =SUMIF($J$10:$J$20,"CM",$E$10:$E$20) | F25: =E25*100 | G25: =SUMIF($J$10:$J$20,"CM",$H$10:$H$20) | H25: =IF(F25=0,0,G25/F25)
A26: Tiêu chí đã chấm | C26: =COUNT(G10:G20)&" / 11" | D26: Tuân thủ - Thời hạn | E26: =SUMIF($J$10:$J$20,"TT",$E$10:$E$20) | F26: =E26*100 | G26: =SUMIF($J$10:$J$20,"TT",$H$10:$H$20) | H26: =IF(F26=0,0,G26/F26)
A27: Xếp loại | C27: =IF(COUNT(G10:G20)=0,"Chưa chấm",IF(COUNT(G10:G20)<11,"Chưa chấm đủ",IF(H21>=80,"Xuất sắc",IF(H21>=70,"Đạt","Cần cải thiện")))) | D27: Phối hợp - Thái độ | E27: =SUMIF($J$10:$J$20,"PH",$E$10:$E$20) | F27: =E27*100 | G27: =SUMIF($J$10:$J$20,"PH",$H$10:$H$20) | H27: =IF(F27=0,0,G27/F27)
A28: Kiểm tra trọng số | C28: =IF(ROUND(E21,4)=1,"Hợp lệ – 100%","SAI – tổng trọng số phải = 100%")
A30: NHẬN XÉT & KẾ HOẠCH CẢI THIỆN (Bước 5 – phản hồi kết quả)
A31: Điểm mạnh
A32: Cần cải thiện
A33: Kế hoạch cải thiện
A34: Ý kiến nhân sự
B36: NHÂN SỰ ĐƯỢC ĐÁNH GIÁ | D36: QUẢN LÝ TRỰC TIẾP | G36: NGƯỜI PHÊ DUYỆT
B37: (Ký, ghi rõ họ tên) | D37: (Ký, ghi rõ họ tên) | G37: (Ký, ghi rõ họ tên)

Sheet 08. KS kỹ thuật - bản vẽ
A1: BẢNG ĐÁNH GIÁ KPI – KỸ SƯ KỸ THUẬT – BẢN VẼ THI CÔNG (SHOP DRAWING)
A2: Công ty xây dựng · Phụ lục 01 kèm Quy chế đánh giá KPI · KK HOME ·
B4: Họ và tên | E4: Loại kỳ đánh giá | G4: Quý | I4: ← chọn Tháng / Quý / Năm
B5: Mã nhân viên | E5: Kỳ đánh giá | I5: VD: Tháng 9/2026, Quý 3/2026, Năm 2026
B6: Người đánh giá | E6: Ngày đánh giá
B7: Bộ phận | C7: [Ban dự án / Công trường / Phòng ...]
A9: STT | B9: Nhóm tiêu chí | C9: Tiêu chí đánh giá | D9: Cách đo / Chứng cứ chấm điểm | E9: Trọng số | F9: Tự đánh giá (1–5) | G9: Quản lý chấm (1–5) | H9: Điểm quy đổi | I9: Ghi chú / Lý do (bắt buộc khi điểm ≤1,5 hoặc 5)
A10: 1 | B10: Chuyên môn - Nghiệp vụ | C10: Bản vẽ thi công đúng hạn | D10: Bản vẽ thi công nộp trước thời điểm thi công theo kế hoạch | E10: 0.12 | H10: =IF(ISNUMBER(G10),G10/5*E10*100,0) | J10: CM
A11: 2 | C11: Bản vẽ được duyệt lần đầu | D11: Tỷ lệ bản vẽ được tư vấn giám sát, chủ đầu tư duyệt ngay lần đầu ≥ [80]% | E11: 0.1 | H11: =IF(ISNUMBER(G11),G11/5*E11*100,0) | J11: CM
A12: 3 | C12: Phối hợp kết cấu – kiến trúc – MEP | D12: Xung đột phát hiện trước thi công; không phá dỡ do va chạm thiết kế | E12: 0.1 | H12: =IF(ISNUMBER(G12),G12/5*E12*100,0) | J12: CM
A13: 4 | C13: Biện pháp thi công | D13: Biện pháp thi công hạng mục chính lập, duyệt trước khi triển khai | E13: 0.08 | H13: =IF(ISNUMBER(G13),G13/5*E13*100,0) | J13: CM
A14: 5 | B14: Tuân thủ - Thời hạn | C14: Quản lý phiên bản bản vẽ | D14: Công trường dùng đúng phiên bản mới nhất; danh mục bản vẽ cập nhật | E14: 0.1 | H14: =IF(ISNUMBER(G14),G14/5*E14*100,0) | J14: TT
A15: 6 | C15: Tuân thủ tiêu chuẩn thiết kế | D15: Không có lỗi kỹ thuật bị tư vấn giám sát bác bỏ | E15: 0.1 | H15: =IF(ISNUMBER(G15),G15/5*E15*100,0) | J15: TT
A16: 7 | C16: Trả lời yêu cầu làm rõ (RFI) | D16: Yêu cầu làm rõ được trả lời trong [03] ngày | E16: 0.08 | H16: =IF(ISNUMBER(G16),G16/5*E16*100,0) | J16: TT
A17: 8 | C17: Lưu trữ hồ sơ kỹ thuật | D17: Hồ sơ thiết kế, thay đổi thiết kế lưu đủ | E17: 0.07 | H17: =IF(ISNUMBER(G17),G17/5*E17*100,0) | J17: TT
A18: 9 | B18: Phối hợp - Thái độ | C18: Hỗ trợ công trường | D18: Giải đáp kỹ thuật cho kỹ sư hiện trường kịp thời | E18: 0.1 | H18: =IF(ISNUMBER(G18),G18/5*E18*100,0) | J18: PH
A19: 10 | C19: Ứng dụng công nghệ (BIM, phần mềm) | D19: Mức độ ứng dụng; mô hình, dữ liệu cập nhật | E19: 0.08 | H19: =IF(ISNUMBER(G19),G19/5*E19*100,0) | J19: PH
A20: 11 | C20: Tinh thần học hỏi | D20: Cập nhật tiêu chuẩn, phần mềm mới | E20: 0.07 | H20: =IF(ISNUMBER(G20),G20/5*E20*100,0) | J20: PH
A21: TỔNG CỘNG | E21: =SUM(E10:E20) | H21: =SUM(H10:H20)
A23: KẾT QUẢ ĐÁNH GIÁ | D23: ĐIỂM THEO NHÓM TIÊU CHÍ
A24: Tổng điểm chính thức | C24: =H21 | D24: Nhóm tiêu chí | E24: Trọng số | F24: Điểm tối đa | G24: Điểm đạt | H24: Tỷ lệ đạt
A25: Điểm tự đánh giá | C25: =IF(COUNT(F10:F20)=0,"",SUMPRODUCT(F10:F20,E10:E20)/5*100) | D25: Chuyên môn - Nghiệp vụ | E25: =SUMIF($J$10:$J$20,"CM",$E$10:$E$20) | F25: =E25*100 | G25: =SUMIF($J$10:$J$20,"CM",$H$10:$H$20) | H25: =IF(F25=0,0,G25/F25)
A26: Tiêu chí đã chấm | C26: =COUNT(G10:G20)&" / 11" | D26: Tuân thủ - Thời hạn | E26: =SUMIF($J$10:$J$20,"TT",$E$10:$E$20) | F26: =E26*100 | G26: =SUMIF($J$10:$J$20,"TT",$H$10:$H$20) | H26: =IF(F26=0,0,G26/F26)
A27: Xếp loại | C27: =IF(COUNT(G10:G20)=0,"Chưa chấm",IF(COUNT(G10:G20)<11,"Chưa chấm đủ",IF(H21>=80,"Xuất sắc",IF(H21>=70,"Đạt","Cần cải thiện")))) | D27: Phối hợp - Thái độ | E27: =SUMIF($J$10:$J$20,"PH",$E$10:$E$20) | F27: =E27*100 | G27: =SUMIF($J$10:$J$20,"PH",$H$10:$H$20) | H27: =IF(F27=0,0,G27/F27)
A28: Kiểm tra trọng số | C28: =IF(ROUND(E21,4)=1,"Hợp lệ – 100%","SAI – tổng trọng số phải = 100%")
A30: NHẬN XÉT & KẾ HOẠCH CẢI THIỆN (Bước 5 – phản hồi kết quả)
A31: Điểm mạnh
A32: Cần cải thiện
A33: Kế hoạch cải thiện
A34: Ý kiến nhân sự
B36: NHÂN SỰ ĐƯỢC ĐÁNH GIÁ | D36: QUẢN LÝ TRỰC TIẾP | G36: NGƯỜI PHÊ DUYỆT
B37: (Ký, ghi rõ họ tên) | D37: (Ký, ghi rõ họ tên) | G37: (Ký, ghi rõ họ tên)

Sheet 09. KS cơ điện MEP
A1: BẢNG ĐÁNH GIÁ KPI – KỸ SƯ CƠ ĐIỆN (MEP)
A2: Công ty xây dựng · Phụ lục 01 kèm Quy chế đánh giá KPI · KK HOME ·
B4: Họ và tên | E4: Loại kỳ đánh giá | G4: Quý | I4: ← chọn Tháng / Quý / Năm
B5: Mã nhân viên | E5: Kỳ đánh giá | I5: VD: Tháng 9/2026, Quý 3/2026, Năm 2026
B6: Người đánh giá | E6: Ngày đánh giá
B7: Bộ phận | C7: [Ban dự án / Công trường / Phòng ...]
A9: STT | B9: Nhóm tiêu chí | C9: Tiêu chí đánh giá | D9: Cách đo / Chứng cứ chấm điểm | E9: Trọng số | F9: Tự đánh giá (1–5) | G9: Quản lý chấm (1–5) | H9: Điểm quy đổi | I9: Ghi chú / Lý do (bắt buộc khi điểm ≤1,5 hoặc 5)
A10: 1 | B10: Chuyên môn - Nghiệp vụ | C10: Tiến độ thi công MEP | D10: Khối lượng điện, nước, điều hòa, PCCC đạt kế hoạch | E10: 0.12 | H10: =IF(ISNUMBER(G10),G10/5*E10*100,0) | J10: CM
A11: 2 | C11: Chất lượng lắp đặt | D11: Hệ thống đạt thử áp, đo cách điện, chạy thử ngay lần đầu | E11: 0.1 | H11: =IF(ISNUMBER(G11),G11/5*E11*100,0) | J11: CM
A12: 3 | C12: Phối hợp không gian | D12: Không đục phá do lắp đặt sai vị trí so với kết cấu, hoàn thiện | E12: 0.1 | H12: =IF(ISNUMBER(G12),G12/5*E12*100,0) | J12: CM
A13: 4 | C13: Kiểm soát vật tư MEP | D13: Vật tư đúng chủng loại được duyệt; hao hụt trong định mức | E13: 0.08 | H13: =IF(ISNUMBER(G13),G13/5*E13*100,0) | J13: CM
A14: 5 | B14: Tuân thủ - Thời hạn | C14: An toàn điện, làm việc trên cao | D14: Không vi phạm an toàn điện, an toàn làm việc trên cao | E14: 0.1 | H14: =IF(ISNUMBER(G14),G14/5*E14*100,0) | J14: TT
A15: 6 | C15: Hồ sơ thử nghiệm, nghiệm thu | D15: Biên bản thử nghiệm, chạy thử, nghiệm thu đầy đủ | E15: 0.1 | H15: =IF(ISNUMBER(G15),G15/5*E15*100,0) | J15: TT
A16: 7 | C16: Hồ sơ nghiệm thu PCCC | D16: Hồ sơ phục vụ nghiệm thu PCCC chuẩn bị đúng hạn | E16: 0.08 | H16: =IF(ISNUMBER(G16),G16/5*E16*100,0) | J16: TT
A17: 8 | C17: Báo cáo đúng hạn | D17: Báo cáo tiến độ MEP hằng tuần | E17: 0.07 | H17: =IF(ISNUMBER(G17),G17/5*E17*100,0) | J17: TT
A18: 9 | B18: Phối hợp - Thái độ | C18: Phối hợp thầu phụ MEP, nhà cung cấp | D18: Thầu phụ đáp ứng tiến độ; vướng mắc xử lý kịp thời | E18: 0.1 | H18: =IF(ISNUMBER(G18),G18/5*E18*100,0) | J18: PH
A19: 10 | C19: Bàn giao vận hành | D19: Đào tạo, bàn giao tài liệu vận hành cho chủ đầu tư | E19: 0.08 | H19: =IF(ISNUMBER(G19),G19/5*E19*100,0) | J19: PH
A20: 11 | C20: Trách nhiệm bảo hành | D20: Xử lý sự cố trong thời gian bảo hành đúng cam kết | E20: 0.07 | H20: =IF(ISNUMBER(G20),G20/5*E20*100,0) | J20: PH
A21: TỔNG CỘNG | E21: =SUM(E10:E20) | H21: =SUM(H10:H20)
A23: KẾT QUẢ ĐÁNH GIÁ | D23: ĐIỂM THEO NHÓM TIÊU CHÍ
A24: Tổng điểm chính thức | C24: =H21 | D24: Nhóm tiêu chí | E24: Trọng số | F24: Điểm tối đa | G24: Điểm đạt | H24: Tỷ lệ đạt
A25: Điểm tự đánh giá | C25: =IF(COUNT(F10:F20)=0,"",SUMPRODUCT(F10:F20,E10:E20)/5*100) | D25: Chuyên môn - Nghiệp vụ | E25: =SUMIF($J$10:$J$20,"CM",$E$10:$E$20) | F25: =E25*100 | G25: =SUMIF($J$10:$J$20,"CM",$H$10:$H$20) | H25: =IF(F25=0,0,G25/F25)
A26: Tiêu chí đã chấm | C26: =COUNT(G10:G20)&" / 11" | D26: Tuân thủ - Thời hạn | E26: =SUMIF($J$10:$J$20,"TT",$E$10:$E$20) | F26: =E26*100 | G26: =SUMIF($J$10:$J$20,"TT",$H$10:$H$20) | H26: =IF(F26=0,0,G26/F26)
A27: Xếp loại | C27: =IF(COUNT(G10:G20)=0,"Chưa chấm",IF(COUNT(G10:G20)<11,"Chưa chấm đủ",IF(H21>=80,"Xuất sắc",IF(H21>=70,"Đạt","Cần cải thiện")))) | D27: Phối hợp - Thái độ | E27: =SUMIF($J$10:$J$20,"PH",$E$10:$E$20) | F27: =E27*100 | G27: =SUMIF($J$10:$J$20,"PH",$H$10:$H$20) | H27: =IF(F27=0,0,G27/F27)
A28: Kiểm tra trọng số | C28: =IF(ROUND(E21,4)=1,"Hợp lệ – 100%","SAI – tổng trọng số phải = 100%")
A30: NHẬN XÉT & KẾ HOẠCH CẢI THIỆN (Bước 5 – phản hồi kết quả)
A31: Điểm mạnh
A32: Cần cải thiện
A33: Kế hoạch cải thiện
A34: Ý kiến nhân sự
B36: NHÂN SỰ ĐƯỢC ĐÁNH GIÁ | D36: QUẢN LÝ TRỰC TIẾP | G36: NGƯỜI PHÊ DUYỆT
B37: (Ký, ghi rõ họ tên) | D37: (Ký, ghi rõ họ tên) | G37: (Ký, ghi rõ họ tên)

Sheet 10. Trắc đạc viên
A1: BẢNG ĐÁNH GIÁ KPI – CÁN BỘ TRẮC ĐẠC
A2: Công ty xây dựng · Phụ lục 01 kèm Quy chế đánh giá KPI · KK HOME ·
B4: Họ và tên | E4: Loại kỳ đánh giá | G4: Quý | I4: ← chọn Tháng / Quý / Năm
B5: Mã nhân viên | E5: Kỳ đánh giá | I5: VD: Tháng 9/2026, Quý 3/2026, Năm 2026
B6: Người đánh giá | E6: Ngày đánh giá
B7: Bộ phận | C7: [Ban dự án / Công trường / Phòng ...]
A9: STT | B9: Nhóm tiêu chí | C9: Tiêu chí đánh giá | D9: Cách đo / Chứng cứ chấm điểm | E9: Trọng số | F9: Tự đánh giá (1–5) | G9: Quản lý chấm (1–5) | H9: Điểm quy đổi | I9: Ghi chú / Lý do (bắt buộc khi điểm ≤1,5 hoặc 5)
A10: 1 | B10: Chuyên môn - Nghiệp vụ | C10: Độ chính xác định vị | D10: Sai số định vị trục, cao độ trong dung sai; không phải sửa do sai trắc đạc | E10: 0.12 | H10: =IF(ISNUMBER(G10),G10/5*E10*100,0) | J10: CM
A11: 2 | C11: Đáp ứng yêu cầu đo đạc | D11: Yêu cầu đo của công trường được đáp ứng trong [04] giờ | E11: 0.1 | H11: =IF(ISNUMBER(G11),G11/5*E11*100,0) | J11: CM
A12: 3 | C12: Quan trắc lún, nghiêng | D12: Đủ chu kỳ theo đề cương; bất thường được báo ngay | E12: 0.1 | H12: =IF(ISNUMBER(G12),G12/5*E12*100,0) | J12: CM
A13: 4 | C13: Đo khối lượng, hoàn công | D13: Số liệu đào đắp, hoàn công chính xác | E13: 0.08 | H13: =IF(ISNUMBER(G13),G13/5*E13*100,0) | J13: CM
A14: 5 | B14: Tuân thủ - Thời hạn | C14: Hồ sơ trắc đạc | D14: Sổ đo, biên bản bàn giao mốc, kết quả quan trắc lưu đủ | E14: 0.1 | H14: =IF(ISNUMBER(G14),G14/5*E14*100,0) | J14: TT
A15: 6 | C15: Kiểm định máy đo | D15: Máy toàn đạc, thủy bình kiểm định, hiệu chuẩn còn hạn | E15: 0.1 | H15: =IF(ISNUMBER(G15),G15/5*E15*100,0) | J15: TT
A16: 7 | C16: Bảo vệ hệ mốc | D16: Hệ mốc chuẩn được bảo vệ, kiểm tra định kỳ | E16: 0.08 | H16: =IF(ISNUMBER(G16),G16/5*E16*100,0) | J16: TT
A17: 8 | C17: Báo cáo đúng hạn | D17: Kết quả đo gửi bộ phận kỹ thuật trong ngày | E17: 0.07 | H17: =IF(ISNUMBER(G17),G17/5*E17*100,0) | J17: TT
A18: 9 | B18: Phối hợp - Thái độ | C18: Phối hợp kỹ sư hiện trường | D18: Lịch đo bám kế hoạch thi công | E18: 0.1 | H18: =IF(ISNUMBER(G18),G18/5*E18*100,0) | J18: PH
A19: 10 | C19: Bảo quản thiết bị | D19: Không hư hỏng thiết bị do lỗi sử dụng | E19: 0.08 | H19: =IF(ISNUMBER(G19),G19/5*E19*100,0) | J19: PH
A20: 11 | C20: Tinh thần trách nhiệm | D20: Sẵn sàng làm ngoài giờ khi đổ bê tông, lắp dựng | E20: 0.07 | H20: =IF(ISNUMBER(G20),G20/5*E20*100,0) | J20: PH
A21: TỔNG CỘNG | E21: =SUM(E10:E20) | H21: =SUM(H10:H20)
A23: KẾT QUẢ ĐÁNH GIÁ | D23: ĐIỂM THEO NHÓM TIÊU CHÍ
A24: Tổng điểm chính thức | C24: =H21 | D24: Nhóm tiêu chí | E24: Trọng số | F24: Điểm tối đa | G24: Điểm đạt | H24: Tỷ lệ đạt
A25: Điểm tự đánh giá | C25: =IF(COUNT(F10:F20)=0,"",SUMPRODUCT(F10:F20,E10:E20)/5*100) | D25: Chuyên môn - Nghiệp vụ | E25: =SUMIF($J$10:$J$20,"CM",$E$10:$E$20) | F25: =E25*100 | G25: =SUMIF($J$10:$J$20,"CM",$H$10:$H$20) | H25: =IF(F25=0,0,G25/F25)
A26: Tiêu chí đã chấm | C26: =COUNT(G10:G20)&" / 11" | D26: Tuân thủ - Thời hạn | E26: =SUMIF($J$10:$J$20,"TT",$E$10:$E$20) | F26: =E26*100 | G26: =SUMIF($J$10:$J$20,"TT",$H$10:$H$20) | H26: =IF(F26=0,0,G26/F26)
A27: Xếp loại | C27: =IF(COUNT(G10:G20)=0,"Chưa chấm",IF(COUNT(G10:G20)<11,"Chưa chấm đủ",IF(H21>=80,"Xuất sắc",IF(H21>=70,"Đạt","Cần cải thiện")))) | D27: Phối hợp - Thái độ | E27: =SUMIF($J$10:$J$20,"PH",$E$10:$E$20) | F27: =E27*100 | G27: =SUMIF($J$10:$J$20,"PH",$H$10:$H$20) | H27: =IF(F27=0,0,G27/F27)
A28: Kiểm tra trọng số | C28: =IF(ROUND(E21,4)=1,"Hợp lệ – 100%","SAI – tổng trọng số phải = 100%")
A30: NHẬN XÉT & KẾ HOẠCH CẢI THIỆN (Bước 5 – phản hồi kết quả)
A31: Điểm mạnh
A32: Cần cải thiện
A33: Kế hoạch cải thiện
A34: Ý kiến nhân sự
B36: NHÂN SỰ ĐƯỢC ĐÁNH GIÁ | D36: QUẢN LÝ TRỰC TIẾP | G36: NGƯỜI PHÊ DUYỆT
B37: (Ký, ghi rõ họ tên) | D37: (Ký, ghi rõ họ tên) | G37: (Ký, ghi rõ họ tên)

Sheet 11. CB vật tư - thủ kho CT
A1: BẢNG ĐÁNH GIÁ KPI – CÁN BỘ VẬT TƯ – THỦ KHO CÔNG TRƯỜNG
A2: Công ty xây dựng · Phụ lục 01 kèm Quy chế đánh giá KPI · KK HOME ·
B4: Họ và tên | E4: Loại kỳ đánh giá | G4: Quý | I4: ← chọn Tháng / Quý / Năm
B5: Mã nhân viên | E5: Kỳ đánh giá | I5: VD: Tháng 9/2026, Quý 3/2026, Năm 2026
B6: Người đánh giá | E6: Ngày đánh giá
B7: Bộ phận | C7: [Ban dự án / Công trường / Phòng ...]
A9: STT | B9: Nhóm tiêu chí | C9: Tiêu chí đánh giá | D9: Cách đo / Chứng cứ chấm điểm | E9: Trọng số | F9: Tự đánh giá (1–5) | G9: Quản lý chấm (1–5) | H9: Điểm quy đổi | I9: Ghi chú / Lý do (bắt buộc khi điểm ≤1,5 hoặc 5)
A10: 1 | B10: Chuyên môn - Nghiệp vụ | C10: Cung ứng vật tư đúng tiến độ | D10: Vật tư có mặt trước thời điểm thi công; công trường không chờ vật tư | E10: 0.12 | H10: =IF(ISNUMBER(G10),G10/5*E10*100,0) | J10: CM
A11: 2 | C11: Nhập – xuất – tồn chính xác | D11: Chênh lệch kiểm kê kho công trường ≤ [0,5]% giá trị | E11: 0.1 | H11: =IF(ISNUMBER(G11),G11/5*E11*100,0) | J11: CM
A12: 3 | C12: Kiểm tra vật tư nhập | D12: Đúng chủng loại, có chứng chỉ, có biên bản giao nhận | E12: 0.1 | H12: =IF(ISNUMBER(G12),G12/5*E12*100,0) | J12: CM
A13: 4 | C13: Hao hụt vật tư | D13: Hao hụt vật tư chính trong định mức; đối chiếu xuất – định mức – thực tế | E13: 0.08 | H13: =IF(ISNUMBER(G13),G13/5*E13*100,0) | J13: CM
A14: 5 | B14: Tuân thủ - Thời hạn | C14: Chứng từ nhập, xuất | D14: Phiếu nhập, xuất, biên bản giao nhận đủ chữ ký, gửi kế toán đúng hạn | E14: 0.1 | H14: =IF(ISNUMBER(G14),G14/5*E14*100,0) | J14: TT
A15: 6 | C15: Bảo quản vật tư | D15: Không hư hỏng, mất mát do bảo quản | E15: 0.1 | H15: =IF(ISNUMBER(G15),G15/5*E15*100,0) | J15: TT
A16: 7 | C16: Kiểm kê định kỳ | D16: Kiểm kê tháng, đối chiếu với kế toán | E16: 0.08 | H16: =IF(ISNUMBER(G16),G16/5*E16*100,0) | J16: TT
A17: 8 | C17: Theo dõi máy, CCDC công trường | D17: Sổ theo dõi máy, CCDC; bàn giao, thu hồi khi kết thúc | E17: 0.07 | H17: =IF(ISNUMBER(G17),G17/5*E17*100,0) | J17: TT
A18: 9 | B18: Phối hợp - Thái độ | C18: Phối hợp mua hàng, kỹ thuật | D18: Kế hoạch vật tư tuần được thống nhất | E18: 0.1 | H18: =IF(ISNUMBER(G18),G18/5*E18*100,0) | J18: PH
A19: 10 | C19: Quản lý giao hàng của nhà cung cấp | D19: Giao hàng đúng hẹn; phản hồi sai lệch kịp thời | E19: 0.08 | H19: =IF(ISNUMBER(G19),G19/5*E19*100,0) | J19: PH
A20: 11 | C20: Trung thực, trách nhiệm | D20: Không nhận quà, hoa hồng trái Quy tắc ứng xử | E20: 0.07 | H20: =IF(ISNUMBER(G20),G20/5*E20*100,0) | J20: PH
A21: TỔNG CỘNG | E21: =SUM(E10:E20) | H21: =SUM(H10:H20)
A23: KẾT QUẢ ĐÁNH GIÁ | D23: ĐIỂM THEO NHÓM TIÊU CHÍ
A24: Tổng điểm chính thức | C24: =H21 | D24: Nhóm tiêu chí | E24: Trọng số | F24: Điểm tối đa | G24: Điểm đạt | H24: Tỷ lệ đạt
A25: Điểm tự đánh giá | C25: =IF(COUNT(F10:F20)=0,"",SUMPRODUCT(F10:F20,E10:E20)/5*100) | D25: Chuyên môn - Nghiệp vụ | E25: =SUMIF($J$10:$J$20,"CM",$E$10:$E$20) | F25: =E25*100 | G25: =SUMIF($J$10:$J$20,"CM",$H$10:$H$20) | H25: =IF(F25=0,0,G25/F25)
A26: Tiêu chí đã chấm | C26: =COUNT(G10:G20)&" / 11" | D26: Tuân thủ - Thời hạn | E26: =SUMIF($J$10:$J$20,"TT",$E$10:$E$20) | F26: =E26*100 | G26: =SUMIF($J$10:$J$20,"TT",$H$10:$H$20) | H26: =IF(F26=0,0,G26/F26)
A27: Xếp loại | C27: =IF(COUNT(G10:G20)=0,"Chưa chấm",IF(COUNT(G10:G20)<11,"Chưa chấm đủ",IF(H21>=80,"Xuất sắc",IF(H21>=70,"Đạt","Cần cải thiện")))) | D27: Phối hợp - Thái độ | E27: =SUMIF($J$10:$J$20,"PH",$E$10:$E$20) | F27: =E27*100 | G27: =SUMIF($J$10:$J$20,"PH",$H$10:$H$20) | H27: =IF(F27=0,0,G27/F27)
A28: Kiểm tra trọng số | C28: =IF(ROUND(E21,4)=1,"Hợp lệ – 100%","SAI – tổng trọng số phải = 100%")
A30: NHẬN XÉT & KẾ HOẠCH CẢI THIỆN (Bước 5 – phản hồi kết quả)
A31: Điểm mạnh
A32: Cần cải thiện
A33: Kế hoạch cải thiện
A34: Ý kiến nhân sự
B36: NHÂN SỰ ĐƯỢC ĐÁNH GIÁ | D36: QUẢN LÝ TRỰC TIẾP | G36: NGƯỜI PHÊ DUYỆT
B37: (Ký, ghi rõ họ tên) | D37: (Ký, ghi rõ họ tên) | G37: (Ký, ghi rõ họ tên)

Sheet 12. Kế toán công trình
A1: BẢNG ĐÁNH GIÁ KPI – KẾ TOÁN CÔNG TRÌNH
A2: Công ty xây dựng · Phụ lục 01 kèm Quy chế đánh giá KPI · KK HOME ·
B4: Họ và tên | E4: Loại kỳ đánh giá | G4: Quý | I4: ← chọn Tháng / Quý / Năm
B5: Mã nhân viên | E5: Kỳ đánh giá | I5: VD: Tháng 9/2026, Quý 3/2026, Năm 2026
B6: Người đánh giá | E6: Ngày đánh giá
B7: Bộ phận | C7: [Ban dự án / Công trường / Phòng ...]
A9: STT | B9: Nhóm tiêu chí | C9: Tiêu chí đánh giá | D9: Cách đo / Chứng cứ chấm điểm | E9: Trọng số | F9: Tự đánh giá (1–5) | G9: Quản lý chấm (1–5) | H9: Điểm quy đổi | I9: Ghi chú / Lý do (bắt buộc khi điểm ≤1,5 hoặc 5)
A10: 1 | B10: Chuyên môn - Nghiệp vụ | C10: Tập hợp chi phí theo công trình | D10: Chi phí vật liệu, nhân công, máy, chi phí chung tập hợp đúng mã công trình | E10: 0.12 | H10: =IF(ISNUMBER(G10),G10/5*E10*100,0) | J10: CM
A11: 2 | C11: So sánh chi phí – dự toán | D11: Báo cáo chi phí thực tế so với dự toán hằng tháng | E11: 0.1 | H11: =IF(ISNUMBER(G11),G11/5*E11*100,0) | J11: CM
